{"name": "test_testinterconnection[caseinfo0]", "status": "broken", "statusDetails": {"message": "pymysql.err.OperationalError: (1049, \"Unknown database 'fe465c177ff74c4db3ace4d9f52162d2_data'\")", "trace": "@pytest.fixture(scope='function')\n    def create_mysqldb_fixture():\n        print(\"=============进入数据库创建流程==============\")\n        host = DubugTalk().get_config('mysql', 'host')\n        user = DubugTalk().get_config('mysql', 'user')\n        password = DubugTalk().get_config('mysql', 'password')\n        database = DubugTalk().get_config('mysql', 'database') + '_data'\n>       conn = pymysql.connect(host=host, user=user, password=password,\n                               database=database)  # 建立 MySQL 连接\n\nconftest.py:17: \n_ _ _ _ _ _ _ _ _ _ _ _ _ _ _ _ _ _ _ _ _ _ _ _ _ _ _ _ _ _ _ _ _ _ _ _ _ _ _ _\nD:\\conda\\envs\\api_cms\\lib\\site-packages\\pymysql\\connections.py:358: in __init__\n    self.connect()\nD:\\conda\\envs\\api_cms\\lib\\site-packages\\pymysql\\connections.py:664: in connect\n    self._request_authentication()\nD:\\conda\\envs\\api_cms\\lib\\site-packages\\pymysql\\connections.py:968: in _request_authentication\n    auth_packet = self._process_auth(plugin_name, auth_packet)\nD:\\conda\\envs\\api_cms\\lib\\site-packages\\pymysql\\connections.py:1062: in _process_auth\n    pkt = self._read_packet()\nD:\\conda\\envs\\api_cms\\lib\\site-packages\\pymysql\\connections.py:772: in _read_packet\n    packet.raise_for_error()\nD:\\conda\\envs\\api_cms\\lib\\site-packages\\pymysql\\protocol.py:221: in raise_for_error\n    err.raise_mysql_exception(self._data)\n_ _ _ _ _ _ _ _ _ _ _ _ _ _ _ _ _ _ _ _ _ _ _ _ _ _ _ _ _ _ _ _ _ _ _ _ _ _ _ _\n\ndata = b\"\\xff\\x19\\x04#42000Unknown database 'fe465c177ff74c4db3ace4d9f52162d2_data'\"\n\n    def raise_mysql_exception(data):\n        errno = struct.unpack(\"<h\", data[1:3])[0]\n        errval = data[9:].decode(\"utf-8\", \"replace\")\n        errorclass = error_map.get(errno)\n        if errorclass is None:\n            errorclass = InternalError if errno < 1000 else OperationalError\n>       raise errorclass(errno, errval)\nE       pymysql.err.OperationalError: (1049, \"Unknown database 'fe465c177ff74c4db3ace4d9f52162d2_data'\")\n\nD:\\conda\\envs\\api_cms\\lib\\site-packages\\pymysql\\err.py:143: OperationalError"}, "parameters": [{"name": "caseinfo", "value": "{'name': '测试连接互联项', 'base_url': '${get_base_url(cms_url)}', 'request': {'url': '/api/v1/connection/test', 'method': 'post', 'json': {'id': None, 'name': 'mysql${get_random_number(1000,9999)}', 'connectionType': 1, 'databaseType': 1, 'authenticationType': None, 'server': '${get_config(mysql,host)}', 'port': '${get_config(mysql,port)}', 'database': '${get_config(mysql,database2)}', 'databasePath': '', 'userName': '${get_config(mysql,user)}', 'password': '${get_config(mysql,password)}', 'changedPassword': True, 'mqttType': None, 'pushType': None, 'timingPeriod': None, 'changingPeriod': None, 'cloudDeviceId': '', 'originalSecret': ''}, 'headers': {'X-Project': '${get_extract_data(x_project)}'}}, 'validate': [{'equals': {'status_code': 200}}]}"}], "start": 1706685116007, "stop": 1706685116007, "uuid": "c2d02d1f-9897-40cf-9b11-9bb13f96b23c", "historyId": "94c2a026320e0f47645a5a62cfde90d5", "testCaseId": "d5c1c7a56b146fb4f4c1a8352fa1fcc7", "fullName": "testcase.9_Interconnection.test_interconnection.TestCreat#test_testinterconnection", "labels": [{"name": "story", "value": "接口名称：测试连接互联项"}, {"name": "parentSuite", "value": "testcase.9_Interconnection"}, {"name": "suite", "value": "test_interconnection"}, {"name": "subSuite", "value": "TestCreat"}, {"name": "host", "value": "DESKTOP-R2L1GT1"}, {"name": "thread", "value": "3040-MainThread"}, {"name": "framework", "value": "pytest"}, {"name": "language", "value": "cpython3"}, {"name": "package", "value": "testcase.9_Interconnection.test_interconnection"}]}