[2023-08-08 10:39:06,807] logger_util.py->write_log line:61 [INFO] -------------接口请求开始-----------
[2023-08-08 10:39:06,807] logger_util.py->write_log line:61 [INFO] 接口名称：modbus协议读取-保存寄存器有符号8位整型
[2023-08-08 10:39:06,807] logger_util.py->write_log line:61 [INFO] 接口方式：post
[2023-08-08 10:39:06,807] logger_util.py->write_log line:61 [INFO] 接口路径：http://127.0.0.1:6700/v1/cms/io/read
[2023-08-08 10:39:06,808] logger_util.py->write_log line:61 [INFO] 请求头：{'Content-Type': 'application/json'}
[2023-08-08 10:39:06,808] logger_util.py->write_log line:61 [INFO] 请求参数：{'tagDatas': ['MOD_SINT1']}
[2023-08-08 10:39:06,808] logger_util.py->write_log line:61 [INFO] 文件上传：None
[2023-08-08 10:39:06,811] logger_util.py->error_log line:65 [INFO] 断言失败:msg不等于All read successfully
[2023-08-08 10:39:06,812] logger_util.py->write_log line:61 [INFO] 接口请求失败！
[2023-08-08 10:39:06,812] logger_util.py->write_log line:61 [INFO] -------------接口请求结束-----------

[2023-08-08 10:39:06,812] logger_util.py->error_log line:65 [INFO] 断言异常：异常信息: Traceback (most recent call last):
  File "E:\Project_python\api_SIOT\common\requests_util.py", line 372, in validate_result
    error_log("断言失败:" + assert_key + "不等于" + str(assert_value))
  File "E:\Project_python\api_SIOT\common\logger_util.py", line 66, in error_log
    raise Exception(log_message)
Exception: 断言失败:msg不等于All read successfully

[2023-08-08 10:39:06,813] logger_util.py->error_log line:65 [INFO] 分析YAML文件异常：异常信息: Traceback (most recent call last):
  File "E:\Project_python\api_SIOT\common\requests_util.py", line 372, in validate_result
    error_log("断言失败:" + assert_key + "不等于" + str(assert_value))
  File "E:\Project_python\api_SIOT\common\logger_util.py", line 66, in error_log
    raise Exception(log_message)
Exception: 断言失败:msg不等于All read successfully

During handling of the above exception, another exception occurred:

Traceback (most recent call last):
  File "E:\Project_python\api_SIOT\common\requests_util.py", line 248, in analysis_yaml
    self.validate_result(yq_result, return_data, status_code)
  File "E:\Project_python\api_SIOT\common\requests_util.py", line 416, in validate_result
    error_log("断言异常：异常信息: %s" % str(traceback.format_exc()))
  File "E:\Project_python\api_SIOT\common\logger_util.py", line 66, in error_log
    raise Exception(log_message)
Exception: 断言异常：异常信息: Traceback (most recent call last):
  File "E:\Project_python\api_SIOT\common\requests_util.py", line 372, in validate_result
    error_log("断言失败:" + assert_key + "不等于" + str(assert_value))
  File "E:\Project_python\api_SIOT\common\logger_util.py", line 66, in error_log
    raise Exception(log_message)
Exception: 断言失败:msg不等于All read successfully


[2023-08-08 10:39:06,920] logger_util.py->write_log line:61 [INFO] -------------接口请求开始-----------
[2023-08-08 10:39:06,920] logger_util.py->write_log line:61 [INFO] 接口名称：modbus协议读取-保存寄存器有符号16位整型
[2023-08-08 10:39:06,920] logger_util.py->write_log line:61 [INFO] 接口方式：post
[2023-08-08 10:39:06,920] logger_util.py->write_log line:61 [INFO] 接口路径：http://127.0.0.1:6700/v1/cms/io/read
[2023-08-08 10:39:06,920] logger_util.py->write_log line:61 [INFO] 请求头：{'Content-Type': 'application/json'}
[2023-08-08 10:39:06,921] logger_util.py->write_log line:61 [INFO] 请求参数：{'tagDatas': ['MOD_INT1']}
[2023-08-08 10:39:06,921] logger_util.py->write_log line:61 [INFO] 文件上传：None
[2023-08-08 10:39:06,922] logger_util.py->error_log line:65 [INFO] 断言失败:msg不等于All read successfully
[2023-08-08 10:39:06,922] logger_util.py->write_log line:61 [INFO] 接口请求失败！
[2023-08-08 10:39:06,923] logger_util.py->write_log line:61 [INFO] -------------接口请求结束-----------

[2023-08-08 10:39:06,923] logger_util.py->error_log line:65 [INFO] 断言异常：异常信息: Traceback (most recent call last):
  File "E:\Project_python\api_SIOT\common\requests_util.py", line 372, in validate_result
    error_log("断言失败:" + assert_key + "不等于" + str(assert_value))
  File "E:\Project_python\api_SIOT\common\logger_util.py", line 66, in error_log
    raise Exception(log_message)
Exception: 断言失败:msg不等于All read successfully

[2023-08-08 10:39:06,923] logger_util.py->error_log line:65 [INFO] 分析YAML文件异常：异常信息: Traceback (most recent call last):
  File "E:\Project_python\api_SIOT\common\requests_util.py", line 372, in validate_result
    error_log("断言失败:" + assert_key + "不等于" + str(assert_value))
  File "E:\Project_python\api_SIOT\common\logger_util.py", line 66, in error_log
    raise Exception(log_message)
Exception: 断言失败:msg不等于All read successfully

During handling of the above exception, another exception occurred:

Traceback (most recent call last):
  File "E:\Project_python\api_SIOT\common\requests_util.py", line 248, in analysis_yaml
    self.validate_result(yq_result, return_data, status_code)
  File "E:\Project_python\api_SIOT\common\requests_util.py", line 416, in validate_result
    error_log("断言异常：异常信息: %s" % str(traceback.format_exc()))
  File "E:\Project_python\api_SIOT\common\logger_util.py", line 66, in error_log
    raise Exception(log_message)
Exception: 断言异常：异常信息: Traceback (most recent call last):
  File "E:\Project_python\api_SIOT\common\requests_util.py", line 372, in validate_result
    error_log("断言失败:" + assert_key + "不等于" + str(assert_value))
  File "E:\Project_python\api_SIOT\common\logger_util.py", line 66, in error_log
    raise Exception(log_message)
Exception: 断言失败:msg不等于All read successfully


[2023-08-08 10:39:06,951] logger_util.py->write_log line:61 [INFO] -------------接口请求开始-----------
[2023-08-08 10:39:06,951] logger_util.py->write_log line:61 [INFO] 接口名称：modbus协议读取-保存寄存器有符号32位整型
[2023-08-08 10:39:06,951] logger_util.py->write_log line:61 [INFO] 接口方式：post
[2023-08-08 10:39:06,951] logger_util.py->write_log line:61 [INFO] 接口路径：http://127.0.0.1:6700/v1/cms/io/read
[2023-08-08 10:39:06,951] logger_util.py->write_log line:61 [INFO] 请求头：{'Content-Type': 'application/json'}
[2023-08-08 10:39:06,951] logger_util.py->write_log line:61 [INFO] 请求参数：{'tagDatas': ['MOD_DINT1']}
[2023-08-08 10:39:06,951] logger_util.py->write_log line:61 [INFO] 文件上传：None
[2023-08-08 10:39:06,953] logger_util.py->error_log line:65 [INFO] 断言失败:msg不等于All read successfully
[2023-08-08 10:39:06,953] logger_util.py->write_log line:61 [INFO] 接口请求失败！
[2023-08-08 10:39:06,953] logger_util.py->write_log line:61 [INFO] -------------接口请求结束-----------

[2023-08-08 10:39:06,953] logger_util.py->error_log line:65 [INFO] 断言异常：异常信息: Traceback (most recent call last):
  File "E:\Project_python\api_SIOT\common\requests_util.py", line 372, in validate_result
    error_log("断言失败:" + assert_key + "不等于" + str(assert_value))
  File "E:\Project_python\api_SIOT\common\logger_util.py", line 66, in error_log
    raise Exception(log_message)
Exception: 断言失败:msg不等于All read successfully

[2023-08-08 10:39:06,954] logger_util.py->error_log line:65 [INFO] 分析YAML文件异常：异常信息: Traceback (most recent call last):
  File "E:\Project_python\api_SIOT\common\requests_util.py", line 372, in validate_result
    error_log("断言失败:" + assert_key + "不等于" + str(assert_value))
  File "E:\Project_python\api_SIOT\common\logger_util.py", line 66, in error_log
    raise Exception(log_message)
Exception: 断言失败:msg不等于All read successfully

During handling of the above exception, another exception occurred:

Traceback (most recent call last):
  File "E:\Project_python\api_SIOT\common\requests_util.py", line 248, in analysis_yaml
    self.validate_result(yq_result, return_data, status_code)
  File "E:\Project_python\api_SIOT\common\requests_util.py", line 416, in validate_result
    error_log("断言异常：异常信息: %s" % str(traceback.format_exc()))
  File "E:\Project_python\api_SIOT\common\logger_util.py", line 66, in error_log
    raise Exception(log_message)
Exception: 断言异常：异常信息: Traceback (most recent call last):
  File "E:\Project_python\api_SIOT\common\requests_util.py", line 372, in validate_result
    error_log("断言失败:" + assert_key + "不等于" + str(assert_value))
  File "E:\Project_python\api_SIOT\common\logger_util.py", line 66, in error_log
    raise Exception(log_message)
Exception: 断言失败:msg不等于All read successfully


[2023-08-08 10:39:06,981] logger_util.py->write_log line:61 [INFO] -------------接口请求开始-----------
[2023-08-08 10:39:06,981] logger_util.py->write_log line:61 [INFO] 接口名称：modbus协议读取-保存寄存器无符号8位整型
[2023-08-08 10:39:06,981] logger_util.py->write_log line:61 [INFO] 接口方式：post
[2023-08-08 10:39:06,981] logger_util.py->write_log line:61 [INFO] 接口路径：http://127.0.0.1:6700/v1/cms/io/read
[2023-08-08 10:39:06,981] logger_util.py->write_log line:61 [INFO] 请求头：{'Content-Type': 'application/json'}
[2023-08-08 10:39:06,982] logger_util.py->write_log line:61 [INFO] 请求参数：{'tagDatas': ['MOD_USINT1']}
[2023-08-08 10:39:06,982] logger_util.py->write_log line:61 [INFO] 文件上传：None
[2023-08-08 10:39:06,984] logger_util.py->error_log line:65 [INFO] 断言失败:msg不等于All read successfully
[2023-08-08 10:39:06,984] logger_util.py->write_log line:61 [INFO] 接口请求失败！
[2023-08-08 10:39:06,984] logger_util.py->write_log line:61 [INFO] -------------接口请求结束-----------

[2023-08-08 10:39:06,984] logger_util.py->error_log line:65 [INFO] 断言异常：异常信息: Traceback (most recent call last):
  File "E:\Project_python\api_SIOT\common\requests_util.py", line 372, in validate_result
    error_log("断言失败:" + assert_key + "不等于" + str(assert_value))
  File "E:\Project_python\api_SIOT\common\logger_util.py", line 66, in error_log
    raise Exception(log_message)
Exception: 断言失败:msg不等于All read successfully

[2023-08-08 10:39:06,984] logger_util.py->error_log line:65 [INFO] 分析YAML文件异常：异常信息: Traceback (most recent call last):
  File "E:\Project_python\api_SIOT\common\requests_util.py", line 372, in validate_result
    error_log("断言失败:" + assert_key + "不等于" + str(assert_value))
  File "E:\Project_python\api_SIOT\common\logger_util.py", line 66, in error_log
    raise Exception(log_message)
Exception: 断言失败:msg不等于All read successfully

During handling of the above exception, another exception occurred:

Traceback (most recent call last):
  File "E:\Project_python\api_SIOT\common\requests_util.py", line 248, in analysis_yaml
    self.validate_result(yq_result, return_data, status_code)
  File "E:\Project_python\api_SIOT\common\requests_util.py", line 416, in validate_result
    error_log("断言异常：异常信息: %s" % str(traceback.format_exc()))
  File "E:\Project_python\api_SIOT\common\logger_util.py", line 66, in error_log
    raise Exception(log_message)
Exception: 断言异常：异常信息: Traceback (most recent call last):
  File "E:\Project_python\api_SIOT\common\requests_util.py", line 372, in validate_result
    error_log("断言失败:" + assert_key + "不等于" + str(assert_value))
  File "E:\Project_python\api_SIOT\common\logger_util.py", line 66, in error_log
    raise Exception(log_message)
Exception: 断言失败:msg不等于All read successfully


[2023-08-08 10:39:07,011] logger_util.py->write_log line:61 [INFO] -------------接口请求开始-----------
[2023-08-08 10:39:07,011] logger_util.py->write_log line:61 [INFO] 接口名称：modbus协议读取-保存寄存器无符号16位整型
[2023-08-08 10:39:07,012] logger_util.py->write_log line:61 [INFO] 接口方式：post
[2023-08-08 10:39:07,012] logger_util.py->write_log line:61 [INFO] 接口路径：http://127.0.0.1:6700/v1/cms/io/read
[2023-08-08 10:39:07,012] logger_util.py->write_log line:61 [INFO] 请求头：{'Content-Type': 'application/json'}
[2023-08-08 10:39:07,012] logger_util.py->write_log line:61 [INFO] 请求参数：{'tagDatas': ['MOD_UINT1']}
[2023-08-08 10:39:07,012] logger_util.py->write_log line:61 [INFO] 文件上传：None
[2023-08-08 10:39:07,014] logger_util.py->error_log line:65 [INFO] 断言失败:msg不等于All read successfully
[2023-08-08 10:39:07,014] logger_util.py->write_log line:61 [INFO] 接口请求失败！
[2023-08-08 10:39:07,014] logger_util.py->write_log line:61 [INFO] -------------接口请求结束-----------

[2023-08-08 10:39:07,014] logger_util.py->error_log line:65 [INFO] 断言异常：异常信息: Traceback (most recent call last):
  File "E:\Project_python\api_SIOT\common\requests_util.py", line 372, in validate_result
    error_log("断言失败:" + assert_key + "不等于" + str(assert_value))
  File "E:\Project_python\api_SIOT\common\logger_util.py", line 66, in error_log
    raise Exception(log_message)
Exception: 断言失败:msg不等于All read successfully

[2023-08-08 10:39:07,014] logger_util.py->error_log line:65 [INFO] 分析YAML文件异常：异常信息: Traceback (most recent call last):
  File "E:\Project_python\api_SIOT\common\requests_util.py", line 372, in validate_result
    error_log("断言失败:" + assert_key + "不等于" + str(assert_value))
  File "E:\Project_python\api_SIOT\common\logger_util.py", line 66, in error_log
    raise Exception(log_message)
Exception: 断言失败:msg不等于All read successfully

During handling of the above exception, another exception occurred:

Traceback (most recent call last):
  File "E:\Project_python\api_SIOT\common\requests_util.py", line 248, in analysis_yaml
    self.validate_result(yq_result, return_data, status_code)
  File "E:\Project_python\api_SIOT\common\requests_util.py", line 416, in validate_result
    error_log("断言异常：异常信息: %s" % str(traceback.format_exc()))
  File "E:\Project_python\api_SIOT\common\logger_util.py", line 66, in error_log
    raise Exception(log_message)
Exception: 断言异常：异常信息: Traceback (most recent call last):
  File "E:\Project_python\api_SIOT\common\requests_util.py", line 372, in validate_result
    error_log("断言失败:" + assert_key + "不等于" + str(assert_value))
  File "E:\Project_python\api_SIOT\common\logger_util.py", line 66, in error_log
    raise Exception(log_message)
Exception: 断言失败:msg不等于All read successfully


[2023-08-08 10:39:07,041] logger_util.py->write_log line:61 [INFO] -------------接口请求开始-----------
[2023-08-08 10:39:07,041] logger_util.py->write_log line:61 [INFO] 接口名称：modbus协议读取-保存寄存器无符号32位整型
[2023-08-08 10:39:07,041] logger_util.py->write_log line:61 [INFO] 接口方式：post
[2023-08-08 10:39:07,041] logger_util.py->write_log line:61 [INFO] 接口路径：http://127.0.0.1:6700/v1/cms/io/read
[2023-08-08 10:39:07,041] logger_util.py->write_log line:61 [INFO] 请求头：{'Content-Type': 'application/json'}
[2023-08-08 10:39:07,041] logger_util.py->write_log line:61 [INFO] 请求参数：{'tagDatas': ['MOD_UDINT1']}
[2023-08-08 10:39:07,041] logger_util.py->write_log line:61 [INFO] 文件上传：None
[2023-08-08 10:39:07,043] logger_util.py->error_log line:65 [INFO] 断言失败:msg不等于All read successfully
[2023-08-08 10:39:07,043] logger_util.py->write_log line:61 [INFO] 接口请求失败！
[2023-08-08 10:39:07,043] logger_util.py->write_log line:61 [INFO] -------------接口请求结束-----------

[2023-08-08 10:39:07,043] logger_util.py->error_log line:65 [INFO] 断言异常：异常信息: Traceback (most recent call last):
  File "E:\Project_python\api_SIOT\common\requests_util.py", line 372, in validate_result
    error_log("断言失败:" + assert_key + "不等于" + str(assert_value))
  File "E:\Project_python\api_SIOT\common\logger_util.py", line 66, in error_log
    raise Exception(log_message)
Exception: 断言失败:msg不等于All read successfully

[2023-08-08 10:39:07,044] logger_util.py->error_log line:65 [INFO] 分析YAML文件异常：异常信息: Traceback (most recent call last):
  File "E:\Project_python\api_SIOT\common\requests_util.py", line 372, in validate_result
    error_log("断言失败:" + assert_key + "不等于" + str(assert_value))
  File "E:\Project_python\api_SIOT\common\logger_util.py", line 66, in error_log
    raise Exception(log_message)
Exception: 断言失败:msg不等于All read successfully

During handling of the above exception, another exception occurred:

Traceback (most recent call last):
  File "E:\Project_python\api_SIOT\common\requests_util.py", line 248, in analysis_yaml
    self.validate_result(yq_result, return_data, status_code)
  File "E:\Project_python\api_SIOT\common\requests_util.py", line 416, in validate_result
    error_log("断言异常：异常信息: %s" % str(traceback.format_exc()))
  File "E:\Project_python\api_SIOT\common\logger_util.py", line 66, in error_log
    raise Exception(log_message)
Exception: 断言异常：异常信息: Traceback (most recent call last):
  File "E:\Project_python\api_SIOT\common\requests_util.py", line 372, in validate_result
    error_log("断言失败:" + assert_key + "不等于" + str(assert_value))
  File "E:\Project_python\api_SIOT\common\logger_util.py", line 66, in error_log
    raise Exception(log_message)
Exception: 断言失败:msg不等于All read successfully


[2023-08-08 10:39:07,070] logger_util.py->write_log line:61 [INFO] -------------接口请求开始-----------
[2023-08-08 10:39:07,070] logger_util.py->write_log line:61 [INFO] 接口名称：modbus协议读取-保存寄存器F32位浮点数IEEE754
[2023-08-08 10:39:07,070] logger_util.py->write_log line:61 [INFO] 接口方式：post
[2023-08-08 10:39:07,070] logger_util.py->write_log line:61 [INFO] 接口路径：http://127.0.0.1:6700/v1/cms/io/read
[2023-08-08 10:39:07,071] logger_util.py->write_log line:61 [INFO] 请求头：{'Content-Type': 'application/json'}
[2023-08-08 10:39:07,071] logger_util.py->write_log line:61 [INFO] 请求参数：{'tagDatas': ['MOD_REAL1']}
[2023-08-08 10:39:07,071] logger_util.py->write_log line:61 [INFO] 文件上传：None
[2023-08-08 10:39:07,072] logger_util.py->error_log line:65 [INFO] 断言失败:msg不等于All read successfully
[2023-08-08 10:39:07,072] logger_util.py->write_log line:61 [INFO] 接口请求失败！
[2023-08-08 10:39:07,073] logger_util.py->write_log line:61 [INFO] -------------接口请求结束-----------

[2023-08-08 10:39:07,073] logger_util.py->error_log line:65 [INFO] 断言异常：异常信息: Traceback (most recent call last):
  File "E:\Project_python\api_SIOT\common\requests_util.py", line 372, in validate_result
    error_log("断言失败:" + assert_key + "不等于" + str(assert_value))
  File "E:\Project_python\api_SIOT\common\logger_util.py", line 66, in error_log
    raise Exception(log_message)
Exception: 断言失败:msg不等于All read successfully

[2023-08-08 10:39:07,073] logger_util.py->error_log line:65 [INFO] 分析YAML文件异常：异常信息: Traceback (most recent call last):
  File "E:\Project_python\api_SIOT\common\requests_util.py", line 372, in validate_result
    error_log("断言失败:" + assert_key + "不等于" + str(assert_value))
  File "E:\Project_python\api_SIOT\common\logger_util.py", line 66, in error_log
    raise Exception(log_message)
Exception: 断言失败:msg不等于All read successfully

During handling of the above exception, another exception occurred:

Traceback (most recent call last):
  File "E:\Project_python\api_SIOT\common\requests_util.py", line 248, in analysis_yaml
    self.validate_result(yq_result, return_data, status_code)
  File "E:\Project_python\api_SIOT\common\requests_util.py", line 416, in validate_result
    error_log("断言异常：异常信息: %s" % str(traceback.format_exc()))
  File "E:\Project_python\api_SIOT\common\logger_util.py", line 66, in error_log
    raise Exception(log_message)
Exception: 断言异常：异常信息: Traceback (most recent call last):
  File "E:\Project_python\api_SIOT\common\requests_util.py", line 372, in validate_result
    error_log("断言失败:" + assert_key + "不等于" + str(assert_value))
  File "E:\Project_python\api_SIOT\common\logger_util.py", line 66, in error_log
    raise Exception(log_message)
Exception: 断言失败:msg不等于All read successfully


[2023-08-08 10:39:07,098] logger_util.py->write_log line:61 [INFO] -------------接口请求开始-----------
[2023-08-08 10:39:07,098] logger_util.py->write_log line:61 [INFO] 接口名称：modbus协议读取-保存寄存器二进制变量1
[2023-08-08 10:39:07,098] logger_util.py->write_log line:61 [INFO] 接口方式：post
[2023-08-08 10:39:07,098] logger_util.py->write_log line:61 [INFO] 接口路径：http://127.0.0.1:6700/v1/cms/io/read
[2023-08-08 10:39:07,098] logger_util.py->write_log line:61 [INFO] 请求头：{'Content-Type': 'application/json'}
[2023-08-08 10:39:07,098] logger_util.py->write_log line:61 [INFO] 请求参数：{'tagDatas': ['MOD_BOOL1']}
[2023-08-08 10:39:07,098] logger_util.py->write_log line:61 [INFO] 文件上传：None
[2023-08-08 10:39:07,100] logger_util.py->error_log line:65 [INFO] 断言失败:msg不等于All read successfully
[2023-08-08 10:39:07,100] logger_util.py->write_log line:61 [INFO] 接口请求失败！
[2023-08-08 10:39:07,100] logger_util.py->write_log line:61 [INFO] -------------接口请求结束-----------

[2023-08-08 10:39:07,100] logger_util.py->error_log line:65 [INFO] 断言异常：异常信息: Traceback (most recent call last):
  File "E:\Project_python\api_SIOT\common\requests_util.py", line 372, in validate_result
    error_log("断言失败:" + assert_key + "不等于" + str(assert_value))
  File "E:\Project_python\api_SIOT\common\logger_util.py", line 66, in error_log
    raise Exception(log_message)
Exception: 断言失败:msg不等于All read successfully

[2023-08-08 10:39:07,101] logger_util.py->error_log line:65 [INFO] 分析YAML文件异常：异常信息: Traceback (most recent call last):
  File "E:\Project_python\api_SIOT\common\requests_util.py", line 372, in validate_result
    error_log("断言失败:" + assert_key + "不等于" + str(assert_value))
  File "E:\Project_python\api_SIOT\common\logger_util.py", line 66, in error_log
    raise Exception(log_message)
Exception: 断言失败:msg不等于All read successfully

During handling of the above exception, another exception occurred:

Traceback (most recent call last):
  File "E:\Project_python\api_SIOT\common\requests_util.py", line 248, in analysis_yaml
    self.validate_result(yq_result, return_data, status_code)
  File "E:\Project_python\api_SIOT\common\requests_util.py", line 416, in validate_result
    error_log("断言异常：异常信息: %s" % str(traceback.format_exc()))
  File "E:\Project_python\api_SIOT\common\logger_util.py", line 66, in error_log
    raise Exception(log_message)
Exception: 断言异常：异常信息: Traceback (most recent call last):
  File "E:\Project_python\api_SIOT\common\requests_util.py", line 372, in validate_result
    error_log("断言失败:" + assert_key + "不等于" + str(assert_value))
  File "E:\Project_python\api_SIOT\common\logger_util.py", line 66, in error_log
    raise Exception(log_message)
Exception: 断言失败:msg不等于All read successfully


[2023-08-08 10:39:07,126] logger_util.py->write_log line:61 [INFO] -------------接口请求开始-----------
[2023-08-08 10:39:07,126] logger_util.py->write_log line:61 [INFO] 接口名称：modbus协议读取-保存寄存器二进制变量2
[2023-08-08 10:39:07,126] logger_util.py->write_log line:61 [INFO] 接口方式：post
[2023-08-08 10:39:07,126] logger_util.py->write_log line:61 [INFO] 接口路径：http://127.0.0.1:6700/v1/cms/io/read
[2023-08-08 10:39:07,127] logger_util.py->write_log line:61 [INFO] 请求头：{'Content-Type': 'application/json'}
[2023-08-08 10:39:07,127] logger_util.py->write_log line:61 [INFO] 请求参数：{'tagDatas': ['MOD_BOOL2']}
[2023-08-08 10:39:07,127] logger_util.py->write_log line:61 [INFO] 文件上传：None
[2023-08-08 10:39:07,148] logger_util.py->error_log line:65 [INFO] 断言失败:msg不等于All read successfully
[2023-08-08 10:39:07,148] logger_util.py->write_log line:61 [INFO] 接口请求失败！
[2023-08-08 10:39:07,149] logger_util.py->write_log line:61 [INFO] -------------接口请求结束-----------

[2023-08-08 10:39:07,149] logger_util.py->error_log line:65 [INFO] 断言异常：异常信息: Traceback (most recent call last):
  File "E:\Project_python\api_SIOT\common\requests_util.py", line 372, in validate_result
    error_log("断言失败:" + assert_key + "不等于" + str(assert_value))
  File "E:\Project_python\api_SIOT\common\logger_util.py", line 66, in error_log
    raise Exception(log_message)
Exception: 断言失败:msg不等于All read successfully

[2023-08-08 10:39:07,149] logger_util.py->error_log line:65 [INFO] 分析YAML文件异常：异常信息: Traceback (most recent call last):
  File "E:\Project_python\api_SIOT\common\requests_util.py", line 372, in validate_result
    error_log("断言失败:" + assert_key + "不等于" + str(assert_value))
  File "E:\Project_python\api_SIOT\common\logger_util.py", line 66, in error_log
    raise Exception(log_message)
Exception: 断言失败:msg不等于All read successfully

During handling of the above exception, another exception occurred:

Traceback (most recent call last):
  File "E:\Project_python\api_SIOT\common\requests_util.py", line 248, in analysis_yaml
    self.validate_result(yq_result, return_data, status_code)
  File "E:\Project_python\api_SIOT\common\requests_util.py", line 416, in validate_result
    error_log("断言异常：异常信息: %s" % str(traceback.format_exc()))
  File "E:\Project_python\api_SIOT\common\logger_util.py", line 66, in error_log
    raise Exception(log_message)
Exception: 断言异常：异常信息: Traceback (most recent call last):
  File "E:\Project_python\api_SIOT\common\requests_util.py", line 372, in validate_result
    error_log("断言失败:" + assert_key + "不等于" + str(assert_value))
  File "E:\Project_python\api_SIOT\common\logger_util.py", line 66, in error_log
    raise Exception(log_message)
Exception: 断言失败:msg不等于All read successfully


[2023-08-08 10:39:07,176] logger_util.py->write_log line:61 [INFO] -------------接口请求开始-----------
[2023-08-08 10:39:07,176] logger_util.py->write_log line:61 [INFO] 接口名称：modbus协议读取-保存寄存器字符串
[2023-08-08 10:39:07,176] logger_util.py->write_log line:61 [INFO] 接口方式：post
[2023-08-08 10:39:07,176] logger_util.py->write_log line:61 [INFO] 接口路径：http://127.0.0.1:6700/v1/cms/io/read
[2023-08-08 10:39:07,176] logger_util.py->write_log line:61 [INFO] 请求头：{'Content-Type': 'application/json'}
[2023-08-08 10:39:07,176] logger_util.py->write_log line:61 [INFO] 请求参数：{'tagDatas': ['MOD_STRING1']}
[2023-08-08 10:39:07,176] logger_util.py->write_log line:61 [INFO] 文件上传：None
[2023-08-08 10:39:07,196] logger_util.py->error_log line:65 [INFO] 断言失败:msg不等于All read successfully
[2023-08-08 10:39:07,197] logger_util.py->write_log line:61 [INFO] 接口请求失败！
[2023-08-08 10:39:07,197] logger_util.py->write_log line:61 [INFO] -------------接口请求结束-----------

[2023-08-08 10:39:07,197] logger_util.py->error_log line:65 [INFO] 断言异常：异常信息: Traceback (most recent call last):
  File "E:\Project_python\api_SIOT\common\requests_util.py", line 372, in validate_result
    error_log("断言失败:" + assert_key + "不等于" + str(assert_value))
  File "E:\Project_python\api_SIOT\common\logger_util.py", line 66, in error_log
    raise Exception(log_message)
Exception: 断言失败:msg不等于All read successfully

[2023-08-08 10:39:07,197] logger_util.py->error_log line:65 [INFO] 分析YAML文件异常：异常信息: Traceback (most recent call last):
  File "E:\Project_python\api_SIOT\common\requests_util.py", line 372, in validate_result
    error_log("断言失败:" + assert_key + "不等于" + str(assert_value))
  File "E:\Project_python\api_SIOT\common\logger_util.py", line 66, in error_log
    raise Exception(log_message)
Exception: 断言失败:msg不等于All read successfully

During handling of the above exception, another exception occurred:

Traceback (most recent call last):
  File "E:\Project_python\api_SIOT\common\requests_util.py", line 248, in analysis_yaml
    self.validate_result(yq_result, return_data, status_code)
  File "E:\Project_python\api_SIOT\common\requests_util.py", line 416, in validate_result
    error_log("断言异常：异常信息: %s" % str(traceback.format_exc()))
  File "E:\Project_python\api_SIOT\common\logger_util.py", line 66, in error_log
    raise Exception(log_message)
Exception: 断言异常：异常信息: Traceback (most recent call last):
  File "E:\Project_python\api_SIOT\common\requests_util.py", line 372, in validate_result
    error_log("断言失败:" + assert_key + "不等于" + str(assert_value))
  File "E:\Project_python\api_SIOT\common\logger_util.py", line 66, in error_log
    raise Exception(log_message)
Exception: 断言失败:msg不等于All read successfully


[2023-08-08 10:39:07,223] logger_util.py->write_log line:61 [INFO] -------------接口请求开始-----------
[2023-08-08 10:39:07,224] logger_util.py->write_log line:61 [INFO] 接口名称：modbus协议读取-二进制变量
[2023-08-08 10:39:07,224] logger_util.py->write_log line:61 [INFO] 接口方式：post
[2023-08-08 10:39:07,224] logger_util.py->write_log line:61 [INFO] 接口路径：http://127.0.0.1:6700/v1/cms/io/read
[2023-08-08 10:39:07,224] logger_util.py->write_log line:61 [INFO] 请求头：{'Content-Type': 'application/json'}
[2023-08-08 10:39:07,224] logger_util.py->write_log line:61 [INFO] 请求参数：{'tagDatas': ['MOD_Q0']}
[2023-08-08 10:39:07,224] logger_util.py->write_log line:61 [INFO] 文件上传：None
[2023-08-08 10:39:07,244] logger_util.py->error_log line:65 [INFO] 断言失败:msg不等于All read successfully
[2023-08-08 10:39:07,245] logger_util.py->write_log line:61 [INFO] 接口请求失败！
[2023-08-08 10:39:07,245] logger_util.py->write_log line:61 [INFO] -------------接口请求结束-----------

[2023-08-08 10:39:07,245] logger_util.py->error_log line:65 [INFO] 断言异常：异常信息: Traceback (most recent call last):
  File "E:\Project_python\api_SIOT\common\requests_util.py", line 372, in validate_result
    error_log("断言失败:" + assert_key + "不等于" + str(assert_value))
  File "E:\Project_python\api_SIOT\common\logger_util.py", line 66, in error_log
    raise Exception(log_message)
Exception: 断言失败:msg不等于All read successfully

[2023-08-08 10:39:07,245] logger_util.py->error_log line:65 [INFO] 分析YAML文件异常：异常信息: Traceback (most recent call last):
  File "E:\Project_python\api_SIOT\common\requests_util.py", line 372, in validate_result
    error_log("断言失败:" + assert_key + "不等于" + str(assert_value))
  File "E:\Project_python\api_SIOT\common\logger_util.py", line 66, in error_log
    raise Exception(log_message)
Exception: 断言失败:msg不等于All read successfully

During handling of the above exception, another exception occurred:

Traceback (most recent call last):
  File "E:\Project_python\api_SIOT\common\requests_util.py", line 248, in analysis_yaml
    self.validate_result(yq_result, return_data, status_code)
  File "E:\Project_python\api_SIOT\common\requests_util.py", line 416, in validate_result
    error_log("断言异常：异常信息: %s" % str(traceback.format_exc()))
  File "E:\Project_python\api_SIOT\common\logger_util.py", line 66, in error_log
    raise Exception(log_message)
Exception: 断言异常：异常信息: Traceback (most recent call last):
  File "E:\Project_python\api_SIOT\common\requests_util.py", line 372, in validate_result
    error_log("断言失败:" + assert_key + "不等于" + str(assert_value))
  File "E:\Project_python\api_SIOT\common\logger_util.py", line 66, in error_log
    raise Exception(log_message)
Exception: 断言失败:msg不等于All read successfully


[2023-08-08 10:39:07,272] logger_util.py->write_log line:61 [INFO] -------------接口请求开始-----------
[2023-08-08 10:39:07,272] logger_util.py->write_log line:61 [INFO] 接口名称：modbus协议读取-二进制变量
[2023-08-08 10:39:07,272] logger_util.py->write_log line:61 [INFO] 接口方式：post
[2023-08-08 10:39:07,272] logger_util.py->write_log line:61 [INFO] 接口路径：http://127.0.0.1:6700/v1/cms/io/read
[2023-08-08 10:39:07,272] logger_util.py->write_log line:61 [INFO] 请求头：{'Content-Type': 'application/json'}
[2023-08-08 10:39:07,272] logger_util.py->write_log line:61 [INFO] 请求参数：{'tagDatas': ['MOD_Q1']}
[2023-08-08 10:39:07,272] logger_util.py->write_log line:61 [INFO] 文件上传：None
[2023-08-08 10:39:07,291] logger_util.py->error_log line:65 [INFO] 断言失败:msg不等于All read successfully
[2023-08-08 10:39:07,291] logger_util.py->write_log line:61 [INFO] 接口请求失败！
[2023-08-08 10:39:07,292] logger_util.py->write_log line:61 [INFO] -------------接口请求结束-----------

[2023-08-08 10:39:07,292] logger_util.py->error_log line:65 [INFO] 断言异常：异常信息: Traceback (most recent call last):
  File "E:\Project_python\api_SIOT\common\requests_util.py", line 372, in validate_result
    error_log("断言失败:" + assert_key + "不等于" + str(assert_value))
  File "E:\Project_python\api_SIOT\common\logger_util.py", line 66, in error_log
    raise Exception(log_message)
Exception: 断言失败:msg不等于All read successfully

[2023-08-08 10:39:07,292] logger_util.py->error_log line:65 [INFO] 分析YAML文件异常：异常信息: Traceback (most recent call last):
  File "E:\Project_python\api_SIOT\common\requests_util.py", line 372, in validate_result
    error_log("断言失败:" + assert_key + "不等于" + str(assert_value))
  File "E:\Project_python\api_SIOT\common\logger_util.py", line 66, in error_log
    raise Exception(log_message)
Exception: 断言失败:msg不等于All read successfully

During handling of the above exception, another exception occurred:

Traceback (most recent call last):
  File "E:\Project_python\api_SIOT\common\requests_util.py", line 248, in analysis_yaml
    self.validate_result(yq_result, return_data, status_code)
  File "E:\Project_python\api_SIOT\common\requests_util.py", line 416, in validate_result
    error_log("断言异常：异常信息: %s" % str(traceback.format_exc()))
  File "E:\Project_python\api_SIOT\common\logger_util.py", line 66, in error_log
    raise Exception(log_message)
Exception: 断言异常：异常信息: Traceback (most recent call last):
  File "E:\Project_python\api_SIOT\common\requests_util.py", line 372, in validate_result
    error_log("断言失败:" + assert_key + "不等于" + str(assert_value))
  File "E:\Project_python\api_SIOT\common\logger_util.py", line 66, in error_log
    raise Exception(log_message)
Exception: 断言失败:msg不等于All read successfully


