[2023-05-28 17:20:56,801] logger_util.py->error_log line:65 [INFO] 发送请求异常：异常信息: Traceback (most recent call last):
  File "E:\Project_python\2TestCMS2.0\common\requests_util.py", line 300, in send_request
    kwargs[key] = self.replace_load(value)
  File "E:\Project_python\2TestCMS2.0\common\requests_util.py", line 28, in replace_load
    str_data = json.dumps(data)
  File "D:\Pyhton\Pyton39\lib\json\__init__.py", line 231, in dumps
    return _default_encoder.encode(obj)
  File "D:\Pyhton\Pyton39\lib\json\encoder.py", line 199, in encode
    chunks = self.iterencode(o, _one_shot=True)
  File "D:\Pyhton\Pyton39\lib\json\encoder.py", line 257, in iterencode
    return _iterencode(o, 0)
  File "D:\Pyhton\Pyton39\lib\json\encoder.py", line 179, in default
    raise TypeError(f'Object of type {o.__class__.__name__} '
TypeError: Object of type datetime is not JSON serializable

[2023-05-28 17:20:56,802] logger_util.py->error_log line:65 [INFO] 分析YAML文件异常：异常信息: Traceback (most recent call last):
  File "E:\Project_python\2TestCMS2.0\common\requests_util.py", line 300, in send_request
    kwargs[key] = self.replace_load(value)
  File "E:\Project_python\2TestCMS2.0\common\requests_util.py", line 28, in replace_load
    str_data = json.dumps(data)
  File "D:\Pyhton\Pyton39\lib\json\__init__.py", line 231, in dumps
    return _default_encoder.encode(obj)
  File "D:\Pyhton\Pyton39\lib\json\encoder.py", line 199, in encode
    chunks = self.iterencode(o, _one_shot=True)
  File "D:\Pyhton\Pyton39\lib\json\encoder.py", line 257, in iterencode
    return _iterencode(o, 0)
  File "D:\Pyhton\Pyton39\lib\json\encoder.py", line 179, in default
    raise TypeError(f'Object of type {o.__class__.__name__} '
TypeError: Object of type datetime is not JSON serializable

During handling of the above exception, another exception occurred:

Traceback (most recent call last):
  File "E:\Project_python\2TestCMS2.0\common\requests_util.py", line 179, in analysis_yaml
    res = self.send_request(name =name,method=method,
  File "E:\Project_python\2TestCMS2.0\common\requests_util.py", line 320, in send_request
    error_log("发送请求异常：异常信息: %s" % str(traceback.format_exc()))
  File "E:\Project_python\2TestCMS2.0\common\logger_util.py", line 66, in error_log
    raise Exception(log_message)
Exception: 发送请求异常：异常信息: Traceback (most recent call last):
  File "E:\Project_python\2TestCMS2.0\common\requests_util.py", line 300, in send_request
    kwargs[key] = self.replace_load(value)
  File "E:\Project_python\2TestCMS2.0\common\requests_util.py", line 28, in replace_load
    str_data = json.dumps(data)
  File "D:\Pyhton\Pyton39\lib\json\__init__.py", line 231, in dumps
    return _default_encoder.encode(obj)
  File "D:\Pyhton\Pyton39\lib\json\encoder.py", line 199, in encode
    chunks = self.iterencode(o, _one_shot=True)
  File "D:\Pyhton\Pyton39\lib\json\encoder.py", line 257, in iterencode
    return _iterencode(o, 0)
  File "D:\Pyhton\Pyton39\lib\json\encoder.py", line 179, in default
    raise TypeError(f'Object of type {o.__class__.__name__} '
TypeError: Object of type datetime is not JSON serializable


