[2023-08-08 10:34:00,077] logger_util.py->write_log line:61 [INFO] -------------接口请求开始-----------
[2023-08-08 10:34:00,077] logger_util.py->write_log line:61 [INFO] 接口名称：modbus协议读取-保存寄存器有符号8位整型
[2023-08-08 10:34:00,077] logger_util.py->write_log line:61 [INFO] 接口方式：post
[2023-08-08 10:34:00,077] logger_util.py->write_log line:61 [INFO] 接口路径：http://127.0.0.1:6700/v1/cms/io/write
[2023-08-08 10:34:00,078] logger_util.py->write_log line:61 [INFO] 请求头：{'Content-Type': 'application/json'}
[2023-08-08 10:34:00,078] logger_util.py->write_log line:61 [INFO] 请求参数：{'tagDatas': ['MOD_SINT1']}
[2023-08-08 10:34:00,078] logger_util.py->write_log line:61 [INFO] 文件上传：None
[2023-08-08 10:34:00,082] logger_util.py->error_log line:65 [INFO] 断言失败:msg不等于All write successfully
[2023-08-08 10:34:00,082] logger_util.py->write_log line:61 [INFO] 接口请求失败！
[2023-08-08 10:34:00,082] logger_util.py->write_log line:61 [INFO] -------------接口请求结束-----------

[2023-08-08 10:34:00,083] logger_util.py->error_log line:65 [INFO] 断言异常：异常信息: Traceback (most recent call last):
  File "E:\Project_python\api_SIOT\common\requests_util.py", line 372, in validate_result
    error_log("断言失败:" + assert_key + "不等于" + str(assert_value))
  File "E:\Project_python\api_SIOT\common\logger_util.py", line 66, in error_log
    raise Exception(log_message)
Exception: 断言失败:msg不等于All write successfully

[2023-08-08 10:34:00,083] logger_util.py->error_log line:65 [INFO] 分析YAML文件异常：异常信息: Traceback (most recent call last):
  File "E:\Project_python\api_SIOT\common\requests_util.py", line 372, in validate_result
    error_log("断言失败:" + assert_key + "不等于" + str(assert_value))
  File "E:\Project_python\api_SIOT\common\logger_util.py", line 66, in error_log
    raise Exception(log_message)
Exception: 断言失败:msg不等于All write successfully

During handling of the above exception, another exception occurred:

Traceback (most recent call last):
  File "E:\Project_python\api_SIOT\common\requests_util.py", line 248, in analysis_yaml
    self.validate_result(yq_result, return_data, status_code)
  File "E:\Project_python\api_SIOT\common\requests_util.py", line 416, in validate_result
    error_log("断言异常：异常信息: %s" % str(traceback.format_exc()))
  File "E:\Project_python\api_SIOT\common\logger_util.py", line 66, in error_log
    raise Exception(log_message)
Exception: 断言异常：异常信息: Traceback (most recent call last):
  File "E:\Project_python\api_SIOT\common\requests_util.py", line 372, in validate_result
    error_log("断言失败:" + assert_key + "不等于" + str(assert_value))
  File "E:\Project_python\api_SIOT\common\logger_util.py", line 66, in error_log
    raise Exception(log_message)
Exception: 断言失败:msg不等于All write successfully


[2023-08-08 10:34:00,194] logger_util.py->write_log line:61 [INFO] -------------接口请求开始-----------
[2023-08-08 10:34:00,194] logger_util.py->write_log line:61 [INFO] 接口名称：modbus协议读取-保存寄存器有符号16位整型
[2023-08-08 10:34:00,194] logger_util.py->write_log line:61 [INFO] 接口方式：post
[2023-08-08 10:34:00,194] logger_util.py->write_log line:61 [INFO] 接口路径：http://127.0.0.1:6700/v1/cms/io/write
[2023-08-08 10:34:00,194] logger_util.py->write_log line:61 [INFO] 请求头：{'Content-Type': 'application/json'}
[2023-08-08 10:34:00,194] logger_util.py->write_log line:61 [INFO] 请求参数：{'tagDatas': ['MOD_INT1']}
[2023-08-08 10:34:00,194] logger_util.py->write_log line:61 [INFO] 文件上传：None
[2023-08-08 10:34:00,220] logger_util.py->error_log line:65 [INFO] 断言失败:msg不等于All write successfully
[2023-08-08 10:34:00,221] logger_util.py->write_log line:61 [INFO] 接口请求失败！
[2023-08-08 10:34:00,221] logger_util.py->write_log line:61 [INFO] -------------接口请求结束-----------

[2023-08-08 10:34:00,221] logger_util.py->error_log line:65 [INFO] 断言异常：异常信息: Traceback (most recent call last):
  File "E:\Project_python\api_SIOT\common\requests_util.py", line 372, in validate_result
    error_log("断言失败:" + assert_key + "不等于" + str(assert_value))
  File "E:\Project_python\api_SIOT\common\logger_util.py", line 66, in error_log
    raise Exception(log_message)
Exception: 断言失败:msg不等于All write successfully

[2023-08-08 10:34:00,221] logger_util.py->error_log line:65 [INFO] 分析YAML文件异常：异常信息: Traceback (most recent call last):
  File "E:\Project_python\api_SIOT\common\requests_util.py", line 372, in validate_result
    error_log("断言失败:" + assert_key + "不等于" + str(assert_value))
  File "E:\Project_python\api_SIOT\common\logger_util.py", line 66, in error_log
    raise Exception(log_message)
Exception: 断言失败:msg不等于All write successfully

During handling of the above exception, another exception occurred:

Traceback (most recent call last):
  File "E:\Project_python\api_SIOT\common\requests_util.py", line 248, in analysis_yaml
    self.validate_result(yq_result, return_data, status_code)
  File "E:\Project_python\api_SIOT\common\requests_util.py", line 416, in validate_result
    error_log("断言异常：异常信息: %s" % str(traceback.format_exc()))
  File "E:\Project_python\api_SIOT\common\logger_util.py", line 66, in error_log
    raise Exception(log_message)
Exception: 断言异常：异常信息: Traceback (most recent call last):
  File "E:\Project_python\api_SIOT\common\requests_util.py", line 372, in validate_result
    error_log("断言失败:" + assert_key + "不等于" + str(assert_value))
  File "E:\Project_python\api_SIOT\common\logger_util.py", line 66, in error_log
    raise Exception(log_message)
Exception: 断言失败:msg不等于All write successfully


[2023-08-08 10:34:00,248] logger_util.py->write_log line:61 [INFO] -------------接口请求开始-----------
[2023-08-08 10:34:00,248] logger_util.py->write_log line:61 [INFO] 接口名称：modbus协议读取-保存寄存器有符号32位整型
[2023-08-08 10:34:00,248] logger_util.py->write_log line:61 [INFO] 接口方式：post
[2023-08-08 10:34:00,248] logger_util.py->write_log line:61 [INFO] 接口路径：http://127.0.0.1:6700/v1/cms/io/write
[2023-08-08 10:34:00,248] logger_util.py->write_log line:61 [INFO] 请求头：{'Content-Type': 'application/json'}
[2023-08-08 10:34:00,248] logger_util.py->write_log line:61 [INFO] 请求参数：{'tagDatas': ['MOD_DINT1']}
[2023-08-08 10:34:00,248] logger_util.py->write_log line:61 [INFO] 文件上传：None
[2023-08-08 10:34:00,268] logger_util.py->error_log line:65 [INFO] 断言失败:msg不等于All write successfully
[2023-08-08 10:34:00,268] logger_util.py->write_log line:61 [INFO] 接口请求失败！
[2023-08-08 10:34:00,269] logger_util.py->write_log line:61 [INFO] -------------接口请求结束-----------

[2023-08-08 10:34:00,269] logger_util.py->error_log line:65 [INFO] 断言异常：异常信息: Traceback (most recent call last):
  File "E:\Project_python\api_SIOT\common\requests_util.py", line 372, in validate_result
    error_log("断言失败:" + assert_key + "不等于" + str(assert_value))
  File "E:\Project_python\api_SIOT\common\logger_util.py", line 66, in error_log
    raise Exception(log_message)
Exception: 断言失败:msg不等于All write successfully

[2023-08-08 10:34:00,269] logger_util.py->error_log line:65 [INFO] 分析YAML文件异常：异常信息: Traceback (most recent call last):
  File "E:\Project_python\api_SIOT\common\requests_util.py", line 372, in validate_result
    error_log("断言失败:" + assert_key + "不等于" + str(assert_value))
  File "E:\Project_python\api_SIOT\common\logger_util.py", line 66, in error_log
    raise Exception(log_message)
Exception: 断言失败:msg不等于All write successfully

During handling of the above exception, another exception occurred:

Traceback (most recent call last):
  File "E:\Project_python\api_SIOT\common\requests_util.py", line 248, in analysis_yaml
    self.validate_result(yq_result, return_data, status_code)
  File "E:\Project_python\api_SIOT\common\requests_util.py", line 416, in validate_result
    error_log("断言异常：异常信息: %s" % str(traceback.format_exc()))
  File "E:\Project_python\api_SIOT\common\logger_util.py", line 66, in error_log
    raise Exception(log_message)
Exception: 断言异常：异常信息: Traceback (most recent call last):
  File "E:\Project_python\api_SIOT\common\requests_util.py", line 372, in validate_result
    error_log("断言失败:" + assert_key + "不等于" + str(assert_value))
  File "E:\Project_python\api_SIOT\common\logger_util.py", line 66, in error_log
    raise Exception(log_message)
Exception: 断言失败:msg不等于All write successfully


[2023-08-08 10:34:00,295] logger_util.py->write_log line:61 [INFO] -------------接口请求开始-----------
[2023-08-08 10:34:00,295] logger_util.py->write_log line:61 [INFO] 接口名称：modbus协议读取-保存寄存器无符号8位整型
[2023-08-08 10:34:00,295] logger_util.py->write_log line:61 [INFO] 接口方式：post
[2023-08-08 10:34:00,295] logger_util.py->write_log line:61 [INFO] 接口路径：http://127.0.0.1:6700/v1/cms/io/write
[2023-08-08 10:34:00,295] logger_util.py->write_log line:61 [INFO] 请求头：{'Content-Type': 'application/json'}
[2023-08-08 10:34:00,295] logger_util.py->write_log line:61 [INFO] 请求参数：{'tagDatas': ['MOD_USINT1']}
[2023-08-08 10:34:00,295] logger_util.py->write_log line:61 [INFO] 文件上传：None
[2023-08-08 10:34:00,316] logger_util.py->error_log line:65 [INFO] 断言失败:msg不等于All write successfully
[2023-08-08 10:34:00,317] logger_util.py->write_log line:61 [INFO] 接口请求失败！
[2023-08-08 10:34:00,317] logger_util.py->write_log line:61 [INFO] -------------接口请求结束-----------

[2023-08-08 10:34:00,317] logger_util.py->error_log line:65 [INFO] 断言异常：异常信息: Traceback (most recent call last):
  File "E:\Project_python\api_SIOT\common\requests_util.py", line 372, in validate_result
    error_log("断言失败:" + assert_key + "不等于" + str(assert_value))
  File "E:\Project_python\api_SIOT\common\logger_util.py", line 66, in error_log
    raise Exception(log_message)
Exception: 断言失败:msg不等于All write successfully

[2023-08-08 10:34:00,317] logger_util.py->error_log line:65 [INFO] 分析YAML文件异常：异常信息: Traceback (most recent call last):
  File "E:\Project_python\api_SIOT\common\requests_util.py", line 372, in validate_result
    error_log("断言失败:" + assert_key + "不等于" + str(assert_value))
  File "E:\Project_python\api_SIOT\common\logger_util.py", line 66, in error_log
    raise Exception(log_message)
Exception: 断言失败:msg不等于All write successfully

During handling of the above exception, another exception occurred:

Traceback (most recent call last):
  File "E:\Project_python\api_SIOT\common\requests_util.py", line 248, in analysis_yaml
    self.validate_result(yq_result, return_data, status_code)
  File "E:\Project_python\api_SIOT\common\requests_util.py", line 416, in validate_result
    error_log("断言异常：异常信息: %s" % str(traceback.format_exc()))
  File "E:\Project_python\api_SIOT\common\logger_util.py", line 66, in error_log
    raise Exception(log_message)
Exception: 断言异常：异常信息: Traceback (most recent call last):
  File "E:\Project_python\api_SIOT\common\requests_util.py", line 372, in validate_result
    error_log("断言失败:" + assert_key + "不等于" + str(assert_value))
  File "E:\Project_python\api_SIOT\common\logger_util.py", line 66, in error_log
    raise Exception(log_message)
Exception: 断言失败:msg不等于All write successfully


[2023-08-08 10:34:00,342] logger_util.py->write_log line:61 [INFO] -------------接口请求开始-----------
[2023-08-08 10:34:00,342] logger_util.py->write_log line:61 [INFO] 接口名称：modbus协议读取-保存寄存器无符号16位整型
[2023-08-08 10:34:00,342] logger_util.py->write_log line:61 [INFO] 接口方式：post
[2023-08-08 10:34:00,343] logger_util.py->write_log line:61 [INFO] 接口路径：http://127.0.0.1:6700/v1/cms/io/write
[2023-08-08 10:34:00,343] logger_util.py->write_log line:61 [INFO] 请求头：{'Content-Type': 'application/json'}
[2023-08-08 10:34:00,343] logger_util.py->write_log line:61 [INFO] 请求参数：{'tagDatas': ['MOD_UINT1']}
[2023-08-08 10:34:00,343] logger_util.py->write_log line:61 [INFO] 文件上传：None
[2023-08-08 10:34:00,363] logger_util.py->error_log line:65 [INFO] 断言失败:msg不等于All write successfully
[2023-08-08 10:34:00,363] logger_util.py->write_log line:61 [INFO] 接口请求失败！
[2023-08-08 10:34:00,364] logger_util.py->write_log line:61 [INFO] -------------接口请求结束-----------

[2023-08-08 10:34:00,364] logger_util.py->error_log line:65 [INFO] 断言异常：异常信息: Traceback (most recent call last):
  File "E:\Project_python\api_SIOT\common\requests_util.py", line 372, in validate_result
    error_log("断言失败:" + assert_key + "不等于" + str(assert_value))
  File "E:\Project_python\api_SIOT\common\logger_util.py", line 66, in error_log
    raise Exception(log_message)
Exception: 断言失败:msg不等于All write successfully

[2023-08-08 10:34:00,364] logger_util.py->error_log line:65 [INFO] 分析YAML文件异常：异常信息: Traceback (most recent call last):
  File "E:\Project_python\api_SIOT\common\requests_util.py", line 372, in validate_result
    error_log("断言失败:" + assert_key + "不等于" + str(assert_value))
  File "E:\Project_python\api_SIOT\common\logger_util.py", line 66, in error_log
    raise Exception(log_message)
Exception: 断言失败:msg不等于All write successfully

During handling of the above exception, another exception occurred:

Traceback (most recent call last):
  File "E:\Project_python\api_SIOT\common\requests_util.py", line 248, in analysis_yaml
    self.validate_result(yq_result, return_data, status_code)
  File "E:\Project_python\api_SIOT\common\requests_util.py", line 416, in validate_result
    error_log("断言异常：异常信息: %s" % str(traceback.format_exc()))
  File "E:\Project_python\api_SIOT\common\logger_util.py", line 66, in error_log
    raise Exception(log_message)
Exception: 断言异常：异常信息: Traceback (most recent call last):
  File "E:\Project_python\api_SIOT\common\requests_util.py", line 372, in validate_result
    error_log("断言失败:" + assert_key + "不等于" + str(assert_value))
  File "E:\Project_python\api_SIOT\common\logger_util.py", line 66, in error_log
    raise Exception(log_message)
Exception: 断言失败:msg不等于All write successfully


[2023-08-08 10:34:00,390] logger_util.py->write_log line:61 [INFO] -------------接口请求开始-----------
[2023-08-08 10:34:00,390] logger_util.py->write_log line:61 [INFO] 接口名称：modbus协议读取-保存寄存器无符号32位整型
[2023-08-08 10:34:00,390] logger_util.py->write_log line:61 [INFO] 接口方式：post
[2023-08-08 10:34:00,390] logger_util.py->write_log line:61 [INFO] 接口路径：http://127.0.0.1:6700/v1/cms/io/write
[2023-08-08 10:34:00,390] logger_util.py->write_log line:61 [INFO] 请求头：{'Content-Type': 'application/json'}
[2023-08-08 10:34:00,391] logger_util.py->write_log line:61 [INFO] 请求参数：{'tagDatas': ['MOD_UDINT1']}
[2023-08-08 10:34:00,391] logger_util.py->write_log line:61 [INFO] 文件上传：None
[2023-08-08 10:34:00,411] logger_util.py->error_log line:65 [INFO] 断言失败:msg不等于All write successfully
[2023-08-08 10:34:00,412] logger_util.py->write_log line:61 [INFO] 接口请求失败！
[2023-08-08 10:34:00,412] logger_util.py->write_log line:61 [INFO] -------------接口请求结束-----------

[2023-08-08 10:34:00,412] logger_util.py->error_log line:65 [INFO] 断言异常：异常信息: Traceback (most recent call last):
  File "E:\Project_python\api_SIOT\common\requests_util.py", line 372, in validate_result
    error_log("断言失败:" + assert_key + "不等于" + str(assert_value))
  File "E:\Project_python\api_SIOT\common\logger_util.py", line 66, in error_log
    raise Exception(log_message)
Exception: 断言失败:msg不等于All write successfully

[2023-08-08 10:34:00,412] logger_util.py->error_log line:65 [INFO] 分析YAML文件异常：异常信息: Traceback (most recent call last):
  File "E:\Project_python\api_SIOT\common\requests_util.py", line 372, in validate_result
    error_log("断言失败:" + assert_key + "不等于" + str(assert_value))
  File "E:\Project_python\api_SIOT\common\logger_util.py", line 66, in error_log
    raise Exception(log_message)
Exception: 断言失败:msg不等于All write successfully

During handling of the above exception, another exception occurred:

Traceback (most recent call last):
  File "E:\Project_python\api_SIOT\common\requests_util.py", line 248, in analysis_yaml
    self.validate_result(yq_result, return_data, status_code)
  File "E:\Project_python\api_SIOT\common\requests_util.py", line 416, in validate_result
    error_log("断言异常：异常信息: %s" % str(traceback.format_exc()))
  File "E:\Project_python\api_SIOT\common\logger_util.py", line 66, in error_log
    raise Exception(log_message)
Exception: 断言异常：异常信息: Traceback (most recent call last):
  File "E:\Project_python\api_SIOT\common\requests_util.py", line 372, in validate_result
    error_log("断言失败:" + assert_key + "不等于" + str(assert_value))
  File "E:\Project_python\api_SIOT\common\logger_util.py", line 66, in error_log
    raise Exception(log_message)
Exception: 断言失败:msg不等于All write successfully


[2023-08-08 10:34:00,438] logger_util.py->write_log line:61 [INFO] -------------接口请求开始-----------
[2023-08-08 10:34:00,438] logger_util.py->write_log line:61 [INFO] 接口名称：modbus协议读取-保存寄存器F32位浮点数IEEE754
[2023-08-08 10:34:00,438] logger_util.py->write_log line:61 [INFO] 接口方式：post
[2023-08-08 10:34:00,438] logger_util.py->write_log line:61 [INFO] 接口路径：http://127.0.0.1:6700/v1/cms/io/write
[2023-08-08 10:34:00,438] logger_util.py->write_log line:61 [INFO] 请求头：{'Content-Type': 'application/json'}
[2023-08-08 10:34:00,438] logger_util.py->write_log line:61 [INFO] 请求参数：{'tagDatas': ['MOD_REAL1']}
[2023-08-08 10:34:00,439] logger_util.py->write_log line:61 [INFO] 文件上传：None
[2023-08-08 10:34:00,459] logger_util.py->error_log line:65 [INFO] 断言失败:msg不等于All write successfully
[2023-08-08 10:34:00,459] logger_util.py->write_log line:61 [INFO] 接口请求失败！
[2023-08-08 10:34:00,459] logger_util.py->write_log line:61 [INFO] -------------接口请求结束-----------

[2023-08-08 10:34:00,459] logger_util.py->error_log line:65 [INFO] 断言异常：异常信息: Traceback (most recent call last):
  File "E:\Project_python\api_SIOT\common\requests_util.py", line 372, in validate_result
    error_log("断言失败:" + assert_key + "不等于" + str(assert_value))
  File "E:\Project_python\api_SIOT\common\logger_util.py", line 66, in error_log
    raise Exception(log_message)
Exception: 断言失败:msg不等于All write successfully

[2023-08-08 10:34:00,459] logger_util.py->error_log line:65 [INFO] 分析YAML文件异常：异常信息: Traceback (most recent call last):
  File "E:\Project_python\api_SIOT\common\requests_util.py", line 372, in validate_result
    error_log("断言失败:" + assert_key + "不等于" + str(assert_value))
  File "E:\Project_python\api_SIOT\common\logger_util.py", line 66, in error_log
    raise Exception(log_message)
Exception: 断言失败:msg不等于All write successfully

During handling of the above exception, another exception occurred:

Traceback (most recent call last):
  File "E:\Project_python\api_SIOT\common\requests_util.py", line 248, in analysis_yaml
    self.validate_result(yq_result, return_data, status_code)
  File "E:\Project_python\api_SIOT\common\requests_util.py", line 416, in validate_result
    error_log("断言异常：异常信息: %s" % str(traceback.format_exc()))
  File "E:\Project_python\api_SIOT\common\logger_util.py", line 66, in error_log
    raise Exception(log_message)
Exception: 断言异常：异常信息: Traceback (most recent call last):
  File "E:\Project_python\api_SIOT\common\requests_util.py", line 372, in validate_result
    error_log("断言失败:" + assert_key + "不等于" + str(assert_value))
  File "E:\Project_python\api_SIOT\common\logger_util.py", line 66, in error_log
    raise Exception(log_message)
Exception: 断言失败:msg不等于All write successfully


[2023-08-08 10:34:00,486] logger_util.py->write_log line:61 [INFO] -------------接口请求开始-----------
[2023-08-08 10:34:00,486] logger_util.py->write_log line:61 [INFO] 接口名称：modbus协议读取-保存寄存器二进制变量1
[2023-08-08 10:34:00,486] logger_util.py->write_log line:61 [INFO] 接口方式：post
[2023-08-08 10:34:00,486] logger_util.py->write_log line:61 [INFO] 接口路径：http://127.0.0.1:6700/v1/cms/io/write
[2023-08-08 10:34:00,486] logger_util.py->write_log line:61 [INFO] 请求头：{'Content-Type': 'application/json'}
[2023-08-08 10:34:00,486] logger_util.py->write_log line:61 [INFO] 请求参数：{'tagDatas': ['MOD_BOOL1']}
[2023-08-08 10:34:00,486] logger_util.py->write_log line:61 [INFO] 文件上传：None
[2023-08-08 10:34:00,506] logger_util.py->error_log line:65 [INFO] 断言失败:msg不等于All write successfully
[2023-08-08 10:34:00,506] logger_util.py->write_log line:61 [INFO] 接口请求失败！
[2023-08-08 10:34:00,507] logger_util.py->write_log line:61 [INFO] -------------接口请求结束-----------

[2023-08-08 10:34:00,507] logger_util.py->error_log line:65 [INFO] 断言异常：异常信息: Traceback (most recent call last):
  File "E:\Project_python\api_SIOT\common\requests_util.py", line 372, in validate_result
    error_log("断言失败:" + assert_key + "不等于" + str(assert_value))
  File "E:\Project_python\api_SIOT\common\logger_util.py", line 66, in error_log
    raise Exception(log_message)
Exception: 断言失败:msg不等于All write successfully

[2023-08-08 10:34:00,507] logger_util.py->error_log line:65 [INFO] 分析YAML文件异常：异常信息: Traceback (most recent call last):
  File "E:\Project_python\api_SIOT\common\requests_util.py", line 372, in validate_result
    error_log("断言失败:" + assert_key + "不等于" + str(assert_value))
  File "E:\Project_python\api_SIOT\common\logger_util.py", line 66, in error_log
    raise Exception(log_message)
Exception: 断言失败:msg不等于All write successfully

During handling of the above exception, another exception occurred:

Traceback (most recent call last):
  File "E:\Project_python\api_SIOT\common\requests_util.py", line 248, in analysis_yaml
    self.validate_result(yq_result, return_data, status_code)
  File "E:\Project_python\api_SIOT\common\requests_util.py", line 416, in validate_result
    error_log("断言异常：异常信息: %s" % str(traceback.format_exc()))
  File "E:\Project_python\api_SIOT\common\logger_util.py", line 66, in error_log
    raise Exception(log_message)
Exception: 断言异常：异常信息: Traceback (most recent call last):
  File "E:\Project_python\api_SIOT\common\requests_util.py", line 372, in validate_result
    error_log("断言失败:" + assert_key + "不等于" + str(assert_value))
  File "E:\Project_python\api_SIOT\common\logger_util.py", line 66, in error_log
    raise Exception(log_message)
Exception: 断言失败:msg不等于All write successfully


[2023-08-08 10:34:00,532] logger_util.py->write_log line:61 [INFO] -------------接口请求开始-----------
[2023-08-08 10:34:00,532] logger_util.py->write_log line:61 [INFO] 接口名称：modbus协议读取-保存寄存器二进制变量2
[2023-08-08 10:34:00,533] logger_util.py->write_log line:61 [INFO] 接口方式：post
[2023-08-08 10:34:00,533] logger_util.py->write_log line:61 [INFO] 接口路径：http://127.0.0.1:6700/v1/cms/io/write
[2023-08-08 10:34:00,533] logger_util.py->write_log line:61 [INFO] 请求头：{'Content-Type': 'application/json'}
[2023-08-08 10:34:00,533] logger_util.py->write_log line:61 [INFO] 请求参数：{'tagDatas': ['MOD_BOOL2']}
[2023-08-08 10:34:00,533] logger_util.py->write_log line:61 [INFO] 文件上传：None
[2023-08-08 10:34:00,553] logger_util.py->error_log line:65 [INFO] 断言失败:msg不等于All write successfully
[2023-08-08 10:34:00,553] logger_util.py->write_log line:61 [INFO] 接口请求失败！
[2023-08-08 10:34:00,554] logger_util.py->write_log line:61 [INFO] -------------接口请求结束-----------

[2023-08-08 10:34:00,554] logger_util.py->error_log line:65 [INFO] 断言异常：异常信息: Traceback (most recent call last):
  File "E:\Project_python\api_SIOT\common\requests_util.py", line 372, in validate_result
    error_log("断言失败:" + assert_key + "不等于" + str(assert_value))
  File "E:\Project_python\api_SIOT\common\logger_util.py", line 66, in error_log
    raise Exception(log_message)
Exception: 断言失败:msg不等于All write successfully

[2023-08-08 10:34:00,554] logger_util.py->error_log line:65 [INFO] 分析YAML文件异常：异常信息: Traceback (most recent call last):
  File "E:\Project_python\api_SIOT\common\requests_util.py", line 372, in validate_result
    error_log("断言失败:" + assert_key + "不等于" + str(assert_value))
  File "E:\Project_python\api_SIOT\common\logger_util.py", line 66, in error_log
    raise Exception(log_message)
Exception: 断言失败:msg不等于All write successfully

During handling of the above exception, another exception occurred:

Traceback (most recent call last):
  File "E:\Project_python\api_SIOT\common\requests_util.py", line 248, in analysis_yaml
    self.validate_result(yq_result, return_data, status_code)
  File "E:\Project_python\api_SIOT\common\requests_util.py", line 416, in validate_result
    error_log("断言异常：异常信息: %s" % str(traceback.format_exc()))
  File "E:\Project_python\api_SIOT\common\logger_util.py", line 66, in error_log
    raise Exception(log_message)
Exception: 断言异常：异常信息: Traceback (most recent call last):
  File "E:\Project_python\api_SIOT\common\requests_util.py", line 372, in validate_result
    error_log("断言失败:" + assert_key + "不等于" + str(assert_value))
  File "E:\Project_python\api_SIOT\common\logger_util.py", line 66, in error_log
    raise Exception(log_message)
Exception: 断言失败:msg不等于All write successfully


[2023-08-08 10:34:00,580] logger_util.py->write_log line:61 [INFO] -------------接口请求开始-----------
[2023-08-08 10:34:00,580] logger_util.py->write_log line:61 [INFO] 接口名称：modbus协议读取-保存寄存器字符串
[2023-08-08 10:34:00,581] logger_util.py->write_log line:61 [INFO] 接口方式：post
[2023-08-08 10:34:00,581] logger_util.py->write_log line:61 [INFO] 接口路径：http://127.0.0.1:6700/v1/cms/io/write
[2023-08-08 10:34:00,581] logger_util.py->write_log line:61 [INFO] 请求头：{'Content-Type': 'application/json'}
[2023-08-08 10:34:00,581] logger_util.py->write_log line:61 [INFO] 请求参数：{'tagDatas': ['MOD_STRING1']}
[2023-08-08 10:34:00,581] logger_util.py->write_log line:61 [INFO] 文件上传：None
[2023-08-08 10:34:00,601] logger_util.py->error_log line:65 [INFO] 断言失败:msg不等于All write successfully
[2023-08-08 10:34:00,602] logger_util.py->write_log line:61 [INFO] 接口请求失败！
[2023-08-08 10:34:00,602] logger_util.py->write_log line:61 [INFO] -------------接口请求结束-----------

[2023-08-08 10:34:00,602] logger_util.py->error_log line:65 [INFO] 断言异常：异常信息: Traceback (most recent call last):
  File "E:\Project_python\api_SIOT\common\requests_util.py", line 372, in validate_result
    error_log("断言失败:" + assert_key + "不等于" + str(assert_value))
  File "E:\Project_python\api_SIOT\common\logger_util.py", line 66, in error_log
    raise Exception(log_message)
Exception: 断言失败:msg不等于All write successfully

[2023-08-08 10:34:00,602] logger_util.py->error_log line:65 [INFO] 分析YAML文件异常：异常信息: Traceback (most recent call last):
  File "E:\Project_python\api_SIOT\common\requests_util.py", line 372, in validate_result
    error_log("断言失败:" + assert_key + "不等于" + str(assert_value))
  File "E:\Project_python\api_SIOT\common\logger_util.py", line 66, in error_log
    raise Exception(log_message)
Exception: 断言失败:msg不等于All write successfully

During handling of the above exception, another exception occurred:

Traceback (most recent call last):
  File "E:\Project_python\api_SIOT\common\requests_util.py", line 248, in analysis_yaml
    self.validate_result(yq_result, return_data, status_code)
  File "E:\Project_python\api_SIOT\common\requests_util.py", line 416, in validate_result
    error_log("断言异常：异常信息: %s" % str(traceback.format_exc()))
  File "E:\Project_python\api_SIOT\common\logger_util.py", line 66, in error_log
    raise Exception(log_message)
Exception: 断言异常：异常信息: Traceback (most recent call last):
  File "E:\Project_python\api_SIOT\common\requests_util.py", line 372, in validate_result
    error_log("断言失败:" + assert_key + "不等于" + str(assert_value))
  File "E:\Project_python\api_SIOT\common\logger_util.py", line 66, in error_log
    raise Exception(log_message)
Exception: 断言失败:msg不等于All write successfully


[2023-08-08 10:34:00,628] logger_util.py->write_log line:61 [INFO] -------------接口请求开始-----------
[2023-08-08 10:34:00,629] logger_util.py->write_log line:61 [INFO] 接口名称：modbus协议读取-二进制变量
[2023-08-08 10:34:00,629] logger_util.py->write_log line:61 [INFO] 接口方式：post
[2023-08-08 10:34:00,629] logger_util.py->write_log line:61 [INFO] 接口路径：http://127.0.0.1:6700/v1/cms/io/write
[2023-08-08 10:34:00,629] logger_util.py->write_log line:61 [INFO] 请求头：{'Content-Type': 'application/json'}
[2023-08-08 10:34:00,629] logger_util.py->write_log line:61 [INFO] 请求参数：{'tagDatas': ['MOD_Q0']}
[2023-08-08 10:34:00,629] logger_util.py->write_log line:61 [INFO] 文件上传：None
[2023-08-08 10:34:00,649] logger_util.py->error_log line:65 [INFO] 断言失败:msg不等于All write successfully
[2023-08-08 10:34:00,649] logger_util.py->write_log line:61 [INFO] 接口请求失败！
[2023-08-08 10:34:00,650] logger_util.py->write_log line:61 [INFO] -------------接口请求结束-----------

[2023-08-08 10:34:00,650] logger_util.py->error_log line:65 [INFO] 断言异常：异常信息: Traceback (most recent call last):
  File "E:\Project_python\api_SIOT\common\requests_util.py", line 372, in validate_result
    error_log("断言失败:" + assert_key + "不等于" + str(assert_value))
  File "E:\Project_python\api_SIOT\common\logger_util.py", line 66, in error_log
    raise Exception(log_message)
Exception: 断言失败:msg不等于All write successfully

[2023-08-08 10:34:00,650] logger_util.py->error_log line:65 [INFO] 分析YAML文件异常：异常信息: Traceback (most recent call last):
  File "E:\Project_python\api_SIOT\common\requests_util.py", line 372, in validate_result
    error_log("断言失败:" + assert_key + "不等于" + str(assert_value))
  File "E:\Project_python\api_SIOT\common\logger_util.py", line 66, in error_log
    raise Exception(log_message)
Exception: 断言失败:msg不等于All write successfully

During handling of the above exception, another exception occurred:

Traceback (most recent call last):
  File "E:\Project_python\api_SIOT\common\requests_util.py", line 248, in analysis_yaml
    self.validate_result(yq_result, return_data, status_code)
  File "E:\Project_python\api_SIOT\common\requests_util.py", line 416, in validate_result
    error_log("断言异常：异常信息: %s" % str(traceback.format_exc()))
  File "E:\Project_python\api_SIOT\common\logger_util.py", line 66, in error_log
    raise Exception(log_message)
Exception: 断言异常：异常信息: Traceback (most recent call last):
  File "E:\Project_python\api_SIOT\common\requests_util.py", line 372, in validate_result
    error_log("断言失败:" + assert_key + "不等于" + str(assert_value))
  File "E:\Project_python\api_SIOT\common\logger_util.py", line 66, in error_log
    raise Exception(log_message)
Exception: 断言失败:msg不等于All write successfully


[2023-08-08 10:34:00,676] logger_util.py->write_log line:61 [INFO] -------------接口请求开始-----------
[2023-08-08 10:34:00,677] logger_util.py->write_log line:61 [INFO] 接口名称：modbus协议读取-二进制变量
[2023-08-08 10:34:00,677] logger_util.py->write_log line:61 [INFO] 接口方式：post
[2023-08-08 10:34:00,677] logger_util.py->write_log line:61 [INFO] 接口路径：http://127.0.0.1:6700/v1/cms/io/write
[2023-08-08 10:34:00,677] logger_util.py->write_log line:61 [INFO] 请求头：{'Content-Type': 'application/json'}
[2023-08-08 10:34:00,677] logger_util.py->write_log line:61 [INFO] 请求参数：{'tagDatas': ['MOD_Q1']}
[2023-08-08 10:34:00,677] logger_util.py->write_log line:61 [INFO] 文件上传：None
[2023-08-08 10:34:00,697] logger_util.py->error_log line:65 [INFO] 断言失败:msg不等于All write successfully
[2023-08-08 10:34:00,697] logger_util.py->write_log line:61 [INFO] 接口请求失败！
[2023-08-08 10:34:00,697] logger_util.py->write_log line:61 [INFO] -------------接口请求结束-----------

[2023-08-08 10:34:00,697] logger_util.py->error_log line:65 [INFO] 断言异常：异常信息: Traceback (most recent call last):
  File "E:\Project_python\api_SIOT\common\requests_util.py", line 372, in validate_result
    error_log("断言失败:" + assert_key + "不等于" + str(assert_value))
  File "E:\Project_python\api_SIOT\common\logger_util.py", line 66, in error_log
    raise Exception(log_message)
Exception: 断言失败:msg不等于All write successfully

[2023-08-08 10:34:00,698] logger_util.py->error_log line:65 [INFO] 分析YAML文件异常：异常信息: Traceback (most recent call last):
  File "E:\Project_python\api_SIOT\common\requests_util.py", line 372, in validate_result
    error_log("断言失败:" + assert_key + "不等于" + str(assert_value))
  File "E:\Project_python\api_SIOT\common\logger_util.py", line 66, in error_log
    raise Exception(log_message)
Exception: 断言失败:msg不等于All write successfully

During handling of the above exception, another exception occurred:

Traceback (most recent call last):
  File "E:\Project_python\api_SIOT\common\requests_util.py", line 248, in analysis_yaml
    self.validate_result(yq_result, return_data, status_code)
  File "E:\Project_python\api_SIOT\common\requests_util.py", line 416, in validate_result
    error_log("断言异常：异常信息: %s" % str(traceback.format_exc()))
  File "E:\Project_python\api_SIOT\common\logger_util.py", line 66, in error_log
    raise Exception(log_message)
Exception: 断言异常：异常信息: Traceback (most recent call last):
  File "E:\Project_python\api_SIOT\common\requests_util.py", line 372, in validate_result
    error_log("断言失败:" + assert_key + "不等于" + str(assert_value))
  File "E:\Project_python\api_SIOT\common\logger_util.py", line 66, in error_log
    raise Exception(log_message)
Exception: 断言失败:msg不等于All write successfully


