[2023-08-08 10:35:49,019] logger_util.py->write_log line:61 [INFO] -------------接口请求开始-----------
[2023-08-08 10:35:49,019] logger_util.py->write_log line:61 [INFO] 接口名称：modbus协议读取-保存寄存器有符号8位整型
[2023-08-08 10:35:49,019] logger_util.py->write_log line:61 [INFO] 接口方式：post
[2023-08-08 10:35:49,019] logger_util.py->write_log line:61 [INFO] 接口路径：http://127.0.0.1:6700/v1/cms/io/write
[2023-08-08 10:35:49,020] logger_util.py->write_log line:61 [INFO] 请求头：{'Content-Type': 'application/json'}
[2023-08-08 10:35:49,020] logger_util.py->write_log line:61 [INFO] 请求参数：{'tagDatas': ['MOD_SINT1']}
[2023-08-08 10:35:49,020] logger_util.py->write_log line:61 [INFO] 文件上传：None
[2023-08-08 10:35:49,023] logger_util.py->error_log line:65 [INFO] 断言失败:msg不等于All read successfully
[2023-08-08 10:35:49,023] logger_util.py->write_log line:61 [INFO] 接口请求失败！
[2023-08-08 10:35:49,023] logger_util.py->write_log line:61 [INFO] -------------接口请求结束-----------

[2023-08-08 10:35:49,024] logger_util.py->error_log line:65 [INFO] 断言异常：异常信息: Traceback (most recent call last):
  File "E:\Project_python\api_SIOT\common\requests_util.py", line 372, in validate_result
    error_log("断言失败:" + assert_key + "不等于" + str(assert_value))
  File "E:\Project_python\api_SIOT\common\logger_util.py", line 66, in error_log
    raise Exception(log_message)
Exception: 断言失败:msg不等于All read successfully

[2023-08-08 10:35:49,024] logger_util.py->error_log line:65 [INFO] 分析YAML文件异常：异常信息: Traceback (most recent call last):
  File "E:\Project_python\api_SIOT\common\requests_util.py", line 372, in validate_result
    error_log("断言失败:" + assert_key + "不等于" + str(assert_value))
  File "E:\Project_python\api_SIOT\common\logger_util.py", line 66, in error_log
    raise Exception(log_message)
Exception: 断言失败:msg不等于All read successfully

During handling of the above exception, another exception occurred:

Traceback (most recent call last):
  File "E:\Project_python\api_SIOT\common\requests_util.py", line 248, in analysis_yaml
    self.validate_result(yq_result, return_data, status_code)
  File "E:\Project_python\api_SIOT\common\requests_util.py", line 416, in validate_result
    error_log("断言异常：异常信息: %s" % str(traceback.format_exc()))
  File "E:\Project_python\api_SIOT\common\logger_util.py", line 66, in error_log
    raise Exception(log_message)
Exception: 断言异常：异常信息: Traceback (most recent call last):
  File "E:\Project_python\api_SIOT\common\requests_util.py", line 372, in validate_result
    error_log("断言失败:" + assert_key + "不等于" + str(assert_value))
  File "E:\Project_python\api_SIOT\common\logger_util.py", line 66, in error_log
    raise Exception(log_message)
Exception: 断言失败:msg不等于All read successfully


[2023-08-08 10:35:49,134] logger_util.py->write_log line:61 [INFO] -------------接口请求开始-----------
[2023-08-08 10:35:49,134] logger_util.py->write_log line:61 [INFO] 接口名称：modbus协议读取-保存寄存器有符号16位整型
[2023-08-08 10:35:49,134] logger_util.py->write_log line:61 [INFO] 接口方式：post
[2023-08-08 10:35:49,134] logger_util.py->write_log line:61 [INFO] 接口路径：http://127.0.0.1:6700/v1/cms/io/write
[2023-08-08 10:35:49,134] logger_util.py->write_log line:61 [INFO] 请求头：{'Content-Type': 'application/json'}
[2023-08-08 10:35:49,134] logger_util.py->write_log line:61 [INFO] 请求参数：{'tagDatas': ['MOD_INT1']}
[2023-08-08 10:35:49,134] logger_util.py->write_log line:61 [INFO] 文件上传：None
[2023-08-08 10:35:49,136] logger_util.py->error_log line:65 [INFO] 断言失败:msg不等于All read successfully
[2023-08-08 10:35:49,136] logger_util.py->write_log line:61 [INFO] 接口请求失败！
[2023-08-08 10:35:49,136] logger_util.py->write_log line:61 [INFO] -------------接口请求结束-----------

[2023-08-08 10:35:49,137] logger_util.py->error_log line:65 [INFO] 断言异常：异常信息: Traceback (most recent call last):
  File "E:\Project_python\api_SIOT\common\requests_util.py", line 372, in validate_result
    error_log("断言失败:" + assert_key + "不等于" + str(assert_value))
  File "E:\Project_python\api_SIOT\common\logger_util.py", line 66, in error_log
    raise Exception(log_message)
Exception: 断言失败:msg不等于All read successfully

[2023-08-08 10:35:49,137] logger_util.py->error_log line:65 [INFO] 分析YAML文件异常：异常信息: Traceback (most recent call last):
  File "E:\Project_python\api_SIOT\common\requests_util.py", line 372, in validate_result
    error_log("断言失败:" + assert_key + "不等于" + str(assert_value))
  File "E:\Project_python\api_SIOT\common\logger_util.py", line 66, in error_log
    raise Exception(log_message)
Exception: 断言失败:msg不等于All read successfully

During handling of the above exception, another exception occurred:

Traceback (most recent call last):
  File "E:\Project_python\api_SIOT\common\requests_util.py", line 248, in analysis_yaml
    self.validate_result(yq_result, return_data, status_code)
  File "E:\Project_python\api_SIOT\common\requests_util.py", line 416, in validate_result
    error_log("断言异常：异常信息: %s" % str(traceback.format_exc()))
  File "E:\Project_python\api_SIOT\common\logger_util.py", line 66, in error_log
    raise Exception(log_message)
Exception: 断言异常：异常信息: Traceback (most recent call last):
  File "E:\Project_python\api_SIOT\common\requests_util.py", line 372, in validate_result
    error_log("断言失败:" + assert_key + "不等于" + str(assert_value))
  File "E:\Project_python\api_SIOT\common\logger_util.py", line 66, in error_log
    raise Exception(log_message)
Exception: 断言失败:msg不等于All read successfully


[2023-08-08 10:35:49,163] logger_util.py->write_log line:61 [INFO] -------------接口请求开始-----------
[2023-08-08 10:35:49,163] logger_util.py->write_log line:61 [INFO] 接口名称：modbus协议读取-保存寄存器有符号32位整型
[2023-08-08 10:35:49,163] logger_util.py->write_log line:61 [INFO] 接口方式：post
[2023-08-08 10:35:49,163] logger_util.py->write_log line:61 [INFO] 接口路径：http://127.0.0.1:6700/v1/cms/io/write
[2023-08-08 10:35:49,164] logger_util.py->write_log line:61 [INFO] 请求头：{'Content-Type': 'application/json'}
[2023-08-08 10:35:49,164] logger_util.py->write_log line:61 [INFO] 请求参数：{'tagDatas': ['MOD_DINT1']}
[2023-08-08 10:35:49,164] logger_util.py->write_log line:61 [INFO] 文件上传：None
[2023-08-08 10:35:49,165] logger_util.py->error_log line:65 [INFO] 断言失败:msg不等于All read successfully
[2023-08-08 10:35:49,165] logger_util.py->write_log line:61 [INFO] 接口请求失败！
[2023-08-08 10:35:49,165] logger_util.py->write_log line:61 [INFO] -------------接口请求结束-----------

[2023-08-08 10:35:49,166] logger_util.py->error_log line:65 [INFO] 断言异常：异常信息: Traceback (most recent call last):
  File "E:\Project_python\api_SIOT\common\requests_util.py", line 372, in validate_result
    error_log("断言失败:" + assert_key + "不等于" + str(assert_value))
  File "E:\Project_python\api_SIOT\common\logger_util.py", line 66, in error_log
    raise Exception(log_message)
Exception: 断言失败:msg不等于All read successfully

[2023-08-08 10:35:49,166] logger_util.py->error_log line:65 [INFO] 分析YAML文件异常：异常信息: Traceback (most recent call last):
  File "E:\Project_python\api_SIOT\common\requests_util.py", line 372, in validate_result
    error_log("断言失败:" + assert_key + "不等于" + str(assert_value))
  File "E:\Project_python\api_SIOT\common\logger_util.py", line 66, in error_log
    raise Exception(log_message)
Exception: 断言失败:msg不等于All read successfully

During handling of the above exception, another exception occurred:

Traceback (most recent call last):
  File "E:\Project_python\api_SIOT\common\requests_util.py", line 248, in analysis_yaml
    self.validate_result(yq_result, return_data, status_code)
  File "E:\Project_python\api_SIOT\common\requests_util.py", line 416, in validate_result
    error_log("断言异常：异常信息: %s" % str(traceback.format_exc()))
  File "E:\Project_python\api_SIOT\common\logger_util.py", line 66, in error_log
    raise Exception(log_message)
Exception: 断言异常：异常信息: Traceback (most recent call last):
  File "E:\Project_python\api_SIOT\common\requests_util.py", line 372, in validate_result
    error_log("断言失败:" + assert_key + "不等于" + str(assert_value))
  File "E:\Project_python\api_SIOT\common\logger_util.py", line 66, in error_log
    raise Exception(log_message)
Exception: 断言失败:msg不等于All read successfully


[2023-08-08 10:35:49,194] logger_util.py->write_log line:61 [INFO] -------------接口请求开始-----------
[2023-08-08 10:35:49,194] logger_util.py->write_log line:61 [INFO] 接口名称：modbus协议读取-保存寄存器无符号8位整型
[2023-08-08 10:35:49,194] logger_util.py->write_log line:61 [INFO] 接口方式：post
[2023-08-08 10:35:49,194] logger_util.py->write_log line:61 [INFO] 接口路径：http://127.0.0.1:6700/v1/cms/io/write
[2023-08-08 10:35:49,194] logger_util.py->write_log line:61 [INFO] 请求头：{'Content-Type': 'application/json'}
[2023-08-08 10:35:49,194] logger_util.py->write_log line:61 [INFO] 请求参数：{'tagDatas': ['MOD_USINT1']}
[2023-08-08 10:35:49,194] logger_util.py->write_log line:61 [INFO] 文件上传：None
[2023-08-08 10:35:49,196] logger_util.py->error_log line:65 [INFO] 断言失败:msg不等于All read successfully
[2023-08-08 10:35:49,196] logger_util.py->write_log line:61 [INFO] 接口请求失败！
[2023-08-08 10:35:49,196] logger_util.py->write_log line:61 [INFO] -------------接口请求结束-----------

[2023-08-08 10:35:49,196] logger_util.py->error_log line:65 [INFO] 断言异常：异常信息: Traceback (most recent call last):
  File "E:\Project_python\api_SIOT\common\requests_util.py", line 372, in validate_result
    error_log("断言失败:" + assert_key + "不等于" + str(assert_value))
  File "E:\Project_python\api_SIOT\common\logger_util.py", line 66, in error_log
    raise Exception(log_message)
Exception: 断言失败:msg不等于All read successfully

[2023-08-08 10:35:49,197] logger_util.py->error_log line:65 [INFO] 分析YAML文件异常：异常信息: Traceback (most recent call last):
  File "E:\Project_python\api_SIOT\common\requests_util.py", line 372, in validate_result
    error_log("断言失败:" + assert_key + "不等于" + str(assert_value))
  File "E:\Project_python\api_SIOT\common\logger_util.py", line 66, in error_log
    raise Exception(log_message)
Exception: 断言失败:msg不等于All read successfully

During handling of the above exception, another exception occurred:

Traceback (most recent call last):
  File "E:\Project_python\api_SIOT\common\requests_util.py", line 248, in analysis_yaml
    self.validate_result(yq_result, return_data, status_code)
  File "E:\Project_python\api_SIOT\common\requests_util.py", line 416, in validate_result
    error_log("断言异常：异常信息: %s" % str(traceback.format_exc()))
  File "E:\Project_python\api_SIOT\common\logger_util.py", line 66, in error_log
    raise Exception(log_message)
Exception: 断言异常：异常信息: Traceback (most recent call last):
  File "E:\Project_python\api_SIOT\common\requests_util.py", line 372, in validate_result
    error_log("断言失败:" + assert_key + "不等于" + str(assert_value))
  File "E:\Project_python\api_SIOT\common\logger_util.py", line 66, in error_log
    raise Exception(log_message)
Exception: 断言失败:msg不等于All read successfully


[2023-08-08 10:35:49,224] logger_util.py->write_log line:61 [INFO] -------------接口请求开始-----------
[2023-08-08 10:35:49,224] logger_util.py->write_log line:61 [INFO] 接口名称：modbus协议读取-保存寄存器无符号16位整型
[2023-08-08 10:35:49,224] logger_util.py->write_log line:61 [INFO] 接口方式：post
[2023-08-08 10:35:49,225] logger_util.py->write_log line:61 [INFO] 接口路径：http://127.0.0.1:6700/v1/cms/io/write
[2023-08-08 10:35:49,225] logger_util.py->write_log line:61 [INFO] 请求头：{'Content-Type': 'application/json'}
[2023-08-08 10:35:49,225] logger_util.py->write_log line:61 [INFO] 请求参数：{'tagDatas': ['MOD_UINT1']}
[2023-08-08 10:35:49,225] logger_util.py->write_log line:61 [INFO] 文件上传：None
[2023-08-08 10:35:49,227] logger_util.py->error_log line:65 [INFO] 断言失败:msg不等于All read successfully
[2023-08-08 10:35:49,227] logger_util.py->write_log line:61 [INFO] 接口请求失败！
[2023-08-08 10:35:49,227] logger_util.py->write_log line:61 [INFO] -------------接口请求结束-----------

[2023-08-08 10:35:49,227] logger_util.py->error_log line:65 [INFO] 断言异常：异常信息: Traceback (most recent call last):
  File "E:\Project_python\api_SIOT\common\requests_util.py", line 372, in validate_result
    error_log("断言失败:" + assert_key + "不等于" + str(assert_value))
  File "E:\Project_python\api_SIOT\common\logger_util.py", line 66, in error_log
    raise Exception(log_message)
Exception: 断言失败:msg不等于All read successfully

[2023-08-08 10:35:49,227] logger_util.py->error_log line:65 [INFO] 分析YAML文件异常：异常信息: Traceback (most recent call last):
  File "E:\Project_python\api_SIOT\common\requests_util.py", line 372, in validate_result
    error_log("断言失败:" + assert_key + "不等于" + str(assert_value))
  File "E:\Project_python\api_SIOT\common\logger_util.py", line 66, in error_log
    raise Exception(log_message)
Exception: 断言失败:msg不等于All read successfully

During handling of the above exception, another exception occurred:

Traceback (most recent call last):
  File "E:\Project_python\api_SIOT\common\requests_util.py", line 248, in analysis_yaml
    self.validate_result(yq_result, return_data, status_code)
  File "E:\Project_python\api_SIOT\common\requests_util.py", line 416, in validate_result
    error_log("断言异常：异常信息: %s" % str(traceback.format_exc()))
  File "E:\Project_python\api_SIOT\common\logger_util.py", line 66, in error_log
    raise Exception(log_message)
Exception: 断言异常：异常信息: Traceback (most recent call last):
  File "E:\Project_python\api_SIOT\common\requests_util.py", line 372, in validate_result
    error_log("断言失败:" + assert_key + "不等于" + str(assert_value))
  File "E:\Project_python\api_SIOT\common\logger_util.py", line 66, in error_log
    raise Exception(log_message)
Exception: 断言失败:msg不等于All read successfully


[2023-08-08 10:35:49,254] logger_util.py->write_log line:61 [INFO] -------------接口请求开始-----------
[2023-08-08 10:35:49,254] logger_util.py->write_log line:61 [INFO] 接口名称：modbus协议读取-保存寄存器无符号32位整型
[2023-08-08 10:35:49,254] logger_util.py->write_log line:61 [INFO] 接口方式：post
[2023-08-08 10:35:49,254] logger_util.py->write_log line:61 [INFO] 接口路径：http://127.0.0.1:6700/v1/cms/io/write
[2023-08-08 10:35:49,254] logger_util.py->write_log line:61 [INFO] 请求头：{'Content-Type': 'application/json'}
[2023-08-08 10:35:49,254] logger_util.py->write_log line:61 [INFO] 请求参数：{'tagDatas': ['MOD_UDINT1']}
[2023-08-08 10:35:49,254] logger_util.py->write_log line:61 [INFO] 文件上传：None
[2023-08-08 10:35:49,256] logger_util.py->error_log line:65 [INFO] 断言失败:msg不等于All read successfully
[2023-08-08 10:35:49,256] logger_util.py->write_log line:61 [INFO] 接口请求失败！
[2023-08-08 10:35:49,256] logger_util.py->write_log line:61 [INFO] -------------接口请求结束-----------

[2023-08-08 10:35:49,257] logger_util.py->error_log line:65 [INFO] 断言异常：异常信息: Traceback (most recent call last):
  File "E:\Project_python\api_SIOT\common\requests_util.py", line 372, in validate_result
    error_log("断言失败:" + assert_key + "不等于" + str(assert_value))
  File "E:\Project_python\api_SIOT\common\logger_util.py", line 66, in error_log
    raise Exception(log_message)
Exception: 断言失败:msg不等于All read successfully

[2023-08-08 10:35:49,257] logger_util.py->error_log line:65 [INFO] 分析YAML文件异常：异常信息: Traceback (most recent call last):
  File "E:\Project_python\api_SIOT\common\requests_util.py", line 372, in validate_result
    error_log("断言失败:" + assert_key + "不等于" + str(assert_value))
  File "E:\Project_python\api_SIOT\common\logger_util.py", line 66, in error_log
    raise Exception(log_message)
Exception: 断言失败:msg不等于All read successfully

During handling of the above exception, another exception occurred:

Traceback (most recent call last):
  File "E:\Project_python\api_SIOT\common\requests_util.py", line 248, in analysis_yaml
    self.validate_result(yq_result, return_data, status_code)
  File "E:\Project_python\api_SIOT\common\requests_util.py", line 416, in validate_result
    error_log("断言异常：异常信息: %s" % str(traceback.format_exc()))
  File "E:\Project_python\api_SIOT\common\logger_util.py", line 66, in error_log
    raise Exception(log_message)
Exception: 断言异常：异常信息: Traceback (most recent call last):
  File "E:\Project_python\api_SIOT\common\requests_util.py", line 372, in validate_result
    error_log("断言失败:" + assert_key + "不等于" + str(assert_value))
  File "E:\Project_python\api_SIOT\common\logger_util.py", line 66, in error_log
    raise Exception(log_message)
Exception: 断言失败:msg不等于All read successfully


[2023-08-08 10:35:49,283] logger_util.py->write_log line:61 [INFO] -------------接口请求开始-----------
[2023-08-08 10:35:49,283] logger_util.py->write_log line:61 [INFO] 接口名称：modbus协议读取-保存寄存器F32位浮点数IEEE754
[2023-08-08 10:35:49,283] logger_util.py->write_log line:61 [INFO] 接口方式：post
[2023-08-08 10:35:49,283] logger_util.py->write_log line:61 [INFO] 接口路径：http://127.0.0.1:6700/v1/cms/io/write
[2023-08-08 10:35:49,283] logger_util.py->write_log line:61 [INFO] 请求头：{'Content-Type': 'application/json'}
[2023-08-08 10:35:49,283] logger_util.py->write_log line:61 [INFO] 请求参数：{'tagDatas': ['MOD_REAL1']}
[2023-08-08 10:35:49,283] logger_util.py->write_log line:61 [INFO] 文件上传：None
[2023-08-08 10:35:49,285] logger_util.py->error_log line:65 [INFO] 断言失败:msg不等于All read successfully
[2023-08-08 10:35:49,285] logger_util.py->write_log line:61 [INFO] 接口请求失败！
[2023-08-08 10:35:49,285] logger_util.py->write_log line:61 [INFO] -------------接口请求结束-----------

[2023-08-08 10:35:49,285] logger_util.py->error_log line:65 [INFO] 断言异常：异常信息: Traceback (most recent call last):
  File "E:\Project_python\api_SIOT\common\requests_util.py", line 372, in validate_result
    error_log("断言失败:" + assert_key + "不等于" + str(assert_value))
  File "E:\Project_python\api_SIOT\common\logger_util.py", line 66, in error_log
    raise Exception(log_message)
Exception: 断言失败:msg不等于All read successfully

[2023-08-08 10:35:49,286] logger_util.py->error_log line:65 [INFO] 分析YAML文件异常：异常信息: Traceback (most recent call last):
  File "E:\Project_python\api_SIOT\common\requests_util.py", line 372, in validate_result
    error_log("断言失败:" + assert_key + "不等于" + str(assert_value))
  File "E:\Project_python\api_SIOT\common\logger_util.py", line 66, in error_log
    raise Exception(log_message)
Exception: 断言失败:msg不等于All read successfully

During handling of the above exception, another exception occurred:

Traceback (most recent call last):
  File "E:\Project_python\api_SIOT\common\requests_util.py", line 248, in analysis_yaml
    self.validate_result(yq_result, return_data, status_code)
  File "E:\Project_python\api_SIOT\common\requests_util.py", line 416, in validate_result
    error_log("断言异常：异常信息: %s" % str(traceback.format_exc()))
  File "E:\Project_python\api_SIOT\common\logger_util.py", line 66, in error_log
    raise Exception(log_message)
Exception: 断言异常：异常信息: Traceback (most recent call last):
  File "E:\Project_python\api_SIOT\common\requests_util.py", line 372, in validate_result
    error_log("断言失败:" + assert_key + "不等于" + str(assert_value))
  File "E:\Project_python\api_SIOT\common\logger_util.py", line 66, in error_log
    raise Exception(log_message)
Exception: 断言失败:msg不等于All read successfully


[2023-08-08 10:35:49,311] logger_util.py->write_log line:61 [INFO] -------------接口请求开始-----------
[2023-08-08 10:35:49,312] logger_util.py->write_log line:61 [INFO] 接口名称：modbus协议读取-保存寄存器二进制变量1
[2023-08-08 10:35:49,312] logger_util.py->write_log line:61 [INFO] 接口方式：post
[2023-08-08 10:35:49,312] logger_util.py->write_log line:61 [INFO] 接口路径：http://127.0.0.1:6700/v1/cms/io/write
[2023-08-08 10:35:49,312] logger_util.py->write_log line:61 [INFO] 请求头：{'Content-Type': 'application/json'}
[2023-08-08 10:35:49,312] logger_util.py->write_log line:61 [INFO] 请求参数：{'tagDatas': ['MOD_BOOL1']}
[2023-08-08 10:35:49,312] logger_util.py->write_log line:61 [INFO] 文件上传：None
[2023-08-08 10:35:49,314] logger_util.py->error_log line:65 [INFO] 断言失败:msg不等于All read successfully
[2023-08-08 10:35:49,314] logger_util.py->write_log line:61 [INFO] 接口请求失败！
[2023-08-08 10:35:49,314] logger_util.py->write_log line:61 [INFO] -------------接口请求结束-----------

[2023-08-08 10:35:49,314] logger_util.py->error_log line:65 [INFO] 断言异常：异常信息: Traceback (most recent call last):
  File "E:\Project_python\api_SIOT\common\requests_util.py", line 372, in validate_result
    error_log("断言失败:" + assert_key + "不等于" + str(assert_value))
  File "E:\Project_python\api_SIOT\common\logger_util.py", line 66, in error_log
    raise Exception(log_message)
Exception: 断言失败:msg不等于All read successfully

[2023-08-08 10:35:49,315] logger_util.py->error_log line:65 [INFO] 分析YAML文件异常：异常信息: Traceback (most recent call last):
  File "E:\Project_python\api_SIOT\common\requests_util.py", line 372, in validate_result
    error_log("断言失败:" + assert_key + "不等于" + str(assert_value))
  File "E:\Project_python\api_SIOT\common\logger_util.py", line 66, in error_log
    raise Exception(log_message)
Exception: 断言失败:msg不等于All read successfully

During handling of the above exception, another exception occurred:

Traceback (most recent call last):
  File "E:\Project_python\api_SIOT\common\requests_util.py", line 248, in analysis_yaml
    self.validate_result(yq_result, return_data, status_code)
  File "E:\Project_python\api_SIOT\common\requests_util.py", line 416, in validate_result
    error_log("断言异常：异常信息: %s" % str(traceback.format_exc()))
  File "E:\Project_python\api_SIOT\common\logger_util.py", line 66, in error_log
    raise Exception(log_message)
Exception: 断言异常：异常信息: Traceback (most recent call last):
  File "E:\Project_python\api_SIOT\common\requests_util.py", line 372, in validate_result
    error_log("断言失败:" + assert_key + "不等于" + str(assert_value))
  File "E:\Project_python\api_SIOT\common\logger_util.py", line 66, in error_log
    raise Exception(log_message)
Exception: 断言失败:msg不等于All read successfully


[2023-08-08 10:35:49,340] logger_util.py->write_log line:61 [INFO] -------------接口请求开始-----------
[2023-08-08 10:35:49,340] logger_util.py->write_log line:61 [INFO] 接口名称：modbus协议读取-保存寄存器二进制变量2
[2023-08-08 10:35:49,340] logger_util.py->write_log line:61 [INFO] 接口方式：post
[2023-08-08 10:35:49,340] logger_util.py->write_log line:61 [INFO] 接口路径：http://127.0.0.1:6700/v1/cms/io/write
[2023-08-08 10:35:49,340] logger_util.py->write_log line:61 [INFO] 请求头：{'Content-Type': 'application/json'}
[2023-08-08 10:35:49,341] logger_util.py->write_log line:61 [INFO] 请求参数：{'tagDatas': ['MOD_BOOL2']}
[2023-08-08 10:35:49,341] logger_util.py->write_log line:61 [INFO] 文件上传：None
[2023-08-08 10:35:49,343] logger_util.py->error_log line:65 [INFO] 断言失败:msg不等于All read successfully
[2023-08-08 10:35:49,343] logger_util.py->write_log line:61 [INFO] 接口请求失败！
[2023-08-08 10:35:49,343] logger_util.py->write_log line:61 [INFO] -------------接口请求结束-----------

[2023-08-08 10:35:49,343] logger_util.py->error_log line:65 [INFO] 断言异常：异常信息: Traceback (most recent call last):
  File "E:\Project_python\api_SIOT\common\requests_util.py", line 372, in validate_result
    error_log("断言失败:" + assert_key + "不等于" + str(assert_value))
  File "E:\Project_python\api_SIOT\common\logger_util.py", line 66, in error_log
    raise Exception(log_message)
Exception: 断言失败:msg不等于All read successfully

[2023-08-08 10:35:49,343] logger_util.py->error_log line:65 [INFO] 分析YAML文件异常：异常信息: Traceback (most recent call last):
  File "E:\Project_python\api_SIOT\common\requests_util.py", line 372, in validate_result
    error_log("断言失败:" + assert_key + "不等于" + str(assert_value))
  File "E:\Project_python\api_SIOT\common\logger_util.py", line 66, in error_log
    raise Exception(log_message)
Exception: 断言失败:msg不等于All read successfully

During handling of the above exception, another exception occurred:

Traceback (most recent call last):
  File "E:\Project_python\api_SIOT\common\requests_util.py", line 248, in analysis_yaml
    self.validate_result(yq_result, return_data, status_code)
  File "E:\Project_python\api_SIOT\common\requests_util.py", line 416, in validate_result
    error_log("断言异常：异常信息: %s" % str(traceback.format_exc()))
  File "E:\Project_python\api_SIOT\common\logger_util.py", line 66, in error_log
    raise Exception(log_message)
Exception: 断言异常：异常信息: Traceback (most recent call last):
  File "E:\Project_python\api_SIOT\common\requests_util.py", line 372, in validate_result
    error_log("断言失败:" + assert_key + "不等于" + str(assert_value))
  File "E:\Project_python\api_SIOT\common\logger_util.py", line 66, in error_log
    raise Exception(log_message)
Exception: 断言失败:msg不等于All read successfully


[2023-08-08 10:35:49,370] logger_util.py->write_log line:61 [INFO] -------------接口请求开始-----------
[2023-08-08 10:35:49,370] logger_util.py->write_log line:61 [INFO] 接口名称：modbus协议读取-保存寄存器字符串
[2023-08-08 10:35:49,370] logger_util.py->write_log line:61 [INFO] 接口方式：post
[2023-08-08 10:35:49,371] logger_util.py->write_log line:61 [INFO] 接口路径：http://127.0.0.1:6700/v1/cms/io/write
[2023-08-08 10:35:49,371] logger_util.py->write_log line:61 [INFO] 请求头：{'Content-Type': 'application/json'}
[2023-08-08 10:35:49,371] logger_util.py->write_log line:61 [INFO] 请求参数：{'tagDatas': ['MOD_STRING1']}
[2023-08-08 10:35:49,371] logger_util.py->write_log line:61 [INFO] 文件上传：None
[2023-08-08 10:35:49,373] logger_util.py->error_log line:65 [INFO] 断言失败:msg不等于All read successfully
[2023-08-08 10:35:49,373] logger_util.py->write_log line:61 [INFO] 接口请求失败！
[2023-08-08 10:35:49,373] logger_util.py->write_log line:61 [INFO] -------------接口请求结束-----------

[2023-08-08 10:35:49,373] logger_util.py->error_log line:65 [INFO] 断言异常：异常信息: Traceback (most recent call last):
  File "E:\Project_python\api_SIOT\common\requests_util.py", line 372, in validate_result
    error_log("断言失败:" + assert_key + "不等于" + str(assert_value))
  File "E:\Project_python\api_SIOT\common\logger_util.py", line 66, in error_log
    raise Exception(log_message)
Exception: 断言失败:msg不等于All read successfully

[2023-08-08 10:35:49,373] logger_util.py->error_log line:65 [INFO] 分析YAML文件异常：异常信息: Traceback (most recent call last):
  File "E:\Project_python\api_SIOT\common\requests_util.py", line 372, in validate_result
    error_log("断言失败:" + assert_key + "不等于" + str(assert_value))
  File "E:\Project_python\api_SIOT\common\logger_util.py", line 66, in error_log
    raise Exception(log_message)
Exception: 断言失败:msg不等于All read successfully

During handling of the above exception, another exception occurred:

Traceback (most recent call last):
  File "E:\Project_python\api_SIOT\common\requests_util.py", line 248, in analysis_yaml
    self.validate_result(yq_result, return_data, status_code)
  File "E:\Project_python\api_SIOT\common\requests_util.py", line 416, in validate_result
    error_log("断言异常：异常信息: %s" % str(traceback.format_exc()))
  File "E:\Project_python\api_SIOT\common\logger_util.py", line 66, in error_log
    raise Exception(log_message)
Exception: 断言异常：异常信息: Traceback (most recent call last):
  File "E:\Project_python\api_SIOT\common\requests_util.py", line 372, in validate_result
    error_log("断言失败:" + assert_key + "不等于" + str(assert_value))
  File "E:\Project_python\api_SIOT\common\logger_util.py", line 66, in error_log
    raise Exception(log_message)
Exception: 断言失败:msg不等于All read successfully


[2023-08-08 10:35:49,399] logger_util.py->write_log line:61 [INFO] -------------接口请求开始-----------
[2023-08-08 10:35:49,400] logger_util.py->write_log line:61 [INFO] 接口名称：modbus协议读取-二进制变量
[2023-08-08 10:35:49,400] logger_util.py->write_log line:61 [INFO] 接口方式：post
[2023-08-08 10:35:49,400] logger_util.py->write_log line:61 [INFO] 接口路径：http://127.0.0.1:6700/v1/cms/io/write
[2023-08-08 10:35:49,400] logger_util.py->write_log line:61 [INFO] 请求头：{'Content-Type': 'application/json'}
[2023-08-08 10:35:49,400] logger_util.py->write_log line:61 [INFO] 请求参数：{'tagDatas': ['MOD_Q0']}
[2023-08-08 10:35:49,400] logger_util.py->write_log line:61 [INFO] 文件上传：None
[2023-08-08 10:35:49,402] logger_util.py->error_log line:65 [INFO] 断言失败:msg不等于All read successfully
[2023-08-08 10:35:49,402] logger_util.py->write_log line:61 [INFO] 接口请求失败！
[2023-08-08 10:35:49,402] logger_util.py->write_log line:61 [INFO] -------------接口请求结束-----------

[2023-08-08 10:35:49,402] logger_util.py->error_log line:65 [INFO] 断言异常：异常信息: Traceback (most recent call last):
  File "E:\Project_python\api_SIOT\common\requests_util.py", line 372, in validate_result
    error_log("断言失败:" + assert_key + "不等于" + str(assert_value))
  File "E:\Project_python\api_SIOT\common\logger_util.py", line 66, in error_log
    raise Exception(log_message)
Exception: 断言失败:msg不等于All read successfully

[2023-08-08 10:35:49,403] logger_util.py->error_log line:65 [INFO] 分析YAML文件异常：异常信息: Traceback (most recent call last):
  File "E:\Project_python\api_SIOT\common\requests_util.py", line 372, in validate_result
    error_log("断言失败:" + assert_key + "不等于" + str(assert_value))
  File "E:\Project_python\api_SIOT\common\logger_util.py", line 66, in error_log
    raise Exception(log_message)
Exception: 断言失败:msg不等于All read successfully

During handling of the above exception, another exception occurred:

Traceback (most recent call last):
  File "E:\Project_python\api_SIOT\common\requests_util.py", line 248, in analysis_yaml
    self.validate_result(yq_result, return_data, status_code)
  File "E:\Project_python\api_SIOT\common\requests_util.py", line 416, in validate_result
    error_log("断言异常：异常信息: %s" % str(traceback.format_exc()))
  File "E:\Project_python\api_SIOT\common\logger_util.py", line 66, in error_log
    raise Exception(log_message)
Exception: 断言异常：异常信息: Traceback (most recent call last):
  File "E:\Project_python\api_SIOT\common\requests_util.py", line 372, in validate_result
    error_log("断言失败:" + assert_key + "不等于" + str(assert_value))
  File "E:\Project_python\api_SIOT\common\logger_util.py", line 66, in error_log
    raise Exception(log_message)
Exception: 断言失败:msg不等于All read successfully


[2023-08-08 10:35:49,432] logger_util.py->write_log line:61 [INFO] -------------接口请求开始-----------
[2023-08-08 10:35:49,432] logger_util.py->write_log line:61 [INFO] 接口名称：modbus协议读取-二进制变量
[2023-08-08 10:35:49,432] logger_util.py->write_log line:61 [INFO] 接口方式：post
[2023-08-08 10:35:49,432] logger_util.py->write_log line:61 [INFO] 接口路径：http://127.0.0.1:6700/v1/cms/io/write
[2023-08-08 10:35:49,432] logger_util.py->write_log line:61 [INFO] 请求头：{'Content-Type': 'application/json'}
[2023-08-08 10:35:49,432] logger_util.py->write_log line:61 [INFO] 请求参数：{'tagDatas': ['MOD_Q1']}
[2023-08-08 10:35:49,432] logger_util.py->write_log line:61 [INFO] 文件上传：None
[2023-08-08 10:35:49,434] logger_util.py->error_log line:65 [INFO] 断言失败:msg不等于All read successfully
[2023-08-08 10:35:49,434] logger_util.py->write_log line:61 [INFO] 接口请求失败！
[2023-08-08 10:35:49,434] logger_util.py->write_log line:61 [INFO] -------------接口请求结束-----------

[2023-08-08 10:35:49,434] logger_util.py->error_log line:65 [INFO] 断言异常：异常信息: Traceback (most recent call last):
  File "E:\Project_python\api_SIOT\common\requests_util.py", line 372, in validate_result
    error_log("断言失败:" + assert_key + "不等于" + str(assert_value))
  File "E:\Project_python\api_SIOT\common\logger_util.py", line 66, in error_log
    raise Exception(log_message)
Exception: 断言失败:msg不等于All read successfully

[2023-08-08 10:35:49,435] logger_util.py->error_log line:65 [INFO] 分析YAML文件异常：异常信息: Traceback (most recent call last):
  File "E:\Project_python\api_SIOT\common\requests_util.py", line 372, in validate_result
    error_log("断言失败:" + assert_key + "不等于" + str(assert_value))
  File "E:\Project_python\api_SIOT\common\logger_util.py", line 66, in error_log
    raise Exception(log_message)
Exception: 断言失败:msg不等于All read successfully

During handling of the above exception, another exception occurred:

Traceback (most recent call last):
  File "E:\Project_python\api_SIOT\common\requests_util.py", line 248, in analysis_yaml
    self.validate_result(yq_result, return_data, status_code)
  File "E:\Project_python\api_SIOT\common\requests_util.py", line 416, in validate_result
    error_log("断言异常：异常信息: %s" % str(traceback.format_exc()))
  File "E:\Project_python\api_SIOT\common\logger_util.py", line 66, in error_log
    raise Exception(log_message)
Exception: 断言异常：异常信息: Traceback (most recent call last):
  File "E:\Project_python\api_SIOT\common\requests_util.py", line 372, in validate_result
    error_log("断言失败:" + assert_key + "不等于" + str(assert_value))
  File "E:\Project_python\api_SIOT\common\logger_util.py", line 66, in error_log
    raise Exception(log_message)
Exception: 断言失败:msg不等于All read successfully


