[2023-06-02 16:34:44,184] logger_util.py->write_log line:61 [INFO] -------------接口请求开始-----------
[2023-06-02 16:34:44,184] logger_util.py->write_log line:61 [INFO] 接口名称：触发类型异常用例--变量触发
[2023-06-02 16:34:44,184] logger_util.py->write_log line:61 [INFO] 接口方式：put
[2023-06-02 16:34:44,184] logger_util.py->write_log line:61 [INFO] 接口路径：http://127.0.0.1:18000/api/v1/dataconfig/aggregatetable/39beb9fa-a60d-4379-8376-9b13863b9442/triggers
[2023-06-02 16:34:44,185] logger_util.py->write_log line:61 [INFO] 请求头：{'Content-Type': 'application/json;charset=UTF-8', 'X-Project': '83d42c5d5ad141bba528b7690b19996e'}
[2023-06-02 16:34:44,186] logger_util.py->write_log line:61 [INFO] 请求参数：{'realTime': False, 'triggers': [{'effectiveDateTime': '', 'frequencyValue': 1, 'frequencyUnit': 1, 'matchAll': False, 'condition': '', 'conditionDetail': 1, 'frequencyCheck': False, 'triggerType': 2}]}
[2023-06-02 16:34:44,186] logger_util.py->write_log line:61 [INFO] 文件上传：None
[2023-06-02 16:34:44,194] logger_util.py->error_log line:65 [INFO] 断言失败：返回结果不包含字符串：$csv{msg}
[2023-06-02 16:34:44,194] logger_util.py->write_log line:61 [INFO] 接口请求失败！
[2023-06-02 16:34:44,194] logger_util.py->write_log line:61 [INFO] -------------接口请求结束-----------

[2023-06-02 16:34:44,198] logger_util.py->error_log line:65 [INFO] 断言异常：异常信息: Traceback (most recent call last):
  File "E:\Project_python\2TestCMS2.0\common\requests_util.py", line 381, in validate_result
    error_log("断言失败：返回结果不包含字符串：" + value)
  File "E:\Project_python\2TestCMS2.0\common\logger_util.py", line 66, in error_log
    raise Exception(log_message)
Exception: 断言失败：返回结果不包含字符串：$csv{msg}

[2023-06-02 16:34:44,199] logger_util.py->error_log line:65 [INFO] 分析YAML文件异常：异常信息: Traceback (most recent call last):
  File "E:\Project_python\2TestCMS2.0\common\requests_util.py", line 381, in validate_result
    error_log("断言失败：返回结果不包含字符串：" + value)
  File "E:\Project_python\2TestCMS2.0\common\logger_util.py", line 66, in error_log
    raise Exception(log_message)
Exception: 断言失败：返回结果不包含字符串：$csv{msg}

During handling of the above exception, another exception occurred:

Traceback (most recent call last):
  File "E:\Project_python\2TestCMS2.0\common\requests_util.py", line 265, in analysis_yaml
    self.validate_result(yq_result, return_text, status_code)
  File "E:\Project_python\2TestCMS2.0\common\requests_util.py", line 416, in validate_result
    error_log("断言异常：异常信息: %s" % str(traceback.format_exc()))
  File "E:\Project_python\2TestCMS2.0\common\logger_util.py", line 66, in error_log
    raise Exception(log_message)
Exception: 断言异常：异常信息: Traceback (most recent call last):
  File "E:\Project_python\2TestCMS2.0\common\requests_util.py", line 381, in validate_result
    error_log("断言失败：返回结果不包含字符串：" + value)
  File "E:\Project_python\2TestCMS2.0\common\logger_util.py", line 66, in error_log
    raise Exception(log_message)
Exception: 断言失败：返回结果不包含字符串：$csv{msg}


[2023-06-02 16:34:44,308] logger_util.py->write_log line:61 [INFO] -------------接口请求开始-----------
[2023-06-02 16:34:44,308] logger_util.py->write_log line:61 [INFO] 接口名称：触发类型异常用例--定时触发
[2023-06-02 16:34:44,308] logger_util.py->write_log line:61 [INFO] 接口方式：put
[2023-06-02 16:34:44,308] logger_util.py->write_log line:61 [INFO] 接口路径：http://127.0.0.1:18000/api/v1/dataconfig/aggregatetable/39beb9fa-a60d-4379-8376-9b13863b9442/triggers
[2023-06-02 16:34:44,308] logger_util.py->write_log line:61 [INFO] 请求头：{'Content-Type': 'application/json;charset=UTF-8', 'X-Project': '83d42c5d5ad141bba528b7690b19996e'}
[2023-06-02 16:34:44,309] logger_util.py->write_log line:61 [INFO] 请求参数：{'realTime': False, 'triggers': [{'effectiveDateTime': '', 'frequencyValue': 1, 'frequencyUnit': 1, 'matchAll': False, 'condition': '', 'conditionDetail': 1, 'frequencyCheck': False, 'triggerType': 1}]}
[2023-06-02 16:34:44,309] logger_util.py->write_log line:61 [INFO] 文件上传：None
[2023-06-02 16:34:44,315] logger_util.py->error_log line:65 [INFO] 断言失败：返回结果不包含字符串：$csv{msg}
[2023-06-02 16:34:44,315] logger_util.py->write_log line:61 [INFO] 接口请求失败！
[2023-06-02 16:34:44,315] logger_util.py->write_log line:61 [INFO] -------------接口请求结束-----------

[2023-06-02 16:34:44,315] logger_util.py->error_log line:65 [INFO] 断言异常：异常信息: Traceback (most recent call last):
  File "E:\Project_python\2TestCMS2.0\common\requests_util.py", line 381, in validate_result
    error_log("断言失败：返回结果不包含字符串：" + value)
  File "E:\Project_python\2TestCMS2.0\common\logger_util.py", line 66, in error_log
    raise Exception(log_message)
Exception: 断言失败：返回结果不包含字符串：$csv{msg}

[2023-06-02 16:34:44,316] logger_util.py->error_log line:65 [INFO] 分析YAML文件异常：异常信息: Traceback (most recent call last):
  File "E:\Project_python\2TestCMS2.0\common\requests_util.py", line 381, in validate_result
    error_log("断言失败：返回结果不包含字符串：" + value)
  File "E:\Project_python\2TestCMS2.0\common\logger_util.py", line 66, in error_log
    raise Exception(log_message)
Exception: 断言失败：返回结果不包含字符串：$csv{msg}

During handling of the above exception, another exception occurred:

Traceback (most recent call last):
  File "E:\Project_python\2TestCMS2.0\common\requests_util.py", line 265, in analysis_yaml
    self.validate_result(yq_result, return_text, status_code)
  File "E:\Project_python\2TestCMS2.0\common\requests_util.py", line 416, in validate_result
    error_log("断言异常：异常信息: %s" % str(traceback.format_exc()))
  File "E:\Project_python\2TestCMS2.0\common\logger_util.py", line 66, in error_log
    raise Exception(log_message)
Exception: 断言异常：异常信息: Traceback (most recent call last):
  File "E:\Project_python\2TestCMS2.0\common\requests_util.py", line 381, in validate_result
    error_log("断言失败：返回结果不包含字符串：" + value)
  File "E:\Project_python\2TestCMS2.0\common\logger_util.py", line 66, in error_log
    raise Exception(log_message)
Exception: 断言失败：返回结果不包含字符串：$csv{msg}


[2023-06-02 16:34:44,343] logger_util.py->write_log line:61 [INFO] -------------接口请求开始-----------
[2023-06-02 16:34:44,343] logger_util.py->write_log line:61 [INFO] 接口名称：触发类型异常用例--定时触发
[2023-06-02 16:34:44,343] logger_util.py->write_log line:61 [INFO] 接口方式：put
[2023-06-02 16:34:44,343] logger_util.py->write_log line:61 [INFO] 接口路径：http://127.0.0.1:18000/api/v1/dataconfig/aggregatetable/39beb9fa-a60d-4379-8376-9b13863b9442/triggers
[2023-06-02 16:34:44,343] logger_util.py->write_log line:61 [INFO] 请求头：{'Content-Type': 'application/json;charset=UTF-8', 'X-Project': '83d42c5d5ad141bba528b7690b19996e'}
[2023-06-02 16:34:44,343] logger_util.py->write_log line:61 [INFO] 请求参数：{'realTime': False, 'triggers': [{'effectiveDateTime': '2023-05-22T06:15:31.000Z', 'frequencyValue': 1, 'frequencyUnit': 1, 'matchAll': True, 'condition': '', 'conditionDetail': 1, 'frequencyCheck': False, 'triggerType': 1}]}
[2023-06-02 16:34:44,343] logger_util.py->write_log line:61 [INFO] 文件上传：None
[2023-06-02 16:34:44,349] logger_util.py->error_log line:65 [INFO] 断言失败：返回结果不包含字符串：$csv{msg}
[2023-06-02 16:34:44,349] logger_util.py->write_log line:61 [INFO] 接口请求失败！
[2023-06-02 16:34:44,349] logger_util.py->write_log line:61 [INFO] -------------接口请求结束-----------

[2023-06-02 16:34:44,349] logger_util.py->error_log line:65 [INFO] 断言异常：异常信息: Traceback (most recent call last):
  File "E:\Project_python\2TestCMS2.0\common\requests_util.py", line 381, in validate_result
    error_log("断言失败：返回结果不包含字符串：" + value)
  File "E:\Project_python\2TestCMS2.0\common\logger_util.py", line 66, in error_log
    raise Exception(log_message)
Exception: 断言失败：返回结果不包含字符串：$csv{msg}

[2023-06-02 16:34:44,350] logger_util.py->error_log line:65 [INFO] 分析YAML文件异常：异常信息: Traceback (most recent call last):
  File "E:\Project_python\2TestCMS2.0\common\requests_util.py", line 381, in validate_result
    error_log("断言失败：返回结果不包含字符串：" + value)
  File "E:\Project_python\2TestCMS2.0\common\logger_util.py", line 66, in error_log
    raise Exception(log_message)
Exception: 断言失败：返回结果不包含字符串：$csv{msg}

During handling of the above exception, another exception occurred:

Traceback (most recent call last):
  File "E:\Project_python\2TestCMS2.0\common\requests_util.py", line 265, in analysis_yaml
    self.validate_result(yq_result, return_text, status_code)
  File "E:\Project_python\2TestCMS2.0\common\requests_util.py", line 416, in validate_result
    error_log("断言异常：异常信息: %s" % str(traceback.format_exc()))
  File "E:\Project_python\2TestCMS2.0\common\logger_util.py", line 66, in error_log
    raise Exception(log_message)
Exception: 断言异常：异常信息: Traceback (most recent call last):
  File "E:\Project_python\2TestCMS2.0\common\requests_util.py", line 381, in validate_result
    error_log("断言失败：返回结果不包含字符串：" + value)
  File "E:\Project_python\2TestCMS2.0\common\logger_util.py", line 66, in error_log
    raise Exception(log_message)
Exception: 断言失败：返回结果不包含字符串：$csv{msg}


[2023-06-02 16:34:44,375] logger_util.py->write_log line:61 [INFO] -------------接口请求开始-----------
[2023-06-02 16:34:44,375] logger_util.py->write_log line:61 [INFO] 接口名称：触发类型异常用例--字段触发
[2023-06-02 16:34:44,375] logger_util.py->write_log line:61 [INFO] 接口方式：put
[2023-06-02 16:34:44,375] logger_util.py->write_log line:61 [INFO] 接口路径：http://127.0.0.1:18000/api/v1/dataconfig/aggregatetable/39beb9fa-a60d-4379-8376-9b13863b9442/triggers
[2023-06-02 16:34:44,375] logger_util.py->write_log line:61 [INFO] 请求头：{'Content-Type': 'application/json;charset=UTF-8', 'X-Project': '83d42c5d5ad141bba528b7690b19996e'}
[2023-06-02 16:34:44,375] logger_util.py->write_log line:61 [INFO] 请求参数：{'realTime': False, 'triggers': [{'effectiveDateTime': '', 'frequencyValue': 1, 'frequencyUnit': 1, 'matchAll': True, 'condition': '', 'conditionDetail': 1, 'frequencyCheck': False, 'triggerType': 3}]}
[2023-06-02 16:34:44,375] logger_util.py->write_log line:61 [INFO] 文件上传：None
[2023-06-02 16:34:44,477] logger_util.py->error_log line:65 [INFO] 断言失败:status_code不等于400
[2023-06-02 16:34:44,477] logger_util.py->write_log line:61 [INFO] 接口请求失败！
[2023-06-02 16:34:44,477] logger_util.py->write_log line:61 [INFO] -------------接口请求结束-----------

[2023-06-02 16:34:44,477] logger_util.py->error_log line:65 [INFO] 断言异常：异常信息: Traceback (most recent call last):
  File "E:\Project_python\2TestCMS2.0\common\requests_util.py", line 366, in validate_result
    error_log("断言失败:"+assert_key+"不等于"+str(assert_value))
  File "E:\Project_python\2TestCMS2.0\common\logger_util.py", line 66, in error_log
    raise Exception(log_message)
Exception: 断言失败:status_code不等于400

[2023-06-02 16:34:44,478] logger_util.py->error_log line:65 [INFO] 分析YAML文件异常：异常信息: Traceback (most recent call last):
  File "E:\Project_python\2TestCMS2.0\common\requests_util.py", line 366, in validate_result
    error_log("断言失败:"+assert_key+"不等于"+str(assert_value))
  File "E:\Project_python\2TestCMS2.0\common\logger_util.py", line 66, in error_log
    raise Exception(log_message)
Exception: 断言失败:status_code不等于400

During handling of the above exception, another exception occurred:

Traceback (most recent call last):
  File "E:\Project_python\2TestCMS2.0\common\requests_util.py", line 265, in analysis_yaml
    self.validate_result(yq_result, return_text, status_code)
  File "E:\Project_python\2TestCMS2.0\common\requests_util.py", line 416, in validate_result
    error_log("断言异常：异常信息: %s" % str(traceback.format_exc()))
  File "E:\Project_python\2TestCMS2.0\common\logger_util.py", line 66, in error_log
    raise Exception(log_message)
Exception: 断言异常：异常信息: Traceback (most recent call last):
  File "E:\Project_python\2TestCMS2.0\common\requests_util.py", line 366, in validate_result
    error_log("断言失败:"+assert_key+"不等于"+str(assert_value))
  File "E:\Project_python\2TestCMS2.0\common\logger_util.py", line 66, in error_log
    raise Exception(log_message)
Exception: 断言失败:status_code不等于400


