[2023-05-18 16:04:24,855] logger_util.py->error_log line:65 [INFO] 发送请求异常：异常信息: Traceback (most recent call last):
  File "E:\Project_python\2TestCMS2.0\common\requests_util.py", line 276, in send_request
    self.base_url = self.replace_load(self.base_url) + self.replace_load(url)
  File "E:\Project_python\2TestCMS2.0\common\requests_util.py", line 41, in replace_load
    new_value = getattr(DubugTalk(), func_name)(*args_value.split(','))
  File "E:\Project_python\2TestCMS2.0\debug_talk.py", line 20, in get_base_url
    return  read_config_file('base',node_name)
  File "E:\Project_python\2TestCMS2.0\common\yaml_util.py", line 13, in read_config_file
    return value[one_node][two_node]
KeyError: 'cms_url'

[2023-05-18 16:04:24,871] logger_util.py->error_log line:65 [INFO] 分析YAML文件异常：异常信息: Traceback (most recent call last):
  File "E:\Project_python\2TestCMS2.0\common\requests_util.py", line 276, in send_request
    self.base_url = self.replace_load(self.base_url) + self.replace_load(url)
  File "E:\Project_python\2TestCMS2.0\common\requests_util.py", line 41, in replace_load
    new_value = getattr(DubugTalk(), func_name)(*args_value.split(','))
  File "E:\Project_python\2TestCMS2.0\debug_talk.py", line 20, in get_base_url
    return  read_config_file('base',node_name)
  File "E:\Project_python\2TestCMS2.0\common\yaml_util.py", line 13, in read_config_file
    return value[one_node][two_node]
KeyError: 'cms_url'

During handling of the above exception, another exception occurred:

Traceback (most recent call last):
  File "E:\Project_python\2TestCMS2.0\common\requests_util.py", line 176, in analysis_yaml
    res = self.send_request(name =name,method=method,
  File "E:\Project_python\2TestCMS2.0\common\requests_util.py", line 304, in send_request
    error_log("发送请求异常：异常信息: %s" % str(traceback.format_exc()))
  File "E:\Project_python\2TestCMS2.0\common\logger_util.py", line 66, in error_log
    raise Exception(log_message)
Exception: 发送请求异常：异常信息: Traceback (most recent call last):
  File "E:\Project_python\2TestCMS2.0\common\requests_util.py", line 276, in send_request
    self.base_url = self.replace_load(self.base_url) + self.replace_load(url)
  File "E:\Project_python\2TestCMS2.0\common\requests_util.py", line 41, in replace_load
    new_value = getattr(DubugTalk(), func_name)(*args_value.split(','))
  File "E:\Project_python\2TestCMS2.0\debug_talk.py", line 20, in get_base_url
    return  read_config_file('base',node_name)
  File "E:\Project_python\2TestCMS2.0\common\yaml_util.py", line 13, in read_config_file
    return value[one_node][two_node]
KeyError: 'cms_url'


[2023-05-18 16:04:25,068] logger_util.py->error_log line:65 [INFO] 发送请求异常：异常信息: Traceback (most recent call last):
  File "E:\Project_python\2TestCMS2.0\common\requests_util.py", line 276, in send_request
    self.base_url = self.replace_load(self.base_url) + self.replace_load(url)
  File "E:\Project_python\2TestCMS2.0\common\requests_util.py", line 41, in replace_load
    new_value = getattr(DubugTalk(), func_name)(*args_value.split(','))
  File "E:\Project_python\2TestCMS2.0\debug_talk.py", line 20, in get_base_url
    return  read_config_file('base',node_name)
  File "E:\Project_python\2TestCMS2.0\common\yaml_util.py", line 13, in read_config_file
    return value[one_node][two_node]
KeyError: 'cms_url'

[2023-05-18 16:04:25,068] logger_util.py->error_log line:65 [INFO] 分析YAML文件异常：异常信息: Traceback (most recent call last):
  File "E:\Project_python\2TestCMS2.0\common\requests_util.py", line 276, in send_request
    self.base_url = self.replace_load(self.base_url) + self.replace_load(url)
  File "E:\Project_python\2TestCMS2.0\common\requests_util.py", line 41, in replace_load
    new_value = getattr(DubugTalk(), func_name)(*args_value.split(','))
  File "E:\Project_python\2TestCMS2.0\debug_talk.py", line 20, in get_base_url
    return  read_config_file('base',node_name)
  File "E:\Project_python\2TestCMS2.0\common\yaml_util.py", line 13, in read_config_file
    return value[one_node][two_node]
KeyError: 'cms_url'

During handling of the above exception, another exception occurred:

Traceback (most recent call last):
  File "E:\Project_python\2TestCMS2.0\common\requests_util.py", line 176, in analysis_yaml
    res = self.send_request(name =name,method=method,
  File "E:\Project_python\2TestCMS2.0\common\requests_util.py", line 304, in send_request
    error_log("发送请求异常：异常信息: %s" % str(traceback.format_exc()))
  File "E:\Project_python\2TestCMS2.0\common\logger_util.py", line 66, in error_log
    raise Exception(log_message)
Exception: 发送请求异常：异常信息: Traceback (most recent call last):
  File "E:\Project_python\2TestCMS2.0\common\requests_util.py", line 276, in send_request
    self.base_url = self.replace_load(self.base_url) + self.replace_load(url)
  File "E:\Project_python\2TestCMS2.0\common\requests_util.py", line 41, in replace_load
    new_value = getattr(DubugTalk(), func_name)(*args_value.split(','))
  File "E:\Project_python\2TestCMS2.0\debug_talk.py", line 20, in get_base_url
    return  read_config_file('base',node_name)
  File "E:\Project_python\2TestCMS2.0\common\yaml_util.py", line 13, in read_config_file
    return value[one_node][two_node]
KeyError: 'cms_url'


[2023-05-18 16:04:25,096] logger_util.py->error_log line:65 [INFO] 发送请求异常：异常信息: Traceback (most recent call last):
  File "E:\Project_python\2TestCMS2.0\common\requests_util.py", line 276, in send_request
    self.base_url = self.replace_load(self.base_url) + self.replace_load(url)
  File "E:\Project_python\2TestCMS2.0\common\requests_util.py", line 41, in replace_load
    new_value = getattr(DubugTalk(), func_name)(*args_value.split(','))
  File "E:\Project_python\2TestCMS2.0\debug_talk.py", line 20, in get_base_url
    return  read_config_file('base',node_name)
  File "E:\Project_python\2TestCMS2.0\common\yaml_util.py", line 13, in read_config_file
    return value[one_node][two_node]
KeyError: 'cms_url'

[2023-05-18 16:04:25,097] logger_util.py->error_log line:65 [INFO] 分析YAML文件异常：异常信息: Traceback (most recent call last):
  File "E:\Project_python\2TestCMS2.0\common\requests_util.py", line 276, in send_request
    self.base_url = self.replace_load(self.base_url) + self.replace_load(url)
  File "E:\Project_python\2TestCMS2.0\common\requests_util.py", line 41, in replace_load
    new_value = getattr(DubugTalk(), func_name)(*args_value.split(','))
  File "E:\Project_python\2TestCMS2.0\debug_talk.py", line 20, in get_base_url
    return  read_config_file('base',node_name)
  File "E:\Project_python\2TestCMS2.0\common\yaml_util.py", line 13, in read_config_file
    return value[one_node][two_node]
KeyError: 'cms_url'

During handling of the above exception, another exception occurred:

Traceback (most recent call last):
  File "E:\Project_python\2TestCMS2.0\common\requests_util.py", line 176, in analysis_yaml
    res = self.send_request(name =name,method=method,
  File "E:\Project_python\2TestCMS2.0\common\requests_util.py", line 304, in send_request
    error_log("发送请求异常：异常信息: %s" % str(traceback.format_exc()))
  File "E:\Project_python\2TestCMS2.0\common\logger_util.py", line 66, in error_log
    raise Exception(log_message)
Exception: 发送请求异常：异常信息: Traceback (most recent call last):
  File "E:\Project_python\2TestCMS2.0\common\requests_util.py", line 276, in send_request
    self.base_url = self.replace_load(self.base_url) + self.replace_load(url)
  File "E:\Project_python\2TestCMS2.0\common\requests_util.py", line 41, in replace_load
    new_value = getattr(DubugTalk(), func_name)(*args_value.split(','))
  File "E:\Project_python\2TestCMS2.0\debug_talk.py", line 20, in get_base_url
    return  read_config_file('base',node_name)
  File "E:\Project_python\2TestCMS2.0\common\yaml_util.py", line 13, in read_config_file
    return value[one_node][two_node]
KeyError: 'cms_url'


[2023-05-18 16:04:25,126] logger_util.py->error_log line:65 [INFO] 发送请求异常：异常信息: Traceback (most recent call last):
  File "E:\Project_python\2TestCMS2.0\common\requests_util.py", line 276, in send_request
    self.base_url = self.replace_load(self.base_url) + self.replace_load(url)
  File "E:\Project_python\2TestCMS2.0\common\requests_util.py", line 41, in replace_load
    new_value = getattr(DubugTalk(), func_name)(*args_value.split(','))
  File "E:\Project_python\2TestCMS2.0\debug_talk.py", line 20, in get_base_url
    return  read_config_file('base',node_name)
  File "E:\Project_python\2TestCMS2.0\common\yaml_util.py", line 13, in read_config_file
    return value[one_node][two_node]
KeyError: 'cms_url'

[2023-05-18 16:04:25,126] logger_util.py->error_log line:65 [INFO] 分析YAML文件异常：异常信息: Traceback (most recent call last):
  File "E:\Project_python\2TestCMS2.0\common\requests_util.py", line 276, in send_request
    self.base_url = self.replace_load(self.base_url) + self.replace_load(url)
  File "E:\Project_python\2TestCMS2.0\common\requests_util.py", line 41, in replace_load
    new_value = getattr(DubugTalk(), func_name)(*args_value.split(','))
  File "E:\Project_python\2TestCMS2.0\debug_talk.py", line 20, in get_base_url
    return  read_config_file('base',node_name)
  File "E:\Project_python\2TestCMS2.0\common\yaml_util.py", line 13, in read_config_file
    return value[one_node][two_node]
KeyError: 'cms_url'

During handling of the above exception, another exception occurred:

Traceback (most recent call last):
  File "E:\Project_python\2TestCMS2.0\common\requests_util.py", line 176, in analysis_yaml
    res = self.send_request(name =name,method=method,
  File "E:\Project_python\2TestCMS2.0\common\requests_util.py", line 304, in send_request
    error_log("发送请求异常：异常信息: %s" % str(traceback.format_exc()))
  File "E:\Project_python\2TestCMS2.0\common\logger_util.py", line 66, in error_log
    raise Exception(log_message)
Exception: 发送请求异常：异常信息: Traceback (most recent call last):
  File "E:\Project_python\2TestCMS2.0\common\requests_util.py", line 276, in send_request
    self.base_url = self.replace_load(self.base_url) + self.replace_load(url)
  File "E:\Project_python\2TestCMS2.0\common\requests_util.py", line 41, in replace_load
    new_value = getattr(DubugTalk(), func_name)(*args_value.split(','))
  File "E:\Project_python\2TestCMS2.0\debug_talk.py", line 20, in get_base_url
    return  read_config_file('base',node_name)
  File "E:\Project_python\2TestCMS2.0\common\yaml_util.py", line 13, in read_config_file
    return value[one_node][two_node]
KeyError: 'cms_url'


[2023-05-18 16:04:25,155] logger_util.py->error_log line:65 [INFO] 发送请求异常：异常信息: Traceback (most recent call last):
  File "E:\Project_python\2TestCMS2.0\common\requests_util.py", line 276, in send_request
    self.base_url = self.replace_load(self.base_url) + self.replace_load(url)
  File "E:\Project_python\2TestCMS2.0\common\requests_util.py", line 41, in replace_load
    new_value = getattr(DubugTalk(), func_name)(*args_value.split(','))
  File "E:\Project_python\2TestCMS2.0\debug_talk.py", line 20, in get_base_url
    return  read_config_file('base',node_name)
  File "E:\Project_python\2TestCMS2.0\common\yaml_util.py", line 13, in read_config_file
    return value[one_node][two_node]
KeyError: 'cms_url'

[2023-05-18 16:04:25,156] logger_util.py->error_log line:65 [INFO] 分析YAML文件异常：异常信息: Traceback (most recent call last):
  File "E:\Project_python\2TestCMS2.0\common\requests_util.py", line 276, in send_request
    self.base_url = self.replace_load(self.base_url) + self.replace_load(url)
  File "E:\Project_python\2TestCMS2.0\common\requests_util.py", line 41, in replace_load
    new_value = getattr(DubugTalk(), func_name)(*args_value.split(','))
  File "E:\Project_python\2TestCMS2.0\debug_talk.py", line 20, in get_base_url
    return  read_config_file('base',node_name)
  File "E:\Project_python\2TestCMS2.0\common\yaml_util.py", line 13, in read_config_file
    return value[one_node][two_node]
KeyError: 'cms_url'

During handling of the above exception, another exception occurred:

Traceback (most recent call last):
  File "E:\Project_python\2TestCMS2.0\common\requests_util.py", line 176, in analysis_yaml
    res = self.send_request(name =name,method=method,
  File "E:\Project_python\2TestCMS2.0\common\requests_util.py", line 304, in send_request
    error_log("发送请求异常：异常信息: %s" % str(traceback.format_exc()))
  File "E:\Project_python\2TestCMS2.0\common\logger_util.py", line 66, in error_log
    raise Exception(log_message)
Exception: 发送请求异常：异常信息: Traceback (most recent call last):
  File "E:\Project_python\2TestCMS2.0\common\requests_util.py", line 276, in send_request
    self.base_url = self.replace_load(self.base_url) + self.replace_load(url)
  File "E:\Project_python\2TestCMS2.0\common\requests_util.py", line 41, in replace_load
    new_value = getattr(DubugTalk(), func_name)(*args_value.split(','))
  File "E:\Project_python\2TestCMS2.0\debug_talk.py", line 20, in get_base_url
    return  read_config_file('base',node_name)
  File "E:\Project_python\2TestCMS2.0\common\yaml_util.py", line 13, in read_config_file
    return value[one_node][two_node]
KeyError: 'cms_url'


[2023-05-18 16:04:25,184] logger_util.py->error_log line:65 [INFO] 发送请求异常：异常信息: Traceback (most recent call last):
  File "E:\Project_python\2TestCMS2.0\common\requests_util.py", line 276, in send_request
    self.base_url = self.replace_load(self.base_url) + self.replace_load(url)
  File "E:\Project_python\2TestCMS2.0\common\requests_util.py", line 41, in replace_load
    new_value = getattr(DubugTalk(), func_name)(*args_value.split(','))
  File "E:\Project_python\2TestCMS2.0\debug_talk.py", line 20, in get_base_url
    return  read_config_file('base',node_name)
  File "E:\Project_python\2TestCMS2.0\common\yaml_util.py", line 13, in read_config_file
    return value[one_node][two_node]
KeyError: 'cms_url'

[2023-05-18 16:04:25,184] logger_util.py->error_log line:65 [INFO] 分析YAML文件异常：异常信息: Traceback (most recent call last):
  File "E:\Project_python\2TestCMS2.0\common\requests_util.py", line 276, in send_request
    self.base_url = self.replace_load(self.base_url) + self.replace_load(url)
  File "E:\Project_python\2TestCMS2.0\common\requests_util.py", line 41, in replace_load
    new_value = getattr(DubugTalk(), func_name)(*args_value.split(','))
  File "E:\Project_python\2TestCMS2.0\debug_talk.py", line 20, in get_base_url
    return  read_config_file('base',node_name)
  File "E:\Project_python\2TestCMS2.0\common\yaml_util.py", line 13, in read_config_file
    return value[one_node][two_node]
KeyError: 'cms_url'

During handling of the above exception, another exception occurred:

Traceback (most recent call last):
  File "E:\Project_python\2TestCMS2.0\common\requests_util.py", line 176, in analysis_yaml
    res = self.send_request(name =name,method=method,
  File "E:\Project_python\2TestCMS2.0\common\requests_util.py", line 304, in send_request
    error_log("发送请求异常：异常信息: %s" % str(traceback.format_exc()))
  File "E:\Project_python\2TestCMS2.0\common\logger_util.py", line 66, in error_log
    raise Exception(log_message)
Exception: 发送请求异常：异常信息: Traceback (most recent call last):
  File "E:\Project_python\2TestCMS2.0\common\requests_util.py", line 276, in send_request
    self.base_url = self.replace_load(self.base_url) + self.replace_load(url)
  File "E:\Project_python\2TestCMS2.0\common\requests_util.py", line 41, in replace_load
    new_value = getattr(DubugTalk(), func_name)(*args_value.split(','))
  File "E:\Project_python\2TestCMS2.0\debug_talk.py", line 20, in get_base_url
    return  read_config_file('base',node_name)
  File "E:\Project_python\2TestCMS2.0\common\yaml_util.py", line 13, in read_config_file
    return value[one_node][two_node]
KeyError: 'cms_url'


[2023-05-18 16:04:25,212] logger_util.py->error_log line:65 [INFO] 发送请求异常：异常信息: Traceback (most recent call last):
  File "E:\Project_python\2TestCMS2.0\common\requests_util.py", line 276, in send_request
    self.base_url = self.replace_load(self.base_url) + self.replace_load(url)
  File "E:\Project_python\2TestCMS2.0\common\requests_util.py", line 41, in replace_load
    new_value = getattr(DubugTalk(), func_name)(*args_value.split(','))
  File "E:\Project_python\2TestCMS2.0\debug_talk.py", line 20, in get_base_url
    return  read_config_file('base',node_name)
  File "E:\Project_python\2TestCMS2.0\common\yaml_util.py", line 13, in read_config_file
    return value[one_node][two_node]
KeyError: 'cms_url'

[2023-05-18 16:04:25,213] logger_util.py->error_log line:65 [INFO] 分析YAML文件异常：异常信息: Traceback (most recent call last):
  File "E:\Project_python\2TestCMS2.0\common\requests_util.py", line 276, in send_request
    self.base_url = self.replace_load(self.base_url) + self.replace_load(url)
  File "E:\Project_python\2TestCMS2.0\common\requests_util.py", line 41, in replace_load
    new_value = getattr(DubugTalk(), func_name)(*args_value.split(','))
  File "E:\Project_python\2TestCMS2.0\debug_talk.py", line 20, in get_base_url
    return  read_config_file('base',node_name)
  File "E:\Project_python\2TestCMS2.0\common\yaml_util.py", line 13, in read_config_file
    return value[one_node][two_node]
KeyError: 'cms_url'

During handling of the above exception, another exception occurred:

Traceback (most recent call last):
  File "E:\Project_python\2TestCMS2.0\common\requests_util.py", line 176, in analysis_yaml
    res = self.send_request(name =name,method=method,
  File "E:\Project_python\2TestCMS2.0\common\requests_util.py", line 304, in send_request
    error_log("发送请求异常：异常信息: %s" % str(traceback.format_exc()))
  File "E:\Project_python\2TestCMS2.0\common\logger_util.py", line 66, in error_log
    raise Exception(log_message)
Exception: 发送请求异常：异常信息: Traceback (most recent call last):
  File "E:\Project_python\2TestCMS2.0\common\requests_util.py", line 276, in send_request
    self.base_url = self.replace_load(self.base_url) + self.replace_load(url)
  File "E:\Project_python\2TestCMS2.0\common\requests_util.py", line 41, in replace_load
    new_value = getattr(DubugTalk(), func_name)(*args_value.split(','))
  File "E:\Project_python\2TestCMS2.0\debug_talk.py", line 20, in get_base_url
    return  read_config_file('base',node_name)
  File "E:\Project_python\2TestCMS2.0\common\yaml_util.py", line 13, in read_config_file
    return value[one_node][two_node]
KeyError: 'cms_url'


[2023-05-18 16:04:25,240] logger_util.py->error_log line:65 [INFO] 发送请求异常：异常信息: Traceback (most recent call last):
  File "E:\Project_python\2TestCMS2.0\common\requests_util.py", line 276, in send_request
    self.base_url = self.replace_load(self.base_url) + self.replace_load(url)
  File "E:\Project_python\2TestCMS2.0\common\requests_util.py", line 41, in replace_load
    new_value = getattr(DubugTalk(), func_name)(*args_value.split(','))
  File "E:\Project_python\2TestCMS2.0\debug_talk.py", line 20, in get_base_url
    return  read_config_file('base',node_name)
  File "E:\Project_python\2TestCMS2.0\common\yaml_util.py", line 13, in read_config_file
    return value[one_node][two_node]
KeyError: 'cms_url'

[2023-05-18 16:04:25,240] logger_util.py->error_log line:65 [INFO] 分析YAML文件异常：异常信息: Traceback (most recent call last):
  File "E:\Project_python\2TestCMS2.0\common\requests_util.py", line 276, in send_request
    self.base_url = self.replace_load(self.base_url) + self.replace_load(url)
  File "E:\Project_python\2TestCMS2.0\common\requests_util.py", line 41, in replace_load
    new_value = getattr(DubugTalk(), func_name)(*args_value.split(','))
  File "E:\Project_python\2TestCMS2.0\debug_talk.py", line 20, in get_base_url
    return  read_config_file('base',node_name)
  File "E:\Project_python\2TestCMS2.0\common\yaml_util.py", line 13, in read_config_file
    return value[one_node][two_node]
KeyError: 'cms_url'

During handling of the above exception, another exception occurred:

Traceback (most recent call last):
  File "E:\Project_python\2TestCMS2.0\common\requests_util.py", line 176, in analysis_yaml
    res = self.send_request(name =name,method=method,
  File "E:\Project_python\2TestCMS2.0\common\requests_util.py", line 304, in send_request
    error_log("发送请求异常：异常信息: %s" % str(traceback.format_exc()))
  File "E:\Project_python\2TestCMS2.0\common\logger_util.py", line 66, in error_log
    raise Exception(log_message)
Exception: 发送请求异常：异常信息: Traceback (most recent call last):
  File "E:\Project_python\2TestCMS2.0\common\requests_util.py", line 276, in send_request
    self.base_url = self.replace_load(self.base_url) + self.replace_load(url)
  File "E:\Project_python\2TestCMS2.0\common\requests_util.py", line 41, in replace_load
    new_value = getattr(DubugTalk(), func_name)(*args_value.split(','))
  File "E:\Project_python\2TestCMS2.0\debug_talk.py", line 20, in get_base_url
    return  read_config_file('base',node_name)
  File "E:\Project_python\2TestCMS2.0\common\yaml_util.py", line 13, in read_config_file
    return value[one_node][two_node]
KeyError: 'cms_url'


[2023-05-18 16:04:25,268] logger_util.py->error_log line:65 [INFO] 发送请求异常：异常信息: Traceback (most recent call last):
  File "E:\Project_python\2TestCMS2.0\common\requests_util.py", line 276, in send_request
    self.base_url = self.replace_load(self.base_url) + self.replace_load(url)
  File "E:\Project_python\2TestCMS2.0\common\requests_util.py", line 41, in replace_load
    new_value = getattr(DubugTalk(), func_name)(*args_value.split(','))
  File "E:\Project_python\2TestCMS2.0\debug_talk.py", line 20, in get_base_url
    return  read_config_file('base',node_name)
  File "E:\Project_python\2TestCMS2.0\common\yaml_util.py", line 13, in read_config_file
    return value[one_node][two_node]
KeyError: 'cms_url'

[2023-05-18 16:04:25,269] logger_util.py->error_log line:65 [INFO] 分析YAML文件异常：异常信息: Traceback (most recent call last):
  File "E:\Project_python\2TestCMS2.0\common\requests_util.py", line 276, in send_request
    self.base_url = self.replace_load(self.base_url) + self.replace_load(url)
  File "E:\Project_python\2TestCMS2.0\common\requests_util.py", line 41, in replace_load
    new_value = getattr(DubugTalk(), func_name)(*args_value.split(','))
  File "E:\Project_python\2TestCMS2.0\debug_talk.py", line 20, in get_base_url
    return  read_config_file('base',node_name)
  File "E:\Project_python\2TestCMS2.0\common\yaml_util.py", line 13, in read_config_file
    return value[one_node][two_node]
KeyError: 'cms_url'

During handling of the above exception, another exception occurred:

Traceback (most recent call last):
  File "E:\Project_python\2TestCMS2.0\common\requests_util.py", line 176, in analysis_yaml
    res = self.send_request(name =name,method=method,
  File "E:\Project_python\2TestCMS2.0\common\requests_util.py", line 304, in send_request
    error_log("发送请求异常：异常信息: %s" % str(traceback.format_exc()))
  File "E:\Project_python\2TestCMS2.0\common\logger_util.py", line 66, in error_log
    raise Exception(log_message)
Exception: 发送请求异常：异常信息: Traceback (most recent call last):
  File "E:\Project_python\2TestCMS2.0\common\requests_util.py", line 276, in send_request
    self.base_url = self.replace_load(self.base_url) + self.replace_load(url)
  File "E:\Project_python\2TestCMS2.0\common\requests_util.py", line 41, in replace_load
    new_value = getattr(DubugTalk(), func_name)(*args_value.split(','))
  File "E:\Project_python\2TestCMS2.0\debug_talk.py", line 20, in get_base_url
    return  read_config_file('base',node_name)
  File "E:\Project_python\2TestCMS2.0\common\yaml_util.py", line 13, in read_config_file
    return value[one_node][two_node]
KeyError: 'cms_url'


[2023-05-18 16:04:25,302] logger_util.py->error_log line:65 [INFO] 发送请求异常：异常信息: Traceback (most recent call last):
  File "E:\Project_python\2TestCMS2.0\common\requests_util.py", line 276, in send_request
    self.base_url = self.replace_load(self.base_url) + self.replace_load(url)
  File "E:\Project_python\2TestCMS2.0\common\requests_util.py", line 41, in replace_load
    new_value = getattr(DubugTalk(), func_name)(*args_value.split(','))
  File "E:\Project_python\2TestCMS2.0\debug_talk.py", line 20, in get_base_url
    return  read_config_file('base',node_name)
  File "E:\Project_python\2TestCMS2.0\common\yaml_util.py", line 13, in read_config_file
    return value[one_node][two_node]
KeyError: 'cms_url'

[2023-05-18 16:04:25,302] logger_util.py->error_log line:65 [INFO] 分析YAML文件异常：异常信息: Traceback (most recent call last):
  File "E:\Project_python\2TestCMS2.0\common\requests_util.py", line 276, in send_request
    self.base_url = self.replace_load(self.base_url) + self.replace_load(url)
  File "E:\Project_python\2TestCMS2.0\common\requests_util.py", line 41, in replace_load
    new_value = getattr(DubugTalk(), func_name)(*args_value.split(','))
  File "E:\Project_python\2TestCMS2.0\debug_talk.py", line 20, in get_base_url
    return  read_config_file('base',node_name)
  File "E:\Project_python\2TestCMS2.0\common\yaml_util.py", line 13, in read_config_file
    return value[one_node][two_node]
KeyError: 'cms_url'

During handling of the above exception, another exception occurred:

Traceback (most recent call last):
  File "E:\Project_python\2TestCMS2.0\common\requests_util.py", line 176, in analysis_yaml
    res = self.send_request(name =name,method=method,
  File "E:\Project_python\2TestCMS2.0\common\requests_util.py", line 304, in send_request
    error_log("发送请求异常：异常信息: %s" % str(traceback.format_exc()))
  File "E:\Project_python\2TestCMS2.0\common\logger_util.py", line 66, in error_log
    raise Exception(log_message)
Exception: 发送请求异常：异常信息: Traceback (most recent call last):
  File "E:\Project_python\2TestCMS2.0\common\requests_util.py", line 276, in send_request
    self.base_url = self.replace_load(self.base_url) + self.replace_load(url)
  File "E:\Project_python\2TestCMS2.0\common\requests_util.py", line 41, in replace_load
    new_value = getattr(DubugTalk(), func_name)(*args_value.split(','))
  File "E:\Project_python\2TestCMS2.0\debug_talk.py", line 20, in get_base_url
    return  read_config_file('base',node_name)
  File "E:\Project_python\2TestCMS2.0\common\yaml_util.py", line 13, in read_config_file
    return value[one_node][two_node]
KeyError: 'cms_url'


[2023-05-18 16:04:25,330] logger_util.py->error_log line:65 [INFO] 发送请求异常：异常信息: Traceback (most recent call last):
  File "E:\Project_python\2TestCMS2.0\common\requests_util.py", line 276, in send_request
    self.base_url = self.replace_load(self.base_url) + self.replace_load(url)
  File "E:\Project_python\2TestCMS2.0\common\requests_util.py", line 41, in replace_load
    new_value = getattr(DubugTalk(), func_name)(*args_value.split(','))
  File "E:\Project_python\2TestCMS2.0\debug_talk.py", line 20, in get_base_url
    return  read_config_file('base',node_name)
  File "E:\Project_python\2TestCMS2.0\common\yaml_util.py", line 13, in read_config_file
    return value[one_node][two_node]
KeyError: 'cms_url'

[2023-05-18 16:04:25,331] logger_util.py->error_log line:65 [INFO] 分析YAML文件异常：异常信息: Traceback (most recent call last):
  File "E:\Project_python\2TestCMS2.0\common\requests_util.py", line 276, in send_request
    self.base_url = self.replace_load(self.base_url) + self.replace_load(url)
  File "E:\Project_python\2TestCMS2.0\common\requests_util.py", line 41, in replace_load
    new_value = getattr(DubugTalk(), func_name)(*args_value.split(','))
  File "E:\Project_python\2TestCMS2.0\debug_talk.py", line 20, in get_base_url
    return  read_config_file('base',node_name)
  File "E:\Project_python\2TestCMS2.0\common\yaml_util.py", line 13, in read_config_file
    return value[one_node][two_node]
KeyError: 'cms_url'

During handling of the above exception, another exception occurred:

Traceback (most recent call last):
  File "E:\Project_python\2TestCMS2.0\common\requests_util.py", line 176, in analysis_yaml
    res = self.send_request(name =name,method=method,
  File "E:\Project_python\2TestCMS2.0\common\requests_util.py", line 304, in send_request
    error_log("发送请求异常：异常信息: %s" % str(traceback.format_exc()))
  File "E:\Project_python\2TestCMS2.0\common\logger_util.py", line 66, in error_log
    raise Exception(log_message)
Exception: 发送请求异常：异常信息: Traceback (most recent call last):
  File "E:\Project_python\2TestCMS2.0\common\requests_util.py", line 276, in send_request
    self.base_url = self.replace_load(self.base_url) + self.replace_load(url)
  File "E:\Project_python\2TestCMS2.0\common\requests_util.py", line 41, in replace_load
    new_value = getattr(DubugTalk(), func_name)(*args_value.split(','))
  File "E:\Project_python\2TestCMS2.0\debug_talk.py", line 20, in get_base_url
    return  read_config_file('base',node_name)
  File "E:\Project_python\2TestCMS2.0\common\yaml_util.py", line 13, in read_config_file
    return value[one_node][two_node]
KeyError: 'cms_url'


[2023-05-18 16:04:25,362] logger_util.py->error_log line:65 [INFO] 发送请求异常：异常信息: Traceback (most recent call last):
  File "E:\Project_python\2TestCMS2.0\common\requests_util.py", line 276, in send_request
    self.base_url = self.replace_load(self.base_url) + self.replace_load(url)
  File "E:\Project_python\2TestCMS2.0\common\requests_util.py", line 41, in replace_load
    new_value = getattr(DubugTalk(), func_name)(*args_value.split(','))
  File "E:\Project_python\2TestCMS2.0\debug_talk.py", line 20, in get_base_url
    return  read_config_file('base',node_name)
  File "E:\Project_python\2TestCMS2.0\common\yaml_util.py", line 13, in read_config_file
    return value[one_node][two_node]
KeyError: 'cms_url'

[2023-05-18 16:04:25,363] logger_util.py->error_log line:65 [INFO] 分析YAML文件异常：异常信息: Traceback (most recent call last):
  File "E:\Project_python\2TestCMS2.0\common\requests_util.py", line 276, in send_request
    self.base_url = self.replace_load(self.base_url) + self.replace_load(url)
  File "E:\Project_python\2TestCMS2.0\common\requests_util.py", line 41, in replace_load
    new_value = getattr(DubugTalk(), func_name)(*args_value.split(','))
  File "E:\Project_python\2TestCMS2.0\debug_talk.py", line 20, in get_base_url
    return  read_config_file('base',node_name)
  File "E:\Project_python\2TestCMS2.0\common\yaml_util.py", line 13, in read_config_file
    return value[one_node][two_node]
KeyError: 'cms_url'

During handling of the above exception, another exception occurred:

Traceback (most recent call last):
  File "E:\Project_python\2TestCMS2.0\common\requests_util.py", line 176, in analysis_yaml
    res = self.send_request(name =name,method=method,
  File "E:\Project_python\2TestCMS2.0\common\requests_util.py", line 304, in send_request
    error_log("发送请求异常：异常信息: %s" % str(traceback.format_exc()))
  File "E:\Project_python\2TestCMS2.0\common\logger_util.py", line 66, in error_log
    raise Exception(log_message)
Exception: 发送请求异常：异常信息: Traceback (most recent call last):
  File "E:\Project_python\2TestCMS2.0\common\requests_util.py", line 276, in send_request
    self.base_url = self.replace_load(self.base_url) + self.replace_load(url)
  File "E:\Project_python\2TestCMS2.0\common\requests_util.py", line 41, in replace_load
    new_value = getattr(DubugTalk(), func_name)(*args_value.split(','))
  File "E:\Project_python\2TestCMS2.0\debug_talk.py", line 20, in get_base_url
    return  read_config_file('base',node_name)
  File "E:\Project_python\2TestCMS2.0\common\yaml_util.py", line 13, in read_config_file
    return value[one_node][two_node]
KeyError: 'cms_url'


[2023-05-18 16:04:25,391] logger_util.py->error_log line:65 [INFO] 发送请求异常：异常信息: Traceback (most recent call last):
  File "E:\Project_python\2TestCMS2.0\common\requests_util.py", line 276, in send_request
    self.base_url = self.replace_load(self.base_url) + self.replace_load(url)
  File "E:\Project_python\2TestCMS2.0\common\requests_util.py", line 41, in replace_load
    new_value = getattr(DubugTalk(), func_name)(*args_value.split(','))
  File "E:\Project_python\2TestCMS2.0\debug_talk.py", line 20, in get_base_url
    return  read_config_file('base',node_name)
  File "E:\Project_python\2TestCMS2.0\common\yaml_util.py", line 13, in read_config_file
    return value[one_node][two_node]
KeyError: 'cms_url'

[2023-05-18 16:04:25,391] logger_util.py->error_log line:65 [INFO] 分析YAML文件异常：异常信息: Traceback (most recent call last):
  File "E:\Project_python\2TestCMS2.0\common\requests_util.py", line 276, in send_request
    self.base_url = self.replace_load(self.base_url) + self.replace_load(url)
  File "E:\Project_python\2TestCMS2.0\common\requests_util.py", line 41, in replace_load
    new_value = getattr(DubugTalk(), func_name)(*args_value.split(','))
  File "E:\Project_python\2TestCMS2.0\debug_talk.py", line 20, in get_base_url
    return  read_config_file('base',node_name)
  File "E:\Project_python\2TestCMS2.0\common\yaml_util.py", line 13, in read_config_file
    return value[one_node][two_node]
KeyError: 'cms_url'

During handling of the above exception, another exception occurred:

Traceback (most recent call last):
  File "E:\Project_python\2TestCMS2.0\common\requests_util.py", line 176, in analysis_yaml
    res = self.send_request(name =name,method=method,
  File "E:\Project_python\2TestCMS2.0\common\requests_util.py", line 304, in send_request
    error_log("发送请求异常：异常信息: %s" % str(traceback.format_exc()))
  File "E:\Project_python\2TestCMS2.0\common\logger_util.py", line 66, in error_log
    raise Exception(log_message)
Exception: 发送请求异常：异常信息: Traceback (most recent call last):
  File "E:\Project_python\2TestCMS2.0\common\requests_util.py", line 276, in send_request
    self.base_url = self.replace_load(self.base_url) + self.replace_load(url)
  File "E:\Project_python\2TestCMS2.0\common\requests_util.py", line 41, in replace_load
    new_value = getattr(DubugTalk(), func_name)(*args_value.split(','))
  File "E:\Project_python\2TestCMS2.0\debug_talk.py", line 20, in get_base_url
    return  read_config_file('base',node_name)
  File "E:\Project_python\2TestCMS2.0\common\yaml_util.py", line 13, in read_config_file
    return value[one_node][two_node]
KeyError: 'cms_url'


[2023-05-18 16:04:25,419] logger_util.py->error_log line:65 [INFO] 发送请求异常：异常信息: Traceback (most recent call last):
  File "E:\Project_python\2TestCMS2.0\common\requests_util.py", line 276, in send_request
    self.base_url = self.replace_load(self.base_url) + self.replace_load(url)
  File "E:\Project_python\2TestCMS2.0\common\requests_util.py", line 41, in replace_load
    new_value = getattr(DubugTalk(), func_name)(*args_value.split(','))
  File "E:\Project_python\2TestCMS2.0\debug_talk.py", line 20, in get_base_url
    return  read_config_file('base',node_name)
  File "E:\Project_python\2TestCMS2.0\common\yaml_util.py", line 13, in read_config_file
    return value[one_node][two_node]
KeyError: 'cms_url'

[2023-05-18 16:04:25,420] logger_util.py->error_log line:65 [INFO] 分析YAML文件异常：异常信息: Traceback (most recent call last):
  File "E:\Project_python\2TestCMS2.0\common\requests_util.py", line 276, in send_request
    self.base_url = self.replace_load(self.base_url) + self.replace_load(url)
  File "E:\Project_python\2TestCMS2.0\common\requests_util.py", line 41, in replace_load
    new_value = getattr(DubugTalk(), func_name)(*args_value.split(','))
  File "E:\Project_python\2TestCMS2.0\debug_talk.py", line 20, in get_base_url
    return  read_config_file('base',node_name)
  File "E:\Project_python\2TestCMS2.0\common\yaml_util.py", line 13, in read_config_file
    return value[one_node][two_node]
KeyError: 'cms_url'

During handling of the above exception, another exception occurred:

Traceback (most recent call last):
  File "E:\Project_python\2TestCMS2.0\common\requests_util.py", line 176, in analysis_yaml
    res = self.send_request(name =name,method=method,
  File "E:\Project_python\2TestCMS2.0\common\requests_util.py", line 304, in send_request
    error_log("发送请求异常：异常信息: %s" % str(traceback.format_exc()))
  File "E:\Project_python\2TestCMS2.0\common\logger_util.py", line 66, in error_log
    raise Exception(log_message)
Exception: 发送请求异常：异常信息: Traceback (most recent call last):
  File "E:\Project_python\2TestCMS2.0\common\requests_util.py", line 276, in send_request
    self.base_url = self.replace_load(self.base_url) + self.replace_load(url)
  File "E:\Project_python\2TestCMS2.0\common\requests_util.py", line 41, in replace_load
    new_value = getattr(DubugTalk(), func_name)(*args_value.split(','))
  File "E:\Project_python\2TestCMS2.0\debug_talk.py", line 20, in get_base_url
    return  read_config_file('base',node_name)
  File "E:\Project_python\2TestCMS2.0\common\yaml_util.py", line 13, in read_config_file
    return value[one_node][two_node]
KeyError: 'cms_url'


[2023-05-18 16:04:25,449] logger_util.py->error_log line:65 [INFO] 发送请求异常：异常信息: Traceback (most recent call last):
  File "E:\Project_python\2TestCMS2.0\common\requests_util.py", line 276, in send_request
    self.base_url = self.replace_load(self.base_url) + self.replace_load(url)
  File "E:\Project_python\2TestCMS2.0\common\requests_util.py", line 41, in replace_load
    new_value = getattr(DubugTalk(), func_name)(*args_value.split(','))
  File "E:\Project_python\2TestCMS2.0\debug_talk.py", line 20, in get_base_url
    return  read_config_file('base',node_name)
  File "E:\Project_python\2TestCMS2.0\common\yaml_util.py", line 13, in read_config_file
    return value[one_node][two_node]
KeyError: 'cms_url'

[2023-05-18 16:04:25,449] logger_util.py->error_log line:65 [INFO] 分析YAML文件异常：异常信息: Traceback (most recent call last):
  File "E:\Project_python\2TestCMS2.0\common\requests_util.py", line 276, in send_request
    self.base_url = self.replace_load(self.base_url) + self.replace_load(url)
  File "E:\Project_python\2TestCMS2.0\common\requests_util.py", line 41, in replace_load
    new_value = getattr(DubugTalk(), func_name)(*args_value.split(','))
  File "E:\Project_python\2TestCMS2.0\debug_talk.py", line 20, in get_base_url
    return  read_config_file('base',node_name)
  File "E:\Project_python\2TestCMS2.0\common\yaml_util.py", line 13, in read_config_file
    return value[one_node][two_node]
KeyError: 'cms_url'

During handling of the above exception, another exception occurred:

Traceback (most recent call last):
  File "E:\Project_python\2TestCMS2.0\common\requests_util.py", line 176, in analysis_yaml
    res = self.send_request(name =name,method=method,
  File "E:\Project_python\2TestCMS2.0\common\requests_util.py", line 304, in send_request
    error_log("发送请求异常：异常信息: %s" % str(traceback.format_exc()))
  File "E:\Project_python\2TestCMS2.0\common\logger_util.py", line 66, in error_log
    raise Exception(log_message)
Exception: 发送请求异常：异常信息: Traceback (most recent call last):
  File "E:\Project_python\2TestCMS2.0\common\requests_util.py", line 276, in send_request
    self.base_url = self.replace_load(self.base_url) + self.replace_load(url)
  File "E:\Project_python\2TestCMS2.0\common\requests_util.py", line 41, in replace_load
    new_value = getattr(DubugTalk(), func_name)(*args_value.split(','))
  File "E:\Project_python\2TestCMS2.0\debug_talk.py", line 20, in get_base_url
    return  read_config_file('base',node_name)
  File "E:\Project_python\2TestCMS2.0\common\yaml_util.py", line 13, in read_config_file
    return value[one_node][two_node]
KeyError: 'cms_url'


[2023-05-18 16:04:25,478] logger_util.py->error_log line:65 [INFO] 发送请求异常：异常信息: Traceback (most recent call last):
  File "E:\Project_python\2TestCMS2.0\common\requests_util.py", line 276, in send_request
    self.base_url = self.replace_load(self.base_url) + self.replace_load(url)
  File "E:\Project_python\2TestCMS2.0\common\requests_util.py", line 41, in replace_load
    new_value = getattr(DubugTalk(), func_name)(*args_value.split(','))
  File "E:\Project_python\2TestCMS2.0\debug_talk.py", line 20, in get_base_url
    return  read_config_file('base',node_name)
  File "E:\Project_python\2TestCMS2.0\common\yaml_util.py", line 13, in read_config_file
    return value[one_node][two_node]
KeyError: 'cms_url'

[2023-05-18 16:04:25,478] logger_util.py->error_log line:65 [INFO] 分析YAML文件异常：异常信息: Traceback (most recent call last):
  File "E:\Project_python\2TestCMS2.0\common\requests_util.py", line 276, in send_request
    self.base_url = self.replace_load(self.base_url) + self.replace_load(url)
  File "E:\Project_python\2TestCMS2.0\common\requests_util.py", line 41, in replace_load
    new_value = getattr(DubugTalk(), func_name)(*args_value.split(','))
  File "E:\Project_python\2TestCMS2.0\debug_talk.py", line 20, in get_base_url
    return  read_config_file('base',node_name)
  File "E:\Project_python\2TestCMS2.0\common\yaml_util.py", line 13, in read_config_file
    return value[one_node][two_node]
KeyError: 'cms_url'

During handling of the above exception, another exception occurred:

Traceback (most recent call last):
  File "E:\Project_python\2TestCMS2.0\common\requests_util.py", line 176, in analysis_yaml
    res = self.send_request(name =name,method=method,
  File "E:\Project_python\2TestCMS2.0\common\requests_util.py", line 304, in send_request
    error_log("发送请求异常：异常信息: %s" % str(traceback.format_exc()))
  File "E:\Project_python\2TestCMS2.0\common\logger_util.py", line 66, in error_log
    raise Exception(log_message)
Exception: 发送请求异常：异常信息: Traceback (most recent call last):
  File "E:\Project_python\2TestCMS2.0\common\requests_util.py", line 276, in send_request
    self.base_url = self.replace_load(self.base_url) + self.replace_load(url)
  File "E:\Project_python\2TestCMS2.0\common\requests_util.py", line 41, in replace_load
    new_value = getattr(DubugTalk(), func_name)(*args_value.split(','))
  File "E:\Project_python\2TestCMS2.0\debug_talk.py", line 20, in get_base_url
    return  read_config_file('base',node_name)
  File "E:\Project_python\2TestCMS2.0\common\yaml_util.py", line 13, in read_config_file
    return value[one_node][two_node]
KeyError: 'cms_url'


[2023-05-18 16:04:25,507] logger_util.py->error_log line:65 [INFO] 发送请求异常：异常信息: Traceback (most recent call last):
  File "E:\Project_python\2TestCMS2.0\common\requests_util.py", line 276, in send_request
    self.base_url = self.replace_load(self.base_url) + self.replace_load(url)
  File "E:\Project_python\2TestCMS2.0\common\requests_util.py", line 41, in replace_load
    new_value = getattr(DubugTalk(), func_name)(*args_value.split(','))
  File "E:\Project_python\2TestCMS2.0\debug_talk.py", line 20, in get_base_url
    return  read_config_file('base',node_name)
  File "E:\Project_python\2TestCMS2.0\common\yaml_util.py", line 13, in read_config_file
    return value[one_node][two_node]
KeyError: 'cms_url'

[2023-05-18 16:04:25,507] logger_util.py->error_log line:65 [INFO] 分析YAML文件异常：异常信息: Traceback (most recent call last):
  File "E:\Project_python\2TestCMS2.0\common\requests_util.py", line 276, in send_request
    self.base_url = self.replace_load(self.base_url) + self.replace_load(url)
  File "E:\Project_python\2TestCMS2.0\common\requests_util.py", line 41, in replace_load
    new_value = getattr(DubugTalk(), func_name)(*args_value.split(','))
  File "E:\Project_python\2TestCMS2.0\debug_talk.py", line 20, in get_base_url
    return  read_config_file('base',node_name)
  File "E:\Project_python\2TestCMS2.0\common\yaml_util.py", line 13, in read_config_file
    return value[one_node][two_node]
KeyError: 'cms_url'

During handling of the above exception, another exception occurred:

Traceback (most recent call last):
  File "E:\Project_python\2TestCMS2.0\common\requests_util.py", line 176, in analysis_yaml
    res = self.send_request(name =name,method=method,
  File "E:\Project_python\2TestCMS2.0\common\requests_util.py", line 304, in send_request
    error_log("发送请求异常：异常信息: %s" % str(traceback.format_exc()))
  File "E:\Project_python\2TestCMS2.0\common\logger_util.py", line 66, in error_log
    raise Exception(log_message)
Exception: 发送请求异常：异常信息: Traceback (most recent call last):
  File "E:\Project_python\2TestCMS2.0\common\requests_util.py", line 276, in send_request
    self.base_url = self.replace_load(self.base_url) + self.replace_load(url)
  File "E:\Project_python\2TestCMS2.0\common\requests_util.py", line 41, in replace_load
    new_value = getattr(DubugTalk(), func_name)(*args_value.split(','))
  File "E:\Project_python\2TestCMS2.0\debug_talk.py", line 20, in get_base_url
    return  read_config_file('base',node_name)
  File "E:\Project_python\2TestCMS2.0\common\yaml_util.py", line 13, in read_config_file
    return value[one_node][two_node]
KeyError: 'cms_url'


[2023-05-18 16:04:25,556] logger_util.py->error_log line:65 [INFO] 发送请求异常：异常信息: Traceback (most recent call last):
  File "E:\Project_python\2TestCMS2.0\common\requests_util.py", line 276, in send_request
    self.base_url = self.replace_load(self.base_url) + self.replace_load(url)
  File "E:\Project_python\2TestCMS2.0\common\requests_util.py", line 41, in replace_load
    new_value = getattr(DubugTalk(), func_name)(*args_value.split(','))
  File "E:\Project_python\2TestCMS2.0\debug_talk.py", line 20, in get_base_url
    return  read_config_file('base',node_name)
  File "E:\Project_python\2TestCMS2.0\common\yaml_util.py", line 13, in read_config_file
    return value[one_node][two_node]
KeyError: 'cms_url'

[2023-05-18 16:04:25,556] logger_util.py->error_log line:65 [INFO] 分析YAML文件异常：异常信息: Traceback (most recent call last):
  File "E:\Project_python\2TestCMS2.0\common\requests_util.py", line 276, in send_request
    self.base_url = self.replace_load(self.base_url) + self.replace_load(url)
  File "E:\Project_python\2TestCMS2.0\common\requests_util.py", line 41, in replace_load
    new_value = getattr(DubugTalk(), func_name)(*args_value.split(','))
  File "E:\Project_python\2TestCMS2.0\debug_talk.py", line 20, in get_base_url
    return  read_config_file('base',node_name)
  File "E:\Project_python\2TestCMS2.0\common\yaml_util.py", line 13, in read_config_file
    return value[one_node][two_node]
KeyError: 'cms_url'

During handling of the above exception, another exception occurred:

Traceback (most recent call last):
  File "E:\Project_python\2TestCMS2.0\common\requests_util.py", line 176, in analysis_yaml
    res = self.send_request(name =name,method=method,
  File "E:\Project_python\2TestCMS2.0\common\requests_util.py", line 304, in send_request
    error_log("发送请求异常：异常信息: %s" % str(traceback.format_exc()))
  File "E:\Project_python\2TestCMS2.0\common\logger_util.py", line 66, in error_log
    raise Exception(log_message)
Exception: 发送请求异常：异常信息: Traceback (most recent call last):
  File "E:\Project_python\2TestCMS2.0\common\requests_util.py", line 276, in send_request
    self.base_url = self.replace_load(self.base_url) + self.replace_load(url)
  File "E:\Project_python\2TestCMS2.0\common\requests_util.py", line 41, in replace_load
    new_value = getattr(DubugTalk(), func_name)(*args_value.split(','))
  File "E:\Project_python\2TestCMS2.0\debug_talk.py", line 20, in get_base_url
    return  read_config_file('base',node_name)
  File "E:\Project_python\2TestCMS2.0\common\yaml_util.py", line 13, in read_config_file
    return value[one_node][two_node]
KeyError: 'cms_url'


[2023-05-18 16:04:25,590] logger_util.py->error_log line:65 [INFO] 发送请求异常：异常信息: Traceback (most recent call last):
  File "E:\Project_python\2TestCMS2.0\common\requests_util.py", line 276, in send_request
    self.base_url = self.replace_load(self.base_url) + self.replace_load(url)
  File "E:\Project_python\2TestCMS2.0\common\requests_util.py", line 41, in replace_load
    new_value = getattr(DubugTalk(), func_name)(*args_value.split(','))
  File "E:\Project_python\2TestCMS2.0\debug_talk.py", line 20, in get_base_url
    return  read_config_file('base',node_name)
  File "E:\Project_python\2TestCMS2.0\common\yaml_util.py", line 13, in read_config_file
    return value[one_node][two_node]
KeyError: 'cms_url'

[2023-05-18 16:04:25,590] logger_util.py->error_log line:65 [INFO] 分析YAML文件异常：异常信息: Traceback (most recent call last):
  File "E:\Project_python\2TestCMS2.0\common\requests_util.py", line 276, in send_request
    self.base_url = self.replace_load(self.base_url) + self.replace_load(url)
  File "E:\Project_python\2TestCMS2.0\common\requests_util.py", line 41, in replace_load
    new_value = getattr(DubugTalk(), func_name)(*args_value.split(','))
  File "E:\Project_python\2TestCMS2.0\debug_talk.py", line 20, in get_base_url
    return  read_config_file('base',node_name)
  File "E:\Project_python\2TestCMS2.0\common\yaml_util.py", line 13, in read_config_file
    return value[one_node][two_node]
KeyError: 'cms_url'

During handling of the above exception, another exception occurred:

Traceback (most recent call last):
  File "E:\Project_python\2TestCMS2.0\common\requests_util.py", line 176, in analysis_yaml
    res = self.send_request(name =name,method=method,
  File "E:\Project_python\2TestCMS2.0\common\requests_util.py", line 304, in send_request
    error_log("发送请求异常：异常信息: %s" % str(traceback.format_exc()))
  File "E:\Project_python\2TestCMS2.0\common\logger_util.py", line 66, in error_log
    raise Exception(log_message)
Exception: 发送请求异常：异常信息: Traceback (most recent call last):
  File "E:\Project_python\2TestCMS2.0\common\requests_util.py", line 276, in send_request
    self.base_url = self.replace_load(self.base_url) + self.replace_load(url)
  File "E:\Project_python\2TestCMS2.0\common\requests_util.py", line 41, in replace_load
    new_value = getattr(DubugTalk(), func_name)(*args_value.split(','))
  File "E:\Project_python\2TestCMS2.0\debug_talk.py", line 20, in get_base_url
    return  read_config_file('base',node_name)
  File "E:\Project_python\2TestCMS2.0\common\yaml_util.py", line 13, in read_config_file
    return value[one_node][two_node]
KeyError: 'cms_url'


[2023-05-18 16:04:25,634] logger_util.py->error_log line:65 [INFO] 发送请求异常：异常信息: Traceback (most recent call last):
  File "E:\Project_python\2TestCMS2.0\common\requests_util.py", line 276, in send_request
    self.base_url = self.replace_load(self.base_url) + self.replace_load(url)
  File "E:\Project_python\2TestCMS2.0\common\requests_util.py", line 41, in replace_load
    new_value = getattr(DubugTalk(), func_name)(*args_value.split(','))
  File "E:\Project_python\2TestCMS2.0\debug_talk.py", line 20, in get_base_url
    return  read_config_file('base',node_name)
  File "E:\Project_python\2TestCMS2.0\common\yaml_util.py", line 13, in read_config_file
    return value[one_node][two_node]
KeyError: 'cms_url'

[2023-05-18 16:04:25,635] logger_util.py->error_log line:65 [INFO] 分析YAML文件异常：异常信息: Traceback (most recent call last):
  File "E:\Project_python\2TestCMS2.0\common\requests_util.py", line 276, in send_request
    self.base_url = self.replace_load(self.base_url) + self.replace_load(url)
  File "E:\Project_python\2TestCMS2.0\common\requests_util.py", line 41, in replace_load
    new_value = getattr(DubugTalk(), func_name)(*args_value.split(','))
  File "E:\Project_python\2TestCMS2.0\debug_talk.py", line 20, in get_base_url
    return  read_config_file('base',node_name)
  File "E:\Project_python\2TestCMS2.0\common\yaml_util.py", line 13, in read_config_file
    return value[one_node][two_node]
KeyError: 'cms_url'

During handling of the above exception, another exception occurred:

Traceback (most recent call last):
  File "E:\Project_python\2TestCMS2.0\common\requests_util.py", line 176, in analysis_yaml
    res = self.send_request(name =name,method=method,
  File "E:\Project_python\2TestCMS2.0\common\requests_util.py", line 304, in send_request
    error_log("发送请求异常：异常信息: %s" % str(traceback.format_exc()))
  File "E:\Project_python\2TestCMS2.0\common\logger_util.py", line 66, in error_log
    raise Exception(log_message)
Exception: 发送请求异常：异常信息: Traceback (most recent call last):
  File "E:\Project_python\2TestCMS2.0\common\requests_util.py", line 276, in send_request
    self.base_url = self.replace_load(self.base_url) + self.replace_load(url)
  File "E:\Project_python\2TestCMS2.0\common\requests_util.py", line 41, in replace_load
    new_value = getattr(DubugTalk(), func_name)(*args_value.split(','))
  File "E:\Project_python\2TestCMS2.0\debug_talk.py", line 20, in get_base_url
    return  read_config_file('base',node_name)
  File "E:\Project_python\2TestCMS2.0\common\yaml_util.py", line 13, in read_config_file
    return value[one_node][two_node]
KeyError: 'cms_url'


[2023-05-18 16:04:25,662] logger_util.py->error_log line:65 [INFO] 发送请求异常：异常信息: Traceback (most recent call last):
  File "E:\Project_python\2TestCMS2.0\common\requests_util.py", line 276, in send_request
    self.base_url = self.replace_load(self.base_url) + self.replace_load(url)
  File "E:\Project_python\2TestCMS2.0\common\requests_util.py", line 41, in replace_load
    new_value = getattr(DubugTalk(), func_name)(*args_value.split(','))
  File "E:\Project_python\2TestCMS2.0\debug_talk.py", line 20, in get_base_url
    return  read_config_file('base',node_name)
  File "E:\Project_python\2TestCMS2.0\common\yaml_util.py", line 13, in read_config_file
    return value[one_node][two_node]
KeyError: 'cms_url'

[2023-05-18 16:04:25,663] logger_util.py->error_log line:65 [INFO] 分析YAML文件异常：异常信息: Traceback (most recent call last):
  File "E:\Project_python\2TestCMS2.0\common\requests_util.py", line 276, in send_request
    self.base_url = self.replace_load(self.base_url) + self.replace_load(url)
  File "E:\Project_python\2TestCMS2.0\common\requests_util.py", line 41, in replace_load
    new_value = getattr(DubugTalk(), func_name)(*args_value.split(','))
  File "E:\Project_python\2TestCMS2.0\debug_talk.py", line 20, in get_base_url
    return  read_config_file('base',node_name)
  File "E:\Project_python\2TestCMS2.0\common\yaml_util.py", line 13, in read_config_file
    return value[one_node][two_node]
KeyError: 'cms_url'

During handling of the above exception, another exception occurred:

Traceback (most recent call last):
  File "E:\Project_python\2TestCMS2.0\common\requests_util.py", line 176, in analysis_yaml
    res = self.send_request(name =name,method=method,
  File "E:\Project_python\2TestCMS2.0\common\requests_util.py", line 304, in send_request
    error_log("发送请求异常：异常信息: %s" % str(traceback.format_exc()))
  File "E:\Project_python\2TestCMS2.0\common\logger_util.py", line 66, in error_log
    raise Exception(log_message)
Exception: 发送请求异常：异常信息: Traceback (most recent call last):
  File "E:\Project_python\2TestCMS2.0\common\requests_util.py", line 276, in send_request
    self.base_url = self.replace_load(self.base_url) + self.replace_load(url)
  File "E:\Project_python\2TestCMS2.0\common\requests_util.py", line 41, in replace_load
    new_value = getattr(DubugTalk(), func_name)(*args_value.split(','))
  File "E:\Project_python\2TestCMS2.0\debug_talk.py", line 20, in get_base_url
    return  read_config_file('base',node_name)
  File "E:\Project_python\2TestCMS2.0\common\yaml_util.py", line 13, in read_config_file
    return value[one_node][two_node]
KeyError: 'cms_url'


[2023-05-18 16:04:25,692] logger_util.py->error_log line:65 [INFO] 发送请求异常：异常信息: Traceback (most recent call last):
  File "E:\Project_python\2TestCMS2.0\common\requests_util.py", line 276, in send_request
    self.base_url = self.replace_load(self.base_url) + self.replace_load(url)
  File "E:\Project_python\2TestCMS2.0\common\requests_util.py", line 41, in replace_load
    new_value = getattr(DubugTalk(), func_name)(*args_value.split(','))
  File "E:\Project_python\2TestCMS2.0\debug_talk.py", line 20, in get_base_url
    return  read_config_file('base',node_name)
  File "E:\Project_python\2TestCMS2.0\common\yaml_util.py", line 13, in read_config_file
    return value[one_node][two_node]
KeyError: 'cms_url'

[2023-05-18 16:04:25,692] logger_util.py->error_log line:65 [INFO] 分析YAML文件异常：异常信息: Traceback (most recent call last):
  File "E:\Project_python\2TestCMS2.0\common\requests_util.py", line 276, in send_request
    self.base_url = self.replace_load(self.base_url) + self.replace_load(url)
  File "E:\Project_python\2TestCMS2.0\common\requests_util.py", line 41, in replace_load
    new_value = getattr(DubugTalk(), func_name)(*args_value.split(','))
  File "E:\Project_python\2TestCMS2.0\debug_talk.py", line 20, in get_base_url
    return  read_config_file('base',node_name)
  File "E:\Project_python\2TestCMS2.0\common\yaml_util.py", line 13, in read_config_file
    return value[one_node][two_node]
KeyError: 'cms_url'

During handling of the above exception, another exception occurred:

Traceback (most recent call last):
  File "E:\Project_python\2TestCMS2.0\common\requests_util.py", line 176, in analysis_yaml
    res = self.send_request(name =name,method=method,
  File "E:\Project_python\2TestCMS2.0\common\requests_util.py", line 304, in send_request
    error_log("发送请求异常：异常信息: %s" % str(traceback.format_exc()))
  File "E:\Project_python\2TestCMS2.0\common\logger_util.py", line 66, in error_log
    raise Exception(log_message)
Exception: 发送请求异常：异常信息: Traceback (most recent call last):
  File "E:\Project_python\2TestCMS2.0\common\requests_util.py", line 276, in send_request
    self.base_url = self.replace_load(self.base_url) + self.replace_load(url)
  File "E:\Project_python\2TestCMS2.0\common\requests_util.py", line 41, in replace_load
    new_value = getattr(DubugTalk(), func_name)(*args_value.split(','))
  File "E:\Project_python\2TestCMS2.0\debug_talk.py", line 20, in get_base_url
    return  read_config_file('base',node_name)
  File "E:\Project_python\2TestCMS2.0\common\yaml_util.py", line 13, in read_config_file
    return value[one_node][two_node]
KeyError: 'cms_url'


[2023-05-18 16:04:25,722] logger_util.py->error_log line:65 [INFO] 发送请求异常：异常信息: Traceback (most recent call last):
  File "E:\Project_python\2TestCMS2.0\common\requests_util.py", line 276, in send_request
    self.base_url = self.replace_load(self.base_url) + self.replace_load(url)
  File "E:\Project_python\2TestCMS2.0\common\requests_util.py", line 41, in replace_load
    new_value = getattr(DubugTalk(), func_name)(*args_value.split(','))
  File "E:\Project_python\2TestCMS2.0\debug_talk.py", line 20, in get_base_url
    return  read_config_file('base',node_name)
  File "E:\Project_python\2TestCMS2.0\common\yaml_util.py", line 13, in read_config_file
    return value[one_node][two_node]
KeyError: 'cms_url'

[2023-05-18 16:04:25,722] logger_util.py->error_log line:65 [INFO] 分析YAML文件异常：异常信息: Traceback (most recent call last):
  File "E:\Project_python\2TestCMS2.0\common\requests_util.py", line 276, in send_request
    self.base_url = self.replace_load(self.base_url) + self.replace_load(url)
  File "E:\Project_python\2TestCMS2.0\common\requests_util.py", line 41, in replace_load
    new_value = getattr(DubugTalk(), func_name)(*args_value.split(','))
  File "E:\Project_python\2TestCMS2.0\debug_talk.py", line 20, in get_base_url
    return  read_config_file('base',node_name)
  File "E:\Project_python\2TestCMS2.0\common\yaml_util.py", line 13, in read_config_file
    return value[one_node][two_node]
KeyError: 'cms_url'

During handling of the above exception, another exception occurred:

Traceback (most recent call last):
  File "E:\Project_python\2TestCMS2.0\common\requests_util.py", line 176, in analysis_yaml
    res = self.send_request(name =name,method=method,
  File "E:\Project_python\2TestCMS2.0\common\requests_util.py", line 304, in send_request
    error_log("发送请求异常：异常信息: %s" % str(traceback.format_exc()))
  File "E:\Project_python\2TestCMS2.0\common\logger_util.py", line 66, in error_log
    raise Exception(log_message)
Exception: 发送请求异常：异常信息: Traceback (most recent call last):
  File "E:\Project_python\2TestCMS2.0\common\requests_util.py", line 276, in send_request
    self.base_url = self.replace_load(self.base_url) + self.replace_load(url)
  File "E:\Project_python\2TestCMS2.0\common\requests_util.py", line 41, in replace_load
    new_value = getattr(DubugTalk(), func_name)(*args_value.split(','))
  File "E:\Project_python\2TestCMS2.0\debug_talk.py", line 20, in get_base_url
    return  read_config_file('base',node_name)
  File "E:\Project_python\2TestCMS2.0\common\yaml_util.py", line 13, in read_config_file
    return value[one_node][two_node]
KeyError: 'cms_url'


[2023-05-18 16:04:25,751] logger_util.py->error_log line:65 [INFO] 发送请求异常：异常信息: Traceback (most recent call last):
  File "E:\Project_python\2TestCMS2.0\common\requests_util.py", line 276, in send_request
    self.base_url = self.replace_load(self.base_url) + self.replace_load(url)
  File "E:\Project_python\2TestCMS2.0\common\requests_util.py", line 41, in replace_load
    new_value = getattr(DubugTalk(), func_name)(*args_value.split(','))
  File "E:\Project_python\2TestCMS2.0\debug_talk.py", line 20, in get_base_url
    return  read_config_file('base',node_name)
  File "E:\Project_python\2TestCMS2.0\common\yaml_util.py", line 13, in read_config_file
    return value[one_node][two_node]
KeyError: 'cms_url'

[2023-05-18 16:04:25,751] logger_util.py->error_log line:65 [INFO] 分析YAML文件异常：异常信息: Traceback (most recent call last):
  File "E:\Project_python\2TestCMS2.0\common\requests_util.py", line 276, in send_request
    self.base_url = self.replace_load(self.base_url) + self.replace_load(url)
  File "E:\Project_python\2TestCMS2.0\common\requests_util.py", line 41, in replace_load
    new_value = getattr(DubugTalk(), func_name)(*args_value.split(','))
  File "E:\Project_python\2TestCMS2.0\debug_talk.py", line 20, in get_base_url
    return  read_config_file('base',node_name)
  File "E:\Project_python\2TestCMS2.0\common\yaml_util.py", line 13, in read_config_file
    return value[one_node][two_node]
KeyError: 'cms_url'

During handling of the above exception, another exception occurred:

Traceback (most recent call last):
  File "E:\Project_python\2TestCMS2.0\common\requests_util.py", line 176, in analysis_yaml
    res = self.send_request(name =name,method=method,
  File "E:\Project_python\2TestCMS2.0\common\requests_util.py", line 304, in send_request
    error_log("发送请求异常：异常信息: %s" % str(traceback.format_exc()))
  File "E:\Project_python\2TestCMS2.0\common\logger_util.py", line 66, in error_log
    raise Exception(log_message)
Exception: 发送请求异常：异常信息: Traceback (most recent call last):
  File "E:\Project_python\2TestCMS2.0\common\requests_util.py", line 276, in send_request
    self.base_url = self.replace_load(self.base_url) + self.replace_load(url)
  File "E:\Project_python\2TestCMS2.0\common\requests_util.py", line 41, in replace_load
    new_value = getattr(DubugTalk(), func_name)(*args_value.split(','))
  File "E:\Project_python\2TestCMS2.0\debug_talk.py", line 20, in get_base_url
    return  read_config_file('base',node_name)
  File "E:\Project_python\2TestCMS2.0\common\yaml_util.py", line 13, in read_config_file
    return value[one_node][two_node]
KeyError: 'cms_url'


[2023-05-18 16:04:25,781] logger_util.py->error_log line:65 [INFO] 发送请求异常：异常信息: Traceback (most recent call last):
  File "E:\Project_python\2TestCMS2.0\common\requests_util.py", line 276, in send_request
    self.base_url = self.replace_load(self.base_url) + self.replace_load(url)
  File "E:\Project_python\2TestCMS2.0\common\requests_util.py", line 41, in replace_load
    new_value = getattr(DubugTalk(), func_name)(*args_value.split(','))
  File "E:\Project_python\2TestCMS2.0\debug_talk.py", line 20, in get_base_url
    return  read_config_file('base',node_name)
  File "E:\Project_python\2TestCMS2.0\common\yaml_util.py", line 13, in read_config_file
    return value[one_node][two_node]
KeyError: 'cms_url'

[2023-05-18 16:04:25,781] logger_util.py->error_log line:65 [INFO] 分析YAML文件异常：异常信息: Traceback (most recent call last):
  File "E:\Project_python\2TestCMS2.0\common\requests_util.py", line 276, in send_request
    self.base_url = self.replace_load(self.base_url) + self.replace_load(url)
  File "E:\Project_python\2TestCMS2.0\common\requests_util.py", line 41, in replace_load
    new_value = getattr(DubugTalk(), func_name)(*args_value.split(','))
  File "E:\Project_python\2TestCMS2.0\debug_talk.py", line 20, in get_base_url
    return  read_config_file('base',node_name)
  File "E:\Project_python\2TestCMS2.0\common\yaml_util.py", line 13, in read_config_file
    return value[one_node][two_node]
KeyError: 'cms_url'

During handling of the above exception, another exception occurred:

Traceback (most recent call last):
  File "E:\Project_python\2TestCMS2.0\common\requests_util.py", line 176, in analysis_yaml
    res = self.send_request(name =name,method=method,
  File "E:\Project_python\2TestCMS2.0\common\requests_util.py", line 304, in send_request
    error_log("发送请求异常：异常信息: %s" % str(traceback.format_exc()))
  File "E:\Project_python\2TestCMS2.0\common\logger_util.py", line 66, in error_log
    raise Exception(log_message)
Exception: 发送请求异常：异常信息: Traceback (most recent call last):
  File "E:\Project_python\2TestCMS2.0\common\requests_util.py", line 276, in send_request
    self.base_url = self.replace_load(self.base_url) + self.replace_load(url)
  File "E:\Project_python\2TestCMS2.0\common\requests_util.py", line 41, in replace_load
    new_value = getattr(DubugTalk(), func_name)(*args_value.split(','))
  File "E:\Project_python\2TestCMS2.0\debug_talk.py", line 20, in get_base_url
    return  read_config_file('base',node_name)
  File "E:\Project_python\2TestCMS2.0\common\yaml_util.py", line 13, in read_config_file
    return value[one_node][two_node]
KeyError: 'cms_url'


[2023-05-18 16:04:25,809] logger_util.py->error_log line:65 [INFO] 发送请求异常：异常信息: Traceback (most recent call last):
  File "E:\Project_python\2TestCMS2.0\common\requests_util.py", line 276, in send_request
    self.base_url = self.replace_load(self.base_url) + self.replace_load(url)
  File "E:\Project_python\2TestCMS2.0\common\requests_util.py", line 41, in replace_load
    new_value = getattr(DubugTalk(), func_name)(*args_value.split(','))
  File "E:\Project_python\2TestCMS2.0\debug_talk.py", line 20, in get_base_url
    return  read_config_file('base',node_name)
  File "E:\Project_python\2TestCMS2.0\common\yaml_util.py", line 13, in read_config_file
    return value[one_node][two_node]
KeyError: 'cms_url'

[2023-05-18 16:04:25,810] logger_util.py->error_log line:65 [INFO] 分析YAML文件异常：异常信息: Traceback (most recent call last):
  File "E:\Project_python\2TestCMS2.0\common\requests_util.py", line 276, in send_request
    self.base_url = self.replace_load(self.base_url) + self.replace_load(url)
  File "E:\Project_python\2TestCMS2.0\common\requests_util.py", line 41, in replace_load
    new_value = getattr(DubugTalk(), func_name)(*args_value.split(','))
  File "E:\Project_python\2TestCMS2.0\debug_talk.py", line 20, in get_base_url
    return  read_config_file('base',node_name)
  File "E:\Project_python\2TestCMS2.0\common\yaml_util.py", line 13, in read_config_file
    return value[one_node][two_node]
KeyError: 'cms_url'

During handling of the above exception, another exception occurred:

Traceback (most recent call last):
  File "E:\Project_python\2TestCMS2.0\common\requests_util.py", line 176, in analysis_yaml
    res = self.send_request(name =name,method=method,
  File "E:\Project_python\2TestCMS2.0\common\requests_util.py", line 304, in send_request
    error_log("发送请求异常：异常信息: %s" % str(traceback.format_exc()))
  File "E:\Project_python\2TestCMS2.0\common\logger_util.py", line 66, in error_log
    raise Exception(log_message)
Exception: 发送请求异常：异常信息: Traceback (most recent call last):
  File "E:\Project_python\2TestCMS2.0\common\requests_util.py", line 276, in send_request
    self.base_url = self.replace_load(self.base_url) + self.replace_load(url)
  File "E:\Project_python\2TestCMS2.0\common\requests_util.py", line 41, in replace_load
    new_value = getattr(DubugTalk(), func_name)(*args_value.split(','))
  File "E:\Project_python\2TestCMS2.0\debug_talk.py", line 20, in get_base_url
    return  read_config_file('base',node_name)
  File "E:\Project_python\2TestCMS2.0\common\yaml_util.py", line 13, in read_config_file
    return value[one_node][two_node]
KeyError: 'cms_url'


[2023-05-18 16:04:25,838] logger_util.py->error_log line:65 [INFO] 发送请求异常：异常信息: Traceback (most recent call last):
  File "E:\Project_python\2TestCMS2.0\common\requests_util.py", line 276, in send_request
    self.base_url = self.replace_load(self.base_url) + self.replace_load(url)
  File "E:\Project_python\2TestCMS2.0\common\requests_util.py", line 41, in replace_load
    new_value = getattr(DubugTalk(), func_name)(*args_value.split(','))
  File "E:\Project_python\2TestCMS2.0\debug_talk.py", line 20, in get_base_url
    return  read_config_file('base',node_name)
  File "E:\Project_python\2TestCMS2.0\common\yaml_util.py", line 13, in read_config_file
    return value[one_node][two_node]
KeyError: 'cms_url'

[2023-05-18 16:04:25,839] logger_util.py->error_log line:65 [INFO] 分析YAML文件异常：异常信息: Traceback (most recent call last):
  File "E:\Project_python\2TestCMS2.0\common\requests_util.py", line 276, in send_request
    self.base_url = self.replace_load(self.base_url) + self.replace_load(url)
  File "E:\Project_python\2TestCMS2.0\common\requests_util.py", line 41, in replace_load
    new_value = getattr(DubugTalk(), func_name)(*args_value.split(','))
  File "E:\Project_python\2TestCMS2.0\debug_talk.py", line 20, in get_base_url
    return  read_config_file('base',node_name)
  File "E:\Project_python\2TestCMS2.0\common\yaml_util.py", line 13, in read_config_file
    return value[one_node][two_node]
KeyError: 'cms_url'

During handling of the above exception, another exception occurred:

Traceback (most recent call last):
  File "E:\Project_python\2TestCMS2.0\common\requests_util.py", line 176, in analysis_yaml
    res = self.send_request(name =name,method=method,
  File "E:\Project_python\2TestCMS2.0\common\requests_util.py", line 304, in send_request
    error_log("发送请求异常：异常信息: %s" % str(traceback.format_exc()))
  File "E:\Project_python\2TestCMS2.0\common\logger_util.py", line 66, in error_log
    raise Exception(log_message)
Exception: 发送请求异常：异常信息: Traceback (most recent call last):
  File "E:\Project_python\2TestCMS2.0\common\requests_util.py", line 276, in send_request
    self.base_url = self.replace_load(self.base_url) + self.replace_load(url)
  File "E:\Project_python\2TestCMS2.0\common\requests_util.py", line 41, in replace_load
    new_value = getattr(DubugTalk(), func_name)(*args_value.split(','))
  File "E:\Project_python\2TestCMS2.0\debug_talk.py", line 20, in get_base_url
    return  read_config_file('base',node_name)
  File "E:\Project_python\2TestCMS2.0\common\yaml_util.py", line 13, in read_config_file
    return value[one_node][two_node]
KeyError: 'cms_url'


[2023-05-18 16:04:25,867] logger_util.py->error_log line:65 [INFO] 发送请求异常：异常信息: Traceback (most recent call last):
  File "E:\Project_python\2TestCMS2.0\common\requests_util.py", line 276, in send_request
    self.base_url = self.replace_load(self.base_url) + self.replace_load(url)
  File "E:\Project_python\2TestCMS2.0\common\requests_util.py", line 41, in replace_load
    new_value = getattr(DubugTalk(), func_name)(*args_value.split(','))
  File "E:\Project_python\2TestCMS2.0\debug_talk.py", line 20, in get_base_url
    return  read_config_file('base',node_name)
  File "E:\Project_python\2TestCMS2.0\common\yaml_util.py", line 13, in read_config_file
    return value[one_node][two_node]
KeyError: 'cms_url'

[2023-05-18 16:04:25,867] logger_util.py->error_log line:65 [INFO] 分析YAML文件异常：异常信息: Traceback (most recent call last):
  File "E:\Project_python\2TestCMS2.0\common\requests_util.py", line 276, in send_request
    self.base_url = self.replace_load(self.base_url) + self.replace_load(url)
  File "E:\Project_python\2TestCMS2.0\common\requests_util.py", line 41, in replace_load
    new_value = getattr(DubugTalk(), func_name)(*args_value.split(','))
  File "E:\Project_python\2TestCMS2.0\debug_talk.py", line 20, in get_base_url
    return  read_config_file('base',node_name)
  File "E:\Project_python\2TestCMS2.0\common\yaml_util.py", line 13, in read_config_file
    return value[one_node][two_node]
KeyError: 'cms_url'

During handling of the above exception, another exception occurred:

Traceback (most recent call last):
  File "E:\Project_python\2TestCMS2.0\common\requests_util.py", line 176, in analysis_yaml
    res = self.send_request(name =name,method=method,
  File "E:\Project_python\2TestCMS2.0\common\requests_util.py", line 304, in send_request
    error_log("发送请求异常：异常信息: %s" % str(traceback.format_exc()))
  File "E:\Project_python\2TestCMS2.0\common\logger_util.py", line 66, in error_log
    raise Exception(log_message)
Exception: 发送请求异常：异常信息: Traceback (most recent call last):
  File "E:\Project_python\2TestCMS2.0\common\requests_util.py", line 276, in send_request
    self.base_url = self.replace_load(self.base_url) + self.replace_load(url)
  File "E:\Project_python\2TestCMS2.0\common\requests_util.py", line 41, in replace_load
    new_value = getattr(DubugTalk(), func_name)(*args_value.split(','))
  File "E:\Project_python\2TestCMS2.0\debug_talk.py", line 20, in get_base_url
    return  read_config_file('base',node_name)
  File "E:\Project_python\2TestCMS2.0\common\yaml_util.py", line 13, in read_config_file
    return value[one_node][two_node]
KeyError: 'cms_url'


[2023-05-18 16:04:25,895] logger_util.py->error_log line:65 [INFO] 发送请求异常：异常信息: Traceback (most recent call last):
  File "E:\Project_python\2TestCMS2.0\common\requests_util.py", line 276, in send_request
    self.base_url = self.replace_load(self.base_url) + self.replace_load(url)
  File "E:\Project_python\2TestCMS2.0\common\requests_util.py", line 41, in replace_load
    new_value = getattr(DubugTalk(), func_name)(*args_value.split(','))
  File "E:\Project_python\2TestCMS2.0\debug_talk.py", line 20, in get_base_url
    return  read_config_file('base',node_name)
  File "E:\Project_python\2TestCMS2.0\common\yaml_util.py", line 13, in read_config_file
    return value[one_node][two_node]
KeyError: 'cms_url'

[2023-05-18 16:04:25,896] logger_util.py->error_log line:65 [INFO] 分析YAML文件异常：异常信息: Traceback (most recent call last):
  File "E:\Project_python\2TestCMS2.0\common\requests_util.py", line 276, in send_request
    self.base_url = self.replace_load(self.base_url) + self.replace_load(url)
  File "E:\Project_python\2TestCMS2.0\common\requests_util.py", line 41, in replace_load
    new_value = getattr(DubugTalk(), func_name)(*args_value.split(','))
  File "E:\Project_python\2TestCMS2.0\debug_talk.py", line 20, in get_base_url
    return  read_config_file('base',node_name)
  File "E:\Project_python\2TestCMS2.0\common\yaml_util.py", line 13, in read_config_file
    return value[one_node][two_node]
KeyError: 'cms_url'

During handling of the above exception, another exception occurred:

Traceback (most recent call last):
  File "E:\Project_python\2TestCMS2.0\common\requests_util.py", line 176, in analysis_yaml
    res = self.send_request(name =name,method=method,
  File "E:\Project_python\2TestCMS2.0\common\requests_util.py", line 304, in send_request
    error_log("发送请求异常：异常信息: %s" % str(traceback.format_exc()))
  File "E:\Project_python\2TestCMS2.0\common\logger_util.py", line 66, in error_log
    raise Exception(log_message)
Exception: 发送请求异常：异常信息: Traceback (most recent call last):
  File "E:\Project_python\2TestCMS2.0\common\requests_util.py", line 276, in send_request
    self.base_url = self.replace_load(self.base_url) + self.replace_load(url)
  File "E:\Project_python\2TestCMS2.0\common\requests_util.py", line 41, in replace_load
    new_value = getattr(DubugTalk(), func_name)(*args_value.split(','))
  File "E:\Project_python\2TestCMS2.0\debug_talk.py", line 20, in get_base_url
    return  read_config_file('base',node_name)
  File "E:\Project_python\2TestCMS2.0\common\yaml_util.py", line 13, in read_config_file
    return value[one_node][two_node]
KeyError: 'cms_url'


[2023-05-18 16:04:25,924] logger_util.py->error_log line:65 [INFO] 发送请求异常：异常信息: Traceback (most recent call last):
  File "E:\Project_python\2TestCMS2.0\common\requests_util.py", line 276, in send_request
    self.base_url = self.replace_load(self.base_url) + self.replace_load(url)
  File "E:\Project_python\2TestCMS2.0\common\requests_util.py", line 41, in replace_load
    new_value = getattr(DubugTalk(), func_name)(*args_value.split(','))
  File "E:\Project_python\2TestCMS2.0\debug_talk.py", line 20, in get_base_url
    return  read_config_file('base',node_name)
  File "E:\Project_python\2TestCMS2.0\common\yaml_util.py", line 13, in read_config_file
    return value[one_node][two_node]
KeyError: 'cms_url'

[2023-05-18 16:04:25,924] logger_util.py->error_log line:65 [INFO] 分析YAML文件异常：异常信息: Traceback (most recent call last):
  File "E:\Project_python\2TestCMS2.0\common\requests_util.py", line 276, in send_request
    self.base_url = self.replace_load(self.base_url) + self.replace_load(url)
  File "E:\Project_python\2TestCMS2.0\common\requests_util.py", line 41, in replace_load
    new_value = getattr(DubugTalk(), func_name)(*args_value.split(','))
  File "E:\Project_python\2TestCMS2.0\debug_talk.py", line 20, in get_base_url
    return  read_config_file('base',node_name)
  File "E:\Project_python\2TestCMS2.0\common\yaml_util.py", line 13, in read_config_file
    return value[one_node][two_node]
KeyError: 'cms_url'

During handling of the above exception, another exception occurred:

Traceback (most recent call last):
  File "E:\Project_python\2TestCMS2.0\common\requests_util.py", line 176, in analysis_yaml
    res = self.send_request(name =name,method=method,
  File "E:\Project_python\2TestCMS2.0\common\requests_util.py", line 304, in send_request
    error_log("发送请求异常：异常信息: %s" % str(traceback.format_exc()))
  File "E:\Project_python\2TestCMS2.0\common\logger_util.py", line 66, in error_log
    raise Exception(log_message)
Exception: 发送请求异常：异常信息: Traceback (most recent call last):
  File "E:\Project_python\2TestCMS2.0\common\requests_util.py", line 276, in send_request
    self.base_url = self.replace_load(self.base_url) + self.replace_load(url)
  File "E:\Project_python\2TestCMS2.0\common\requests_util.py", line 41, in replace_load
    new_value = getattr(DubugTalk(), func_name)(*args_value.split(','))
  File "E:\Project_python\2TestCMS2.0\debug_talk.py", line 20, in get_base_url
    return  read_config_file('base',node_name)
  File "E:\Project_python\2TestCMS2.0\common\yaml_util.py", line 13, in read_config_file
    return value[one_node][two_node]
KeyError: 'cms_url'


[2023-05-18 16:04:25,954] logger_util.py->error_log line:65 [INFO] 发送请求异常：异常信息: Traceback (most recent call last):
  File "E:\Project_python\2TestCMS2.0\common\requests_util.py", line 276, in send_request
    self.base_url = self.replace_load(self.base_url) + self.replace_load(url)
  File "E:\Project_python\2TestCMS2.0\common\requests_util.py", line 41, in replace_load
    new_value = getattr(DubugTalk(), func_name)(*args_value.split(','))
  File "E:\Project_python\2TestCMS2.0\debug_talk.py", line 20, in get_base_url
    return  read_config_file('base',node_name)
  File "E:\Project_python\2TestCMS2.0\common\yaml_util.py", line 13, in read_config_file
    return value[one_node][two_node]
KeyError: 'cms_url'

[2023-05-18 16:04:25,954] logger_util.py->error_log line:65 [INFO] 分析YAML文件异常：异常信息: Traceback (most recent call last):
  File "E:\Project_python\2TestCMS2.0\common\requests_util.py", line 276, in send_request
    self.base_url = self.replace_load(self.base_url) + self.replace_load(url)
  File "E:\Project_python\2TestCMS2.0\common\requests_util.py", line 41, in replace_load
    new_value = getattr(DubugTalk(), func_name)(*args_value.split(','))
  File "E:\Project_python\2TestCMS2.0\debug_talk.py", line 20, in get_base_url
    return  read_config_file('base',node_name)
  File "E:\Project_python\2TestCMS2.0\common\yaml_util.py", line 13, in read_config_file
    return value[one_node][two_node]
KeyError: 'cms_url'

During handling of the above exception, another exception occurred:

Traceback (most recent call last):
  File "E:\Project_python\2TestCMS2.0\common\requests_util.py", line 176, in analysis_yaml
    res = self.send_request(name =name,method=method,
  File "E:\Project_python\2TestCMS2.0\common\requests_util.py", line 304, in send_request
    error_log("发送请求异常：异常信息: %s" % str(traceback.format_exc()))
  File "E:\Project_python\2TestCMS2.0\common\logger_util.py", line 66, in error_log
    raise Exception(log_message)
Exception: 发送请求异常：异常信息: Traceback (most recent call last):
  File "E:\Project_python\2TestCMS2.0\common\requests_util.py", line 276, in send_request
    self.base_url = self.replace_load(self.base_url) + self.replace_load(url)
  File "E:\Project_python\2TestCMS2.0\common\requests_util.py", line 41, in replace_load
    new_value = getattr(DubugTalk(), func_name)(*args_value.split(','))
  File "E:\Project_python\2TestCMS2.0\debug_talk.py", line 20, in get_base_url
    return  read_config_file('base',node_name)
  File "E:\Project_python\2TestCMS2.0\common\yaml_util.py", line 13, in read_config_file
    return value[one_node][two_node]
KeyError: 'cms_url'


[2023-05-18 16:04:25,982] logger_util.py->error_log line:65 [INFO] 发送请求异常：异常信息: Traceback (most recent call last):
  File "E:\Project_python\2TestCMS2.0\common\requests_util.py", line 276, in send_request
    self.base_url = self.replace_load(self.base_url) + self.replace_load(url)
  File "E:\Project_python\2TestCMS2.0\common\requests_util.py", line 41, in replace_load
    new_value = getattr(DubugTalk(), func_name)(*args_value.split(','))
  File "E:\Project_python\2TestCMS2.0\debug_talk.py", line 20, in get_base_url
    return  read_config_file('base',node_name)
  File "E:\Project_python\2TestCMS2.0\common\yaml_util.py", line 13, in read_config_file
    return value[one_node][two_node]
KeyError: 'cms_url'

[2023-05-18 16:04:25,983] logger_util.py->error_log line:65 [INFO] 分析YAML文件异常：异常信息: Traceback (most recent call last):
  File "E:\Project_python\2TestCMS2.0\common\requests_util.py", line 276, in send_request
    self.base_url = self.replace_load(self.base_url) + self.replace_load(url)
  File "E:\Project_python\2TestCMS2.0\common\requests_util.py", line 41, in replace_load
    new_value = getattr(DubugTalk(), func_name)(*args_value.split(','))
  File "E:\Project_python\2TestCMS2.0\debug_talk.py", line 20, in get_base_url
    return  read_config_file('base',node_name)
  File "E:\Project_python\2TestCMS2.0\common\yaml_util.py", line 13, in read_config_file
    return value[one_node][two_node]
KeyError: 'cms_url'

During handling of the above exception, another exception occurred:

Traceback (most recent call last):
  File "E:\Project_python\2TestCMS2.0\common\requests_util.py", line 176, in analysis_yaml
    res = self.send_request(name =name,method=method,
  File "E:\Project_python\2TestCMS2.0\common\requests_util.py", line 304, in send_request
    error_log("发送请求异常：异常信息: %s" % str(traceback.format_exc()))
  File "E:\Project_python\2TestCMS2.0\common\logger_util.py", line 66, in error_log
    raise Exception(log_message)
Exception: 发送请求异常：异常信息: Traceback (most recent call last):
  File "E:\Project_python\2TestCMS2.0\common\requests_util.py", line 276, in send_request
    self.base_url = self.replace_load(self.base_url) + self.replace_load(url)
  File "E:\Project_python\2TestCMS2.0\common\requests_util.py", line 41, in replace_load
    new_value = getattr(DubugTalk(), func_name)(*args_value.split(','))
  File "E:\Project_python\2TestCMS2.0\debug_talk.py", line 20, in get_base_url
    return  read_config_file('base',node_name)
  File "E:\Project_python\2TestCMS2.0\common\yaml_util.py", line 13, in read_config_file
    return value[one_node][two_node]
KeyError: 'cms_url'


[2023-05-18 16:04:26,012] logger_util.py->error_log line:65 [INFO] 发送请求异常：异常信息: Traceback (most recent call last):
  File "E:\Project_python\2TestCMS2.0\common\requests_util.py", line 276, in send_request
    self.base_url = self.replace_load(self.base_url) + self.replace_load(url)
  File "E:\Project_python\2TestCMS2.0\common\requests_util.py", line 41, in replace_load
    new_value = getattr(DubugTalk(), func_name)(*args_value.split(','))
  File "E:\Project_python\2TestCMS2.0\debug_talk.py", line 20, in get_base_url
    return  read_config_file('base',node_name)
  File "E:\Project_python\2TestCMS2.0\common\yaml_util.py", line 13, in read_config_file
    return value[one_node][two_node]
KeyError: 'cms_url'

[2023-05-18 16:04:26,012] logger_util.py->error_log line:65 [INFO] 分析YAML文件异常：异常信息: Traceback (most recent call last):
  File "E:\Project_python\2TestCMS2.0\common\requests_util.py", line 276, in send_request
    self.base_url = self.replace_load(self.base_url) + self.replace_load(url)
  File "E:\Project_python\2TestCMS2.0\common\requests_util.py", line 41, in replace_load
    new_value = getattr(DubugTalk(), func_name)(*args_value.split(','))
  File "E:\Project_python\2TestCMS2.0\debug_talk.py", line 20, in get_base_url
    return  read_config_file('base',node_name)
  File "E:\Project_python\2TestCMS2.0\common\yaml_util.py", line 13, in read_config_file
    return value[one_node][two_node]
KeyError: 'cms_url'

During handling of the above exception, another exception occurred:

Traceback (most recent call last):
  File "E:\Project_python\2TestCMS2.0\common\requests_util.py", line 176, in analysis_yaml
    res = self.send_request(name =name,method=method,
  File "E:\Project_python\2TestCMS2.0\common\requests_util.py", line 304, in send_request
    error_log("发送请求异常：异常信息: %s" % str(traceback.format_exc()))
  File "E:\Project_python\2TestCMS2.0\common\logger_util.py", line 66, in error_log
    raise Exception(log_message)
Exception: 发送请求异常：异常信息: Traceback (most recent call last):
  File "E:\Project_python\2TestCMS2.0\common\requests_util.py", line 276, in send_request
    self.base_url = self.replace_load(self.base_url) + self.replace_load(url)
  File "E:\Project_python\2TestCMS2.0\common\requests_util.py", line 41, in replace_load
    new_value = getattr(DubugTalk(), func_name)(*args_value.split(','))
  File "E:\Project_python\2TestCMS2.0\debug_talk.py", line 20, in get_base_url
    return  read_config_file('base',node_name)
  File "E:\Project_python\2TestCMS2.0\common\yaml_util.py", line 13, in read_config_file
    return value[one_node][two_node]
KeyError: 'cms_url'


[2023-05-18 16:04:26,040] logger_util.py->error_log line:65 [INFO] 发送请求异常：异常信息: Traceback (most recent call last):
  File "E:\Project_python\2TestCMS2.0\common\requests_util.py", line 276, in send_request
    self.base_url = self.replace_load(self.base_url) + self.replace_load(url)
  File "E:\Project_python\2TestCMS2.0\common\requests_util.py", line 41, in replace_load
    new_value = getattr(DubugTalk(), func_name)(*args_value.split(','))
  File "E:\Project_python\2TestCMS2.0\debug_talk.py", line 20, in get_base_url
    return  read_config_file('base',node_name)
  File "E:\Project_python\2TestCMS2.0\common\yaml_util.py", line 13, in read_config_file
    return value[one_node][two_node]
KeyError: 'cms_url'

[2023-05-18 16:04:26,041] logger_util.py->error_log line:65 [INFO] 分析YAML文件异常：异常信息: Traceback (most recent call last):
  File "E:\Project_python\2TestCMS2.0\common\requests_util.py", line 276, in send_request
    self.base_url = self.replace_load(self.base_url) + self.replace_load(url)
  File "E:\Project_python\2TestCMS2.0\common\requests_util.py", line 41, in replace_load
    new_value = getattr(DubugTalk(), func_name)(*args_value.split(','))
  File "E:\Project_python\2TestCMS2.0\debug_talk.py", line 20, in get_base_url
    return  read_config_file('base',node_name)
  File "E:\Project_python\2TestCMS2.0\common\yaml_util.py", line 13, in read_config_file
    return value[one_node][two_node]
KeyError: 'cms_url'

During handling of the above exception, another exception occurred:

Traceback (most recent call last):
  File "E:\Project_python\2TestCMS2.0\common\requests_util.py", line 176, in analysis_yaml
    res = self.send_request(name =name,method=method,
  File "E:\Project_python\2TestCMS2.0\common\requests_util.py", line 304, in send_request
    error_log("发送请求异常：异常信息: %s" % str(traceback.format_exc()))
  File "E:\Project_python\2TestCMS2.0\common\logger_util.py", line 66, in error_log
    raise Exception(log_message)
Exception: 发送请求异常：异常信息: Traceback (most recent call last):
  File "E:\Project_python\2TestCMS2.0\common\requests_util.py", line 276, in send_request
    self.base_url = self.replace_load(self.base_url) + self.replace_load(url)
  File "E:\Project_python\2TestCMS2.0\common\requests_util.py", line 41, in replace_load
    new_value = getattr(DubugTalk(), func_name)(*args_value.split(','))
  File "E:\Project_python\2TestCMS2.0\debug_talk.py", line 20, in get_base_url
    return  read_config_file('base',node_name)
  File "E:\Project_python\2TestCMS2.0\common\yaml_util.py", line 13, in read_config_file
    return value[one_node][two_node]
KeyError: 'cms_url'


[2023-05-18 16:04:26,068] logger_util.py->error_log line:65 [INFO] 发送请求异常：异常信息: Traceback (most recent call last):
  File "E:\Project_python\2TestCMS2.0\common\requests_util.py", line 276, in send_request
    self.base_url = self.replace_load(self.base_url) + self.replace_load(url)
  File "E:\Project_python\2TestCMS2.0\common\requests_util.py", line 41, in replace_load
    new_value = getattr(DubugTalk(), func_name)(*args_value.split(','))
  File "E:\Project_python\2TestCMS2.0\debug_talk.py", line 20, in get_base_url
    return  read_config_file('base',node_name)
  File "E:\Project_python\2TestCMS2.0\common\yaml_util.py", line 13, in read_config_file
    return value[one_node][two_node]
KeyError: 'cms_url'

[2023-05-18 16:04:26,069] logger_util.py->error_log line:65 [INFO] 分析YAML文件异常：异常信息: Traceback (most recent call last):
  File "E:\Project_python\2TestCMS2.0\common\requests_util.py", line 276, in send_request
    self.base_url = self.replace_load(self.base_url) + self.replace_load(url)
  File "E:\Project_python\2TestCMS2.0\common\requests_util.py", line 41, in replace_load
    new_value = getattr(DubugTalk(), func_name)(*args_value.split(','))
  File "E:\Project_python\2TestCMS2.0\debug_talk.py", line 20, in get_base_url
    return  read_config_file('base',node_name)
  File "E:\Project_python\2TestCMS2.0\common\yaml_util.py", line 13, in read_config_file
    return value[one_node][two_node]
KeyError: 'cms_url'

During handling of the above exception, another exception occurred:

Traceback (most recent call last):
  File "E:\Project_python\2TestCMS2.0\common\requests_util.py", line 176, in analysis_yaml
    res = self.send_request(name =name,method=method,
  File "E:\Project_python\2TestCMS2.0\common\requests_util.py", line 304, in send_request
    error_log("发送请求异常：异常信息: %s" % str(traceback.format_exc()))
  File "E:\Project_python\2TestCMS2.0\common\logger_util.py", line 66, in error_log
    raise Exception(log_message)
Exception: 发送请求异常：异常信息: Traceback (most recent call last):
  File "E:\Project_python\2TestCMS2.0\common\requests_util.py", line 276, in send_request
    self.base_url = self.replace_load(self.base_url) + self.replace_load(url)
  File "E:\Project_python\2TestCMS2.0\common\requests_util.py", line 41, in replace_load
    new_value = getattr(DubugTalk(), func_name)(*args_value.split(','))
  File "E:\Project_python\2TestCMS2.0\debug_talk.py", line 20, in get_base_url
    return  read_config_file('base',node_name)
  File "E:\Project_python\2TestCMS2.0\common\yaml_util.py", line 13, in read_config_file
    return value[one_node][two_node]
KeyError: 'cms_url'


[2023-05-18 16:04:26,159] logger_util.py->error_log line:65 [INFO] 发送请求异常：异常信息: Traceback (most recent call last):
  File "E:\Project_python\2TestCMS2.0\common\requests_util.py", line 276, in send_request
    self.base_url = self.replace_load(self.base_url) + self.replace_load(url)
  File "E:\Project_python\2TestCMS2.0\common\requests_util.py", line 41, in replace_load
    new_value = getattr(DubugTalk(), func_name)(*args_value.split(','))
  File "E:\Project_python\2TestCMS2.0\debug_talk.py", line 20, in get_base_url
    return  read_config_file('base',node_name)
  File "E:\Project_python\2TestCMS2.0\common\yaml_util.py", line 13, in read_config_file
    return value[one_node][two_node]
KeyError: 'cms_url'

[2023-05-18 16:04:26,159] logger_util.py->error_log line:65 [INFO] 分析YAML文件异常：异常信息: Traceback (most recent call last):
  File "E:\Project_python\2TestCMS2.0\common\requests_util.py", line 276, in send_request
    self.base_url = self.replace_load(self.base_url) + self.replace_load(url)
  File "E:\Project_python\2TestCMS2.0\common\requests_util.py", line 41, in replace_load
    new_value = getattr(DubugTalk(), func_name)(*args_value.split(','))
  File "E:\Project_python\2TestCMS2.0\debug_talk.py", line 20, in get_base_url
    return  read_config_file('base',node_name)
  File "E:\Project_python\2TestCMS2.0\common\yaml_util.py", line 13, in read_config_file
    return value[one_node][two_node]
KeyError: 'cms_url'

During handling of the above exception, another exception occurred:

Traceback (most recent call last):
  File "E:\Project_python\2TestCMS2.0\common\requests_util.py", line 176, in analysis_yaml
    res = self.send_request(name =name,method=method,
  File "E:\Project_python\2TestCMS2.0\common\requests_util.py", line 304, in send_request
    error_log("发送请求异常：异常信息: %s" % str(traceback.format_exc()))
  File "E:\Project_python\2TestCMS2.0\common\logger_util.py", line 66, in error_log
    raise Exception(log_message)
Exception: 发送请求异常：异常信息: Traceback (most recent call last):
  File "E:\Project_python\2TestCMS2.0\common\requests_util.py", line 276, in send_request
    self.base_url = self.replace_load(self.base_url) + self.replace_load(url)
  File "E:\Project_python\2TestCMS2.0\common\requests_util.py", line 41, in replace_load
    new_value = getattr(DubugTalk(), func_name)(*args_value.split(','))
  File "E:\Project_python\2TestCMS2.0\debug_talk.py", line 20, in get_base_url
    return  read_config_file('base',node_name)
  File "E:\Project_python\2TestCMS2.0\common\yaml_util.py", line 13, in read_config_file
    return value[one_node][two_node]
KeyError: 'cms_url'


[2023-05-18 16:04:26,213] logger_util.py->error_log line:65 [INFO] 发送请求异常：异常信息: Traceback (most recent call last):
  File "E:\Project_python\2TestCMS2.0\common\requests_util.py", line 276, in send_request
    self.base_url = self.replace_load(self.base_url) + self.replace_load(url)
  File "E:\Project_python\2TestCMS2.0\common\requests_util.py", line 41, in replace_load
    new_value = getattr(DubugTalk(), func_name)(*args_value.split(','))
  File "E:\Project_python\2TestCMS2.0\debug_talk.py", line 20, in get_base_url
    return  read_config_file('base',node_name)
  File "E:\Project_python\2TestCMS2.0\common\yaml_util.py", line 13, in read_config_file
    return value[one_node][two_node]
KeyError: 'cms_url'

[2023-05-18 16:04:26,214] logger_util.py->error_log line:65 [INFO] 分析YAML文件异常：异常信息: Traceback (most recent call last):
  File "E:\Project_python\2TestCMS2.0\common\requests_util.py", line 276, in send_request
    self.base_url = self.replace_load(self.base_url) + self.replace_load(url)
  File "E:\Project_python\2TestCMS2.0\common\requests_util.py", line 41, in replace_load
    new_value = getattr(DubugTalk(), func_name)(*args_value.split(','))
  File "E:\Project_python\2TestCMS2.0\debug_talk.py", line 20, in get_base_url
    return  read_config_file('base',node_name)
  File "E:\Project_python\2TestCMS2.0\common\yaml_util.py", line 13, in read_config_file
    return value[one_node][two_node]
KeyError: 'cms_url'

During handling of the above exception, another exception occurred:

Traceback (most recent call last):
  File "E:\Project_python\2TestCMS2.0\common\requests_util.py", line 176, in analysis_yaml
    res = self.send_request(name =name,method=method,
  File "E:\Project_python\2TestCMS2.0\common\requests_util.py", line 304, in send_request
    error_log("发送请求异常：异常信息: %s" % str(traceback.format_exc()))
  File "E:\Project_python\2TestCMS2.0\common\logger_util.py", line 66, in error_log
    raise Exception(log_message)
Exception: 发送请求异常：异常信息: Traceback (most recent call last):
  File "E:\Project_python\2TestCMS2.0\common\requests_util.py", line 276, in send_request
    self.base_url = self.replace_load(self.base_url) + self.replace_load(url)
  File "E:\Project_python\2TestCMS2.0\common\requests_util.py", line 41, in replace_load
    new_value = getattr(DubugTalk(), func_name)(*args_value.split(','))
  File "E:\Project_python\2TestCMS2.0\debug_talk.py", line 20, in get_base_url
    return  read_config_file('base',node_name)
  File "E:\Project_python\2TestCMS2.0\common\yaml_util.py", line 13, in read_config_file
    return value[one_node][two_node]
KeyError: 'cms_url'


[2023-05-18 16:04:26,278] logger_util.py->error_log line:65 [INFO] 发送请求异常：异常信息: Traceback (most recent call last):
  File "E:\Project_python\2TestCMS2.0\common\requests_util.py", line 276, in send_request
    self.base_url = self.replace_load(self.base_url) + self.replace_load(url)
  File "E:\Project_python\2TestCMS2.0\common\requests_util.py", line 41, in replace_load
    new_value = getattr(DubugTalk(), func_name)(*args_value.split(','))
  File "E:\Project_python\2TestCMS2.0\debug_talk.py", line 20, in get_base_url
    return  read_config_file('base',node_name)
  File "E:\Project_python\2TestCMS2.0\common\yaml_util.py", line 13, in read_config_file
    return value[one_node][two_node]
KeyError: 'cms_url'

[2023-05-18 16:04:26,279] logger_util.py->error_log line:65 [INFO] 分析YAML文件异常：异常信息: Traceback (most recent call last):
  File "E:\Project_python\2TestCMS2.0\common\requests_util.py", line 276, in send_request
    self.base_url = self.replace_load(self.base_url) + self.replace_load(url)
  File "E:\Project_python\2TestCMS2.0\common\requests_util.py", line 41, in replace_load
    new_value = getattr(DubugTalk(), func_name)(*args_value.split(','))
  File "E:\Project_python\2TestCMS2.0\debug_talk.py", line 20, in get_base_url
    return  read_config_file('base',node_name)
  File "E:\Project_python\2TestCMS2.0\common\yaml_util.py", line 13, in read_config_file
    return value[one_node][two_node]
KeyError: 'cms_url'

During handling of the above exception, another exception occurred:

Traceback (most recent call last):
  File "E:\Project_python\2TestCMS2.0\common\requests_util.py", line 176, in analysis_yaml
    res = self.send_request(name =name,method=method,
  File "E:\Project_python\2TestCMS2.0\common\requests_util.py", line 304, in send_request
    error_log("发送请求异常：异常信息: %s" % str(traceback.format_exc()))
  File "E:\Project_python\2TestCMS2.0\common\logger_util.py", line 66, in error_log
    raise Exception(log_message)
Exception: 发送请求异常：异常信息: Traceback (most recent call last):
  File "E:\Project_python\2TestCMS2.0\common\requests_util.py", line 276, in send_request
    self.base_url = self.replace_load(self.base_url) + self.replace_load(url)
  File "E:\Project_python\2TestCMS2.0\common\requests_util.py", line 41, in replace_load
    new_value = getattr(DubugTalk(), func_name)(*args_value.split(','))
  File "E:\Project_python\2TestCMS2.0\debug_talk.py", line 20, in get_base_url
    return  read_config_file('base',node_name)
  File "E:\Project_python\2TestCMS2.0\common\yaml_util.py", line 13, in read_config_file
    return value[one_node][two_node]
KeyError: 'cms_url'


[2023-05-18 16:04:26,331] logger_util.py->error_log line:65 [INFO] 发送请求异常：异常信息: Traceback (most recent call last):
  File "E:\Project_python\2TestCMS2.0\common\requests_util.py", line 276, in send_request
    self.base_url = self.replace_load(self.base_url) + self.replace_load(url)
  File "E:\Project_python\2TestCMS2.0\common\requests_util.py", line 41, in replace_load
    new_value = getattr(DubugTalk(), func_name)(*args_value.split(','))
  File "E:\Project_python\2TestCMS2.0\debug_talk.py", line 20, in get_base_url
    return  read_config_file('base',node_name)
  File "E:\Project_python\2TestCMS2.0\common\yaml_util.py", line 13, in read_config_file
    return value[one_node][two_node]
KeyError: 'cms_url'

[2023-05-18 16:04:26,331] logger_util.py->error_log line:65 [INFO] 分析YAML文件异常：异常信息: Traceback (most recent call last):
  File "E:\Project_python\2TestCMS2.0\common\requests_util.py", line 276, in send_request
    self.base_url = self.replace_load(self.base_url) + self.replace_load(url)
  File "E:\Project_python\2TestCMS2.0\common\requests_util.py", line 41, in replace_load
    new_value = getattr(DubugTalk(), func_name)(*args_value.split(','))
  File "E:\Project_python\2TestCMS2.0\debug_talk.py", line 20, in get_base_url
    return  read_config_file('base',node_name)
  File "E:\Project_python\2TestCMS2.0\common\yaml_util.py", line 13, in read_config_file
    return value[one_node][two_node]
KeyError: 'cms_url'

During handling of the above exception, another exception occurred:

Traceback (most recent call last):
  File "E:\Project_python\2TestCMS2.0\common\requests_util.py", line 176, in analysis_yaml
    res = self.send_request(name =name,method=method,
  File "E:\Project_python\2TestCMS2.0\common\requests_util.py", line 304, in send_request
    error_log("发送请求异常：异常信息: %s" % str(traceback.format_exc()))
  File "E:\Project_python\2TestCMS2.0\common\logger_util.py", line 66, in error_log
    raise Exception(log_message)
Exception: 发送请求异常：异常信息: Traceback (most recent call last):
  File "E:\Project_python\2TestCMS2.0\common\requests_util.py", line 276, in send_request
    self.base_url = self.replace_load(self.base_url) + self.replace_load(url)
  File "E:\Project_python\2TestCMS2.0\common\requests_util.py", line 41, in replace_load
    new_value = getattr(DubugTalk(), func_name)(*args_value.split(','))
  File "E:\Project_python\2TestCMS2.0\debug_talk.py", line 20, in get_base_url
    return  read_config_file('base',node_name)
  File "E:\Project_python\2TestCMS2.0\common\yaml_util.py", line 13, in read_config_file
    return value[one_node][two_node]
KeyError: 'cms_url'


[2023-05-18 16:04:26,406] logger_util.py->error_log line:65 [INFO] 发送请求异常：异常信息: Traceback (most recent call last):
  File "E:\Project_python\2TestCMS2.0\common\requests_util.py", line 276, in send_request
    self.base_url = self.replace_load(self.base_url) + self.replace_load(url)
  File "E:\Project_python\2TestCMS2.0\common\requests_util.py", line 41, in replace_load
    new_value = getattr(DubugTalk(), func_name)(*args_value.split(','))
  File "E:\Project_python\2TestCMS2.0\debug_talk.py", line 20, in get_base_url
    return  read_config_file('base',node_name)
  File "E:\Project_python\2TestCMS2.0\common\yaml_util.py", line 13, in read_config_file
    return value[one_node][two_node]
KeyError: 'cms_url'

[2023-05-18 16:04:26,406] logger_util.py->error_log line:65 [INFO] 分析YAML文件异常：异常信息: Traceback (most recent call last):
  File "E:\Project_python\2TestCMS2.0\common\requests_util.py", line 276, in send_request
    self.base_url = self.replace_load(self.base_url) + self.replace_load(url)
  File "E:\Project_python\2TestCMS2.0\common\requests_util.py", line 41, in replace_load
    new_value = getattr(DubugTalk(), func_name)(*args_value.split(','))
  File "E:\Project_python\2TestCMS2.0\debug_talk.py", line 20, in get_base_url
    return  read_config_file('base',node_name)
  File "E:\Project_python\2TestCMS2.0\common\yaml_util.py", line 13, in read_config_file
    return value[one_node][two_node]
KeyError: 'cms_url'

During handling of the above exception, another exception occurred:

Traceback (most recent call last):
  File "E:\Project_python\2TestCMS2.0\common\requests_util.py", line 176, in analysis_yaml
    res = self.send_request(name =name,method=method,
  File "E:\Project_python\2TestCMS2.0\common\requests_util.py", line 304, in send_request
    error_log("发送请求异常：异常信息: %s" % str(traceback.format_exc()))
  File "E:\Project_python\2TestCMS2.0\common\logger_util.py", line 66, in error_log
    raise Exception(log_message)
Exception: 发送请求异常：异常信息: Traceback (most recent call last):
  File "E:\Project_python\2TestCMS2.0\common\requests_util.py", line 276, in send_request
    self.base_url = self.replace_load(self.base_url) + self.replace_load(url)
  File "E:\Project_python\2TestCMS2.0\common\requests_util.py", line 41, in replace_load
    new_value = getattr(DubugTalk(), func_name)(*args_value.split(','))
  File "E:\Project_python\2TestCMS2.0\debug_talk.py", line 20, in get_base_url
    return  read_config_file('base',node_name)
  File "E:\Project_python\2TestCMS2.0\common\yaml_util.py", line 13, in read_config_file
    return value[one_node][two_node]
KeyError: 'cms_url'


[2023-05-18 16:04:26,433] logger_util.py->error_log line:65 [INFO] 发送请求异常：异常信息: Traceback (most recent call last):
  File "E:\Project_python\2TestCMS2.0\common\requests_util.py", line 276, in send_request
    self.base_url = self.replace_load(self.base_url) + self.replace_load(url)
  File "E:\Project_python\2TestCMS2.0\common\requests_util.py", line 41, in replace_load
    new_value = getattr(DubugTalk(), func_name)(*args_value.split(','))
  File "E:\Project_python\2TestCMS2.0\debug_talk.py", line 20, in get_base_url
    return  read_config_file('base',node_name)
  File "E:\Project_python\2TestCMS2.0\common\yaml_util.py", line 13, in read_config_file
    return value[one_node][two_node]
KeyError: 'cms_url'

[2023-05-18 16:04:26,434] logger_util.py->error_log line:65 [INFO] 分析YAML文件异常：异常信息: Traceback (most recent call last):
  File "E:\Project_python\2TestCMS2.0\common\requests_util.py", line 276, in send_request
    self.base_url = self.replace_load(self.base_url) + self.replace_load(url)
  File "E:\Project_python\2TestCMS2.0\common\requests_util.py", line 41, in replace_load
    new_value = getattr(DubugTalk(), func_name)(*args_value.split(','))
  File "E:\Project_python\2TestCMS2.0\debug_talk.py", line 20, in get_base_url
    return  read_config_file('base',node_name)
  File "E:\Project_python\2TestCMS2.0\common\yaml_util.py", line 13, in read_config_file
    return value[one_node][two_node]
KeyError: 'cms_url'

During handling of the above exception, another exception occurred:

Traceback (most recent call last):
  File "E:\Project_python\2TestCMS2.0\common\requests_util.py", line 176, in analysis_yaml
    res = self.send_request(name =name,method=method,
  File "E:\Project_python\2TestCMS2.0\common\requests_util.py", line 304, in send_request
    error_log("发送请求异常：异常信息: %s" % str(traceback.format_exc()))
  File "E:\Project_python\2TestCMS2.0\common\logger_util.py", line 66, in error_log
    raise Exception(log_message)
Exception: 发送请求异常：异常信息: Traceback (most recent call last):
  File "E:\Project_python\2TestCMS2.0\common\requests_util.py", line 276, in send_request
    self.base_url = self.replace_load(self.base_url) + self.replace_load(url)
  File "E:\Project_python\2TestCMS2.0\common\requests_util.py", line 41, in replace_load
    new_value = getattr(DubugTalk(), func_name)(*args_value.split(','))
  File "E:\Project_python\2TestCMS2.0\debug_talk.py", line 20, in get_base_url
    return  read_config_file('base',node_name)
  File "E:\Project_python\2TestCMS2.0\common\yaml_util.py", line 13, in read_config_file
    return value[one_node][two_node]
KeyError: 'cms_url'


[2023-05-18 16:04:26,461] logger_util.py->error_log line:65 [INFO] 发送请求异常：异常信息: Traceback (most recent call last):
  File "E:\Project_python\2TestCMS2.0\common\requests_util.py", line 276, in send_request
    self.base_url = self.replace_load(self.base_url) + self.replace_load(url)
  File "E:\Project_python\2TestCMS2.0\common\requests_util.py", line 41, in replace_load
    new_value = getattr(DubugTalk(), func_name)(*args_value.split(','))
  File "E:\Project_python\2TestCMS2.0\debug_talk.py", line 20, in get_base_url
    return  read_config_file('base',node_name)
  File "E:\Project_python\2TestCMS2.0\common\yaml_util.py", line 13, in read_config_file
    return value[one_node][two_node]
KeyError: 'cms_url'

[2023-05-18 16:04:26,461] logger_util.py->error_log line:65 [INFO] 分析YAML文件异常：异常信息: Traceback (most recent call last):
  File "E:\Project_python\2TestCMS2.0\common\requests_util.py", line 276, in send_request
    self.base_url = self.replace_load(self.base_url) + self.replace_load(url)
  File "E:\Project_python\2TestCMS2.0\common\requests_util.py", line 41, in replace_load
    new_value = getattr(DubugTalk(), func_name)(*args_value.split(','))
  File "E:\Project_python\2TestCMS2.0\debug_talk.py", line 20, in get_base_url
    return  read_config_file('base',node_name)
  File "E:\Project_python\2TestCMS2.0\common\yaml_util.py", line 13, in read_config_file
    return value[one_node][two_node]
KeyError: 'cms_url'

During handling of the above exception, another exception occurred:

Traceback (most recent call last):
  File "E:\Project_python\2TestCMS2.0\common\requests_util.py", line 176, in analysis_yaml
    res = self.send_request(name =name,method=method,
  File "E:\Project_python\2TestCMS2.0\common\requests_util.py", line 304, in send_request
    error_log("发送请求异常：异常信息: %s" % str(traceback.format_exc()))
  File "E:\Project_python\2TestCMS2.0\common\logger_util.py", line 66, in error_log
    raise Exception(log_message)
Exception: 发送请求异常：异常信息: Traceback (most recent call last):
  File "E:\Project_python\2TestCMS2.0\common\requests_util.py", line 276, in send_request
    self.base_url = self.replace_load(self.base_url) + self.replace_load(url)
  File "E:\Project_python\2TestCMS2.0\common\requests_util.py", line 41, in replace_load
    new_value = getattr(DubugTalk(), func_name)(*args_value.split(','))
  File "E:\Project_python\2TestCMS2.0\debug_talk.py", line 20, in get_base_url
    return  read_config_file('base',node_name)
  File "E:\Project_python\2TestCMS2.0\common\yaml_util.py", line 13, in read_config_file
    return value[one_node][two_node]
KeyError: 'cms_url'


