[2023-08-22 16:24:16,377] logger_util.py->write_log line:61 [INFO] 
-------------接口请求开始-----------
[2023-08-22 16:24:16,377] logger_util.py->write_log line:61 [INFO] 接口名称：创建通道设备IP为空
[2023-08-22 16:24:16,377] logger_util.py->write_log line:61 [INFO] 接口方式：post
[2023-08-22 16:24:16,377] logger_util.py->write_log line:61 [INFO] 接口路径：http://127.0.0.1:18000/api/v1/variable/tunnel
[2023-08-22 16:24:16,377] logger_util.py->write_log line:61 [INFO] 请求头：{}
[2023-08-22 16:24:16,378] logger_util.py->write_log line:61 [INFO] 请求参数：{'parentId': None, 'type': 1, 'name': '通道5056', 'description': '', 'config': {'suppiler': 'ModBus', 'model': 'Modbus_TCP', 'protocol': 'Modbus_TCP', 'parameters': {'ServerName': '', 'DeviceID': '1', 'Port': '502', 'HeadAddress': '1', 'ConnectTimeOut': '502', 'ResponseTimeout': '502', 'Int32ByteOrder': '2143', 'Int64ByteOrder': '2143', 'UInt32ByteOrder': '2143', 'UInt64ByteOrder': '2143', 'F32ByteOrder': '3412', 'F64ByteOrder': '2143', 'StrByteOrder': '2143', 'EnableIndependentLink': '禁用', 'EnablePduDiagnosis': '启用', 'PduLength': '502'}}, 'copyConfig': None}
[2023-08-22 16:24:16,379] logger_util.py->write_log line:61 [INFO] 文件上传：None
[2023-08-22 16:24:16,395] logger_util.py->write_log line:61 [INFO] 预期结果：[{'equals': {'status_code': 400}}]
[2023-08-22 16:24:16,395] logger_util.py->write_log line:61 [INFO] 实际结果：通道配置错误：驱动配置中设备IP不能为空
[2023-08-22 16:24:16,396] logger_util.py->write_log line:61 [INFO] 接口请求成功！
[2023-08-22 16:24:16,396] logger_util.py->write_log line:61 [INFO] 
-------------接口请求结束-----------

[2023-08-22 16:24:16,400] logger_util.py->write_log line:61 [INFO] 
-------------接口请求开始-----------
[2023-08-22 16:24:16,401] logger_util.py->write_log line:61 [INFO] 接口名称：创建通道设备IP非法
[2023-08-22 16:24:16,401] logger_util.py->write_log line:61 [INFO] 接口方式：post
[2023-08-22 16:24:16,401] logger_util.py->write_log line:61 [INFO] 接口路径：http://127.0.0.1:18000/api/v1/variable/tunnel
[2023-08-22 16:24:16,401] logger_util.py->write_log line:61 [INFO] 请求头：{}
[2023-08-22 16:24:16,401] logger_util.py->write_log line:61 [INFO] 请求参数：{'parentId': None, 'type': 1, 'name': '通道8705', 'description': '', 'config': {'suppiler': 'ModBus', 'model': 'Modbus_TCP', 'protocol': 'Modbus_TCP', 'parameters': {'ServerName': 'abc', 'DeviceID': '1', 'Port': '502', 'HeadAddress': '1', 'ConnectTimeOut': '502', 'ResponseTimeout': '502', 'Int32ByteOrder': '2143', 'Int64ByteOrder': '2143', 'UInt32ByteOrder': '2143', 'UInt64ByteOrder': '2143', 'F32ByteOrder': '3412', 'F64ByteOrder': '2143', 'StrByteOrder': '2143', 'EnableIndependentLink': '禁用', 'EnablePduDiagnosis': '启用', 'PduLength': '502'}}, 'copyConfig': None}
[2023-08-22 16:24:16,401] logger_util.py->write_log line:61 [INFO] 文件上传：None
[2023-08-22 16:24:16,407] logger_util.py->write_log line:61 [INFO] 预期结果：[{'equals': {'status_code': 400}}]
[2023-08-22 16:24:16,407] logger_util.py->write_log line:61 [INFO] 实际结果：通道配置错误：驱动配置中设备IP<abc>不正确
[2023-08-22 16:24:16,407] logger_util.py->write_log line:61 [INFO] 接口请求成功！
[2023-08-22 16:24:16,407] logger_util.py->write_log line:61 [INFO] 
-------------接口请求结束-----------

[2023-08-22 16:24:16,412] logger_util.py->write_log line:61 [INFO] 
-------------接口请求开始-----------
[2023-08-22 16:24:16,412] logger_util.py->write_log line:61 [INFO] 接口名称：创建通道设备ID为空
[2023-08-22 16:24:16,412] logger_util.py->write_log line:61 [INFO] 接口方式：post
[2023-08-22 16:24:16,412] logger_util.py->write_log line:61 [INFO] 接口路径：http://127.0.0.1:18000/api/v1/variable/tunnel
[2023-08-22 16:24:16,412] logger_util.py->write_log line:61 [INFO] 请求头：{}
[2023-08-22 16:24:16,412] logger_util.py->write_log line:61 [INFO] 请求参数：{'parentId': None, 'type': 1, 'name': '通道5679', 'description': '', 'config': {'suppiler': 'ModBus', 'model': 'Modbus_TCP', 'protocol': 'Modbus_TCP', 'parameters': {'ServerName': '127.0.0.1', 'DeviceID': '', 'Port': '502', 'HeadAddress': '1', 'ConnectTimeOut': '502', 'ResponseTimeout': '502', 'Int32ByteOrder': '2143', 'Int64ByteOrder': '2143', 'UInt32ByteOrder': '2143', 'UInt64ByteOrder': '2143', 'F32ByteOrder': '3412', 'F64ByteOrder': '2143', 'StrByteOrder': '2143', 'EnableIndependentLink': '禁用', 'EnablePduDiagnosis': '启用', 'PduLength': '502'}}, 'copyConfig': None}
[2023-08-22 16:24:16,412] logger_util.py->write_log line:61 [INFO] 文件上传：None
[2023-08-22 16:24:16,418] logger_util.py->write_log line:61 [INFO] 预期结果：[{'equals': {'status_code': 400}}]
[2023-08-22 16:24:16,418] logger_util.py->write_log line:61 [INFO] 实际结果：通道配置错误：驱动配置中设备ID不能为空
[2023-08-22 16:24:16,418] logger_util.py->write_log line:61 [INFO] 接口请求成功！
[2023-08-22 16:24:16,418] logger_util.py->write_log line:61 [INFO] 
-------------接口请求结束-----------

[2023-08-22 16:24:16,423] logger_util.py->write_log line:61 [INFO] 
-------------接口请求开始-----------
[2023-08-22 16:24:16,423] logger_util.py->write_log line:61 [INFO] 接口名称：创建通道设备ID非法
[2023-08-22 16:24:16,423] logger_util.py->write_log line:61 [INFO] 接口方式：post
[2023-08-22 16:24:16,423] logger_util.py->write_log line:61 [INFO] 接口路径：http://127.0.0.1:18000/api/v1/variable/tunnel
[2023-08-22 16:24:16,423] logger_util.py->write_log line:61 [INFO] 请求头：{}
[2023-08-22 16:24:16,423] logger_util.py->write_log line:61 [INFO] 请求参数：{'parentId': None, 'type': 1, 'name': '通道6705', 'description': '', 'config': {'suppiler': 'ModBus', 'model': 'Modbus_TCP', 'protocol': 'Modbus_TCP', 'parameters': {'ServerName': '127.0.0.1', 'DeviceID': 'abc', 'Port': '502', 'HeadAddress': '1', 'ConnectTimeOut': '502', 'ResponseTimeout': '502', 'Int32ByteOrder': '2143', 'Int64ByteOrder': '2143', 'UInt32ByteOrder': '2143', 'UInt64ByteOrder': '2143', 'F32ByteOrder': '3412', 'F64ByteOrder': '2143', 'StrByteOrder': '2143', 'EnableIndependentLink': '禁用', 'EnablePduDiagnosis': '启用', 'PduLength': '502'}}, 'copyConfig': None}
[2023-08-22 16:24:16,423] logger_util.py->write_log line:61 [INFO] 文件上传：None
[2023-08-22 16:24:16,429] logger_util.py->write_log line:61 [INFO] 预期结果：[{'equals': {'status_code': 400}}]
[2023-08-22 16:24:16,429] logger_util.py->write_log line:61 [INFO] 实际结果：通道名称不能重复
[2023-08-22 16:24:16,429] logger_util.py->write_log line:61 [INFO] 接口请求成功！
[2023-08-22 16:24:16,429] logger_util.py->write_log line:61 [INFO] 
-------------接口请求结束-----------

[2023-08-22 16:24:16,434] logger_util.py->write_log line:61 [INFO] 
-------------接口请求开始-----------
[2023-08-22 16:24:16,434] logger_util.py->write_log line:61 [INFO] 接口名称：创建通道端口号为空
[2023-08-22 16:24:16,435] logger_util.py->write_log line:61 [INFO] 接口方式：post
[2023-08-22 16:24:16,435] logger_util.py->write_log line:61 [INFO] 接口路径：http://127.0.0.1:18000/api/v1/variable/tunnel
[2023-08-22 16:24:16,435] logger_util.py->write_log line:61 [INFO] 请求头：{}
[2023-08-22 16:24:16,435] logger_util.py->write_log line:61 [INFO] 请求参数：{'parentId': None, 'type': 1, 'name': '通道3003', 'description': '', 'config': {'suppiler': 'ModBus', 'model': 'Modbus_TCP', 'protocol': 'Modbus_TCP', 'parameters': {'ServerName': '127.0.0.1', 'DeviceID': '1', 'Port': '', 'HeadAddress': '1', 'ConnectTimeOut': '', 'ResponseTimeout': '', 'Int32ByteOrder': '2143', 'Int64ByteOrder': '2143', 'UInt32ByteOrder': '2143', 'UInt64ByteOrder': '2143', 'F32ByteOrder': '3412', 'F64ByteOrder': '2143', 'StrByteOrder': '2143', 'EnableIndependentLink': '禁用', 'EnablePduDiagnosis': '启用', 'PduLength': ''}}, 'copyConfig': None}
[2023-08-22 16:24:16,435] logger_util.py->write_log line:61 [INFO] 文件上传：None
[2023-08-22 16:24:16,441] logger_util.py->write_log line:61 [INFO] 预期结果：[{'equals': {'status_code': 400}}]
[2023-08-22 16:24:16,441] logger_util.py->write_log line:61 [INFO] 实际结果：通道配置错误：驱动配置中端口号不能为空
[2023-08-22 16:24:16,441] logger_util.py->write_log line:61 [INFO] 接口请求成功！
[2023-08-22 16:24:16,441] logger_util.py->write_log line:61 [INFO] 
-------------接口请求结束-----------

[2023-08-22 16:24:16,445] logger_util.py->write_log line:61 [INFO] 
-------------接口请求开始-----------
[2023-08-22 16:24:16,445] logger_util.py->write_log line:61 [INFO] 接口名称：创建通道端口号非法
[2023-08-22 16:24:16,446] logger_util.py->write_log line:61 [INFO] 接口方式：post
[2023-08-22 16:24:16,446] logger_util.py->write_log line:61 [INFO] 接口路径：http://127.0.0.1:18000/api/v1/variable/tunnel
[2023-08-22 16:24:16,446] logger_util.py->write_log line:61 [INFO] 请求头：{}
[2023-08-22 16:24:16,446] logger_util.py->write_log line:61 [INFO] 请求参数：{'parentId': None, 'type': 1, 'name': '通道3907', 'description': '', 'config': {'suppiler': 'ModBus', 'model': 'Modbus_TCP', 'protocol': 'Modbus_TCP', 'parameters': {'ServerName': '127.0.0.1', 'DeviceID': '1', 'Port': 'abc', 'HeadAddress': '1', 'ConnectTimeOut': 'abc', 'ResponseTimeout': 'abc', 'Int32ByteOrder': '2143', 'Int64ByteOrder': '2143', 'UInt32ByteOrder': '2143', 'UInt64ByteOrder': '2143', 'F32ByteOrder': '3412', 'F64ByteOrder': '2143', 'StrByteOrder': '2143', 'EnableIndependentLink': '禁用', 'EnablePduDiagnosis': '启用', 'PduLength': 'abc'}}, 'copyConfig': None}
[2023-08-22 16:24:16,446] logger_util.py->write_log line:61 [INFO] 文件上传：None
[2023-08-22 16:24:16,451] logger_util.py->write_log line:61 [INFO] 预期结果：[{'equals': {'status_code': 400}}]
[2023-08-22 16:24:16,452] logger_util.py->write_log line:61 [INFO] 实际结果：通道配置错误：驱动配置中端口号<abc>不正确
[2023-08-22 16:24:16,452] logger_util.py->write_log line:61 [INFO] 接口请求成功！
[2023-08-22 16:24:16,452] logger_util.py->write_log line:61 [INFO] 
-------------接口请求结束-----------

[2023-08-22 16:24:16,456] logger_util.py->write_log line:61 [INFO] 
-------------接口请求开始-----------
[2023-08-22 16:24:16,456] logger_util.py->write_log line:61 [INFO] 接口名称：创建通道连接超时为空
[2023-08-22 16:24:16,456] logger_util.py->write_log line:61 [INFO] 接口方式：post
[2023-08-22 16:24:16,457] logger_util.py->write_log line:61 [INFO] 接口路径：http://127.0.0.1:18000/api/v1/variable/tunnel
[2023-08-22 16:24:16,457] logger_util.py->write_log line:61 [INFO] 请求头：{}
[2023-08-22 16:24:16,457] logger_util.py->write_log line:61 [INFO] 请求参数：{'parentId': None, 'type': 1, 'name': '通道6688', 'description': '', 'config': {'suppiler': 'ModBus', 'model': 'Modbus_TCP', 'protocol': 'Modbus_TCP', 'parameters': {'ServerName': '127.0.0.1', 'DeviceID': '1', 'Port': '502', 'HeadAddress': '1', 'ConnectTimeOut': '502', 'ResponseTimeout': '502', 'Int32ByteOrder': '2143', 'Int64ByteOrder': '2143', 'UInt32ByteOrder': '2143', 'UInt64ByteOrder': '2143', 'F32ByteOrder': '3412', 'F64ByteOrder': '2143', 'StrByteOrder': '2143', 'EnableIndependentLink': '禁用', 'EnablePduDiagnosis': '启用', 'PduLength': '502'}}, 'copyConfig': None}
[2023-08-22 16:24:16,457] logger_util.py->write_log line:61 [INFO] 文件上传：None
[2023-08-22 16:24:16,478] logger_util.py->error_log line:65 [INFO] 断言失败:status_code不等于400
[2023-08-22 16:24:16,478] logger_util.py->write_log line:61 [INFO] 接口请求失败！
[2023-08-22 16:24:16,478] logger_util.py->write_log line:61 [INFO] -------------接口请求结束-----------

[2023-08-22 16:24:16,479] logger_util.py->error_log line:65 [INFO] 断言异常：异常信息: Traceback (most recent call last):
  File "E:\Project_python\api_cms\common\requests_util.py", line 347, in validate_result
    error_log("断言失败:"+assert_key+"不等于"+str(assert_value))
  File "E:\Project_python\api_cms\common\logger_util.py", line 66, in error_log
    raise Exception(log_message)
Exception: 断言失败:status_code不等于400

[2023-08-22 16:24:16,479] logger_util.py->error_log line:65 [INFO] 分析YAML文件异常：异常信息: Traceback (most recent call last):
  File "E:\Project_python\api_cms\common\requests_util.py", line 347, in validate_result
    error_log("断言失败:"+assert_key+"不等于"+str(assert_value))
  File "E:\Project_python\api_cms\common\logger_util.py", line 66, in error_log
    raise Exception(log_message)
Exception: 断言失败:status_code不等于400

During handling of the above exception, another exception occurred:

Traceback (most recent call last):
  File "E:\Project_python\api_cms\common\requests_util.py", line 232, in analysis_yaml
    self.validate_result(yq_result, return_data, status_code)
  File "E:\Project_python\api_cms\common\requests_util.py", line 401, in validate_result
    error_log("断言异常：异常信息: %s" % str(traceback.format_exc()))
  File "E:\Project_python\api_cms\common\logger_util.py", line 66, in error_log
    raise Exception(log_message)
Exception: 断言异常：异常信息: Traceback (most recent call last):
  File "E:\Project_python\api_cms\common\requests_util.py", line 347, in validate_result
    error_log("断言失败:"+assert_key+"不等于"+str(assert_value))
  File "E:\Project_python\api_cms\common\logger_util.py", line 66, in error_log
    raise Exception(log_message)
Exception: 断言失败:status_code不等于400


[2023-08-22 16:24:16,585] logger_util.py->write_log line:61 [INFO] 
-------------接口请求开始-----------
[2023-08-22 16:24:16,585] logger_util.py->write_log line:61 [INFO] 接口名称：创建通道连接超时非法
[2023-08-22 16:24:16,585] logger_util.py->write_log line:61 [INFO] 接口方式：post
[2023-08-22 16:24:16,585] logger_util.py->write_log line:61 [INFO] 接口路径：http://127.0.0.1:18000/api/v1/variable/tunnel
[2023-08-22 16:24:16,585] logger_util.py->write_log line:61 [INFO] 请求头：{}
[2023-08-22 16:24:16,586] logger_util.py->write_log line:61 [INFO] 请求参数：{'parentId': None, 'type': 1, 'name': '通道2697', 'description': '', 'config': {'suppiler': 'ModBus', 'model': 'Modbus_TCP', 'protocol': 'Modbus_TCP', 'parameters': {'ServerName': '127.0.0.1', 'DeviceID': '1', 'Port': '502', 'HeadAddress': '1', 'ConnectTimeOut': '502', 'ResponseTimeout': '502', 'Int32ByteOrder': '2143', 'Int64ByteOrder': '2143', 'UInt32ByteOrder': '2143', 'UInt64ByteOrder': '2143', 'F32ByteOrder': '3412', 'F64ByteOrder': '2143', 'StrByteOrder': '2143', 'EnableIndependentLink': '禁用', 'EnablePduDiagnosis': '启用', 'PduLength': '502'}}, 'copyConfig': None}
[2023-08-22 16:24:16,586] logger_util.py->write_log line:61 [INFO] 文件上传：None
[2023-08-22 16:24:16,604] logger_util.py->error_log line:65 [INFO] 断言失败:status_code不等于400
[2023-08-22 16:24:16,605] logger_util.py->write_log line:61 [INFO] 接口请求失败！
[2023-08-22 16:24:16,605] logger_util.py->write_log line:61 [INFO] -------------接口请求结束-----------

[2023-08-22 16:24:16,605] logger_util.py->error_log line:65 [INFO] 断言异常：异常信息: Traceback (most recent call last):
  File "E:\Project_python\api_cms\common\requests_util.py", line 347, in validate_result
    error_log("断言失败:"+assert_key+"不等于"+str(assert_value))
  File "E:\Project_python\api_cms\common\logger_util.py", line 66, in error_log
    raise Exception(log_message)
Exception: 断言失败:status_code不等于400

[2023-08-22 16:24:16,605] logger_util.py->error_log line:65 [INFO] 分析YAML文件异常：异常信息: Traceback (most recent call last):
  File "E:\Project_python\api_cms\common\requests_util.py", line 347, in validate_result
    error_log("断言失败:"+assert_key+"不等于"+str(assert_value))
  File "E:\Project_python\api_cms\common\logger_util.py", line 66, in error_log
    raise Exception(log_message)
Exception: 断言失败:status_code不等于400

During handling of the above exception, another exception occurred:

Traceback (most recent call last):
  File "E:\Project_python\api_cms\common\requests_util.py", line 232, in analysis_yaml
    self.validate_result(yq_result, return_data, status_code)
  File "E:\Project_python\api_cms\common\requests_util.py", line 401, in validate_result
    error_log("断言异常：异常信息: %s" % str(traceback.format_exc()))
  File "E:\Project_python\api_cms\common\logger_util.py", line 66, in error_log
    raise Exception(log_message)
Exception: 断言异常：异常信息: Traceback (most recent call last):
  File "E:\Project_python\api_cms\common\requests_util.py", line 347, in validate_result
    error_log("断言失败:"+assert_key+"不等于"+str(assert_value))
  File "E:\Project_python\api_cms\common\logger_util.py", line 66, in error_log
    raise Exception(log_message)
Exception: 断言失败:status_code不等于400


[2023-08-22 16:24:16,630] logger_util.py->write_log line:61 [INFO] 
-------------接口请求开始-----------
[2023-08-22 16:24:16,630] logger_util.py->write_log line:61 [INFO] 接口名称：创建通道响应超时为空
[2023-08-22 16:24:16,630] logger_util.py->write_log line:61 [INFO] 接口方式：post
[2023-08-22 16:24:16,631] logger_util.py->write_log line:61 [INFO] 接口路径：http://127.0.0.1:18000/api/v1/variable/tunnel
[2023-08-22 16:24:16,631] logger_util.py->write_log line:61 [INFO] 请求头：{}
[2023-08-22 16:24:16,631] logger_util.py->write_log line:61 [INFO] 请求参数：{'parentId': None, 'type': 1, 'name': '通道9051', 'description': '', 'config': {'suppiler': 'ModBus', 'model': 'Modbus_TCP', 'protocol': 'Modbus_TCP', 'parameters': {'ServerName': '127.0.0.1', 'DeviceID': '1', 'Port': '502', 'HeadAddress': '1', 'ConnectTimeOut': '502', 'ResponseTimeout': '502', 'Int32ByteOrder': '2143', 'Int64ByteOrder': '2143', 'UInt32ByteOrder': '2143', 'UInt64ByteOrder': '2143', 'F32ByteOrder': '3412', 'F64ByteOrder': '2143', 'StrByteOrder': '2143', 'EnableIndependentLink': '禁用', 'EnablePduDiagnosis': '启用', 'PduLength': '502'}}, 'copyConfig': None}
[2023-08-22 16:24:16,631] logger_util.py->write_log line:61 [INFO] 文件上传：None
[2023-08-22 16:24:16,650] logger_util.py->error_log line:65 [INFO] 断言失败:status_code不等于400
[2023-08-22 16:24:16,650] logger_util.py->write_log line:61 [INFO] 接口请求失败！
[2023-08-22 16:24:16,650] logger_util.py->write_log line:61 [INFO] -------------接口请求结束-----------

[2023-08-22 16:24:16,650] logger_util.py->error_log line:65 [INFO] 断言异常：异常信息: Traceback (most recent call last):
  File "E:\Project_python\api_cms\common\requests_util.py", line 347, in validate_result
    error_log("断言失败:"+assert_key+"不等于"+str(assert_value))
  File "E:\Project_python\api_cms\common\logger_util.py", line 66, in error_log
    raise Exception(log_message)
Exception: 断言失败:status_code不等于400

[2023-08-22 16:24:16,651] logger_util.py->error_log line:65 [INFO] 分析YAML文件异常：异常信息: Traceback (most recent call last):
  File "E:\Project_python\api_cms\common\requests_util.py", line 347, in validate_result
    error_log("断言失败:"+assert_key+"不等于"+str(assert_value))
  File "E:\Project_python\api_cms\common\logger_util.py", line 66, in error_log
    raise Exception(log_message)
Exception: 断言失败:status_code不等于400

During handling of the above exception, another exception occurred:

Traceback (most recent call last):
  File "E:\Project_python\api_cms\common\requests_util.py", line 232, in analysis_yaml
    self.validate_result(yq_result, return_data, status_code)
  File "E:\Project_python\api_cms\common\requests_util.py", line 401, in validate_result
    error_log("断言异常：异常信息: %s" % str(traceback.format_exc()))
  File "E:\Project_python\api_cms\common\logger_util.py", line 66, in error_log
    raise Exception(log_message)
Exception: 断言异常：异常信息: Traceback (most recent call last):
  File "E:\Project_python\api_cms\common\requests_util.py", line 347, in validate_result
    error_log("断言失败:"+assert_key+"不等于"+str(assert_value))
  File "E:\Project_python\api_cms\common\logger_util.py", line 66, in error_log
    raise Exception(log_message)
Exception: 断言失败:status_code不等于400


[2023-08-22 16:24:16,675] logger_util.py->write_log line:61 [INFO] 
-------------接口请求开始-----------
[2023-08-22 16:24:16,675] logger_util.py->write_log line:61 [INFO] 接口名称：创建通道响应超时非法
[2023-08-22 16:24:16,675] logger_util.py->write_log line:61 [INFO] 接口方式：post
[2023-08-22 16:24:16,675] logger_util.py->write_log line:61 [INFO] 接口路径：http://127.0.0.1:18000/api/v1/variable/tunnel
[2023-08-22 16:24:16,676] logger_util.py->write_log line:61 [INFO] 请求头：{}
[2023-08-22 16:24:16,676] logger_util.py->write_log line:61 [INFO] 请求参数：{'parentId': None, 'type': 1, 'name': '通道7506', 'description': '', 'config': {'suppiler': 'ModBus', 'model': 'Modbus_TCP', 'protocol': 'Modbus_TCP', 'parameters': {'ServerName': '127.0.0.1', 'DeviceID': '1', 'Port': '502', 'HeadAddress': '1', 'ConnectTimeOut': '502', 'ResponseTimeout': '502', 'Int32ByteOrder': '2143', 'Int64ByteOrder': '2143', 'UInt32ByteOrder': '2143', 'UInt64ByteOrder': '2143', 'F32ByteOrder': '3412', 'F64ByteOrder': '2143', 'StrByteOrder': '2143', 'EnableIndependentLink': '禁用', 'EnablePduDiagnosis': '启用', 'PduLength': '502'}}, 'copyConfig': None}
[2023-08-22 16:24:16,676] logger_util.py->write_log line:61 [INFO] 文件上传：None
[2023-08-22 16:24:16,695] logger_util.py->error_log line:65 [INFO] 断言失败:status_code不等于400
[2023-08-22 16:24:16,695] logger_util.py->write_log line:61 [INFO] 接口请求失败！
[2023-08-22 16:24:16,695] logger_util.py->write_log line:61 [INFO] -------------接口请求结束-----------

[2023-08-22 16:24:16,695] logger_util.py->error_log line:65 [INFO] 断言异常：异常信息: Traceback (most recent call last):
  File "E:\Project_python\api_cms\common\requests_util.py", line 347, in validate_result
    error_log("断言失败:"+assert_key+"不等于"+str(assert_value))
  File "E:\Project_python\api_cms\common\logger_util.py", line 66, in error_log
    raise Exception(log_message)
Exception: 断言失败:status_code不等于400

[2023-08-22 16:24:16,696] logger_util.py->error_log line:65 [INFO] 分析YAML文件异常：异常信息: Traceback (most recent call last):
  File "E:\Project_python\api_cms\common\requests_util.py", line 347, in validate_result
    error_log("断言失败:"+assert_key+"不等于"+str(assert_value))
  File "E:\Project_python\api_cms\common\logger_util.py", line 66, in error_log
    raise Exception(log_message)
Exception: 断言失败:status_code不等于400

During handling of the above exception, another exception occurred:

Traceback (most recent call last):
  File "E:\Project_python\api_cms\common\requests_util.py", line 232, in analysis_yaml
    self.validate_result(yq_result, return_data, status_code)
  File "E:\Project_python\api_cms\common\requests_util.py", line 401, in validate_result
    error_log("断言异常：异常信息: %s" % str(traceback.format_exc()))
  File "E:\Project_python\api_cms\common\logger_util.py", line 66, in error_log
    raise Exception(log_message)
Exception: 断言异常：异常信息: Traceback (most recent call last):
  File "E:\Project_python\api_cms\common\requests_util.py", line 347, in validate_result
    error_log("断言失败:"+assert_key+"不等于"+str(assert_value))
  File "E:\Project_python\api_cms\common\logger_util.py", line 66, in error_log
    raise Exception(log_message)
Exception: 断言失败:status_code不等于400


[2023-08-22 16:24:16,721] logger_util.py->write_log line:61 [INFO] 
-------------接口请求开始-----------
[2023-08-22 16:24:16,721] logger_util.py->write_log line:61 [INFO] 接口名称：创建通道PDU长度为空
[2023-08-22 16:24:16,721] logger_util.py->write_log line:61 [INFO] 接口方式：post
[2023-08-22 16:24:16,721] logger_util.py->write_log line:61 [INFO] 接口路径：http://127.0.0.1:18000/api/v1/variable/tunnel
[2023-08-22 16:24:16,722] logger_util.py->write_log line:61 [INFO] 请求头：{}
[2023-08-22 16:24:16,722] logger_util.py->write_log line:61 [INFO] 请求参数：{'parentId': None, 'type': 1, 'name': '通道7841', 'description': '', 'config': {'suppiler': 'ModBus', 'model': 'Modbus_TCP', 'protocol': 'Modbus_TCP', 'parameters': {'ServerName': '127.0.0.1', 'DeviceID': '1', 'Port': '502', 'HeadAddress': '1', 'ConnectTimeOut': '502', 'ResponseTimeout': '502', 'Int32ByteOrder': '2143', 'Int64ByteOrder': '2143', 'UInt32ByteOrder': '2143', 'UInt64ByteOrder': '2143', 'F32ByteOrder': '3412', 'F64ByteOrder': '2143', 'StrByteOrder': '2143', 'EnableIndependentLink': '禁用', 'EnablePduDiagnosis': '启用', 'PduLength': '502'}}, 'copyConfig': None}
[2023-08-22 16:24:16,722] logger_util.py->write_log line:61 [INFO] 文件上传：None
[2023-08-22 16:24:16,741] logger_util.py->error_log line:65 [INFO] 断言失败:status_code不等于400
[2023-08-22 16:24:16,741] logger_util.py->write_log line:61 [INFO] 接口请求失败！
[2023-08-22 16:24:16,741] logger_util.py->write_log line:61 [INFO] -------------接口请求结束-----------

[2023-08-22 16:24:16,742] logger_util.py->error_log line:65 [INFO] 断言异常：异常信息: Traceback (most recent call last):
  File "E:\Project_python\api_cms\common\requests_util.py", line 347, in validate_result
    error_log("断言失败:"+assert_key+"不等于"+str(assert_value))
  File "E:\Project_python\api_cms\common\logger_util.py", line 66, in error_log
    raise Exception(log_message)
Exception: 断言失败:status_code不等于400

[2023-08-22 16:24:16,742] logger_util.py->error_log line:65 [INFO] 分析YAML文件异常：异常信息: Traceback (most recent call last):
  File "E:\Project_python\api_cms\common\requests_util.py", line 347, in validate_result
    error_log("断言失败:"+assert_key+"不等于"+str(assert_value))
  File "E:\Project_python\api_cms\common\logger_util.py", line 66, in error_log
    raise Exception(log_message)
Exception: 断言失败:status_code不等于400

During handling of the above exception, another exception occurred:

Traceback (most recent call last):
  File "E:\Project_python\api_cms\common\requests_util.py", line 232, in analysis_yaml
    self.validate_result(yq_result, return_data, status_code)
  File "E:\Project_python\api_cms\common\requests_util.py", line 401, in validate_result
    error_log("断言异常：异常信息: %s" % str(traceback.format_exc()))
  File "E:\Project_python\api_cms\common\logger_util.py", line 66, in error_log
    raise Exception(log_message)
Exception: 断言异常：异常信息: Traceback (most recent call last):
  File "E:\Project_python\api_cms\common\requests_util.py", line 347, in validate_result
    error_log("断言失败:"+assert_key+"不等于"+str(assert_value))
  File "E:\Project_python\api_cms\common\logger_util.py", line 66, in error_log
    raise Exception(log_message)
Exception: 断言失败:status_code不等于400


[2023-08-22 16:24:16,767] logger_util.py->write_log line:61 [INFO] 
-------------接口请求开始-----------
[2023-08-22 16:24:16,768] logger_util.py->write_log line:61 [INFO] 接口名称：创建通道PDU长度非法
[2023-08-22 16:24:16,768] logger_util.py->write_log line:61 [INFO] 接口方式：post
[2023-08-22 16:24:16,768] logger_util.py->write_log line:61 [INFO] 接口路径：http://127.0.0.1:18000/api/v1/variable/tunnel
[2023-08-22 16:24:16,768] logger_util.py->write_log line:61 [INFO] 请求头：{}
[2023-08-22 16:24:16,768] logger_util.py->write_log line:61 [INFO] 请求参数：{'parentId': None, 'type': 1, 'name': '通道4118', 'description': '', 'config': {'suppiler': 'ModBus', 'model': 'Modbus_TCP', 'protocol': 'Modbus_TCP', 'parameters': {'ServerName': '127.0.0.1', 'DeviceID': '1', 'Port': '502', 'HeadAddress': '1', 'ConnectTimeOut': '502', 'ResponseTimeout': '502', 'Int32ByteOrder': '2143', 'Int64ByteOrder': '2143', 'UInt32ByteOrder': '2143', 'UInt64ByteOrder': '2143', 'F32ByteOrder': '3412', 'F64ByteOrder': '2143', 'StrByteOrder': '2143', 'EnableIndependentLink': '禁用', 'EnablePduDiagnosis': '启用', 'PduLength': '502'}}, 'copyConfig': None}
[2023-08-22 16:24:16,768] logger_util.py->write_log line:61 [INFO] 文件上传：None
[2023-08-22 16:24:16,787] logger_util.py->error_log line:65 [INFO] 断言失败:status_code不等于400
[2023-08-22 16:24:16,787] logger_util.py->write_log line:61 [INFO] 接口请求失败！
[2023-08-22 16:24:16,787] logger_util.py->write_log line:61 [INFO] -------------接口请求结束-----------

[2023-08-22 16:24:16,787] logger_util.py->error_log line:65 [INFO] 断言异常：异常信息: Traceback (most recent call last):
  File "E:\Project_python\api_cms\common\requests_util.py", line 347, in validate_result
    error_log("断言失败:"+assert_key+"不等于"+str(assert_value))
  File "E:\Project_python\api_cms\common\logger_util.py", line 66, in error_log
    raise Exception(log_message)
Exception: 断言失败:status_code不等于400

[2023-08-22 16:24:16,787] logger_util.py->error_log line:65 [INFO] 分析YAML文件异常：异常信息: Traceback (most recent call last):
  File "E:\Project_python\api_cms\common\requests_util.py", line 347, in validate_result
    error_log("断言失败:"+assert_key+"不等于"+str(assert_value))
  File "E:\Project_python\api_cms\common\logger_util.py", line 66, in error_log
    raise Exception(log_message)
Exception: 断言失败:status_code不等于400

During handling of the above exception, another exception occurred:

Traceback (most recent call last):
  File "E:\Project_python\api_cms\common\requests_util.py", line 232, in analysis_yaml
    self.validate_result(yq_result, return_data, status_code)
  File "E:\Project_python\api_cms\common\requests_util.py", line 401, in validate_result
    error_log("断言异常：异常信息: %s" % str(traceback.format_exc()))
  File "E:\Project_python\api_cms\common\logger_util.py", line 66, in error_log
    raise Exception(log_message)
Exception: 断言异常：异常信息: Traceback (most recent call last):
  File "E:\Project_python\api_cms\common\requests_util.py", line 347, in validate_result
    error_log("断言失败:"+assert_key+"不等于"+str(assert_value))
  File "E:\Project_python\api_cms\common\logger_util.py", line 66, in error_log
    raise Exception(log_message)
Exception: 断言失败:status_code不等于400


