[2023-06-02 13:57:32,662] logger_util.py->error_log line:65 [INFO] 读取用例文件异常：异常信息: Traceback (most recent call last):
  File "E:\Project_python\2TestCMS2.0\common\parameters_util.py", line 23, in read_testcase_file
    caseinfo = yaml.load(stream=f, Loader=yaml.FullLoader)
  File "D:\Pyhton\Pyton39\lib\site-packages\yaml\__init__.py", line 114, in load
    return loader.get_single_data()
  File "D:\Pyhton\Pyton39\lib\site-packages\yaml\constructor.py", line 49, in get_single_data
    node = self.get_single_node()
  File "D:\Pyhton\Pyton39\lib\site-packages\yaml\composer.py", line 36, in get_single_node
    document = self.compose_document()
  File "D:\Pyhton\Pyton39\lib\site-packages\yaml\composer.py", line 55, in compose_document
    node = self.compose_node(None, None)
  File "D:\Pyhton\Pyton39\lib\site-packages\yaml\composer.py", line 82, in compose_node
    node = self.compose_sequence_node(anchor)
  File "D:\Pyhton\Pyton39\lib\site-packages\yaml\composer.py", line 111, in compose_sequence_node
    node.value.append(self.compose_node(node, index))
  File "D:\Pyhton\Pyton39\lib\site-packages\yaml\composer.py", line 84, in compose_node
    node = self.compose_mapping_node(anchor)
  File "D:\Pyhton\Pyton39\lib\site-packages\yaml\composer.py", line 133, in compose_mapping_node
    item_value = self.compose_node(node, item_key)
  File "D:\Pyhton\Pyton39\lib\site-packages\yaml\composer.py", line 84, in compose_node
    node = self.compose_mapping_node(anchor)
  File "D:\Pyhton\Pyton39\lib\site-packages\yaml\composer.py", line 133, in compose_mapping_node
    item_value = self.compose_node(node, item_key)
  File "D:\Pyhton\Pyton39\lib\site-packages\yaml\composer.py", line 84, in compose_node
    node = self.compose_mapping_node(anchor)
  File "D:\Pyhton\Pyton39\lib\site-packages\yaml\composer.py", line 133, in compose_mapping_node
    item_value = self.compose_node(node, item_key)
  File "D:\Pyhton\Pyton39\lib\site-packages\yaml\composer.py", line 64, in compose_node
    if self.check_event(AliasEvent):
  File "D:\Pyhton\Pyton39\lib\site-packages\yaml\parser.py", line 98, in check_event
    self.current_event = self.state()
  File "D:\Pyhton\Pyton39\lib\site-packages\yaml\parser.py", line 449, in parse_block_mapping_value
    if not self.check_token(KeyToken, ValueToken, BlockEndToken):
  File "D:\Pyhton\Pyton39\lib\site-packages\yaml\scanner.py", line 116, in check_token
    self.fetch_more_tokens()
  File "D:\Pyhton\Pyton39\lib\site-packages\yaml\scanner.py", line 215, in fetch_more_tokens
    return self.fetch_block_entry()
  File "D:\Pyhton\Pyton39\lib\site-packages\yaml\scanner.py", line 491, in fetch_block_entry
    raise ScannerError(None, None,
yaml.scanner.ScannerError: sequence entries are not allowed here
  in "E:\Project_python\2TestCMS2.0/testcase/5_DataManagement/create_aggregate_table_trigger.yml", line 10, column 20

