[2023-08-09 11:47:30,954] logger_util.py->write_log line:61 [INFO] -------------接口请求开始-----------
[2023-08-09 11:47:30,954] logger_util.py->write_log line:61 [INFO] 接口名称：有符号8位整型_变量下发
[2023-08-09 11:47:30,954] logger_util.py->write_log line:61 [INFO] 接口方式：post
[2023-08-09 11:47:30,954] logger_util.py->write_log line:61 [INFO] 接口路径：http://127.0.0.1:18000/api/v1/variable/setvalues
[2023-08-09 11:47:30,954] logger_util.py->write_log line:61 [INFO] 请求头：{'X-Project': 'e786e771376446668698f5250ecb11ed', 'Authorization': 'Bearer Bearer eyJhbGciOiJIUzI1NiIsInR5cCI6IkpXVCJ9.eyJodHRwOi8vc2NoZW1hcy54bWxzb2FwLm9yZy93cy8yMDA1LzA1L2lkZW50aXR5L2NsYWltcy9uYW1lIjoiU3VwZXJBZG1pbiIsImh0dHA6Ly9zY2hlbWFzLnhtbHNvYXAub3JnL3dzLzIwMDUvMDUvaWRlbnRpdHkvY2xhaW1zL25hbWVpZGVudGlmaWVyIjoiU3VwZXJBZG1pbiIsImV4cCI6MTY5MjE1NzY1MCwiaXNzIjoiQ01TdjIiLCJhdWQiOiJBcGkifQ.g-DoBjMtTJ6zI-muMn9gsS9unB2CSb25JF58fmnQov4'}
[2023-08-09 11:47:30,955] logger_util.py->write_log line:61 [INFO] 请求参数：{'A1': '-11'}
[2023-08-09 11:47:30,955] logger_util.py->write_log line:61 [INFO] 文件上传：None
[2023-08-09 11:47:30,965] logger_util.py->error_log line:65 [INFO] 断言失败:status_code不等于200
[2023-08-09 11:47:30,965] logger_util.py->write_log line:61 [INFO] 接口请求失败！
[2023-08-09 11:47:30,965] logger_util.py->write_log line:61 [INFO] -------------接口请求结束-----------

[2023-08-09 11:47:30,966] logger_util.py->error_log line:65 [INFO] 断言异常：异常信息: Traceback (most recent call last):
  File "E:\Project_python\api_SIOT\common\requests_util.py", line 374, in validate_result
    error_log("断言失败:"+assert_key+"不等于"+str(assert_value))
  File "E:\Project_python\api_SIOT\common\logger_util.py", line 66, in error_log
    raise Exception(log_message)
Exception: 断言失败:status_code不等于200

[2023-08-09 11:47:30,966] logger_util.py->error_log line:65 [INFO] 分析YAML文件异常：异常信息: Traceback (most recent call last):
  File "E:\Project_python\api_SIOT\common\requests_util.py", line 374, in validate_result
    error_log("断言失败:"+assert_key+"不等于"+str(assert_value))
  File "E:\Project_python\api_SIOT\common\logger_util.py", line 66, in error_log
    raise Exception(log_message)
Exception: 断言失败:status_code不等于200

During handling of the above exception, another exception occurred:

Traceback (most recent call last):
  File "E:\Project_python\api_SIOT\common\requests_util.py", line 273, in analysis_yaml
    self.validate_result(yq_result, return_text, status_code)
  File "E:\Project_python\api_SIOT\common\requests_util.py", line 424, in validate_result
    error_log("断言异常：异常信息: %s" % str(traceback.format_exc()))
  File "E:\Project_python\api_SIOT\common\logger_util.py", line 66, in error_log
    raise Exception(log_message)
Exception: 断言异常：异常信息: Traceback (most recent call last):
  File "E:\Project_python\api_SIOT\common\requests_util.py", line 374, in validate_result
    error_log("断言失败:"+assert_key+"不等于"+str(assert_value))
  File "E:\Project_python\api_SIOT\common\logger_util.py", line 66, in error_log
    raise Exception(log_message)
Exception: 断言失败:status_code不等于200


[2023-08-09 11:47:31,080] logger_util.py->write_log line:61 [INFO] -------------接口请求开始-----------
[2023-08-09 11:47:31,080] logger_util.py->write_log line:61 [INFO] 接口名称：无符号8位整型_变量下发
[2023-08-09 11:47:31,080] logger_util.py->write_log line:61 [INFO] 接口方式：post
[2023-08-09 11:47:31,080] logger_util.py->write_log line:61 [INFO] 接口路径：http://127.0.0.1:18000/api/v1/variable/setvalues
[2023-08-09 11:47:31,080] logger_util.py->write_log line:61 [INFO] 请求头：{'X-Project': 'e786e771376446668698f5250ecb11ed', 'Authorization': 'Bearer Bearer eyJhbGciOiJIUzI1NiIsInR5cCI6IkpXVCJ9.eyJodHRwOi8vc2NoZW1hcy54bWxzb2FwLm9yZy93cy8yMDA1LzA1L2lkZW50aXR5L2NsYWltcy9uYW1lIjoiU3VwZXJBZG1pbiIsImh0dHA6Ly9zY2hlbWFzLnhtbHNvYXAub3JnL3dzLzIwMDUvMDUvaWRlbnRpdHkvY2xhaW1zL25hbWVpZGVudGlmaWVyIjoiU3VwZXJBZG1pbiIsImV4cCI6MTY5MjE1NzY1MCwiaXNzIjoiQ01TdjIiLCJhdWQiOiJBcGkifQ.g-DoBjMtTJ6zI-muMn9gsS9unB2CSb25JF58fmnQov4'}
[2023-08-09 11:47:31,080] logger_util.py->write_log line:61 [INFO] 请求参数：{'A2': '22'}
[2023-08-09 11:47:31,080] logger_util.py->write_log line:61 [INFO] 文件上传：None
[2023-08-09 11:47:31,082] logger_util.py->error_log line:65 [INFO] 断言失败:status_code不等于200
[2023-08-09 11:47:31,082] logger_util.py->write_log line:61 [INFO] 接口请求失败！
[2023-08-09 11:47:31,082] logger_util.py->write_log line:61 [INFO] -------------接口请求结束-----------

[2023-08-09 11:47:31,082] logger_util.py->error_log line:65 [INFO] 断言异常：异常信息: Traceback (most recent call last):
  File "E:\Project_python\api_SIOT\common\requests_util.py", line 374, in validate_result
    error_log("断言失败:"+assert_key+"不等于"+str(assert_value))
  File "E:\Project_python\api_SIOT\common\logger_util.py", line 66, in error_log
    raise Exception(log_message)
Exception: 断言失败:status_code不等于200

[2023-08-09 11:47:31,083] logger_util.py->error_log line:65 [INFO] 分析YAML文件异常：异常信息: Traceback (most recent call last):
  File "E:\Project_python\api_SIOT\common\requests_util.py", line 374, in validate_result
    error_log("断言失败:"+assert_key+"不等于"+str(assert_value))
  File "E:\Project_python\api_SIOT\common\logger_util.py", line 66, in error_log
    raise Exception(log_message)
Exception: 断言失败:status_code不等于200

During handling of the above exception, another exception occurred:

Traceback (most recent call last):
  File "E:\Project_python\api_SIOT\common\requests_util.py", line 273, in analysis_yaml
    self.validate_result(yq_result, return_text, status_code)
  File "E:\Project_python\api_SIOT\common\requests_util.py", line 424, in validate_result
    error_log("断言异常：异常信息: %s" % str(traceback.format_exc()))
  File "E:\Project_python\api_SIOT\common\logger_util.py", line 66, in error_log
    raise Exception(log_message)
Exception: 断言异常：异常信息: Traceback (most recent call last):
  File "E:\Project_python\api_SIOT\common\requests_util.py", line 374, in validate_result
    error_log("断言失败:"+assert_key+"不等于"+str(assert_value))
  File "E:\Project_python\api_SIOT\common\logger_util.py", line 66, in error_log
    raise Exception(log_message)
Exception: 断言失败:status_code不等于200


[2023-08-09 11:47:31,112] logger_util.py->write_log line:61 [INFO] -------------接口请求开始-----------
[2023-08-09 11:47:31,112] logger_util.py->write_log line:61 [INFO] 接口名称：有符号16位整型_变量下发
[2023-08-09 11:47:31,112] logger_util.py->write_log line:61 [INFO] 接口方式：post
[2023-08-09 11:47:31,113] logger_util.py->write_log line:61 [INFO] 接口路径：http://127.0.0.1:18000/api/v1/variable/setvalues
[2023-08-09 11:47:31,113] logger_util.py->write_log line:61 [INFO] 请求头：{'X-Project': 'e786e771376446668698f5250ecb11ed', 'Authorization': 'Bearer Bearer eyJhbGciOiJIUzI1NiIsInR5cCI6IkpXVCJ9.eyJodHRwOi8vc2NoZW1hcy54bWxzb2FwLm9yZy93cy8yMDA1LzA1L2lkZW50aXR5L2NsYWltcy9uYW1lIjoiU3VwZXJBZG1pbiIsImh0dHA6Ly9zY2hlbWFzLnhtbHNvYXAub3JnL3dzLzIwMDUvMDUvaWRlbnRpdHkvY2xhaW1zL25hbWVpZGVudGlmaWVyIjoiU3VwZXJBZG1pbiIsImV4cCI6MTY5MjE1NzY1MCwiaXNzIjoiQ01TdjIiLCJhdWQiOiJBcGkifQ.g-DoBjMtTJ6zI-muMn9gsS9unB2CSb25JF58fmnQov4'}
[2023-08-09 11:47:31,113] logger_util.py->write_log line:61 [INFO] 请求参数：{'A3': '33'}
[2023-08-09 11:47:31,113] logger_util.py->write_log line:61 [INFO] 文件上传：None
[2023-08-09 11:47:31,115] logger_util.py->error_log line:65 [INFO] 断言失败:status_code不等于200
[2023-08-09 11:47:31,115] logger_util.py->write_log line:61 [INFO] 接口请求失败！
[2023-08-09 11:47:31,115] logger_util.py->write_log line:61 [INFO] -------------接口请求结束-----------

[2023-08-09 11:47:31,116] logger_util.py->error_log line:65 [INFO] 断言异常：异常信息: Traceback (most recent call last):
  File "E:\Project_python\api_SIOT\common\requests_util.py", line 374, in validate_result
    error_log("断言失败:"+assert_key+"不等于"+str(assert_value))
  File "E:\Project_python\api_SIOT\common\logger_util.py", line 66, in error_log
    raise Exception(log_message)
Exception: 断言失败:status_code不等于200

[2023-08-09 11:47:31,116] logger_util.py->error_log line:65 [INFO] 分析YAML文件异常：异常信息: Traceback (most recent call last):
  File "E:\Project_python\api_SIOT\common\requests_util.py", line 374, in validate_result
    error_log("断言失败:"+assert_key+"不等于"+str(assert_value))
  File "E:\Project_python\api_SIOT\common\logger_util.py", line 66, in error_log
    raise Exception(log_message)
Exception: 断言失败:status_code不等于200

During handling of the above exception, another exception occurred:

Traceback (most recent call last):
  File "E:\Project_python\api_SIOT\common\requests_util.py", line 273, in analysis_yaml
    self.validate_result(yq_result, return_text, status_code)
  File "E:\Project_python\api_SIOT\common\requests_util.py", line 424, in validate_result
    error_log("断言异常：异常信息: %s" % str(traceback.format_exc()))
  File "E:\Project_python\api_SIOT\common\logger_util.py", line 66, in error_log
    raise Exception(log_message)
Exception: 断言异常：异常信息: Traceback (most recent call last):
  File "E:\Project_python\api_SIOT\common\requests_util.py", line 374, in validate_result
    error_log("断言失败:"+assert_key+"不等于"+str(assert_value))
  File "E:\Project_python\api_SIOT\common\logger_util.py", line 66, in error_log
    raise Exception(log_message)
Exception: 断言失败:status_code不等于200


[2023-08-09 11:47:31,146] logger_util.py->write_log line:61 [INFO] -------------接口请求开始-----------
[2023-08-09 11:47:31,146] logger_util.py->write_log line:61 [INFO] 接口名称：无符号16位整型_变量下发
[2023-08-09 11:47:31,146] logger_util.py->write_log line:61 [INFO] 接口方式：post
[2023-08-09 11:47:31,146] logger_util.py->write_log line:61 [INFO] 接口路径：http://127.0.0.1:18000/api/v1/variable/setvalues
[2023-08-09 11:47:31,146] logger_util.py->write_log line:61 [INFO] 请求头：{'X-Project': 'e786e771376446668698f5250ecb11ed', 'Authorization': 'Bearer Bearer eyJhbGciOiJIUzI1NiIsInR5cCI6IkpXVCJ9.eyJodHRwOi8vc2NoZW1hcy54bWxzb2FwLm9yZy93cy8yMDA1LzA1L2lkZW50aXR5L2NsYWltcy9uYW1lIjoiU3VwZXJBZG1pbiIsImh0dHA6Ly9zY2hlbWFzLnhtbHNvYXAub3JnL3dzLzIwMDUvMDUvaWRlbnRpdHkvY2xhaW1zL25hbWVpZGVudGlmaWVyIjoiU3VwZXJBZG1pbiIsImV4cCI6MTY5MjE1NzY1MCwiaXNzIjoiQ01TdjIiLCJhdWQiOiJBcGkifQ.g-DoBjMtTJ6zI-muMn9gsS9unB2CSb25JF58fmnQov4'}
[2023-08-09 11:47:31,146] logger_util.py->write_log line:61 [INFO] 请求参数：{'A4': '44'}
[2023-08-09 11:47:31,147] logger_util.py->write_log line:61 [INFO] 文件上传：None
[2023-08-09 11:47:31,149] logger_util.py->error_log line:65 [INFO] 断言失败:status_code不等于200
[2023-08-09 11:47:31,149] logger_util.py->write_log line:61 [INFO] 接口请求失败！
[2023-08-09 11:47:31,149] logger_util.py->write_log line:61 [INFO] -------------接口请求结束-----------

[2023-08-09 11:47:31,149] logger_util.py->error_log line:65 [INFO] 断言异常：异常信息: Traceback (most recent call last):
  File "E:\Project_python\api_SIOT\common\requests_util.py", line 374, in validate_result
    error_log("断言失败:"+assert_key+"不等于"+str(assert_value))
  File "E:\Project_python\api_SIOT\common\logger_util.py", line 66, in error_log
    raise Exception(log_message)
Exception: 断言失败:status_code不等于200

[2023-08-09 11:47:31,150] logger_util.py->error_log line:65 [INFO] 分析YAML文件异常：异常信息: Traceback (most recent call last):
  File "E:\Project_python\api_SIOT\common\requests_util.py", line 374, in validate_result
    error_log("断言失败:"+assert_key+"不等于"+str(assert_value))
  File "E:\Project_python\api_SIOT\common\logger_util.py", line 66, in error_log
    raise Exception(log_message)
Exception: 断言失败:status_code不等于200

During handling of the above exception, another exception occurred:

Traceback (most recent call last):
  File "E:\Project_python\api_SIOT\common\requests_util.py", line 273, in analysis_yaml
    self.validate_result(yq_result, return_text, status_code)
  File "E:\Project_python\api_SIOT\common\requests_util.py", line 424, in validate_result
    error_log("断言异常：异常信息: %s" % str(traceback.format_exc()))
  File "E:\Project_python\api_SIOT\common\logger_util.py", line 66, in error_log
    raise Exception(log_message)
Exception: 断言异常：异常信息: Traceback (most recent call last):
  File "E:\Project_python\api_SIOT\common\requests_util.py", line 374, in validate_result
    error_log("断言失败:"+assert_key+"不等于"+str(assert_value))
  File "E:\Project_python\api_SIOT\common\logger_util.py", line 66, in error_log
    raise Exception(log_message)
Exception: 断言失败:status_code不等于200


[2023-08-09 11:47:31,178] logger_util.py->write_log line:61 [INFO] -------------接口请求开始-----------
[2023-08-09 11:47:31,179] logger_util.py->write_log line:61 [INFO] 接口名称：32位浮点数_变量下发
[2023-08-09 11:47:31,179] logger_util.py->write_log line:61 [INFO] 接口方式：post
[2023-08-09 11:47:31,179] logger_util.py->write_log line:61 [INFO] 接口路径：http://127.0.0.1:18000/api/v1/variable/setvalues
[2023-08-09 11:47:31,179] logger_util.py->write_log line:61 [INFO] 请求头：{'X-Project': 'e786e771376446668698f5250ecb11ed', 'Authorization': 'Bearer Bearer eyJhbGciOiJIUzI1NiIsInR5cCI6IkpXVCJ9.eyJodHRwOi8vc2NoZW1hcy54bWxzb2FwLm9yZy93cy8yMDA1LzA1L2lkZW50aXR5L2NsYWltcy9uYW1lIjoiU3VwZXJBZG1pbiIsImh0dHA6Ly9zY2hlbWFzLnhtbHNvYXAub3JnL3dzLzIwMDUvMDUvaWRlbnRpdHkvY2xhaW1zL25hbWVpZGVudGlmaWVyIjoiU3VwZXJBZG1pbiIsImV4cCI6MTY5MjE1NzY1MCwiaXNzIjoiQ01TdjIiLCJhdWQiOiJBcGkifQ.g-DoBjMtTJ6zI-muMn9gsS9unB2CSb25JF58fmnQov4'}
[2023-08-09 11:47:31,179] logger_util.py->write_log line:61 [INFO] 请求参数：{'A5': '55.456'}
[2023-08-09 11:47:31,179] logger_util.py->write_log line:61 [INFO] 文件上传：None
[2023-08-09 11:47:31,181] logger_util.py->error_log line:65 [INFO] 断言失败:status_code不等于200
[2023-08-09 11:47:31,181] logger_util.py->write_log line:61 [INFO] 接口请求失败！
[2023-08-09 11:47:31,182] logger_util.py->write_log line:61 [INFO] -------------接口请求结束-----------

[2023-08-09 11:47:31,182] logger_util.py->error_log line:65 [INFO] 断言异常：异常信息: Traceback (most recent call last):
  File "E:\Project_python\api_SIOT\common\requests_util.py", line 374, in validate_result
    error_log("断言失败:"+assert_key+"不等于"+str(assert_value))
  File "E:\Project_python\api_SIOT\common\logger_util.py", line 66, in error_log
    raise Exception(log_message)
Exception: 断言失败:status_code不等于200

[2023-08-09 11:47:31,182] logger_util.py->error_log line:65 [INFO] 分析YAML文件异常：异常信息: Traceback (most recent call last):
  File "E:\Project_python\api_SIOT\common\requests_util.py", line 374, in validate_result
    error_log("断言失败:"+assert_key+"不等于"+str(assert_value))
  File "E:\Project_python\api_SIOT\common\logger_util.py", line 66, in error_log
    raise Exception(log_message)
Exception: 断言失败:status_code不等于200

During handling of the above exception, another exception occurred:

Traceback (most recent call last):
  File "E:\Project_python\api_SIOT\common\requests_util.py", line 273, in analysis_yaml
    self.validate_result(yq_result, return_text, status_code)
  File "E:\Project_python\api_SIOT\common\requests_util.py", line 424, in validate_result
    error_log("断言异常：异常信息: %s" % str(traceback.format_exc()))
  File "E:\Project_python\api_SIOT\common\logger_util.py", line 66, in error_log
    raise Exception(log_message)
Exception: 断言异常：异常信息: Traceback (most recent call last):
  File "E:\Project_python\api_SIOT\common\requests_util.py", line 374, in validate_result
    error_log("断言失败:"+assert_key+"不等于"+str(assert_value))
  File "E:\Project_python\api_SIOT\common\logger_util.py", line 66, in error_log
    raise Exception(log_message)
Exception: 断言失败:status_code不等于200


[2023-08-09 11:47:31,211] logger_util.py->write_log line:61 [INFO] -------------接口请求开始-----------
[2023-08-09 11:47:31,212] logger_util.py->write_log line:61 [INFO] 接口名称：二进制_变量下发
[2023-08-09 11:47:31,212] logger_util.py->write_log line:61 [INFO] 接口方式：post
[2023-08-09 11:47:31,212] logger_util.py->write_log line:61 [INFO] 接口路径：http://127.0.0.1:18000/api/v1/variable/setvalues
[2023-08-09 11:47:31,212] logger_util.py->write_log line:61 [INFO] 请求头：{'X-Project': 'e786e771376446668698f5250ecb11ed', 'Authorization': 'Bearer Bearer eyJhbGciOiJIUzI1NiIsInR5cCI6IkpXVCJ9.eyJodHRwOi8vc2NoZW1hcy54bWxzb2FwLm9yZy93cy8yMDA1LzA1L2lkZW50aXR5L2NsYWltcy9uYW1lIjoiU3VwZXJBZG1pbiIsImh0dHA6Ly9zY2hlbWFzLnhtbHNvYXAub3JnL3dzLzIwMDUvMDUvaWRlbnRpdHkvY2xhaW1zL25hbWVpZGVudGlmaWVyIjoiU3VwZXJBZG1pbiIsImV4cCI6MTY5MjE1NzY1MCwiaXNzIjoiQ01TdjIiLCJhdWQiOiJBcGkifQ.g-DoBjMtTJ6zI-muMn9gsS9unB2CSb25JF58fmnQov4'}
[2023-08-09 11:47:31,212] logger_util.py->write_log line:61 [INFO] 请求参数：{'A6': '1'}
[2023-08-09 11:47:31,212] logger_util.py->write_log line:61 [INFO] 文件上传：None
[2023-08-09 11:47:31,214] logger_util.py->error_log line:65 [INFO] 断言失败:status_code不等于200
[2023-08-09 11:47:31,215] logger_util.py->write_log line:61 [INFO] 接口请求失败！
[2023-08-09 11:47:31,215] logger_util.py->write_log line:61 [INFO] -------------接口请求结束-----------

[2023-08-09 11:47:31,215] logger_util.py->error_log line:65 [INFO] 断言异常：异常信息: Traceback (most recent call last):
  File "E:\Project_python\api_SIOT\common\requests_util.py", line 374, in validate_result
    error_log("断言失败:"+assert_key+"不等于"+str(assert_value))
  File "E:\Project_python\api_SIOT\common\logger_util.py", line 66, in error_log
    raise Exception(log_message)
Exception: 断言失败:status_code不等于200

[2023-08-09 11:47:31,215] logger_util.py->error_log line:65 [INFO] 分析YAML文件异常：异常信息: Traceback (most recent call last):
  File "E:\Project_python\api_SIOT\common\requests_util.py", line 374, in validate_result
    error_log("断言失败:"+assert_key+"不等于"+str(assert_value))
  File "E:\Project_python\api_SIOT\common\logger_util.py", line 66, in error_log
    raise Exception(log_message)
Exception: 断言失败:status_code不等于200

During handling of the above exception, another exception occurred:

Traceback (most recent call last):
  File "E:\Project_python\api_SIOT\common\requests_util.py", line 273, in analysis_yaml
    self.validate_result(yq_result, return_text, status_code)
  File "E:\Project_python\api_SIOT\common\requests_util.py", line 424, in validate_result
    error_log("断言异常：异常信息: %s" % str(traceback.format_exc()))
  File "E:\Project_python\api_SIOT\common\logger_util.py", line 66, in error_log
    raise Exception(log_message)
Exception: 断言异常：异常信息: Traceback (most recent call last):
  File "E:\Project_python\api_SIOT\common\requests_util.py", line 374, in validate_result
    error_log("断言失败:"+assert_key+"不等于"+str(assert_value))
  File "E:\Project_python\api_SIOT\common\logger_util.py", line 66, in error_log
    raise Exception(log_message)
Exception: 断言失败:status_code不等于200


[2023-08-09 11:47:31,247] logger_util.py->write_log line:61 [INFO] -------------接口请求开始-----------
[2023-08-09 11:47:31,247] logger_util.py->write_log line:61 [INFO] 接口名称：字符串_变量下发
[2023-08-09 11:47:31,247] logger_util.py->write_log line:61 [INFO] 接口方式：post
[2023-08-09 11:47:31,248] logger_util.py->write_log line:61 [INFO] 接口路径：http://127.0.0.1:18000/api/v1/variable/setvalues
[2023-08-09 11:47:31,248] logger_util.py->write_log line:61 [INFO] 请求头：{'X-Project': 'e786e771376446668698f5250ecb11ed', 'Authorization': 'Bearer Bearer eyJhbGciOiJIUzI1NiIsInR5cCI6IkpXVCJ9.eyJodHRwOi8vc2NoZW1hcy54bWxzb2FwLm9yZy93cy8yMDA1LzA1L2lkZW50aXR5L2NsYWltcy9uYW1lIjoiU3VwZXJBZG1pbiIsImh0dHA6Ly9zY2hlbWFzLnhtbHNvYXAub3JnL3dzLzIwMDUvMDUvaWRlbnRpdHkvY2xhaW1zL25hbWVpZGVudGlmaWVyIjoiU3VwZXJBZG1pbiIsImV4cCI6MTY5MjE1NzY1MCwiaXNzIjoiQ01TdjIiLCJhdWQiOiJBcGkifQ.g-DoBjMtTJ6zI-muMn9gsS9unB2CSb25JF58fmnQov4'}
[2023-08-09 11:47:31,248] logger_util.py->write_log line:61 [INFO] 请求参数：{'A7': '文本1'}
[2023-08-09 11:47:31,248] logger_util.py->write_log line:61 [INFO] 文件上传：None
[2023-08-09 11:47:31,251] logger_util.py->error_log line:65 [INFO] 断言失败:status_code不等于200
[2023-08-09 11:47:31,251] logger_util.py->write_log line:61 [INFO] 接口请求失败！
[2023-08-09 11:47:31,251] logger_util.py->write_log line:61 [INFO] -------------接口请求结束-----------

[2023-08-09 11:47:31,251] logger_util.py->error_log line:65 [INFO] 断言异常：异常信息: Traceback (most recent call last):
  File "E:\Project_python\api_SIOT\common\requests_util.py", line 374, in validate_result
    error_log("断言失败:"+assert_key+"不等于"+str(assert_value))
  File "E:\Project_python\api_SIOT\common\logger_util.py", line 66, in error_log
    raise Exception(log_message)
Exception: 断言失败:status_code不等于200

[2023-08-09 11:47:31,251] logger_util.py->error_log line:65 [INFO] 分析YAML文件异常：异常信息: Traceback (most recent call last):
  File "E:\Project_python\api_SIOT\common\requests_util.py", line 374, in validate_result
    error_log("断言失败:"+assert_key+"不等于"+str(assert_value))
  File "E:\Project_python\api_SIOT\common\logger_util.py", line 66, in error_log
    raise Exception(log_message)
Exception: 断言失败:status_code不等于200

During handling of the above exception, another exception occurred:

Traceback (most recent call last):
  File "E:\Project_python\api_SIOT\common\requests_util.py", line 273, in analysis_yaml
    self.validate_result(yq_result, return_text, status_code)
  File "E:\Project_python\api_SIOT\common\requests_util.py", line 424, in validate_result
    error_log("断言异常：异常信息: %s" % str(traceback.format_exc()))
  File "E:\Project_python\api_SIOT\common\logger_util.py", line 66, in error_log
    raise Exception(log_message)
Exception: 断言异常：异常信息: Traceback (most recent call last):
  File "E:\Project_python\api_SIOT\common\requests_util.py", line 374, in validate_result
    error_log("断言失败:"+assert_key+"不等于"+str(assert_value))
  File "E:\Project_python\api_SIOT\common\logger_util.py", line 66, in error_log
    raise Exception(log_message)
Exception: 断言失败:status_code不等于200


