[2023-08-08 20:09:07,909] logger_util.py->error_log line:65 [INFO] 分析YAML文件异常：异常信息: Traceback (most recent call last):
  File "E:\Project_python\api_SIOT\common\requests_util.py", line 200, in analysis_yaml
    files_value = self.replace_load(value)
  File "E:\Project_python\api_SIOT\common\requests_util.py", line 156, in replace_load
    new_value = getattr(DubugTalk(), func_name)(*args_value.split(','))
TypeError: get_project_path() takes 1 positional argument but 2 were given

