[2023-05-28 17:16:24,594] logger_util.py->error_log line:65 [INFO] 发送请求异常：异常信息: Traceback (most recent call last):
  File "E:\Project_python\2TestCMS2.0\common\requests_util.py", line 300, in send_request
    kwargs[key] = self.replace_load(value)
  File "E:\Project_python\2TestCMS2.0\common\requests_util.py", line 89, in replace_load
    int_value = int(num)
ValueError: invalid literal for int() with base 10: 'ectiveDateTime": "", "frequencyValue": "ddt{{1}}", "frequencyUnit": "ddt{{1}}", "matchAll": "ddt{{false}}", "condition": "G1 ==  true", "conditionDetail": "ddt{{1}}", "frequencyCheck": "ddt{{false}}"

[2023-05-28 17:16:24,594] logger_util.py->error_log line:65 [INFO] 分析YAML文件异常：异常信息: Traceback (most recent call last):
  File "E:\Project_python\2TestCMS2.0\common\requests_util.py", line 300, in send_request
    kwargs[key] = self.replace_load(value)
  File "E:\Project_python\2TestCMS2.0\common\requests_util.py", line 89, in replace_load
    int_value = int(num)
ValueError: invalid literal for int() with base 10: 'ectiveDateTime": "", "frequencyValue": "ddt{{1}}", "frequencyUnit": "ddt{{1}}", "matchAll": "ddt{{false}}", "condition": "G1 ==  true", "conditionDetail": "ddt{{1}}", "frequencyCheck": "ddt{{false}}"

During handling of the above exception, another exception occurred:

Traceback (most recent call last):
  File "E:\Project_python\2TestCMS2.0\common\requests_util.py", line 179, in analysis_yaml
    res = self.send_request(name =name,method=method,
  File "E:\Project_python\2TestCMS2.0\common\requests_util.py", line 320, in send_request
    error_log("发送请求异常：异常信息: %s" % str(traceback.format_exc()))
  File "E:\Project_python\2TestCMS2.0\common\logger_util.py", line 66, in error_log
    raise Exception(log_message)
Exception: 发送请求异常：异常信息: Traceback (most recent call last):
  File "E:\Project_python\2TestCMS2.0\common\requests_util.py", line 300, in send_request
    kwargs[key] = self.replace_load(value)
  File "E:\Project_python\2TestCMS2.0\common\requests_util.py", line 89, in replace_load
    int_value = int(num)
ValueError: invalid literal for int() with base 10: 'ectiveDateTime": "", "frequencyValue": "ddt{{1}}", "frequencyUnit": "ddt{{1}}", "matchAll": "ddt{{false}}", "condition": "G1 ==  true", "conditionDetail": "ddt{{1}}", "frequencyCheck": "ddt{{false}}"


[2023-05-28 17:16:24,703] logger_util.py->error_log line:65 [INFO] 发送请求异常：异常信息: Traceback (most recent call last):
  File "E:\Project_python\2TestCMS2.0\common\requests_util.py", line 300, in send_request
    kwargs[key] = self.replace_load(value)
  File "E:\Project_python\2TestCMS2.0\common\requests_util.py", line 89, in replace_load
    int_value = int(num)
ValueError: invalid literal for int() with base 10: 'ectiveDateTime": "", "frequencyValue": "ddt{{1}}", "frequencyUnit": "ddt{{1}}", "matchAll": "ddt{{false}}", "condition": "G1 ==  true", "conditionDetail": "ddt{{2}}", "frequencyCheck": "ddt{{false}}"

[2023-05-28 17:16:24,703] logger_util.py->error_log line:65 [INFO] 分析YAML文件异常：异常信息: Traceback (most recent call last):
  File "E:\Project_python\2TestCMS2.0\common\requests_util.py", line 300, in send_request
    kwargs[key] = self.replace_load(value)
  File "E:\Project_python\2TestCMS2.0\common\requests_util.py", line 89, in replace_load
    int_value = int(num)
ValueError: invalid literal for int() with base 10: 'ectiveDateTime": "", "frequencyValue": "ddt{{1}}", "frequencyUnit": "ddt{{1}}", "matchAll": "ddt{{false}}", "condition": "G1 ==  true", "conditionDetail": "ddt{{2}}", "frequencyCheck": "ddt{{false}}"

During handling of the above exception, another exception occurred:

Traceback (most recent call last):
  File "E:\Project_python\2TestCMS2.0\common\requests_util.py", line 179, in analysis_yaml
    res = self.send_request(name =name,method=method,
  File "E:\Project_python\2TestCMS2.0\common\requests_util.py", line 320, in send_request
    error_log("发送请求异常：异常信息: %s" % str(traceback.format_exc()))
  File "E:\Project_python\2TestCMS2.0\common\logger_util.py", line 66, in error_log
    raise Exception(log_message)
Exception: 发送请求异常：异常信息: Traceback (most recent call last):
  File "E:\Project_python\2TestCMS2.0\common\requests_util.py", line 300, in send_request
    kwargs[key] = self.replace_load(value)
  File "E:\Project_python\2TestCMS2.0\common\requests_util.py", line 89, in replace_load
    int_value = int(num)
ValueError: invalid literal for int() with base 10: 'ectiveDateTime": "", "frequencyValue": "ddt{{1}}", "frequencyUnit": "ddt{{1}}", "matchAll": "ddt{{false}}", "condition": "G1 ==  true", "conditionDetail": "ddt{{2}}", "frequencyCheck": "ddt{{false}}"


[2023-05-28 17:16:24,733] logger_util.py->error_log line:65 [INFO] 发送请求异常：异常信息: Traceback (most recent call last):
  File "E:\Project_python\2TestCMS2.0\common\requests_util.py", line 300, in send_request
    kwargs[key] = self.replace_load(value)
  File "E:\Project_python\2TestCMS2.0\common\requests_util.py", line 89, in replace_load
    int_value = int(num)
ValueError: invalid literal for int() with base 10: 'ectiveDateTime": "", "frequencyValue": "ddt{{1}}", "frequencyUnit": "ddt{{1}}", "matchAll": "ddt{{false}}", "condition": "G1 ==  true", "conditionDetail": "ddt{{3}}", "frequencyCheck": "ddt{{false}}"

[2023-05-28 17:16:24,733] logger_util.py->error_log line:65 [INFO] 分析YAML文件异常：异常信息: Traceback (most recent call last):
  File "E:\Project_python\2TestCMS2.0\common\requests_util.py", line 300, in send_request
    kwargs[key] = self.replace_load(value)
  File "E:\Project_python\2TestCMS2.0\common\requests_util.py", line 89, in replace_load
    int_value = int(num)
ValueError: invalid literal for int() with base 10: 'ectiveDateTime": "", "frequencyValue": "ddt{{1}}", "frequencyUnit": "ddt{{1}}", "matchAll": "ddt{{false}}", "condition": "G1 ==  true", "conditionDetail": "ddt{{3}}", "frequencyCheck": "ddt{{false}}"

During handling of the above exception, another exception occurred:

Traceback (most recent call last):
  File "E:\Project_python\2TestCMS2.0\common\requests_util.py", line 179, in analysis_yaml
    res = self.send_request(name =name,method=method,
  File "E:\Project_python\2TestCMS2.0\common\requests_util.py", line 320, in send_request
    error_log("发送请求异常：异常信息: %s" % str(traceback.format_exc()))
  File "E:\Project_python\2TestCMS2.0\common\logger_util.py", line 66, in error_log
    raise Exception(log_message)
Exception: 发送请求异常：异常信息: Traceback (most recent call last):
  File "E:\Project_python\2TestCMS2.0\common\requests_util.py", line 300, in send_request
    kwargs[key] = self.replace_load(value)
  File "E:\Project_python\2TestCMS2.0\common\requests_util.py", line 89, in replace_load
    int_value = int(num)
ValueError: invalid literal for int() with base 10: 'ectiveDateTime": "", "frequencyValue": "ddt{{1}}", "frequencyUnit": "ddt{{1}}", "matchAll": "ddt{{false}}", "condition": "G1 ==  true", "conditionDetail": "ddt{{3}}", "frequencyCheck": "ddt{{false}}"


[2023-05-28 17:16:24,763] logger_util.py->error_log line:65 [INFO] 发送请求异常：异常信息: Traceback (most recent call last):
  File "E:\Project_python\2TestCMS2.0\common\requests_util.py", line 300, in send_request
    kwargs[key] = self.replace_load(value)
  File "E:\Project_python\2TestCMS2.0\common\requests_util.py", line 89, in replace_load
    int_value = int(num)
ValueError: invalid literal for int() with base 10: 'ectiveDateTime": "", "frequencyValue": "ddt{{1}}", "frequencyUnit": "ddt{{1}}", "matchAll": "ddt{{false}}", "condition": "G1 ==  true", "conditionDetail": "ddt{{1}}", "frequencyCheck": "ddt{{true}}",

[2023-05-28 17:16:24,763] logger_util.py->error_log line:65 [INFO] 分析YAML文件异常：异常信息: Traceback (most recent call last):
  File "E:\Project_python\2TestCMS2.0\common\requests_util.py", line 300, in send_request
    kwargs[key] = self.replace_load(value)
  File "E:\Project_python\2TestCMS2.0\common\requests_util.py", line 89, in replace_load
    int_value = int(num)
ValueError: invalid literal for int() with base 10: 'ectiveDateTime": "", "frequencyValue": "ddt{{1}}", "frequencyUnit": "ddt{{1}}", "matchAll": "ddt{{false}}", "condition": "G1 ==  true", "conditionDetail": "ddt{{1}}", "frequencyCheck": "ddt{{true}}",

During handling of the above exception, another exception occurred:

Traceback (most recent call last):
  File "E:\Project_python\2TestCMS2.0\common\requests_util.py", line 179, in analysis_yaml
    res = self.send_request(name =name,method=method,
  File "E:\Project_python\2TestCMS2.0\common\requests_util.py", line 320, in send_request
    error_log("发送请求异常：异常信息: %s" % str(traceback.format_exc()))
  File "E:\Project_python\2TestCMS2.0\common\logger_util.py", line 66, in error_log
    raise Exception(log_message)
Exception: 发送请求异常：异常信息: Traceback (most recent call last):
  File "E:\Project_python\2TestCMS2.0\common\requests_util.py", line 300, in send_request
    kwargs[key] = self.replace_load(value)
  File "E:\Project_python\2TestCMS2.0\common\requests_util.py", line 89, in replace_load
    int_value = int(num)
ValueError: invalid literal for int() with base 10: 'ectiveDateTime": "", "frequencyValue": "ddt{{1}}", "frequencyUnit": "ddt{{1}}", "matchAll": "ddt{{false}}", "condition": "G1 ==  true", "conditionDetail": "ddt{{1}}", "frequencyCheck": "ddt{{true}}",


[2023-05-28 17:16:24,793] logger_util.py->error_log line:65 [INFO] 发送请求异常：异常信息: Traceback (most recent call last):
  File "E:\Project_python\2TestCMS2.0\common\requests_util.py", line 300, in send_request
    kwargs[key] = self.replace_load(value)
  File "E:\Project_python\2TestCMS2.0\common\requests_util.py", line 89, in replace_load
    int_value = int(num)
ValueError: invalid literal for int() with base 10: 'ectiveDateTime": "", "frequencyValue": "ddt{{5}}", "frequencyUnit": "ddt{{2}}", "matchAll": "ddt{{false}}", "condition": "G1 ==  true", "conditionDetail": "ddt{{1}}", "frequencyCheck": "ddt{{true}}",

[2023-05-28 17:16:24,793] logger_util.py->error_log line:65 [INFO] 分析YAML文件异常：异常信息: Traceback (most recent call last):
  File "E:\Project_python\2TestCMS2.0\common\requests_util.py", line 300, in send_request
    kwargs[key] = self.replace_load(value)
  File "E:\Project_python\2TestCMS2.0\common\requests_util.py", line 89, in replace_load
    int_value = int(num)
ValueError: invalid literal for int() with base 10: 'ectiveDateTime": "", "frequencyValue": "ddt{{5}}", "frequencyUnit": "ddt{{2}}", "matchAll": "ddt{{false}}", "condition": "G1 ==  true", "conditionDetail": "ddt{{1}}", "frequencyCheck": "ddt{{true}}",

During handling of the above exception, another exception occurred:

Traceback (most recent call last):
  File "E:\Project_python\2TestCMS2.0\common\requests_util.py", line 179, in analysis_yaml
    res = self.send_request(name =name,method=method,
  File "E:\Project_python\2TestCMS2.0\common\requests_util.py", line 320, in send_request
    error_log("发送请求异常：异常信息: %s" % str(traceback.format_exc()))
  File "E:\Project_python\2TestCMS2.0\common\logger_util.py", line 66, in error_log
    raise Exception(log_message)
Exception: 发送请求异常：异常信息: Traceback (most recent call last):
  File "E:\Project_python\2TestCMS2.0\common\requests_util.py", line 300, in send_request
    kwargs[key] = self.replace_load(value)
  File "E:\Project_python\2TestCMS2.0\common\requests_util.py", line 89, in replace_load
    int_value = int(num)
ValueError: invalid literal for int() with base 10: 'ectiveDateTime": "", "frequencyValue": "ddt{{5}}", "frequencyUnit": "ddt{{2}}", "matchAll": "ddt{{false}}", "condition": "G1 ==  true", "conditionDetail": "ddt{{1}}", "frequencyCheck": "ddt{{true}}",


[2023-05-28 17:16:24,823] logger_util.py->error_log line:65 [INFO] 发送请求异常：异常信息: Traceback (most recent call last):
  File "E:\Project_python\2TestCMS2.0\common\requests_util.py", line 300, in send_request
    kwargs[key] = self.replace_load(value)
  File "E:\Project_python\2TestCMS2.0\common\requests_util.py", line 89, in replace_load
    int_value = int(num)
ValueError: invalid literal for int() with base 10: 'ectiveDateTime": "", "frequencyValue": "ddt{{1}}", "frequencyUnit": "ddt{{3}}", "matchAll": "ddt{{false}}", "condition": "G1 ==  true", "conditionDetail": "ddt{{1}}", "frequencyCheck": "ddt{{true}}",

[2023-05-28 17:16:24,823] logger_util.py->error_log line:65 [INFO] 分析YAML文件异常：异常信息: Traceback (most recent call last):
  File "E:\Project_python\2TestCMS2.0\common\requests_util.py", line 300, in send_request
    kwargs[key] = self.replace_load(value)
  File "E:\Project_python\2TestCMS2.0\common\requests_util.py", line 89, in replace_load
    int_value = int(num)
ValueError: invalid literal for int() with base 10: 'ectiveDateTime": "", "frequencyValue": "ddt{{1}}", "frequencyUnit": "ddt{{3}}", "matchAll": "ddt{{false}}", "condition": "G1 ==  true", "conditionDetail": "ddt{{1}}", "frequencyCheck": "ddt{{true}}",

During handling of the above exception, another exception occurred:

Traceback (most recent call last):
  File "E:\Project_python\2TestCMS2.0\common\requests_util.py", line 179, in analysis_yaml
    res = self.send_request(name =name,method=method,
  File "E:\Project_python\2TestCMS2.0\common\requests_util.py", line 320, in send_request
    error_log("发送请求异常：异常信息: %s" % str(traceback.format_exc()))
  File "E:\Project_python\2TestCMS2.0\common\logger_util.py", line 66, in error_log
    raise Exception(log_message)
Exception: 发送请求异常：异常信息: Traceback (most recent call last):
  File "E:\Project_python\2TestCMS2.0\common\requests_util.py", line 300, in send_request
    kwargs[key] = self.replace_load(value)
  File "E:\Project_python\2TestCMS2.0\common\requests_util.py", line 89, in replace_load
    int_value = int(num)
ValueError: invalid literal for int() with base 10: 'ectiveDateTime": "", "frequencyValue": "ddt{{1}}", "frequencyUnit": "ddt{{3}}", "matchAll": "ddt{{false}}", "condition": "G1 ==  true", "conditionDetail": "ddt{{1}}", "frequencyCheck": "ddt{{true}}",


[2023-05-28 17:16:24,853] logger_util.py->error_log line:65 [INFO] 发送请求异常：异常信息: Traceback (most recent call last):
  File "E:\Project_python\2TestCMS2.0\common\requests_util.py", line 300, in send_request
    kwargs[key] = self.replace_load(value)
  File "E:\Project_python\2TestCMS2.0\common\requests_util.py", line 89, in replace_load
    int_value = int(num)
ValueError: invalid literal for int() with base 10: 'ectiveDateTime": "", "frequencyValue": "ddt{{1}}", "frequencyUnit": "ddt{{4}}", "matchAll": "ddt{{false}}", "condition": "G1 ==  true", "conditionDetail": "ddt{{1}}", "frequencyCheck": "ddt{{true}}",

[2023-05-28 17:16:24,853] logger_util.py->error_log line:65 [INFO] 分析YAML文件异常：异常信息: Traceback (most recent call last):
  File "E:\Project_python\2TestCMS2.0\common\requests_util.py", line 300, in send_request
    kwargs[key] = self.replace_load(value)
  File "E:\Project_python\2TestCMS2.0\common\requests_util.py", line 89, in replace_load
    int_value = int(num)
ValueError: invalid literal for int() with base 10: 'ectiveDateTime": "", "frequencyValue": "ddt{{1}}", "frequencyUnit": "ddt{{4}}", "matchAll": "ddt{{false}}", "condition": "G1 ==  true", "conditionDetail": "ddt{{1}}", "frequencyCheck": "ddt{{true}}",

During handling of the above exception, another exception occurred:

Traceback (most recent call last):
  File "E:\Project_python\2TestCMS2.0\common\requests_util.py", line 179, in analysis_yaml
    res = self.send_request(name =name,method=method,
  File "E:\Project_python\2TestCMS2.0\common\requests_util.py", line 320, in send_request
    error_log("发送请求异常：异常信息: %s" % str(traceback.format_exc()))
  File "E:\Project_python\2TestCMS2.0\common\logger_util.py", line 66, in error_log
    raise Exception(log_message)
Exception: 发送请求异常：异常信息: Traceback (most recent call last):
  File "E:\Project_python\2TestCMS2.0\common\requests_util.py", line 300, in send_request
    kwargs[key] = self.replace_load(value)
  File "E:\Project_python\2TestCMS2.0\common\requests_util.py", line 89, in replace_load
    int_value = int(num)
ValueError: invalid literal for int() with base 10: 'ectiveDateTime": "", "frequencyValue": "ddt{{1}}", "frequencyUnit": "ddt{{4}}", "matchAll": "ddt{{false}}", "condition": "G1 ==  true", "conditionDetail": "ddt{{1}}", "frequencyCheck": "ddt{{true}}",


[2023-05-28 17:16:24,883] logger_util.py->error_log line:65 [INFO] 发送请求异常：异常信息: Traceback (most recent call last):
  File "E:\Project_python\2TestCMS2.0\common\requests_util.py", line 300, in send_request
    kwargs[key] = self.replace_load(value)
  File "E:\Project_python\2TestCMS2.0\common\requests_util.py", line 89, in replace_load
    int_value = int(num)
ValueError: invalid literal for int() with base 10: 'ectiveDateTime": "", "frequencyValue": "ddt{{36}}", "frequencyUnit": "ddt{{5}}", "matchAll": "ddt{{false}}", "condition": "G1 ==  true", "conditionDetail": "ddt{{1}}", "frequencyCheck": "ddt{{true}}"

[2023-05-28 17:16:24,883] logger_util.py->error_log line:65 [INFO] 分析YAML文件异常：异常信息: Traceback (most recent call last):
  File "E:\Project_python\2TestCMS2.0\common\requests_util.py", line 300, in send_request
    kwargs[key] = self.replace_load(value)
  File "E:\Project_python\2TestCMS2.0\common\requests_util.py", line 89, in replace_load
    int_value = int(num)
ValueError: invalid literal for int() with base 10: 'ectiveDateTime": "", "frequencyValue": "ddt{{36}}", "frequencyUnit": "ddt{{5}}", "matchAll": "ddt{{false}}", "condition": "G1 ==  true", "conditionDetail": "ddt{{1}}", "frequencyCheck": "ddt{{true}}"

During handling of the above exception, another exception occurred:

Traceback (most recent call last):
  File "E:\Project_python\2TestCMS2.0\common\requests_util.py", line 179, in analysis_yaml
    res = self.send_request(name =name,method=method,
  File "E:\Project_python\2TestCMS2.0\common\requests_util.py", line 320, in send_request
    error_log("发送请求异常：异常信息: %s" % str(traceback.format_exc()))
  File "E:\Project_python\2TestCMS2.0\common\logger_util.py", line 66, in error_log
    raise Exception(log_message)
Exception: 发送请求异常：异常信息: Traceback (most recent call last):
  File "E:\Project_python\2TestCMS2.0\common\requests_util.py", line 300, in send_request
    kwargs[key] = self.replace_load(value)
  File "E:\Project_python\2TestCMS2.0\common\requests_util.py", line 89, in replace_load
    int_value = int(num)
ValueError: invalid literal for int() with base 10: 'ectiveDateTime": "", "frequencyValue": "ddt{{36}}", "frequencyUnit": "ddt{{5}}", "matchAll": "ddt{{false}}", "condition": "G1 ==  true", "conditionDetail": "ddt{{1}}", "frequencyCheck": "ddt{{true}}"


[2023-05-28 17:16:24,913] logger_util.py->error_log line:65 [INFO] 发送请求异常：异常信息: Traceback (most recent call last):
  File "E:\Project_python\2TestCMS2.0\common\requests_util.py", line 300, in send_request
    kwargs[key] = self.replace_load(value)
  File "E:\Project_python\2TestCMS2.0\common\requests_util.py", line 89, in replace_load
    int_value = int(num)
ValueError: invalid literal for int() with base 10: 'ectiveDateTime": "", "frequencyValue": "ddt{{1}}", "frequencyUnit": "ddt{{1}}", "matchAll": "ddt{{false}}", "condition": "G1 ==  true ||  H1 != \'\\u4e2d\\u6587\'", "conditionDetail": "ddt{{1}}", "fr

[2023-05-28 17:16:24,914] logger_util.py->error_log line:65 [INFO] 分析YAML文件异常：异常信息: Traceback (most recent call last):
  File "E:\Project_python\2TestCMS2.0\common\requests_util.py", line 300, in send_request
    kwargs[key] = self.replace_load(value)
  File "E:\Project_python\2TestCMS2.0\common\requests_util.py", line 89, in replace_load
    int_value = int(num)
ValueError: invalid literal for int() with base 10: 'ectiveDateTime": "", "frequencyValue": "ddt{{1}}", "frequencyUnit": "ddt{{1}}", "matchAll": "ddt{{false}}", "condition": "G1 ==  true ||  H1 != \'\\u4e2d\\u6587\'", "conditionDetail": "ddt{{1}}", "fr

During handling of the above exception, another exception occurred:

Traceback (most recent call last):
  File "E:\Project_python\2TestCMS2.0\common\requests_util.py", line 179, in analysis_yaml
    res = self.send_request(name =name,method=method,
  File "E:\Project_python\2TestCMS2.0\common\requests_util.py", line 320, in send_request
    error_log("发送请求异常：异常信息: %s" % str(traceback.format_exc()))
  File "E:\Project_python\2TestCMS2.0\common\logger_util.py", line 66, in error_log
    raise Exception(log_message)
Exception: 发送请求异常：异常信息: Traceback (most recent call last):
  File "E:\Project_python\2TestCMS2.0\common\requests_util.py", line 300, in send_request
    kwargs[key] = self.replace_load(value)
  File "E:\Project_python\2TestCMS2.0\common\requests_util.py", line 89, in replace_load
    int_value = int(num)
ValueError: invalid literal for int() with base 10: 'ectiveDateTime": "", "frequencyValue": "ddt{{1}}", "frequencyUnit": "ddt{{1}}", "matchAll": "ddt{{false}}", "condition": "G1 ==  true ||  H1 != \'\\u4e2d\\u6587\'", "conditionDetail": "ddt{{1}}", "fr


[2023-05-28 17:16:24,944] logger_util.py->error_log line:65 [INFO] 发送请求异常：异常信息: Traceback (most recent call last):
  File "E:\Project_python\2TestCMS2.0\common\requests_util.py", line 300, in send_request
    kwargs[key] = self.replace_load(value)
  File "E:\Project_python\2TestCMS2.0\common\requests_util.py", line 89, in replace_load
    int_value = int(num)
ValueError: invalid literal for int() with base 10: 'ectiveDateTime": "", "frequencyValue": "ddt{{1}}", "frequencyUnit": "ddt{{1}}", "matchAll": "ddt{{false}}", "condition": "A1 + B1)  <=  0 ||  (A1 - B1) <= 0", "conditionDetail": "ddt{{1}}", "frequenc

[2023-05-28 17:16:24,944] logger_util.py->error_log line:65 [INFO] 分析YAML文件异常：异常信息: Traceback (most recent call last):
  File "E:\Project_python\2TestCMS2.0\common\requests_util.py", line 300, in send_request
    kwargs[key] = self.replace_load(value)
  File "E:\Project_python\2TestCMS2.0\common\requests_util.py", line 89, in replace_load
    int_value = int(num)
ValueError: invalid literal for int() with base 10: 'ectiveDateTime": "", "frequencyValue": "ddt{{1}}", "frequencyUnit": "ddt{{1}}", "matchAll": "ddt{{false}}", "condition": "A1 + B1)  <=  0 ||  (A1 - B1) <= 0", "conditionDetail": "ddt{{1}}", "frequenc

During handling of the above exception, another exception occurred:

Traceback (most recent call last):
  File "E:\Project_python\2TestCMS2.0\common\requests_util.py", line 179, in analysis_yaml
    res = self.send_request(name =name,method=method,
  File "E:\Project_python\2TestCMS2.0\common\requests_util.py", line 320, in send_request
    error_log("发送请求异常：异常信息: %s" % str(traceback.format_exc()))
  File "E:\Project_python\2TestCMS2.0\common\logger_util.py", line 66, in error_log
    raise Exception(log_message)
Exception: 发送请求异常：异常信息: Traceback (most recent call last):
  File "E:\Project_python\2TestCMS2.0\common\requests_util.py", line 300, in send_request
    kwargs[key] = self.replace_load(value)
  File "E:\Project_python\2TestCMS2.0\common\requests_util.py", line 89, in replace_load
    int_value = int(num)
ValueError: invalid literal for int() with base 10: 'ectiveDateTime": "", "frequencyValue": "ddt{{1}}", "frequencyUnit": "ddt{{1}}", "matchAll": "ddt{{false}}", "condition": "A1 + B1)  <=  0 ||  (A1 - B1) <= 0", "conditionDetail": "ddt{{1}}", "frequenc


[2023-05-28 17:16:24,974] logger_util.py->error_log line:65 [INFO] 发送请求异常：异常信息: Traceback (most recent call last):
  File "E:\Project_python\2TestCMS2.0\common\requests_util.py", line 300, in send_request
    kwargs[key] = self.replace_load(value)
  File "E:\Project_python\2TestCMS2.0\common\requests_util.py", line 89, in replace_load
    int_value = int(num)
ValueError: invalid literal for int() with base 10: 'ectiveDateTime": "", "frequencyValue": "ddt{{1}}", "frequencyUnit": "ddt{{1}}", "matchAll": "ddt{{false}}", "condition": "(A1 * B1) > 0 &&  (A1 / B1)>0", "conditionDetail": "ddt{{1}}", "frequencyChec

[2023-05-28 17:16:24,974] logger_util.py->error_log line:65 [INFO] 分析YAML文件异常：异常信息: Traceback (most recent call last):
  File "E:\Project_python\2TestCMS2.0\common\requests_util.py", line 300, in send_request
    kwargs[key] = self.replace_load(value)
  File "E:\Project_python\2TestCMS2.0\common\requests_util.py", line 89, in replace_load
    int_value = int(num)
ValueError: invalid literal for int() with base 10: 'ectiveDateTime": "", "frequencyValue": "ddt{{1}}", "frequencyUnit": "ddt{{1}}", "matchAll": "ddt{{false}}", "condition": "(A1 * B1) > 0 &&  (A1 / B1)>0", "conditionDetail": "ddt{{1}}", "frequencyChec

During handling of the above exception, another exception occurred:

Traceback (most recent call last):
  File "E:\Project_python\2TestCMS2.0\common\requests_util.py", line 179, in analysis_yaml
    res = self.send_request(name =name,method=method,
  File "E:\Project_python\2TestCMS2.0\common\requests_util.py", line 320, in send_request
    error_log("发送请求异常：异常信息: %s" % str(traceback.format_exc()))
  File "E:\Project_python\2TestCMS2.0\common\logger_util.py", line 66, in error_log
    raise Exception(log_message)
Exception: 发送请求异常：异常信息: Traceback (most recent call last):
  File "E:\Project_python\2TestCMS2.0\common\requests_util.py", line 300, in send_request
    kwargs[key] = self.replace_load(value)
  File "E:\Project_python\2TestCMS2.0\common\requests_util.py", line 89, in replace_load
    int_value = int(num)
ValueError: invalid literal for int() with base 10: 'ectiveDateTime": "", "frequencyValue": "ddt{{1}}", "frequencyUnit": "ddt{{1}}", "matchAll": "ddt{{false}}", "condition": "(A1 * B1) > 0 &&  (A1 / B1)>0", "conditionDetail": "ddt{{1}}", "frequencyChec


[2023-05-28 17:16:25,005] logger_util.py->error_log line:65 [INFO] 发送请求异常：异常信息: Traceback (most recent call last):
  File "E:\Project_python\2TestCMS2.0\common\requests_util.py", line 300, in send_request
    kwargs[key] = self.replace_load(value)
  File "E:\Project_python\2TestCMS2.0\common\requests_util.py", line 81, in replace_load
    int_value = float(num)
ValueError: could not convert string to float: 'ectiveDateTime": "2023-05-22T06:15:31.000Z", "frequencyValue": "ddt{{1}}", "frequencyUnit": "ddt{{1}}", "matchAll": "ddt{{false}}", "condition": "", "conditionDetail": "ddt{{1}}", "frequencyCheck": "ddt{{false}}", "alarmPointIds": "", "triggerType": "ddt{{1}}'

[2023-05-28 17:16:25,005] logger_util.py->error_log line:65 [INFO] 分析YAML文件异常：异常信息: Traceback (most recent call last):
  File "E:\Project_python\2TestCMS2.0\common\requests_util.py", line 300, in send_request
    kwargs[key] = self.replace_load(value)
  File "E:\Project_python\2TestCMS2.0\common\requests_util.py", line 81, in replace_load
    int_value = float(num)
ValueError: could not convert string to float: 'ectiveDateTime": "2023-05-22T06:15:31.000Z", "frequencyValue": "ddt{{1}}", "frequencyUnit": "ddt{{1}}", "matchAll": "ddt{{false}}", "condition": "", "conditionDetail": "ddt{{1}}", "frequencyCheck": "ddt{{false}}", "alarmPointIds": "", "triggerType": "ddt{{1}}'

During handling of the above exception, another exception occurred:

Traceback (most recent call last):
  File "E:\Project_python\2TestCMS2.0\common\requests_util.py", line 179, in analysis_yaml
    res = self.send_request(name =name,method=method,
  File "E:\Project_python\2TestCMS2.0\common\requests_util.py", line 320, in send_request
    error_log("发送请求异常：异常信息: %s" % str(traceback.format_exc()))
  File "E:\Project_python\2TestCMS2.0\common\logger_util.py", line 66, in error_log
    raise Exception(log_message)
Exception: 发送请求异常：异常信息: Traceback (most recent call last):
  File "E:\Project_python\2TestCMS2.0\common\requests_util.py", line 300, in send_request
    kwargs[key] = self.replace_load(value)
  File "E:\Project_python\2TestCMS2.0\common\requests_util.py", line 81, in replace_load
    int_value = float(num)
ValueError: could not convert string to float: 'ectiveDateTime": "2023-05-22T06:15:31.000Z", "frequencyValue": "ddt{{1}}", "frequencyUnit": "ddt{{1}}", "matchAll": "ddt{{false}}", "condition": "", "conditionDetail": "ddt{{1}}", "frequencyCheck": "ddt{{false}}", "alarmPointIds": "", "triggerType": "ddt{{1}}'


[2023-05-28 17:16:25,034] logger_util.py->error_log line:65 [INFO] 发送请求异常：异常信息: Traceback (most recent call last):
  File "E:\Project_python\2TestCMS2.0\common\requests_util.py", line 300, in send_request
    kwargs[key] = self.replace_load(value)
  File "E:\Project_python\2TestCMS2.0\common\requests_util.py", line 81, in replace_load
    int_value = float(num)
ValueError: could not convert string to float: 'ectiveDateTime": "2023-05-22T06:15:31.000Z", "frequencyValue": "ddt{{5}}", "frequencyUnit": "ddt{{2}}", "matchAll": "ddt{{false}}", "condition": "", "conditionDetail": "ddt{{1}}", "frequencyCheck": "ddt{{false}}", "alarmPointIds": "", "triggerType": "ddt{{1}}'

[2023-05-28 17:16:25,035] logger_util.py->error_log line:65 [INFO] 分析YAML文件异常：异常信息: Traceback (most recent call last):
  File "E:\Project_python\2TestCMS2.0\common\requests_util.py", line 300, in send_request
    kwargs[key] = self.replace_load(value)
  File "E:\Project_python\2TestCMS2.0\common\requests_util.py", line 81, in replace_load
    int_value = float(num)
ValueError: could not convert string to float: 'ectiveDateTime": "2023-05-22T06:15:31.000Z", "frequencyValue": "ddt{{5}}", "frequencyUnit": "ddt{{2}}", "matchAll": "ddt{{false}}", "condition": "", "conditionDetail": "ddt{{1}}", "frequencyCheck": "ddt{{false}}", "alarmPointIds": "", "triggerType": "ddt{{1}}'

During handling of the above exception, another exception occurred:

Traceback (most recent call last):
  File "E:\Project_python\2TestCMS2.0\common\requests_util.py", line 179, in analysis_yaml
    res = self.send_request(name =name,method=method,
  File "E:\Project_python\2TestCMS2.0\common\requests_util.py", line 320, in send_request
    error_log("发送请求异常：异常信息: %s" % str(traceback.format_exc()))
  File "E:\Project_python\2TestCMS2.0\common\logger_util.py", line 66, in error_log
    raise Exception(log_message)
Exception: 发送请求异常：异常信息: Traceback (most recent call last):
  File "E:\Project_python\2TestCMS2.0\common\requests_util.py", line 300, in send_request
    kwargs[key] = self.replace_load(value)
  File "E:\Project_python\2TestCMS2.0\common\requests_util.py", line 81, in replace_load
    int_value = float(num)
ValueError: could not convert string to float: 'ectiveDateTime": "2023-05-22T06:15:31.000Z", "frequencyValue": "ddt{{5}}", "frequencyUnit": "ddt{{2}}", "matchAll": "ddt{{false}}", "condition": "", "conditionDetail": "ddt{{1}}", "frequencyCheck": "ddt{{false}}", "alarmPointIds": "", "triggerType": "ddt{{1}}'


[2023-05-28 17:16:25,064] logger_util.py->error_log line:65 [INFO] 发送请求异常：异常信息: Traceback (most recent call last):
  File "E:\Project_python\2TestCMS2.0\common\requests_util.py", line 300, in send_request
    kwargs[key] = self.replace_load(value)
  File "E:\Project_python\2TestCMS2.0\common\requests_util.py", line 81, in replace_load
    int_value = float(num)
ValueError: could not convert string to float: 'ectiveDateTime": "2023-05-22T06:15:31.000Z", "frequencyValue": "ddt{{1}}", "frequencyUnit": "ddt{{3}}", "matchAll": "ddt{{false}}", "condition": "", "conditionDetail": "ddt{{1}}", "frequencyCheck": "ddt{{false}}", "alarmPointIds": "", "triggerType": "ddt{{1}}'

[2023-05-28 17:16:25,064] logger_util.py->error_log line:65 [INFO] 分析YAML文件异常：异常信息: Traceback (most recent call last):
  File "E:\Project_python\2TestCMS2.0\common\requests_util.py", line 300, in send_request
    kwargs[key] = self.replace_load(value)
  File "E:\Project_python\2TestCMS2.0\common\requests_util.py", line 81, in replace_load
    int_value = float(num)
ValueError: could not convert string to float: 'ectiveDateTime": "2023-05-22T06:15:31.000Z", "frequencyValue": "ddt{{1}}", "frequencyUnit": "ddt{{3}}", "matchAll": "ddt{{false}}", "condition": "", "conditionDetail": "ddt{{1}}", "frequencyCheck": "ddt{{false}}", "alarmPointIds": "", "triggerType": "ddt{{1}}'

During handling of the above exception, another exception occurred:

Traceback (most recent call last):
  File "E:\Project_python\2TestCMS2.0\common\requests_util.py", line 179, in analysis_yaml
    res = self.send_request(name =name,method=method,
  File "E:\Project_python\2TestCMS2.0\common\requests_util.py", line 320, in send_request
    error_log("发送请求异常：异常信息: %s" % str(traceback.format_exc()))
  File "E:\Project_python\2TestCMS2.0\common\logger_util.py", line 66, in error_log
    raise Exception(log_message)
Exception: 发送请求异常：异常信息: Traceback (most recent call last):
  File "E:\Project_python\2TestCMS2.0\common\requests_util.py", line 300, in send_request
    kwargs[key] = self.replace_load(value)
  File "E:\Project_python\2TestCMS2.0\common\requests_util.py", line 81, in replace_load
    int_value = float(num)
ValueError: could not convert string to float: 'ectiveDateTime": "2023-05-22T06:15:31.000Z", "frequencyValue": "ddt{{1}}", "frequencyUnit": "ddt{{3}}", "matchAll": "ddt{{false}}", "condition": "", "conditionDetail": "ddt{{1}}", "frequencyCheck": "ddt{{false}}", "alarmPointIds": "", "triggerType": "ddt{{1}}'


[2023-05-28 17:16:25,094] logger_util.py->error_log line:65 [INFO] 发送请求异常：异常信息: Traceback (most recent call last):
  File "E:\Project_python\2TestCMS2.0\common\requests_util.py", line 300, in send_request
    kwargs[key] = self.replace_load(value)
  File "E:\Project_python\2TestCMS2.0\common\requests_util.py", line 81, in replace_load
    int_value = float(num)
ValueError: could not convert string to float: 'ectiveDateTime": "2023-05-22T06:15:31.000Z", "frequencyValue": "ddt{{1}}", "frequencyUnit": "ddt{{4}}", "matchAll": "ddt{{false}}", "condition": "", "conditionDetail": "ddt{{1}}", "frequencyCheck": "ddt{{false}}", "alarmPointIds": "", "triggerType": "ddt{{1}}'

[2023-05-28 17:16:25,095] logger_util.py->error_log line:65 [INFO] 分析YAML文件异常：异常信息: Traceback (most recent call last):
  File "E:\Project_python\2TestCMS2.0\common\requests_util.py", line 300, in send_request
    kwargs[key] = self.replace_load(value)
  File "E:\Project_python\2TestCMS2.0\common\requests_util.py", line 81, in replace_load
    int_value = float(num)
ValueError: could not convert string to float: 'ectiveDateTime": "2023-05-22T06:15:31.000Z", "frequencyValue": "ddt{{1}}", "frequencyUnit": "ddt{{4}}", "matchAll": "ddt{{false}}", "condition": "", "conditionDetail": "ddt{{1}}", "frequencyCheck": "ddt{{false}}", "alarmPointIds": "", "triggerType": "ddt{{1}}'

During handling of the above exception, another exception occurred:

Traceback (most recent call last):
  File "E:\Project_python\2TestCMS2.0\common\requests_util.py", line 179, in analysis_yaml
    res = self.send_request(name =name,method=method,
  File "E:\Project_python\2TestCMS2.0\common\requests_util.py", line 320, in send_request
    error_log("发送请求异常：异常信息: %s" % str(traceback.format_exc()))
  File "E:\Project_python\2TestCMS2.0\common\logger_util.py", line 66, in error_log
    raise Exception(log_message)
Exception: 发送请求异常：异常信息: Traceback (most recent call last):
  File "E:\Project_python\2TestCMS2.0\common\requests_util.py", line 300, in send_request
    kwargs[key] = self.replace_load(value)
  File "E:\Project_python\2TestCMS2.0\common\requests_util.py", line 81, in replace_load
    int_value = float(num)
ValueError: could not convert string to float: 'ectiveDateTime": "2023-05-22T06:15:31.000Z", "frequencyValue": "ddt{{1}}", "frequencyUnit": "ddt{{4}}", "matchAll": "ddt{{false}}", "condition": "", "conditionDetail": "ddt{{1}}", "frequencyCheck": "ddt{{false}}", "alarmPointIds": "", "triggerType": "ddt{{1}}'


[2023-05-28 17:16:25,125] logger_util.py->error_log line:65 [INFO] 发送请求异常：异常信息: Traceback (most recent call last):
  File "E:\Project_python\2TestCMS2.0\common\requests_util.py", line 300, in send_request
    kwargs[key] = self.replace_load(value)
  File "E:\Project_python\2TestCMS2.0\common\requests_util.py", line 81, in replace_load
    int_value = float(num)
ValueError: could not convert string to float: 'ectiveDateTime": "2023-05-22T06:15:31.000Z", "frequencyValue": "ddt{{36}}", "frequencyUnit": "ddt{{5}}", "matchAll": "ddt{{false}}", "condition": "", "conditionDetail": "ddt{{1}}", "frequencyCheck": "ddt{{false}}", "alarmPointIds": "", "triggerType": "ddt{{1}}'

[2023-05-28 17:16:25,125] logger_util.py->error_log line:65 [INFO] 分析YAML文件异常：异常信息: Traceback (most recent call last):
  File "E:\Project_python\2TestCMS2.0\common\requests_util.py", line 300, in send_request
    kwargs[key] = self.replace_load(value)
  File "E:\Project_python\2TestCMS2.0\common\requests_util.py", line 81, in replace_load
    int_value = float(num)
ValueError: could not convert string to float: 'ectiveDateTime": "2023-05-22T06:15:31.000Z", "frequencyValue": "ddt{{36}}", "frequencyUnit": "ddt{{5}}", "matchAll": "ddt{{false}}", "condition": "", "conditionDetail": "ddt{{1}}", "frequencyCheck": "ddt{{false}}", "alarmPointIds": "", "triggerType": "ddt{{1}}'

During handling of the above exception, another exception occurred:

Traceback (most recent call last):
  File "E:\Project_python\2TestCMS2.0\common\requests_util.py", line 179, in analysis_yaml
    res = self.send_request(name =name,method=method,
  File "E:\Project_python\2TestCMS2.0\common\requests_util.py", line 320, in send_request
    error_log("发送请求异常：异常信息: %s" % str(traceback.format_exc()))
  File "E:\Project_python\2TestCMS2.0\common\logger_util.py", line 66, in error_log
    raise Exception(log_message)
Exception: 发送请求异常：异常信息: Traceback (most recent call last):
  File "E:\Project_python\2TestCMS2.0\common\requests_util.py", line 300, in send_request
    kwargs[key] = self.replace_load(value)
  File "E:\Project_python\2TestCMS2.0\common\requests_util.py", line 81, in replace_load
    int_value = float(num)
ValueError: could not convert string to float: 'ectiveDateTime": "2023-05-22T06:15:31.000Z", "frequencyValue": "ddt{{36}}", "frequencyUnit": "ddt{{5}}", "matchAll": "ddt{{false}}", "condition": "", "conditionDetail": "ddt{{1}}", "frequencyCheck": "ddt{{false}}", "alarmPointIds": "", "triggerType": "ddt{{1}}'


[2023-05-28 17:16:25,155] logger_util.py->error_log line:65 [INFO] 发送请求异常：异常信息: Traceback (most recent call last):
  File "E:\Project_python\2TestCMS2.0\common\requests_util.py", line 300, in send_request
    kwargs[key] = self.replace_load(value)
  File "E:\Project_python\2TestCMS2.0\common\requests_util.py", line 81, in replace_load
    int_value = float(num)
ValueError: could not convert string to float: 'ectiveDateTime": "2023-05-22T06:15:31.000Z", "frequencyValue": "ddt{{1}}", "frequencyUnit": "ddt{{1}}", "matchAll": "ddt{{true}}", "condition": "G1 ==  true ||  H1 != \'\\u4e2d\\u6587\'", "conditionDetail": "ddt{{1}}", "frequencyCheck": "ddt{{false}}", "alarmPointIds": "", "triggerType": "ddt{{1}}'

[2023-05-28 17:16:25,155] logger_util.py->error_log line:65 [INFO] 分析YAML文件异常：异常信息: Traceback (most recent call last):
  File "E:\Project_python\2TestCMS2.0\common\requests_util.py", line 300, in send_request
    kwargs[key] = self.replace_load(value)
  File "E:\Project_python\2TestCMS2.0\common\requests_util.py", line 81, in replace_load
    int_value = float(num)
ValueError: could not convert string to float: 'ectiveDateTime": "2023-05-22T06:15:31.000Z", "frequencyValue": "ddt{{1}}", "frequencyUnit": "ddt{{1}}", "matchAll": "ddt{{true}}", "condition": "G1 ==  true ||  H1 != \'\\u4e2d\\u6587\'", "conditionDetail": "ddt{{1}}", "frequencyCheck": "ddt{{false}}", "alarmPointIds": "", "triggerType": "ddt{{1}}'

During handling of the above exception, another exception occurred:

Traceback (most recent call last):
  File "E:\Project_python\2TestCMS2.0\common\requests_util.py", line 179, in analysis_yaml
    res = self.send_request(name =name,method=method,
  File "E:\Project_python\2TestCMS2.0\common\requests_util.py", line 320, in send_request
    error_log("发送请求异常：异常信息: %s" % str(traceback.format_exc()))
  File "E:\Project_python\2TestCMS2.0\common\logger_util.py", line 66, in error_log
    raise Exception(log_message)
Exception: 发送请求异常：异常信息: Traceback (most recent call last):
  File "E:\Project_python\2TestCMS2.0\common\requests_util.py", line 300, in send_request
    kwargs[key] = self.replace_load(value)
  File "E:\Project_python\2TestCMS2.0\common\requests_util.py", line 81, in replace_load
    int_value = float(num)
ValueError: could not convert string to float: 'ectiveDateTime": "2023-05-22T06:15:31.000Z", "frequencyValue": "ddt{{1}}", "frequencyUnit": "ddt{{1}}", "matchAll": "ddt{{true}}", "condition": "G1 ==  true ||  H1 != \'\\u4e2d\\u6587\'", "conditionDetail": "ddt{{1}}", "frequencyCheck": "ddt{{false}}", "alarmPointIds": "", "triggerType": "ddt{{1}}'


[2023-05-28 17:16:25,198] logger_util.py->error_log line:65 [INFO] 发送请求异常：异常信息: Traceback (most recent call last):
  File "E:\Project_python\2TestCMS2.0\common\requests_util.py", line 300, in send_request
    kwargs[key] = self.replace_load(value)
  File "E:\Project_python\2TestCMS2.0\common\requests_util.py", line 81, in replace_load
    int_value = float(num)
ValueError: could not convert string to float: 'ectiveDateTime": "2023-05-22T06:15:31.000Z", "frequencyValue": "ddt{{1}}", "frequencyUnit": "ddt{{1}}", "matchAll": "ddt{{true}}", "condition": "A1 + B1)  <=  0 ||  (A1 - B1) <= 0", "conditionDetail": "ddt{{1}}", "frequencyCheck": "ddt{{false}}", "alarmPointIds": "", "triggerType": "ddt{{1}}'

[2023-05-28 17:16:25,198] logger_util.py->error_log line:65 [INFO] 分析YAML文件异常：异常信息: Traceback (most recent call last):
  File "E:\Project_python\2TestCMS2.0\common\requests_util.py", line 300, in send_request
    kwargs[key] = self.replace_load(value)
  File "E:\Project_python\2TestCMS2.0\common\requests_util.py", line 81, in replace_load
    int_value = float(num)
ValueError: could not convert string to float: 'ectiveDateTime": "2023-05-22T06:15:31.000Z", "frequencyValue": "ddt{{1}}", "frequencyUnit": "ddt{{1}}", "matchAll": "ddt{{true}}", "condition": "A1 + B1)  <=  0 ||  (A1 - B1) <= 0", "conditionDetail": "ddt{{1}}", "frequencyCheck": "ddt{{false}}", "alarmPointIds": "", "triggerType": "ddt{{1}}'

During handling of the above exception, another exception occurred:

Traceback (most recent call last):
  File "E:\Project_python\2TestCMS2.0\common\requests_util.py", line 179, in analysis_yaml
    res = self.send_request(name =name,method=method,
  File "E:\Project_python\2TestCMS2.0\common\requests_util.py", line 320, in send_request
    error_log("发送请求异常：异常信息: %s" % str(traceback.format_exc()))
  File "E:\Project_python\2TestCMS2.0\common\logger_util.py", line 66, in error_log
    raise Exception(log_message)
Exception: 发送请求异常：异常信息: Traceback (most recent call last):
  File "E:\Project_python\2TestCMS2.0\common\requests_util.py", line 300, in send_request
    kwargs[key] = self.replace_load(value)
  File "E:\Project_python\2TestCMS2.0\common\requests_util.py", line 81, in replace_load
    int_value = float(num)
ValueError: could not convert string to float: 'ectiveDateTime": "2023-05-22T06:15:31.000Z", "frequencyValue": "ddt{{1}}", "frequencyUnit": "ddt{{1}}", "matchAll": "ddt{{true}}", "condition": "A1 + B1)  <=  0 ||  (A1 - B1) <= 0", "conditionDetail": "ddt{{1}}", "frequencyCheck": "ddt{{false}}", "alarmPointIds": "", "triggerType": "ddt{{1}}'


[2023-05-28 17:16:25,230] logger_util.py->error_log line:65 [INFO] 发送请求异常：异常信息: Traceback (most recent call last):
  File "E:\Project_python\2TestCMS2.0\common\requests_util.py", line 300, in send_request
    kwargs[key] = self.replace_load(value)
  File "E:\Project_python\2TestCMS2.0\common\requests_util.py", line 81, in replace_load
    int_value = float(num)
ValueError: could not convert string to float: 'ectiveDateTime": "2023-05-22T06:15:31.000Z", "frequencyValue": "ddt{{1}}", "frequencyUnit": "ddt{{1}}", "matchAll": "ddt{{true}}", "condition": "(A1 * B1) > 0 &&  (A1 / B1)>0", "conditionDetail": "ddt{{1}}", "frequencyCheck": "ddt{{false}}", "alarmPointIds": "", "triggerType": "ddt{{1}}'

[2023-05-28 17:16:25,230] logger_util.py->error_log line:65 [INFO] 分析YAML文件异常：异常信息: Traceback (most recent call last):
  File "E:\Project_python\2TestCMS2.0\common\requests_util.py", line 300, in send_request
    kwargs[key] = self.replace_load(value)
  File "E:\Project_python\2TestCMS2.0\common\requests_util.py", line 81, in replace_load
    int_value = float(num)
ValueError: could not convert string to float: 'ectiveDateTime": "2023-05-22T06:15:31.000Z", "frequencyValue": "ddt{{1}}", "frequencyUnit": "ddt{{1}}", "matchAll": "ddt{{true}}", "condition": "(A1 * B1) > 0 &&  (A1 / B1)>0", "conditionDetail": "ddt{{1}}", "frequencyCheck": "ddt{{false}}", "alarmPointIds": "", "triggerType": "ddt{{1}}'

During handling of the above exception, another exception occurred:

Traceback (most recent call last):
  File "E:\Project_python\2TestCMS2.0\common\requests_util.py", line 179, in analysis_yaml
    res = self.send_request(name =name,method=method,
  File "E:\Project_python\2TestCMS2.0\common\requests_util.py", line 320, in send_request
    error_log("发送请求异常：异常信息: %s" % str(traceback.format_exc()))
  File "E:\Project_python\2TestCMS2.0\common\logger_util.py", line 66, in error_log
    raise Exception(log_message)
Exception: 发送请求异常：异常信息: Traceback (most recent call last):
  File "E:\Project_python\2TestCMS2.0\common\requests_util.py", line 300, in send_request
    kwargs[key] = self.replace_load(value)
  File "E:\Project_python\2TestCMS2.0\common\requests_util.py", line 81, in replace_load
    int_value = float(num)
ValueError: could not convert string to float: 'ectiveDateTime": "2023-05-22T06:15:31.000Z", "frequencyValue": "ddt{{1}}", "frequencyUnit": "ddt{{1}}", "matchAll": "ddt{{true}}", "condition": "(A1 * B1) > 0 &&  (A1 / B1)>0", "conditionDetail": "ddt{{1}}", "frequencyCheck": "ddt{{false}}", "alarmPointIds": "", "triggerType": "ddt{{1}}'


