[2023-05-26 15:59:34,270] logger_util.py->write_log line:61 [INFO] -------------接口请求开始-----------
[2023-05-26 15:59:34,270] logger_util.py->write_log line:61 [INFO] 接口名称：设置归档表触发配置
[2023-05-26 15:59:34,270] logger_util.py->write_log line:61 [INFO] 接口方式：put
[2023-05-26 15:59:34,270] logger_util.py->write_log line:61 [INFO] 接口路径：http://127.0.0.1:18000/api/v1/dataconfig/filingtable/8cd7d30c-dd00-4708-9bd5-67edf283ca3a/triggers
[2023-05-26 15:59:34,270] logger_util.py->write_log line:61 [INFO] 请求头：{'Content-Type': 'application/json; =UTF-8', 'X-Project': '83d42c5d5ad141bba528b7690b19996e'}
[2023-05-26 15:59:34,271] logger_util.py->write_log line:61 [INFO] 请求参数：[{'effectiveDateTime': None, 'frequencyValue': 1, 'frequencyUnit': 1, 'matchAll': False, 'condition': 'G1 ==  true', 'conditionDetail': 1, 'frequencyCheck': False, 'alarmPointIds': None, 'triggerType': 2}]
[2023-05-26 15:59:34,271] logger_util.py->write_log line:61 [INFO] 文件上传：None
[2023-05-26 15:59:36,332] logger_util.py->error_log line:65 [INFO] 断言失败:status_code不等于200
[2023-05-26 15:59:36,332] logger_util.py->write_log line:61 [INFO] 接口请求失败！
[2023-05-26 15:59:36,333] logger_util.py->write_log line:61 [INFO] -------------接口请求结束-----------

[2023-05-26 15:59:36,373] logger_util.py->error_log line:65 [INFO] 断言异常：异常信息: Traceback (most recent call last):
  File "E:\Project_python\2TestCMS2.0\common\requests_util.py", line 348, in validate_result
    error_log("断言失败:"+assert_key+"不等于"+str(assert_value))
  File "E:\Project_python\2TestCMS2.0\common\logger_util.py", line 66, in error_log
    raise Exception(log_message)
Exception: 断言失败:status_code不等于200

[2023-05-26 15:59:36,373] logger_util.py->error_log line:65 [INFO] 分析YAML文件异常：异常信息: Traceback (most recent call last):
  File "E:\Project_python\2TestCMS2.0\common\requests_util.py", line 348, in validate_result
    error_log("断言失败:"+assert_key+"不等于"+str(assert_value))
  File "E:\Project_python\2TestCMS2.0\common\logger_util.py", line 66, in error_log
    raise Exception(log_message)
Exception: 断言失败:status_code不等于200

During handling of the above exception, another exception occurred:

Traceback (most recent call last):
  File "E:\Project_python\2TestCMS2.0\common\requests_util.py", line 247, in analysis_yaml
    self.validate_result(yq_result, return_text, status_code)
  File "E:\Project_python\2TestCMS2.0\common\requests_util.py", line 398, in validate_result
    error_log("断言异常：异常信息: %s" % str(traceback.format_exc()))
  File "E:\Project_python\2TestCMS2.0\common\logger_util.py", line 66, in error_log
    raise Exception(log_message)
Exception: 断言异常：异常信息: Traceback (most recent call last):
  File "E:\Project_python\2TestCMS2.0\common\requests_util.py", line 348, in validate_result
    error_log("断言失败:"+assert_key+"不等于"+str(assert_value))
  File "E:\Project_python\2TestCMS2.0\common\logger_util.py", line 66, in error_log
    raise Exception(log_message)
Exception: 断言失败:status_code不等于200


[2023-05-26 15:59:36,548] logger_util.py->write_log line:61 [INFO] -------------接口请求开始-----------
[2023-05-26 15:59:36,548] logger_util.py->write_log line:61 [INFO] 接口名称：设置归档表触发配置
[2023-05-26 15:59:36,548] logger_util.py->write_log line:61 [INFO] 接口方式：put
[2023-05-26 15:59:36,548] logger_util.py->write_log line:61 [INFO] 接口路径：http://127.0.0.1:18000/api/v1/dataconfig/filingtable/8cd7d30c-dd00-4708-9bd5-67edf283ca3a/triggers
[2023-05-26 15:59:36,548] logger_util.py->write_log line:61 [INFO] 请求头：{'Content-Type': 'application/json; =UTF-8', 'X-Project': '83d42c5d5ad141bba528b7690b19996e'}
[2023-05-26 15:59:36,548] logger_util.py->write_log line:61 [INFO] 请求参数：[{'effectiveDateTime': None, 'frequencyValue': 1, 'frequencyUnit': 1, 'matchAll': False, 'condition': 'G1 ==  true', 'conditionDetail': 2, 'frequencyCheck': False, 'alarmPointIds': None, 'triggerType': 2}]
[2023-05-26 15:59:36,548] logger_util.py->write_log line:61 [INFO] 文件上传：None
[2023-05-26 15:59:38,589] logger_util.py->error_log line:65 [INFO] 断言失败:status_code不等于200
[2023-05-26 15:59:38,589] logger_util.py->write_log line:61 [INFO] 接口请求失败！
[2023-05-26 15:59:38,590] logger_util.py->write_log line:61 [INFO] -------------接口请求结束-----------

[2023-05-26 15:59:38,590] logger_util.py->error_log line:65 [INFO] 断言异常：异常信息: Traceback (most recent call last):
  File "E:\Project_python\2TestCMS2.0\common\requests_util.py", line 348, in validate_result
    error_log("断言失败:"+assert_key+"不等于"+str(assert_value))
  File "E:\Project_python\2TestCMS2.0\common\logger_util.py", line 66, in error_log
    raise Exception(log_message)
Exception: 断言失败:status_code不等于200

[2023-05-26 15:59:38,590] logger_util.py->error_log line:65 [INFO] 分析YAML文件异常：异常信息: Traceback (most recent call last):
  File "E:\Project_python\2TestCMS2.0\common\requests_util.py", line 348, in validate_result
    error_log("断言失败:"+assert_key+"不等于"+str(assert_value))
  File "E:\Project_python\2TestCMS2.0\common\logger_util.py", line 66, in error_log
    raise Exception(log_message)
Exception: 断言失败:status_code不等于200

During handling of the above exception, another exception occurred:

Traceback (most recent call last):
  File "E:\Project_python\2TestCMS2.0\common\requests_util.py", line 247, in analysis_yaml
    self.validate_result(yq_result, return_text, status_code)
  File "E:\Project_python\2TestCMS2.0\common\requests_util.py", line 398, in validate_result
    error_log("断言异常：异常信息: %s" % str(traceback.format_exc()))
  File "E:\Project_python\2TestCMS2.0\common\logger_util.py", line 66, in error_log
    raise Exception(log_message)
Exception: 断言异常：异常信息: Traceback (most recent call last):
  File "E:\Project_python\2TestCMS2.0\common\requests_util.py", line 348, in validate_result
    error_log("断言失败:"+assert_key+"不等于"+str(assert_value))
  File "E:\Project_python\2TestCMS2.0\common\logger_util.py", line 66, in error_log
    raise Exception(log_message)
Exception: 断言失败:status_code不等于200


[2023-05-26 15:59:38,617] logger_util.py->write_log line:61 [INFO] -------------接口请求开始-----------
[2023-05-26 15:59:38,617] logger_util.py->write_log line:61 [INFO] 接口名称：设置归档表触发配置
[2023-05-26 15:59:38,618] logger_util.py->write_log line:61 [INFO] 接口方式：put
[2023-05-26 15:59:38,618] logger_util.py->write_log line:61 [INFO] 接口路径：http://127.0.0.1:18000/api/v1/dataconfig/filingtable/8cd7d30c-dd00-4708-9bd5-67edf283ca3a/triggers
[2023-05-26 15:59:38,618] logger_util.py->write_log line:61 [INFO] 请求头：{'Content-Type': 'application/json; =UTF-8', 'X-Project': '83d42c5d5ad141bba528b7690b19996e'}
[2023-05-26 15:59:38,618] logger_util.py->write_log line:61 [INFO] 请求参数：[{'effectiveDateTime': None, 'frequencyValue': 1, 'frequencyUnit': 1, 'matchAll': False, 'condition': 'G1 ==  true', 'conditionDetail': 3, 'frequencyCheck': False, 'alarmPointIds': None, 'triggerType': 2}]
[2023-05-26 15:59:38,618] logger_util.py->write_log line:61 [INFO] 文件上传：None
[2023-05-26 15:59:40,675] logger_util.py->error_log line:65 [INFO] 断言失败:status_code不等于200
[2023-05-26 15:59:40,675] logger_util.py->write_log line:61 [INFO] 接口请求失败！
[2023-05-26 15:59:40,675] logger_util.py->write_log line:61 [INFO] -------------接口请求结束-----------

[2023-05-26 15:59:40,676] logger_util.py->error_log line:65 [INFO] 断言异常：异常信息: Traceback (most recent call last):
  File "E:\Project_python\2TestCMS2.0\common\requests_util.py", line 348, in validate_result
    error_log("断言失败:"+assert_key+"不等于"+str(assert_value))
  File "E:\Project_python\2TestCMS2.0\common\logger_util.py", line 66, in error_log
    raise Exception(log_message)
Exception: 断言失败:status_code不等于200

[2023-05-26 15:59:40,676] logger_util.py->error_log line:65 [INFO] 分析YAML文件异常：异常信息: Traceback (most recent call last):
  File "E:\Project_python\2TestCMS2.0\common\requests_util.py", line 348, in validate_result
    error_log("断言失败:"+assert_key+"不等于"+str(assert_value))
  File "E:\Project_python\2TestCMS2.0\common\logger_util.py", line 66, in error_log
    raise Exception(log_message)
Exception: 断言失败:status_code不等于200

During handling of the above exception, another exception occurred:

Traceback (most recent call last):
  File "E:\Project_python\2TestCMS2.0\common\requests_util.py", line 247, in analysis_yaml
    self.validate_result(yq_result, return_text, status_code)
  File "E:\Project_python\2TestCMS2.0\common\requests_util.py", line 398, in validate_result
    error_log("断言异常：异常信息: %s" % str(traceback.format_exc()))
  File "E:\Project_python\2TestCMS2.0\common\logger_util.py", line 66, in error_log
    raise Exception(log_message)
Exception: 断言异常：异常信息: Traceback (most recent call last):
  File "E:\Project_python\2TestCMS2.0\common\requests_util.py", line 348, in validate_result
    error_log("断言失败:"+assert_key+"不等于"+str(assert_value))
  File "E:\Project_python\2TestCMS2.0\common\logger_util.py", line 66, in error_log
    raise Exception(log_message)
Exception: 断言失败:status_code不等于200


[2023-05-26 15:59:40,702] logger_util.py->write_log line:61 [INFO] -------------接口请求开始-----------
[2023-05-26 15:59:40,702] logger_util.py->write_log line:61 [INFO] 接口名称：设置归档表触发配置
[2023-05-26 15:59:40,702] logger_util.py->write_log line:61 [INFO] 接口方式：put
[2023-05-26 15:59:40,702] logger_util.py->write_log line:61 [INFO] 接口路径：http://127.0.0.1:18000/api/v1/dataconfig/filingtable/8cd7d30c-dd00-4708-9bd5-67edf283ca3a/triggers
[2023-05-26 15:59:40,702] logger_util.py->write_log line:61 [INFO] 请求头：{'Content-Type': 'application/json; =UTF-8', 'X-Project': '83d42c5d5ad141bba528b7690b19996e'}
[2023-05-26 15:59:40,702] logger_util.py->write_log line:61 [INFO] 请求参数：[{'effectiveDateTime': None, 'frequencyValue': 1, 'frequencyUnit': 1, 'matchAll': False, 'condition': 'G1 ==  true', 'conditionDetail': 1, 'frequencyCheck': True, 'alarmPointIds': None, 'triggerType': 2}]
[2023-05-26 15:59:40,702] logger_util.py->write_log line:61 [INFO] 文件上传：None
[2023-05-26 15:59:42,763] logger_util.py->error_log line:65 [INFO] 断言失败:status_code不等于200
[2023-05-26 15:59:42,764] logger_util.py->write_log line:61 [INFO] 接口请求失败！
[2023-05-26 15:59:42,764] logger_util.py->write_log line:61 [INFO] -------------接口请求结束-----------

[2023-05-26 15:59:42,765] logger_util.py->error_log line:65 [INFO] 断言异常：异常信息: Traceback (most recent call last):
  File "E:\Project_python\2TestCMS2.0\common\requests_util.py", line 348, in validate_result
    error_log("断言失败:"+assert_key+"不等于"+str(assert_value))
  File "E:\Project_python\2TestCMS2.0\common\logger_util.py", line 66, in error_log
    raise Exception(log_message)
Exception: 断言失败:status_code不等于200

[2023-05-26 15:59:42,766] logger_util.py->error_log line:65 [INFO] 分析YAML文件异常：异常信息: Traceback (most recent call last):
  File "E:\Project_python\2TestCMS2.0\common\requests_util.py", line 348, in validate_result
    error_log("断言失败:"+assert_key+"不等于"+str(assert_value))
  File "E:\Project_python\2TestCMS2.0\common\logger_util.py", line 66, in error_log
    raise Exception(log_message)
Exception: 断言失败:status_code不等于200

During handling of the above exception, another exception occurred:

Traceback (most recent call last):
  File "E:\Project_python\2TestCMS2.0\common\requests_util.py", line 247, in analysis_yaml
    self.validate_result(yq_result, return_text, status_code)
  File "E:\Project_python\2TestCMS2.0\common\requests_util.py", line 398, in validate_result
    error_log("断言异常：异常信息: %s" % str(traceback.format_exc()))
  File "E:\Project_python\2TestCMS2.0\common\logger_util.py", line 66, in error_log
    raise Exception(log_message)
Exception: 断言异常：异常信息: Traceback (most recent call last):
  File "E:\Project_python\2TestCMS2.0\common\requests_util.py", line 348, in validate_result
    error_log("断言失败:"+assert_key+"不等于"+str(assert_value))
  File "E:\Project_python\2TestCMS2.0\common\logger_util.py", line 66, in error_log
    raise Exception(log_message)
Exception: 断言失败:status_code不等于200


[2023-05-26 15:59:42,810] logger_util.py->write_log line:61 [INFO] -------------接口请求开始-----------
[2023-05-26 15:59:42,810] logger_util.py->write_log line:61 [INFO] 接口名称：设置归档表触发配置
[2023-05-26 15:59:42,810] logger_util.py->write_log line:61 [INFO] 接口方式：put
[2023-05-26 15:59:42,810] logger_util.py->write_log line:61 [INFO] 接口路径：http://127.0.0.1:18000/api/v1/dataconfig/filingtable/8cd7d30c-dd00-4708-9bd5-67edf283ca3a/triggers
[2023-05-26 15:59:42,810] logger_util.py->write_log line:61 [INFO] 请求头：{'Content-Type': 'application/json; =UTF-8', 'X-Project': '83d42c5d5ad141bba528b7690b19996e'}
[2023-05-26 15:59:42,810] logger_util.py->write_log line:61 [INFO] 请求参数：[{'effectiveDateTime': None, 'frequencyValue': 5, 'frequencyUnit': 2, 'matchAll': False, 'condition': 'G1 ==  true', 'conditionDetail': 1, 'frequencyCheck': True, 'alarmPointIds': None, 'triggerType': 2}]
[2023-05-26 15:59:42,811] logger_util.py->write_log line:61 [INFO] 文件上传：None
[2023-05-26 15:59:44,847] logger_util.py->error_log line:65 [INFO] 断言失败:status_code不等于200
[2023-05-26 15:59:44,847] logger_util.py->write_log line:61 [INFO] 接口请求失败！
[2023-05-26 15:59:44,848] logger_util.py->write_log line:61 [INFO] -------------接口请求结束-----------

[2023-05-26 15:59:44,849] logger_util.py->error_log line:65 [INFO] 断言异常：异常信息: Traceback (most recent call last):
  File "E:\Project_python\2TestCMS2.0\common\requests_util.py", line 348, in validate_result
    error_log("断言失败:"+assert_key+"不等于"+str(assert_value))
  File "E:\Project_python\2TestCMS2.0\common\logger_util.py", line 66, in error_log
    raise Exception(log_message)
Exception: 断言失败:status_code不等于200

[2023-05-26 15:59:44,850] logger_util.py->error_log line:65 [INFO] 分析YAML文件异常：异常信息: Traceback (most recent call last):
  File "E:\Project_python\2TestCMS2.0\common\requests_util.py", line 348, in validate_result
    error_log("断言失败:"+assert_key+"不等于"+str(assert_value))
  File "E:\Project_python\2TestCMS2.0\common\logger_util.py", line 66, in error_log
    raise Exception(log_message)
Exception: 断言失败:status_code不等于200

During handling of the above exception, another exception occurred:

Traceback (most recent call last):
  File "E:\Project_python\2TestCMS2.0\common\requests_util.py", line 247, in analysis_yaml
    self.validate_result(yq_result, return_text, status_code)
  File "E:\Project_python\2TestCMS2.0\common\requests_util.py", line 398, in validate_result
    error_log("断言异常：异常信息: %s" % str(traceback.format_exc()))
  File "E:\Project_python\2TestCMS2.0\common\logger_util.py", line 66, in error_log
    raise Exception(log_message)
Exception: 断言异常：异常信息: Traceback (most recent call last):
  File "E:\Project_python\2TestCMS2.0\common\requests_util.py", line 348, in validate_result
    error_log("断言失败:"+assert_key+"不等于"+str(assert_value))
  File "E:\Project_python\2TestCMS2.0\common\logger_util.py", line 66, in error_log
    raise Exception(log_message)
Exception: 断言失败:status_code不等于200


[2023-05-26 15:59:44,877] logger_util.py->write_log line:61 [INFO] -------------接口请求开始-----------
[2023-05-26 15:59:44,877] logger_util.py->write_log line:61 [INFO] 接口名称：设置归档表触发配置
[2023-05-26 15:59:44,877] logger_util.py->write_log line:61 [INFO] 接口方式：put
[2023-05-26 15:59:44,877] logger_util.py->write_log line:61 [INFO] 接口路径：http://127.0.0.1:18000/api/v1/dataconfig/filingtable/8cd7d30c-dd00-4708-9bd5-67edf283ca3a/triggers
[2023-05-26 15:59:44,877] logger_util.py->write_log line:61 [INFO] 请求头：{'Content-Type': 'application/json; =UTF-8', 'X-Project': '83d42c5d5ad141bba528b7690b19996e'}
[2023-05-26 15:59:44,877] logger_util.py->write_log line:61 [INFO] 请求参数：[{'effectiveDateTime': None, 'frequencyValue': 1, 'frequencyUnit': 3, 'matchAll': False, 'condition': 'G1 ==  true', 'conditionDetail': 1, 'frequencyCheck': True, 'alarmPointIds': None, 'triggerType': 2}]
[2023-05-26 15:59:44,877] logger_util.py->write_log line:61 [INFO] 文件上传：None
[2023-05-26 15:59:46,929] logger_util.py->error_log line:65 [INFO] 断言失败:status_code不等于200
[2023-05-26 15:59:46,929] logger_util.py->write_log line:61 [INFO] 接口请求失败！
[2023-05-26 15:59:46,930] logger_util.py->write_log line:61 [INFO] -------------接口请求结束-----------

[2023-05-26 15:59:46,931] logger_util.py->error_log line:65 [INFO] 断言异常：异常信息: Traceback (most recent call last):
  File "E:\Project_python\2TestCMS2.0\common\requests_util.py", line 348, in validate_result
    error_log("断言失败:"+assert_key+"不等于"+str(assert_value))
  File "E:\Project_python\2TestCMS2.0\common\logger_util.py", line 66, in error_log
    raise Exception(log_message)
Exception: 断言失败:status_code不等于200

[2023-05-26 15:59:46,931] logger_util.py->error_log line:65 [INFO] 分析YAML文件异常：异常信息: Traceback (most recent call last):
  File "E:\Project_python\2TestCMS2.0\common\requests_util.py", line 348, in validate_result
    error_log("断言失败:"+assert_key+"不等于"+str(assert_value))
  File "E:\Project_python\2TestCMS2.0\common\logger_util.py", line 66, in error_log
    raise Exception(log_message)
Exception: 断言失败:status_code不等于200

During handling of the above exception, another exception occurred:

Traceback (most recent call last):
  File "E:\Project_python\2TestCMS2.0\common\requests_util.py", line 247, in analysis_yaml
    self.validate_result(yq_result, return_text, status_code)
  File "E:\Project_python\2TestCMS2.0\common\requests_util.py", line 398, in validate_result
    error_log("断言异常：异常信息: %s" % str(traceback.format_exc()))
  File "E:\Project_python\2TestCMS2.0\common\logger_util.py", line 66, in error_log
    raise Exception(log_message)
Exception: 断言异常：异常信息: Traceback (most recent call last):
  File "E:\Project_python\2TestCMS2.0\common\requests_util.py", line 348, in validate_result
    error_log("断言失败:"+assert_key+"不等于"+str(assert_value))
  File "E:\Project_python\2TestCMS2.0\common\logger_util.py", line 66, in error_log
    raise Exception(log_message)
Exception: 断言失败:status_code不等于200


[2023-05-26 15:59:46,958] logger_util.py->write_log line:61 [INFO] -------------接口请求开始-----------
[2023-05-26 15:59:46,959] logger_util.py->write_log line:61 [INFO] 接口名称：设置归档表触发配置
[2023-05-26 15:59:46,959] logger_util.py->write_log line:61 [INFO] 接口方式：put
[2023-05-26 15:59:46,959] logger_util.py->write_log line:61 [INFO] 接口路径：http://127.0.0.1:18000/api/v1/dataconfig/filingtable/8cd7d30c-dd00-4708-9bd5-67edf283ca3a/triggers
[2023-05-26 15:59:46,959] logger_util.py->write_log line:61 [INFO] 请求头：{'Content-Type': 'application/json; =UTF-8', 'X-Project': '83d42c5d5ad141bba528b7690b19996e'}
[2023-05-26 15:59:46,959] logger_util.py->write_log line:61 [INFO] 请求参数：[{'effectiveDateTime': None, 'frequencyValue': 1, 'frequencyUnit': 4, 'matchAll': False, 'condition': 'G1 ==  true', 'conditionDetail': 1, 'frequencyCheck': True, 'alarmPointIds': None, 'triggerType': 2}]
[2023-05-26 15:59:46,959] logger_util.py->write_log line:61 [INFO] 文件上传：None
[2023-05-26 15:59:49,014] logger_util.py->error_log line:65 [INFO] 断言失败:status_code不等于200
[2023-05-26 15:59:49,014] logger_util.py->write_log line:61 [INFO] 接口请求失败！
[2023-05-26 15:59:49,014] logger_util.py->write_log line:61 [INFO] -------------接口请求结束-----------

[2023-05-26 15:59:49,015] logger_util.py->error_log line:65 [INFO] 断言异常：异常信息: Traceback (most recent call last):
  File "E:\Project_python\2TestCMS2.0\common\requests_util.py", line 348, in validate_result
    error_log("断言失败:"+assert_key+"不等于"+str(assert_value))
  File "E:\Project_python\2TestCMS2.0\common\logger_util.py", line 66, in error_log
    raise Exception(log_message)
Exception: 断言失败:status_code不等于200

[2023-05-26 15:59:49,015] logger_util.py->error_log line:65 [INFO] 分析YAML文件异常：异常信息: Traceback (most recent call last):
  File "E:\Project_python\2TestCMS2.0\common\requests_util.py", line 348, in validate_result
    error_log("断言失败:"+assert_key+"不等于"+str(assert_value))
  File "E:\Project_python\2TestCMS2.0\common\logger_util.py", line 66, in error_log
    raise Exception(log_message)
Exception: 断言失败:status_code不等于200

During handling of the above exception, another exception occurred:

Traceback (most recent call last):
  File "E:\Project_python\2TestCMS2.0\common\requests_util.py", line 247, in analysis_yaml
    self.validate_result(yq_result, return_text, status_code)
  File "E:\Project_python\2TestCMS2.0\common\requests_util.py", line 398, in validate_result
    error_log("断言异常：异常信息: %s" % str(traceback.format_exc()))
  File "E:\Project_python\2TestCMS2.0\common\logger_util.py", line 66, in error_log
    raise Exception(log_message)
Exception: 断言异常：异常信息: Traceback (most recent call last):
  File "E:\Project_python\2TestCMS2.0\common\requests_util.py", line 348, in validate_result
    error_log("断言失败:"+assert_key+"不等于"+str(assert_value))
  File "E:\Project_python\2TestCMS2.0\common\logger_util.py", line 66, in error_log
    raise Exception(log_message)
Exception: 断言失败:status_code不等于200


[2023-05-26 15:59:49,042] logger_util.py->write_log line:61 [INFO] -------------接口请求开始-----------
[2023-05-26 15:59:49,042] logger_util.py->write_log line:61 [INFO] 接口名称：设置归档表触发配置
[2023-05-26 15:59:49,042] logger_util.py->write_log line:61 [INFO] 接口方式：put
[2023-05-26 15:59:49,042] logger_util.py->write_log line:61 [INFO] 接口路径：http://127.0.0.1:18000/api/v1/dataconfig/filingtable/8cd7d30c-dd00-4708-9bd5-67edf283ca3a/triggers
[2023-05-26 15:59:49,042] logger_util.py->write_log line:61 [INFO] 请求头：{'Content-Type': 'application/json; =UTF-8', 'X-Project': '83d42c5d5ad141bba528b7690b19996e'}
[2023-05-26 15:59:49,042] logger_util.py->write_log line:61 [INFO] 请求参数：[{'effectiveDateTime': None, 'frequencyValue': 36, 'frequencyUnit': 5, 'matchAll': False, 'condition': 'G1 ==  true', 'conditionDetail': 1, 'frequencyCheck': True, 'alarmPointIds': None, 'triggerType': 2}]
[2023-05-26 15:59:49,042] logger_util.py->write_log line:61 [INFO] 文件上传：None
[2023-05-26 15:59:51,094] logger_util.py->error_log line:65 [INFO] 断言失败:status_code不等于200
[2023-05-26 15:59:51,094] logger_util.py->write_log line:61 [INFO] 接口请求失败！
[2023-05-26 15:59:51,094] logger_util.py->write_log line:61 [INFO] -------------接口请求结束-----------

[2023-05-26 15:59:51,095] logger_util.py->error_log line:65 [INFO] 断言异常：异常信息: Traceback (most recent call last):
  File "E:\Project_python\2TestCMS2.0\common\requests_util.py", line 348, in validate_result
    error_log("断言失败:"+assert_key+"不等于"+str(assert_value))
  File "E:\Project_python\2TestCMS2.0\common\logger_util.py", line 66, in error_log
    raise Exception(log_message)
Exception: 断言失败:status_code不等于200

[2023-05-26 15:59:51,096] logger_util.py->error_log line:65 [INFO] 分析YAML文件异常：异常信息: Traceback (most recent call last):
  File "E:\Project_python\2TestCMS2.0\common\requests_util.py", line 348, in validate_result
    error_log("断言失败:"+assert_key+"不等于"+str(assert_value))
  File "E:\Project_python\2TestCMS2.0\common\logger_util.py", line 66, in error_log
    raise Exception(log_message)
Exception: 断言失败:status_code不等于200

During handling of the above exception, another exception occurred:

Traceback (most recent call last):
  File "E:\Project_python\2TestCMS2.0\common\requests_util.py", line 247, in analysis_yaml
    self.validate_result(yq_result, return_text, status_code)
  File "E:\Project_python\2TestCMS2.0\common\requests_util.py", line 398, in validate_result
    error_log("断言异常：异常信息: %s" % str(traceback.format_exc()))
  File "E:\Project_python\2TestCMS2.0\common\logger_util.py", line 66, in error_log
    raise Exception(log_message)
Exception: 断言异常：异常信息: Traceback (most recent call last):
  File "E:\Project_python\2TestCMS2.0\common\requests_util.py", line 348, in validate_result
    error_log("断言失败:"+assert_key+"不等于"+str(assert_value))
  File "E:\Project_python\2TestCMS2.0\common\logger_util.py", line 66, in error_log
    raise Exception(log_message)
Exception: 断言失败:status_code不等于200


[2023-05-26 15:59:51,124] logger_util.py->write_log line:61 [INFO] -------------接口请求开始-----------
[2023-05-26 15:59:51,124] logger_util.py->write_log line:61 [INFO] 接口名称：设置归档表触发配置
[2023-05-26 15:59:51,124] logger_util.py->write_log line:61 [INFO] 接口方式：put
[2023-05-26 15:59:51,124] logger_util.py->write_log line:61 [INFO] 接口路径：http://127.0.0.1:18000/api/v1/dataconfig/filingtable/8cd7d30c-dd00-4708-9bd5-67edf283ca3a/triggers
[2023-05-26 15:59:51,124] logger_util.py->write_log line:61 [INFO] 请求头：{'Content-Type': 'application/json; =UTF-8', 'X-Project': '83d42c5d5ad141bba528b7690b19996e'}
[2023-05-26 15:59:51,125] logger_util.py->write_log line:61 [INFO] 请求参数：[{'effectiveDateTime': None, 'frequencyValue': 1, 'frequencyUnit': 1, 'matchAll': False, 'condition': "G1 ==  true ||  H1 != '中文'", 'conditionDetail': 1, 'frequencyCheck': False, 'alarmPointIds': None, 'triggerType': 2}]
[2023-05-26 15:59:51,125] logger_util.py->write_log line:61 [INFO] 文件上传：None
[2023-05-26 15:59:53,172] logger_util.py->error_log line:65 [INFO] 断言失败:status_code不等于200
[2023-05-26 15:59:53,173] logger_util.py->write_log line:61 [INFO] 接口请求失败！
[2023-05-26 15:59:53,173] logger_util.py->write_log line:61 [INFO] -------------接口请求结束-----------

[2023-05-26 15:59:53,174] logger_util.py->error_log line:65 [INFO] 断言异常：异常信息: Traceback (most recent call last):
  File "E:\Project_python\2TestCMS2.0\common\requests_util.py", line 348, in validate_result
    error_log("断言失败:"+assert_key+"不等于"+str(assert_value))
  File "E:\Project_python\2TestCMS2.0\common\logger_util.py", line 66, in error_log
    raise Exception(log_message)
Exception: 断言失败:status_code不等于200

[2023-05-26 15:59:53,175] logger_util.py->error_log line:65 [INFO] 分析YAML文件异常：异常信息: Traceback (most recent call last):
  File "E:\Project_python\2TestCMS2.0\common\requests_util.py", line 348, in validate_result
    error_log("断言失败:"+assert_key+"不等于"+str(assert_value))
  File "E:\Project_python\2TestCMS2.0\common\logger_util.py", line 66, in error_log
    raise Exception(log_message)
Exception: 断言失败:status_code不等于200

During handling of the above exception, another exception occurred:

Traceback (most recent call last):
  File "E:\Project_python\2TestCMS2.0\common\requests_util.py", line 247, in analysis_yaml
    self.validate_result(yq_result, return_text, status_code)
  File "E:\Project_python\2TestCMS2.0\common\requests_util.py", line 398, in validate_result
    error_log("断言异常：异常信息: %s" % str(traceback.format_exc()))
  File "E:\Project_python\2TestCMS2.0\common\logger_util.py", line 66, in error_log
    raise Exception(log_message)
Exception: 断言异常：异常信息: Traceback (most recent call last):
  File "E:\Project_python\2TestCMS2.0\common\requests_util.py", line 348, in validate_result
    error_log("断言失败:"+assert_key+"不等于"+str(assert_value))
  File "E:\Project_python\2TestCMS2.0\common\logger_util.py", line 66, in error_log
    raise Exception(log_message)
Exception: 断言失败:status_code不等于200


[2023-05-26 15:59:53,209] logger_util.py->write_log line:61 [INFO] -------------接口请求开始-----------
[2023-05-26 15:59:53,209] logger_util.py->write_log line:61 [INFO] 接口名称：设置归档表触发配置
[2023-05-26 15:59:53,209] logger_util.py->write_log line:61 [INFO] 接口方式：put
[2023-05-26 15:59:53,209] logger_util.py->write_log line:61 [INFO] 接口路径：http://127.0.0.1:18000/api/v1/dataconfig/filingtable/8cd7d30c-dd00-4708-9bd5-67edf283ca3a/triggers
[2023-05-26 15:59:53,209] logger_util.py->write_log line:61 [INFO] 请求头：{'Content-Type': 'application/json; =UTF-8', 'X-Project': '83d42c5d5ad141bba528b7690b19996e'}
[2023-05-26 15:59:53,209] logger_util.py->write_log line:61 [INFO] 请求参数：[{'effectiveDateTime': None, 'frequencyValue': 1, 'frequencyUnit': 1, 'matchAll': False, 'condition': 'A1 + B1)  <=  0 ||  (A1 - B1) <= 0', 'conditionDetail': 1, 'frequencyCheck': False, 'alarmPointIds': None, 'triggerType': 2}]
[2023-05-26 15:59:53,209] logger_util.py->write_log line:61 [INFO] 文件上传：None
[2023-05-26 15:59:55,265] logger_util.py->error_log line:65 [INFO] 断言失败:status_code不等于200
[2023-05-26 15:59:55,266] logger_util.py->write_log line:61 [INFO] 接口请求失败！
[2023-05-26 15:59:55,266] logger_util.py->write_log line:61 [INFO] -------------接口请求结束-----------

[2023-05-26 15:59:55,266] logger_util.py->error_log line:65 [INFO] 断言异常：异常信息: Traceback (most recent call last):
  File "E:\Project_python\2TestCMS2.0\common\requests_util.py", line 348, in validate_result
    error_log("断言失败:"+assert_key+"不等于"+str(assert_value))
  File "E:\Project_python\2TestCMS2.0\common\logger_util.py", line 66, in error_log
    raise Exception(log_message)
Exception: 断言失败:status_code不等于200

[2023-05-26 15:59:55,267] logger_util.py->error_log line:65 [INFO] 分析YAML文件异常：异常信息: Traceback (most recent call last):
  File "E:\Project_python\2TestCMS2.0\common\requests_util.py", line 348, in validate_result
    error_log("断言失败:"+assert_key+"不等于"+str(assert_value))
  File "E:\Project_python\2TestCMS2.0\common\logger_util.py", line 66, in error_log
    raise Exception(log_message)
Exception: 断言失败:status_code不等于200

During handling of the above exception, another exception occurred:

Traceback (most recent call last):
  File "E:\Project_python\2TestCMS2.0\common\requests_util.py", line 247, in analysis_yaml
    self.validate_result(yq_result, return_text, status_code)
  File "E:\Project_python\2TestCMS2.0\common\requests_util.py", line 398, in validate_result
    error_log("断言异常：异常信息: %s" % str(traceback.format_exc()))
  File "E:\Project_python\2TestCMS2.0\common\logger_util.py", line 66, in error_log
    raise Exception(log_message)
Exception: 断言异常：异常信息: Traceback (most recent call last):
  File "E:\Project_python\2TestCMS2.0\common\requests_util.py", line 348, in validate_result
    error_log("断言失败:"+assert_key+"不等于"+str(assert_value))
  File "E:\Project_python\2TestCMS2.0\common\logger_util.py", line 66, in error_log
    raise Exception(log_message)
Exception: 断言失败:status_code不等于200


[2023-05-26 15:59:55,293] logger_util.py->write_log line:61 [INFO] -------------接口请求开始-----------
[2023-05-26 15:59:55,293] logger_util.py->write_log line:61 [INFO] 接口名称：设置归档表触发配置
[2023-05-26 15:59:55,293] logger_util.py->write_log line:61 [INFO] 接口方式：put
[2023-05-26 15:59:55,294] logger_util.py->write_log line:61 [INFO] 接口路径：http://127.0.0.1:18000/api/v1/dataconfig/filingtable/8cd7d30c-dd00-4708-9bd5-67edf283ca3a/triggers
[2023-05-26 15:59:55,294] logger_util.py->write_log line:61 [INFO] 请求头：{'Content-Type': 'application/json; =UTF-8', 'X-Project': '83d42c5d5ad141bba528b7690b19996e'}
[2023-05-26 15:59:55,294] logger_util.py->write_log line:61 [INFO] 请求参数：[{'effectiveDateTime': None, 'frequencyValue': 1, 'frequencyUnit': 1, 'matchAll': False, 'condition': '(A1 * B1) > 0 &&  (A1 / B1)>0', 'conditionDetail': 1, 'frequencyCheck': False, 'alarmPointIds': None, 'triggerType': 2}]
[2023-05-26 15:59:55,294] logger_util.py->write_log line:61 [INFO] 文件上传：None
[2023-05-26 15:59:57,350] logger_util.py->error_log line:65 [INFO] 断言失败:status_code不等于200
[2023-05-26 15:59:57,350] logger_util.py->write_log line:61 [INFO] 接口请求失败！
[2023-05-26 15:59:57,350] logger_util.py->write_log line:61 [INFO] -------------接口请求结束-----------

[2023-05-26 15:59:57,351] logger_util.py->error_log line:65 [INFO] 断言异常：异常信息: Traceback (most recent call last):
  File "E:\Project_python\2TestCMS2.0\common\requests_util.py", line 348, in validate_result
    error_log("断言失败:"+assert_key+"不等于"+str(assert_value))
  File "E:\Project_python\2TestCMS2.0\common\logger_util.py", line 66, in error_log
    raise Exception(log_message)
Exception: 断言失败:status_code不等于200

[2023-05-26 15:59:57,351] logger_util.py->error_log line:65 [INFO] 分析YAML文件异常：异常信息: Traceback (most recent call last):
  File "E:\Project_python\2TestCMS2.0\common\requests_util.py", line 348, in validate_result
    error_log("断言失败:"+assert_key+"不等于"+str(assert_value))
  File "E:\Project_python\2TestCMS2.0\common\logger_util.py", line 66, in error_log
    raise Exception(log_message)
Exception: 断言失败:status_code不等于200

During handling of the above exception, another exception occurred:

Traceback (most recent call last):
  File "E:\Project_python\2TestCMS2.0\common\requests_util.py", line 247, in analysis_yaml
    self.validate_result(yq_result, return_text, status_code)
  File "E:\Project_python\2TestCMS2.0\common\requests_util.py", line 398, in validate_result
    error_log("断言异常：异常信息: %s" % str(traceback.format_exc()))
  File "E:\Project_python\2TestCMS2.0\common\logger_util.py", line 66, in error_log
    raise Exception(log_message)
Exception: 断言异常：异常信息: Traceback (most recent call last):
  File "E:\Project_python\2TestCMS2.0\common\requests_util.py", line 348, in validate_result
    error_log("断言失败:"+assert_key+"不等于"+str(assert_value))
  File "E:\Project_python\2TestCMS2.0\common\logger_util.py", line 66, in error_log
    raise Exception(log_message)
Exception: 断言失败:status_code不等于200


