[2023-12-05 14:00:00,786] logger_util.py->write_log line:61 [INFO] 
-------------接口请求开始-----------
[2023-12-05 14:00:00,786] logger_util.py->write_log line:61 [INFO] 接口名称：创建工程
[2023-12-05 14:00:00,786] logger_util.py->write_log line:61 [INFO] 接口方式：post
[2023-12-05 14:00:00,786] logger_util.py->write_log line:61 [INFO] 接口路径：http://127.0.0.1:18001/api/v1/project/node
[2023-12-05 14:00:00,786] logger_util.py->write_log line:61 [INFO] 请求头：{}
[2023-12-05 14:00:00,786] logger_util.py->write_log line:61 [INFO] 请求参数：{'name': '工程1361', 'path': 'C:\\自动化工程', 'type': 1}
[2023-12-05 14:00:00,787] logger_util.py->write_log line:61 [INFO] 文件上传：None
[2023-12-05 14:00:02,937] logger_util.py->error_log line:65 [INFO] 发送请求异常：异常信息: Traceback (most recent call last):
  File "E:\Project_python\api_cms\venv\lib\site-packages\urllib3\connection.py", line 203, in _new_conn
    sock = connection.create_connection(
  File "E:\Project_python\api_cms\venv\lib\site-packages\urllib3\util\connection.py", line 85, in create_connection
    raise err
  File "E:\Project_python\api_cms\venv\lib\site-packages\urllib3\util\connection.py", line 73, in create_connection
    sock.connect(sa)
ConnectionRefusedError: [WinError 10061] 由于目标计算机积极拒绝，无法连接。

The above exception was the direct cause of the following exception:

Traceback (most recent call last):
  File "E:\Project_python\api_cms\venv\lib\site-packages\urllib3\connectionpool.py", line 790, in urlopen
    response = self._make_request(
  File "E:\Project_python\api_cms\venv\lib\site-packages\urllib3\connectionpool.py", line 496, in _make_request
    conn.request(
  File "E:\Project_python\api_cms\venv\lib\site-packages\urllib3\connection.py", line 395, in request
    self.endheaders()
  File "D:\Pyhton\Pyton39\lib\http\client.py", line 1280, in endheaders
    self._send_output(message_body, encode_chunked=encode_chunked)
  File "D:\Pyhton\Pyton39\lib\http\client.py", line 1040, in _send_output
    self.send(msg)
  File "D:\Pyhton\Pyton39\lib\http\client.py", line 980, in send
    self.connect()
  File "E:\Project_python\api_cms\venv\lib\site-packages\urllib3\connection.py", line 243, in connect
    self.sock = self._new_conn()
  File "E:\Project_python\api_cms\venv\lib\site-packages\urllib3\connection.py", line 218, in _new_conn
    raise NewConnectionError(
urllib3.exceptions.NewConnectionError: <urllib3.connection.HTTPConnection object at 0x000002554DD53340>: Failed to establish a new connection: [WinError 10061] 由于目标计算机积极拒绝，无法连接。

The above exception was the direct cause of the following exception:

Traceback (most recent call last):
  File "E:\Project_python\api_cms\venv\lib\site-packages\requests\adapters.py", line 486, in send
    resp = conn.urlopen(
  File "E:\Project_python\api_cms\venv\lib\site-packages\urllib3\connectionpool.py", line 844, in urlopen
    retries = retries.increment(
  File "E:\Project_python\api_cms\venv\lib\site-packages\urllib3\util\retry.py", line 515, in increment
    raise MaxRetryError(_pool, url, reason) from reason  # type: ignore[arg-type]
urllib3.exceptions.MaxRetryError: HTTPConnectionPool(host='127.0.0.1', port=18001): Max retries exceeded with url: /api/v1/project/node (Caused by NewConnectionError('<urllib3.connection.HTTPConnection object at 0x000002554DD53340>: Failed to establish a new connection: [WinError 10061] 由于目标计算机积极拒绝，无法连接。'))

During handling of the above exception, another exception occurred:

Traceback (most recent call last):
  File "E:\Project_python\api_cms\common\requests_util.py", line 332, in send_request
    res = RequestUtil.session.request(method=self.last_method, url=self.base_url, headers=self.last_headers, **kwargs)
  File "E:\Project_python\api_cms\venv\lib\site-packages\requests\sessions.py", line 589, in request
    resp = self.send(prep, **send_kwargs)
  File "E:\Project_python\api_cms\venv\lib\site-packages\requests\sessions.py", line 703, in send
    r = adapter.send(request, **kwargs)
  File "E:\Project_python\api_cms\venv\lib\site-packages\requests\adapters.py", line 519, in send
    raise ConnectionError(e, request=request)
requests.exceptions.ConnectionError: HTTPConnectionPool(host='127.0.0.1', port=18001): Max retries exceeded with url: /api/v1/project/node (Caused by NewConnectionError('<urllib3.connection.HTTPConnection object at 0x000002554DD53340>: Failed to establish a new connection: [WinError 10061] 由于目标计算机积极拒绝，无法连接。'))

[2023-12-05 14:00:02,951] logger_util.py->error_log line:65 [INFO] 分析YAML文件异常：异常信息: Traceback (most recent call last):
  File "E:\Project_python\api_cms\venv\lib\site-packages\urllib3\connection.py", line 203, in _new_conn
    sock = connection.create_connection(
  File "E:\Project_python\api_cms\venv\lib\site-packages\urllib3\util\connection.py", line 85, in create_connection
    raise err
  File "E:\Project_python\api_cms\venv\lib\site-packages\urllib3\util\connection.py", line 73, in create_connection
    sock.connect(sa)
ConnectionRefusedError: [WinError 10061] 由于目标计算机积极拒绝，无法连接。

The above exception was the direct cause of the following exception:

Traceback (most recent call last):
  File "E:\Project_python\api_cms\venv\lib\site-packages\urllib3\connectionpool.py", line 790, in urlopen
    response = self._make_request(
  File "E:\Project_python\api_cms\venv\lib\site-packages\urllib3\connectionpool.py", line 496, in _make_request
    conn.request(
  File "E:\Project_python\api_cms\venv\lib\site-packages\urllib3\connection.py", line 395, in request
    self.endheaders()
  File "D:\Pyhton\Pyton39\lib\http\client.py", line 1280, in endheaders
    self._send_output(message_body, encode_chunked=encode_chunked)
  File "D:\Pyhton\Pyton39\lib\http\client.py", line 1040, in _send_output
    self.send(msg)
  File "D:\Pyhton\Pyton39\lib\http\client.py", line 980, in send
    self.connect()
  File "E:\Project_python\api_cms\venv\lib\site-packages\urllib3\connection.py", line 243, in connect
    self.sock = self._new_conn()
  File "E:\Project_python\api_cms\venv\lib\site-packages\urllib3\connection.py", line 218, in _new_conn
    raise NewConnectionError(
urllib3.exceptions.NewConnectionError: <urllib3.connection.HTTPConnection object at 0x000002554DD53340>: Failed to establish a new connection: [WinError 10061] 由于目标计算机积极拒绝，无法连接。

The above exception was the direct cause of the following exception:

Traceback (most recent call last):
  File "E:\Project_python\api_cms\venv\lib\site-packages\requests\adapters.py", line 486, in send
    resp = conn.urlopen(
  File "E:\Project_python\api_cms\venv\lib\site-packages\urllib3\connectionpool.py", line 844, in urlopen
    retries = retries.increment(
  File "E:\Project_python\api_cms\venv\lib\site-packages\urllib3\util\retry.py", line 515, in increment
    raise MaxRetryError(_pool, url, reason) from reason  # type: ignore[arg-type]
urllib3.exceptions.MaxRetryError: HTTPConnectionPool(host='127.0.0.1', port=18001): Max retries exceeded with url: /api/v1/project/node (Caused by NewConnectionError('<urllib3.connection.HTTPConnection object at 0x000002554DD53340>: Failed to establish a new connection: [WinError 10061] 由于目标计算机积极拒绝，无法连接。'))

During handling of the above exception, another exception occurred:

Traceback (most recent call last):
  File "E:\Project_python\api_cms\common\requests_util.py", line 332, in send_request
    res = RequestUtil.session.request(method=self.last_method, url=self.base_url, headers=self.last_headers, **kwargs)
  File "E:\Project_python\api_cms\venv\lib\site-packages\requests\sessions.py", line 589, in request
    resp = self.send(prep, **send_kwargs)
  File "E:\Project_python\api_cms\venv\lib\site-packages\requests\sessions.py", line 703, in send
    r = adapter.send(request, **kwargs)
  File "E:\Project_python\api_cms\venv\lib\site-packages\requests\adapters.py", line 519, in send
    raise ConnectionError(e, request=request)
requests.exceptions.ConnectionError: HTTPConnectionPool(host='127.0.0.1', port=18001): Max retries exceeded with url: /api/v1/project/node (Caused by NewConnectionError('<urllib3.connection.HTTPConnection object at 0x000002554DD53340>: Failed to establish a new connection: [WinError 10061] 由于目标计算机积极拒绝，无法连接。'))

During handling of the above exception, another exception occurred:

Traceback (most recent call last):
  File "E:\Project_python\api_cms\common\requests_util.py", line 185, in analysis_yaml
    res = self.send_request(name =name,method=method,
  File "E:\Project_python\api_cms\common\requests_util.py", line 335, in send_request
    error_log("发送请求异常：异常信息: %s" % str(traceback.format_exc()))
  File "E:\Project_python\api_cms\common\logger_util.py", line 66, in error_log
    raise Exception(log_message)
Exception: 发送请求异常：异常信息: Traceback (most recent call last):
  File "E:\Project_python\api_cms\venv\lib\site-packages\urllib3\connection.py", line 203, in _new_conn
    sock = connection.create_connection(
  File "E:\Project_python\api_cms\venv\lib\site-packages\urllib3\util\connection.py", line 85, in create_connection
    raise err
  File "E:\Project_python\api_cms\venv\lib\site-packages\urllib3\util\connection.py", line 73, in create_connection
    sock.connect(sa)
ConnectionRefusedError: [WinError 10061] 由于目标计算机积极拒绝，无法连接。

The above exception was the direct cause of the following exception:

Traceback (most recent call last):
  File "E:\Project_python\api_cms\venv\lib\site-packages\urllib3\connectionpool.py", line 790, in urlopen
    response = self._make_request(
  File "E:\Project_python\api_cms\venv\lib\site-packages\urllib3\connectionpool.py", line 496, in _make_request
    conn.request(
  File "E:\Project_python\api_cms\venv\lib\site-packages\urllib3\connection.py", line 395, in request
    self.endheaders()
  File "D:\Pyhton\Pyton39\lib\http\client.py", line 1280, in endheaders
    self._send_output(message_body, encode_chunked=encode_chunked)
  File "D:\Pyhton\Pyton39\lib\http\client.py", line 1040, in _send_output
    self.send(msg)
  File "D:\Pyhton\Pyton39\lib\http\client.py", line 980, in send
    self.connect()
  File "E:\Project_python\api_cms\venv\lib\site-packages\urllib3\connection.py", line 243, in connect
    self.sock = self._new_conn()
  File "E:\Project_python\api_cms\venv\lib\site-packages\urllib3\connection.py", line 218, in _new_conn
    raise NewConnectionError(
urllib3.exceptions.NewConnectionError: <urllib3.connection.HTTPConnection object at 0x000002554DD53340>: Failed to establish a new connection: [WinError 10061] 由于目标计算机积极拒绝，无法连接。

The above exception was the direct cause of the following exception:

Traceback (most recent call last):
  File "E:\Project_python\api_cms\venv\lib\site-packages\requests\adapters.py", line 486, in send
    resp = conn.urlopen(
  File "E:\Project_python\api_cms\venv\lib\site-packages\urllib3\connectionpool.py", line 844, in urlopen
    retries = retries.increment(
  File "E:\Project_python\api_cms\venv\lib\site-packages\urllib3\util\retry.py", line 515, in increment
    raise MaxRetryError(_pool, url, reason) from reason  # type: ignore[arg-type]
urllib3.exceptions.MaxRetryError: HTTPConnectionPool(host='127.0.0.1', port=18001): Max retries exceeded with url: /api/v1/project/node (Caused by NewConnectionError('<urllib3.connection.HTTPConnection object at 0x000002554DD53340>: Failed to establish a new connection: [WinError 10061] 由于目标计算机积极拒绝，无法连接。'))

During handling of the above exception, another exception occurred:

Traceback (most recent call last):
  File "E:\Project_python\api_cms\common\requests_util.py", line 332, in send_request
    res = RequestUtil.session.request(method=self.last_method, url=self.base_url, headers=self.last_headers, **kwargs)
  File "E:\Project_python\api_cms\venv\lib\site-packages\requests\sessions.py", line 589, in request
    resp = self.send(prep, **send_kwargs)
  File "E:\Project_python\api_cms\venv\lib\site-packages\requests\sessions.py", line 703, in send
    r = adapter.send(request, **kwargs)
  File "E:\Project_python\api_cms\venv\lib\site-packages\requests\adapters.py", line 519, in send
    raise ConnectionError(e, request=request)
requests.exceptions.ConnectionError: HTTPConnectionPool(host='127.0.0.1', port=18001): Max retries exceeded with url: /api/v1/project/node (Caused by NewConnectionError('<urllib3.connection.HTTPConnection object at 0x000002554DD53340>: Failed to establish a new connection: [WinError 10061] 由于目标计算机积极拒绝，无法连接。'))


[2023-12-05 14:00:03,176] logger_util.py->write_log line:61 [INFO] 
-------------接口请求开始-----------
[2023-12-05 14:00:03,176] logger_util.py->write_log line:61 [INFO] 接口名称：创建文件夹
[2023-12-05 14:00:03,176] logger_util.py->write_log line:61 [INFO] 接口方式：post
[2023-12-05 14:00:03,176] logger_util.py->write_log line:61 [INFO] 接口路径：http://127.0.0.1:18001/api/v1/project/node
[2023-12-05 14:00:03,177] logger_util.py->write_log line:61 [INFO] 请求头：{}
[2023-12-05 14:00:03,177] logger_util.py->write_log line:61 [INFO] 请求参数：{'name': '文件夹5880', 'type': 0}
[2023-12-05 14:00:03,177] logger_util.py->write_log line:61 [INFO] 文件上传：None
[2023-12-05 14:00:05,226] logger_util.py->error_log line:65 [INFO] 发送请求异常：异常信息: Traceback (most recent call last):
  File "E:\Project_python\api_cms\venv\lib\site-packages\urllib3\connection.py", line 203, in _new_conn
    sock = connection.create_connection(
  File "E:\Project_python\api_cms\venv\lib\site-packages\urllib3\util\connection.py", line 85, in create_connection
    raise err
  File "E:\Project_python\api_cms\venv\lib\site-packages\urllib3\util\connection.py", line 73, in create_connection
    sock.connect(sa)
ConnectionRefusedError: [WinError 10061] 由于目标计算机积极拒绝，无法连接。

The above exception was the direct cause of the following exception:

Traceback (most recent call last):
  File "E:\Project_python\api_cms\venv\lib\site-packages\urllib3\connectionpool.py", line 790, in urlopen
    response = self._make_request(
  File "E:\Project_python\api_cms\venv\lib\site-packages\urllib3\connectionpool.py", line 496, in _make_request
    conn.request(
  File "E:\Project_python\api_cms\venv\lib\site-packages\urllib3\connection.py", line 395, in request
    self.endheaders()
  File "D:\Pyhton\Pyton39\lib\http\client.py", line 1280, in endheaders
    self._send_output(message_body, encode_chunked=encode_chunked)
  File "D:\Pyhton\Pyton39\lib\http\client.py", line 1040, in _send_output
    self.send(msg)
  File "D:\Pyhton\Pyton39\lib\http\client.py", line 980, in send
    self.connect()
  File "E:\Project_python\api_cms\venv\lib\site-packages\urllib3\connection.py", line 243, in connect
    self.sock = self._new_conn()
  File "E:\Project_python\api_cms\venv\lib\site-packages\urllib3\connection.py", line 218, in _new_conn
    raise NewConnectionError(
urllib3.exceptions.NewConnectionError: <urllib3.connection.HTTPConnection object at 0x000002554E72A220>: Failed to establish a new connection: [WinError 10061] 由于目标计算机积极拒绝，无法连接。

The above exception was the direct cause of the following exception:

Traceback (most recent call last):
  File "E:\Project_python\api_cms\venv\lib\site-packages\requests\adapters.py", line 486, in send
    resp = conn.urlopen(
  File "E:\Project_python\api_cms\venv\lib\site-packages\urllib3\connectionpool.py", line 844, in urlopen
    retries = retries.increment(
  File "E:\Project_python\api_cms\venv\lib\site-packages\urllib3\util\retry.py", line 515, in increment
    raise MaxRetryError(_pool, url, reason) from reason  # type: ignore[arg-type]
urllib3.exceptions.MaxRetryError: HTTPConnectionPool(host='127.0.0.1', port=18001): Max retries exceeded with url: /api/v1/project/node (Caused by NewConnectionError('<urllib3.connection.HTTPConnection object at 0x000002554E72A220>: Failed to establish a new connection: [WinError 10061] 由于目标计算机积极拒绝，无法连接。'))

During handling of the above exception, another exception occurred:

Traceback (most recent call last):
  File "E:\Project_python\api_cms\common\requests_util.py", line 332, in send_request
    res = RequestUtil.session.request(method=self.last_method, url=self.base_url, headers=self.last_headers, **kwargs)
  File "E:\Project_python\api_cms\venv\lib\site-packages\requests\sessions.py", line 589, in request
    resp = self.send(prep, **send_kwargs)
  File "E:\Project_python\api_cms\venv\lib\site-packages\requests\sessions.py", line 703, in send
    r = adapter.send(request, **kwargs)
  File "E:\Project_python\api_cms\venv\lib\site-packages\requests\adapters.py", line 519, in send
    raise ConnectionError(e, request=request)
requests.exceptions.ConnectionError: HTTPConnectionPool(host='127.0.0.1', port=18001): Max retries exceeded with url: /api/v1/project/node (Caused by NewConnectionError('<urllib3.connection.HTTPConnection object at 0x000002554E72A220>: Failed to establish a new connection: [WinError 10061] 由于目标计算机积极拒绝，无法连接。'))

[2023-12-05 14:00:05,226] logger_util.py->error_log line:65 [INFO] 分析YAML文件异常：异常信息: Traceback (most recent call last):
  File "E:\Project_python\api_cms\venv\lib\site-packages\urllib3\connection.py", line 203, in _new_conn
    sock = connection.create_connection(
  File "E:\Project_python\api_cms\venv\lib\site-packages\urllib3\util\connection.py", line 85, in create_connection
    raise err
  File "E:\Project_python\api_cms\venv\lib\site-packages\urllib3\util\connection.py", line 73, in create_connection
    sock.connect(sa)
ConnectionRefusedError: [WinError 10061] 由于目标计算机积极拒绝，无法连接。

The above exception was the direct cause of the following exception:

Traceback (most recent call last):
  File "E:\Project_python\api_cms\venv\lib\site-packages\urllib3\connectionpool.py", line 790, in urlopen
    response = self._make_request(
  File "E:\Project_python\api_cms\venv\lib\site-packages\urllib3\connectionpool.py", line 496, in _make_request
    conn.request(
  File "E:\Project_python\api_cms\venv\lib\site-packages\urllib3\connection.py", line 395, in request
    self.endheaders()
  File "D:\Pyhton\Pyton39\lib\http\client.py", line 1280, in endheaders
    self._send_output(message_body, encode_chunked=encode_chunked)
  File "D:\Pyhton\Pyton39\lib\http\client.py", line 1040, in _send_output
    self.send(msg)
  File "D:\Pyhton\Pyton39\lib\http\client.py", line 980, in send
    self.connect()
  File "E:\Project_python\api_cms\venv\lib\site-packages\urllib3\connection.py", line 243, in connect
    self.sock = self._new_conn()
  File "E:\Project_python\api_cms\venv\lib\site-packages\urllib3\connection.py", line 218, in _new_conn
    raise NewConnectionError(
urllib3.exceptions.NewConnectionError: <urllib3.connection.HTTPConnection object at 0x000002554E72A220>: Failed to establish a new connection: [WinError 10061] 由于目标计算机积极拒绝，无法连接。

The above exception was the direct cause of the following exception:

Traceback (most recent call last):
  File "E:\Project_python\api_cms\venv\lib\site-packages\requests\adapters.py", line 486, in send
    resp = conn.urlopen(
  File "E:\Project_python\api_cms\venv\lib\site-packages\urllib3\connectionpool.py", line 844, in urlopen
    retries = retries.increment(
  File "E:\Project_python\api_cms\venv\lib\site-packages\urllib3\util\retry.py", line 515, in increment
    raise MaxRetryError(_pool, url, reason) from reason  # type: ignore[arg-type]
urllib3.exceptions.MaxRetryError: HTTPConnectionPool(host='127.0.0.1', port=18001): Max retries exceeded with url: /api/v1/project/node (Caused by NewConnectionError('<urllib3.connection.HTTPConnection object at 0x000002554E72A220>: Failed to establish a new connection: [WinError 10061] 由于目标计算机积极拒绝，无法连接。'))

During handling of the above exception, another exception occurred:

Traceback (most recent call last):
  File "E:\Project_python\api_cms\common\requests_util.py", line 332, in send_request
    res = RequestUtil.session.request(method=self.last_method, url=self.base_url, headers=self.last_headers, **kwargs)
  File "E:\Project_python\api_cms\venv\lib\site-packages\requests\sessions.py", line 589, in request
    resp = self.send(prep, **send_kwargs)
  File "E:\Project_python\api_cms\venv\lib\site-packages\requests\sessions.py", line 703, in send
    r = adapter.send(request, **kwargs)
  File "E:\Project_python\api_cms\venv\lib\site-packages\requests\adapters.py", line 519, in send
    raise ConnectionError(e, request=request)
requests.exceptions.ConnectionError: HTTPConnectionPool(host='127.0.0.1', port=18001): Max retries exceeded with url: /api/v1/project/node (Caused by NewConnectionError('<urllib3.connection.HTTPConnection object at 0x000002554E72A220>: Failed to establish a new connection: [WinError 10061] 由于目标计算机积极拒绝，无法连接。'))

During handling of the above exception, another exception occurred:

Traceback (most recent call last):
  File "E:\Project_python\api_cms\common\requests_util.py", line 185, in analysis_yaml
    res = self.send_request(name =name,method=method,
  File "E:\Project_python\api_cms\common\requests_util.py", line 335, in send_request
    error_log("发送请求异常：异常信息: %s" % str(traceback.format_exc()))
  File "E:\Project_python\api_cms\common\logger_util.py", line 66, in error_log
    raise Exception(log_message)
Exception: 发送请求异常：异常信息: Traceback (most recent call last):
  File "E:\Project_python\api_cms\venv\lib\site-packages\urllib3\connection.py", line 203, in _new_conn
    sock = connection.create_connection(
  File "E:\Project_python\api_cms\venv\lib\site-packages\urllib3\util\connection.py", line 85, in create_connection
    raise err
  File "E:\Project_python\api_cms\venv\lib\site-packages\urllib3\util\connection.py", line 73, in create_connection
    sock.connect(sa)
ConnectionRefusedError: [WinError 10061] 由于目标计算机积极拒绝，无法连接。

The above exception was the direct cause of the following exception:

Traceback (most recent call last):
  File "E:\Project_python\api_cms\venv\lib\site-packages\urllib3\connectionpool.py", line 790, in urlopen
    response = self._make_request(
  File "E:\Project_python\api_cms\venv\lib\site-packages\urllib3\connectionpool.py", line 496, in _make_request
    conn.request(
  File "E:\Project_python\api_cms\venv\lib\site-packages\urllib3\connection.py", line 395, in request
    self.endheaders()
  File "D:\Pyhton\Pyton39\lib\http\client.py", line 1280, in endheaders
    self._send_output(message_body, encode_chunked=encode_chunked)
  File "D:\Pyhton\Pyton39\lib\http\client.py", line 1040, in _send_output
    self.send(msg)
  File "D:\Pyhton\Pyton39\lib\http\client.py", line 980, in send
    self.connect()
  File "E:\Project_python\api_cms\venv\lib\site-packages\urllib3\connection.py", line 243, in connect
    self.sock = self._new_conn()
  File "E:\Project_python\api_cms\venv\lib\site-packages\urllib3\connection.py", line 218, in _new_conn
    raise NewConnectionError(
urllib3.exceptions.NewConnectionError: <urllib3.connection.HTTPConnection object at 0x000002554E72A220>: Failed to establish a new connection: [WinError 10061] 由于目标计算机积极拒绝，无法连接。

The above exception was the direct cause of the following exception:

Traceback (most recent call last):
  File "E:\Project_python\api_cms\venv\lib\site-packages\requests\adapters.py", line 486, in send
    resp = conn.urlopen(
  File "E:\Project_python\api_cms\venv\lib\site-packages\urllib3\connectionpool.py", line 844, in urlopen
    retries = retries.increment(
  File "E:\Project_python\api_cms\venv\lib\site-packages\urllib3\util\retry.py", line 515, in increment
    raise MaxRetryError(_pool, url, reason) from reason  # type: ignore[arg-type]
urllib3.exceptions.MaxRetryError: HTTPConnectionPool(host='127.0.0.1', port=18001): Max retries exceeded with url: /api/v1/project/node (Caused by NewConnectionError('<urllib3.connection.HTTPConnection object at 0x000002554E72A220>: Failed to establish a new connection: [WinError 10061] 由于目标计算机积极拒绝，无法连接。'))

During handling of the above exception, another exception occurred:

Traceback (most recent call last):
  File "E:\Project_python\api_cms\common\requests_util.py", line 332, in send_request
    res = RequestUtil.session.request(method=self.last_method, url=self.base_url, headers=self.last_headers, **kwargs)
  File "E:\Project_python\api_cms\venv\lib\site-packages\requests\sessions.py", line 589, in request
    resp = self.send(prep, **send_kwargs)
  File "E:\Project_python\api_cms\venv\lib\site-packages\requests\sessions.py", line 703, in send
    r = adapter.send(request, **kwargs)
  File "E:\Project_python\api_cms\venv\lib\site-packages\requests\adapters.py", line 519, in send
    raise ConnectionError(e, request=request)
requests.exceptions.ConnectionError: HTTPConnectionPool(host='127.0.0.1', port=18001): Max retries exceeded with url: /api/v1/project/node (Caused by NewConnectionError('<urllib3.connection.HTTPConnection object at 0x000002554E72A220>: Failed to establish a new connection: [WinError 10061] 由于目标计算机积极拒绝，无法连接。'))


[2023-12-05 14:00:05,378] logger_util.py->error_log line:65 [INFO] 发送请求异常：异常信息: Traceback (most recent call last):
  File "E:\Project_python\api_cms\common\requests_util.py", line 309, in send_request
    self.base_url = self.replace_load(self.base_url) + self.replace_load(url)
  File "E:\Project_python\api_cms\common\requests_util.py", line 140, in replace_load
    new_value = getattr(DubugTalk(), func_name)(*args_value.split(','))
  File "E:\Project_python\api_cms\debug_talk.py", line 26, in get_extract_data
    return read_extract_file(node_name)
  File "E:\Project_python\api_cms\common\yaml_util.py", line 19, in read_extract_file
    return value[one_node]
TypeError: 'NoneType' object is not subscriptable

[2023-12-05 14:00:05,379] logger_util.py->error_log line:65 [INFO] 分析YAML文件异常：异常信息: Traceback (most recent call last):
  File "E:\Project_python\api_cms\common\requests_util.py", line 309, in send_request
    self.base_url = self.replace_load(self.base_url) + self.replace_load(url)
  File "E:\Project_python\api_cms\common\requests_util.py", line 140, in replace_load
    new_value = getattr(DubugTalk(), func_name)(*args_value.split(','))
  File "E:\Project_python\api_cms\debug_talk.py", line 26, in get_extract_data
    return read_extract_file(node_name)
  File "E:\Project_python\api_cms\common\yaml_util.py", line 19, in read_extract_file
    return value[one_node]
TypeError: 'NoneType' object is not subscriptable

During handling of the above exception, another exception occurred:

Traceback (most recent call last):
  File "E:\Project_python\api_cms\common\requests_util.py", line 185, in analysis_yaml
    res = self.send_request(name =name,method=method,
  File "E:\Project_python\api_cms\common\requests_util.py", line 335, in send_request
    error_log("发送请求异常：异常信息: %s" % str(traceback.format_exc()))
  File "E:\Project_python\api_cms\common\logger_util.py", line 66, in error_log
    raise Exception(log_message)
Exception: 发送请求异常：异常信息: Traceback (most recent call last):
  File "E:\Project_python\api_cms\common\requests_util.py", line 309, in send_request
    self.base_url = self.replace_load(self.base_url) + self.replace_load(url)
  File "E:\Project_python\api_cms\common\requests_util.py", line 140, in replace_load
    new_value = getattr(DubugTalk(), func_name)(*args_value.split(','))
  File "E:\Project_python\api_cms\debug_talk.py", line 26, in get_extract_data
    return read_extract_file(node_name)
  File "E:\Project_python\api_cms\common\yaml_util.py", line 19, in read_extract_file
    return value[one_node]
TypeError: 'NoneType' object is not subscriptable


[2023-12-05 14:00:05,424] logger_util.py->error_log line:65 [INFO] 发送请求异常：异常信息: Traceback (most recent call last):
  File "E:\Project_python\api_cms\common\requests_util.py", line 312, in send_request
    self.last_headers = self.replace_load(headers)
  File "E:\Project_python\api_cms\common\requests_util.py", line 140, in replace_load
    new_value = getattr(DubugTalk(), func_name)(*args_value.split(','))
  File "E:\Project_python\api_cms\debug_talk.py", line 26, in get_extract_data
    return read_extract_file(node_name)
  File "E:\Project_python\api_cms\common\yaml_util.py", line 19, in read_extract_file
    return value[one_node]
TypeError: 'NoneType' object is not subscriptable

[2023-12-05 14:00:05,424] logger_util.py->error_log line:65 [INFO] 分析YAML文件异常：异常信息: Traceback (most recent call last):
  File "E:\Project_python\api_cms\common\requests_util.py", line 312, in send_request
    self.last_headers = self.replace_load(headers)
  File "E:\Project_python\api_cms\common\requests_util.py", line 140, in replace_load
    new_value = getattr(DubugTalk(), func_name)(*args_value.split(','))
  File "E:\Project_python\api_cms\debug_talk.py", line 26, in get_extract_data
    return read_extract_file(node_name)
  File "E:\Project_python\api_cms\common\yaml_util.py", line 19, in read_extract_file
    return value[one_node]
TypeError: 'NoneType' object is not subscriptable

During handling of the above exception, another exception occurred:

Traceback (most recent call last):
  File "E:\Project_python\api_cms\common\requests_util.py", line 185, in analysis_yaml
    res = self.send_request(name =name,method=method,
  File "E:\Project_python\api_cms\common\requests_util.py", line 335, in send_request
    error_log("发送请求异常：异常信息: %s" % str(traceback.format_exc()))
  File "E:\Project_python\api_cms\common\logger_util.py", line 66, in error_log
    raise Exception(log_message)
Exception: 发送请求异常：异常信息: Traceback (most recent call last):
  File "E:\Project_python\api_cms\common\requests_util.py", line 312, in send_request
    self.last_headers = self.replace_load(headers)
  File "E:\Project_python\api_cms\common\requests_util.py", line 140, in replace_load
    new_value = getattr(DubugTalk(), func_name)(*args_value.split(','))
  File "E:\Project_python\api_cms\debug_talk.py", line 26, in get_extract_data
    return read_extract_file(node_name)
  File "E:\Project_python\api_cms\common\yaml_util.py", line 19, in read_extract_file
    return value[one_node]
TypeError: 'NoneType' object is not subscriptable


[2023-12-05 14:00:05,501] logger_util.py->error_log line:65 [INFO] 发送请求异常：异常信息: Traceback (most recent call last):
  File "E:\Project_python\api_cms\common\requests_util.py", line 312, in send_request
    self.last_headers = self.replace_load(headers)
  File "E:\Project_python\api_cms\common\requests_util.py", line 140, in replace_load
    new_value = getattr(DubugTalk(), func_name)(*args_value.split(','))
  File "E:\Project_python\api_cms\debug_talk.py", line 26, in get_extract_data
    return read_extract_file(node_name)
  File "E:\Project_python\api_cms\common\yaml_util.py", line 19, in read_extract_file
    return value[one_node]
TypeError: 'NoneType' object is not subscriptable

[2023-12-05 14:00:05,502] logger_util.py->error_log line:65 [INFO] 分析YAML文件异常：异常信息: Traceback (most recent call last):
  File "E:\Project_python\api_cms\common\requests_util.py", line 312, in send_request
    self.last_headers = self.replace_load(headers)
  File "E:\Project_python\api_cms\common\requests_util.py", line 140, in replace_load
    new_value = getattr(DubugTalk(), func_name)(*args_value.split(','))
  File "E:\Project_python\api_cms\debug_talk.py", line 26, in get_extract_data
    return read_extract_file(node_name)
  File "E:\Project_python\api_cms\common\yaml_util.py", line 19, in read_extract_file
    return value[one_node]
TypeError: 'NoneType' object is not subscriptable

During handling of the above exception, another exception occurred:

Traceback (most recent call last):
  File "E:\Project_python\api_cms\common\requests_util.py", line 185, in analysis_yaml
    res = self.send_request(name =name,method=method,
  File "E:\Project_python\api_cms\common\requests_util.py", line 335, in send_request
    error_log("发送请求异常：异常信息: %s" % str(traceback.format_exc()))
  File "E:\Project_python\api_cms\common\logger_util.py", line 66, in error_log
    raise Exception(log_message)
Exception: 发送请求异常：异常信息: Traceback (most recent call last):
  File "E:\Project_python\api_cms\common\requests_util.py", line 312, in send_request
    self.last_headers = self.replace_load(headers)
  File "E:\Project_python\api_cms\common\requests_util.py", line 140, in replace_load
    new_value = getattr(DubugTalk(), func_name)(*args_value.split(','))
  File "E:\Project_python\api_cms\debug_talk.py", line 26, in get_extract_data
    return read_extract_file(node_name)
  File "E:\Project_python\api_cms\common\yaml_util.py", line 19, in read_extract_file
    return value[one_node]
TypeError: 'NoneType' object is not subscriptable


[2023-12-05 14:00:05,548] logger_util.py->error_log line:65 [INFO] 发送请求异常：异常信息: Traceback (most recent call last):
  File "E:\Project_python\api_cms\common\requests_util.py", line 312, in send_request
    self.last_headers = self.replace_load(headers)
  File "E:\Project_python\api_cms\common\requests_util.py", line 140, in replace_load
    new_value = getattr(DubugTalk(), func_name)(*args_value.split(','))
  File "E:\Project_python\api_cms\debug_talk.py", line 26, in get_extract_data
    return read_extract_file(node_name)
  File "E:\Project_python\api_cms\common\yaml_util.py", line 19, in read_extract_file
    return value[one_node]
TypeError: 'NoneType' object is not subscriptable

[2023-12-05 14:00:05,549] logger_util.py->error_log line:65 [INFO] 分析YAML文件异常：异常信息: Traceback (most recent call last):
  File "E:\Project_python\api_cms\common\requests_util.py", line 312, in send_request
    self.last_headers = self.replace_load(headers)
  File "E:\Project_python\api_cms\common\requests_util.py", line 140, in replace_load
    new_value = getattr(DubugTalk(), func_name)(*args_value.split(','))
  File "E:\Project_python\api_cms\debug_talk.py", line 26, in get_extract_data
    return read_extract_file(node_name)
  File "E:\Project_python\api_cms\common\yaml_util.py", line 19, in read_extract_file
    return value[one_node]
TypeError: 'NoneType' object is not subscriptable

During handling of the above exception, another exception occurred:

Traceback (most recent call last):
  File "E:\Project_python\api_cms\common\requests_util.py", line 185, in analysis_yaml
    res = self.send_request(name =name,method=method,
  File "E:\Project_python\api_cms\common\requests_util.py", line 335, in send_request
    error_log("发送请求异常：异常信息: %s" % str(traceback.format_exc()))
  File "E:\Project_python\api_cms\common\logger_util.py", line 66, in error_log
    raise Exception(log_message)
Exception: 发送请求异常：异常信息: Traceback (most recent call last):
  File "E:\Project_python\api_cms\common\requests_util.py", line 312, in send_request
    self.last_headers = self.replace_load(headers)
  File "E:\Project_python\api_cms\common\requests_util.py", line 140, in replace_load
    new_value = getattr(DubugTalk(), func_name)(*args_value.split(','))
  File "E:\Project_python\api_cms\debug_talk.py", line 26, in get_extract_data
    return read_extract_file(node_name)
  File "E:\Project_python\api_cms\common\yaml_util.py", line 19, in read_extract_file
    return value[one_node]
TypeError: 'NoneType' object is not subscriptable


[2023-12-05 14:00:05,593] logger_util.py->error_log line:65 [INFO] 发送请求异常：异常信息: Traceback (most recent call last):
  File "E:\Project_python\api_cms\common\requests_util.py", line 312, in send_request
    self.last_headers = self.replace_load(headers)
  File "E:\Project_python\api_cms\common\requests_util.py", line 140, in replace_load
    new_value = getattr(DubugTalk(), func_name)(*args_value.split(','))
  File "E:\Project_python\api_cms\debug_talk.py", line 26, in get_extract_data
    return read_extract_file(node_name)
  File "E:\Project_python\api_cms\common\yaml_util.py", line 19, in read_extract_file
    return value[one_node]
TypeError: 'NoneType' object is not subscriptable

[2023-12-05 14:00:05,594] logger_util.py->error_log line:65 [INFO] 分析YAML文件异常：异常信息: Traceback (most recent call last):
  File "E:\Project_python\api_cms\common\requests_util.py", line 312, in send_request
    self.last_headers = self.replace_load(headers)
  File "E:\Project_python\api_cms\common\requests_util.py", line 140, in replace_load
    new_value = getattr(DubugTalk(), func_name)(*args_value.split(','))
  File "E:\Project_python\api_cms\debug_talk.py", line 26, in get_extract_data
    return read_extract_file(node_name)
  File "E:\Project_python\api_cms\common\yaml_util.py", line 19, in read_extract_file
    return value[one_node]
TypeError: 'NoneType' object is not subscriptable

During handling of the above exception, another exception occurred:

Traceback (most recent call last):
  File "E:\Project_python\api_cms\common\requests_util.py", line 185, in analysis_yaml
    res = self.send_request(name =name,method=method,
  File "E:\Project_python\api_cms\common\requests_util.py", line 335, in send_request
    error_log("发送请求异常：异常信息: %s" % str(traceback.format_exc()))
  File "E:\Project_python\api_cms\common\logger_util.py", line 66, in error_log
    raise Exception(log_message)
Exception: 发送请求异常：异常信息: Traceback (most recent call last):
  File "E:\Project_python\api_cms\common\requests_util.py", line 312, in send_request
    self.last_headers = self.replace_load(headers)
  File "E:\Project_python\api_cms\common\requests_util.py", line 140, in replace_load
    new_value = getattr(DubugTalk(), func_name)(*args_value.split(','))
  File "E:\Project_python\api_cms\debug_talk.py", line 26, in get_extract_data
    return read_extract_file(node_name)
  File "E:\Project_python\api_cms\common\yaml_util.py", line 19, in read_extract_file
    return value[one_node]
TypeError: 'NoneType' object is not subscriptable


[2023-12-05 14:00:05,638] logger_util.py->error_log line:65 [INFO] 发送请求异常：异常信息: Traceback (most recent call last):
  File "E:\Project_python\api_cms\common\requests_util.py", line 312, in send_request
    self.last_headers = self.replace_load(headers)
  File "E:\Project_python\api_cms\common\requests_util.py", line 140, in replace_load
    new_value = getattr(DubugTalk(), func_name)(*args_value.split(','))
  File "E:\Project_python\api_cms\debug_talk.py", line 26, in get_extract_data
    return read_extract_file(node_name)
  File "E:\Project_python\api_cms\common\yaml_util.py", line 19, in read_extract_file
    return value[one_node]
TypeError: 'NoneType' object is not subscriptable

[2023-12-05 14:00:05,638] logger_util.py->error_log line:65 [INFO] 分析YAML文件异常：异常信息: Traceback (most recent call last):
  File "E:\Project_python\api_cms\common\requests_util.py", line 312, in send_request
    self.last_headers = self.replace_load(headers)
  File "E:\Project_python\api_cms\common\requests_util.py", line 140, in replace_load
    new_value = getattr(DubugTalk(), func_name)(*args_value.split(','))
  File "E:\Project_python\api_cms\debug_talk.py", line 26, in get_extract_data
    return read_extract_file(node_name)
  File "E:\Project_python\api_cms\common\yaml_util.py", line 19, in read_extract_file
    return value[one_node]
TypeError: 'NoneType' object is not subscriptable

During handling of the above exception, another exception occurred:

Traceback (most recent call last):
  File "E:\Project_python\api_cms\common\requests_util.py", line 185, in analysis_yaml
    res = self.send_request(name =name,method=method,
  File "E:\Project_python\api_cms\common\requests_util.py", line 335, in send_request
    error_log("发送请求异常：异常信息: %s" % str(traceback.format_exc()))
  File "E:\Project_python\api_cms\common\logger_util.py", line 66, in error_log
    raise Exception(log_message)
Exception: 发送请求异常：异常信息: Traceback (most recent call last):
  File "E:\Project_python\api_cms\common\requests_util.py", line 312, in send_request
    self.last_headers = self.replace_load(headers)
  File "E:\Project_python\api_cms\common\requests_util.py", line 140, in replace_load
    new_value = getattr(DubugTalk(), func_name)(*args_value.split(','))
  File "E:\Project_python\api_cms\debug_talk.py", line 26, in get_extract_data
    return read_extract_file(node_name)
  File "E:\Project_python\api_cms\common\yaml_util.py", line 19, in read_extract_file
    return value[one_node]
TypeError: 'NoneType' object is not subscriptable


[2023-12-05 14:00:05,702] logger_util.py->error_log line:65 [INFO] 发送请求异常：异常信息: Traceback (most recent call last):
  File "E:\Project_python\api_cms\common\requests_util.py", line 312, in send_request
    self.last_headers = self.replace_load(headers)
  File "E:\Project_python\api_cms\common\requests_util.py", line 140, in replace_load
    new_value = getattr(DubugTalk(), func_name)(*args_value.split(','))
  File "E:\Project_python\api_cms\debug_talk.py", line 26, in get_extract_data
    return read_extract_file(node_name)
  File "E:\Project_python\api_cms\common\yaml_util.py", line 19, in read_extract_file
    return value[one_node]
TypeError: 'NoneType' object is not subscriptable

[2023-12-05 14:00:05,702] logger_util.py->error_log line:65 [INFO] 分析YAML文件异常：异常信息: Traceback (most recent call last):
  File "E:\Project_python\api_cms\common\requests_util.py", line 312, in send_request
    self.last_headers = self.replace_load(headers)
  File "E:\Project_python\api_cms\common\requests_util.py", line 140, in replace_load
    new_value = getattr(DubugTalk(), func_name)(*args_value.split(','))
  File "E:\Project_python\api_cms\debug_talk.py", line 26, in get_extract_data
    return read_extract_file(node_name)
  File "E:\Project_python\api_cms\common\yaml_util.py", line 19, in read_extract_file
    return value[one_node]
TypeError: 'NoneType' object is not subscriptable

During handling of the above exception, another exception occurred:

Traceback (most recent call last):
  File "E:\Project_python\api_cms\common\requests_util.py", line 185, in analysis_yaml
    res = self.send_request(name =name,method=method,
  File "E:\Project_python\api_cms\common\requests_util.py", line 335, in send_request
    error_log("发送请求异常：异常信息: %s" % str(traceback.format_exc()))
  File "E:\Project_python\api_cms\common\logger_util.py", line 66, in error_log
    raise Exception(log_message)
Exception: 发送请求异常：异常信息: Traceback (most recent call last):
  File "E:\Project_python\api_cms\common\requests_util.py", line 312, in send_request
    self.last_headers = self.replace_load(headers)
  File "E:\Project_python\api_cms\common\requests_util.py", line 140, in replace_load
    new_value = getattr(DubugTalk(), func_name)(*args_value.split(','))
  File "E:\Project_python\api_cms\debug_talk.py", line 26, in get_extract_data
    return read_extract_file(node_name)
  File "E:\Project_python\api_cms\common\yaml_util.py", line 19, in read_extract_file
    return value[one_node]
TypeError: 'NoneType' object is not subscriptable


[2023-12-05 14:00:05,749] logger_util.py->error_log line:65 [INFO] 发送请求异常：异常信息: Traceback (most recent call last):
  File "E:\Project_python\api_cms\common\requests_util.py", line 312, in send_request
    self.last_headers = self.replace_load(headers)
  File "E:\Project_python\api_cms\common\requests_util.py", line 140, in replace_load
    new_value = getattr(DubugTalk(), func_name)(*args_value.split(','))
  File "E:\Project_python\api_cms\debug_talk.py", line 26, in get_extract_data
    return read_extract_file(node_name)
  File "E:\Project_python\api_cms\common\yaml_util.py", line 19, in read_extract_file
    return value[one_node]
TypeError: 'NoneType' object is not subscriptable

[2023-12-05 14:00:05,749] logger_util.py->error_log line:65 [INFO] 分析YAML文件异常：异常信息: Traceback (most recent call last):
  File "E:\Project_python\api_cms\common\requests_util.py", line 312, in send_request
    self.last_headers = self.replace_load(headers)
  File "E:\Project_python\api_cms\common\requests_util.py", line 140, in replace_load
    new_value = getattr(DubugTalk(), func_name)(*args_value.split(','))
  File "E:\Project_python\api_cms\debug_talk.py", line 26, in get_extract_data
    return read_extract_file(node_name)
  File "E:\Project_python\api_cms\common\yaml_util.py", line 19, in read_extract_file
    return value[one_node]
TypeError: 'NoneType' object is not subscriptable

During handling of the above exception, another exception occurred:

Traceback (most recent call last):
  File "E:\Project_python\api_cms\common\requests_util.py", line 185, in analysis_yaml
    res = self.send_request(name =name,method=method,
  File "E:\Project_python\api_cms\common\requests_util.py", line 335, in send_request
    error_log("发送请求异常：异常信息: %s" % str(traceback.format_exc()))
  File "E:\Project_python\api_cms\common\logger_util.py", line 66, in error_log
    raise Exception(log_message)
Exception: 发送请求异常：异常信息: Traceback (most recent call last):
  File "E:\Project_python\api_cms\common\requests_util.py", line 312, in send_request
    self.last_headers = self.replace_load(headers)
  File "E:\Project_python\api_cms\common\requests_util.py", line 140, in replace_load
    new_value = getattr(DubugTalk(), func_name)(*args_value.split(','))
  File "E:\Project_python\api_cms\debug_talk.py", line 26, in get_extract_data
    return read_extract_file(node_name)
  File "E:\Project_python\api_cms\common\yaml_util.py", line 19, in read_extract_file
    return value[one_node]
TypeError: 'NoneType' object is not subscriptable


[2023-12-05 14:00:05,793] logger_util.py->error_log line:65 [INFO] 发送请求异常：异常信息: Traceback (most recent call last):
  File "E:\Project_python\api_cms\common\requests_util.py", line 312, in send_request
    self.last_headers = self.replace_load(headers)
  File "E:\Project_python\api_cms\common\requests_util.py", line 140, in replace_load
    new_value = getattr(DubugTalk(), func_name)(*args_value.split(','))
  File "E:\Project_python\api_cms\debug_talk.py", line 26, in get_extract_data
    return read_extract_file(node_name)
  File "E:\Project_python\api_cms\common\yaml_util.py", line 19, in read_extract_file
    return value[one_node]
TypeError: 'NoneType' object is not subscriptable

[2023-12-05 14:00:05,794] logger_util.py->error_log line:65 [INFO] 分析YAML文件异常：异常信息: Traceback (most recent call last):
  File "E:\Project_python\api_cms\common\requests_util.py", line 312, in send_request
    self.last_headers = self.replace_load(headers)
  File "E:\Project_python\api_cms\common\requests_util.py", line 140, in replace_load
    new_value = getattr(DubugTalk(), func_name)(*args_value.split(','))
  File "E:\Project_python\api_cms\debug_talk.py", line 26, in get_extract_data
    return read_extract_file(node_name)
  File "E:\Project_python\api_cms\common\yaml_util.py", line 19, in read_extract_file
    return value[one_node]
TypeError: 'NoneType' object is not subscriptable

During handling of the above exception, another exception occurred:

Traceback (most recent call last):
  File "E:\Project_python\api_cms\common\requests_util.py", line 185, in analysis_yaml
    res = self.send_request(name =name,method=method,
  File "E:\Project_python\api_cms\common\requests_util.py", line 335, in send_request
    error_log("发送请求异常：异常信息: %s" % str(traceback.format_exc()))
  File "E:\Project_python\api_cms\common\logger_util.py", line 66, in error_log
    raise Exception(log_message)
Exception: 发送请求异常：异常信息: Traceback (most recent call last):
  File "E:\Project_python\api_cms\common\requests_util.py", line 312, in send_request
    self.last_headers = self.replace_load(headers)
  File "E:\Project_python\api_cms\common\requests_util.py", line 140, in replace_load
    new_value = getattr(DubugTalk(), func_name)(*args_value.split(','))
  File "E:\Project_python\api_cms\debug_talk.py", line 26, in get_extract_data
    return read_extract_file(node_name)
  File "E:\Project_python\api_cms\common\yaml_util.py", line 19, in read_extract_file
    return value[one_node]
TypeError: 'NoneType' object is not subscriptable


[2023-12-05 14:00:05,846] logger_util.py->error_log line:65 [INFO] 发送请求异常：异常信息: Traceback (most recent call last):
  File "E:\Project_python\api_cms\common\requests_util.py", line 312, in send_request
    self.last_headers = self.replace_load(headers)
  File "E:\Project_python\api_cms\common\requests_util.py", line 140, in replace_load
    new_value = getattr(DubugTalk(), func_name)(*args_value.split(','))
  File "E:\Project_python\api_cms\debug_talk.py", line 26, in get_extract_data
    return read_extract_file(node_name)
  File "E:\Project_python\api_cms\common\yaml_util.py", line 19, in read_extract_file
    return value[one_node]
TypeError: 'NoneType' object is not subscriptable

[2023-12-05 14:00:05,847] logger_util.py->error_log line:65 [INFO] 分析YAML文件异常：异常信息: Traceback (most recent call last):
  File "E:\Project_python\api_cms\common\requests_util.py", line 312, in send_request
    self.last_headers = self.replace_load(headers)
  File "E:\Project_python\api_cms\common\requests_util.py", line 140, in replace_load
    new_value = getattr(DubugTalk(), func_name)(*args_value.split(','))
  File "E:\Project_python\api_cms\debug_talk.py", line 26, in get_extract_data
    return read_extract_file(node_name)
  File "E:\Project_python\api_cms\common\yaml_util.py", line 19, in read_extract_file
    return value[one_node]
TypeError: 'NoneType' object is not subscriptable

During handling of the above exception, another exception occurred:

Traceback (most recent call last):
  File "E:\Project_python\api_cms\common\requests_util.py", line 185, in analysis_yaml
    res = self.send_request(name =name,method=method,
  File "E:\Project_python\api_cms\common\requests_util.py", line 335, in send_request
    error_log("发送请求异常：异常信息: %s" % str(traceback.format_exc()))
  File "E:\Project_python\api_cms\common\logger_util.py", line 66, in error_log
    raise Exception(log_message)
Exception: 发送请求异常：异常信息: Traceback (most recent call last):
  File "E:\Project_python\api_cms\common\requests_util.py", line 312, in send_request
    self.last_headers = self.replace_load(headers)
  File "E:\Project_python\api_cms\common\requests_util.py", line 140, in replace_load
    new_value = getattr(DubugTalk(), func_name)(*args_value.split(','))
  File "E:\Project_python\api_cms\debug_talk.py", line 26, in get_extract_data
    return read_extract_file(node_name)
  File "E:\Project_python\api_cms\common\yaml_util.py", line 19, in read_extract_file
    return value[one_node]
TypeError: 'NoneType' object is not subscriptable


[2023-12-05 14:00:05,896] logger_util.py->error_log line:65 [INFO] 发送请求异常：异常信息: Traceback (most recent call last):
  File "E:\Project_python\api_cms\common\requests_util.py", line 312, in send_request
    self.last_headers = self.replace_load(headers)
  File "E:\Project_python\api_cms\common\requests_util.py", line 140, in replace_load
    new_value = getattr(DubugTalk(), func_name)(*args_value.split(','))
  File "E:\Project_python\api_cms\debug_talk.py", line 26, in get_extract_data
    return read_extract_file(node_name)
  File "E:\Project_python\api_cms\common\yaml_util.py", line 19, in read_extract_file
    return value[one_node]
TypeError: 'NoneType' object is not subscriptable

[2023-12-05 14:00:05,896] logger_util.py->error_log line:65 [INFO] 分析YAML文件异常：异常信息: Traceback (most recent call last):
  File "E:\Project_python\api_cms\common\requests_util.py", line 312, in send_request
    self.last_headers = self.replace_load(headers)
  File "E:\Project_python\api_cms\common\requests_util.py", line 140, in replace_load
    new_value = getattr(DubugTalk(), func_name)(*args_value.split(','))
  File "E:\Project_python\api_cms\debug_talk.py", line 26, in get_extract_data
    return read_extract_file(node_name)
  File "E:\Project_python\api_cms\common\yaml_util.py", line 19, in read_extract_file
    return value[one_node]
TypeError: 'NoneType' object is not subscriptable

During handling of the above exception, another exception occurred:

Traceback (most recent call last):
  File "E:\Project_python\api_cms\common\requests_util.py", line 185, in analysis_yaml
    res = self.send_request(name =name,method=method,
  File "E:\Project_python\api_cms\common\requests_util.py", line 335, in send_request
    error_log("发送请求异常：异常信息: %s" % str(traceback.format_exc()))
  File "E:\Project_python\api_cms\common\logger_util.py", line 66, in error_log
    raise Exception(log_message)
Exception: 发送请求异常：异常信息: Traceback (most recent call last):
  File "E:\Project_python\api_cms\common\requests_util.py", line 312, in send_request
    self.last_headers = self.replace_load(headers)
  File "E:\Project_python\api_cms\common\requests_util.py", line 140, in replace_load
    new_value = getattr(DubugTalk(), func_name)(*args_value.split(','))
  File "E:\Project_python\api_cms\debug_talk.py", line 26, in get_extract_data
    return read_extract_file(node_name)
  File "E:\Project_python\api_cms\common\yaml_util.py", line 19, in read_extract_file
    return value[one_node]
TypeError: 'NoneType' object is not subscriptable


[2023-12-05 14:00:05,967] logger_util.py->error_log line:65 [INFO] 发送请求异常：异常信息: Traceback (most recent call last):
  File "E:\Project_python\api_cms\common\requests_util.py", line 312, in send_request
    self.last_headers = self.replace_load(headers)
  File "E:\Project_python\api_cms\common\requests_util.py", line 140, in replace_load
    new_value = getattr(DubugTalk(), func_name)(*args_value.split(','))
  File "E:\Project_python\api_cms\debug_talk.py", line 26, in get_extract_data
    return read_extract_file(node_name)
  File "E:\Project_python\api_cms\common\yaml_util.py", line 19, in read_extract_file
    return value[one_node]
TypeError: 'NoneType' object is not subscriptable

[2023-12-05 14:00:05,967] logger_util.py->error_log line:65 [INFO] 分析YAML文件异常：异常信息: Traceback (most recent call last):
  File "E:\Project_python\api_cms\common\requests_util.py", line 312, in send_request
    self.last_headers = self.replace_load(headers)
  File "E:\Project_python\api_cms\common\requests_util.py", line 140, in replace_load
    new_value = getattr(DubugTalk(), func_name)(*args_value.split(','))
  File "E:\Project_python\api_cms\debug_talk.py", line 26, in get_extract_data
    return read_extract_file(node_name)
  File "E:\Project_python\api_cms\common\yaml_util.py", line 19, in read_extract_file
    return value[one_node]
TypeError: 'NoneType' object is not subscriptable

During handling of the above exception, another exception occurred:

Traceback (most recent call last):
  File "E:\Project_python\api_cms\common\requests_util.py", line 185, in analysis_yaml
    res = self.send_request(name =name,method=method,
  File "E:\Project_python\api_cms\common\requests_util.py", line 335, in send_request
    error_log("发送请求异常：异常信息: %s" % str(traceback.format_exc()))
  File "E:\Project_python\api_cms\common\logger_util.py", line 66, in error_log
    raise Exception(log_message)
Exception: 发送请求异常：异常信息: Traceback (most recent call last):
  File "E:\Project_python\api_cms\common\requests_util.py", line 312, in send_request
    self.last_headers = self.replace_load(headers)
  File "E:\Project_python\api_cms\common\requests_util.py", line 140, in replace_load
    new_value = getattr(DubugTalk(), func_name)(*args_value.split(','))
  File "E:\Project_python\api_cms\debug_talk.py", line 26, in get_extract_data
    return read_extract_file(node_name)
  File "E:\Project_python\api_cms\common\yaml_util.py", line 19, in read_extract_file
    return value[one_node]
TypeError: 'NoneType' object is not subscriptable


[2023-12-05 14:00:06,016] logger_util.py->error_log line:65 [INFO] 发送请求异常：异常信息: Traceback (most recent call last):
  File "E:\Project_python\api_cms\common\requests_util.py", line 312, in send_request
    self.last_headers = self.replace_load(headers)
  File "E:\Project_python\api_cms\common\requests_util.py", line 140, in replace_load
    new_value = getattr(DubugTalk(), func_name)(*args_value.split(','))
  File "E:\Project_python\api_cms\debug_talk.py", line 26, in get_extract_data
    return read_extract_file(node_name)
  File "E:\Project_python\api_cms\common\yaml_util.py", line 19, in read_extract_file
    return value[one_node]
TypeError: 'NoneType' object is not subscriptable

[2023-12-05 14:00:06,017] logger_util.py->error_log line:65 [INFO] 分析YAML文件异常：异常信息: Traceback (most recent call last):
  File "E:\Project_python\api_cms\common\requests_util.py", line 312, in send_request
    self.last_headers = self.replace_load(headers)
  File "E:\Project_python\api_cms\common\requests_util.py", line 140, in replace_load
    new_value = getattr(DubugTalk(), func_name)(*args_value.split(','))
  File "E:\Project_python\api_cms\debug_talk.py", line 26, in get_extract_data
    return read_extract_file(node_name)
  File "E:\Project_python\api_cms\common\yaml_util.py", line 19, in read_extract_file
    return value[one_node]
TypeError: 'NoneType' object is not subscriptable

During handling of the above exception, another exception occurred:

Traceback (most recent call last):
  File "E:\Project_python\api_cms\common\requests_util.py", line 185, in analysis_yaml
    res = self.send_request(name =name,method=method,
  File "E:\Project_python\api_cms\common\requests_util.py", line 335, in send_request
    error_log("发送请求异常：异常信息: %s" % str(traceback.format_exc()))
  File "E:\Project_python\api_cms\common\logger_util.py", line 66, in error_log
    raise Exception(log_message)
Exception: 发送请求异常：异常信息: Traceback (most recent call last):
  File "E:\Project_python\api_cms\common\requests_util.py", line 312, in send_request
    self.last_headers = self.replace_load(headers)
  File "E:\Project_python\api_cms\common\requests_util.py", line 140, in replace_load
    new_value = getattr(DubugTalk(), func_name)(*args_value.split(','))
  File "E:\Project_python\api_cms\debug_talk.py", line 26, in get_extract_data
    return read_extract_file(node_name)
  File "E:\Project_python\api_cms\common\yaml_util.py", line 19, in read_extract_file
    return value[one_node]
TypeError: 'NoneType' object is not subscriptable


[2023-12-05 14:00:06,065] logger_util.py->error_log line:65 [INFO] 发送请求异常：异常信息: Traceback (most recent call last):
  File "E:\Project_python\api_cms\common\requests_util.py", line 312, in send_request
    self.last_headers = self.replace_load(headers)
  File "E:\Project_python\api_cms\common\requests_util.py", line 140, in replace_load
    new_value = getattr(DubugTalk(), func_name)(*args_value.split(','))
  File "E:\Project_python\api_cms\debug_talk.py", line 26, in get_extract_data
    return read_extract_file(node_name)
  File "E:\Project_python\api_cms\common\yaml_util.py", line 19, in read_extract_file
    return value[one_node]
TypeError: 'NoneType' object is not subscriptable

[2023-12-05 14:00:06,065] logger_util.py->error_log line:65 [INFO] 分析YAML文件异常：异常信息: Traceback (most recent call last):
  File "E:\Project_python\api_cms\common\requests_util.py", line 312, in send_request
    self.last_headers = self.replace_load(headers)
  File "E:\Project_python\api_cms\common\requests_util.py", line 140, in replace_load
    new_value = getattr(DubugTalk(), func_name)(*args_value.split(','))
  File "E:\Project_python\api_cms\debug_talk.py", line 26, in get_extract_data
    return read_extract_file(node_name)
  File "E:\Project_python\api_cms\common\yaml_util.py", line 19, in read_extract_file
    return value[one_node]
TypeError: 'NoneType' object is not subscriptable

During handling of the above exception, another exception occurred:

Traceback (most recent call last):
  File "E:\Project_python\api_cms\common\requests_util.py", line 185, in analysis_yaml
    res = self.send_request(name =name,method=method,
  File "E:\Project_python\api_cms\common\requests_util.py", line 335, in send_request
    error_log("发送请求异常：异常信息: %s" % str(traceback.format_exc()))
  File "E:\Project_python\api_cms\common\logger_util.py", line 66, in error_log
    raise Exception(log_message)
Exception: 发送请求异常：异常信息: Traceback (most recent call last):
  File "E:\Project_python\api_cms\common\requests_util.py", line 312, in send_request
    self.last_headers = self.replace_load(headers)
  File "E:\Project_python\api_cms\common\requests_util.py", line 140, in replace_load
    new_value = getattr(DubugTalk(), func_name)(*args_value.split(','))
  File "E:\Project_python\api_cms\debug_talk.py", line 26, in get_extract_data
    return read_extract_file(node_name)
  File "E:\Project_python\api_cms\common\yaml_util.py", line 19, in read_extract_file
    return value[one_node]
TypeError: 'NoneType' object is not subscriptable


[2023-12-05 14:00:06,113] logger_util.py->error_log line:65 [INFO] 发送请求异常：异常信息: Traceback (most recent call last):
  File "E:\Project_python\api_cms\common\requests_util.py", line 312, in send_request
    self.last_headers = self.replace_load(headers)
  File "E:\Project_python\api_cms\common\requests_util.py", line 140, in replace_load
    new_value = getattr(DubugTalk(), func_name)(*args_value.split(','))
  File "E:\Project_python\api_cms\debug_talk.py", line 26, in get_extract_data
    return read_extract_file(node_name)
  File "E:\Project_python\api_cms\common\yaml_util.py", line 19, in read_extract_file
    return value[one_node]
TypeError: 'NoneType' object is not subscriptable

[2023-12-05 14:00:06,114] logger_util.py->error_log line:65 [INFO] 分析YAML文件异常：异常信息: Traceback (most recent call last):
  File "E:\Project_python\api_cms\common\requests_util.py", line 312, in send_request
    self.last_headers = self.replace_load(headers)
  File "E:\Project_python\api_cms\common\requests_util.py", line 140, in replace_load
    new_value = getattr(DubugTalk(), func_name)(*args_value.split(','))
  File "E:\Project_python\api_cms\debug_talk.py", line 26, in get_extract_data
    return read_extract_file(node_name)
  File "E:\Project_python\api_cms\common\yaml_util.py", line 19, in read_extract_file
    return value[one_node]
TypeError: 'NoneType' object is not subscriptable

During handling of the above exception, another exception occurred:

Traceback (most recent call last):
  File "E:\Project_python\api_cms\common\requests_util.py", line 185, in analysis_yaml
    res = self.send_request(name =name,method=method,
  File "E:\Project_python\api_cms\common\requests_util.py", line 335, in send_request
    error_log("发送请求异常：异常信息: %s" % str(traceback.format_exc()))
  File "E:\Project_python\api_cms\common\logger_util.py", line 66, in error_log
    raise Exception(log_message)
Exception: 发送请求异常：异常信息: Traceback (most recent call last):
  File "E:\Project_python\api_cms\common\requests_util.py", line 312, in send_request
    self.last_headers = self.replace_load(headers)
  File "E:\Project_python\api_cms\common\requests_util.py", line 140, in replace_load
    new_value = getattr(DubugTalk(), func_name)(*args_value.split(','))
  File "E:\Project_python\api_cms\debug_talk.py", line 26, in get_extract_data
    return read_extract_file(node_name)
  File "E:\Project_python\api_cms\common\yaml_util.py", line 19, in read_extract_file
    return value[one_node]
TypeError: 'NoneType' object is not subscriptable


[2023-12-05 14:00:06,157] logger_util.py->error_log line:65 [INFO] 发送请求异常：异常信息: Traceback (most recent call last):
  File "E:\Project_python\api_cms\common\requests_util.py", line 312, in send_request
    self.last_headers = self.replace_load(headers)
  File "E:\Project_python\api_cms\common\requests_util.py", line 140, in replace_load
    new_value = getattr(DubugTalk(), func_name)(*args_value.split(','))
  File "E:\Project_python\api_cms\debug_talk.py", line 26, in get_extract_data
    return read_extract_file(node_name)
  File "E:\Project_python\api_cms\common\yaml_util.py", line 19, in read_extract_file
    return value[one_node]
TypeError: 'NoneType' object is not subscriptable

[2023-12-05 14:00:06,158] logger_util.py->error_log line:65 [INFO] 分析YAML文件异常：异常信息: Traceback (most recent call last):
  File "E:\Project_python\api_cms\common\requests_util.py", line 312, in send_request
    self.last_headers = self.replace_load(headers)
  File "E:\Project_python\api_cms\common\requests_util.py", line 140, in replace_load
    new_value = getattr(DubugTalk(), func_name)(*args_value.split(','))
  File "E:\Project_python\api_cms\debug_talk.py", line 26, in get_extract_data
    return read_extract_file(node_name)
  File "E:\Project_python\api_cms\common\yaml_util.py", line 19, in read_extract_file
    return value[one_node]
TypeError: 'NoneType' object is not subscriptable

During handling of the above exception, another exception occurred:

Traceback (most recent call last):
  File "E:\Project_python\api_cms\common\requests_util.py", line 185, in analysis_yaml
    res = self.send_request(name =name,method=method,
  File "E:\Project_python\api_cms\common\requests_util.py", line 335, in send_request
    error_log("发送请求异常：异常信息: %s" % str(traceback.format_exc()))
  File "E:\Project_python\api_cms\common\logger_util.py", line 66, in error_log
    raise Exception(log_message)
Exception: 发送请求异常：异常信息: Traceback (most recent call last):
  File "E:\Project_python\api_cms\common\requests_util.py", line 312, in send_request
    self.last_headers = self.replace_load(headers)
  File "E:\Project_python\api_cms\common\requests_util.py", line 140, in replace_load
    new_value = getattr(DubugTalk(), func_name)(*args_value.split(','))
  File "E:\Project_python\api_cms\debug_talk.py", line 26, in get_extract_data
    return read_extract_file(node_name)
  File "E:\Project_python\api_cms\common\yaml_util.py", line 19, in read_extract_file
    return value[one_node]
TypeError: 'NoneType' object is not subscriptable


[2023-12-05 14:00:06,202] logger_util.py->error_log line:65 [INFO] 发送请求异常：异常信息: Traceback (most recent call last):
  File "E:\Project_python\api_cms\common\requests_util.py", line 312, in send_request
    self.last_headers = self.replace_load(headers)
  File "E:\Project_python\api_cms\common\requests_util.py", line 140, in replace_load
    new_value = getattr(DubugTalk(), func_name)(*args_value.split(','))
  File "E:\Project_python\api_cms\debug_talk.py", line 26, in get_extract_data
    return read_extract_file(node_name)
  File "E:\Project_python\api_cms\common\yaml_util.py", line 19, in read_extract_file
    return value[one_node]
TypeError: 'NoneType' object is not subscriptable

[2023-12-05 14:00:06,203] logger_util.py->error_log line:65 [INFO] 分析YAML文件异常：异常信息: Traceback (most recent call last):
  File "E:\Project_python\api_cms\common\requests_util.py", line 312, in send_request
    self.last_headers = self.replace_load(headers)
  File "E:\Project_python\api_cms\common\requests_util.py", line 140, in replace_load
    new_value = getattr(DubugTalk(), func_name)(*args_value.split(','))
  File "E:\Project_python\api_cms\debug_talk.py", line 26, in get_extract_data
    return read_extract_file(node_name)
  File "E:\Project_python\api_cms\common\yaml_util.py", line 19, in read_extract_file
    return value[one_node]
TypeError: 'NoneType' object is not subscriptable

During handling of the above exception, another exception occurred:

Traceback (most recent call last):
  File "E:\Project_python\api_cms\common\requests_util.py", line 185, in analysis_yaml
    res = self.send_request(name =name,method=method,
  File "E:\Project_python\api_cms\common\requests_util.py", line 335, in send_request
    error_log("发送请求异常：异常信息: %s" % str(traceback.format_exc()))
  File "E:\Project_python\api_cms\common\logger_util.py", line 66, in error_log
    raise Exception(log_message)
Exception: 发送请求异常：异常信息: Traceback (most recent call last):
  File "E:\Project_python\api_cms\common\requests_util.py", line 312, in send_request
    self.last_headers = self.replace_load(headers)
  File "E:\Project_python\api_cms\common\requests_util.py", line 140, in replace_load
    new_value = getattr(DubugTalk(), func_name)(*args_value.split(','))
  File "E:\Project_python\api_cms\debug_talk.py", line 26, in get_extract_data
    return read_extract_file(node_name)
  File "E:\Project_python\api_cms\common\yaml_util.py", line 19, in read_extract_file
    return value[one_node]
TypeError: 'NoneType' object is not subscriptable


[2023-12-05 14:00:06,250] logger_util.py->error_log line:65 [INFO] 发送请求异常：异常信息: Traceback (most recent call last):
  File "E:\Project_python\api_cms\common\requests_util.py", line 312, in send_request
    self.last_headers = self.replace_load(headers)
  File "E:\Project_python\api_cms\common\requests_util.py", line 140, in replace_load
    new_value = getattr(DubugTalk(), func_name)(*args_value.split(','))
  File "E:\Project_python\api_cms\debug_talk.py", line 26, in get_extract_data
    return read_extract_file(node_name)
  File "E:\Project_python\api_cms\common\yaml_util.py", line 19, in read_extract_file
    return value[one_node]
TypeError: 'NoneType' object is not subscriptable

[2023-12-05 14:00:06,250] logger_util.py->error_log line:65 [INFO] 分析YAML文件异常：异常信息: Traceback (most recent call last):
  File "E:\Project_python\api_cms\common\requests_util.py", line 312, in send_request
    self.last_headers = self.replace_load(headers)
  File "E:\Project_python\api_cms\common\requests_util.py", line 140, in replace_load
    new_value = getattr(DubugTalk(), func_name)(*args_value.split(','))
  File "E:\Project_python\api_cms\debug_talk.py", line 26, in get_extract_data
    return read_extract_file(node_name)
  File "E:\Project_python\api_cms\common\yaml_util.py", line 19, in read_extract_file
    return value[one_node]
TypeError: 'NoneType' object is not subscriptable

During handling of the above exception, another exception occurred:

Traceback (most recent call last):
  File "E:\Project_python\api_cms\common\requests_util.py", line 185, in analysis_yaml
    res = self.send_request(name =name,method=method,
  File "E:\Project_python\api_cms\common\requests_util.py", line 335, in send_request
    error_log("发送请求异常：异常信息: %s" % str(traceback.format_exc()))
  File "E:\Project_python\api_cms\common\logger_util.py", line 66, in error_log
    raise Exception(log_message)
Exception: 发送请求异常：异常信息: Traceback (most recent call last):
  File "E:\Project_python\api_cms\common\requests_util.py", line 312, in send_request
    self.last_headers = self.replace_load(headers)
  File "E:\Project_python\api_cms\common\requests_util.py", line 140, in replace_load
    new_value = getattr(DubugTalk(), func_name)(*args_value.split(','))
  File "E:\Project_python\api_cms\debug_talk.py", line 26, in get_extract_data
    return read_extract_file(node_name)
  File "E:\Project_python\api_cms\common\yaml_util.py", line 19, in read_extract_file
    return value[one_node]
TypeError: 'NoneType' object is not subscriptable


[2023-12-05 14:00:06,297] logger_util.py->error_log line:65 [INFO] 发送请求异常：异常信息: Traceback (most recent call last):
  File "E:\Project_python\api_cms\common\requests_util.py", line 312, in send_request
    self.last_headers = self.replace_load(headers)
  File "E:\Project_python\api_cms\common\requests_util.py", line 140, in replace_load
    new_value = getattr(DubugTalk(), func_name)(*args_value.split(','))
  File "E:\Project_python\api_cms\debug_talk.py", line 26, in get_extract_data
    return read_extract_file(node_name)
  File "E:\Project_python\api_cms\common\yaml_util.py", line 19, in read_extract_file
    return value[one_node]
TypeError: 'NoneType' object is not subscriptable

[2023-12-05 14:00:06,298] logger_util.py->error_log line:65 [INFO] 分析YAML文件异常：异常信息: Traceback (most recent call last):
  File "E:\Project_python\api_cms\common\requests_util.py", line 312, in send_request
    self.last_headers = self.replace_load(headers)
  File "E:\Project_python\api_cms\common\requests_util.py", line 140, in replace_load
    new_value = getattr(DubugTalk(), func_name)(*args_value.split(','))
  File "E:\Project_python\api_cms\debug_talk.py", line 26, in get_extract_data
    return read_extract_file(node_name)
  File "E:\Project_python\api_cms\common\yaml_util.py", line 19, in read_extract_file
    return value[one_node]
TypeError: 'NoneType' object is not subscriptable

During handling of the above exception, another exception occurred:

Traceback (most recent call last):
  File "E:\Project_python\api_cms\common\requests_util.py", line 185, in analysis_yaml
    res = self.send_request(name =name,method=method,
  File "E:\Project_python\api_cms\common\requests_util.py", line 335, in send_request
    error_log("发送请求异常：异常信息: %s" % str(traceback.format_exc()))
  File "E:\Project_python\api_cms\common\logger_util.py", line 66, in error_log
    raise Exception(log_message)
Exception: 发送请求异常：异常信息: Traceback (most recent call last):
  File "E:\Project_python\api_cms\common\requests_util.py", line 312, in send_request
    self.last_headers = self.replace_load(headers)
  File "E:\Project_python\api_cms\common\requests_util.py", line 140, in replace_load
    new_value = getattr(DubugTalk(), func_name)(*args_value.split(','))
  File "E:\Project_python\api_cms\debug_talk.py", line 26, in get_extract_data
    return read_extract_file(node_name)
  File "E:\Project_python\api_cms\common\yaml_util.py", line 19, in read_extract_file
    return value[one_node]
TypeError: 'NoneType' object is not subscriptable


[2023-12-05 14:00:06,361] logger_util.py->error_log line:65 [INFO] 发送请求异常：异常信息: Traceback (most recent call last):
  File "E:\Project_python\api_cms\common\requests_util.py", line 312, in send_request
    self.last_headers = self.replace_load(headers)
  File "E:\Project_python\api_cms\common\requests_util.py", line 140, in replace_load
    new_value = getattr(DubugTalk(), func_name)(*args_value.split(','))
  File "E:\Project_python\api_cms\debug_talk.py", line 26, in get_extract_data
    return read_extract_file(node_name)
  File "E:\Project_python\api_cms\common\yaml_util.py", line 19, in read_extract_file
    return value[one_node]
TypeError: 'NoneType' object is not subscriptable

[2023-12-05 14:00:06,361] logger_util.py->error_log line:65 [INFO] 分析YAML文件异常：异常信息: Traceback (most recent call last):
  File "E:\Project_python\api_cms\common\requests_util.py", line 312, in send_request
    self.last_headers = self.replace_load(headers)
  File "E:\Project_python\api_cms\common\requests_util.py", line 140, in replace_load
    new_value = getattr(DubugTalk(), func_name)(*args_value.split(','))
  File "E:\Project_python\api_cms\debug_talk.py", line 26, in get_extract_data
    return read_extract_file(node_name)
  File "E:\Project_python\api_cms\common\yaml_util.py", line 19, in read_extract_file
    return value[one_node]
TypeError: 'NoneType' object is not subscriptable

During handling of the above exception, another exception occurred:

Traceback (most recent call last):
  File "E:\Project_python\api_cms\common\requests_util.py", line 185, in analysis_yaml
    res = self.send_request(name =name,method=method,
  File "E:\Project_python\api_cms\common\requests_util.py", line 335, in send_request
    error_log("发送请求异常：异常信息: %s" % str(traceback.format_exc()))
  File "E:\Project_python\api_cms\common\logger_util.py", line 66, in error_log
    raise Exception(log_message)
Exception: 发送请求异常：异常信息: Traceback (most recent call last):
  File "E:\Project_python\api_cms\common\requests_util.py", line 312, in send_request
    self.last_headers = self.replace_load(headers)
  File "E:\Project_python\api_cms\common\requests_util.py", line 140, in replace_load
    new_value = getattr(DubugTalk(), func_name)(*args_value.split(','))
  File "E:\Project_python\api_cms\debug_talk.py", line 26, in get_extract_data
    return read_extract_file(node_name)
  File "E:\Project_python\api_cms\common\yaml_util.py", line 19, in read_extract_file
    return value[one_node]
TypeError: 'NoneType' object is not subscriptable


[2023-12-05 14:00:06,410] logger_util.py->error_log line:65 [INFO] 发送请求异常：异常信息: Traceback (most recent call last):
  File "E:\Project_python\api_cms\common\requests_util.py", line 309, in send_request
    self.base_url = self.replace_load(self.base_url) + self.replace_load(url)
  File "E:\Project_python\api_cms\common\requests_util.py", line 140, in replace_load
    new_value = getattr(DubugTalk(), func_name)(*args_value.split(','))
  File "E:\Project_python\api_cms\debug_talk.py", line 26, in get_extract_data
    return read_extract_file(node_name)
  File "E:\Project_python\api_cms\common\yaml_util.py", line 19, in read_extract_file
    return value[one_node]
TypeError: 'NoneType' object is not subscriptable

[2023-12-05 14:00:06,410] logger_util.py->error_log line:65 [INFO] 分析YAML文件异常：异常信息: Traceback (most recent call last):
  File "E:\Project_python\api_cms\common\requests_util.py", line 309, in send_request
    self.base_url = self.replace_load(self.base_url) + self.replace_load(url)
  File "E:\Project_python\api_cms\common\requests_util.py", line 140, in replace_load
    new_value = getattr(DubugTalk(), func_name)(*args_value.split(','))
  File "E:\Project_python\api_cms\debug_talk.py", line 26, in get_extract_data
    return read_extract_file(node_name)
  File "E:\Project_python\api_cms\common\yaml_util.py", line 19, in read_extract_file
    return value[one_node]
TypeError: 'NoneType' object is not subscriptable

During handling of the above exception, another exception occurred:

Traceback (most recent call last):
  File "E:\Project_python\api_cms\common\requests_util.py", line 185, in analysis_yaml
    res = self.send_request(name =name,method=method,
  File "E:\Project_python\api_cms\common\requests_util.py", line 335, in send_request
    error_log("发送请求异常：异常信息: %s" % str(traceback.format_exc()))
  File "E:\Project_python\api_cms\common\logger_util.py", line 66, in error_log
    raise Exception(log_message)
Exception: 发送请求异常：异常信息: Traceback (most recent call last):
  File "E:\Project_python\api_cms\common\requests_util.py", line 309, in send_request
    self.base_url = self.replace_load(self.base_url) + self.replace_load(url)
  File "E:\Project_python\api_cms\common\requests_util.py", line 140, in replace_load
    new_value = getattr(DubugTalk(), func_name)(*args_value.split(','))
  File "E:\Project_python\api_cms\debug_talk.py", line 26, in get_extract_data
    return read_extract_file(node_name)
  File "E:\Project_python\api_cms\common\yaml_util.py", line 19, in read_extract_file
    return value[one_node]
TypeError: 'NoneType' object is not subscriptable


[2023-12-05 14:00:06,457] logger_util.py->error_log line:65 [INFO] 发送请求异常：异常信息: Traceback (most recent call last):
  File "E:\Project_python\api_cms\common\requests_util.py", line 312, in send_request
    self.last_headers = self.replace_load(headers)
  File "E:\Project_python\api_cms\common\requests_util.py", line 140, in replace_load
    new_value = getattr(DubugTalk(), func_name)(*args_value.split(','))
  File "E:\Project_python\api_cms\debug_talk.py", line 26, in get_extract_data
    return read_extract_file(node_name)
  File "E:\Project_python\api_cms\common\yaml_util.py", line 19, in read_extract_file
    return value[one_node]
TypeError: 'NoneType' object is not subscriptable

[2023-12-05 14:00:06,458] logger_util.py->error_log line:65 [INFO] 分析YAML文件异常：异常信息: Traceback (most recent call last):
  File "E:\Project_python\api_cms\common\requests_util.py", line 312, in send_request
    self.last_headers = self.replace_load(headers)
  File "E:\Project_python\api_cms\common\requests_util.py", line 140, in replace_load
    new_value = getattr(DubugTalk(), func_name)(*args_value.split(','))
  File "E:\Project_python\api_cms\debug_talk.py", line 26, in get_extract_data
    return read_extract_file(node_name)
  File "E:\Project_python\api_cms\common\yaml_util.py", line 19, in read_extract_file
    return value[one_node]
TypeError: 'NoneType' object is not subscriptable

During handling of the above exception, another exception occurred:

Traceback (most recent call last):
  File "E:\Project_python\api_cms\common\requests_util.py", line 185, in analysis_yaml
    res = self.send_request(name =name,method=method,
  File "E:\Project_python\api_cms\common\requests_util.py", line 335, in send_request
    error_log("发送请求异常：异常信息: %s" % str(traceback.format_exc()))
  File "E:\Project_python\api_cms\common\logger_util.py", line 66, in error_log
    raise Exception(log_message)
Exception: 发送请求异常：异常信息: Traceback (most recent call last):
  File "E:\Project_python\api_cms\common\requests_util.py", line 312, in send_request
    self.last_headers = self.replace_load(headers)
  File "E:\Project_python\api_cms\common\requests_util.py", line 140, in replace_load
    new_value = getattr(DubugTalk(), func_name)(*args_value.split(','))
  File "E:\Project_python\api_cms\debug_talk.py", line 26, in get_extract_data
    return read_extract_file(node_name)
  File "E:\Project_python\api_cms\common\yaml_util.py", line 19, in read_extract_file
    return value[one_node]
TypeError: 'NoneType' object is not subscriptable


[2023-12-05 14:00:06,504] logger_util.py->error_log line:65 [INFO] 发送请求异常：异常信息: Traceback (most recent call last):
  File "E:\Project_python\api_cms\common\requests_util.py", line 309, in send_request
    self.base_url = self.replace_load(self.base_url) + self.replace_load(url)
  File "E:\Project_python\api_cms\common\requests_util.py", line 140, in replace_load
    new_value = getattr(DubugTalk(), func_name)(*args_value.split(','))
  File "E:\Project_python\api_cms\debug_talk.py", line 26, in get_extract_data
    return read_extract_file(node_name)
  File "E:\Project_python\api_cms\common\yaml_util.py", line 19, in read_extract_file
    return value[one_node]
TypeError: 'NoneType' object is not subscriptable

[2023-12-05 14:00:06,505] logger_util.py->error_log line:65 [INFO] 分析YAML文件异常：异常信息: Traceback (most recent call last):
  File "E:\Project_python\api_cms\common\requests_util.py", line 309, in send_request
    self.base_url = self.replace_load(self.base_url) + self.replace_load(url)
  File "E:\Project_python\api_cms\common\requests_util.py", line 140, in replace_load
    new_value = getattr(DubugTalk(), func_name)(*args_value.split(','))
  File "E:\Project_python\api_cms\debug_talk.py", line 26, in get_extract_data
    return read_extract_file(node_name)
  File "E:\Project_python\api_cms\common\yaml_util.py", line 19, in read_extract_file
    return value[one_node]
TypeError: 'NoneType' object is not subscriptable

During handling of the above exception, another exception occurred:

Traceback (most recent call last):
  File "E:\Project_python\api_cms\common\requests_util.py", line 185, in analysis_yaml
    res = self.send_request(name =name,method=method,
  File "E:\Project_python\api_cms\common\requests_util.py", line 335, in send_request
    error_log("发送请求异常：异常信息: %s" % str(traceback.format_exc()))
  File "E:\Project_python\api_cms\common\logger_util.py", line 66, in error_log
    raise Exception(log_message)
Exception: 发送请求异常：异常信息: Traceback (most recent call last):
  File "E:\Project_python\api_cms\common\requests_util.py", line 309, in send_request
    self.base_url = self.replace_load(self.base_url) + self.replace_load(url)
  File "E:\Project_python\api_cms\common\requests_util.py", line 140, in replace_load
    new_value = getattr(DubugTalk(), func_name)(*args_value.split(','))
  File "E:\Project_python\api_cms\debug_talk.py", line 26, in get_extract_data
    return read_extract_file(node_name)
  File "E:\Project_python\api_cms\common\yaml_util.py", line 19, in read_extract_file
    return value[one_node]
TypeError: 'NoneType' object is not subscriptable


[2023-12-05 14:00:06,552] logger_util.py->error_log line:65 [INFO] 发送请求异常：异常信息: Traceback (most recent call last):
  File "E:\Project_python\api_cms\common\requests_util.py", line 309, in send_request
    self.base_url = self.replace_load(self.base_url) + self.replace_load(url)
  File "E:\Project_python\api_cms\common\requests_util.py", line 140, in replace_load
    new_value = getattr(DubugTalk(), func_name)(*args_value.split(','))
  File "E:\Project_python\api_cms\debug_talk.py", line 26, in get_extract_data
    return read_extract_file(node_name)
  File "E:\Project_python\api_cms\common\yaml_util.py", line 19, in read_extract_file
    return value[one_node]
TypeError: 'NoneType' object is not subscriptable

[2023-12-05 14:00:06,552] logger_util.py->error_log line:65 [INFO] 分析YAML文件异常：异常信息: Traceback (most recent call last):
  File "E:\Project_python\api_cms\common\requests_util.py", line 309, in send_request
    self.base_url = self.replace_load(self.base_url) + self.replace_load(url)
  File "E:\Project_python\api_cms\common\requests_util.py", line 140, in replace_load
    new_value = getattr(DubugTalk(), func_name)(*args_value.split(','))
  File "E:\Project_python\api_cms\debug_talk.py", line 26, in get_extract_data
    return read_extract_file(node_name)
  File "E:\Project_python\api_cms\common\yaml_util.py", line 19, in read_extract_file
    return value[one_node]
TypeError: 'NoneType' object is not subscriptable

During handling of the above exception, another exception occurred:

Traceback (most recent call last):
  File "E:\Project_python\api_cms\common\requests_util.py", line 185, in analysis_yaml
    res = self.send_request(name =name,method=method,
  File "E:\Project_python\api_cms\common\requests_util.py", line 335, in send_request
    error_log("发送请求异常：异常信息: %s" % str(traceback.format_exc()))
  File "E:\Project_python\api_cms\common\logger_util.py", line 66, in error_log
    raise Exception(log_message)
Exception: 发送请求异常：异常信息: Traceback (most recent call last):
  File "E:\Project_python\api_cms\common\requests_util.py", line 309, in send_request
    self.base_url = self.replace_load(self.base_url) + self.replace_load(url)
  File "E:\Project_python\api_cms\common\requests_util.py", line 140, in replace_load
    new_value = getattr(DubugTalk(), func_name)(*args_value.split(','))
  File "E:\Project_python\api_cms\debug_talk.py", line 26, in get_extract_data
    return read_extract_file(node_name)
  File "E:\Project_python\api_cms\common\yaml_util.py", line 19, in read_extract_file
    return value[one_node]
TypeError: 'NoneType' object is not subscriptable


[2023-12-05 14:00:06,599] logger_util.py->error_log line:65 [INFO] 发送请求异常：异常信息: Traceback (most recent call last):
  File "E:\Project_python\api_cms\common\requests_util.py", line 309, in send_request
    self.base_url = self.replace_load(self.base_url) + self.replace_load(url)
  File "E:\Project_python\api_cms\common\requests_util.py", line 140, in replace_load
    new_value = getattr(DubugTalk(), func_name)(*args_value.split(','))
  File "E:\Project_python\api_cms\debug_talk.py", line 26, in get_extract_data
    return read_extract_file(node_name)
  File "E:\Project_python\api_cms\common\yaml_util.py", line 19, in read_extract_file
    return value[one_node]
TypeError: 'NoneType' object is not subscriptable

[2023-12-05 14:00:06,600] logger_util.py->error_log line:65 [INFO] 分析YAML文件异常：异常信息: Traceback (most recent call last):
  File "E:\Project_python\api_cms\common\requests_util.py", line 309, in send_request
    self.base_url = self.replace_load(self.base_url) + self.replace_load(url)
  File "E:\Project_python\api_cms\common\requests_util.py", line 140, in replace_load
    new_value = getattr(DubugTalk(), func_name)(*args_value.split(','))
  File "E:\Project_python\api_cms\debug_talk.py", line 26, in get_extract_data
    return read_extract_file(node_name)
  File "E:\Project_python\api_cms\common\yaml_util.py", line 19, in read_extract_file
    return value[one_node]
TypeError: 'NoneType' object is not subscriptable

During handling of the above exception, another exception occurred:

Traceback (most recent call last):
  File "E:\Project_python\api_cms\common\requests_util.py", line 185, in analysis_yaml
    res = self.send_request(name =name,method=method,
  File "E:\Project_python\api_cms\common\requests_util.py", line 335, in send_request
    error_log("发送请求异常：异常信息: %s" % str(traceback.format_exc()))
  File "E:\Project_python\api_cms\common\logger_util.py", line 66, in error_log
    raise Exception(log_message)
Exception: 发送请求异常：异常信息: Traceback (most recent call last):
  File "E:\Project_python\api_cms\common\requests_util.py", line 309, in send_request
    self.base_url = self.replace_load(self.base_url) + self.replace_load(url)
  File "E:\Project_python\api_cms\common\requests_util.py", line 140, in replace_load
    new_value = getattr(DubugTalk(), func_name)(*args_value.split(','))
  File "E:\Project_python\api_cms\debug_talk.py", line 26, in get_extract_data
    return read_extract_file(node_name)
  File "E:\Project_python\api_cms\common\yaml_util.py", line 19, in read_extract_file
    return value[one_node]
TypeError: 'NoneType' object is not subscriptable


[2023-12-05 14:00:06,646] logger_util.py->error_log line:65 [INFO] 发送请求异常：异常信息: Traceback (most recent call last):
  File "E:\Project_python\api_cms\common\requests_util.py", line 309, in send_request
    self.base_url = self.replace_load(self.base_url) + self.replace_load(url)
  File "E:\Project_python\api_cms\common\requests_util.py", line 140, in replace_load
    new_value = getattr(DubugTalk(), func_name)(*args_value.split(','))
  File "E:\Project_python\api_cms\debug_talk.py", line 26, in get_extract_data
    return read_extract_file(node_name)
  File "E:\Project_python\api_cms\common\yaml_util.py", line 19, in read_extract_file
    return value[one_node]
TypeError: 'NoneType' object is not subscriptable

[2023-12-05 14:00:06,647] logger_util.py->error_log line:65 [INFO] 分析YAML文件异常：异常信息: Traceback (most recent call last):
  File "E:\Project_python\api_cms\common\requests_util.py", line 309, in send_request
    self.base_url = self.replace_load(self.base_url) + self.replace_load(url)
  File "E:\Project_python\api_cms\common\requests_util.py", line 140, in replace_load
    new_value = getattr(DubugTalk(), func_name)(*args_value.split(','))
  File "E:\Project_python\api_cms\debug_talk.py", line 26, in get_extract_data
    return read_extract_file(node_name)
  File "E:\Project_python\api_cms\common\yaml_util.py", line 19, in read_extract_file
    return value[one_node]
TypeError: 'NoneType' object is not subscriptable

During handling of the above exception, another exception occurred:

Traceback (most recent call last):
  File "E:\Project_python\api_cms\common\requests_util.py", line 185, in analysis_yaml
    res = self.send_request(name =name,method=method,
  File "E:\Project_python\api_cms\common\requests_util.py", line 335, in send_request
    error_log("发送请求异常：异常信息: %s" % str(traceback.format_exc()))
  File "E:\Project_python\api_cms\common\logger_util.py", line 66, in error_log
    raise Exception(log_message)
Exception: 发送请求异常：异常信息: Traceback (most recent call last):
  File "E:\Project_python\api_cms\common\requests_util.py", line 309, in send_request
    self.base_url = self.replace_load(self.base_url) + self.replace_load(url)
  File "E:\Project_python\api_cms\common\requests_util.py", line 140, in replace_load
    new_value = getattr(DubugTalk(), func_name)(*args_value.split(','))
  File "E:\Project_python\api_cms\debug_talk.py", line 26, in get_extract_data
    return read_extract_file(node_name)
  File "E:\Project_python\api_cms\common\yaml_util.py", line 19, in read_extract_file
    return value[one_node]
TypeError: 'NoneType' object is not subscriptable


[2023-12-05 14:00:06,714] logger_util.py->error_log line:65 [INFO] 发送请求异常：异常信息: Traceback (most recent call last):
  File "E:\Project_python\api_cms\common\requests_util.py", line 309, in send_request
    self.base_url = self.replace_load(self.base_url) + self.replace_load(url)
  File "E:\Project_python\api_cms\common\requests_util.py", line 140, in replace_load
    new_value = getattr(DubugTalk(), func_name)(*args_value.split(','))
  File "E:\Project_python\api_cms\debug_talk.py", line 26, in get_extract_data
    return read_extract_file(node_name)
  File "E:\Project_python\api_cms\common\yaml_util.py", line 19, in read_extract_file
    return value[one_node]
TypeError: 'NoneType' object is not subscriptable

[2023-12-05 14:00:06,715] logger_util.py->error_log line:65 [INFO] 分析YAML文件异常：异常信息: Traceback (most recent call last):
  File "E:\Project_python\api_cms\common\requests_util.py", line 309, in send_request
    self.base_url = self.replace_load(self.base_url) + self.replace_load(url)
  File "E:\Project_python\api_cms\common\requests_util.py", line 140, in replace_load
    new_value = getattr(DubugTalk(), func_name)(*args_value.split(','))
  File "E:\Project_python\api_cms\debug_talk.py", line 26, in get_extract_data
    return read_extract_file(node_name)
  File "E:\Project_python\api_cms\common\yaml_util.py", line 19, in read_extract_file
    return value[one_node]
TypeError: 'NoneType' object is not subscriptable

During handling of the above exception, another exception occurred:

Traceback (most recent call last):
  File "E:\Project_python\api_cms\common\requests_util.py", line 185, in analysis_yaml
    res = self.send_request(name =name,method=method,
  File "E:\Project_python\api_cms\common\requests_util.py", line 335, in send_request
    error_log("发送请求异常：异常信息: %s" % str(traceback.format_exc()))
  File "E:\Project_python\api_cms\common\logger_util.py", line 66, in error_log
    raise Exception(log_message)
Exception: 发送请求异常：异常信息: Traceback (most recent call last):
  File "E:\Project_python\api_cms\common\requests_util.py", line 309, in send_request
    self.base_url = self.replace_load(self.base_url) + self.replace_load(url)
  File "E:\Project_python\api_cms\common\requests_util.py", line 140, in replace_load
    new_value = getattr(DubugTalk(), func_name)(*args_value.split(','))
  File "E:\Project_python\api_cms\debug_talk.py", line 26, in get_extract_data
    return read_extract_file(node_name)
  File "E:\Project_python\api_cms\common\yaml_util.py", line 19, in read_extract_file
    return value[one_node]
TypeError: 'NoneType' object is not subscriptable


[2023-12-05 14:00:06,761] logger_util.py->error_log line:65 [INFO] 发送请求异常：异常信息: Traceback (most recent call last):
  File "E:\Project_python\api_cms\common\requests_util.py", line 309, in send_request
    self.base_url = self.replace_load(self.base_url) + self.replace_load(url)
  File "E:\Project_python\api_cms\common\requests_util.py", line 140, in replace_load
    new_value = getattr(DubugTalk(), func_name)(*args_value.split(','))
  File "E:\Project_python\api_cms\debug_talk.py", line 26, in get_extract_data
    return read_extract_file(node_name)
  File "E:\Project_python\api_cms\common\yaml_util.py", line 19, in read_extract_file
    return value[one_node]
TypeError: 'NoneType' object is not subscriptable

[2023-12-05 14:00:06,761] logger_util.py->error_log line:65 [INFO] 分析YAML文件异常：异常信息: Traceback (most recent call last):
  File "E:\Project_python\api_cms\common\requests_util.py", line 309, in send_request
    self.base_url = self.replace_load(self.base_url) + self.replace_load(url)
  File "E:\Project_python\api_cms\common\requests_util.py", line 140, in replace_load
    new_value = getattr(DubugTalk(), func_name)(*args_value.split(','))
  File "E:\Project_python\api_cms\debug_talk.py", line 26, in get_extract_data
    return read_extract_file(node_name)
  File "E:\Project_python\api_cms\common\yaml_util.py", line 19, in read_extract_file
    return value[one_node]
TypeError: 'NoneType' object is not subscriptable

During handling of the above exception, another exception occurred:

Traceback (most recent call last):
  File "E:\Project_python\api_cms\common\requests_util.py", line 185, in analysis_yaml
    res = self.send_request(name =name,method=method,
  File "E:\Project_python\api_cms\common\requests_util.py", line 335, in send_request
    error_log("发送请求异常：异常信息: %s" % str(traceback.format_exc()))
  File "E:\Project_python\api_cms\common\logger_util.py", line 66, in error_log
    raise Exception(log_message)
Exception: 发送请求异常：异常信息: Traceback (most recent call last):
  File "E:\Project_python\api_cms\common\requests_util.py", line 309, in send_request
    self.base_url = self.replace_load(self.base_url) + self.replace_load(url)
  File "E:\Project_python\api_cms\common\requests_util.py", line 140, in replace_load
    new_value = getattr(DubugTalk(), func_name)(*args_value.split(','))
  File "E:\Project_python\api_cms\debug_talk.py", line 26, in get_extract_data
    return read_extract_file(node_name)
  File "E:\Project_python\api_cms\common\yaml_util.py", line 19, in read_extract_file
    return value[one_node]
TypeError: 'NoneType' object is not subscriptable


[2023-12-05 14:00:06,809] logger_util.py->error_log line:65 [INFO] 发送请求异常：异常信息: Traceback (most recent call last):
  File "E:\Project_python\api_cms\common\requests_util.py", line 309, in send_request
    self.base_url = self.replace_load(self.base_url) + self.replace_load(url)
  File "E:\Project_python\api_cms\common\requests_util.py", line 140, in replace_load
    new_value = getattr(DubugTalk(), func_name)(*args_value.split(','))
  File "E:\Project_python\api_cms\debug_talk.py", line 26, in get_extract_data
    return read_extract_file(node_name)
  File "E:\Project_python\api_cms\common\yaml_util.py", line 19, in read_extract_file
    return value[one_node]
TypeError: 'NoneType' object is not subscriptable

[2023-12-05 14:00:06,809] logger_util.py->error_log line:65 [INFO] 分析YAML文件异常：异常信息: Traceback (most recent call last):
  File "E:\Project_python\api_cms\common\requests_util.py", line 309, in send_request
    self.base_url = self.replace_load(self.base_url) + self.replace_load(url)
  File "E:\Project_python\api_cms\common\requests_util.py", line 140, in replace_load
    new_value = getattr(DubugTalk(), func_name)(*args_value.split(','))
  File "E:\Project_python\api_cms\debug_talk.py", line 26, in get_extract_data
    return read_extract_file(node_name)
  File "E:\Project_python\api_cms\common\yaml_util.py", line 19, in read_extract_file
    return value[one_node]
TypeError: 'NoneType' object is not subscriptable

During handling of the above exception, another exception occurred:

Traceback (most recent call last):
  File "E:\Project_python\api_cms\common\requests_util.py", line 185, in analysis_yaml
    res = self.send_request(name =name,method=method,
  File "E:\Project_python\api_cms\common\requests_util.py", line 335, in send_request
    error_log("发送请求异常：异常信息: %s" % str(traceback.format_exc()))
  File "E:\Project_python\api_cms\common\logger_util.py", line 66, in error_log
    raise Exception(log_message)
Exception: 发送请求异常：异常信息: Traceback (most recent call last):
  File "E:\Project_python\api_cms\common\requests_util.py", line 309, in send_request
    self.base_url = self.replace_load(self.base_url) + self.replace_load(url)
  File "E:\Project_python\api_cms\common\requests_util.py", line 140, in replace_load
    new_value = getattr(DubugTalk(), func_name)(*args_value.split(','))
  File "E:\Project_python\api_cms\debug_talk.py", line 26, in get_extract_data
    return read_extract_file(node_name)
  File "E:\Project_python\api_cms\common\yaml_util.py", line 19, in read_extract_file
    return value[one_node]
TypeError: 'NoneType' object is not subscriptable


[2023-12-05 14:00:06,856] logger_util.py->error_log line:65 [INFO] 发送请求异常：异常信息: Traceback (most recent call last):
  File "E:\Project_python\api_cms\common\requests_util.py", line 309, in send_request
    self.base_url = self.replace_load(self.base_url) + self.replace_load(url)
  File "E:\Project_python\api_cms\common\requests_util.py", line 140, in replace_load
    new_value = getattr(DubugTalk(), func_name)(*args_value.split(','))
  File "E:\Project_python\api_cms\debug_talk.py", line 26, in get_extract_data
    return read_extract_file(node_name)
  File "E:\Project_python\api_cms\common\yaml_util.py", line 19, in read_extract_file
    return value[one_node]
TypeError: 'NoneType' object is not subscriptable

[2023-12-05 14:00:06,857] logger_util.py->error_log line:65 [INFO] 分析YAML文件异常：异常信息: Traceback (most recent call last):
  File "E:\Project_python\api_cms\common\requests_util.py", line 309, in send_request
    self.base_url = self.replace_load(self.base_url) + self.replace_load(url)
  File "E:\Project_python\api_cms\common\requests_util.py", line 140, in replace_load
    new_value = getattr(DubugTalk(), func_name)(*args_value.split(','))
  File "E:\Project_python\api_cms\debug_talk.py", line 26, in get_extract_data
    return read_extract_file(node_name)
  File "E:\Project_python\api_cms\common\yaml_util.py", line 19, in read_extract_file
    return value[one_node]
TypeError: 'NoneType' object is not subscriptable

During handling of the above exception, another exception occurred:

Traceback (most recent call last):
  File "E:\Project_python\api_cms\common\requests_util.py", line 185, in analysis_yaml
    res = self.send_request(name =name,method=method,
  File "E:\Project_python\api_cms\common\requests_util.py", line 335, in send_request
    error_log("发送请求异常：异常信息: %s" % str(traceback.format_exc()))
  File "E:\Project_python\api_cms\common\logger_util.py", line 66, in error_log
    raise Exception(log_message)
Exception: 发送请求异常：异常信息: Traceback (most recent call last):
  File "E:\Project_python\api_cms\common\requests_util.py", line 309, in send_request
    self.base_url = self.replace_load(self.base_url) + self.replace_load(url)
  File "E:\Project_python\api_cms\common\requests_util.py", line 140, in replace_load
    new_value = getattr(DubugTalk(), func_name)(*args_value.split(','))
  File "E:\Project_python\api_cms\debug_talk.py", line 26, in get_extract_data
    return read_extract_file(node_name)
  File "E:\Project_python\api_cms\common\yaml_util.py", line 19, in read_extract_file
    return value[one_node]
TypeError: 'NoneType' object is not subscriptable


[2023-12-05 14:00:06,903] logger_util.py->error_log line:65 [INFO] 发送请求异常：异常信息: Traceback (most recent call last):
  File "E:\Project_python\api_cms\common\requests_util.py", line 309, in send_request
    self.base_url = self.replace_load(self.base_url) + self.replace_load(url)
  File "E:\Project_python\api_cms\common\requests_util.py", line 140, in replace_load
    new_value = getattr(DubugTalk(), func_name)(*args_value.split(','))
  File "E:\Project_python\api_cms\debug_talk.py", line 26, in get_extract_data
    return read_extract_file(node_name)
  File "E:\Project_python\api_cms\common\yaml_util.py", line 19, in read_extract_file
    return value[one_node]
TypeError: 'NoneType' object is not subscriptable

[2023-12-05 14:00:06,903] logger_util.py->error_log line:65 [INFO] 分析YAML文件异常：异常信息: Traceback (most recent call last):
  File "E:\Project_python\api_cms\common\requests_util.py", line 309, in send_request
    self.base_url = self.replace_load(self.base_url) + self.replace_load(url)
  File "E:\Project_python\api_cms\common\requests_util.py", line 140, in replace_load
    new_value = getattr(DubugTalk(), func_name)(*args_value.split(','))
  File "E:\Project_python\api_cms\debug_talk.py", line 26, in get_extract_data
    return read_extract_file(node_name)
  File "E:\Project_python\api_cms\common\yaml_util.py", line 19, in read_extract_file
    return value[one_node]
TypeError: 'NoneType' object is not subscriptable

During handling of the above exception, another exception occurred:

Traceback (most recent call last):
  File "E:\Project_python\api_cms\common\requests_util.py", line 185, in analysis_yaml
    res = self.send_request(name =name,method=method,
  File "E:\Project_python\api_cms\common\requests_util.py", line 335, in send_request
    error_log("发送请求异常：异常信息: %s" % str(traceback.format_exc()))
  File "E:\Project_python\api_cms\common\logger_util.py", line 66, in error_log
    raise Exception(log_message)
Exception: 发送请求异常：异常信息: Traceback (most recent call last):
  File "E:\Project_python\api_cms\common\requests_util.py", line 309, in send_request
    self.base_url = self.replace_load(self.base_url) + self.replace_load(url)
  File "E:\Project_python\api_cms\common\requests_util.py", line 140, in replace_load
    new_value = getattr(DubugTalk(), func_name)(*args_value.split(','))
  File "E:\Project_python\api_cms\debug_talk.py", line 26, in get_extract_data
    return read_extract_file(node_name)
  File "E:\Project_python\api_cms\common\yaml_util.py", line 19, in read_extract_file
    return value[one_node]
TypeError: 'NoneType' object is not subscriptable


[2023-12-05 14:00:06,950] logger_util.py->error_log line:65 [INFO] 发送请求异常：异常信息: Traceback (most recent call last):
  File "E:\Project_python\api_cms\common\requests_util.py", line 309, in send_request
    self.base_url = self.replace_load(self.base_url) + self.replace_load(url)
  File "E:\Project_python\api_cms\common\requests_util.py", line 140, in replace_load
    new_value = getattr(DubugTalk(), func_name)(*args_value.split(','))
  File "E:\Project_python\api_cms\debug_talk.py", line 26, in get_extract_data
    return read_extract_file(node_name)
  File "E:\Project_python\api_cms\common\yaml_util.py", line 19, in read_extract_file
    return value[one_node]
TypeError: 'NoneType' object is not subscriptable

[2023-12-05 14:00:06,951] logger_util.py->error_log line:65 [INFO] 分析YAML文件异常：异常信息: Traceback (most recent call last):
  File "E:\Project_python\api_cms\common\requests_util.py", line 309, in send_request
    self.base_url = self.replace_load(self.base_url) + self.replace_load(url)
  File "E:\Project_python\api_cms\common\requests_util.py", line 140, in replace_load
    new_value = getattr(DubugTalk(), func_name)(*args_value.split(','))
  File "E:\Project_python\api_cms\debug_talk.py", line 26, in get_extract_data
    return read_extract_file(node_name)
  File "E:\Project_python\api_cms\common\yaml_util.py", line 19, in read_extract_file
    return value[one_node]
TypeError: 'NoneType' object is not subscriptable

During handling of the above exception, another exception occurred:

Traceback (most recent call last):
  File "E:\Project_python\api_cms\common\requests_util.py", line 185, in analysis_yaml
    res = self.send_request(name =name,method=method,
  File "E:\Project_python\api_cms\common\requests_util.py", line 335, in send_request
    error_log("发送请求异常：异常信息: %s" % str(traceback.format_exc()))
  File "E:\Project_python\api_cms\common\logger_util.py", line 66, in error_log
    raise Exception(log_message)
Exception: 发送请求异常：异常信息: Traceback (most recent call last):
  File "E:\Project_python\api_cms\common\requests_util.py", line 309, in send_request
    self.base_url = self.replace_load(self.base_url) + self.replace_load(url)
  File "E:\Project_python\api_cms\common\requests_util.py", line 140, in replace_load
    new_value = getattr(DubugTalk(), func_name)(*args_value.split(','))
  File "E:\Project_python\api_cms\debug_talk.py", line 26, in get_extract_data
    return read_extract_file(node_name)
  File "E:\Project_python\api_cms\common\yaml_util.py", line 19, in read_extract_file
    return value[one_node]
TypeError: 'NoneType' object is not subscriptable


[2023-12-05 14:00:06,997] logger_util.py->error_log line:65 [INFO] 发送请求异常：异常信息: Traceback (most recent call last):
  File "E:\Project_python\api_cms\common\requests_util.py", line 309, in send_request
    self.base_url = self.replace_load(self.base_url) + self.replace_load(url)
  File "E:\Project_python\api_cms\common\requests_util.py", line 140, in replace_load
    new_value = getattr(DubugTalk(), func_name)(*args_value.split(','))
  File "E:\Project_python\api_cms\debug_talk.py", line 26, in get_extract_data
    return read_extract_file(node_name)
  File "E:\Project_python\api_cms\common\yaml_util.py", line 19, in read_extract_file
    return value[one_node]
TypeError: 'NoneType' object is not subscriptable

[2023-12-05 14:00:06,997] logger_util.py->error_log line:65 [INFO] 分析YAML文件异常：异常信息: Traceback (most recent call last):
  File "E:\Project_python\api_cms\common\requests_util.py", line 309, in send_request
    self.base_url = self.replace_load(self.base_url) + self.replace_load(url)
  File "E:\Project_python\api_cms\common\requests_util.py", line 140, in replace_load
    new_value = getattr(DubugTalk(), func_name)(*args_value.split(','))
  File "E:\Project_python\api_cms\debug_talk.py", line 26, in get_extract_data
    return read_extract_file(node_name)
  File "E:\Project_python\api_cms\common\yaml_util.py", line 19, in read_extract_file
    return value[one_node]
TypeError: 'NoneType' object is not subscriptable

During handling of the above exception, another exception occurred:

Traceback (most recent call last):
  File "E:\Project_python\api_cms\common\requests_util.py", line 185, in analysis_yaml
    res = self.send_request(name =name,method=method,
  File "E:\Project_python\api_cms\common\requests_util.py", line 335, in send_request
    error_log("发送请求异常：异常信息: %s" % str(traceback.format_exc()))
  File "E:\Project_python\api_cms\common\logger_util.py", line 66, in error_log
    raise Exception(log_message)
Exception: 发送请求异常：异常信息: Traceback (most recent call last):
  File "E:\Project_python\api_cms\common\requests_util.py", line 309, in send_request
    self.base_url = self.replace_load(self.base_url) + self.replace_load(url)
  File "E:\Project_python\api_cms\common\requests_util.py", line 140, in replace_load
    new_value = getattr(DubugTalk(), func_name)(*args_value.split(','))
  File "E:\Project_python\api_cms\debug_talk.py", line 26, in get_extract_data
    return read_extract_file(node_name)
  File "E:\Project_python\api_cms\common\yaml_util.py", line 19, in read_extract_file
    return value[one_node]
TypeError: 'NoneType' object is not subscriptable


[2023-12-05 14:00:07,042] logger_util.py->error_log line:65 [INFO] 发送请求异常：异常信息: Traceback (most recent call last):
  File "E:\Project_python\api_cms\common\requests_util.py", line 309, in send_request
    self.base_url = self.replace_load(self.base_url) + self.replace_load(url)
  File "E:\Project_python\api_cms\common\requests_util.py", line 140, in replace_load
    new_value = getattr(DubugTalk(), func_name)(*args_value.split(','))
  File "E:\Project_python\api_cms\debug_talk.py", line 26, in get_extract_data
    return read_extract_file(node_name)
  File "E:\Project_python\api_cms\common\yaml_util.py", line 19, in read_extract_file
    return value[one_node]
TypeError: 'NoneType' object is not subscriptable

[2023-12-05 14:00:07,042] logger_util.py->error_log line:65 [INFO] 分析YAML文件异常：异常信息: Traceback (most recent call last):
  File "E:\Project_python\api_cms\common\requests_util.py", line 309, in send_request
    self.base_url = self.replace_load(self.base_url) + self.replace_load(url)
  File "E:\Project_python\api_cms\common\requests_util.py", line 140, in replace_load
    new_value = getattr(DubugTalk(), func_name)(*args_value.split(','))
  File "E:\Project_python\api_cms\debug_talk.py", line 26, in get_extract_data
    return read_extract_file(node_name)
  File "E:\Project_python\api_cms\common\yaml_util.py", line 19, in read_extract_file
    return value[one_node]
TypeError: 'NoneType' object is not subscriptable

During handling of the above exception, another exception occurred:

Traceback (most recent call last):
  File "E:\Project_python\api_cms\common\requests_util.py", line 185, in analysis_yaml
    res = self.send_request(name =name,method=method,
  File "E:\Project_python\api_cms\common\requests_util.py", line 335, in send_request
    error_log("发送请求异常：异常信息: %s" % str(traceback.format_exc()))
  File "E:\Project_python\api_cms\common\logger_util.py", line 66, in error_log
    raise Exception(log_message)
Exception: 发送请求异常：异常信息: Traceback (most recent call last):
  File "E:\Project_python\api_cms\common\requests_util.py", line 309, in send_request
    self.base_url = self.replace_load(self.base_url) + self.replace_load(url)
  File "E:\Project_python\api_cms\common\requests_util.py", line 140, in replace_load
    new_value = getattr(DubugTalk(), func_name)(*args_value.split(','))
  File "E:\Project_python\api_cms\debug_talk.py", line 26, in get_extract_data
    return read_extract_file(node_name)
  File "E:\Project_python\api_cms\common\yaml_util.py", line 19, in read_extract_file
    return value[one_node]
TypeError: 'NoneType' object is not subscriptable


[2023-12-05 14:00:07,109] logger_util.py->error_log line:65 [INFO] 发送请求异常：异常信息: Traceback (most recent call last):
  File "E:\Project_python\api_cms\common\requests_util.py", line 309, in send_request
    self.base_url = self.replace_load(self.base_url) + self.replace_load(url)
  File "E:\Project_python\api_cms\common\requests_util.py", line 140, in replace_load
    new_value = getattr(DubugTalk(), func_name)(*args_value.split(','))
  File "E:\Project_python\api_cms\debug_talk.py", line 26, in get_extract_data
    return read_extract_file(node_name)
  File "E:\Project_python\api_cms\common\yaml_util.py", line 19, in read_extract_file
    return value[one_node]
TypeError: 'NoneType' object is not subscriptable

[2023-12-05 14:00:07,109] logger_util.py->error_log line:65 [INFO] 分析YAML文件异常：异常信息: Traceback (most recent call last):
  File "E:\Project_python\api_cms\common\requests_util.py", line 309, in send_request
    self.base_url = self.replace_load(self.base_url) + self.replace_load(url)
  File "E:\Project_python\api_cms\common\requests_util.py", line 140, in replace_load
    new_value = getattr(DubugTalk(), func_name)(*args_value.split(','))
  File "E:\Project_python\api_cms\debug_talk.py", line 26, in get_extract_data
    return read_extract_file(node_name)
  File "E:\Project_python\api_cms\common\yaml_util.py", line 19, in read_extract_file
    return value[one_node]
TypeError: 'NoneType' object is not subscriptable

During handling of the above exception, another exception occurred:

Traceback (most recent call last):
  File "E:\Project_python\api_cms\common\requests_util.py", line 185, in analysis_yaml
    res = self.send_request(name =name,method=method,
  File "E:\Project_python\api_cms\common\requests_util.py", line 335, in send_request
    error_log("发送请求异常：异常信息: %s" % str(traceback.format_exc()))
  File "E:\Project_python\api_cms\common\logger_util.py", line 66, in error_log
    raise Exception(log_message)
Exception: 发送请求异常：异常信息: Traceback (most recent call last):
  File "E:\Project_python\api_cms\common\requests_util.py", line 309, in send_request
    self.base_url = self.replace_load(self.base_url) + self.replace_load(url)
  File "E:\Project_python\api_cms\common\requests_util.py", line 140, in replace_load
    new_value = getattr(DubugTalk(), func_name)(*args_value.split(','))
  File "E:\Project_python\api_cms\debug_talk.py", line 26, in get_extract_data
    return read_extract_file(node_name)
  File "E:\Project_python\api_cms\common\yaml_util.py", line 19, in read_extract_file
    return value[one_node]
TypeError: 'NoneType' object is not subscriptable


[2023-12-05 14:00:07,155] logger_util.py->error_log line:65 [INFO] 发送请求异常：异常信息: Traceback (most recent call last):
  File "E:\Project_python\api_cms\common\requests_util.py", line 309, in send_request
    self.base_url = self.replace_load(self.base_url) + self.replace_load(url)
  File "E:\Project_python\api_cms\common\requests_util.py", line 140, in replace_load
    new_value = getattr(DubugTalk(), func_name)(*args_value.split(','))
  File "E:\Project_python\api_cms\debug_talk.py", line 26, in get_extract_data
    return read_extract_file(node_name)
  File "E:\Project_python\api_cms\common\yaml_util.py", line 19, in read_extract_file
    return value[one_node]
TypeError: 'NoneType' object is not subscriptable

[2023-12-05 14:00:07,155] logger_util.py->error_log line:65 [INFO] 分析YAML文件异常：异常信息: Traceback (most recent call last):
  File "E:\Project_python\api_cms\common\requests_util.py", line 309, in send_request
    self.base_url = self.replace_load(self.base_url) + self.replace_load(url)
  File "E:\Project_python\api_cms\common\requests_util.py", line 140, in replace_load
    new_value = getattr(DubugTalk(), func_name)(*args_value.split(','))
  File "E:\Project_python\api_cms\debug_talk.py", line 26, in get_extract_data
    return read_extract_file(node_name)
  File "E:\Project_python\api_cms\common\yaml_util.py", line 19, in read_extract_file
    return value[one_node]
TypeError: 'NoneType' object is not subscriptable

During handling of the above exception, another exception occurred:

Traceback (most recent call last):
  File "E:\Project_python\api_cms\common\requests_util.py", line 185, in analysis_yaml
    res = self.send_request(name =name,method=method,
  File "E:\Project_python\api_cms\common\requests_util.py", line 335, in send_request
    error_log("发送请求异常：异常信息: %s" % str(traceback.format_exc()))
  File "E:\Project_python\api_cms\common\logger_util.py", line 66, in error_log
    raise Exception(log_message)
Exception: 发送请求异常：异常信息: Traceback (most recent call last):
  File "E:\Project_python\api_cms\common\requests_util.py", line 309, in send_request
    self.base_url = self.replace_load(self.base_url) + self.replace_load(url)
  File "E:\Project_python\api_cms\common\requests_util.py", line 140, in replace_load
    new_value = getattr(DubugTalk(), func_name)(*args_value.split(','))
  File "E:\Project_python\api_cms\debug_talk.py", line 26, in get_extract_data
    return read_extract_file(node_name)
  File "E:\Project_python\api_cms\common\yaml_util.py", line 19, in read_extract_file
    return value[one_node]
TypeError: 'NoneType' object is not subscriptable


[2023-12-05 14:00:07,200] logger_util.py->error_log line:65 [INFO] 发送请求异常：异常信息: Traceback (most recent call last):
  File "E:\Project_python\api_cms\common\requests_util.py", line 312, in send_request
    self.last_headers = self.replace_load(headers)
  File "E:\Project_python\api_cms\common\requests_util.py", line 140, in replace_load
    new_value = getattr(DubugTalk(), func_name)(*args_value.split(','))
  File "E:\Project_python\api_cms\debug_talk.py", line 26, in get_extract_data
    return read_extract_file(node_name)
  File "E:\Project_python\api_cms\common\yaml_util.py", line 19, in read_extract_file
    return value[one_node]
TypeError: 'NoneType' object is not subscriptable

[2023-12-05 14:00:07,200] logger_util.py->error_log line:65 [INFO] 分析YAML文件异常：异常信息: Traceback (most recent call last):
  File "E:\Project_python\api_cms\common\requests_util.py", line 312, in send_request
    self.last_headers = self.replace_load(headers)
  File "E:\Project_python\api_cms\common\requests_util.py", line 140, in replace_load
    new_value = getattr(DubugTalk(), func_name)(*args_value.split(','))
  File "E:\Project_python\api_cms\debug_talk.py", line 26, in get_extract_data
    return read_extract_file(node_name)
  File "E:\Project_python\api_cms\common\yaml_util.py", line 19, in read_extract_file
    return value[one_node]
TypeError: 'NoneType' object is not subscriptable

During handling of the above exception, another exception occurred:

Traceback (most recent call last):
  File "E:\Project_python\api_cms\common\requests_util.py", line 185, in analysis_yaml
    res = self.send_request(name =name,method=method,
  File "E:\Project_python\api_cms\common\requests_util.py", line 335, in send_request
    error_log("发送请求异常：异常信息: %s" % str(traceback.format_exc()))
  File "E:\Project_python\api_cms\common\logger_util.py", line 66, in error_log
    raise Exception(log_message)
Exception: 发送请求异常：异常信息: Traceback (most recent call last):
  File "E:\Project_python\api_cms\common\requests_util.py", line 312, in send_request
    self.last_headers = self.replace_load(headers)
  File "E:\Project_python\api_cms\common\requests_util.py", line 140, in replace_load
    new_value = getattr(DubugTalk(), func_name)(*args_value.split(','))
  File "E:\Project_python\api_cms\debug_talk.py", line 26, in get_extract_data
    return read_extract_file(node_name)
  File "E:\Project_python\api_cms\common\yaml_util.py", line 19, in read_extract_file
    return value[one_node]
TypeError: 'NoneType' object is not subscriptable


[2023-12-05 14:00:07,247] logger_util.py->error_log line:65 [INFO] 发送请求异常：异常信息: Traceback (most recent call last):
  File "E:\Project_python\api_cms\common\requests_util.py", line 309, in send_request
    self.base_url = self.replace_load(self.base_url) + self.replace_load(url)
  File "E:\Project_python\api_cms\common\requests_util.py", line 140, in replace_load
    new_value = getattr(DubugTalk(), func_name)(*args_value.split(','))
  File "E:\Project_python\api_cms\debug_talk.py", line 26, in get_extract_data
    return read_extract_file(node_name)
  File "E:\Project_python\api_cms\common\yaml_util.py", line 19, in read_extract_file
    return value[one_node]
TypeError: 'NoneType' object is not subscriptable

[2023-12-05 14:00:07,247] logger_util.py->error_log line:65 [INFO] 分析YAML文件异常：异常信息: Traceback (most recent call last):
  File "E:\Project_python\api_cms\common\requests_util.py", line 309, in send_request
    self.base_url = self.replace_load(self.base_url) + self.replace_load(url)
  File "E:\Project_python\api_cms\common\requests_util.py", line 140, in replace_load
    new_value = getattr(DubugTalk(), func_name)(*args_value.split(','))
  File "E:\Project_python\api_cms\debug_talk.py", line 26, in get_extract_data
    return read_extract_file(node_name)
  File "E:\Project_python\api_cms\common\yaml_util.py", line 19, in read_extract_file
    return value[one_node]
TypeError: 'NoneType' object is not subscriptable

During handling of the above exception, another exception occurred:

Traceback (most recent call last):
  File "E:\Project_python\api_cms\common\requests_util.py", line 185, in analysis_yaml
    res = self.send_request(name =name,method=method,
  File "E:\Project_python\api_cms\common\requests_util.py", line 335, in send_request
    error_log("发送请求异常：异常信息: %s" % str(traceback.format_exc()))
  File "E:\Project_python\api_cms\common\logger_util.py", line 66, in error_log
    raise Exception(log_message)
Exception: 发送请求异常：异常信息: Traceback (most recent call last):
  File "E:\Project_python\api_cms\common\requests_util.py", line 309, in send_request
    self.base_url = self.replace_load(self.base_url) + self.replace_load(url)
  File "E:\Project_python\api_cms\common\requests_util.py", line 140, in replace_load
    new_value = getattr(DubugTalk(), func_name)(*args_value.split(','))
  File "E:\Project_python\api_cms\debug_talk.py", line 26, in get_extract_data
    return read_extract_file(node_name)
  File "E:\Project_python\api_cms\common\yaml_util.py", line 19, in read_extract_file
    return value[one_node]
TypeError: 'NoneType' object is not subscriptable


[2023-12-05 14:00:07,293] logger_util.py->error_log line:65 [INFO] 发送请求异常：异常信息: Traceback (most recent call last):
  File "E:\Project_python\api_cms\common\requests_util.py", line 309, in send_request
    self.base_url = self.replace_load(self.base_url) + self.replace_load(url)
  File "E:\Project_python\api_cms\common\requests_util.py", line 140, in replace_load
    new_value = getattr(DubugTalk(), func_name)(*args_value.split(','))
  File "E:\Project_python\api_cms\debug_talk.py", line 26, in get_extract_data
    return read_extract_file(node_name)
  File "E:\Project_python\api_cms\common\yaml_util.py", line 19, in read_extract_file
    return value[one_node]
TypeError: 'NoneType' object is not subscriptable

[2023-12-05 14:00:07,294] logger_util.py->error_log line:65 [INFO] 分析YAML文件异常：异常信息: Traceback (most recent call last):
  File "E:\Project_python\api_cms\common\requests_util.py", line 309, in send_request
    self.base_url = self.replace_load(self.base_url) + self.replace_load(url)
  File "E:\Project_python\api_cms\common\requests_util.py", line 140, in replace_load
    new_value = getattr(DubugTalk(), func_name)(*args_value.split(','))
  File "E:\Project_python\api_cms\debug_talk.py", line 26, in get_extract_data
    return read_extract_file(node_name)
  File "E:\Project_python\api_cms\common\yaml_util.py", line 19, in read_extract_file
    return value[one_node]
TypeError: 'NoneType' object is not subscriptable

During handling of the above exception, another exception occurred:

Traceback (most recent call last):
  File "E:\Project_python\api_cms\common\requests_util.py", line 185, in analysis_yaml
    res = self.send_request(name =name,method=method,
  File "E:\Project_python\api_cms\common\requests_util.py", line 335, in send_request
    error_log("发送请求异常：异常信息: %s" % str(traceback.format_exc()))
  File "E:\Project_python\api_cms\common\logger_util.py", line 66, in error_log
    raise Exception(log_message)
Exception: 发送请求异常：异常信息: Traceback (most recent call last):
  File "E:\Project_python\api_cms\common\requests_util.py", line 309, in send_request
    self.base_url = self.replace_load(self.base_url) + self.replace_load(url)
  File "E:\Project_python\api_cms\common\requests_util.py", line 140, in replace_load
    new_value = getattr(DubugTalk(), func_name)(*args_value.split(','))
  File "E:\Project_python\api_cms\debug_talk.py", line 26, in get_extract_data
    return read_extract_file(node_name)
  File "E:\Project_python\api_cms\common\yaml_util.py", line 19, in read_extract_file
    return value[one_node]
TypeError: 'NoneType' object is not subscriptable


[2023-12-05 14:00:07,340] logger_util.py->error_log line:65 [INFO] 发送请求异常：异常信息: Traceback (most recent call last):
  File "E:\Project_python\api_cms\common\requests_util.py", line 309, in send_request
    self.base_url = self.replace_load(self.base_url) + self.replace_load(url)
  File "E:\Project_python\api_cms\common\requests_util.py", line 140, in replace_load
    new_value = getattr(DubugTalk(), func_name)(*args_value.split(','))
  File "E:\Project_python\api_cms\debug_talk.py", line 26, in get_extract_data
    return read_extract_file(node_name)
  File "E:\Project_python\api_cms\common\yaml_util.py", line 19, in read_extract_file
    return value[one_node]
TypeError: 'NoneType' object is not subscriptable

[2023-12-05 14:00:07,341] logger_util.py->error_log line:65 [INFO] 分析YAML文件异常：异常信息: Traceback (most recent call last):
  File "E:\Project_python\api_cms\common\requests_util.py", line 309, in send_request
    self.base_url = self.replace_load(self.base_url) + self.replace_load(url)
  File "E:\Project_python\api_cms\common\requests_util.py", line 140, in replace_load
    new_value = getattr(DubugTalk(), func_name)(*args_value.split(','))
  File "E:\Project_python\api_cms\debug_talk.py", line 26, in get_extract_data
    return read_extract_file(node_name)
  File "E:\Project_python\api_cms\common\yaml_util.py", line 19, in read_extract_file
    return value[one_node]
TypeError: 'NoneType' object is not subscriptable

During handling of the above exception, another exception occurred:

Traceback (most recent call last):
  File "E:\Project_python\api_cms\common\requests_util.py", line 185, in analysis_yaml
    res = self.send_request(name =name,method=method,
  File "E:\Project_python\api_cms\common\requests_util.py", line 335, in send_request
    error_log("发送请求异常：异常信息: %s" % str(traceback.format_exc()))
  File "E:\Project_python\api_cms\common\logger_util.py", line 66, in error_log
    raise Exception(log_message)
Exception: 发送请求异常：异常信息: Traceback (most recent call last):
  File "E:\Project_python\api_cms\common\requests_util.py", line 309, in send_request
    self.base_url = self.replace_load(self.base_url) + self.replace_load(url)
  File "E:\Project_python\api_cms\common\requests_util.py", line 140, in replace_load
    new_value = getattr(DubugTalk(), func_name)(*args_value.split(','))
  File "E:\Project_python\api_cms\debug_talk.py", line 26, in get_extract_data
    return read_extract_file(node_name)
  File "E:\Project_python\api_cms\common\yaml_util.py", line 19, in read_extract_file
    return value[one_node]
TypeError: 'NoneType' object is not subscriptable


[2023-12-05 14:00:07,399] logger_util.py->error_log line:65 [INFO] 发送请求异常：异常信息: Traceback (most recent call last):
  File "E:\Project_python\api_cms\common\requests_util.py", line 309, in send_request
    self.base_url = self.replace_load(self.base_url) + self.replace_load(url)
  File "E:\Project_python\api_cms\common\requests_util.py", line 140, in replace_load
    new_value = getattr(DubugTalk(), func_name)(*args_value.split(','))
  File "E:\Project_python\api_cms\debug_talk.py", line 26, in get_extract_data
    return read_extract_file(node_name)
  File "E:\Project_python\api_cms\common\yaml_util.py", line 19, in read_extract_file
    return value[one_node]
TypeError: 'NoneType' object is not subscriptable

[2023-12-05 14:00:07,399] logger_util.py->error_log line:65 [INFO] 分析YAML文件异常：异常信息: Traceback (most recent call last):
  File "E:\Project_python\api_cms\common\requests_util.py", line 309, in send_request
    self.base_url = self.replace_load(self.base_url) + self.replace_load(url)
  File "E:\Project_python\api_cms\common\requests_util.py", line 140, in replace_load
    new_value = getattr(DubugTalk(), func_name)(*args_value.split(','))
  File "E:\Project_python\api_cms\debug_talk.py", line 26, in get_extract_data
    return read_extract_file(node_name)
  File "E:\Project_python\api_cms\common\yaml_util.py", line 19, in read_extract_file
    return value[one_node]
TypeError: 'NoneType' object is not subscriptable

During handling of the above exception, another exception occurred:

Traceback (most recent call last):
  File "E:\Project_python\api_cms\common\requests_util.py", line 185, in analysis_yaml
    res = self.send_request(name =name,method=method,
  File "E:\Project_python\api_cms\common\requests_util.py", line 335, in send_request
    error_log("发送请求异常：异常信息: %s" % str(traceback.format_exc()))
  File "E:\Project_python\api_cms\common\logger_util.py", line 66, in error_log
    raise Exception(log_message)
Exception: 发送请求异常：异常信息: Traceback (most recent call last):
  File "E:\Project_python\api_cms\common\requests_util.py", line 309, in send_request
    self.base_url = self.replace_load(self.base_url) + self.replace_load(url)
  File "E:\Project_python\api_cms\common\requests_util.py", line 140, in replace_load
    new_value = getattr(DubugTalk(), func_name)(*args_value.split(','))
  File "E:\Project_python\api_cms\debug_talk.py", line 26, in get_extract_data
    return read_extract_file(node_name)
  File "E:\Project_python\api_cms\common\yaml_util.py", line 19, in read_extract_file
    return value[one_node]
TypeError: 'NoneType' object is not subscriptable


[2023-12-05 14:00:07,452] logger_util.py->error_log line:65 [INFO] 发送请求异常：异常信息: Traceback (most recent call last):
  File "E:\Project_python\api_cms\common\requests_util.py", line 309, in send_request
    self.base_url = self.replace_load(self.base_url) + self.replace_load(url)
  File "E:\Project_python\api_cms\common\requests_util.py", line 140, in replace_load
    new_value = getattr(DubugTalk(), func_name)(*args_value.split(','))
  File "E:\Project_python\api_cms\debug_talk.py", line 26, in get_extract_data
    return read_extract_file(node_name)
  File "E:\Project_python\api_cms\common\yaml_util.py", line 19, in read_extract_file
    return value[one_node]
TypeError: 'NoneType' object is not subscriptable

[2023-12-05 14:00:07,453] logger_util.py->error_log line:65 [INFO] 分析YAML文件异常：异常信息: Traceback (most recent call last):
  File "E:\Project_python\api_cms\common\requests_util.py", line 309, in send_request
    self.base_url = self.replace_load(self.base_url) + self.replace_load(url)
  File "E:\Project_python\api_cms\common\requests_util.py", line 140, in replace_load
    new_value = getattr(DubugTalk(), func_name)(*args_value.split(','))
  File "E:\Project_python\api_cms\debug_talk.py", line 26, in get_extract_data
    return read_extract_file(node_name)
  File "E:\Project_python\api_cms\common\yaml_util.py", line 19, in read_extract_file
    return value[one_node]
TypeError: 'NoneType' object is not subscriptable

During handling of the above exception, another exception occurred:

Traceback (most recent call last):
  File "E:\Project_python\api_cms\common\requests_util.py", line 185, in analysis_yaml
    res = self.send_request(name =name,method=method,
  File "E:\Project_python\api_cms\common\requests_util.py", line 335, in send_request
    error_log("发送请求异常：异常信息: %s" % str(traceback.format_exc()))
  File "E:\Project_python\api_cms\common\logger_util.py", line 66, in error_log
    raise Exception(log_message)
Exception: 发送请求异常：异常信息: Traceback (most recent call last):
  File "E:\Project_python\api_cms\common\requests_util.py", line 309, in send_request
    self.base_url = self.replace_load(self.base_url) + self.replace_load(url)
  File "E:\Project_python\api_cms\common\requests_util.py", line 140, in replace_load
    new_value = getattr(DubugTalk(), func_name)(*args_value.split(','))
  File "E:\Project_python\api_cms\debug_talk.py", line 26, in get_extract_data
    return read_extract_file(node_name)
  File "E:\Project_python\api_cms\common\yaml_util.py", line 19, in read_extract_file
    return value[one_node]
TypeError: 'NoneType' object is not subscriptable


[2023-12-05 14:00:07,524] logger_util.py->error_log line:65 [INFO] 发送请求异常：异常信息: Traceback (most recent call last):
  File "E:\Project_python\api_cms\common\requests_util.py", line 309, in send_request
    self.base_url = self.replace_load(self.base_url) + self.replace_load(url)
  File "E:\Project_python\api_cms\common\requests_util.py", line 140, in replace_load
    new_value = getattr(DubugTalk(), func_name)(*args_value.split(','))
  File "E:\Project_python\api_cms\debug_talk.py", line 26, in get_extract_data
    return read_extract_file(node_name)
  File "E:\Project_python\api_cms\common\yaml_util.py", line 19, in read_extract_file
    return value[one_node]
TypeError: 'NoneType' object is not subscriptable

[2023-12-05 14:00:07,525] logger_util.py->error_log line:65 [INFO] 分析YAML文件异常：异常信息: Traceback (most recent call last):
  File "E:\Project_python\api_cms\common\requests_util.py", line 309, in send_request
    self.base_url = self.replace_load(self.base_url) + self.replace_load(url)
  File "E:\Project_python\api_cms\common\requests_util.py", line 140, in replace_load
    new_value = getattr(DubugTalk(), func_name)(*args_value.split(','))
  File "E:\Project_python\api_cms\debug_talk.py", line 26, in get_extract_data
    return read_extract_file(node_name)
  File "E:\Project_python\api_cms\common\yaml_util.py", line 19, in read_extract_file
    return value[one_node]
TypeError: 'NoneType' object is not subscriptable

During handling of the above exception, another exception occurred:

Traceback (most recent call last):
  File "E:\Project_python\api_cms\common\requests_util.py", line 185, in analysis_yaml
    res = self.send_request(name =name,method=method,
  File "E:\Project_python\api_cms\common\requests_util.py", line 335, in send_request
    error_log("发送请求异常：异常信息: %s" % str(traceback.format_exc()))
  File "E:\Project_python\api_cms\common\logger_util.py", line 66, in error_log
    raise Exception(log_message)
Exception: 发送请求异常：异常信息: Traceback (most recent call last):
  File "E:\Project_python\api_cms\common\requests_util.py", line 309, in send_request
    self.base_url = self.replace_load(self.base_url) + self.replace_load(url)
  File "E:\Project_python\api_cms\common\requests_util.py", line 140, in replace_load
    new_value = getattr(DubugTalk(), func_name)(*args_value.split(','))
  File "E:\Project_python\api_cms\debug_talk.py", line 26, in get_extract_data
    return read_extract_file(node_name)
  File "E:\Project_python\api_cms\common\yaml_util.py", line 19, in read_extract_file
    return value[one_node]
TypeError: 'NoneType' object is not subscriptable


[2023-12-05 14:00:07,574] logger_util.py->error_log line:65 [INFO] 发送请求异常：异常信息: Traceback (most recent call last):
  File "E:\Project_python\api_cms\common\requests_util.py", line 309, in send_request
    self.base_url = self.replace_load(self.base_url) + self.replace_load(url)
  File "E:\Project_python\api_cms\common\requests_util.py", line 140, in replace_load
    new_value = getattr(DubugTalk(), func_name)(*args_value.split(','))
  File "E:\Project_python\api_cms\debug_talk.py", line 26, in get_extract_data
    return read_extract_file(node_name)
  File "E:\Project_python\api_cms\common\yaml_util.py", line 19, in read_extract_file
    return value[one_node]
TypeError: 'NoneType' object is not subscriptable

[2023-12-05 14:00:07,574] logger_util.py->error_log line:65 [INFO] 分析YAML文件异常：异常信息: Traceback (most recent call last):
  File "E:\Project_python\api_cms\common\requests_util.py", line 309, in send_request
    self.base_url = self.replace_load(self.base_url) + self.replace_load(url)
  File "E:\Project_python\api_cms\common\requests_util.py", line 140, in replace_load
    new_value = getattr(DubugTalk(), func_name)(*args_value.split(','))
  File "E:\Project_python\api_cms\debug_talk.py", line 26, in get_extract_data
    return read_extract_file(node_name)
  File "E:\Project_python\api_cms\common\yaml_util.py", line 19, in read_extract_file
    return value[one_node]
TypeError: 'NoneType' object is not subscriptable

During handling of the above exception, another exception occurred:

Traceback (most recent call last):
  File "E:\Project_python\api_cms\common\requests_util.py", line 185, in analysis_yaml
    res = self.send_request(name =name,method=method,
  File "E:\Project_python\api_cms\common\requests_util.py", line 335, in send_request
    error_log("发送请求异常：异常信息: %s" % str(traceback.format_exc()))
  File "E:\Project_python\api_cms\common\logger_util.py", line 66, in error_log
    raise Exception(log_message)
Exception: 发送请求异常：异常信息: Traceback (most recent call last):
  File "E:\Project_python\api_cms\common\requests_util.py", line 309, in send_request
    self.base_url = self.replace_load(self.base_url) + self.replace_load(url)
  File "E:\Project_python\api_cms\common\requests_util.py", line 140, in replace_load
    new_value = getattr(DubugTalk(), func_name)(*args_value.split(','))
  File "E:\Project_python\api_cms\debug_talk.py", line 26, in get_extract_data
    return read_extract_file(node_name)
  File "E:\Project_python\api_cms\common\yaml_util.py", line 19, in read_extract_file
    return value[one_node]
TypeError: 'NoneType' object is not subscriptable


