[2023-12-18 11:39:30,011] logger_util.py->write_log line:61 [INFO] 
-------------接口请求开始-----------
[2023-12-18 11:39:30,011] logger_util.py->write_log line:61 [INFO] 接口名称：测试连接互联项
[2023-12-18 11:39:30,011] logger_util.py->write_log line:61 [INFO] 接口方式：post
[2023-12-18 11:39:30,011] logger_util.py->write_log line:61 [INFO] 接口路径：http://127.0.0.1:18000/api/v1/connection/test
[2023-12-18 11:39:30,011] logger_util.py->write_log line:61 [INFO] 请求头：{'X-Project': 'fb63700a195245b9bb42ef9e036ce674'}
[2023-12-18 11:39:30,011] logger_util.py->write_log line:61 [INFO] 请求参数：{'id': None, 'name': 'mysql4796', 'connectionType': 1, 'databaseType': 1, 'authenticationType': None, 'server': '192.168.2.98', 'port': '3306', 'database': 'TestDB', 'databasePath': '', 'userName': 'root', 'password': 'syc123', 'changedPassword': True, 'mqttType': None, 'pushType': None, 'timingPeriod': None, 'changingPeriod': None, 'cloudDeviceId': '', 'originalSecret': ''}
[2023-12-18 11:39:30,012] logger_util.py->write_log line:61 [INFO] 文件上传：None
[2023-12-18 11:39:30,015] logger_util.py->error_log line:65 [INFO] 断言失败:status_code不等于200
[2023-12-18 11:39:30,016] logger_util.py->write_log line:61 [INFO] 实际结果：{'code': 409, 'msg': 'Projcet Conflict'}
[2023-12-18 11:39:30,016] logger_util.py->write_log line:61 [INFO] 接口请求失败！
[2023-12-18 11:39:30,016] logger_util.py->write_log line:61 [INFO] -------------接口请求结束-----------

[2023-12-18 11:39:30,017] logger_util.py->error_log line:65 [INFO] 断言异常：异常信息: Traceback (most recent call last):
  File "E:\Project_python\api_cms\common\requests_util.py", line 368, in validate_result
    error_log("断言失败:"+assert_key+"不等于"+str(assert_value))
  File "E:\Project_python\api_cms\common\logger_util.py", line 66, in error_log
    raise Exception(log_message)
Exception: 断言失败:status_code不等于200

[2023-12-18 11:39:30,017] logger_util.py->error_log line:65 [INFO] 分析YAML文件异常：异常信息: Traceback (most recent call last):
  File "E:\Project_python\api_cms\common\requests_util.py", line 368, in validate_result
    error_log("断言失败:"+assert_key+"不等于"+str(assert_value))
  File "E:\Project_python\api_cms\common\logger_util.py", line 66, in error_log
    raise Exception(log_message)
Exception: 断言失败:status_code不等于200

During handling of the above exception, another exception occurred:

Traceback (most recent call last):
  File "E:\Project_python\api_cms\common\requests_util.py", line 248, in analysis_yaml
    self.validate_result(yq_result, return_data, status_code)
  File "E:\Project_python\api_cms\common\requests_util.py", line 448, in validate_result
    error_log("断言异常：异常信息: %s" % str(traceback.format_exc()))
  File "E:\Project_python\api_cms\common\logger_util.py", line 66, in error_log
    raise Exception(log_message)
Exception: 断言异常：异常信息: Traceback (most recent call last):
  File "E:\Project_python\api_cms\common\requests_util.py", line 368, in validate_result
    error_log("断言失败:"+assert_key+"不等于"+str(assert_value))
  File "E:\Project_python\api_cms\common\logger_util.py", line 66, in error_log
    raise Exception(log_message)
Exception: 断言失败:status_code不等于200


[2023-12-18 11:39:30,134] logger_util.py->write_log line:61 [INFO] 
-------------接口请求开始-----------
[2023-12-18 11:39:30,135] logger_util.py->write_log line:61 [INFO] 接口名称：创建互联项
[2023-12-18 11:39:30,135] logger_util.py->write_log line:61 [INFO] 接口方式：post
[2023-12-18 11:39:30,135] logger_util.py->write_log line:61 [INFO] 接口路径：http://127.0.0.1:18000/api/v1/connection
[2023-12-18 11:39:30,135] logger_util.py->write_log line:61 [INFO] 请求头：{'X-Project': 'fb63700a195245b9bb42ef9e036ce674'}
[2023-12-18 11:39:30,135] logger_util.py->write_log line:61 [INFO] 请求参数：{'id': None, 'name': 'mysql2185', 'connectionType': 1, 'databaseType': 1, 'authenticationType': None, 'server': '192.168.2.98', 'port': '3306', 'database': 'TestDB', 'databasePath': '', 'userName': 'root', 'password': 'syc123', 'changedPassword': True, 'mqttType': None, 'pushType': None, 'timingPeriod': None, 'changingPeriod': None, 'cloudDeviceId': '', 'originalSecret': ''}
[2023-12-18 11:39:30,135] logger_util.py->write_log line:61 [INFO] 文件上传：None
[2023-12-18 11:39:30,137] logger_util.py->error_log line:65 [INFO] 分析YAML文件异常：异常信息: Traceback (most recent call last):
  File "E:\Project_python\api_cms\common\requests_util.py", line 241, in analysis_yaml
    extract_data = {key: value_data[0]}
TypeError: 'bool' object is not subscriptable

[2023-12-18 11:39:30,163] logger_util.py->error_log line:65 [INFO] 发送请求异常：异常信息: Traceback (most recent call last):
  File "E:\Project_python\api_cms\common\requests_util.py", line 309, in send_request
    self.base_url = self.replace_load(self.base_url) + self.replace_load(url)
  File "E:\Project_python\api_cms\common\requests_util.py", line 140, in replace_load
    new_value = getattr(DubugTalk(), func_name)(*args_value.split(','))
  File "E:\Project_python\api_cms\debug_talk.py", line 26, in get_extract_data
    return read_extract_file(node_name)
  File "E:\Project_python\api_cms\common\yaml_util.py", line 19, in read_extract_file
    return value[one_node]
TypeError: 'NoneType' object is not subscriptable

[2023-12-18 11:39:30,164] logger_util.py->error_log line:65 [INFO] 分析YAML文件异常：异常信息: Traceback (most recent call last):
  File "E:\Project_python\api_cms\common\requests_util.py", line 309, in send_request
    self.base_url = self.replace_load(self.base_url) + self.replace_load(url)
  File "E:\Project_python\api_cms\common\requests_util.py", line 140, in replace_load
    new_value = getattr(DubugTalk(), func_name)(*args_value.split(','))
  File "E:\Project_python\api_cms\debug_talk.py", line 26, in get_extract_data
    return read_extract_file(node_name)
  File "E:\Project_python\api_cms\common\yaml_util.py", line 19, in read_extract_file
    return value[one_node]
TypeError: 'NoneType' object is not subscriptable

During handling of the above exception, another exception occurred:

Traceback (most recent call last):
  File "E:\Project_python\api_cms\common\requests_util.py", line 185, in analysis_yaml
    res = self.send_request(name =name,method=method,
  File "E:\Project_python\api_cms\common\requests_util.py", line 335, in send_request
    error_log("发送请求异常：异常信息: %s" % str(traceback.format_exc()))
  File "E:\Project_python\api_cms\common\logger_util.py", line 66, in error_log
    raise Exception(log_message)
Exception: 发送请求异常：异常信息: Traceback (most recent call last):
  File "E:\Project_python\api_cms\common\requests_util.py", line 309, in send_request
    self.base_url = self.replace_load(self.base_url) + self.replace_load(url)
  File "E:\Project_python\api_cms\common\requests_util.py", line 140, in replace_load
    new_value = getattr(DubugTalk(), func_name)(*args_value.split(','))
  File "E:\Project_python\api_cms\debug_talk.py", line 26, in get_extract_data
    return read_extract_file(node_name)
  File "E:\Project_python\api_cms\common\yaml_util.py", line 19, in read_extract_file
    return value[one_node]
TypeError: 'NoneType' object is not subscriptable


[2023-12-18 11:39:30,207] logger_util.py->error_log line:65 [INFO] 发送请求异常：异常信息: Traceback (most recent call last):
  File "E:\Project_python\api_cms\common\requests_util.py", line 309, in send_request
    self.base_url = self.replace_load(self.base_url) + self.replace_load(url)
  File "E:\Project_python\api_cms\common\requests_util.py", line 140, in replace_load
    new_value = getattr(DubugTalk(), func_name)(*args_value.split(','))
  File "E:\Project_python\api_cms\debug_talk.py", line 26, in get_extract_data
    return read_extract_file(node_name)
  File "E:\Project_python\api_cms\common\yaml_util.py", line 19, in read_extract_file
    return value[one_node]
TypeError: 'NoneType' object is not subscriptable

[2023-12-18 11:39:30,207] logger_util.py->error_log line:65 [INFO] 分析YAML文件异常：异常信息: Traceback (most recent call last):
  File "E:\Project_python\api_cms\common\requests_util.py", line 309, in send_request
    self.base_url = self.replace_load(self.base_url) + self.replace_load(url)
  File "E:\Project_python\api_cms\common\requests_util.py", line 140, in replace_load
    new_value = getattr(DubugTalk(), func_name)(*args_value.split(','))
  File "E:\Project_python\api_cms\debug_talk.py", line 26, in get_extract_data
    return read_extract_file(node_name)
  File "E:\Project_python\api_cms\common\yaml_util.py", line 19, in read_extract_file
    return value[one_node]
TypeError: 'NoneType' object is not subscriptable

During handling of the above exception, another exception occurred:

Traceback (most recent call last):
  File "E:\Project_python\api_cms\common\requests_util.py", line 185, in analysis_yaml
    res = self.send_request(name =name,method=method,
  File "E:\Project_python\api_cms\common\requests_util.py", line 335, in send_request
    error_log("发送请求异常：异常信息: %s" % str(traceback.format_exc()))
  File "E:\Project_python\api_cms\common\logger_util.py", line 66, in error_log
    raise Exception(log_message)
Exception: 发送请求异常：异常信息: Traceback (most recent call last):
  File "E:\Project_python\api_cms\common\requests_util.py", line 309, in send_request
    self.base_url = self.replace_load(self.base_url) + self.replace_load(url)
  File "E:\Project_python\api_cms\common\requests_util.py", line 140, in replace_load
    new_value = getattr(DubugTalk(), func_name)(*args_value.split(','))
  File "E:\Project_python\api_cms\debug_talk.py", line 26, in get_extract_data
    return read_extract_file(node_name)
  File "E:\Project_python\api_cms\common\yaml_util.py", line 19, in read_extract_file
    return value[one_node]
TypeError: 'NoneType' object is not subscriptable


[2023-12-18 11:39:30,251] logger_util.py->error_log line:65 [INFO] 发送请求异常：异常信息: Traceback (most recent call last):
  File "E:\Project_python\api_cms\common\requests_util.py", line 309, in send_request
    self.base_url = self.replace_load(self.base_url) + self.replace_load(url)
  File "E:\Project_python\api_cms\common\requests_util.py", line 140, in replace_load
    new_value = getattr(DubugTalk(), func_name)(*args_value.split(','))
  File "E:\Project_python\api_cms\debug_talk.py", line 26, in get_extract_data
    return read_extract_file(node_name)
  File "E:\Project_python\api_cms\common\yaml_util.py", line 19, in read_extract_file
    return value[one_node]
TypeError: 'NoneType' object is not subscriptable

[2023-12-18 11:39:30,251] logger_util.py->error_log line:65 [INFO] 分析YAML文件异常：异常信息: Traceback (most recent call last):
  File "E:\Project_python\api_cms\common\requests_util.py", line 309, in send_request
    self.base_url = self.replace_load(self.base_url) + self.replace_load(url)
  File "E:\Project_python\api_cms\common\requests_util.py", line 140, in replace_load
    new_value = getattr(DubugTalk(), func_name)(*args_value.split(','))
  File "E:\Project_python\api_cms\debug_talk.py", line 26, in get_extract_data
    return read_extract_file(node_name)
  File "E:\Project_python\api_cms\common\yaml_util.py", line 19, in read_extract_file
    return value[one_node]
TypeError: 'NoneType' object is not subscriptable

During handling of the above exception, another exception occurred:

Traceback (most recent call last):
  File "E:\Project_python\api_cms\common\requests_util.py", line 185, in analysis_yaml
    res = self.send_request(name =name,method=method,
  File "E:\Project_python\api_cms\common\requests_util.py", line 335, in send_request
    error_log("发送请求异常：异常信息: %s" % str(traceback.format_exc()))
  File "E:\Project_python\api_cms\common\logger_util.py", line 66, in error_log
    raise Exception(log_message)
Exception: 发送请求异常：异常信息: Traceback (most recent call last):
  File "E:\Project_python\api_cms\common\requests_util.py", line 309, in send_request
    self.base_url = self.replace_load(self.base_url) + self.replace_load(url)
  File "E:\Project_python\api_cms\common\requests_util.py", line 140, in replace_load
    new_value = getattr(DubugTalk(), func_name)(*args_value.split(','))
  File "E:\Project_python\api_cms\debug_talk.py", line 26, in get_extract_data
    return read_extract_file(node_name)
  File "E:\Project_python\api_cms\common\yaml_util.py", line 19, in read_extract_file
    return value[one_node]
TypeError: 'NoneType' object is not subscriptable


[2023-12-18 11:39:30,296] logger_util.py->error_log line:65 [INFO] 发送请求异常：异常信息: Traceback (most recent call last):
  File "E:\Project_python\api_cms\common\requests_util.py", line 309, in send_request
    self.base_url = self.replace_load(self.base_url) + self.replace_load(url)
  File "E:\Project_python\api_cms\common\requests_util.py", line 140, in replace_load
    new_value = getattr(DubugTalk(), func_name)(*args_value.split(','))
  File "E:\Project_python\api_cms\debug_talk.py", line 26, in get_extract_data
    return read_extract_file(node_name)
  File "E:\Project_python\api_cms\common\yaml_util.py", line 19, in read_extract_file
    return value[one_node]
TypeError: 'NoneType' object is not subscriptable

[2023-12-18 11:39:30,296] logger_util.py->error_log line:65 [INFO] 分析YAML文件异常：异常信息: Traceback (most recent call last):
  File "E:\Project_python\api_cms\common\requests_util.py", line 309, in send_request
    self.base_url = self.replace_load(self.base_url) + self.replace_load(url)
  File "E:\Project_python\api_cms\common\requests_util.py", line 140, in replace_load
    new_value = getattr(DubugTalk(), func_name)(*args_value.split(','))
  File "E:\Project_python\api_cms\debug_talk.py", line 26, in get_extract_data
    return read_extract_file(node_name)
  File "E:\Project_python\api_cms\common\yaml_util.py", line 19, in read_extract_file
    return value[one_node]
TypeError: 'NoneType' object is not subscriptable

During handling of the above exception, another exception occurred:

Traceback (most recent call last):
  File "E:\Project_python\api_cms\common\requests_util.py", line 185, in analysis_yaml
    res = self.send_request(name =name,method=method,
  File "E:\Project_python\api_cms\common\requests_util.py", line 335, in send_request
    error_log("发送请求异常：异常信息: %s" % str(traceback.format_exc()))
  File "E:\Project_python\api_cms\common\logger_util.py", line 66, in error_log
    raise Exception(log_message)
Exception: 发送请求异常：异常信息: Traceback (most recent call last):
  File "E:\Project_python\api_cms\common\requests_util.py", line 309, in send_request
    self.base_url = self.replace_load(self.base_url) + self.replace_load(url)
  File "E:\Project_python\api_cms\common\requests_util.py", line 140, in replace_load
    new_value = getattr(DubugTalk(), func_name)(*args_value.split(','))
  File "E:\Project_python\api_cms\debug_talk.py", line 26, in get_extract_data
    return read_extract_file(node_name)
  File "E:\Project_python\api_cms\common\yaml_util.py", line 19, in read_extract_file
    return value[one_node]
TypeError: 'NoneType' object is not subscriptable


[2023-12-18 11:39:30,337] logger_util.py->error_log line:65 [INFO] 发送请求异常：异常信息: Traceback (most recent call last):
  File "E:\Project_python\api_cms\common\requests_util.py", line 309, in send_request
    self.base_url = self.replace_load(self.base_url) + self.replace_load(url)
  File "E:\Project_python\api_cms\common\requests_util.py", line 140, in replace_load
    new_value = getattr(DubugTalk(), func_name)(*args_value.split(','))
  File "E:\Project_python\api_cms\debug_talk.py", line 26, in get_extract_data
    return read_extract_file(node_name)
  File "E:\Project_python\api_cms\common\yaml_util.py", line 19, in read_extract_file
    return value[one_node]
TypeError: 'NoneType' object is not subscriptable

[2023-12-18 11:39:30,338] logger_util.py->error_log line:65 [INFO] 分析YAML文件异常：异常信息: Traceback (most recent call last):
  File "E:\Project_python\api_cms\common\requests_util.py", line 309, in send_request
    self.base_url = self.replace_load(self.base_url) + self.replace_load(url)
  File "E:\Project_python\api_cms\common\requests_util.py", line 140, in replace_load
    new_value = getattr(DubugTalk(), func_name)(*args_value.split(','))
  File "E:\Project_python\api_cms\debug_talk.py", line 26, in get_extract_data
    return read_extract_file(node_name)
  File "E:\Project_python\api_cms\common\yaml_util.py", line 19, in read_extract_file
    return value[one_node]
TypeError: 'NoneType' object is not subscriptable

During handling of the above exception, another exception occurred:

Traceback (most recent call last):
  File "E:\Project_python\api_cms\common\requests_util.py", line 185, in analysis_yaml
    res = self.send_request(name =name,method=method,
  File "E:\Project_python\api_cms\common\requests_util.py", line 335, in send_request
    error_log("发送请求异常：异常信息: %s" % str(traceback.format_exc()))
  File "E:\Project_python\api_cms\common\logger_util.py", line 66, in error_log
    raise Exception(log_message)
Exception: 发送请求异常：异常信息: Traceback (most recent call last):
  File "E:\Project_python\api_cms\common\requests_util.py", line 309, in send_request
    self.base_url = self.replace_load(self.base_url) + self.replace_load(url)
  File "E:\Project_python\api_cms\common\requests_util.py", line 140, in replace_load
    new_value = getattr(DubugTalk(), func_name)(*args_value.split(','))
  File "E:\Project_python\api_cms\debug_talk.py", line 26, in get_extract_data
    return read_extract_file(node_name)
  File "E:\Project_python\api_cms\common\yaml_util.py", line 19, in read_extract_file
    return value[one_node]
TypeError: 'NoneType' object is not subscriptable


[2023-12-18 11:39:30,392] logger_util.py->write_log line:61 [INFO] 
-------------接口请求开始-----------
[2023-12-18 11:39:30,392] logger_util.py->write_log line:61 [INFO] 接口名称：创建互联项
[2023-12-18 11:39:30,392] logger_util.py->write_log line:61 [INFO] 接口方式：post
[2023-12-18 11:39:30,392] logger_util.py->write_log line:61 [INFO] 接口路径：http://127.0.0.1:18000/api/v1/connection
[2023-12-18 11:39:30,392] logger_util.py->write_log line:61 [INFO] 请求头：{'X-Project': 'fb63700a195245b9bb42ef9e036ce674'}
[2023-12-18 11:39:30,392] logger_util.py->write_log line:61 [INFO] 请求参数：{'id': None, 'name': 'mysql7815', 'connectionType': 1, 'databaseType': 1, 'authenticationType': None, 'server': '192.168.2.98', 'port': '3306', 'database': 'TestDB', 'databasePath': '', 'userName': 'root', 'password': 'syc123', 'changedPassword': True, 'mqttType': None, 'pushType': None, 'timingPeriod': None, 'changingPeriod': None, 'cloudDeviceId': '', 'originalSecret': ''}
[2023-12-18 11:39:30,392] logger_util.py->write_log line:61 [INFO] 文件上传：None
[2023-12-18 11:39:30,395] logger_util.py->error_log line:65 [INFO] 分析YAML文件异常：异常信息: Traceback (most recent call last):
  File "E:\Project_python\api_cms\common\requests_util.py", line 241, in analysis_yaml
    extract_data = {key: value_data[0]}
TypeError: 'bool' object is not subscriptable

[2023-12-18 11:39:30,422] logger_util.py->error_log line:65 [INFO] 发送请求异常：异常信息: Traceback (most recent call last):
  File "E:\Project_python\api_cms\common\requests_util.py", line 309, in send_request
    self.base_url = self.replace_load(self.base_url) + self.replace_load(url)
  File "E:\Project_python\api_cms\common\requests_util.py", line 140, in replace_load
    new_value = getattr(DubugTalk(), func_name)(*args_value.split(','))
  File "E:\Project_python\api_cms\debug_talk.py", line 26, in get_extract_data
    return read_extract_file(node_name)
  File "E:\Project_python\api_cms\common\yaml_util.py", line 19, in read_extract_file
    return value[one_node]
TypeError: 'NoneType' object is not subscriptable

[2023-12-18 11:39:30,423] logger_util.py->error_log line:65 [INFO] 分析YAML文件异常：异常信息: Traceback (most recent call last):
  File "E:\Project_python\api_cms\common\requests_util.py", line 309, in send_request
    self.base_url = self.replace_load(self.base_url) + self.replace_load(url)
  File "E:\Project_python\api_cms\common\requests_util.py", line 140, in replace_load
    new_value = getattr(DubugTalk(), func_name)(*args_value.split(','))
  File "E:\Project_python\api_cms\debug_talk.py", line 26, in get_extract_data
    return read_extract_file(node_name)
  File "E:\Project_python\api_cms\common\yaml_util.py", line 19, in read_extract_file
    return value[one_node]
TypeError: 'NoneType' object is not subscriptable

During handling of the above exception, another exception occurred:

Traceback (most recent call last):
  File "E:\Project_python\api_cms\common\requests_util.py", line 185, in analysis_yaml
    res = self.send_request(name =name,method=method,
  File "E:\Project_python\api_cms\common\requests_util.py", line 335, in send_request
    error_log("发送请求异常：异常信息: %s" % str(traceback.format_exc()))
  File "E:\Project_python\api_cms\common\logger_util.py", line 66, in error_log
    raise Exception(log_message)
Exception: 发送请求异常：异常信息: Traceback (most recent call last):
  File "E:\Project_python\api_cms\common\requests_util.py", line 309, in send_request
    self.base_url = self.replace_load(self.base_url) + self.replace_load(url)
  File "E:\Project_python\api_cms\common\requests_util.py", line 140, in replace_load
    new_value = getattr(DubugTalk(), func_name)(*args_value.split(','))
  File "E:\Project_python\api_cms\debug_talk.py", line 26, in get_extract_data
    return read_extract_file(node_name)
  File "E:\Project_python\api_cms\common\yaml_util.py", line 19, in read_extract_file
    return value[one_node]
TypeError: 'NoneType' object is not subscriptable


[2023-12-18 11:39:30,477] logger_util.py->error_log line:65 [INFO] 发送请求异常：异常信息: Traceback (most recent call last):
  File "E:\Project_python\api_cms\common\requests_util.py", line 309, in send_request
    self.base_url = self.replace_load(self.base_url) + self.replace_load(url)
  File "E:\Project_python\api_cms\common\requests_util.py", line 140, in replace_load
    new_value = getattr(DubugTalk(), func_name)(*args_value.split(','))
  File "E:\Project_python\api_cms\debug_talk.py", line 26, in get_extract_data
    return read_extract_file(node_name)
  File "E:\Project_python\api_cms\common\yaml_util.py", line 19, in read_extract_file
    return value[one_node]
TypeError: 'NoneType' object is not subscriptable

[2023-12-18 11:39:30,477] logger_util.py->error_log line:65 [INFO] 分析YAML文件异常：异常信息: Traceback (most recent call last):
  File "E:\Project_python\api_cms\common\requests_util.py", line 309, in send_request
    self.base_url = self.replace_load(self.base_url) + self.replace_load(url)
  File "E:\Project_python\api_cms\common\requests_util.py", line 140, in replace_load
    new_value = getattr(DubugTalk(), func_name)(*args_value.split(','))
  File "E:\Project_python\api_cms\debug_talk.py", line 26, in get_extract_data
    return read_extract_file(node_name)
  File "E:\Project_python\api_cms\common\yaml_util.py", line 19, in read_extract_file
    return value[one_node]
TypeError: 'NoneType' object is not subscriptable

During handling of the above exception, another exception occurred:

Traceback (most recent call last):
  File "E:\Project_python\api_cms\common\requests_util.py", line 185, in analysis_yaml
    res = self.send_request(name =name,method=method,
  File "E:\Project_python\api_cms\common\requests_util.py", line 335, in send_request
    error_log("发送请求异常：异常信息: %s" % str(traceback.format_exc()))
  File "E:\Project_python\api_cms\common\logger_util.py", line 66, in error_log
    raise Exception(log_message)
Exception: 发送请求异常：异常信息: Traceback (most recent call last):
  File "E:\Project_python\api_cms\common\requests_util.py", line 309, in send_request
    self.base_url = self.replace_load(self.base_url) + self.replace_load(url)
  File "E:\Project_python\api_cms\common\requests_util.py", line 140, in replace_load
    new_value = getattr(DubugTalk(), func_name)(*args_value.split(','))
  File "E:\Project_python\api_cms\debug_talk.py", line 26, in get_extract_data
    return read_extract_file(node_name)
  File "E:\Project_python\api_cms\common\yaml_util.py", line 19, in read_extract_file
    return value[one_node]
TypeError: 'NoneType' object is not subscriptable


[2023-12-18 11:39:30,518] logger_util.py->error_log line:65 [INFO] 发送请求异常：异常信息: Traceback (most recent call last):
  File "E:\Project_python\api_cms\common\requests_util.py", line 309, in send_request
    self.base_url = self.replace_load(self.base_url) + self.replace_load(url)
  File "E:\Project_python\api_cms\common\requests_util.py", line 140, in replace_load
    new_value = getattr(DubugTalk(), func_name)(*args_value.split(','))
  File "E:\Project_python\api_cms\debug_talk.py", line 26, in get_extract_data
    return read_extract_file(node_name)
  File "E:\Project_python\api_cms\common\yaml_util.py", line 19, in read_extract_file
    return value[one_node]
TypeError: 'NoneType' object is not subscriptable

[2023-12-18 11:39:30,519] logger_util.py->error_log line:65 [INFO] 分析YAML文件异常：异常信息: Traceback (most recent call last):
  File "E:\Project_python\api_cms\common\requests_util.py", line 309, in send_request
    self.base_url = self.replace_load(self.base_url) + self.replace_load(url)
  File "E:\Project_python\api_cms\common\requests_util.py", line 140, in replace_load
    new_value = getattr(DubugTalk(), func_name)(*args_value.split(','))
  File "E:\Project_python\api_cms\debug_talk.py", line 26, in get_extract_data
    return read_extract_file(node_name)
  File "E:\Project_python\api_cms\common\yaml_util.py", line 19, in read_extract_file
    return value[one_node]
TypeError: 'NoneType' object is not subscriptable

During handling of the above exception, another exception occurred:

Traceback (most recent call last):
  File "E:\Project_python\api_cms\common\requests_util.py", line 185, in analysis_yaml
    res = self.send_request(name =name,method=method,
  File "E:\Project_python\api_cms\common\requests_util.py", line 335, in send_request
    error_log("发送请求异常：异常信息: %s" % str(traceback.format_exc()))
  File "E:\Project_python\api_cms\common\logger_util.py", line 66, in error_log
    raise Exception(log_message)
Exception: 发送请求异常：异常信息: Traceback (most recent call last):
  File "E:\Project_python\api_cms\common\requests_util.py", line 309, in send_request
    self.base_url = self.replace_load(self.base_url) + self.replace_load(url)
  File "E:\Project_python\api_cms\common\requests_util.py", line 140, in replace_load
    new_value = getattr(DubugTalk(), func_name)(*args_value.split(','))
  File "E:\Project_python\api_cms\debug_talk.py", line 26, in get_extract_data
    return read_extract_file(node_name)
  File "E:\Project_python\api_cms\common\yaml_util.py", line 19, in read_extract_file
    return value[one_node]
TypeError: 'NoneType' object is not subscriptable


[2023-12-18 11:39:30,559] logger_util.py->error_log line:65 [INFO] 发送请求异常：异常信息: Traceback (most recent call last):
  File "E:\Project_python\api_cms\common\requests_util.py", line 309, in send_request
    self.base_url = self.replace_load(self.base_url) + self.replace_load(url)
  File "E:\Project_python\api_cms\common\requests_util.py", line 140, in replace_load
    new_value = getattr(DubugTalk(), func_name)(*args_value.split(','))
  File "E:\Project_python\api_cms\debug_talk.py", line 26, in get_extract_data
    return read_extract_file(node_name)
  File "E:\Project_python\api_cms\common\yaml_util.py", line 19, in read_extract_file
    return value[one_node]
TypeError: 'NoneType' object is not subscriptable

[2023-12-18 11:39:30,560] logger_util.py->error_log line:65 [INFO] 分析YAML文件异常：异常信息: Traceback (most recent call last):
  File "E:\Project_python\api_cms\common\requests_util.py", line 309, in send_request
    self.base_url = self.replace_load(self.base_url) + self.replace_load(url)
  File "E:\Project_python\api_cms\common\requests_util.py", line 140, in replace_load
    new_value = getattr(DubugTalk(), func_name)(*args_value.split(','))
  File "E:\Project_python\api_cms\debug_talk.py", line 26, in get_extract_data
    return read_extract_file(node_name)
  File "E:\Project_python\api_cms\common\yaml_util.py", line 19, in read_extract_file
    return value[one_node]
TypeError: 'NoneType' object is not subscriptable

During handling of the above exception, another exception occurred:

Traceback (most recent call last):
  File "E:\Project_python\api_cms\common\requests_util.py", line 185, in analysis_yaml
    res = self.send_request(name =name,method=method,
  File "E:\Project_python\api_cms\common\requests_util.py", line 335, in send_request
    error_log("发送请求异常：异常信息: %s" % str(traceback.format_exc()))
  File "E:\Project_python\api_cms\common\logger_util.py", line 66, in error_log
    raise Exception(log_message)
Exception: 发送请求异常：异常信息: Traceback (most recent call last):
  File "E:\Project_python\api_cms\common\requests_util.py", line 309, in send_request
    self.base_url = self.replace_load(self.base_url) + self.replace_load(url)
  File "E:\Project_python\api_cms\common\requests_util.py", line 140, in replace_load
    new_value = getattr(DubugTalk(), func_name)(*args_value.split(','))
  File "E:\Project_python\api_cms\debug_talk.py", line 26, in get_extract_data
    return read_extract_file(node_name)
  File "E:\Project_python\api_cms\common\yaml_util.py", line 19, in read_extract_file
    return value[one_node]
TypeError: 'NoneType' object is not subscriptable


[2023-12-18 11:39:30,602] logger_util.py->error_log line:65 [INFO] 发送请求异常：异常信息: Traceback (most recent call last):
  File "E:\Project_python\api_cms\common\requests_util.py", line 309, in send_request
    self.base_url = self.replace_load(self.base_url) + self.replace_load(url)
  File "E:\Project_python\api_cms\common\requests_util.py", line 140, in replace_load
    new_value = getattr(DubugTalk(), func_name)(*args_value.split(','))
  File "E:\Project_python\api_cms\debug_talk.py", line 26, in get_extract_data
    return read_extract_file(node_name)
  File "E:\Project_python\api_cms\common\yaml_util.py", line 19, in read_extract_file
    return value[one_node]
TypeError: 'NoneType' object is not subscriptable

[2023-12-18 11:39:30,602] logger_util.py->error_log line:65 [INFO] 分析YAML文件异常：异常信息: Traceback (most recent call last):
  File "E:\Project_python\api_cms\common\requests_util.py", line 309, in send_request
    self.base_url = self.replace_load(self.base_url) + self.replace_load(url)
  File "E:\Project_python\api_cms\common\requests_util.py", line 140, in replace_load
    new_value = getattr(DubugTalk(), func_name)(*args_value.split(','))
  File "E:\Project_python\api_cms\debug_talk.py", line 26, in get_extract_data
    return read_extract_file(node_name)
  File "E:\Project_python\api_cms\common\yaml_util.py", line 19, in read_extract_file
    return value[one_node]
TypeError: 'NoneType' object is not subscriptable

During handling of the above exception, another exception occurred:

Traceback (most recent call last):
  File "E:\Project_python\api_cms\common\requests_util.py", line 185, in analysis_yaml
    res = self.send_request(name =name,method=method,
  File "E:\Project_python\api_cms\common\requests_util.py", line 335, in send_request
    error_log("发送请求异常：异常信息: %s" % str(traceback.format_exc()))
  File "E:\Project_python\api_cms\common\logger_util.py", line 66, in error_log
    raise Exception(log_message)
Exception: 发送请求异常：异常信息: Traceback (most recent call last):
  File "E:\Project_python\api_cms\common\requests_util.py", line 309, in send_request
    self.base_url = self.replace_load(self.base_url) + self.replace_load(url)
  File "E:\Project_python\api_cms\common\requests_util.py", line 140, in replace_load
    new_value = getattr(DubugTalk(), func_name)(*args_value.split(','))
  File "E:\Project_python\api_cms\debug_talk.py", line 26, in get_extract_data
    return read_extract_file(node_name)
  File "E:\Project_python\api_cms\common\yaml_util.py", line 19, in read_extract_file
    return value[one_node]
TypeError: 'NoneType' object is not subscriptable


[2023-12-18 11:39:30,647] logger_util.py->error_log line:65 [INFO] 发送请求异常：异常信息: Traceback (most recent call last):
  File "E:\Project_python\api_cms\common\requests_util.py", line 309, in send_request
    self.base_url = self.replace_load(self.base_url) + self.replace_load(url)
  File "E:\Project_python\api_cms\common\requests_util.py", line 140, in replace_load
    new_value = getattr(DubugTalk(), func_name)(*args_value.split(','))
  File "E:\Project_python\api_cms\debug_talk.py", line 26, in get_extract_data
    return read_extract_file(node_name)
  File "E:\Project_python\api_cms\common\yaml_util.py", line 19, in read_extract_file
    return value[one_node]
TypeError: 'NoneType' object is not subscriptable

[2023-12-18 11:39:30,647] logger_util.py->error_log line:65 [INFO] 分析YAML文件异常：异常信息: Traceback (most recent call last):
  File "E:\Project_python\api_cms\common\requests_util.py", line 309, in send_request
    self.base_url = self.replace_load(self.base_url) + self.replace_load(url)
  File "E:\Project_python\api_cms\common\requests_util.py", line 140, in replace_load
    new_value = getattr(DubugTalk(), func_name)(*args_value.split(','))
  File "E:\Project_python\api_cms\debug_talk.py", line 26, in get_extract_data
    return read_extract_file(node_name)
  File "E:\Project_python\api_cms\common\yaml_util.py", line 19, in read_extract_file
    return value[one_node]
TypeError: 'NoneType' object is not subscriptable

During handling of the above exception, another exception occurred:

Traceback (most recent call last):
  File "E:\Project_python\api_cms\common\requests_util.py", line 185, in analysis_yaml
    res = self.send_request(name =name,method=method,
  File "E:\Project_python\api_cms\common\requests_util.py", line 335, in send_request
    error_log("发送请求异常：异常信息: %s" % str(traceback.format_exc()))
  File "E:\Project_python\api_cms\common\logger_util.py", line 66, in error_log
    raise Exception(log_message)
Exception: 发送请求异常：异常信息: Traceback (most recent call last):
  File "E:\Project_python\api_cms\common\requests_util.py", line 309, in send_request
    self.base_url = self.replace_load(self.base_url) + self.replace_load(url)
  File "E:\Project_python\api_cms\common\requests_util.py", line 140, in replace_load
    new_value = getattr(DubugTalk(), func_name)(*args_value.split(','))
  File "E:\Project_python\api_cms\debug_talk.py", line 26, in get_extract_data
    return read_extract_file(node_name)
  File "E:\Project_python\api_cms\common\yaml_util.py", line 19, in read_extract_file
    return value[one_node]
TypeError: 'NoneType' object is not subscriptable


[2023-12-18 11:39:30,691] logger_util.py->error_log line:65 [INFO] 发送请求异常：异常信息: Traceback (most recent call last):
  File "E:\Project_python\api_cms\common\requests_util.py", line 309, in send_request
    self.base_url = self.replace_load(self.base_url) + self.replace_load(url)
  File "E:\Project_python\api_cms\common\requests_util.py", line 140, in replace_load
    new_value = getattr(DubugTalk(), func_name)(*args_value.split(','))
  File "E:\Project_python\api_cms\debug_talk.py", line 26, in get_extract_data
    return read_extract_file(node_name)
  File "E:\Project_python\api_cms\common\yaml_util.py", line 19, in read_extract_file
    return value[one_node]
TypeError: 'NoneType' object is not subscriptable

[2023-12-18 11:39:30,691] logger_util.py->error_log line:65 [INFO] 分析YAML文件异常：异常信息: Traceback (most recent call last):
  File "E:\Project_python\api_cms\common\requests_util.py", line 309, in send_request
    self.base_url = self.replace_load(self.base_url) + self.replace_load(url)
  File "E:\Project_python\api_cms\common\requests_util.py", line 140, in replace_load
    new_value = getattr(DubugTalk(), func_name)(*args_value.split(','))
  File "E:\Project_python\api_cms\debug_talk.py", line 26, in get_extract_data
    return read_extract_file(node_name)
  File "E:\Project_python\api_cms\common\yaml_util.py", line 19, in read_extract_file
    return value[one_node]
TypeError: 'NoneType' object is not subscriptable

During handling of the above exception, another exception occurred:

Traceback (most recent call last):
  File "E:\Project_python\api_cms\common\requests_util.py", line 185, in analysis_yaml
    res = self.send_request(name =name,method=method,
  File "E:\Project_python\api_cms\common\requests_util.py", line 335, in send_request
    error_log("发送请求异常：异常信息: %s" % str(traceback.format_exc()))
  File "E:\Project_python\api_cms\common\logger_util.py", line 66, in error_log
    raise Exception(log_message)
Exception: 发送请求异常：异常信息: Traceback (most recent call last):
  File "E:\Project_python\api_cms\common\requests_util.py", line 309, in send_request
    self.base_url = self.replace_load(self.base_url) + self.replace_load(url)
  File "E:\Project_python\api_cms\common\requests_util.py", line 140, in replace_load
    new_value = getattr(DubugTalk(), func_name)(*args_value.split(','))
  File "E:\Project_python\api_cms\debug_talk.py", line 26, in get_extract_data
    return read_extract_file(node_name)
  File "E:\Project_python\api_cms\common\yaml_util.py", line 19, in read_extract_file
    return value[one_node]
TypeError: 'NoneType' object is not subscriptable


[2023-12-18 11:39:30,733] logger_util.py->error_log line:65 [INFO] 发送请求异常：异常信息: Traceback (most recent call last):
  File "E:\Project_python\api_cms\common\requests_util.py", line 309, in send_request
    self.base_url = self.replace_load(self.base_url) + self.replace_load(url)
  File "E:\Project_python\api_cms\common\requests_util.py", line 140, in replace_load
    new_value = getattr(DubugTalk(), func_name)(*args_value.split(','))
  File "E:\Project_python\api_cms\debug_talk.py", line 26, in get_extract_data
    return read_extract_file(node_name)
  File "E:\Project_python\api_cms\common\yaml_util.py", line 19, in read_extract_file
    return value[one_node]
TypeError: 'NoneType' object is not subscriptable

[2023-12-18 11:39:30,733] logger_util.py->error_log line:65 [INFO] 分析YAML文件异常：异常信息: Traceback (most recent call last):
  File "E:\Project_python\api_cms\common\requests_util.py", line 309, in send_request
    self.base_url = self.replace_load(self.base_url) + self.replace_load(url)
  File "E:\Project_python\api_cms\common\requests_util.py", line 140, in replace_load
    new_value = getattr(DubugTalk(), func_name)(*args_value.split(','))
  File "E:\Project_python\api_cms\debug_talk.py", line 26, in get_extract_data
    return read_extract_file(node_name)
  File "E:\Project_python\api_cms\common\yaml_util.py", line 19, in read_extract_file
    return value[one_node]
TypeError: 'NoneType' object is not subscriptable

During handling of the above exception, another exception occurred:

Traceback (most recent call last):
  File "E:\Project_python\api_cms\common\requests_util.py", line 185, in analysis_yaml
    res = self.send_request(name =name,method=method,
  File "E:\Project_python\api_cms\common\requests_util.py", line 335, in send_request
    error_log("发送请求异常：异常信息: %s" % str(traceback.format_exc()))
  File "E:\Project_python\api_cms\common\logger_util.py", line 66, in error_log
    raise Exception(log_message)
Exception: 发送请求异常：异常信息: Traceback (most recent call last):
  File "E:\Project_python\api_cms\common\requests_util.py", line 309, in send_request
    self.base_url = self.replace_load(self.base_url) + self.replace_load(url)
  File "E:\Project_python\api_cms\common\requests_util.py", line 140, in replace_load
    new_value = getattr(DubugTalk(), func_name)(*args_value.split(','))
  File "E:\Project_python\api_cms\debug_talk.py", line 26, in get_extract_data
    return read_extract_file(node_name)
  File "E:\Project_python\api_cms\common\yaml_util.py", line 19, in read_extract_file
    return value[one_node]
TypeError: 'NoneType' object is not subscriptable


[2023-12-18 11:39:30,777] logger_util.py->error_log line:65 [INFO] 发送请求异常：异常信息: Traceback (most recent call last):
  File "E:\Project_python\api_cms\common\requests_util.py", line 309, in send_request
    self.base_url = self.replace_load(self.base_url) + self.replace_load(url)
  File "E:\Project_python\api_cms\common\requests_util.py", line 140, in replace_load
    new_value = getattr(DubugTalk(), func_name)(*args_value.split(','))
  File "E:\Project_python\api_cms\debug_talk.py", line 26, in get_extract_data
    return read_extract_file(node_name)
  File "E:\Project_python\api_cms\common\yaml_util.py", line 19, in read_extract_file
    return value[one_node]
TypeError: 'NoneType' object is not subscriptable

[2023-12-18 11:39:30,777] logger_util.py->error_log line:65 [INFO] 分析YAML文件异常：异常信息: Traceback (most recent call last):
  File "E:\Project_python\api_cms\common\requests_util.py", line 309, in send_request
    self.base_url = self.replace_load(self.base_url) + self.replace_load(url)
  File "E:\Project_python\api_cms\common\requests_util.py", line 140, in replace_load
    new_value = getattr(DubugTalk(), func_name)(*args_value.split(','))
  File "E:\Project_python\api_cms\debug_talk.py", line 26, in get_extract_data
    return read_extract_file(node_name)
  File "E:\Project_python\api_cms\common\yaml_util.py", line 19, in read_extract_file
    return value[one_node]
TypeError: 'NoneType' object is not subscriptable

During handling of the above exception, another exception occurred:

Traceback (most recent call last):
  File "E:\Project_python\api_cms\common\requests_util.py", line 185, in analysis_yaml
    res = self.send_request(name =name,method=method,
  File "E:\Project_python\api_cms\common\requests_util.py", line 335, in send_request
    error_log("发送请求异常：异常信息: %s" % str(traceback.format_exc()))
  File "E:\Project_python\api_cms\common\logger_util.py", line 66, in error_log
    raise Exception(log_message)
Exception: 发送请求异常：异常信息: Traceback (most recent call last):
  File "E:\Project_python\api_cms\common\requests_util.py", line 309, in send_request
    self.base_url = self.replace_load(self.base_url) + self.replace_load(url)
  File "E:\Project_python\api_cms\common\requests_util.py", line 140, in replace_load
    new_value = getattr(DubugTalk(), func_name)(*args_value.split(','))
  File "E:\Project_python\api_cms\debug_talk.py", line 26, in get_extract_data
    return read_extract_file(node_name)
  File "E:\Project_python\api_cms\common\yaml_util.py", line 19, in read_extract_file
    return value[one_node]
TypeError: 'NoneType' object is not subscriptable


[2023-12-18 11:39:30,838] logger_util.py->write_log line:61 [INFO] 
-------------接口请求开始-----------
[2023-12-18 11:39:30,838] logger_util.py->write_log line:61 [INFO] 接口名称：下发A2=10
[2023-12-18 11:39:30,839] logger_util.py->write_log line:61 [INFO] 接口方式：post
[2023-12-18 11:39:30,839] logger_util.py->write_log line:61 [INFO] 接口路径：http://127.0.0.1:18000/api/v1/variable/setvalues
[2023-12-18 11:39:30,839] logger_util.py->write_log line:61 [INFO] 请求头：{'X-Project': 'fb63700a195245b9bb42ef9e036ce674', 'Authorization': 'Bearer eyJhbGciOiJIUzI1NiIsInR5cCI6IkpXVCJ9.eyJodHRwOi8vc2NoZW1hcy54bWxzb2FwLm9yZy93cy8yMDA1LzA1L2lkZW50aXR5L2NsYWltcy9uYW1lIjoiU3VwZXJBZG1pbiIsImh0dHA6Ly9zY2hlbWFzLnhtbHNvYXAub3JnL3dzLzIwMDUvMDUvaWRlbnRpdHkvY2xhaW1zL25hbWVpZGVudGlmaWVyIjoiU3VwZXJBZG1pbiIsImV4cCI6MTcwMjk0OTM5MiwiaXNzIjoiQ01TdjIiLCJhdWQiOiJBcGkifQ.DTE3ExRd5e35qx7qyEGhaNLjjzP8QxhHUoLCzYg7Hcc'}
[2023-12-18 11:39:30,839] logger_util.py->write_log line:61 [INFO] 请求参数：{'A2': '10'}
[2023-12-18 11:39:30,839] logger_util.py->write_log line:61 [INFO] 文件上传：None
[2023-12-18 11:39:30,841] logger_util.py->error_log line:65 [INFO] 断言失败:status_code不等于200
[2023-12-18 11:39:30,841] logger_util.py->write_log line:61 [INFO] 实际结果：{'code': 409, 'msg': 'Projcet Conflict'}
[2023-12-18 11:39:30,841] logger_util.py->write_log line:61 [INFO] 接口请求失败！
[2023-12-18 11:39:30,841] logger_util.py->write_log line:61 [INFO] -------------接口请求结束-----------

[2023-12-18 11:39:30,841] logger_util.py->error_log line:65 [INFO] 断言异常：异常信息: Traceback (most recent call last):
  File "E:\Project_python\api_cms\common\requests_util.py", line 368, in validate_result
    error_log("断言失败:"+assert_key+"不等于"+str(assert_value))
  File "E:\Project_python\api_cms\common\logger_util.py", line 66, in error_log
    raise Exception(log_message)
Exception: 断言失败:status_code不等于200

[2023-12-18 11:39:30,842] logger_util.py->error_log line:65 [INFO] 分析YAML文件异常：异常信息: Traceback (most recent call last):
  File "E:\Project_python\api_cms\common\requests_util.py", line 368, in validate_result
    error_log("断言失败:"+assert_key+"不等于"+str(assert_value))
  File "E:\Project_python\api_cms\common\logger_util.py", line 66, in error_log
    raise Exception(log_message)
Exception: 断言失败:status_code不等于200

During handling of the above exception, another exception occurred:

Traceback (most recent call last):
  File "E:\Project_python\api_cms\common\requests_util.py", line 248, in analysis_yaml
    self.validate_result(yq_result, return_data, status_code)
  File "E:\Project_python\api_cms\common\requests_util.py", line 448, in validate_result
    error_log("断言异常：异常信息: %s" % str(traceback.format_exc()))
  File "E:\Project_python\api_cms\common\logger_util.py", line 66, in error_log
    raise Exception(log_message)
Exception: 断言异常：异常信息: Traceback (most recent call last):
  File "E:\Project_python\api_cms\common\requests_util.py", line 368, in validate_result
    error_log("断言失败:"+assert_key+"不等于"+str(assert_value))
  File "E:\Project_python\api_cms\common\logger_util.py", line 66, in error_log
    raise Exception(log_message)
Exception: 断言失败:status_code不等于200


[2023-12-18 11:39:30,891] logger_util.py->write_log line:61 [INFO] 
-------------接口请求开始-----------
[2023-12-18 11:39:30,891] logger_util.py->write_log line:61 [INFO] 接口名称：下发A10=10.456
[2023-12-18 11:39:30,891] logger_util.py->write_log line:61 [INFO] 接口方式：post
[2023-12-18 11:39:30,891] logger_util.py->write_log line:61 [INFO] 接口路径：http://127.0.0.1:18000/api/v1/variable/setvalues
[2023-12-18 11:39:30,891] logger_util.py->write_log line:61 [INFO] 请求头：{'X-Project': 'fb63700a195245b9bb42ef9e036ce674', 'Authorization': 'Bearer eyJhbGciOiJIUzI1NiIsInR5cCI6IkpXVCJ9.eyJodHRwOi8vc2NoZW1hcy54bWxzb2FwLm9yZy93cy8yMDA1LzA1L2lkZW50aXR5L2NsYWltcy9uYW1lIjoiU3VwZXJBZG1pbiIsImh0dHA6Ly9zY2hlbWFzLnhtbHNvYXAub3JnL3dzLzIwMDUvMDUvaWRlbnRpdHkvY2xhaW1zL25hbWVpZGVudGlmaWVyIjoiU3VwZXJBZG1pbiIsImV4cCI6MTcwMjk0OTM5MiwiaXNzIjoiQ01TdjIiLCJhdWQiOiJBcGkifQ.DTE3ExRd5e35qx7qyEGhaNLjjzP8QxhHUoLCzYg7Hcc'}
[2023-12-18 11:39:30,891] logger_util.py->write_log line:61 [INFO] 请求参数：{'A10': '10.456'}
[2023-12-18 11:39:30,891] logger_util.py->write_log line:61 [INFO] 文件上传：None
[2023-12-18 11:39:30,893] logger_util.py->error_log line:65 [INFO] 断言失败:status_code不等于200
[2023-12-18 11:39:30,893] logger_util.py->write_log line:61 [INFO] 实际结果：{'code': 409, 'msg': 'Projcet Conflict'}
[2023-12-18 11:39:30,893] logger_util.py->write_log line:61 [INFO] 接口请求失败！
[2023-12-18 11:39:30,894] logger_util.py->write_log line:61 [INFO] -------------接口请求结束-----------

[2023-12-18 11:39:30,894] logger_util.py->error_log line:65 [INFO] 断言异常：异常信息: Traceback (most recent call last):
  File "E:\Project_python\api_cms\common\requests_util.py", line 368, in validate_result
    error_log("断言失败:"+assert_key+"不等于"+str(assert_value))
  File "E:\Project_python\api_cms\common\logger_util.py", line 66, in error_log
    raise Exception(log_message)
Exception: 断言失败:status_code不等于200

[2023-12-18 11:39:30,894] logger_util.py->error_log line:65 [INFO] 分析YAML文件异常：异常信息: Traceback (most recent call last):
  File "E:\Project_python\api_cms\common\requests_util.py", line 368, in validate_result
    error_log("断言失败:"+assert_key+"不等于"+str(assert_value))
  File "E:\Project_python\api_cms\common\logger_util.py", line 66, in error_log
    raise Exception(log_message)
Exception: 断言失败:status_code不等于200

During handling of the above exception, another exception occurred:

Traceback (most recent call last):
  File "E:\Project_python\api_cms\common\requests_util.py", line 248, in analysis_yaml
    self.validate_result(yq_result, return_data, status_code)
  File "E:\Project_python\api_cms\common\requests_util.py", line 448, in validate_result
    error_log("断言异常：异常信息: %s" % str(traceback.format_exc()))
  File "E:\Project_python\api_cms\common\logger_util.py", line 66, in error_log
    raise Exception(log_message)
Exception: 断言异常：异常信息: Traceback (most recent call last):
  File "E:\Project_python\api_cms\common\requests_util.py", line 368, in validate_result
    error_log("断言失败:"+assert_key+"不等于"+str(assert_value))
  File "E:\Project_python\api_cms\common\logger_util.py", line 66, in error_log
    raise Exception(log_message)
Exception: 断言失败:status_code不等于200


[2023-12-18 11:39:30,938] logger_util.py->write_log line:61 [INFO] 
-------------接口请求开始-----------
[2023-12-18 11:39:30,938] logger_util.py->write_log line:61 [INFO] 接口名称：下发A12=中文1
[2023-12-18 11:39:30,938] logger_util.py->write_log line:61 [INFO] 接口方式：post
[2023-12-18 11:39:30,938] logger_util.py->write_log line:61 [INFO] 接口路径：http://127.0.0.1:18000/api/v1/variable/setvalues
[2023-12-18 11:39:30,938] logger_util.py->write_log line:61 [INFO] 请求头：{'X-Project': 'fb63700a195245b9bb42ef9e036ce674', 'Authorization': 'Bearer eyJhbGciOiJIUzI1NiIsInR5cCI6IkpXVCJ9.eyJodHRwOi8vc2NoZW1hcy54bWxzb2FwLm9yZy93cy8yMDA1LzA1L2lkZW50aXR5L2NsYWltcy9uYW1lIjoiU3VwZXJBZG1pbiIsImh0dHA6Ly9zY2hlbWFzLnhtbHNvYXAub3JnL3dzLzIwMDUvMDUvaWRlbnRpdHkvY2xhaW1zL25hbWVpZGVudGlmaWVyIjoiU3VwZXJBZG1pbiIsImV4cCI6MTcwMjk0OTM5MiwiaXNzIjoiQ01TdjIiLCJhdWQiOiJBcGkifQ.DTE3ExRd5e35qx7qyEGhaNLjjzP8QxhHUoLCzYg7Hcc'}
[2023-12-18 11:39:30,938] logger_util.py->write_log line:61 [INFO] 请求参数：{'A12': '中文1'}
[2023-12-18 11:39:30,938] logger_util.py->write_log line:61 [INFO] 文件上传：None
[2023-12-18 11:39:30,940] logger_util.py->error_log line:65 [INFO] 断言失败:status_code不等于200
[2023-12-18 11:39:30,940] logger_util.py->write_log line:61 [INFO] 实际结果：{'code': 409, 'msg': 'Projcet Conflict'}
[2023-12-18 11:39:30,940] logger_util.py->write_log line:61 [INFO] 接口请求失败！
[2023-12-18 11:39:30,940] logger_util.py->write_log line:61 [INFO] -------------接口请求结束-----------

[2023-12-18 11:39:30,941] logger_util.py->error_log line:65 [INFO] 断言异常：异常信息: Traceback (most recent call last):
  File "E:\Project_python\api_cms\common\requests_util.py", line 368, in validate_result
    error_log("断言失败:"+assert_key+"不等于"+str(assert_value))
  File "E:\Project_python\api_cms\common\logger_util.py", line 66, in error_log
    raise Exception(log_message)
Exception: 断言失败:status_code不等于200

[2023-12-18 11:39:30,941] logger_util.py->error_log line:65 [INFO] 分析YAML文件异常：异常信息: Traceback (most recent call last):
  File "E:\Project_python\api_cms\common\requests_util.py", line 368, in validate_result
    error_log("断言失败:"+assert_key+"不等于"+str(assert_value))
  File "E:\Project_python\api_cms\common\logger_util.py", line 66, in error_log
    raise Exception(log_message)
Exception: 断言失败:status_code不等于200

During handling of the above exception, another exception occurred:

Traceback (most recent call last):
  File "E:\Project_python\api_cms\common\requests_util.py", line 248, in analysis_yaml
    self.validate_result(yq_result, return_data, status_code)
  File "E:\Project_python\api_cms\common\requests_util.py", line 448, in validate_result
    error_log("断言异常：异常信息: %s" % str(traceback.format_exc()))
  File "E:\Project_python\api_cms\common\logger_util.py", line 66, in error_log
    raise Exception(log_message)
Exception: 断言异常：异常信息: Traceback (most recent call last):
  File "E:\Project_python\api_cms\common\requests_util.py", line 368, in validate_result
    error_log("断言失败:"+assert_key+"不等于"+str(assert_value))
  File "E:\Project_python\api_cms\common\logger_util.py", line 66, in error_log
    raise Exception(log_message)
Exception: 断言失败:status_code不等于200


[2023-12-18 11:39:30,984] logger_util.py->write_log line:61 [INFO] 
-------------接口请求开始-----------
[2023-12-18 11:39:30,984] logger_util.py->write_log line:61 [INFO] 接口名称：下发aa16=2023-10-20 18:40:55
[2023-12-18 11:39:30,984] logger_util.py->write_log line:61 [INFO] 接口方式：post
[2023-12-18 11:39:30,984] logger_util.py->write_log line:61 [INFO] 接口路径：http://127.0.0.1:18000/api/v1/variable/setvalues
[2023-12-18 11:39:30,984] logger_util.py->write_log line:61 [INFO] 请求头：{'X-Project': 'fb63700a195245b9bb42ef9e036ce674', 'Authorization': 'Bearer eyJhbGciOiJIUzI1NiIsInR5cCI6IkpXVCJ9.eyJodHRwOi8vc2NoZW1hcy54bWxzb2FwLm9yZy93cy8yMDA1LzA1L2lkZW50aXR5L2NsYWltcy9uYW1lIjoiU3VwZXJBZG1pbiIsImh0dHA6Ly9zY2hlbWFzLnhtbHNvYXAub3JnL3dzLzIwMDUvMDUvaWRlbnRpdHkvY2xhaW1zL25hbWVpZGVudGlmaWVyIjoiU3VwZXJBZG1pbiIsImV4cCI6MTcwMjk0OTM5MiwiaXNzIjoiQ01TdjIiLCJhdWQiOiJBcGkifQ.DTE3ExRd5e35qx7qyEGhaNLjjzP8QxhHUoLCzYg7Hcc'}
[2023-12-18 11:39:30,984] logger_util.py->write_log line:61 [INFO] 请求参数：{'aa16': '2023-10-20 18:40:55'}
[2023-12-18 11:39:30,984] logger_util.py->write_log line:61 [INFO] 文件上传：None
[2023-12-18 11:39:30,986] logger_util.py->error_log line:65 [INFO] 断言失败:status_code不等于200
[2023-12-18 11:39:30,986] logger_util.py->write_log line:61 [INFO] 实际结果：{'code': 409, 'msg': 'Projcet Conflict'}
[2023-12-18 11:39:30,986] logger_util.py->write_log line:61 [INFO] 接口请求失败！
[2023-12-18 11:39:30,987] logger_util.py->write_log line:61 [INFO] -------------接口请求结束-----------

[2023-12-18 11:39:30,987] logger_util.py->error_log line:65 [INFO] 断言异常：异常信息: Traceback (most recent call last):
  File "E:\Project_python\api_cms\common\requests_util.py", line 368, in validate_result
    error_log("断言失败:"+assert_key+"不等于"+str(assert_value))
  File "E:\Project_python\api_cms\common\logger_util.py", line 66, in error_log
    raise Exception(log_message)
Exception: 断言失败:status_code不等于200

[2023-12-18 11:39:30,987] logger_util.py->error_log line:65 [INFO] 分析YAML文件异常：异常信息: Traceback (most recent call last):
  File "E:\Project_python\api_cms\common\requests_util.py", line 368, in validate_result
    error_log("断言失败:"+assert_key+"不等于"+str(assert_value))
  File "E:\Project_python\api_cms\common\logger_util.py", line 66, in error_log
    raise Exception(log_message)
Exception: 断言失败:status_code不等于200

During handling of the above exception, another exception occurred:

Traceback (most recent call last):
  File "E:\Project_python\api_cms\common\requests_util.py", line 248, in analysis_yaml
    self.validate_result(yq_result, return_data, status_code)
  File "E:\Project_python\api_cms\common\requests_util.py", line 448, in validate_result
    error_log("断言异常：异常信息: %s" % str(traceback.format_exc()))
  File "E:\Project_python\api_cms\common\logger_util.py", line 66, in error_log
    raise Exception(log_message)
Exception: 断言异常：异常信息: Traceback (most recent call last):
  File "E:\Project_python\api_cms\common\requests_util.py", line 368, in validate_result
    error_log("断言失败:"+assert_key+"不等于"+str(assert_value))
  File "E:\Project_python\api_cms\common\logger_util.py", line 66, in error_log
    raise Exception(log_message)
Exception: 断言失败:status_code不等于200


[2023-12-18 11:39:31,118] logger_util.py->error_log line:65 [INFO] 发送请求异常：异常信息: Traceback (most recent call last):
  File "E:\Project_python\api_cms\common\requests_util.py", line 309, in send_request
    self.base_url = self.replace_load(self.base_url) + self.replace_load(url)
  File "E:\Project_python\api_cms\common\requests_util.py", line 140, in replace_load
    new_value = getattr(DubugTalk(), func_name)(*args_value.split(','))
  File "E:\Project_python\api_cms\debug_talk.py", line 26, in get_extract_data
    return read_extract_file(node_name)
  File "E:\Project_python\api_cms\common\yaml_util.py", line 19, in read_extract_file
    return value[one_node]
TypeError: 'NoneType' object is not subscriptable

[2023-12-18 11:39:31,119] logger_util.py->error_log line:65 [INFO] 分析YAML文件异常：异常信息: Traceback (most recent call last):
  File "E:\Project_python\api_cms\common\requests_util.py", line 309, in send_request
    self.base_url = self.replace_load(self.base_url) + self.replace_load(url)
  File "E:\Project_python\api_cms\common\requests_util.py", line 140, in replace_load
    new_value = getattr(DubugTalk(), func_name)(*args_value.split(','))
  File "E:\Project_python\api_cms\debug_talk.py", line 26, in get_extract_data
    return read_extract_file(node_name)
  File "E:\Project_python\api_cms\common\yaml_util.py", line 19, in read_extract_file
    return value[one_node]
TypeError: 'NoneType' object is not subscriptable

During handling of the above exception, another exception occurred:

Traceback (most recent call last):
  File "E:\Project_python\api_cms\common\requests_util.py", line 185, in analysis_yaml
    res = self.send_request(name =name,method=method,
  File "E:\Project_python\api_cms\common\requests_util.py", line 335, in send_request
    error_log("发送请求异常：异常信息: %s" % str(traceback.format_exc()))
  File "E:\Project_python\api_cms\common\logger_util.py", line 66, in error_log
    raise Exception(log_message)
Exception: 发送请求异常：异常信息: Traceback (most recent call last):
  File "E:\Project_python\api_cms\common\requests_util.py", line 309, in send_request
    self.base_url = self.replace_load(self.base_url) + self.replace_load(url)
  File "E:\Project_python\api_cms\common\requests_util.py", line 140, in replace_load
    new_value = getattr(DubugTalk(), func_name)(*args_value.split(','))
  File "E:\Project_python\api_cms\debug_talk.py", line 26, in get_extract_data
    return read_extract_file(node_name)
  File "E:\Project_python\api_cms\common\yaml_util.py", line 19, in read_extract_file
    return value[one_node]
TypeError: 'NoneType' object is not subscriptable


[2023-12-18 11:39:31,163] logger_util.py->error_log line:65 [INFO] 发送请求异常：异常信息: Traceback (most recent call last):
  File "E:\Project_python\api_cms\common\requests_util.py", line 309, in send_request
    self.base_url = self.replace_load(self.base_url) + self.replace_load(url)
  File "E:\Project_python\api_cms\common\requests_util.py", line 140, in replace_load
    new_value = getattr(DubugTalk(), func_name)(*args_value.split(','))
  File "E:\Project_python\api_cms\debug_talk.py", line 26, in get_extract_data
    return read_extract_file(node_name)
  File "E:\Project_python\api_cms\common\yaml_util.py", line 19, in read_extract_file
    return value[one_node]
TypeError: 'NoneType' object is not subscriptable

[2023-12-18 11:39:31,163] logger_util.py->error_log line:65 [INFO] 分析YAML文件异常：异常信息: Traceback (most recent call last):
  File "E:\Project_python\api_cms\common\requests_util.py", line 309, in send_request
    self.base_url = self.replace_load(self.base_url) + self.replace_load(url)
  File "E:\Project_python\api_cms\common\requests_util.py", line 140, in replace_load
    new_value = getattr(DubugTalk(), func_name)(*args_value.split(','))
  File "E:\Project_python\api_cms\debug_talk.py", line 26, in get_extract_data
    return read_extract_file(node_name)
  File "E:\Project_python\api_cms\common\yaml_util.py", line 19, in read_extract_file
    return value[one_node]
TypeError: 'NoneType' object is not subscriptable

During handling of the above exception, another exception occurred:

Traceback (most recent call last):
  File "E:\Project_python\api_cms\common\requests_util.py", line 185, in analysis_yaml
    res = self.send_request(name =name,method=method,
  File "E:\Project_python\api_cms\common\requests_util.py", line 335, in send_request
    error_log("发送请求异常：异常信息: %s" % str(traceback.format_exc()))
  File "E:\Project_python\api_cms\common\logger_util.py", line 66, in error_log
    raise Exception(log_message)
Exception: 发送请求异常：异常信息: Traceback (most recent call last):
  File "E:\Project_python\api_cms\common\requests_util.py", line 309, in send_request
    self.base_url = self.replace_load(self.base_url) + self.replace_load(url)
  File "E:\Project_python\api_cms\common\requests_util.py", line 140, in replace_load
    new_value = getattr(DubugTalk(), func_name)(*args_value.split(','))
  File "E:\Project_python\api_cms\debug_talk.py", line 26, in get_extract_data
    return read_extract_file(node_name)
  File "E:\Project_python\api_cms\common\yaml_util.py", line 19, in read_extract_file
    return value[one_node]
TypeError: 'NoneType' object is not subscriptable


[2023-12-18 11:39:31,204] logger_util.py->error_log line:65 [INFO] 发送请求异常：异常信息: Traceback (most recent call last):
  File "E:\Project_python\api_cms\common\requests_util.py", line 309, in send_request
    self.base_url = self.replace_load(self.base_url) + self.replace_load(url)
  File "E:\Project_python\api_cms\common\requests_util.py", line 140, in replace_load
    new_value = getattr(DubugTalk(), func_name)(*args_value.split(','))
  File "E:\Project_python\api_cms\debug_talk.py", line 26, in get_extract_data
    return read_extract_file(node_name)
  File "E:\Project_python\api_cms\common\yaml_util.py", line 19, in read_extract_file
    return value[one_node]
TypeError: 'NoneType' object is not subscriptable

[2023-12-18 11:39:31,204] logger_util.py->error_log line:65 [INFO] 分析YAML文件异常：异常信息: Traceback (most recent call last):
  File "E:\Project_python\api_cms\common\requests_util.py", line 309, in send_request
    self.base_url = self.replace_load(self.base_url) + self.replace_load(url)
  File "E:\Project_python\api_cms\common\requests_util.py", line 140, in replace_load
    new_value = getattr(DubugTalk(), func_name)(*args_value.split(','))
  File "E:\Project_python\api_cms\debug_talk.py", line 26, in get_extract_data
    return read_extract_file(node_name)
  File "E:\Project_python\api_cms\common\yaml_util.py", line 19, in read_extract_file
    return value[one_node]
TypeError: 'NoneType' object is not subscriptable

During handling of the above exception, another exception occurred:

Traceback (most recent call last):
  File "E:\Project_python\api_cms\common\requests_util.py", line 185, in analysis_yaml
    res = self.send_request(name =name,method=method,
  File "E:\Project_python\api_cms\common\requests_util.py", line 335, in send_request
    error_log("发送请求异常：异常信息: %s" % str(traceback.format_exc()))
  File "E:\Project_python\api_cms\common\logger_util.py", line 66, in error_log
    raise Exception(log_message)
Exception: 发送请求异常：异常信息: Traceback (most recent call last):
  File "E:\Project_python\api_cms\common\requests_util.py", line 309, in send_request
    self.base_url = self.replace_load(self.base_url) + self.replace_load(url)
  File "E:\Project_python\api_cms\common\requests_util.py", line 140, in replace_load
    new_value = getattr(DubugTalk(), func_name)(*args_value.split(','))
  File "E:\Project_python\api_cms\debug_talk.py", line 26, in get_extract_data
    return read_extract_file(node_name)
  File "E:\Project_python\api_cms\common\yaml_util.py", line 19, in read_extract_file
    return value[one_node]
TypeError: 'NoneType' object is not subscriptable


[2023-12-18 11:39:31,247] logger_util.py->error_log line:65 [INFO] 发送请求异常：异常信息: Traceback (most recent call last):
  File "E:\Project_python\api_cms\common\requests_util.py", line 309, in send_request
    self.base_url = self.replace_load(self.base_url) + self.replace_load(url)
  File "E:\Project_python\api_cms\common\requests_util.py", line 140, in replace_load
    new_value = getattr(DubugTalk(), func_name)(*args_value.split(','))
  File "E:\Project_python\api_cms\debug_talk.py", line 26, in get_extract_data
    return read_extract_file(node_name)
  File "E:\Project_python\api_cms\common\yaml_util.py", line 19, in read_extract_file
    return value[one_node]
TypeError: 'NoneType' object is not subscriptable

[2023-12-18 11:39:31,248] logger_util.py->error_log line:65 [INFO] 分析YAML文件异常：异常信息: Traceback (most recent call last):
  File "E:\Project_python\api_cms\common\requests_util.py", line 309, in send_request
    self.base_url = self.replace_load(self.base_url) + self.replace_load(url)
  File "E:\Project_python\api_cms\common\requests_util.py", line 140, in replace_load
    new_value = getattr(DubugTalk(), func_name)(*args_value.split(','))
  File "E:\Project_python\api_cms\debug_talk.py", line 26, in get_extract_data
    return read_extract_file(node_name)
  File "E:\Project_python\api_cms\common\yaml_util.py", line 19, in read_extract_file
    return value[one_node]
TypeError: 'NoneType' object is not subscriptable

During handling of the above exception, another exception occurred:

Traceback (most recent call last):
  File "E:\Project_python\api_cms\common\requests_util.py", line 185, in analysis_yaml
    res = self.send_request(name =name,method=method,
  File "E:\Project_python\api_cms\common\requests_util.py", line 335, in send_request
    error_log("发送请求异常：异常信息: %s" % str(traceback.format_exc()))
  File "E:\Project_python\api_cms\common\logger_util.py", line 66, in error_log
    raise Exception(log_message)
Exception: 发送请求异常：异常信息: Traceback (most recent call last):
  File "E:\Project_python\api_cms\common\requests_util.py", line 309, in send_request
    self.base_url = self.replace_load(self.base_url) + self.replace_load(url)
  File "E:\Project_python\api_cms\common\requests_util.py", line 140, in replace_load
    new_value = getattr(DubugTalk(), func_name)(*args_value.split(','))
  File "E:\Project_python\api_cms\debug_talk.py", line 26, in get_extract_data
    return read_extract_file(node_name)
  File "E:\Project_python\api_cms\common\yaml_util.py", line 19, in read_extract_file
    return value[one_node]
TypeError: 'NoneType' object is not subscriptable


[2023-12-18 11:39:31,310] logger_util.py->error_log line:65 [INFO] 发送请求异常：异常信息: Traceback (most recent call last):
  File "E:\Project_python\api_cms\common\requests_util.py", line 309, in send_request
    self.base_url = self.replace_load(self.base_url) + self.replace_load(url)
  File "E:\Project_python\api_cms\common\requests_util.py", line 140, in replace_load
    new_value = getattr(DubugTalk(), func_name)(*args_value.split(','))
  File "E:\Project_python\api_cms\debug_talk.py", line 26, in get_extract_data
    return read_extract_file(node_name)
  File "E:\Project_python\api_cms\common\yaml_util.py", line 19, in read_extract_file
    return value[one_node]
TypeError: 'NoneType' object is not subscriptable

[2023-12-18 11:39:31,310] logger_util.py->error_log line:65 [INFO] 分析YAML文件异常：异常信息: Traceback (most recent call last):
  File "E:\Project_python\api_cms\common\requests_util.py", line 309, in send_request
    self.base_url = self.replace_load(self.base_url) + self.replace_load(url)
  File "E:\Project_python\api_cms\common\requests_util.py", line 140, in replace_load
    new_value = getattr(DubugTalk(), func_name)(*args_value.split(','))
  File "E:\Project_python\api_cms\debug_talk.py", line 26, in get_extract_data
    return read_extract_file(node_name)
  File "E:\Project_python\api_cms\common\yaml_util.py", line 19, in read_extract_file
    return value[one_node]
TypeError: 'NoneType' object is not subscriptable

During handling of the above exception, another exception occurred:

Traceback (most recent call last):
  File "E:\Project_python\api_cms\common\requests_util.py", line 185, in analysis_yaml
    res = self.send_request(name =name,method=method,
  File "E:\Project_python\api_cms\common\requests_util.py", line 335, in send_request
    error_log("发送请求异常：异常信息: %s" % str(traceback.format_exc()))
  File "E:\Project_python\api_cms\common\logger_util.py", line 66, in error_log
    raise Exception(log_message)
Exception: 发送请求异常：异常信息: Traceback (most recent call last):
  File "E:\Project_python\api_cms\common\requests_util.py", line 309, in send_request
    self.base_url = self.replace_load(self.base_url) + self.replace_load(url)
  File "E:\Project_python\api_cms\common\requests_util.py", line 140, in replace_load
    new_value = getattr(DubugTalk(), func_name)(*args_value.split(','))
  File "E:\Project_python\api_cms\debug_talk.py", line 26, in get_extract_data
    return read_extract_file(node_name)
  File "E:\Project_python\api_cms\common\yaml_util.py", line 19, in read_extract_file
    return value[one_node]
TypeError: 'NoneType' object is not subscriptable


[2023-12-18 11:39:31,355] logger_util.py->error_log line:65 [INFO] 发送请求异常：异常信息: Traceback (most recent call last):
  File "E:\Project_python\api_cms\common\requests_util.py", line 309, in send_request
    self.base_url = self.replace_load(self.base_url) + self.replace_load(url)
  File "E:\Project_python\api_cms\common\requests_util.py", line 140, in replace_load
    new_value = getattr(DubugTalk(), func_name)(*args_value.split(','))
  File "E:\Project_python\api_cms\debug_talk.py", line 26, in get_extract_data
    return read_extract_file(node_name)
  File "E:\Project_python\api_cms\common\yaml_util.py", line 19, in read_extract_file
    return value[one_node]
TypeError: 'NoneType' object is not subscriptable

[2023-12-18 11:39:31,356] logger_util.py->error_log line:65 [INFO] 分析YAML文件异常：异常信息: Traceback (most recent call last):
  File "E:\Project_python\api_cms\common\requests_util.py", line 309, in send_request
    self.base_url = self.replace_load(self.base_url) + self.replace_load(url)
  File "E:\Project_python\api_cms\common\requests_util.py", line 140, in replace_load
    new_value = getattr(DubugTalk(), func_name)(*args_value.split(','))
  File "E:\Project_python\api_cms\debug_talk.py", line 26, in get_extract_data
    return read_extract_file(node_name)
  File "E:\Project_python\api_cms\common\yaml_util.py", line 19, in read_extract_file
    return value[one_node]
TypeError: 'NoneType' object is not subscriptable

During handling of the above exception, another exception occurred:

Traceback (most recent call last):
  File "E:\Project_python\api_cms\common\requests_util.py", line 185, in analysis_yaml
    res = self.send_request(name =name,method=method,
  File "E:\Project_python\api_cms\common\requests_util.py", line 335, in send_request
    error_log("发送请求异常：异常信息: %s" % str(traceback.format_exc()))
  File "E:\Project_python\api_cms\common\logger_util.py", line 66, in error_log
    raise Exception(log_message)
Exception: 发送请求异常：异常信息: Traceback (most recent call last):
  File "E:\Project_python\api_cms\common\requests_util.py", line 309, in send_request
    self.base_url = self.replace_load(self.base_url) + self.replace_load(url)
  File "E:\Project_python\api_cms\common\requests_util.py", line 140, in replace_load
    new_value = getattr(DubugTalk(), func_name)(*args_value.split(','))
  File "E:\Project_python\api_cms\debug_talk.py", line 26, in get_extract_data
    return read_extract_file(node_name)
  File "E:\Project_python\api_cms\common\yaml_util.py", line 19, in read_extract_file
    return value[one_node]
TypeError: 'NoneType' object is not subscriptable


[2023-12-18 11:39:31,401] logger_util.py->write_log line:61 [INFO] 
-------------接口请求开始-----------
[2023-12-18 11:39:31,401] logger_util.py->write_log line:61 [INFO] 接口名称：下发A2=70
[2023-12-18 11:39:31,401] logger_util.py->write_log line:61 [INFO] 接口方式：post
[2023-12-18 11:39:31,401] logger_util.py->write_log line:61 [INFO] 接口路径：http://127.0.0.1:18000/api/v1/variable/setvalues
[2023-12-18 11:39:31,401] logger_util.py->write_log line:61 [INFO] 请求头：{'X-Project': 'fb63700a195245b9bb42ef9e036ce674', 'Authorization': 'Bearer eyJhbGciOiJIUzI1NiIsInR5cCI6IkpXVCJ9.eyJodHRwOi8vc2NoZW1hcy54bWxzb2FwLm9yZy93cy8yMDA1LzA1L2lkZW50aXR5L2NsYWltcy9uYW1lIjoiU3VwZXJBZG1pbiIsImh0dHA6Ly9zY2hlbWFzLnhtbHNvYXAub3JnL3dzLzIwMDUvMDUvaWRlbnRpdHkvY2xhaW1zL25hbWVpZGVudGlmaWVyIjoiU3VwZXJBZG1pbiIsImV4cCI6MTcwMjk0OTM5MiwiaXNzIjoiQ01TdjIiLCJhdWQiOiJBcGkifQ.DTE3ExRd5e35qx7qyEGhaNLjjzP8QxhHUoLCzYg7Hcc'}
[2023-12-18 11:39:31,401] logger_util.py->write_log line:61 [INFO] 请求参数：{'A2': '70'}
[2023-12-18 11:39:31,401] logger_util.py->write_log line:61 [INFO] 文件上传：None
[2023-12-18 11:39:31,403] logger_util.py->error_log line:65 [INFO] 断言失败:status_code不等于200
[2023-12-18 11:39:31,403] logger_util.py->write_log line:61 [INFO] 实际结果：{'code': 409, 'msg': 'Projcet Conflict'}
[2023-12-18 11:39:31,403] logger_util.py->write_log line:61 [INFO] 接口请求失败！
[2023-12-18 11:39:31,403] logger_util.py->write_log line:61 [INFO] -------------接口请求结束-----------

[2023-12-18 11:39:31,404] logger_util.py->error_log line:65 [INFO] 断言异常：异常信息: Traceback (most recent call last):
  File "E:\Project_python\api_cms\common\requests_util.py", line 368, in validate_result
    error_log("断言失败:"+assert_key+"不等于"+str(assert_value))
  File "E:\Project_python\api_cms\common\logger_util.py", line 66, in error_log
    raise Exception(log_message)
Exception: 断言失败:status_code不等于200

[2023-12-18 11:39:31,404] logger_util.py->error_log line:65 [INFO] 分析YAML文件异常：异常信息: Traceback (most recent call last):
  File "E:\Project_python\api_cms\common\requests_util.py", line 368, in validate_result
    error_log("断言失败:"+assert_key+"不等于"+str(assert_value))
  File "E:\Project_python\api_cms\common\logger_util.py", line 66, in error_log
    raise Exception(log_message)
Exception: 断言失败:status_code不等于200

During handling of the above exception, another exception occurred:

Traceback (most recent call last):
  File "E:\Project_python\api_cms\common\requests_util.py", line 248, in analysis_yaml
    self.validate_result(yq_result, return_data, status_code)
  File "E:\Project_python\api_cms\common\requests_util.py", line 448, in validate_result
    error_log("断言异常：异常信息: %s" % str(traceback.format_exc()))
  File "E:\Project_python\api_cms\common\logger_util.py", line 66, in error_log
    raise Exception(log_message)
Exception: 断言异常：异常信息: Traceback (most recent call last):
  File "E:\Project_python\api_cms\common\requests_util.py", line 368, in validate_result
    error_log("断言失败:"+assert_key+"不等于"+str(assert_value))
  File "E:\Project_python\api_cms\common\logger_util.py", line 66, in error_log
    raise Exception(log_message)
Exception: 断言失败:status_code不等于200


[2023-12-18 11:39:31,445] logger_util.py->write_log line:61 [INFO] 
-------------接口请求开始-----------
[2023-12-18 11:39:31,445] logger_util.py->write_log line:61 [INFO] 接口名称：下发A10=70.456
[2023-12-18 11:39:31,446] logger_util.py->write_log line:61 [INFO] 接口方式：post
[2023-12-18 11:39:31,446] logger_util.py->write_log line:61 [INFO] 接口路径：http://127.0.0.1:18000/api/v1/variable/setvalues
[2023-12-18 11:39:31,446] logger_util.py->write_log line:61 [INFO] 请求头：{'X-Project': 'fb63700a195245b9bb42ef9e036ce674', 'Authorization': 'Bearer eyJhbGciOiJIUzI1NiIsInR5cCI6IkpXVCJ9.eyJodHRwOi8vc2NoZW1hcy54bWxzb2FwLm9yZy93cy8yMDA1LzA1L2lkZW50aXR5L2NsYWltcy9uYW1lIjoiU3VwZXJBZG1pbiIsImh0dHA6Ly9zY2hlbWFzLnhtbHNvYXAub3JnL3dzLzIwMDUvMDUvaWRlbnRpdHkvY2xhaW1zL25hbWVpZGVudGlmaWVyIjoiU3VwZXJBZG1pbiIsImV4cCI6MTcwMjk0OTM5MiwiaXNzIjoiQ01TdjIiLCJhdWQiOiJBcGkifQ.DTE3ExRd5e35qx7qyEGhaNLjjzP8QxhHUoLCzYg7Hcc'}
[2023-12-18 11:39:31,446] logger_util.py->write_log line:61 [INFO] 请求参数：{'A10': '70.456'}
[2023-12-18 11:39:31,446] logger_util.py->write_log line:61 [INFO] 文件上传：None
[2023-12-18 11:39:31,448] logger_util.py->error_log line:65 [INFO] 断言失败:status_code不等于200
[2023-12-18 11:39:31,448] logger_util.py->write_log line:61 [INFO] 实际结果：{'code': 409, 'msg': 'Projcet Conflict'}
[2023-12-18 11:39:31,448] logger_util.py->write_log line:61 [INFO] 接口请求失败！
[2023-12-18 11:39:31,448] logger_util.py->write_log line:61 [INFO] -------------接口请求结束-----------

[2023-12-18 11:39:31,448] logger_util.py->error_log line:65 [INFO] 断言异常：异常信息: Traceback (most recent call last):
  File "E:\Project_python\api_cms\common\requests_util.py", line 368, in validate_result
    error_log("断言失败:"+assert_key+"不等于"+str(assert_value))
  File "E:\Project_python\api_cms\common\logger_util.py", line 66, in error_log
    raise Exception(log_message)
Exception: 断言失败:status_code不等于200

[2023-12-18 11:39:31,449] logger_util.py->error_log line:65 [INFO] 分析YAML文件异常：异常信息: Traceback (most recent call last):
  File "E:\Project_python\api_cms\common\requests_util.py", line 368, in validate_result
    error_log("断言失败:"+assert_key+"不等于"+str(assert_value))
  File "E:\Project_python\api_cms\common\logger_util.py", line 66, in error_log
    raise Exception(log_message)
Exception: 断言失败:status_code不等于200

During handling of the above exception, another exception occurred:

Traceback (most recent call last):
  File "E:\Project_python\api_cms\common\requests_util.py", line 248, in analysis_yaml
    self.validate_result(yq_result, return_data, status_code)
  File "E:\Project_python\api_cms\common\requests_util.py", line 448, in validate_result
    error_log("断言异常：异常信息: %s" % str(traceback.format_exc()))
  File "E:\Project_python\api_cms\common\logger_util.py", line 66, in error_log
    raise Exception(log_message)
Exception: 断言异常：异常信息: Traceback (most recent call last):
  File "E:\Project_python\api_cms\common\requests_util.py", line 368, in validate_result
    error_log("断言失败:"+assert_key+"不等于"+str(assert_value))
  File "E:\Project_python\api_cms\common\logger_util.py", line 66, in error_log
    raise Exception(log_message)
Exception: 断言失败:status_code不等于200


[2023-12-18 11:39:31,491] logger_util.py->write_log line:61 [INFO] 
-------------接口请求开始-----------
[2023-12-18 11:39:31,491] logger_util.py->write_log line:61 [INFO] 接口名称：下发A12=中文1
[2023-12-18 11:39:31,491] logger_util.py->write_log line:61 [INFO] 接口方式：post
[2023-12-18 11:39:31,492] logger_util.py->write_log line:61 [INFO] 接口路径：http://127.0.0.1:18000/api/v1/variable/setvalues
[2023-12-18 11:39:31,492] logger_util.py->write_log line:61 [INFO] 请求头：{'X-Project': 'fb63700a195245b9bb42ef9e036ce674', 'Authorization': 'Bearer eyJhbGciOiJIUzI1NiIsInR5cCI6IkpXVCJ9.eyJodHRwOi8vc2NoZW1hcy54bWxzb2FwLm9yZy93cy8yMDA1LzA1L2lkZW50aXR5L2NsYWltcy9uYW1lIjoiU3VwZXJBZG1pbiIsImh0dHA6Ly9zY2hlbWFzLnhtbHNvYXAub3JnL3dzLzIwMDUvMDUvaWRlbnRpdHkvY2xhaW1zL25hbWVpZGVudGlmaWVyIjoiU3VwZXJBZG1pbiIsImV4cCI6MTcwMjk0OTM5MiwiaXNzIjoiQ01TdjIiLCJhdWQiOiJBcGkifQ.DTE3ExRd5e35qx7qyEGhaNLjjzP8QxhHUoLCzYg7Hcc'}
[2023-12-18 11:39:31,492] logger_util.py->write_log line:61 [INFO] 请求参数：{'A12': '中文1'}
[2023-12-18 11:39:31,492] logger_util.py->write_log line:61 [INFO] 文件上传：None
[2023-12-18 11:39:31,494] logger_util.py->error_log line:65 [INFO] 断言失败:status_code不等于200
[2023-12-18 11:39:31,494] logger_util.py->write_log line:61 [INFO] 实际结果：{'code': 409, 'msg': 'Projcet Conflict'}
[2023-12-18 11:39:31,494] logger_util.py->write_log line:61 [INFO] 接口请求失败！
[2023-12-18 11:39:31,494] logger_util.py->write_log line:61 [INFO] -------------接口请求结束-----------

[2023-12-18 11:39:31,494] logger_util.py->error_log line:65 [INFO] 断言异常：异常信息: Traceback (most recent call last):
  File "E:\Project_python\api_cms\common\requests_util.py", line 368, in validate_result
    error_log("断言失败:"+assert_key+"不等于"+str(assert_value))
  File "E:\Project_python\api_cms\common\logger_util.py", line 66, in error_log
    raise Exception(log_message)
Exception: 断言失败:status_code不等于200

[2023-12-18 11:39:31,495] logger_util.py->error_log line:65 [INFO] 分析YAML文件异常：异常信息: Traceback (most recent call last):
  File "E:\Project_python\api_cms\common\requests_util.py", line 368, in validate_result
    error_log("断言失败:"+assert_key+"不等于"+str(assert_value))
  File "E:\Project_python\api_cms\common\logger_util.py", line 66, in error_log
    raise Exception(log_message)
Exception: 断言失败:status_code不等于200

During handling of the above exception, another exception occurred:

Traceback (most recent call last):
  File "E:\Project_python\api_cms\common\requests_util.py", line 248, in analysis_yaml
    self.validate_result(yq_result, return_data, status_code)
  File "E:\Project_python\api_cms\common\requests_util.py", line 448, in validate_result
    error_log("断言异常：异常信息: %s" % str(traceback.format_exc()))
  File "E:\Project_python\api_cms\common\logger_util.py", line 66, in error_log
    raise Exception(log_message)
Exception: 断言异常：异常信息: Traceback (most recent call last):
  File "E:\Project_python\api_cms\common\requests_util.py", line 368, in validate_result
    error_log("断言失败:"+assert_key+"不等于"+str(assert_value))
  File "E:\Project_python\api_cms\common\logger_util.py", line 66, in error_log
    raise Exception(log_message)
Exception: 断言失败:status_code不等于200


[2023-12-18 11:39:31,537] logger_util.py->write_log line:61 [INFO] 
-------------接口请求开始-----------
[2023-12-18 11:39:31,538] logger_util.py->write_log line:61 [INFO] 接口名称：下发aa16=2022-11-28 09:05:01
[2023-12-18 11:39:31,538] logger_util.py->write_log line:61 [INFO] 接口方式：post
[2023-12-18 11:39:31,538] logger_util.py->write_log line:61 [INFO] 接口路径：http://127.0.0.1:18000/api/v1/variable/setvalues
[2023-12-18 11:39:31,538] logger_util.py->write_log line:61 [INFO] 请求头：{'X-Project': 'fb63700a195245b9bb42ef9e036ce674', 'Authorization': 'Bearer eyJhbGciOiJIUzI1NiIsInR5cCI6IkpXVCJ9.eyJodHRwOi8vc2NoZW1hcy54bWxzb2FwLm9yZy93cy8yMDA1LzA1L2lkZW50aXR5L2NsYWltcy9uYW1lIjoiU3VwZXJBZG1pbiIsImh0dHA6Ly9zY2hlbWFzLnhtbHNvYXAub3JnL3dzLzIwMDUvMDUvaWRlbnRpdHkvY2xhaW1zL25hbWVpZGVudGlmaWVyIjoiU3VwZXJBZG1pbiIsImV4cCI6MTcwMjk0OTM5MiwiaXNzIjoiQ01TdjIiLCJhdWQiOiJBcGkifQ.DTE3ExRd5e35qx7qyEGhaNLjjzP8QxhHUoLCzYg7Hcc'}
[2023-12-18 11:39:31,538] logger_util.py->write_log line:61 [INFO] 请求参数：{'aa16': '2022-11-28 09:05:01'}
[2023-12-18 11:39:31,538] logger_util.py->write_log line:61 [INFO] 文件上传：None
[2023-12-18 11:39:31,539] logger_util.py->error_log line:65 [INFO] 断言失败:status_code不等于200
[2023-12-18 11:39:31,539] logger_util.py->write_log line:61 [INFO] 实际结果：{'code': 409, 'msg': 'Projcet Conflict'}
[2023-12-18 11:39:31,539] logger_util.py->write_log line:61 [INFO] 接口请求失败！
[2023-12-18 11:39:31,539] logger_util.py->write_log line:61 [INFO] -------------接口请求结束-----------

[2023-12-18 11:39:31,540] logger_util.py->error_log line:65 [INFO] 断言异常：异常信息: Traceback (most recent call last):
  File "E:\Project_python\api_cms\common\requests_util.py", line 368, in validate_result
    error_log("断言失败:"+assert_key+"不等于"+str(assert_value))
  File "E:\Project_python\api_cms\common\logger_util.py", line 66, in error_log
    raise Exception(log_message)
Exception: 断言失败:status_code不等于200

[2023-12-18 11:39:31,540] logger_util.py->error_log line:65 [INFO] 分析YAML文件异常：异常信息: Traceback (most recent call last):
  File "E:\Project_python\api_cms\common\requests_util.py", line 368, in validate_result
    error_log("断言失败:"+assert_key+"不等于"+str(assert_value))
  File "E:\Project_python\api_cms\common\logger_util.py", line 66, in error_log
    raise Exception(log_message)
Exception: 断言失败:status_code不等于200

During handling of the above exception, another exception occurred:

Traceback (most recent call last):
  File "E:\Project_python\api_cms\common\requests_util.py", line 248, in analysis_yaml
    self.validate_result(yq_result, return_data, status_code)
  File "E:\Project_python\api_cms\common\requests_util.py", line 448, in validate_result
    error_log("断言异常：异常信息: %s" % str(traceback.format_exc()))
  File "E:\Project_python\api_cms\common\logger_util.py", line 66, in error_log
    raise Exception(log_message)
Exception: 断言异常：异常信息: Traceback (most recent call last):
  File "E:\Project_python\api_cms\common\requests_util.py", line 368, in validate_result
    error_log("断言失败:"+assert_key+"不等于"+str(assert_value))
  File "E:\Project_python\api_cms\common\logger_util.py", line 66, in error_log
    raise Exception(log_message)
Exception: 断言失败:status_code不等于200


[2023-12-18 11:39:31,578] logger_util.py->error_log line:65 [INFO] 发送请求异常：异常信息: Traceback (most recent call last):
  File "E:\Project_python\api_cms\common\requests_util.py", line 309, in send_request
    self.base_url = self.replace_load(self.base_url) + self.replace_load(url)
  File "E:\Project_python\api_cms\common\requests_util.py", line 140, in replace_load
    new_value = getattr(DubugTalk(), func_name)(*args_value.split(','))
  File "E:\Project_python\api_cms\debug_talk.py", line 26, in get_extract_data
    return read_extract_file(node_name)
  File "E:\Project_python\api_cms\common\yaml_util.py", line 19, in read_extract_file
    return value[one_node]
TypeError: 'NoneType' object is not subscriptable

[2023-12-18 11:39:31,578] logger_util.py->error_log line:65 [INFO] 分析YAML文件异常：异常信息: Traceback (most recent call last):
  File "E:\Project_python\api_cms\common\requests_util.py", line 309, in send_request
    self.base_url = self.replace_load(self.base_url) + self.replace_load(url)
  File "E:\Project_python\api_cms\common\requests_util.py", line 140, in replace_load
    new_value = getattr(DubugTalk(), func_name)(*args_value.split(','))
  File "E:\Project_python\api_cms\debug_talk.py", line 26, in get_extract_data
    return read_extract_file(node_name)
  File "E:\Project_python\api_cms\common\yaml_util.py", line 19, in read_extract_file
    return value[one_node]
TypeError: 'NoneType' object is not subscriptable

During handling of the above exception, another exception occurred:

Traceback (most recent call last):
  File "E:\Project_python\api_cms\common\requests_util.py", line 185, in analysis_yaml
    res = self.send_request(name =name,method=method,
  File "E:\Project_python\api_cms\common\requests_util.py", line 335, in send_request
    error_log("发送请求异常：异常信息: %s" % str(traceback.format_exc()))
  File "E:\Project_python\api_cms\common\logger_util.py", line 66, in error_log
    raise Exception(log_message)
Exception: 发送请求异常：异常信息: Traceback (most recent call last):
  File "E:\Project_python\api_cms\common\requests_util.py", line 309, in send_request
    self.base_url = self.replace_load(self.base_url) + self.replace_load(url)
  File "E:\Project_python\api_cms\common\requests_util.py", line 140, in replace_load
    new_value = getattr(DubugTalk(), func_name)(*args_value.split(','))
  File "E:\Project_python\api_cms\debug_talk.py", line 26, in get_extract_data
    return read_extract_file(node_name)
  File "E:\Project_python\api_cms\common\yaml_util.py", line 19, in read_extract_file
    return value[one_node]
TypeError: 'NoneType' object is not subscriptable


[2023-12-18 11:39:31,619] logger_util.py->error_log line:65 [INFO] 发送请求异常：异常信息: Traceback (most recent call last):
  File "E:\Project_python\api_cms\common\requests_util.py", line 309, in send_request
    self.base_url = self.replace_load(self.base_url) + self.replace_load(url)
  File "E:\Project_python\api_cms\common\requests_util.py", line 140, in replace_load
    new_value = getattr(DubugTalk(), func_name)(*args_value.split(','))
  File "E:\Project_python\api_cms\debug_talk.py", line 26, in get_extract_data
    return read_extract_file(node_name)
  File "E:\Project_python\api_cms\common\yaml_util.py", line 19, in read_extract_file
    return value[one_node]
TypeError: 'NoneType' object is not subscriptable

[2023-12-18 11:39:31,619] logger_util.py->error_log line:65 [INFO] 分析YAML文件异常：异常信息: Traceback (most recent call last):
  File "E:\Project_python\api_cms\common\requests_util.py", line 309, in send_request
    self.base_url = self.replace_load(self.base_url) + self.replace_load(url)
  File "E:\Project_python\api_cms\common\requests_util.py", line 140, in replace_load
    new_value = getattr(DubugTalk(), func_name)(*args_value.split(','))
  File "E:\Project_python\api_cms\debug_talk.py", line 26, in get_extract_data
    return read_extract_file(node_name)
  File "E:\Project_python\api_cms\common\yaml_util.py", line 19, in read_extract_file
    return value[one_node]
TypeError: 'NoneType' object is not subscriptable

During handling of the above exception, another exception occurred:

Traceback (most recent call last):
  File "E:\Project_python\api_cms\common\requests_util.py", line 185, in analysis_yaml
    res = self.send_request(name =name,method=method,
  File "E:\Project_python\api_cms\common\requests_util.py", line 335, in send_request
    error_log("发送请求异常：异常信息: %s" % str(traceback.format_exc()))
  File "E:\Project_python\api_cms\common\logger_util.py", line 66, in error_log
    raise Exception(log_message)
Exception: 发送请求异常：异常信息: Traceback (most recent call last):
  File "E:\Project_python\api_cms\common\requests_util.py", line 309, in send_request
    self.base_url = self.replace_load(self.base_url) + self.replace_load(url)
  File "E:\Project_python\api_cms\common\requests_util.py", line 140, in replace_load
    new_value = getattr(DubugTalk(), func_name)(*args_value.split(','))
  File "E:\Project_python\api_cms\debug_talk.py", line 26, in get_extract_data
    return read_extract_file(node_name)
  File "E:\Project_python\api_cms\common\yaml_util.py", line 19, in read_extract_file
    return value[one_node]
TypeError: 'NoneType' object is not subscriptable


[2023-12-18 11:39:31,660] logger_util.py->error_log line:65 [INFO] 发送请求异常：异常信息: Traceback (most recent call last):
  File "E:\Project_python\api_cms\common\requests_util.py", line 309, in send_request
    self.base_url = self.replace_load(self.base_url) + self.replace_load(url)
  File "E:\Project_python\api_cms\common\requests_util.py", line 140, in replace_load
    new_value = getattr(DubugTalk(), func_name)(*args_value.split(','))
  File "E:\Project_python\api_cms\debug_talk.py", line 26, in get_extract_data
    return read_extract_file(node_name)
  File "E:\Project_python\api_cms\common\yaml_util.py", line 19, in read_extract_file
    return value[one_node]
TypeError: 'NoneType' object is not subscriptable

[2023-12-18 11:39:31,661] logger_util.py->error_log line:65 [INFO] 分析YAML文件异常：异常信息: Traceback (most recent call last):
  File "E:\Project_python\api_cms\common\requests_util.py", line 309, in send_request
    self.base_url = self.replace_load(self.base_url) + self.replace_load(url)
  File "E:\Project_python\api_cms\common\requests_util.py", line 140, in replace_load
    new_value = getattr(DubugTalk(), func_name)(*args_value.split(','))
  File "E:\Project_python\api_cms\debug_talk.py", line 26, in get_extract_data
    return read_extract_file(node_name)
  File "E:\Project_python\api_cms\common\yaml_util.py", line 19, in read_extract_file
    return value[one_node]
TypeError: 'NoneType' object is not subscriptable

During handling of the above exception, another exception occurred:

Traceback (most recent call last):
  File "E:\Project_python\api_cms\common\requests_util.py", line 185, in analysis_yaml
    res = self.send_request(name =name,method=method,
  File "E:\Project_python\api_cms\common\requests_util.py", line 335, in send_request
    error_log("发送请求异常：异常信息: %s" % str(traceback.format_exc()))
  File "E:\Project_python\api_cms\common\logger_util.py", line 66, in error_log
    raise Exception(log_message)
Exception: 发送请求异常：异常信息: Traceback (most recent call last):
  File "E:\Project_python\api_cms\common\requests_util.py", line 309, in send_request
    self.base_url = self.replace_load(self.base_url) + self.replace_load(url)
  File "E:\Project_python\api_cms\common\requests_util.py", line 140, in replace_load
    new_value = getattr(DubugTalk(), func_name)(*args_value.split(','))
  File "E:\Project_python\api_cms\debug_talk.py", line 26, in get_extract_data
    return read_extract_file(node_name)
  File "E:\Project_python\api_cms\common\yaml_util.py", line 19, in read_extract_file
    return value[one_node]
TypeError: 'NoneType' object is not subscriptable


[2023-12-18 11:39:31,718] logger_util.py->error_log line:65 [INFO] 发送请求异常：异常信息: Traceback (most recent call last):
  File "E:\Project_python\api_cms\common\requests_util.py", line 309, in send_request
    self.base_url = self.replace_load(self.base_url) + self.replace_load(url)
  File "E:\Project_python\api_cms\common\requests_util.py", line 140, in replace_load
    new_value = getattr(DubugTalk(), func_name)(*args_value.split(','))
  File "E:\Project_python\api_cms\debug_talk.py", line 26, in get_extract_data
    return read_extract_file(node_name)
  File "E:\Project_python\api_cms\common\yaml_util.py", line 19, in read_extract_file
    return value[one_node]
TypeError: 'NoneType' object is not subscriptable

[2023-12-18 11:39:31,718] logger_util.py->error_log line:65 [INFO] 分析YAML文件异常：异常信息: Traceback (most recent call last):
  File "E:\Project_python\api_cms\common\requests_util.py", line 309, in send_request
    self.base_url = self.replace_load(self.base_url) + self.replace_load(url)
  File "E:\Project_python\api_cms\common\requests_util.py", line 140, in replace_load
    new_value = getattr(DubugTalk(), func_name)(*args_value.split(','))
  File "E:\Project_python\api_cms\debug_talk.py", line 26, in get_extract_data
    return read_extract_file(node_name)
  File "E:\Project_python\api_cms\common\yaml_util.py", line 19, in read_extract_file
    return value[one_node]
TypeError: 'NoneType' object is not subscriptable

During handling of the above exception, another exception occurred:

Traceback (most recent call last):
  File "E:\Project_python\api_cms\common\requests_util.py", line 185, in analysis_yaml
    res = self.send_request(name =name,method=method,
  File "E:\Project_python\api_cms\common\requests_util.py", line 335, in send_request
    error_log("发送请求异常：异常信息: %s" % str(traceback.format_exc()))
  File "E:\Project_python\api_cms\common\logger_util.py", line 66, in error_log
    raise Exception(log_message)
Exception: 发送请求异常：异常信息: Traceback (most recent call last):
  File "E:\Project_python\api_cms\common\requests_util.py", line 309, in send_request
    self.base_url = self.replace_load(self.base_url) + self.replace_load(url)
  File "E:\Project_python\api_cms\common\requests_util.py", line 140, in replace_load
    new_value = getattr(DubugTalk(), func_name)(*args_value.split(','))
  File "E:\Project_python\api_cms\debug_talk.py", line 26, in get_extract_data
    return read_extract_file(node_name)
  File "E:\Project_python\api_cms\common\yaml_util.py", line 19, in read_extract_file
    return value[one_node]
TypeError: 'NoneType' object is not subscriptable


[2023-12-18 11:39:31,857] logger_util.py->write_log line:61 [INFO] 
-------------接口请求开始-----------
[2023-12-18 11:39:31,858] logger_util.py->write_log line:61 [INFO] 接口名称：下发A2=77
[2023-12-18 11:39:31,858] logger_util.py->write_log line:61 [INFO] 接口方式：post
[2023-12-18 11:39:31,858] logger_util.py->write_log line:61 [INFO] 接口路径：http://127.0.0.1:18000/api/v1/variable/setvalues
[2023-12-18 11:39:31,858] logger_util.py->write_log line:61 [INFO] 请求头：{'X-Project': 'fb63700a195245b9bb42ef9e036ce674', 'Authorization': 'Bearer eyJhbGciOiJIUzI1NiIsInR5cCI6IkpXVCJ9.eyJodHRwOi8vc2NoZW1hcy54bWxzb2FwLm9yZy93cy8yMDA1LzA1L2lkZW50aXR5L2NsYWltcy9uYW1lIjoiU3VwZXJBZG1pbiIsImh0dHA6Ly9zY2hlbWFzLnhtbHNvYXAub3JnL3dzLzIwMDUvMDUvaWRlbnRpdHkvY2xhaW1zL25hbWVpZGVudGlmaWVyIjoiU3VwZXJBZG1pbiIsImV4cCI6MTcwMjk0OTM5MiwiaXNzIjoiQ01TdjIiLCJhdWQiOiJBcGkifQ.DTE3ExRd5e35qx7qyEGhaNLjjzP8QxhHUoLCzYg7Hcc'}
[2023-12-18 11:39:31,858] logger_util.py->write_log line:61 [INFO] 请求参数：{'A2': '77'}
[2023-12-18 11:39:31,858] logger_util.py->write_log line:61 [INFO] 文件上传：None
[2023-12-18 11:39:31,860] logger_util.py->error_log line:65 [INFO] 断言失败:status_code不等于200
[2023-12-18 11:39:31,860] logger_util.py->write_log line:61 [INFO] 实际结果：{'code': 409, 'msg': 'Projcet Conflict'}
[2023-12-18 11:39:31,860] logger_util.py->write_log line:61 [INFO] 接口请求失败！
[2023-12-18 11:39:31,860] logger_util.py->write_log line:61 [INFO] -------------接口请求结束-----------

[2023-12-18 11:39:31,860] logger_util.py->error_log line:65 [INFO] 断言异常：异常信息: Traceback (most recent call last):
  File "E:\Project_python\api_cms\common\requests_util.py", line 368, in validate_result
    error_log("断言失败:"+assert_key+"不等于"+str(assert_value))
  File "E:\Project_python\api_cms\common\logger_util.py", line 66, in error_log
    raise Exception(log_message)
Exception: 断言失败:status_code不等于200

[2023-12-18 11:39:31,861] logger_util.py->error_log line:65 [INFO] 分析YAML文件异常：异常信息: Traceback (most recent call last):
  File "E:\Project_python\api_cms\common\requests_util.py", line 368, in validate_result
    error_log("断言失败:"+assert_key+"不等于"+str(assert_value))
  File "E:\Project_python\api_cms\common\logger_util.py", line 66, in error_log
    raise Exception(log_message)
Exception: 断言失败:status_code不等于200

During handling of the above exception, another exception occurred:

Traceback (most recent call last):
  File "E:\Project_python\api_cms\common\requests_util.py", line 248, in analysis_yaml
    self.validate_result(yq_result, return_data, status_code)
  File "E:\Project_python\api_cms\common\requests_util.py", line 448, in validate_result
    error_log("断言异常：异常信息: %s" % str(traceback.format_exc()))
  File "E:\Project_python\api_cms\common\logger_util.py", line 66, in error_log
    raise Exception(log_message)
Exception: 断言异常：异常信息: Traceback (most recent call last):
  File "E:\Project_python\api_cms\common\requests_util.py", line 368, in validate_result
    error_log("断言失败:"+assert_key+"不等于"+str(assert_value))
  File "E:\Project_python\api_cms\common\logger_util.py", line 66, in error_log
    raise Exception(log_message)
Exception: 断言失败:status_code不等于200


[2023-12-18 11:39:32,002] logger_util.py->write_log line:61 [INFO] 
-------------接口请求开始-----------
[2023-12-18 11:39:32,003] logger_util.py->write_log line:61 [INFO] 接口名称：下发A10=77.456
[2023-12-18 11:39:32,003] logger_util.py->write_log line:61 [INFO] 接口方式：post
[2023-12-18 11:39:32,003] logger_util.py->write_log line:61 [INFO] 接口路径：http://127.0.0.1:18000/api/v1/variable/setvalues
[2023-12-18 11:39:32,003] logger_util.py->write_log line:61 [INFO] 请求头：{'X-Project': 'fb63700a195245b9bb42ef9e036ce674', 'Authorization': 'Bearer eyJhbGciOiJIUzI1NiIsInR5cCI6IkpXVCJ9.eyJodHRwOi8vc2NoZW1hcy54bWxzb2FwLm9yZy93cy8yMDA1LzA1L2lkZW50aXR5L2NsYWltcy9uYW1lIjoiU3VwZXJBZG1pbiIsImh0dHA6Ly9zY2hlbWFzLnhtbHNvYXAub3JnL3dzLzIwMDUvMDUvaWRlbnRpdHkvY2xhaW1zL25hbWVpZGVudGlmaWVyIjoiU3VwZXJBZG1pbiIsImV4cCI6MTcwMjk0OTM5MiwiaXNzIjoiQ01TdjIiLCJhdWQiOiJBcGkifQ.DTE3ExRd5e35qx7qyEGhaNLjjzP8QxhHUoLCzYg7Hcc'}
[2023-12-18 11:39:32,003] logger_util.py->write_log line:61 [INFO] 请求参数：{'A10': '77.456'}
[2023-12-18 11:39:32,003] logger_util.py->write_log line:61 [INFO] 文件上传：None
[2023-12-18 11:39:32,005] logger_util.py->error_log line:65 [INFO] 断言失败:status_code不等于200
[2023-12-18 11:39:32,005] logger_util.py->write_log line:61 [INFO] 实际结果：{'code': 409, 'msg': 'Projcet Conflict'}
[2023-12-18 11:39:32,005] logger_util.py->write_log line:61 [INFO] 接口请求失败！
[2023-12-18 11:39:32,005] logger_util.py->write_log line:61 [INFO] -------------接口请求结束-----------

[2023-12-18 11:39:32,006] logger_util.py->error_log line:65 [INFO] 断言异常：异常信息: Traceback (most recent call last):
  File "E:\Project_python\api_cms\common\requests_util.py", line 368, in validate_result
    error_log("断言失败:"+assert_key+"不等于"+str(assert_value))
  File "E:\Project_python\api_cms\common\logger_util.py", line 66, in error_log
    raise Exception(log_message)
Exception: 断言失败:status_code不等于200

[2023-12-18 11:39:32,006] logger_util.py->error_log line:65 [INFO] 分析YAML文件异常：异常信息: Traceback (most recent call last):
  File "E:\Project_python\api_cms\common\requests_util.py", line 368, in validate_result
    error_log("断言失败:"+assert_key+"不等于"+str(assert_value))
  File "E:\Project_python\api_cms\common\logger_util.py", line 66, in error_log
    raise Exception(log_message)
Exception: 断言失败:status_code不等于200

During handling of the above exception, another exception occurred:

Traceback (most recent call last):
  File "E:\Project_python\api_cms\common\requests_util.py", line 248, in analysis_yaml
    self.validate_result(yq_result, return_data, status_code)
  File "E:\Project_python\api_cms\common\requests_util.py", line 448, in validate_result
    error_log("断言异常：异常信息: %s" % str(traceback.format_exc()))
  File "E:\Project_python\api_cms\common\logger_util.py", line 66, in error_log
    raise Exception(log_message)
Exception: 断言异常：异常信息: Traceback (most recent call last):
  File "E:\Project_python\api_cms\common\requests_util.py", line 368, in validate_result
    error_log("断言失败:"+assert_key+"不等于"+str(assert_value))
  File "E:\Project_python\api_cms\common\logger_util.py", line 66, in error_log
    raise Exception(log_message)
Exception: 断言失败:status_code不等于200


[2023-12-18 11:39:32,166] logger_util.py->write_log line:61 [INFO] 
-------------接口请求开始-----------
[2023-12-18 11:39:32,166] logger_util.py->write_log line:61 [INFO] 接口名称：下发A12=中文1
[2023-12-18 11:39:32,166] logger_util.py->write_log line:61 [INFO] 接口方式：post
[2023-12-18 11:39:32,167] logger_util.py->write_log line:61 [INFO] 接口路径：http://127.0.0.1:18000/api/v1/variable/setvalues
[2023-12-18 11:39:32,167] logger_util.py->write_log line:61 [INFO] 请求头：{'X-Project': 'fb63700a195245b9bb42ef9e036ce674', 'Authorization': 'Bearer eyJhbGciOiJIUzI1NiIsInR5cCI6IkpXVCJ9.eyJodHRwOi8vc2NoZW1hcy54bWxzb2FwLm9yZy93cy8yMDA1LzA1L2lkZW50aXR5L2NsYWltcy9uYW1lIjoiU3VwZXJBZG1pbiIsImh0dHA6Ly9zY2hlbWFzLnhtbHNvYXAub3JnL3dzLzIwMDUvMDUvaWRlbnRpdHkvY2xhaW1zL25hbWVpZGVudGlmaWVyIjoiU3VwZXJBZG1pbiIsImV4cCI6MTcwMjk0OTM5MiwiaXNzIjoiQ01TdjIiLCJhdWQiOiJBcGkifQ.DTE3ExRd5e35qx7qyEGhaNLjjzP8QxhHUoLCzYg7Hcc'}
[2023-12-18 11:39:32,167] logger_util.py->write_log line:61 [INFO] 请求参数：{'A12': '中文1'}
[2023-12-18 11:39:32,167] logger_util.py->write_log line:61 [INFO] 文件上传：None
[2023-12-18 11:39:32,169] logger_util.py->error_log line:65 [INFO] 断言失败:status_code不等于200
[2023-12-18 11:39:32,169] logger_util.py->write_log line:61 [INFO] 实际结果：{'code': 409, 'msg': 'Projcet Conflict'}
[2023-12-18 11:39:32,169] logger_util.py->write_log line:61 [INFO] 接口请求失败！
[2023-12-18 11:39:32,169] logger_util.py->write_log line:61 [INFO] -------------接口请求结束-----------

[2023-12-18 11:39:32,170] logger_util.py->error_log line:65 [INFO] 断言异常：异常信息: Traceback (most recent call last):
  File "E:\Project_python\api_cms\common\requests_util.py", line 368, in validate_result
    error_log("断言失败:"+assert_key+"不等于"+str(assert_value))
  File "E:\Project_python\api_cms\common\logger_util.py", line 66, in error_log
    raise Exception(log_message)
Exception: 断言失败:status_code不等于200

[2023-12-18 11:39:32,170] logger_util.py->error_log line:65 [INFO] 分析YAML文件异常：异常信息: Traceback (most recent call last):
  File "E:\Project_python\api_cms\common\requests_util.py", line 368, in validate_result
    error_log("断言失败:"+assert_key+"不等于"+str(assert_value))
  File "E:\Project_python\api_cms\common\logger_util.py", line 66, in error_log
    raise Exception(log_message)
Exception: 断言失败:status_code不等于200

During handling of the above exception, another exception occurred:

Traceback (most recent call last):
  File "E:\Project_python\api_cms\common\requests_util.py", line 248, in analysis_yaml
    self.validate_result(yq_result, return_data, status_code)
  File "E:\Project_python\api_cms\common\requests_util.py", line 448, in validate_result
    error_log("断言异常：异常信息: %s" % str(traceback.format_exc()))
  File "E:\Project_python\api_cms\common\logger_util.py", line 66, in error_log
    raise Exception(log_message)
Exception: 断言异常：异常信息: Traceback (most recent call last):
  File "E:\Project_python\api_cms\common\requests_util.py", line 368, in validate_result
    error_log("断言失败:"+assert_key+"不等于"+str(assert_value))
  File "E:\Project_python\api_cms\common\logger_util.py", line 66, in error_log
    raise Exception(log_message)
Exception: 断言失败:status_code不等于200


[2023-12-18 11:39:32,287] logger_util.py->write_log line:61 [INFO] 
-------------接口请求开始-----------
[2023-12-18 11:39:32,287] logger_util.py->write_log line:61 [INFO] 接口名称：下发aa16=2022-11-28 09:05:01
[2023-12-18 11:39:32,287] logger_util.py->write_log line:61 [INFO] 接口方式：post
[2023-12-18 11:39:32,287] logger_util.py->write_log line:61 [INFO] 接口路径：http://127.0.0.1:18000/api/v1/variable/setvalues
[2023-12-18 11:39:32,287] logger_util.py->write_log line:61 [INFO] 请求头：{'X-Project': 'fb63700a195245b9bb42ef9e036ce674', 'Authorization': 'Bearer eyJhbGciOiJIUzI1NiIsInR5cCI6IkpXVCJ9.eyJodHRwOi8vc2NoZW1hcy54bWxzb2FwLm9yZy93cy8yMDA1LzA1L2lkZW50aXR5L2NsYWltcy9uYW1lIjoiU3VwZXJBZG1pbiIsImh0dHA6Ly9zY2hlbWFzLnhtbHNvYXAub3JnL3dzLzIwMDUvMDUvaWRlbnRpdHkvY2xhaW1zL25hbWVpZGVudGlmaWVyIjoiU3VwZXJBZG1pbiIsImV4cCI6MTcwMjk0OTM5MiwiaXNzIjoiQ01TdjIiLCJhdWQiOiJBcGkifQ.DTE3ExRd5e35qx7qyEGhaNLjjzP8QxhHUoLCzYg7Hcc'}
[2023-12-18 11:39:32,287] logger_util.py->write_log line:61 [INFO] 请求参数：{'aa16': '2022-11-28 09:05:01'}
[2023-12-18 11:39:32,287] logger_util.py->write_log line:61 [INFO] 文件上传：None
[2023-12-18 11:39:32,290] logger_util.py->error_log line:65 [INFO] 断言失败:status_code不等于200
[2023-12-18 11:39:32,290] logger_util.py->write_log line:61 [INFO] 实际结果：{'code': 409, 'msg': 'Projcet Conflict'}
[2023-12-18 11:39:32,290] logger_util.py->write_log line:61 [INFO] 接口请求失败！
[2023-12-18 11:39:32,290] logger_util.py->write_log line:61 [INFO] -------------接口请求结束-----------

[2023-12-18 11:39:32,290] logger_util.py->error_log line:65 [INFO] 断言异常：异常信息: Traceback (most recent call last):
  File "E:\Project_python\api_cms\common\requests_util.py", line 368, in validate_result
    error_log("断言失败:"+assert_key+"不等于"+str(assert_value))
  File "E:\Project_python\api_cms\common\logger_util.py", line 66, in error_log
    raise Exception(log_message)
Exception: 断言失败:status_code不等于200

[2023-12-18 11:39:32,291] logger_util.py->error_log line:65 [INFO] 分析YAML文件异常：异常信息: Traceback (most recent call last):
  File "E:\Project_python\api_cms\common\requests_util.py", line 368, in validate_result
    error_log("断言失败:"+assert_key+"不等于"+str(assert_value))
  File "E:\Project_python\api_cms\common\logger_util.py", line 66, in error_log
    raise Exception(log_message)
Exception: 断言失败:status_code不等于200

During handling of the above exception, another exception occurred:

Traceback (most recent call last):
  File "E:\Project_python\api_cms\common\requests_util.py", line 248, in analysis_yaml
    self.validate_result(yq_result, return_data, status_code)
  File "E:\Project_python\api_cms\common\requests_util.py", line 448, in validate_result
    error_log("断言异常：异常信息: %s" % str(traceback.format_exc()))
  File "E:\Project_python\api_cms\common\logger_util.py", line 66, in error_log
    raise Exception(log_message)
Exception: 断言异常：异常信息: Traceback (most recent call last):
  File "E:\Project_python\api_cms\common\requests_util.py", line 368, in validate_result
    error_log("断言失败:"+assert_key+"不等于"+str(assert_value))
  File "E:\Project_python\api_cms\common\logger_util.py", line 66, in error_log
    raise Exception(log_message)
Exception: 断言失败:status_code不等于200


[2023-12-18 11:39:32,329] logger_util.py->error_log line:65 [INFO] 发送请求异常：异常信息: Traceback (most recent call last):
  File "E:\Project_python\api_cms\common\requests_util.py", line 309, in send_request
    self.base_url = self.replace_load(self.base_url) + self.replace_load(url)
  File "E:\Project_python\api_cms\common\requests_util.py", line 140, in replace_load
    new_value = getattr(DubugTalk(), func_name)(*args_value.split(','))
  File "E:\Project_python\api_cms\debug_talk.py", line 26, in get_extract_data
    return read_extract_file(node_name)
  File "E:\Project_python\api_cms\common\yaml_util.py", line 19, in read_extract_file
    return value[one_node]
TypeError: 'NoneType' object is not subscriptable

[2023-12-18 11:39:32,329] logger_util.py->error_log line:65 [INFO] 分析YAML文件异常：异常信息: Traceback (most recent call last):
  File "E:\Project_python\api_cms\common\requests_util.py", line 309, in send_request
    self.base_url = self.replace_load(self.base_url) + self.replace_load(url)
  File "E:\Project_python\api_cms\common\requests_util.py", line 140, in replace_load
    new_value = getattr(DubugTalk(), func_name)(*args_value.split(','))
  File "E:\Project_python\api_cms\debug_talk.py", line 26, in get_extract_data
    return read_extract_file(node_name)
  File "E:\Project_python\api_cms\common\yaml_util.py", line 19, in read_extract_file
    return value[one_node]
TypeError: 'NoneType' object is not subscriptable

During handling of the above exception, another exception occurred:

Traceback (most recent call last):
  File "E:\Project_python\api_cms\common\requests_util.py", line 185, in analysis_yaml
    res = self.send_request(name =name,method=method,
  File "E:\Project_python\api_cms\common\requests_util.py", line 335, in send_request
    error_log("发送请求异常：异常信息: %s" % str(traceback.format_exc()))
  File "E:\Project_python\api_cms\common\logger_util.py", line 66, in error_log
    raise Exception(log_message)
Exception: 发送请求异常：异常信息: Traceback (most recent call last):
  File "E:\Project_python\api_cms\common\requests_util.py", line 309, in send_request
    self.base_url = self.replace_load(self.base_url) + self.replace_load(url)
  File "E:\Project_python\api_cms\common\requests_util.py", line 140, in replace_load
    new_value = getattr(DubugTalk(), func_name)(*args_value.split(','))
  File "E:\Project_python\api_cms\debug_talk.py", line 26, in get_extract_data
    return read_extract_file(node_name)
  File "E:\Project_python\api_cms\common\yaml_util.py", line 19, in read_extract_file
    return value[one_node]
TypeError: 'NoneType' object is not subscriptable


[2023-12-18 11:39:32,372] logger_util.py->error_log line:65 [INFO] 发送请求异常：异常信息: Traceback (most recent call last):
  File "E:\Project_python\api_cms\common\requests_util.py", line 309, in send_request
    self.base_url = self.replace_load(self.base_url) + self.replace_load(url)
  File "E:\Project_python\api_cms\common\requests_util.py", line 140, in replace_load
    new_value = getattr(DubugTalk(), func_name)(*args_value.split(','))
  File "E:\Project_python\api_cms\debug_talk.py", line 26, in get_extract_data
    return read_extract_file(node_name)
  File "E:\Project_python\api_cms\common\yaml_util.py", line 19, in read_extract_file
    return value[one_node]
TypeError: 'NoneType' object is not subscriptable

[2023-12-18 11:39:32,373] logger_util.py->error_log line:65 [INFO] 分析YAML文件异常：异常信息: Traceback (most recent call last):
  File "E:\Project_python\api_cms\common\requests_util.py", line 309, in send_request
    self.base_url = self.replace_load(self.base_url) + self.replace_load(url)
  File "E:\Project_python\api_cms\common\requests_util.py", line 140, in replace_load
    new_value = getattr(DubugTalk(), func_name)(*args_value.split(','))
  File "E:\Project_python\api_cms\debug_talk.py", line 26, in get_extract_data
    return read_extract_file(node_name)
  File "E:\Project_python\api_cms\common\yaml_util.py", line 19, in read_extract_file
    return value[one_node]
TypeError: 'NoneType' object is not subscriptable

During handling of the above exception, another exception occurred:

Traceback (most recent call last):
  File "E:\Project_python\api_cms\common\requests_util.py", line 185, in analysis_yaml
    res = self.send_request(name =name,method=method,
  File "E:\Project_python\api_cms\common\requests_util.py", line 335, in send_request
    error_log("发送请求异常：异常信息: %s" % str(traceback.format_exc()))
  File "E:\Project_python\api_cms\common\logger_util.py", line 66, in error_log
    raise Exception(log_message)
Exception: 发送请求异常：异常信息: Traceback (most recent call last):
  File "E:\Project_python\api_cms\common\requests_util.py", line 309, in send_request
    self.base_url = self.replace_load(self.base_url) + self.replace_load(url)
  File "E:\Project_python\api_cms\common\requests_util.py", line 140, in replace_load
    new_value = getattr(DubugTalk(), func_name)(*args_value.split(','))
  File "E:\Project_python\api_cms\debug_talk.py", line 26, in get_extract_data
    return read_extract_file(node_name)
  File "E:\Project_python\api_cms\common\yaml_util.py", line 19, in read_extract_file
    return value[one_node]
TypeError: 'NoneType' object is not subscriptable


[2023-12-18 11:39:32,418] logger_util.py->error_log line:65 [INFO] 发送请求异常：异常信息: Traceback (most recent call last):
  File "E:\Project_python\api_cms\common\requests_util.py", line 309, in send_request
    self.base_url = self.replace_load(self.base_url) + self.replace_load(url)
  File "E:\Project_python\api_cms\common\requests_util.py", line 140, in replace_load
    new_value = getattr(DubugTalk(), func_name)(*args_value.split(','))
  File "E:\Project_python\api_cms\debug_talk.py", line 26, in get_extract_data
    return read_extract_file(node_name)
  File "E:\Project_python\api_cms\common\yaml_util.py", line 19, in read_extract_file
    return value[one_node]
TypeError: 'NoneType' object is not subscriptable

[2023-12-18 11:39:32,418] logger_util.py->error_log line:65 [INFO] 分析YAML文件异常：异常信息: Traceback (most recent call last):
  File "E:\Project_python\api_cms\common\requests_util.py", line 309, in send_request
    self.base_url = self.replace_load(self.base_url) + self.replace_load(url)
  File "E:\Project_python\api_cms\common\requests_util.py", line 140, in replace_load
    new_value = getattr(DubugTalk(), func_name)(*args_value.split(','))
  File "E:\Project_python\api_cms\debug_talk.py", line 26, in get_extract_data
    return read_extract_file(node_name)
  File "E:\Project_python\api_cms\common\yaml_util.py", line 19, in read_extract_file
    return value[one_node]
TypeError: 'NoneType' object is not subscriptable

During handling of the above exception, another exception occurred:

Traceback (most recent call last):
  File "E:\Project_python\api_cms\common\requests_util.py", line 185, in analysis_yaml
    res = self.send_request(name =name,method=method,
  File "E:\Project_python\api_cms\common\requests_util.py", line 335, in send_request
    error_log("发送请求异常：异常信息: %s" % str(traceback.format_exc()))
  File "E:\Project_python\api_cms\common\logger_util.py", line 66, in error_log
    raise Exception(log_message)
Exception: 发送请求异常：异常信息: Traceback (most recent call last):
  File "E:\Project_python\api_cms\common\requests_util.py", line 309, in send_request
    self.base_url = self.replace_load(self.base_url) + self.replace_load(url)
  File "E:\Project_python\api_cms\common\requests_util.py", line 140, in replace_load
    new_value = getattr(DubugTalk(), func_name)(*args_value.split(','))
  File "E:\Project_python\api_cms\debug_talk.py", line 26, in get_extract_data
    return read_extract_file(node_name)
  File "E:\Project_python\api_cms\common\yaml_util.py", line 19, in read_extract_file
    return value[one_node]
TypeError: 'NoneType' object is not subscriptable


[2023-12-18 11:39:32,464] logger_util.py->error_log line:65 [INFO] 发送请求异常：异常信息: Traceback (most recent call last):
  File "E:\Project_python\api_cms\common\requests_util.py", line 309, in send_request
    self.base_url = self.replace_load(self.base_url) + self.replace_load(url)
  File "E:\Project_python\api_cms\common\requests_util.py", line 140, in replace_load
    new_value = getattr(DubugTalk(), func_name)(*args_value.split(','))
  File "E:\Project_python\api_cms\debug_talk.py", line 26, in get_extract_data
    return read_extract_file(node_name)
  File "E:\Project_python\api_cms\common\yaml_util.py", line 19, in read_extract_file
    return value[one_node]
TypeError: 'NoneType' object is not subscriptable

[2023-12-18 11:39:32,464] logger_util.py->error_log line:65 [INFO] 分析YAML文件异常：异常信息: Traceback (most recent call last):
  File "E:\Project_python\api_cms\common\requests_util.py", line 309, in send_request
    self.base_url = self.replace_load(self.base_url) + self.replace_load(url)
  File "E:\Project_python\api_cms\common\requests_util.py", line 140, in replace_load
    new_value = getattr(DubugTalk(), func_name)(*args_value.split(','))
  File "E:\Project_python\api_cms\debug_talk.py", line 26, in get_extract_data
    return read_extract_file(node_name)
  File "E:\Project_python\api_cms\common\yaml_util.py", line 19, in read_extract_file
    return value[one_node]
TypeError: 'NoneType' object is not subscriptable

During handling of the above exception, another exception occurred:

Traceback (most recent call last):
  File "E:\Project_python\api_cms\common\requests_util.py", line 185, in analysis_yaml
    res = self.send_request(name =name,method=method,
  File "E:\Project_python\api_cms\common\requests_util.py", line 335, in send_request
    error_log("发送请求异常：异常信息: %s" % str(traceback.format_exc()))
  File "E:\Project_python\api_cms\common\logger_util.py", line 66, in error_log
    raise Exception(log_message)
Exception: 发送请求异常：异常信息: Traceback (most recent call last):
  File "E:\Project_python\api_cms\common\requests_util.py", line 309, in send_request
    self.base_url = self.replace_load(self.base_url) + self.replace_load(url)
  File "E:\Project_python\api_cms\common\requests_util.py", line 140, in replace_load
    new_value = getattr(DubugTalk(), func_name)(*args_value.split(','))
  File "E:\Project_python\api_cms\debug_talk.py", line 26, in get_extract_data
    return read_extract_file(node_name)
  File "E:\Project_python\api_cms\common\yaml_util.py", line 19, in read_extract_file
    return value[one_node]
TypeError: 'NoneType' object is not subscriptable


[2023-12-18 11:39:32,601] logger_util.py->error_log line:65 [INFO] 发送请求异常：异常信息: Traceback (most recent call last):
  File "E:\Project_python\api_cms\common\requests_util.py", line 309, in send_request
    self.base_url = self.replace_load(self.base_url) + self.replace_load(url)
  File "E:\Project_python\api_cms\common\requests_util.py", line 140, in replace_load
    new_value = getattr(DubugTalk(), func_name)(*args_value.split(','))
  File "E:\Project_python\api_cms\debug_talk.py", line 26, in get_extract_data
    return read_extract_file(node_name)
  File "E:\Project_python\api_cms\common\yaml_util.py", line 19, in read_extract_file
    return value[one_node]
TypeError: 'NoneType' object is not subscriptable

[2023-12-18 11:39:32,601] logger_util.py->error_log line:65 [INFO] 分析YAML文件异常：异常信息: Traceback (most recent call last):
  File "E:\Project_python\api_cms\common\requests_util.py", line 309, in send_request
    self.base_url = self.replace_load(self.base_url) + self.replace_load(url)
  File "E:\Project_python\api_cms\common\requests_util.py", line 140, in replace_load
    new_value = getattr(DubugTalk(), func_name)(*args_value.split(','))
  File "E:\Project_python\api_cms\debug_talk.py", line 26, in get_extract_data
    return read_extract_file(node_name)
  File "E:\Project_python\api_cms\common\yaml_util.py", line 19, in read_extract_file
    return value[one_node]
TypeError: 'NoneType' object is not subscriptable

During handling of the above exception, another exception occurred:

Traceback (most recent call last):
  File "E:\Project_python\api_cms\common\requests_util.py", line 185, in analysis_yaml
    res = self.send_request(name =name,method=method,
  File "E:\Project_python\api_cms\common\requests_util.py", line 335, in send_request
    error_log("发送请求异常：异常信息: %s" % str(traceback.format_exc()))
  File "E:\Project_python\api_cms\common\logger_util.py", line 66, in error_log
    raise Exception(log_message)
Exception: 发送请求异常：异常信息: Traceback (most recent call last):
  File "E:\Project_python\api_cms\common\requests_util.py", line 309, in send_request
    self.base_url = self.replace_load(self.base_url) + self.replace_load(url)
  File "E:\Project_python\api_cms\common\requests_util.py", line 140, in replace_load
    new_value = getattr(DubugTalk(), func_name)(*args_value.split(','))
  File "E:\Project_python\api_cms\debug_talk.py", line 26, in get_extract_data
    return read_extract_file(node_name)
  File "E:\Project_python\api_cms\common\yaml_util.py", line 19, in read_extract_file
    return value[one_node]
TypeError: 'NoneType' object is not subscriptable


[2023-12-18 11:39:32,645] logger_util.py->error_log line:65 [INFO] 发送请求异常：异常信息: Traceback (most recent call last):
  File "E:\Project_python\api_cms\common\requests_util.py", line 309, in send_request
    self.base_url = self.replace_load(self.base_url) + self.replace_load(url)
  File "E:\Project_python\api_cms\common\requests_util.py", line 140, in replace_load
    new_value = getattr(DubugTalk(), func_name)(*args_value.split(','))
  File "E:\Project_python\api_cms\debug_talk.py", line 26, in get_extract_data
    return read_extract_file(node_name)
  File "E:\Project_python\api_cms\common\yaml_util.py", line 19, in read_extract_file
    return value[one_node]
TypeError: 'NoneType' object is not subscriptable

[2023-12-18 11:39:32,646] logger_util.py->error_log line:65 [INFO] 分析YAML文件异常：异常信息: Traceback (most recent call last):
  File "E:\Project_python\api_cms\common\requests_util.py", line 309, in send_request
    self.base_url = self.replace_load(self.base_url) + self.replace_load(url)
  File "E:\Project_python\api_cms\common\requests_util.py", line 140, in replace_load
    new_value = getattr(DubugTalk(), func_name)(*args_value.split(','))
  File "E:\Project_python\api_cms\debug_talk.py", line 26, in get_extract_data
    return read_extract_file(node_name)
  File "E:\Project_python\api_cms\common\yaml_util.py", line 19, in read_extract_file
    return value[one_node]
TypeError: 'NoneType' object is not subscriptable

During handling of the above exception, another exception occurred:

Traceback (most recent call last):
  File "E:\Project_python\api_cms\common\requests_util.py", line 185, in analysis_yaml
    res = self.send_request(name =name,method=method,
  File "E:\Project_python\api_cms\common\requests_util.py", line 335, in send_request
    error_log("发送请求异常：异常信息: %s" % str(traceback.format_exc()))
  File "E:\Project_python\api_cms\common\logger_util.py", line 66, in error_log
    raise Exception(log_message)
Exception: 发送请求异常：异常信息: Traceback (most recent call last):
  File "E:\Project_python\api_cms\common\requests_util.py", line 309, in send_request
    self.base_url = self.replace_load(self.base_url) + self.replace_load(url)
  File "E:\Project_python\api_cms\common\requests_util.py", line 140, in replace_load
    new_value = getattr(DubugTalk(), func_name)(*args_value.split(','))
  File "E:\Project_python\api_cms\debug_talk.py", line 26, in get_extract_data
    return read_extract_file(node_name)
  File "E:\Project_python\api_cms\common\yaml_util.py", line 19, in read_extract_file
    return value[one_node]
TypeError: 'NoneType' object is not subscriptable


[2023-12-18 11:39:32,689] logger_util.py->error_log line:65 [INFO] 发送请求异常：异常信息: Traceback (most recent call last):
  File "E:\Project_python\api_cms\common\requests_util.py", line 309, in send_request
    self.base_url = self.replace_load(self.base_url) + self.replace_load(url)
  File "E:\Project_python\api_cms\common\requests_util.py", line 140, in replace_load
    new_value = getattr(DubugTalk(), func_name)(*args_value.split(','))
  File "E:\Project_python\api_cms\debug_talk.py", line 26, in get_extract_data
    return read_extract_file(node_name)
  File "E:\Project_python\api_cms\common\yaml_util.py", line 19, in read_extract_file
    return value[one_node]
TypeError: 'NoneType' object is not subscriptable

[2023-12-18 11:39:32,689] logger_util.py->error_log line:65 [INFO] 分析YAML文件异常：异常信息: Traceback (most recent call last):
  File "E:\Project_python\api_cms\common\requests_util.py", line 309, in send_request
    self.base_url = self.replace_load(self.base_url) + self.replace_load(url)
  File "E:\Project_python\api_cms\common\requests_util.py", line 140, in replace_load
    new_value = getattr(DubugTalk(), func_name)(*args_value.split(','))
  File "E:\Project_python\api_cms\debug_talk.py", line 26, in get_extract_data
    return read_extract_file(node_name)
  File "E:\Project_python\api_cms\common\yaml_util.py", line 19, in read_extract_file
    return value[one_node]
TypeError: 'NoneType' object is not subscriptable

During handling of the above exception, another exception occurred:

Traceback (most recent call last):
  File "E:\Project_python\api_cms\common\requests_util.py", line 185, in analysis_yaml
    res = self.send_request(name =name,method=method,
  File "E:\Project_python\api_cms\common\requests_util.py", line 335, in send_request
    error_log("发送请求异常：异常信息: %s" % str(traceback.format_exc()))
  File "E:\Project_python\api_cms\common\logger_util.py", line 66, in error_log
    raise Exception(log_message)
Exception: 发送请求异常：异常信息: Traceback (most recent call last):
  File "E:\Project_python\api_cms\common\requests_util.py", line 309, in send_request
    self.base_url = self.replace_load(self.base_url) + self.replace_load(url)
  File "E:\Project_python\api_cms\common\requests_util.py", line 140, in replace_load
    new_value = getattr(DubugTalk(), func_name)(*args_value.split(','))
  File "E:\Project_python\api_cms\debug_talk.py", line 26, in get_extract_data
    return read_extract_file(node_name)
  File "E:\Project_python\api_cms\common\yaml_util.py", line 19, in read_extract_file
    return value[one_node]
TypeError: 'NoneType' object is not subscriptable


[2023-12-18 11:39:32,733] logger_util.py->error_log line:65 [INFO] 发送请求异常：异常信息: Traceback (most recent call last):
  File "E:\Project_python\api_cms\common\requests_util.py", line 309, in send_request
    self.base_url = self.replace_load(self.base_url) + self.replace_load(url)
  File "E:\Project_python\api_cms\common\requests_util.py", line 140, in replace_load
    new_value = getattr(DubugTalk(), func_name)(*args_value.split(','))
  File "E:\Project_python\api_cms\debug_talk.py", line 26, in get_extract_data
    return read_extract_file(node_name)
  File "E:\Project_python\api_cms\common\yaml_util.py", line 19, in read_extract_file
    return value[one_node]
TypeError: 'NoneType' object is not subscriptable

[2023-12-18 11:39:32,734] logger_util.py->error_log line:65 [INFO] 分析YAML文件异常：异常信息: Traceback (most recent call last):
  File "E:\Project_python\api_cms\common\requests_util.py", line 309, in send_request
    self.base_url = self.replace_load(self.base_url) + self.replace_load(url)
  File "E:\Project_python\api_cms\common\requests_util.py", line 140, in replace_load
    new_value = getattr(DubugTalk(), func_name)(*args_value.split(','))
  File "E:\Project_python\api_cms\debug_talk.py", line 26, in get_extract_data
    return read_extract_file(node_name)
  File "E:\Project_python\api_cms\common\yaml_util.py", line 19, in read_extract_file
    return value[one_node]
TypeError: 'NoneType' object is not subscriptable

During handling of the above exception, another exception occurred:

Traceback (most recent call last):
  File "E:\Project_python\api_cms\common\requests_util.py", line 185, in analysis_yaml
    res = self.send_request(name =name,method=method,
  File "E:\Project_python\api_cms\common\requests_util.py", line 335, in send_request
    error_log("发送请求异常：异常信息: %s" % str(traceback.format_exc()))
  File "E:\Project_python\api_cms\common\logger_util.py", line 66, in error_log
    raise Exception(log_message)
Exception: 发送请求异常：异常信息: Traceback (most recent call last):
  File "E:\Project_python\api_cms\common\requests_util.py", line 309, in send_request
    self.base_url = self.replace_load(self.base_url) + self.replace_load(url)
  File "E:\Project_python\api_cms\common\requests_util.py", line 140, in replace_load
    new_value = getattr(DubugTalk(), func_name)(*args_value.split(','))
  File "E:\Project_python\api_cms\debug_talk.py", line 26, in get_extract_data
    return read_extract_file(node_name)
  File "E:\Project_python\api_cms\common\yaml_util.py", line 19, in read_extract_file
    return value[one_node]
TypeError: 'NoneType' object is not subscriptable


[2023-12-18 11:39:32,782] logger_util.py->write_log line:61 [INFO] 
-------------接口请求开始-----------
[2023-12-18 11:39:32,782] logger_util.py->write_log line:61 [INFO] 接口名称：下发A1=false
[2023-12-18 11:39:32,782] logger_util.py->write_log line:61 [INFO] 接口方式：post
[2023-12-18 11:39:32,782] logger_util.py->write_log line:61 [INFO] 接口路径：http://127.0.0.1:18000/api/v1/variable/setvalues
[2023-12-18 11:39:32,783] logger_util.py->write_log line:61 [INFO] 请求头：{'X-Project': 'fb63700a195245b9bb42ef9e036ce674', 'Authorization': 'Bearer eyJhbGciOiJIUzI1NiIsInR5cCI6IkpXVCJ9.eyJodHRwOi8vc2NoZW1hcy54bWxzb2FwLm9yZy93cy8yMDA1LzA1L2lkZW50aXR5L2NsYWltcy9uYW1lIjoiU3VwZXJBZG1pbiIsImh0dHA6Ly9zY2hlbWFzLnhtbHNvYXAub3JnL3dzLzIwMDUvMDUvaWRlbnRpdHkvY2xhaW1zL25hbWVpZGVudGlmaWVyIjoiU3VwZXJBZG1pbiIsImV4cCI6MTcwMjk0OTM5MiwiaXNzIjoiQ01TdjIiLCJhdWQiOiJBcGkifQ.DTE3ExRd5e35qx7qyEGhaNLjjzP8QxhHUoLCzYg7Hcc'}
[2023-12-18 11:39:32,783] logger_util.py->write_log line:61 [INFO] 请求参数：{'A1': 'false'}
[2023-12-18 11:39:32,783] logger_util.py->write_log line:61 [INFO] 文件上传：None
[2023-12-18 11:39:32,785] logger_util.py->error_log line:65 [INFO] 断言失败:status_code不等于200
[2023-12-18 11:39:32,785] logger_util.py->write_log line:61 [INFO] 实际结果：{'code': 409, 'msg': 'Projcet Conflict'}
[2023-12-18 11:39:32,785] logger_util.py->write_log line:61 [INFO] 接口请求失败！
[2023-12-18 11:39:32,785] logger_util.py->write_log line:61 [INFO] -------------接口请求结束-----------

[2023-12-18 11:39:32,785] logger_util.py->error_log line:65 [INFO] 断言异常：异常信息: Traceback (most recent call last):
  File "E:\Project_python\api_cms\common\requests_util.py", line 368, in validate_result
    error_log("断言失败:"+assert_key+"不等于"+str(assert_value))
  File "E:\Project_python\api_cms\common\logger_util.py", line 66, in error_log
    raise Exception(log_message)
Exception: 断言失败:status_code不等于200

[2023-12-18 11:39:32,786] logger_util.py->error_log line:65 [INFO] 分析YAML文件异常：异常信息: Traceback (most recent call last):
  File "E:\Project_python\api_cms\common\requests_util.py", line 368, in validate_result
    error_log("断言失败:"+assert_key+"不等于"+str(assert_value))
  File "E:\Project_python\api_cms\common\logger_util.py", line 66, in error_log
    raise Exception(log_message)
Exception: 断言失败:status_code不等于200

During handling of the above exception, another exception occurred:

Traceback (most recent call last):
  File "E:\Project_python\api_cms\common\requests_util.py", line 248, in analysis_yaml
    self.validate_result(yq_result, return_data, status_code)
  File "E:\Project_python\api_cms\common\requests_util.py", line 448, in validate_result
    error_log("断言异常：异常信息: %s" % str(traceback.format_exc()))
  File "E:\Project_python\api_cms\common\logger_util.py", line 66, in error_log
    raise Exception(log_message)
Exception: 断言异常：异常信息: Traceback (most recent call last):
  File "E:\Project_python\api_cms\common\requests_util.py", line 368, in validate_result
    error_log("断言失败:"+assert_key+"不等于"+str(assert_value))
  File "E:\Project_python\api_cms\common\logger_util.py", line 66, in error_log
    raise Exception(log_message)
Exception: 断言失败:status_code不等于200


[2023-12-18 11:39:32,830] logger_util.py->write_log line:61 [INFO] 
-------------接口请求开始-----------
[2023-12-18 11:39:32,830] logger_util.py->write_log line:61 [INFO] 接口名称：下发A1=true
[2023-12-18 11:39:32,831] logger_util.py->write_log line:61 [INFO] 接口方式：post
[2023-12-18 11:39:32,831] logger_util.py->write_log line:61 [INFO] 接口路径：http://127.0.0.1:18000/api/v1/variable/setvalues
[2023-12-18 11:39:32,831] logger_util.py->write_log line:61 [INFO] 请求头：{'X-Project': 'fb63700a195245b9bb42ef9e036ce674', 'Authorization': 'Bearer eyJhbGciOiJIUzI1NiIsInR5cCI6IkpXVCJ9.eyJodHRwOi8vc2NoZW1hcy54bWxzb2FwLm9yZy93cy8yMDA1LzA1L2lkZW50aXR5L2NsYWltcy9uYW1lIjoiU3VwZXJBZG1pbiIsImh0dHA6Ly9zY2hlbWFzLnhtbHNvYXAub3JnL3dzLzIwMDUvMDUvaWRlbnRpdHkvY2xhaW1zL25hbWVpZGVudGlmaWVyIjoiU3VwZXJBZG1pbiIsImV4cCI6MTcwMjk0OTM5MiwiaXNzIjoiQ01TdjIiLCJhdWQiOiJBcGkifQ.DTE3ExRd5e35qx7qyEGhaNLjjzP8QxhHUoLCzYg7Hcc'}
[2023-12-18 11:39:32,831] logger_util.py->write_log line:61 [INFO] 请求参数：{'A1': 'true'}
[2023-12-18 11:39:32,831] logger_util.py->write_log line:61 [INFO] 文件上传：None
[2023-12-18 11:39:32,833] logger_util.py->error_log line:65 [INFO] 断言失败:status_code不等于200
[2023-12-18 11:39:32,833] logger_util.py->write_log line:61 [INFO] 实际结果：{'code': 409, 'msg': 'Projcet Conflict'}
[2023-12-18 11:39:32,833] logger_util.py->write_log line:61 [INFO] 接口请求失败！
[2023-12-18 11:39:32,833] logger_util.py->write_log line:61 [INFO] -------------接口请求结束-----------

[2023-12-18 11:39:32,835] logger_util.py->error_log line:65 [INFO] 断言异常：异常信息: Traceback (most recent call last):
  File "E:\Project_python\api_cms\common\requests_util.py", line 368, in validate_result
    error_log("断言失败:"+assert_key+"不等于"+str(assert_value))
  File "E:\Project_python\api_cms\common\logger_util.py", line 66, in error_log
    raise Exception(log_message)
Exception: 断言失败:status_code不等于200

[2023-12-18 11:39:32,835] logger_util.py->error_log line:65 [INFO] 分析YAML文件异常：异常信息: Traceback (most recent call last):
  File "E:\Project_python\api_cms\common\requests_util.py", line 368, in validate_result
    error_log("断言失败:"+assert_key+"不等于"+str(assert_value))
  File "E:\Project_python\api_cms\common\logger_util.py", line 66, in error_log
    raise Exception(log_message)
Exception: 断言失败:status_code不等于200

During handling of the above exception, another exception occurred:

Traceback (most recent call last):
  File "E:\Project_python\api_cms\common\requests_util.py", line 248, in analysis_yaml
    self.validate_result(yq_result, return_data, status_code)
  File "E:\Project_python\api_cms\common\requests_util.py", line 448, in validate_result
    error_log("断言异常：异常信息: %s" % str(traceback.format_exc()))
  File "E:\Project_python\api_cms\common\logger_util.py", line 66, in error_log
    raise Exception(log_message)
Exception: 断言异常：异常信息: Traceback (most recent call last):
  File "E:\Project_python\api_cms\common\requests_util.py", line 368, in validate_result
    error_log("断言失败:"+assert_key+"不等于"+str(assert_value))
  File "E:\Project_python\api_cms\common\logger_util.py", line 66, in error_log
    raise Exception(log_message)
Exception: 断言失败:status_code不等于200


[2023-12-18 11:39:32,875] logger_util.py->error_log line:65 [INFO] 发送请求异常：异常信息: Traceback (most recent call last):
  File "E:\Project_python\api_cms\common\requests_util.py", line 309, in send_request
    self.base_url = self.replace_load(self.base_url) + self.replace_load(url)
  File "E:\Project_python\api_cms\common\requests_util.py", line 140, in replace_load
    new_value = getattr(DubugTalk(), func_name)(*args_value.split(','))
  File "E:\Project_python\api_cms\debug_talk.py", line 26, in get_extract_data
    return read_extract_file(node_name)
  File "E:\Project_python\api_cms\common\yaml_util.py", line 19, in read_extract_file
    return value[one_node]
TypeError: 'NoneType' object is not subscriptable

[2023-12-18 11:39:32,875] logger_util.py->error_log line:65 [INFO] 分析YAML文件异常：异常信息: Traceback (most recent call last):
  File "E:\Project_python\api_cms\common\requests_util.py", line 309, in send_request
    self.base_url = self.replace_load(self.base_url) + self.replace_load(url)
  File "E:\Project_python\api_cms\common\requests_util.py", line 140, in replace_load
    new_value = getattr(DubugTalk(), func_name)(*args_value.split(','))
  File "E:\Project_python\api_cms\debug_talk.py", line 26, in get_extract_data
    return read_extract_file(node_name)
  File "E:\Project_python\api_cms\common\yaml_util.py", line 19, in read_extract_file
    return value[one_node]
TypeError: 'NoneType' object is not subscriptable

During handling of the above exception, another exception occurred:

Traceback (most recent call last):
  File "E:\Project_python\api_cms\common\requests_util.py", line 185, in analysis_yaml
    res = self.send_request(name =name,method=method,
  File "E:\Project_python\api_cms\common\requests_util.py", line 335, in send_request
    error_log("发送请求异常：异常信息: %s" % str(traceback.format_exc()))
  File "E:\Project_python\api_cms\common\logger_util.py", line 66, in error_log
    raise Exception(log_message)
Exception: 发送请求异常：异常信息: Traceback (most recent call last):
  File "E:\Project_python\api_cms\common\requests_util.py", line 309, in send_request
    self.base_url = self.replace_load(self.base_url) + self.replace_load(url)
  File "E:\Project_python\api_cms\common\requests_util.py", line 140, in replace_load
    new_value = getattr(DubugTalk(), func_name)(*args_value.split(','))
  File "E:\Project_python\api_cms\debug_talk.py", line 26, in get_extract_data
    return read_extract_file(node_name)
  File "E:\Project_python\api_cms\common\yaml_util.py", line 19, in read_extract_file
    return value[one_node]
TypeError: 'NoneType' object is not subscriptable


[2023-12-18 11:39:33,039] logger_util.py->error_log line:65 [INFO] 发送请求异常：异常信息: Traceback (most recent call last):
  File "E:\Project_python\api_cms\common\requests_util.py", line 309, in send_request
    self.base_url = self.replace_load(self.base_url) + self.replace_load(url)
  File "E:\Project_python\api_cms\common\requests_util.py", line 140, in replace_load
    new_value = getattr(DubugTalk(), func_name)(*args_value.split(','))
  File "E:\Project_python\api_cms\debug_talk.py", line 26, in get_extract_data
    return read_extract_file(node_name)
  File "E:\Project_python\api_cms\common\yaml_util.py", line 19, in read_extract_file
    return value[one_node]
TypeError: 'NoneType' object is not subscriptable

[2023-12-18 11:39:33,039] logger_util.py->error_log line:65 [INFO] 分析YAML文件异常：异常信息: Traceback (most recent call last):
  File "E:\Project_python\api_cms\common\requests_util.py", line 309, in send_request
    self.base_url = self.replace_load(self.base_url) + self.replace_load(url)
  File "E:\Project_python\api_cms\common\requests_util.py", line 140, in replace_load
    new_value = getattr(DubugTalk(), func_name)(*args_value.split(','))
  File "E:\Project_python\api_cms\debug_talk.py", line 26, in get_extract_data
    return read_extract_file(node_name)
  File "E:\Project_python\api_cms\common\yaml_util.py", line 19, in read_extract_file
    return value[one_node]
TypeError: 'NoneType' object is not subscriptable

During handling of the above exception, another exception occurred:

Traceback (most recent call last):
  File "E:\Project_python\api_cms\common\requests_util.py", line 185, in analysis_yaml
    res = self.send_request(name =name,method=method,
  File "E:\Project_python\api_cms\common\requests_util.py", line 335, in send_request
    error_log("发送请求异常：异常信息: %s" % str(traceback.format_exc()))
  File "E:\Project_python\api_cms\common\logger_util.py", line 66, in error_log
    raise Exception(log_message)
Exception: 发送请求异常：异常信息: Traceback (most recent call last):
  File "E:\Project_python\api_cms\common\requests_util.py", line 309, in send_request
    self.base_url = self.replace_load(self.base_url) + self.replace_load(url)
  File "E:\Project_python\api_cms\common\requests_util.py", line 140, in replace_load
    new_value = getattr(DubugTalk(), func_name)(*args_value.split(','))
  File "E:\Project_python\api_cms\debug_talk.py", line 26, in get_extract_data
    return read_extract_file(node_name)
  File "E:\Project_python\api_cms\common\yaml_util.py", line 19, in read_extract_file
    return value[one_node]
TypeError: 'NoneType' object is not subscriptable


