[2023-11-17 14:47:33,707] logger_util.py->error_log line:65 [INFO] 发送请求异常：异常信息: Traceback (most recent call last):
  File "E:\Project_python\api_cms\common\requests_util.py", line 306, in send_request
    kwargs[key] = self.replace_load(value)
  File "E:\Project_python\api_cms\common\requests_util.py", line 130, in replace_load
    for i in range(1, str_data.count('${') + 1):
AttributeError: 'bool' object has no attribute 'count'

[2023-11-17 14:47:33,707] logger_util.py->error_log line:65 [INFO] 分析YAML文件异常：异常信息: Traceback (most recent call last):
  File "E:\Project_python\api_cms\common\requests_util.py", line 306, in send_request
    kwargs[key] = self.replace_load(value)
  File "E:\Project_python\api_cms\common\requests_util.py", line 130, in replace_load
    for i in range(1, str_data.count('${') + 1):
AttributeError: 'bool' object has no attribute 'count'

During handling of the above exception, another exception occurred:

Traceback (most recent call last):
  File "E:\Project_python\api_cms\common\requests_util.py", line 185, in analysis_yaml
    res = self.send_request(name =name,method=method,
  File "E:\Project_python\api_cms\common\requests_util.py", line 325, in send_request
    error_log("发送请求异常：异常信息: %s" % str(traceback.format_exc()))
  File "E:\Project_python\api_cms\common\logger_util.py", line 66, in error_log
    raise Exception(log_message)
Exception: 发送请求异常：异常信息: Traceback (most recent call last):
  File "E:\Project_python\api_cms\common\requests_util.py", line 306, in send_request
    kwargs[key] = self.replace_load(value)
  File "E:\Project_python\api_cms\common\requests_util.py", line 130, in replace_load
    for i in range(1, str_data.count('${') + 1):
AttributeError: 'bool' object has no attribute 'count'


