[2023-08-22 11:46:59,343] logger_util.py->write_log line:61 [INFO] 
-------------接口请求开始-----------
[2023-08-22 11:46:59,343] logger_util.py->write_log line:61 [INFO] 接口名称：异常校验-新建通道
[2023-08-22 11:46:59,344] logger_util.py->write_log line:61 [INFO] 接口方式：post
[2023-08-22 11:46:59,344] logger_util.py->write_log line:61 [INFO] 接口路径：http://127.0.0.1:18000/api/v1/variable/tunnel
[2023-08-22 11:46:59,344] logger_util.py->write_log line:61 [INFO] 请求头：{}
[2023-08-22 11:46:59,344] logger_util.py->write_log line:61 [INFO] 请求参数：{'parentId': None, 'type': 1, 'name': '通道11501', 'description': '\t新建通道1', 'config': {'suppiler': 'ModBus', 'model': 'Modbus_TCP', 'protocol': 'Modbus_TCP', 'parameters': {'ServerName': '127.0.0.1', 'DeviceID': '$csv{}', 'Port': '502', 'HeadAddress': '1', 'ConnectTimeOut': '3', 'ResponseTimeout': '1000', 'Int32ByteOrder': '2143', 'Int64ByteOrder': '2143', 'UInt32ByteOrder': '2143', 'UInt64ByteOrder': '2143', 'F32ByteOrder': '2143', 'F64ByteOrder': '2143', 'StrByteOrder': '2143', 'EnableIndependentLink': '禁用', 'EnablePduDiagnosis': '启用', 'PduLength': '220'}}, 'copyConfig': None}
[2023-08-22 11:46:59,344] logger_util.py->write_log line:61 [INFO] 文件上传：None
[2023-08-22 11:46:59,363] logger_util.py->error_log line:65 [INFO] 断言失败:status_code不等于200
[2023-08-22 11:46:59,363] logger_util.py->write_log line:61 [INFO] 接口请求失败！
[2023-08-22 11:46:59,363] logger_util.py->write_log line:61 [INFO] -------------接口请求结束-----------

[2023-08-22 11:46:59,395] logger_util.py->error_log line:65 [INFO] 断言异常：异常信息: Traceback (most recent call last):
  File "E:\Project_python\api_cms\common\requests_util.py", line 347, in validate_result
    error_log("断言失败:"+assert_key+"不等于"+str(assert_value))
  File "E:\Project_python\api_cms\common\logger_util.py", line 66, in error_log
    raise Exception(log_message)
Exception: 断言失败:status_code不等于200

[2023-08-22 11:46:59,396] logger_util.py->error_log line:65 [INFO] 分析YAML文件异常：异常信息: Traceback (most recent call last):
  File "E:\Project_python\api_cms\common\requests_util.py", line 347, in validate_result
    error_log("断言失败:"+assert_key+"不等于"+str(assert_value))
  File "E:\Project_python\api_cms\common\logger_util.py", line 66, in error_log
    raise Exception(log_message)
Exception: 断言失败:status_code不等于200

During handling of the above exception, another exception occurred:

Traceback (most recent call last):
  File "E:\Project_python\api_cms\common\requests_util.py", line 249, in analysis_yaml
    self.validate_result(yq_result, return_text, status_code)
  File "E:\Project_python\api_cms\common\requests_util.py", line 401, in validate_result
    error_log("断言异常：异常信息: %s" % str(traceback.format_exc()))
  File "E:\Project_python\api_cms\common\logger_util.py", line 66, in error_log
    raise Exception(log_message)
Exception: 断言异常：异常信息: Traceback (most recent call last):
  File "E:\Project_python\api_cms\common\requests_util.py", line 347, in validate_result
    error_log("断言失败:"+assert_key+"不等于"+str(assert_value))
  File "E:\Project_python\api_cms\common\logger_util.py", line 66, in error_log
    raise Exception(log_message)
Exception: 断言失败:status_code不等于200


