[2023-08-23 14:08:13,710] logger_util.py->error_log line:65 [INFO] 发送请求异常：异常信息: Traceback (most recent call last):
  File "E:\Project_python\api_cms\common\requests_util.py", line 302, in send_request
    self.last_headers = self.replace_load(headers)
  File "E:\Project_python\api_cms\common\requests_util.py", line 142, in replace_load
    new_value = getattr(DubugTalk(), func_name)(*args_value.split(','))
TypeError: get_extract_data() takes 2 positional arguments but 3 were given

[2023-08-23 14:08:13,710] logger_util.py->error_log line:65 [INFO] 分析YAML文件异常：异常信息: Traceback (most recent call last):
  File "E:\Project_python\api_cms\common\requests_util.py", line 302, in send_request
    self.last_headers = self.replace_load(headers)
  File "E:\Project_python\api_cms\common\requests_util.py", line 142, in replace_load
    new_value = getattr(DubugTalk(), func_name)(*args_value.split(','))
TypeError: get_extract_data() takes 2 positional arguments but 3 were given

During handling of the above exception, another exception occurred:

Traceback (most recent call last):
  File "E:\Project_python\api_cms\common\requests_util.py", line 187, in analysis_yaml
    res = self.send_request(name =name,method=method,
  File "E:\Project_python\api_cms\common\requests_util.py", line 325, in send_request
    error_log("发送请求异常：异常信息: %s" % str(traceback.format_exc()))
  File "E:\Project_python\api_cms\common\logger_util.py", line 66, in error_log
    raise Exception(log_message)
Exception: 发送请求异常：异常信息: Traceback (most recent call last):
  File "E:\Project_python\api_cms\common\requests_util.py", line 302, in send_request
    self.last_headers = self.replace_load(headers)
  File "E:\Project_python\api_cms\common\requests_util.py", line 142, in replace_load
    new_value = getattr(DubugTalk(), func_name)(*args_value.split(','))
TypeError: get_extract_data() takes 2 positional arguments but 3 were given


[2023-08-23 14:08:13,819] logger_util.py->error_log line:65 [INFO] 发送请求异常：异常信息: Traceback (most recent call last):
  File "E:\Project_python\api_cms\common\requests_util.py", line 302, in send_request
    self.last_headers = self.replace_load(headers)
  File "E:\Project_python\api_cms\common\requests_util.py", line 142, in replace_load
    new_value = getattr(DubugTalk(), func_name)(*args_value.split(','))
TypeError: get_extract_data() takes 2 positional arguments but 3 were given

[2023-08-23 14:08:13,819] logger_util.py->error_log line:65 [INFO] 分析YAML文件异常：异常信息: Traceback (most recent call last):
  File "E:\Project_python\api_cms\common\requests_util.py", line 302, in send_request
    self.last_headers = self.replace_load(headers)
  File "E:\Project_python\api_cms\common\requests_util.py", line 142, in replace_load
    new_value = getattr(DubugTalk(), func_name)(*args_value.split(','))
TypeError: get_extract_data() takes 2 positional arguments but 3 were given

During handling of the above exception, another exception occurred:

Traceback (most recent call last):
  File "E:\Project_python\api_cms\common\requests_util.py", line 187, in analysis_yaml
    res = self.send_request(name =name,method=method,
  File "E:\Project_python\api_cms\common\requests_util.py", line 325, in send_request
    error_log("发送请求异常：异常信息: %s" % str(traceback.format_exc()))
  File "E:\Project_python\api_cms\common\logger_util.py", line 66, in error_log
    raise Exception(log_message)
Exception: 发送请求异常：异常信息: Traceback (most recent call last):
  File "E:\Project_python\api_cms\common\requests_util.py", line 302, in send_request
    self.last_headers = self.replace_load(headers)
  File "E:\Project_python\api_cms\common\requests_util.py", line 142, in replace_load
    new_value = getattr(DubugTalk(), func_name)(*args_value.split(','))
TypeError: get_extract_data() takes 2 positional arguments but 3 were given


[2023-08-23 14:08:13,847] logger_util.py->error_log line:65 [INFO] 发送请求异常：异常信息: Traceback (most recent call last):
  File "E:\Project_python\api_cms\common\requests_util.py", line 302, in send_request
    self.last_headers = self.replace_load(headers)
  File "E:\Project_python\api_cms\common\requests_util.py", line 142, in replace_load
    new_value = getattr(DubugTalk(), func_name)(*args_value.split(','))
TypeError: get_extract_data() takes 2 positional arguments but 3 were given

[2023-08-23 14:08:13,848] logger_util.py->error_log line:65 [INFO] 分析YAML文件异常：异常信息: Traceback (most recent call last):
  File "E:\Project_python\api_cms\common\requests_util.py", line 302, in send_request
    self.last_headers = self.replace_load(headers)
  File "E:\Project_python\api_cms\common\requests_util.py", line 142, in replace_load
    new_value = getattr(DubugTalk(), func_name)(*args_value.split(','))
TypeError: get_extract_data() takes 2 positional arguments but 3 were given

During handling of the above exception, another exception occurred:

Traceback (most recent call last):
  File "E:\Project_python\api_cms\common\requests_util.py", line 187, in analysis_yaml
    res = self.send_request(name =name,method=method,
  File "E:\Project_python\api_cms\common\requests_util.py", line 325, in send_request
    error_log("发送请求异常：异常信息: %s" % str(traceback.format_exc()))
  File "E:\Project_python\api_cms\common\logger_util.py", line 66, in error_log
    raise Exception(log_message)
Exception: 发送请求异常：异常信息: Traceback (most recent call last):
  File "E:\Project_python\api_cms\common\requests_util.py", line 302, in send_request
    self.last_headers = self.replace_load(headers)
  File "E:\Project_python\api_cms\common\requests_util.py", line 142, in replace_load
    new_value = getattr(DubugTalk(), func_name)(*args_value.split(','))
TypeError: get_extract_data() takes 2 positional arguments but 3 were given


[2023-08-23 14:08:13,876] logger_util.py->error_log line:65 [INFO] 发送请求异常：异常信息: Traceback (most recent call last):
  File "E:\Project_python\api_cms\common\requests_util.py", line 302, in send_request
    self.last_headers = self.replace_load(headers)
  File "E:\Project_python\api_cms\common\requests_util.py", line 142, in replace_load
    new_value = getattr(DubugTalk(), func_name)(*args_value.split(','))
TypeError: get_extract_data() takes 2 positional arguments but 3 were given

[2023-08-23 14:08:13,876] logger_util.py->error_log line:65 [INFO] 分析YAML文件异常：异常信息: Traceback (most recent call last):
  File "E:\Project_python\api_cms\common\requests_util.py", line 302, in send_request
    self.last_headers = self.replace_load(headers)
  File "E:\Project_python\api_cms\common\requests_util.py", line 142, in replace_load
    new_value = getattr(DubugTalk(), func_name)(*args_value.split(','))
TypeError: get_extract_data() takes 2 positional arguments but 3 were given

During handling of the above exception, another exception occurred:

Traceback (most recent call last):
  File "E:\Project_python\api_cms\common\requests_util.py", line 187, in analysis_yaml
    res = self.send_request(name =name,method=method,
  File "E:\Project_python\api_cms\common\requests_util.py", line 325, in send_request
    error_log("发送请求异常：异常信息: %s" % str(traceback.format_exc()))
  File "E:\Project_python\api_cms\common\logger_util.py", line 66, in error_log
    raise Exception(log_message)
Exception: 发送请求异常：异常信息: Traceback (most recent call last):
  File "E:\Project_python\api_cms\common\requests_util.py", line 302, in send_request
    self.last_headers = self.replace_load(headers)
  File "E:\Project_python\api_cms\common\requests_util.py", line 142, in replace_load
    new_value = getattr(DubugTalk(), func_name)(*args_value.split(','))
TypeError: get_extract_data() takes 2 positional arguments but 3 were given


[2023-08-23 14:08:13,905] logger_util.py->error_log line:65 [INFO] 发送请求异常：异常信息: Traceback (most recent call last):
  File "E:\Project_python\api_cms\common\requests_util.py", line 302, in send_request
    self.last_headers = self.replace_load(headers)
  File "E:\Project_python\api_cms\common\requests_util.py", line 142, in replace_load
    new_value = getattr(DubugTalk(), func_name)(*args_value.split(','))
TypeError: get_extract_data() takes 2 positional arguments but 3 were given

[2023-08-23 14:08:13,906] logger_util.py->error_log line:65 [INFO] 分析YAML文件异常：异常信息: Traceback (most recent call last):
  File "E:\Project_python\api_cms\common\requests_util.py", line 302, in send_request
    self.last_headers = self.replace_load(headers)
  File "E:\Project_python\api_cms\common\requests_util.py", line 142, in replace_load
    new_value = getattr(DubugTalk(), func_name)(*args_value.split(','))
TypeError: get_extract_data() takes 2 positional arguments but 3 were given

During handling of the above exception, another exception occurred:

Traceback (most recent call last):
  File "E:\Project_python\api_cms\common\requests_util.py", line 187, in analysis_yaml
    res = self.send_request(name =name,method=method,
  File "E:\Project_python\api_cms\common\requests_util.py", line 325, in send_request
    error_log("发送请求异常：异常信息: %s" % str(traceback.format_exc()))
  File "E:\Project_python\api_cms\common\logger_util.py", line 66, in error_log
    raise Exception(log_message)
Exception: 发送请求异常：异常信息: Traceback (most recent call last):
  File "E:\Project_python\api_cms\common\requests_util.py", line 302, in send_request
    self.last_headers = self.replace_load(headers)
  File "E:\Project_python\api_cms\common\requests_util.py", line 142, in replace_load
    new_value = getattr(DubugTalk(), func_name)(*args_value.split(','))
TypeError: get_extract_data() takes 2 positional arguments but 3 were given


[2023-08-23 14:08:13,934] logger_util.py->error_log line:65 [INFO] 发送请求异常：异常信息: Traceback (most recent call last):
  File "E:\Project_python\api_cms\common\requests_util.py", line 302, in send_request
    self.last_headers = self.replace_load(headers)
  File "E:\Project_python\api_cms\common\requests_util.py", line 142, in replace_load
    new_value = getattr(DubugTalk(), func_name)(*args_value.split(','))
TypeError: get_extract_data() takes 2 positional arguments but 3 were given

[2023-08-23 14:08:13,934] logger_util.py->error_log line:65 [INFO] 分析YAML文件异常：异常信息: Traceback (most recent call last):
  File "E:\Project_python\api_cms\common\requests_util.py", line 302, in send_request
    self.last_headers = self.replace_load(headers)
  File "E:\Project_python\api_cms\common\requests_util.py", line 142, in replace_load
    new_value = getattr(DubugTalk(), func_name)(*args_value.split(','))
TypeError: get_extract_data() takes 2 positional arguments but 3 were given

During handling of the above exception, another exception occurred:

Traceback (most recent call last):
  File "E:\Project_python\api_cms\common\requests_util.py", line 187, in analysis_yaml
    res = self.send_request(name =name,method=method,
  File "E:\Project_python\api_cms\common\requests_util.py", line 325, in send_request
    error_log("发送请求异常：异常信息: %s" % str(traceback.format_exc()))
  File "E:\Project_python\api_cms\common\logger_util.py", line 66, in error_log
    raise Exception(log_message)
Exception: 发送请求异常：异常信息: Traceback (most recent call last):
  File "E:\Project_python\api_cms\common\requests_util.py", line 302, in send_request
    self.last_headers = self.replace_load(headers)
  File "E:\Project_python\api_cms\common\requests_util.py", line 142, in replace_load
    new_value = getattr(DubugTalk(), func_name)(*args_value.split(','))
TypeError: get_extract_data() takes 2 positional arguments but 3 were given


[2023-08-23 14:08:13,961] logger_util.py->error_log line:65 [INFO] 发送请求异常：异常信息: Traceback (most recent call last):
  File "E:\Project_python\api_cms\common\requests_util.py", line 302, in send_request
    self.last_headers = self.replace_load(headers)
  File "E:\Project_python\api_cms\common\requests_util.py", line 142, in replace_load
    new_value = getattr(DubugTalk(), func_name)(*args_value.split(','))
TypeError: get_extract_data() takes 2 positional arguments but 3 were given

[2023-08-23 14:08:13,961] logger_util.py->error_log line:65 [INFO] 分析YAML文件异常：异常信息: Traceback (most recent call last):
  File "E:\Project_python\api_cms\common\requests_util.py", line 302, in send_request
    self.last_headers = self.replace_load(headers)
  File "E:\Project_python\api_cms\common\requests_util.py", line 142, in replace_load
    new_value = getattr(DubugTalk(), func_name)(*args_value.split(','))
TypeError: get_extract_data() takes 2 positional arguments but 3 were given

During handling of the above exception, another exception occurred:

Traceback (most recent call last):
  File "E:\Project_python\api_cms\common\requests_util.py", line 187, in analysis_yaml
    res = self.send_request(name =name,method=method,
  File "E:\Project_python\api_cms\common\requests_util.py", line 325, in send_request
    error_log("发送请求异常：异常信息: %s" % str(traceback.format_exc()))
  File "E:\Project_python\api_cms\common\logger_util.py", line 66, in error_log
    raise Exception(log_message)
Exception: 发送请求异常：异常信息: Traceback (most recent call last):
  File "E:\Project_python\api_cms\common\requests_util.py", line 302, in send_request
    self.last_headers = self.replace_load(headers)
  File "E:\Project_python\api_cms\common\requests_util.py", line 142, in replace_load
    new_value = getattr(DubugTalk(), func_name)(*args_value.split(','))
TypeError: get_extract_data() takes 2 positional arguments but 3 were given


[2023-08-23 14:08:13,988] logger_util.py->error_log line:65 [INFO] 发送请求异常：异常信息: Traceback (most recent call last):
  File "E:\Project_python\api_cms\common\requests_util.py", line 302, in send_request
    self.last_headers = self.replace_load(headers)
  File "E:\Project_python\api_cms\common\requests_util.py", line 142, in replace_load
    new_value = getattr(DubugTalk(), func_name)(*args_value.split(','))
TypeError: get_extract_data() takes 2 positional arguments but 3 were given

[2023-08-23 14:08:13,988] logger_util.py->error_log line:65 [INFO] 分析YAML文件异常：异常信息: Traceback (most recent call last):
  File "E:\Project_python\api_cms\common\requests_util.py", line 302, in send_request
    self.last_headers = self.replace_load(headers)
  File "E:\Project_python\api_cms\common\requests_util.py", line 142, in replace_load
    new_value = getattr(DubugTalk(), func_name)(*args_value.split(','))
TypeError: get_extract_data() takes 2 positional arguments but 3 were given

During handling of the above exception, another exception occurred:

Traceback (most recent call last):
  File "E:\Project_python\api_cms\common\requests_util.py", line 187, in analysis_yaml
    res = self.send_request(name =name,method=method,
  File "E:\Project_python\api_cms\common\requests_util.py", line 325, in send_request
    error_log("发送请求异常：异常信息: %s" % str(traceback.format_exc()))
  File "E:\Project_python\api_cms\common\logger_util.py", line 66, in error_log
    raise Exception(log_message)
Exception: 发送请求异常：异常信息: Traceback (most recent call last):
  File "E:\Project_python\api_cms\common\requests_util.py", line 302, in send_request
    self.last_headers = self.replace_load(headers)
  File "E:\Project_python\api_cms\common\requests_util.py", line 142, in replace_load
    new_value = getattr(DubugTalk(), func_name)(*args_value.split(','))
TypeError: get_extract_data() takes 2 positional arguments but 3 were given


[2023-08-23 14:08:14,016] logger_util.py->error_log line:65 [INFO] 发送请求异常：异常信息: Traceback (most recent call last):
  File "E:\Project_python\api_cms\common\requests_util.py", line 302, in send_request
    self.last_headers = self.replace_load(headers)
  File "E:\Project_python\api_cms\common\requests_util.py", line 142, in replace_load
    new_value = getattr(DubugTalk(), func_name)(*args_value.split(','))
TypeError: get_extract_data() takes 2 positional arguments but 3 were given

[2023-08-23 14:08:14,016] logger_util.py->error_log line:65 [INFO] 分析YAML文件异常：异常信息: Traceback (most recent call last):
  File "E:\Project_python\api_cms\common\requests_util.py", line 302, in send_request
    self.last_headers = self.replace_load(headers)
  File "E:\Project_python\api_cms\common\requests_util.py", line 142, in replace_load
    new_value = getattr(DubugTalk(), func_name)(*args_value.split(','))
TypeError: get_extract_data() takes 2 positional arguments but 3 were given

During handling of the above exception, another exception occurred:

Traceback (most recent call last):
  File "E:\Project_python\api_cms\common\requests_util.py", line 187, in analysis_yaml
    res = self.send_request(name =name,method=method,
  File "E:\Project_python\api_cms\common\requests_util.py", line 325, in send_request
    error_log("发送请求异常：异常信息: %s" % str(traceback.format_exc()))
  File "E:\Project_python\api_cms\common\logger_util.py", line 66, in error_log
    raise Exception(log_message)
Exception: 发送请求异常：异常信息: Traceback (most recent call last):
  File "E:\Project_python\api_cms\common\requests_util.py", line 302, in send_request
    self.last_headers = self.replace_load(headers)
  File "E:\Project_python\api_cms\common\requests_util.py", line 142, in replace_load
    new_value = getattr(DubugTalk(), func_name)(*args_value.split(','))
TypeError: get_extract_data() takes 2 positional arguments but 3 were given


[2023-08-23 14:08:14,046] logger_util.py->error_log line:65 [INFO] 发送请求异常：异常信息: Traceback (most recent call last):
  File "E:\Project_python\api_cms\common\requests_util.py", line 302, in send_request
    self.last_headers = self.replace_load(headers)
  File "E:\Project_python\api_cms\common\requests_util.py", line 142, in replace_load
    new_value = getattr(DubugTalk(), func_name)(*args_value.split(','))
TypeError: get_extract_data() takes 2 positional arguments but 3 were given

[2023-08-23 14:08:14,046] logger_util.py->error_log line:65 [INFO] 分析YAML文件异常：异常信息: Traceback (most recent call last):
  File "E:\Project_python\api_cms\common\requests_util.py", line 302, in send_request
    self.last_headers = self.replace_load(headers)
  File "E:\Project_python\api_cms\common\requests_util.py", line 142, in replace_load
    new_value = getattr(DubugTalk(), func_name)(*args_value.split(','))
TypeError: get_extract_data() takes 2 positional arguments but 3 were given

During handling of the above exception, another exception occurred:

Traceback (most recent call last):
  File "E:\Project_python\api_cms\common\requests_util.py", line 187, in analysis_yaml
    res = self.send_request(name =name,method=method,
  File "E:\Project_python\api_cms\common\requests_util.py", line 325, in send_request
    error_log("发送请求异常：异常信息: %s" % str(traceback.format_exc()))
  File "E:\Project_python\api_cms\common\logger_util.py", line 66, in error_log
    raise Exception(log_message)
Exception: 发送请求异常：异常信息: Traceback (most recent call last):
  File "E:\Project_python\api_cms\common\requests_util.py", line 302, in send_request
    self.last_headers = self.replace_load(headers)
  File "E:\Project_python\api_cms\common\requests_util.py", line 142, in replace_load
    new_value = getattr(DubugTalk(), func_name)(*args_value.split(','))
TypeError: get_extract_data() takes 2 positional arguments but 3 were given


[2023-08-23 14:08:14,075] logger_util.py->error_log line:65 [INFO] 发送请求异常：异常信息: Traceback (most recent call last):
  File "E:\Project_python\api_cms\common\requests_util.py", line 302, in send_request
    self.last_headers = self.replace_load(headers)
  File "E:\Project_python\api_cms\common\requests_util.py", line 142, in replace_load
    new_value = getattr(DubugTalk(), func_name)(*args_value.split(','))
TypeError: get_extract_data() takes 2 positional arguments but 3 were given

[2023-08-23 14:08:14,075] logger_util.py->error_log line:65 [INFO] 分析YAML文件异常：异常信息: Traceback (most recent call last):
  File "E:\Project_python\api_cms\common\requests_util.py", line 302, in send_request
    self.last_headers = self.replace_load(headers)
  File "E:\Project_python\api_cms\common\requests_util.py", line 142, in replace_load
    new_value = getattr(DubugTalk(), func_name)(*args_value.split(','))
TypeError: get_extract_data() takes 2 positional arguments but 3 were given

During handling of the above exception, another exception occurred:

Traceback (most recent call last):
  File "E:\Project_python\api_cms\common\requests_util.py", line 187, in analysis_yaml
    res = self.send_request(name =name,method=method,
  File "E:\Project_python\api_cms\common\requests_util.py", line 325, in send_request
    error_log("发送请求异常：异常信息: %s" % str(traceback.format_exc()))
  File "E:\Project_python\api_cms\common\logger_util.py", line 66, in error_log
    raise Exception(log_message)
Exception: 发送请求异常：异常信息: Traceback (most recent call last):
  File "E:\Project_python\api_cms\common\requests_util.py", line 302, in send_request
    self.last_headers = self.replace_load(headers)
  File "E:\Project_python\api_cms\common\requests_util.py", line 142, in replace_load
    new_value = getattr(DubugTalk(), func_name)(*args_value.split(','))
TypeError: get_extract_data() takes 2 positional arguments but 3 were given


[2023-08-23 14:08:14,103] logger_util.py->error_log line:65 [INFO] 发送请求异常：异常信息: Traceback (most recent call last):
  File "E:\Project_python\api_cms\common\requests_util.py", line 302, in send_request
    self.last_headers = self.replace_load(headers)
  File "E:\Project_python\api_cms\common\requests_util.py", line 142, in replace_load
    new_value = getattr(DubugTalk(), func_name)(*args_value.split(','))
TypeError: get_extract_data() takes 2 positional arguments but 3 were given

[2023-08-23 14:08:14,103] logger_util.py->error_log line:65 [INFO] 分析YAML文件异常：异常信息: Traceback (most recent call last):
  File "E:\Project_python\api_cms\common\requests_util.py", line 302, in send_request
    self.last_headers = self.replace_load(headers)
  File "E:\Project_python\api_cms\common\requests_util.py", line 142, in replace_load
    new_value = getattr(DubugTalk(), func_name)(*args_value.split(','))
TypeError: get_extract_data() takes 2 positional arguments but 3 were given

During handling of the above exception, another exception occurred:

Traceback (most recent call last):
  File "E:\Project_python\api_cms\common\requests_util.py", line 187, in analysis_yaml
    res = self.send_request(name =name,method=method,
  File "E:\Project_python\api_cms\common\requests_util.py", line 325, in send_request
    error_log("发送请求异常：异常信息: %s" % str(traceback.format_exc()))
  File "E:\Project_python\api_cms\common\logger_util.py", line 66, in error_log
    raise Exception(log_message)
Exception: 发送请求异常：异常信息: Traceback (most recent call last):
  File "E:\Project_python\api_cms\common\requests_util.py", line 302, in send_request
    self.last_headers = self.replace_load(headers)
  File "E:\Project_python\api_cms\common\requests_util.py", line 142, in replace_load
    new_value = getattr(DubugTalk(), func_name)(*args_value.split(','))
TypeError: get_extract_data() takes 2 positional arguments but 3 were given


[2023-08-23 14:08:14,132] logger_util.py->error_log line:65 [INFO] 发送请求异常：异常信息: Traceback (most recent call last):
  File "E:\Project_python\api_cms\common\requests_util.py", line 302, in send_request
    self.last_headers = self.replace_load(headers)
  File "E:\Project_python\api_cms\common\requests_util.py", line 142, in replace_load
    new_value = getattr(DubugTalk(), func_name)(*args_value.split(','))
TypeError: get_extract_data() takes 2 positional arguments but 3 were given

[2023-08-23 14:08:14,132] logger_util.py->error_log line:65 [INFO] 分析YAML文件异常：异常信息: Traceback (most recent call last):
  File "E:\Project_python\api_cms\common\requests_util.py", line 302, in send_request
    self.last_headers = self.replace_load(headers)
  File "E:\Project_python\api_cms\common\requests_util.py", line 142, in replace_load
    new_value = getattr(DubugTalk(), func_name)(*args_value.split(','))
TypeError: get_extract_data() takes 2 positional arguments but 3 were given

During handling of the above exception, another exception occurred:

Traceback (most recent call last):
  File "E:\Project_python\api_cms\common\requests_util.py", line 187, in analysis_yaml
    res = self.send_request(name =name,method=method,
  File "E:\Project_python\api_cms\common\requests_util.py", line 325, in send_request
    error_log("发送请求异常：异常信息: %s" % str(traceback.format_exc()))
  File "E:\Project_python\api_cms\common\logger_util.py", line 66, in error_log
    raise Exception(log_message)
Exception: 发送请求异常：异常信息: Traceback (most recent call last):
  File "E:\Project_python\api_cms\common\requests_util.py", line 302, in send_request
    self.last_headers = self.replace_load(headers)
  File "E:\Project_python\api_cms\common\requests_util.py", line 142, in replace_load
    new_value = getattr(DubugTalk(), func_name)(*args_value.split(','))
TypeError: get_extract_data() takes 2 positional arguments but 3 were given


[2023-08-23 14:08:14,159] logger_util.py->error_log line:65 [INFO] 发送请求异常：异常信息: Traceback (most recent call last):
  File "E:\Project_python\api_cms\common\requests_util.py", line 302, in send_request
    self.last_headers = self.replace_load(headers)
  File "E:\Project_python\api_cms\common\requests_util.py", line 142, in replace_load
    new_value = getattr(DubugTalk(), func_name)(*args_value.split(','))
TypeError: get_extract_data() takes 2 positional arguments but 3 were given

[2023-08-23 14:08:14,159] logger_util.py->error_log line:65 [INFO] 分析YAML文件异常：异常信息: Traceback (most recent call last):
  File "E:\Project_python\api_cms\common\requests_util.py", line 302, in send_request
    self.last_headers = self.replace_load(headers)
  File "E:\Project_python\api_cms\common\requests_util.py", line 142, in replace_load
    new_value = getattr(DubugTalk(), func_name)(*args_value.split(','))
TypeError: get_extract_data() takes 2 positional arguments but 3 were given

During handling of the above exception, another exception occurred:

Traceback (most recent call last):
  File "E:\Project_python\api_cms\common\requests_util.py", line 187, in analysis_yaml
    res = self.send_request(name =name,method=method,
  File "E:\Project_python\api_cms\common\requests_util.py", line 325, in send_request
    error_log("发送请求异常：异常信息: %s" % str(traceback.format_exc()))
  File "E:\Project_python\api_cms\common\logger_util.py", line 66, in error_log
    raise Exception(log_message)
Exception: 发送请求异常：异常信息: Traceback (most recent call last):
  File "E:\Project_python\api_cms\common\requests_util.py", line 302, in send_request
    self.last_headers = self.replace_load(headers)
  File "E:\Project_python\api_cms\common\requests_util.py", line 142, in replace_load
    new_value = getattr(DubugTalk(), func_name)(*args_value.split(','))
TypeError: get_extract_data() takes 2 positional arguments but 3 were given


[2023-08-23 14:08:14,188] logger_util.py->error_log line:65 [INFO] 发送请求异常：异常信息: Traceback (most recent call last):
  File "E:\Project_python\api_cms\common\requests_util.py", line 302, in send_request
    self.last_headers = self.replace_load(headers)
  File "E:\Project_python\api_cms\common\requests_util.py", line 142, in replace_load
    new_value = getattr(DubugTalk(), func_name)(*args_value.split(','))
TypeError: get_extract_data() takes 2 positional arguments but 3 were given

[2023-08-23 14:08:14,188] logger_util.py->error_log line:65 [INFO] 分析YAML文件异常：异常信息: Traceback (most recent call last):
  File "E:\Project_python\api_cms\common\requests_util.py", line 302, in send_request
    self.last_headers = self.replace_load(headers)
  File "E:\Project_python\api_cms\common\requests_util.py", line 142, in replace_load
    new_value = getattr(DubugTalk(), func_name)(*args_value.split(','))
TypeError: get_extract_data() takes 2 positional arguments but 3 were given

During handling of the above exception, another exception occurred:

Traceback (most recent call last):
  File "E:\Project_python\api_cms\common\requests_util.py", line 187, in analysis_yaml
    res = self.send_request(name =name,method=method,
  File "E:\Project_python\api_cms\common\requests_util.py", line 325, in send_request
    error_log("发送请求异常：异常信息: %s" % str(traceback.format_exc()))
  File "E:\Project_python\api_cms\common\logger_util.py", line 66, in error_log
    raise Exception(log_message)
Exception: 发送请求异常：异常信息: Traceback (most recent call last):
  File "E:\Project_python\api_cms\common\requests_util.py", line 302, in send_request
    self.last_headers = self.replace_load(headers)
  File "E:\Project_python\api_cms\common\requests_util.py", line 142, in replace_load
    new_value = getattr(DubugTalk(), func_name)(*args_value.split(','))
TypeError: get_extract_data() takes 2 positional arguments but 3 were given


[2023-08-23 14:08:14,217] logger_util.py->error_log line:65 [INFO] 发送请求异常：异常信息: Traceback (most recent call last):
  File "E:\Project_python\api_cms\common\requests_util.py", line 302, in send_request
    self.last_headers = self.replace_load(headers)
  File "E:\Project_python\api_cms\common\requests_util.py", line 142, in replace_load
    new_value = getattr(DubugTalk(), func_name)(*args_value.split(','))
TypeError: get_extract_data() takes 2 positional arguments but 3 were given

[2023-08-23 14:08:14,217] logger_util.py->error_log line:65 [INFO] 分析YAML文件异常：异常信息: Traceback (most recent call last):
  File "E:\Project_python\api_cms\common\requests_util.py", line 302, in send_request
    self.last_headers = self.replace_load(headers)
  File "E:\Project_python\api_cms\common\requests_util.py", line 142, in replace_load
    new_value = getattr(DubugTalk(), func_name)(*args_value.split(','))
TypeError: get_extract_data() takes 2 positional arguments but 3 were given

During handling of the above exception, another exception occurred:

Traceback (most recent call last):
  File "E:\Project_python\api_cms\common\requests_util.py", line 187, in analysis_yaml
    res = self.send_request(name =name,method=method,
  File "E:\Project_python\api_cms\common\requests_util.py", line 325, in send_request
    error_log("发送请求异常：异常信息: %s" % str(traceback.format_exc()))
  File "E:\Project_python\api_cms\common\logger_util.py", line 66, in error_log
    raise Exception(log_message)
Exception: 发送请求异常：异常信息: Traceback (most recent call last):
  File "E:\Project_python\api_cms\common\requests_util.py", line 302, in send_request
    self.last_headers = self.replace_load(headers)
  File "E:\Project_python\api_cms\common\requests_util.py", line 142, in replace_load
    new_value = getattr(DubugTalk(), func_name)(*args_value.split(','))
TypeError: get_extract_data() takes 2 positional arguments but 3 were given


[2023-08-23 14:08:14,246] logger_util.py->error_log line:65 [INFO] 发送请求异常：异常信息: Traceback (most recent call last):
  File "E:\Project_python\api_cms\common\requests_util.py", line 302, in send_request
    self.last_headers = self.replace_load(headers)
  File "E:\Project_python\api_cms\common\requests_util.py", line 142, in replace_load
    new_value = getattr(DubugTalk(), func_name)(*args_value.split(','))
TypeError: get_extract_data() takes 2 positional arguments but 3 were given

[2023-08-23 14:08:14,246] logger_util.py->error_log line:65 [INFO] 分析YAML文件异常：异常信息: Traceback (most recent call last):
  File "E:\Project_python\api_cms\common\requests_util.py", line 302, in send_request
    self.last_headers = self.replace_load(headers)
  File "E:\Project_python\api_cms\common\requests_util.py", line 142, in replace_load
    new_value = getattr(DubugTalk(), func_name)(*args_value.split(','))
TypeError: get_extract_data() takes 2 positional arguments but 3 were given

During handling of the above exception, another exception occurred:

Traceback (most recent call last):
  File "E:\Project_python\api_cms\common\requests_util.py", line 187, in analysis_yaml
    res = self.send_request(name =name,method=method,
  File "E:\Project_python\api_cms\common\requests_util.py", line 325, in send_request
    error_log("发送请求异常：异常信息: %s" % str(traceback.format_exc()))
  File "E:\Project_python\api_cms\common\logger_util.py", line 66, in error_log
    raise Exception(log_message)
Exception: 发送请求异常：异常信息: Traceback (most recent call last):
  File "E:\Project_python\api_cms\common\requests_util.py", line 302, in send_request
    self.last_headers = self.replace_load(headers)
  File "E:\Project_python\api_cms\common\requests_util.py", line 142, in replace_load
    new_value = getattr(DubugTalk(), func_name)(*args_value.split(','))
TypeError: get_extract_data() takes 2 positional arguments but 3 were given


[2023-08-23 14:08:14,286] logger_util.py->error_log line:65 [INFO] 发送请求异常：异常信息: Traceback (most recent call last):
  File "E:\Project_python\api_cms\common\requests_util.py", line 302, in send_request
    self.last_headers = self.replace_load(headers)
  File "E:\Project_python\api_cms\common\requests_util.py", line 142, in replace_load
    new_value = getattr(DubugTalk(), func_name)(*args_value.split(','))
TypeError: get_extract_data() takes 2 positional arguments but 3 were given

[2023-08-23 14:08:14,286] logger_util.py->error_log line:65 [INFO] 分析YAML文件异常：异常信息: Traceback (most recent call last):
  File "E:\Project_python\api_cms\common\requests_util.py", line 302, in send_request
    self.last_headers = self.replace_load(headers)
  File "E:\Project_python\api_cms\common\requests_util.py", line 142, in replace_load
    new_value = getattr(DubugTalk(), func_name)(*args_value.split(','))
TypeError: get_extract_data() takes 2 positional arguments but 3 were given

During handling of the above exception, another exception occurred:

Traceback (most recent call last):
  File "E:\Project_python\api_cms\common\requests_util.py", line 187, in analysis_yaml
    res = self.send_request(name =name,method=method,
  File "E:\Project_python\api_cms\common\requests_util.py", line 325, in send_request
    error_log("发送请求异常：异常信息: %s" % str(traceback.format_exc()))
  File "E:\Project_python\api_cms\common\logger_util.py", line 66, in error_log
    raise Exception(log_message)
Exception: 发送请求异常：异常信息: Traceback (most recent call last):
  File "E:\Project_python\api_cms\common\requests_util.py", line 302, in send_request
    self.last_headers = self.replace_load(headers)
  File "E:\Project_python\api_cms\common\requests_util.py", line 142, in replace_load
    new_value = getattr(DubugTalk(), func_name)(*args_value.split(','))
TypeError: get_extract_data() takes 2 positional arguments but 3 were given


[2023-08-23 14:08:14,314] logger_util.py->error_log line:65 [INFO] 发送请求异常：异常信息: Traceback (most recent call last):
  File "E:\Project_python\api_cms\common\requests_util.py", line 302, in send_request
    self.last_headers = self.replace_load(headers)
  File "E:\Project_python\api_cms\common\requests_util.py", line 142, in replace_load
    new_value = getattr(DubugTalk(), func_name)(*args_value.split(','))
TypeError: get_extract_data() takes 2 positional arguments but 3 were given

[2023-08-23 14:08:14,314] logger_util.py->error_log line:65 [INFO] 分析YAML文件异常：异常信息: Traceback (most recent call last):
  File "E:\Project_python\api_cms\common\requests_util.py", line 302, in send_request
    self.last_headers = self.replace_load(headers)
  File "E:\Project_python\api_cms\common\requests_util.py", line 142, in replace_load
    new_value = getattr(DubugTalk(), func_name)(*args_value.split(','))
TypeError: get_extract_data() takes 2 positional arguments but 3 were given

During handling of the above exception, another exception occurred:

Traceback (most recent call last):
  File "E:\Project_python\api_cms\common\requests_util.py", line 187, in analysis_yaml
    res = self.send_request(name =name,method=method,
  File "E:\Project_python\api_cms\common\requests_util.py", line 325, in send_request
    error_log("发送请求异常：异常信息: %s" % str(traceback.format_exc()))
  File "E:\Project_python\api_cms\common\logger_util.py", line 66, in error_log
    raise Exception(log_message)
Exception: 发送请求异常：异常信息: Traceback (most recent call last):
  File "E:\Project_python\api_cms\common\requests_util.py", line 302, in send_request
    self.last_headers = self.replace_load(headers)
  File "E:\Project_python\api_cms\common\requests_util.py", line 142, in replace_load
    new_value = getattr(DubugTalk(), func_name)(*args_value.split(','))
TypeError: get_extract_data() takes 2 positional arguments but 3 were given


[2023-08-23 14:08:14,343] logger_util.py->error_log line:65 [INFO] 发送请求异常：异常信息: Traceback (most recent call last):
  File "E:\Project_python\api_cms\common\requests_util.py", line 302, in send_request
    self.last_headers = self.replace_load(headers)
  File "E:\Project_python\api_cms\common\requests_util.py", line 142, in replace_load
    new_value = getattr(DubugTalk(), func_name)(*args_value.split(','))
TypeError: get_extract_data() takes 2 positional arguments but 3 were given

[2023-08-23 14:08:14,343] logger_util.py->error_log line:65 [INFO] 分析YAML文件异常：异常信息: Traceback (most recent call last):
  File "E:\Project_python\api_cms\common\requests_util.py", line 302, in send_request
    self.last_headers = self.replace_load(headers)
  File "E:\Project_python\api_cms\common\requests_util.py", line 142, in replace_load
    new_value = getattr(DubugTalk(), func_name)(*args_value.split(','))
TypeError: get_extract_data() takes 2 positional arguments but 3 were given

During handling of the above exception, another exception occurred:

Traceback (most recent call last):
  File "E:\Project_python\api_cms\common\requests_util.py", line 187, in analysis_yaml
    res = self.send_request(name =name,method=method,
  File "E:\Project_python\api_cms\common\requests_util.py", line 325, in send_request
    error_log("发送请求异常：异常信息: %s" % str(traceback.format_exc()))
  File "E:\Project_python\api_cms\common\logger_util.py", line 66, in error_log
    raise Exception(log_message)
Exception: 发送请求异常：异常信息: Traceback (most recent call last):
  File "E:\Project_python\api_cms\common\requests_util.py", line 302, in send_request
    self.last_headers = self.replace_load(headers)
  File "E:\Project_python\api_cms\common\requests_util.py", line 142, in replace_load
    new_value = getattr(DubugTalk(), func_name)(*args_value.split(','))
TypeError: get_extract_data() takes 2 positional arguments but 3 were given


