[2023-08-23 13:49:11,422] logger_util.py->write_log line:61 [INFO] 
-------------接口请求开始-----------
[2023-08-23 13:49:11,423] logger_util.py->write_log line:61 [INFO] 接口名称：新增io变量
[2023-08-23 13:49:11,423] logger_util.py->write_log line:61 [INFO] 接口方式：post
[2023-08-23 13:49:11,423] logger_util.py->write_log line:61 [INFO] 接口路径：http://127.0.0.1:18000/api/v1/variable/tunnel/80/tag
[2023-08-23 13:49:11,423] logger_util.py->write_log line:61 [INFO] 请求头：{}
[2023-08-23 13:49:11,423] logger_util.py->write_log line:61 [INFO] 请求参数：[{'archiveSetting': None, 'groupId': None, 'name': 'B1', 'description': '缩放比10', 'typeName': '有符号8位整型', 'config': {'readWriteMode': 0, 'address': '400080', 'interval': '10000', 'stringLength': 'null', 'zoom': '10', 'digit': 'null', 'readWriteRule': '1'}, 'index': '1'}]
[2023-08-23 13:49:11,424] logger_util.py->write_log line:61 [INFO] 文件上传：None
[2023-08-23 13:49:11,441] logger_util.py->error_log line:65 [INFO] 断言失败:status_code不等于200
[2023-08-23 13:49:11,441] logger_util.py->write_log line:61 [INFO] 实际结果：序号<1>变量配置错误
[2023-08-23 13:49:11,441] logger_util.py->write_log line:61 [INFO] 接口请求失败！
[2023-08-23 13:49:11,441] logger_util.py->write_log line:61 [INFO] -------------接口请求结束-----------

[2023-08-23 13:49:11,442] logger_util.py->error_log line:65 [INFO] 断言异常：异常信息: Traceback (most recent call last):
  File "E:\Project_python\api_cms\common\requests_util.py", line 353, in validate_result
    error_log("断言失败:"+assert_key+"不等于"+str(assert_value))
  File "E:\Project_python\api_cms\common\logger_util.py", line 66, in error_log
    raise Exception(log_message)
Exception: 断言失败:status_code不等于200

[2023-08-23 13:49:11,442] logger_util.py->error_log line:65 [INFO] 分析YAML文件异常：异常信息: Traceback (most recent call last):
  File "E:\Project_python\api_cms\common\requests_util.py", line 353, in validate_result
    error_log("断言失败:"+assert_key+"不等于"+str(assert_value))
  File "E:\Project_python\api_cms\common\logger_util.py", line 66, in error_log
    raise Exception(log_message)
Exception: 断言失败:status_code不等于200

During handling of the above exception, another exception occurred:

Traceback (most recent call last):
  File "E:\Project_python\api_cms\common\requests_util.py", line 255, in analysis_yaml
    self.validate_result(yq_result, return_text, status_code)
  File "E:\Project_python\api_cms\common\requests_util.py", line 408, in validate_result
    error_log("断言异常：异常信息: %s" % str(traceback.format_exc()))
  File "E:\Project_python\api_cms\common\logger_util.py", line 66, in error_log
    raise Exception(log_message)
Exception: 断言异常：异常信息: Traceback (most recent call last):
  File "E:\Project_python\api_cms\common\requests_util.py", line 353, in validate_result
    error_log("断言失败:"+assert_key+"不等于"+str(assert_value))
  File "E:\Project_python\api_cms\common\logger_util.py", line 66, in error_log
    raise Exception(log_message)
Exception: 断言失败:status_code不等于200


[2023-08-23 13:49:11,541] logger_util.py->write_log line:61 [INFO] 
-------------接口请求开始-----------
[2023-08-23 13:49:11,541] logger_util.py->write_log line:61 [INFO] 接口名称：新增io变量
[2023-08-23 13:49:11,541] logger_util.py->write_log line:61 [INFO] 接口方式：post
[2023-08-23 13:49:11,541] logger_util.py->write_log line:61 [INFO] 接口路径：http://127.0.0.1:18000/api/v1/variable/tunnel/80/tag
[2023-08-23 13:49:11,541] logger_util.py->write_log line:61 [INFO] 请求头：{}
[2023-08-23 13:49:11,541] logger_util.py->write_log line:61 [INFO] 请求参数：[{'archiveSetting': None, 'groupId': None, 'name': 'B2', 'description': '缩放比0.1', 'typeName': '有符号8位整型', 'config': {'readWriteMode': 0, 'address': '400081', 'interval': '10000', 'stringLength': 'null', 'zoom': '0.1', 'digit': 'null', 'readWriteRule': '1'}, 'index': '2'}]
[2023-08-23 13:49:11,542] logger_util.py->write_log line:61 [INFO] 文件上传：None
[2023-08-23 13:49:11,549] logger_util.py->error_log line:65 [INFO] 断言失败:status_code不等于200
[2023-08-23 13:49:11,549] logger_util.py->write_log line:61 [INFO] 实际结果：序号<2>变量配置错误
[2023-08-23 13:49:11,549] logger_util.py->write_log line:61 [INFO] 接口请求失败！
[2023-08-23 13:49:11,550] logger_util.py->write_log line:61 [INFO] -------------接口请求结束-----------

[2023-08-23 13:49:11,550] logger_util.py->error_log line:65 [INFO] 断言异常：异常信息: Traceback (most recent call last):
  File "E:\Project_python\api_cms\common\requests_util.py", line 353, in validate_result
    error_log("断言失败:"+assert_key+"不等于"+str(assert_value))
  File "E:\Project_python\api_cms\common\logger_util.py", line 66, in error_log
    raise Exception(log_message)
Exception: 断言失败:status_code不等于200

[2023-08-23 13:49:11,550] logger_util.py->error_log line:65 [INFO] 分析YAML文件异常：异常信息: Traceback (most recent call last):
  File "E:\Project_python\api_cms\common\requests_util.py", line 353, in validate_result
    error_log("断言失败:"+assert_key+"不等于"+str(assert_value))
  File "E:\Project_python\api_cms\common\logger_util.py", line 66, in error_log
    raise Exception(log_message)
Exception: 断言失败:status_code不等于200

During handling of the above exception, another exception occurred:

Traceback (most recent call last):
  File "E:\Project_python\api_cms\common\requests_util.py", line 255, in analysis_yaml
    self.validate_result(yq_result, return_text, status_code)
  File "E:\Project_python\api_cms\common\requests_util.py", line 408, in validate_result
    error_log("断言异常：异常信息: %s" % str(traceback.format_exc()))
  File "E:\Project_python\api_cms\common\logger_util.py", line 66, in error_log
    raise Exception(log_message)
Exception: 断言异常：异常信息: Traceback (most recent call last):
  File "E:\Project_python\api_cms\common\requests_util.py", line 353, in validate_result
    error_log("断言失败:"+assert_key+"不等于"+str(assert_value))
  File "E:\Project_python\api_cms\common\logger_util.py", line 66, in error_log
    raise Exception(log_message)
Exception: 断言失败:status_code不等于200


[2023-08-23 13:49:11,577] logger_util.py->write_log line:61 [INFO] 
-------------接口请求开始-----------
[2023-08-23 13:49:11,577] logger_util.py->write_log line:61 [INFO] 接口名称：新增io变量
[2023-08-23 13:49:11,577] logger_util.py->write_log line:61 [INFO] 接口方式：post
[2023-08-23 13:49:11,578] logger_util.py->write_log line:61 [INFO] 接口路径：http://127.0.0.1:18000/api/v1/variable/tunnel/80/tag
[2023-08-23 13:49:11,578] logger_util.py->write_log line:61 [INFO] 请求头：{}
[2023-08-23 13:49:11,578] logger_util.py->write_log line:61 [INFO] 请求参数：[{'archiveSetting': None, 'groupId': None, 'name': 'B3', 'description': '验证缩放比小数位，舍位', 'typeName': '有符号16位整型', 'config': {'readWriteMode': 0, 'address': '400082', 'interval': '10000', 'stringLength': 'null', 'zoom': '0.01', 'digit': '1', 'readWriteRule': '1'}, 'index': '3'}]
[2023-08-23 13:49:11,578] logger_util.py->write_log line:61 [INFO] 文件上传：None
[2023-08-23 13:49:11,585] logger_util.py->error_log line:65 [INFO] 断言失败:status_code不等于200
[2023-08-23 13:49:11,586] logger_util.py->write_log line:61 [INFO] 实际结果：序号<3>变量配置错误
[2023-08-23 13:49:11,586] logger_util.py->write_log line:61 [INFO] 接口请求失败！
[2023-08-23 13:49:11,586] logger_util.py->write_log line:61 [INFO] -------------接口请求结束-----------

[2023-08-23 13:49:11,586] logger_util.py->error_log line:65 [INFO] 断言异常：异常信息: Traceback (most recent call last):
  File "E:\Project_python\api_cms\common\requests_util.py", line 353, in validate_result
    error_log("断言失败:"+assert_key+"不等于"+str(assert_value))
  File "E:\Project_python\api_cms\common\logger_util.py", line 66, in error_log
    raise Exception(log_message)
Exception: 断言失败:status_code不等于200

[2023-08-23 13:49:11,586] logger_util.py->error_log line:65 [INFO] 分析YAML文件异常：异常信息: Traceback (most recent call last):
  File "E:\Project_python\api_cms\common\requests_util.py", line 353, in validate_result
    error_log("断言失败:"+assert_key+"不等于"+str(assert_value))
  File "E:\Project_python\api_cms\common\logger_util.py", line 66, in error_log
    raise Exception(log_message)
Exception: 断言失败:status_code不等于200

During handling of the above exception, another exception occurred:

Traceback (most recent call last):
  File "E:\Project_python\api_cms\common\requests_util.py", line 255, in analysis_yaml
    self.validate_result(yq_result, return_text, status_code)
  File "E:\Project_python\api_cms\common\requests_util.py", line 408, in validate_result
    error_log("断言异常：异常信息: %s" % str(traceback.format_exc()))
  File "E:\Project_python\api_cms\common\logger_util.py", line 66, in error_log
    raise Exception(log_message)
Exception: 断言异常：异常信息: Traceback (most recent call last):
  File "E:\Project_python\api_cms\common\requests_util.py", line 353, in validate_result
    error_log("断言失败:"+assert_key+"不等于"+str(assert_value))
  File "E:\Project_python\api_cms\common\logger_util.py", line 66, in error_log
    raise Exception(log_message)
Exception: 断言失败:status_code不等于200


[2023-08-23 13:49:11,612] logger_util.py->write_log line:61 [INFO] 
-------------接口请求开始-----------
[2023-08-23 13:49:11,612] logger_util.py->write_log line:61 [INFO] 接口名称：新增io变量
[2023-08-23 13:49:11,613] logger_util.py->write_log line:61 [INFO] 接口方式：post
[2023-08-23 13:49:11,613] logger_util.py->write_log line:61 [INFO] 接口路径：http://127.0.0.1:18000/api/v1/variable/tunnel/80/tag
[2023-08-23 13:49:11,613] logger_util.py->write_log line:61 [INFO] 请求头：{}
[2023-08-23 13:49:11,613] logger_util.py->write_log line:61 [INFO] 请求参数：[{'archiveSetting': None, 'groupId': None, 'name': 'B4', 'description': '验证缩放比小数位，四舍', 'typeName': '有符号16位整型', 'config': {'readWriteMode': 0, 'address': '400083', 'interval': '10000', 'stringLength': 'null', 'zoom': '0.01', 'digit': '1', 'readWriteRule': '2'}, 'index': '4'}]
[2023-08-23 13:49:11,613] logger_util.py->write_log line:61 [INFO] 文件上传：None
[2023-08-23 13:49:11,620] logger_util.py->error_log line:65 [INFO] 断言失败:status_code不等于200
[2023-08-23 13:49:11,621] logger_util.py->write_log line:61 [INFO] 实际结果：序号<4>变量配置错误
[2023-08-23 13:49:11,621] logger_util.py->write_log line:61 [INFO] 接口请求失败！
[2023-08-23 13:49:11,621] logger_util.py->write_log line:61 [INFO] -------------接口请求结束-----------

[2023-08-23 13:49:11,621] logger_util.py->error_log line:65 [INFO] 断言异常：异常信息: Traceback (most recent call last):
  File "E:\Project_python\api_cms\common\requests_util.py", line 353, in validate_result
    error_log("断言失败:"+assert_key+"不等于"+str(assert_value))
  File "E:\Project_python\api_cms\common\logger_util.py", line 66, in error_log
    raise Exception(log_message)
Exception: 断言失败:status_code不等于200

[2023-08-23 13:49:11,621] logger_util.py->error_log line:65 [INFO] 分析YAML文件异常：异常信息: Traceback (most recent call last):
  File "E:\Project_python\api_cms\common\requests_util.py", line 353, in validate_result
    error_log("断言失败:"+assert_key+"不等于"+str(assert_value))
  File "E:\Project_python\api_cms\common\logger_util.py", line 66, in error_log
    raise Exception(log_message)
Exception: 断言失败:status_code不等于200

During handling of the above exception, another exception occurred:

Traceback (most recent call last):
  File "E:\Project_python\api_cms\common\requests_util.py", line 255, in analysis_yaml
    self.validate_result(yq_result, return_text, status_code)
  File "E:\Project_python\api_cms\common\requests_util.py", line 408, in validate_result
    error_log("断言异常：异常信息: %s" % str(traceback.format_exc()))
  File "E:\Project_python\api_cms\common\logger_util.py", line 66, in error_log
    raise Exception(log_message)
Exception: 断言异常：异常信息: Traceback (most recent call last):
  File "E:\Project_python\api_cms\common\requests_util.py", line 353, in validate_result
    error_log("断言失败:"+assert_key+"不等于"+str(assert_value))
  File "E:\Project_python\api_cms\common\logger_util.py", line 66, in error_log
    raise Exception(log_message)
Exception: 断言失败:status_code不等于200


[2023-08-23 13:49:11,648] logger_util.py->write_log line:61 [INFO] 
-------------接口请求开始-----------
[2023-08-23 13:49:11,648] logger_util.py->write_log line:61 [INFO] 接口名称：新增io变量
[2023-08-23 13:49:11,648] logger_util.py->write_log line:61 [INFO] 接口方式：post
[2023-08-23 13:49:11,648] logger_util.py->write_log line:61 [INFO] 接口路径：http://127.0.0.1:18000/api/v1/variable/tunnel/80/tag
[2023-08-23 13:49:11,648] logger_util.py->write_log line:61 [INFO] 请求头：{}
[2023-08-23 13:49:11,648] logger_util.py->write_log line:61 [INFO] 请求参数：[{'archiveSetting': None, 'groupId': None, 'name': 'B5', 'description': '验证缩放比小数位，进位', 'typeName': '有符号16位整型', 'config': {'readWriteMode': 0, 'address': '400084', 'interval': '10000', 'stringLength': 'null', 'zoom': '0.01', 'digit': '1', 'readWriteRule': '3'}, 'index': '5'}]
[2023-08-23 13:49:11,648] logger_util.py->write_log line:61 [INFO] 文件上传：None
[2023-08-23 13:49:11,656] logger_util.py->error_log line:65 [INFO] 断言失败:status_code不等于200
[2023-08-23 13:49:11,656] logger_util.py->write_log line:61 [INFO] 实际结果：序号<5>变量配置错误
[2023-08-23 13:49:11,656] logger_util.py->write_log line:61 [INFO] 接口请求失败！
[2023-08-23 13:49:11,656] logger_util.py->write_log line:61 [INFO] -------------接口请求结束-----------

[2023-08-23 13:49:11,657] logger_util.py->error_log line:65 [INFO] 断言异常：异常信息: Traceback (most recent call last):
  File "E:\Project_python\api_cms\common\requests_util.py", line 353, in validate_result
    error_log("断言失败:"+assert_key+"不等于"+str(assert_value))
  File "E:\Project_python\api_cms\common\logger_util.py", line 66, in error_log
    raise Exception(log_message)
Exception: 断言失败:status_code不等于200

[2023-08-23 13:49:11,657] logger_util.py->error_log line:65 [INFO] 分析YAML文件异常：异常信息: Traceback (most recent call last):
  File "E:\Project_python\api_cms\common\requests_util.py", line 353, in validate_result
    error_log("断言失败:"+assert_key+"不等于"+str(assert_value))
  File "E:\Project_python\api_cms\common\logger_util.py", line 66, in error_log
    raise Exception(log_message)
Exception: 断言失败:status_code不等于200

During handling of the above exception, another exception occurred:

Traceback (most recent call last):
  File "E:\Project_python\api_cms\common\requests_util.py", line 255, in analysis_yaml
    self.validate_result(yq_result, return_text, status_code)
  File "E:\Project_python\api_cms\common\requests_util.py", line 408, in validate_result
    error_log("断言异常：异常信息: %s" % str(traceback.format_exc()))
  File "E:\Project_python\api_cms\common\logger_util.py", line 66, in error_log
    raise Exception(log_message)
Exception: 断言异常：异常信息: Traceback (most recent call last):
  File "E:\Project_python\api_cms\common\requests_util.py", line 353, in validate_result
    error_log("断言失败:"+assert_key+"不等于"+str(assert_value))
  File "E:\Project_python\api_cms\common\logger_util.py", line 66, in error_log
    raise Exception(log_message)
Exception: 断言失败:status_code不等于200


[2023-08-23 13:49:11,683] logger_util.py->write_log line:61 [INFO] 
-------------接口请求开始-----------
[2023-08-23 13:49:11,683] logger_util.py->write_log line:61 [INFO] 接口名称：新增io变量
[2023-08-23 13:49:11,683] logger_util.py->write_log line:61 [INFO] 接口方式：post
[2023-08-23 13:49:11,684] logger_util.py->write_log line:61 [INFO] 接口路径：http://127.0.0.1:18000/api/v1/variable/tunnel/80/tag
[2023-08-23 13:49:11,684] logger_util.py->write_log line:61 [INFO] 请求头：{}
[2023-08-23 13:49:11,684] logger_util.py->write_log line:61 [INFO] 请求参数：[{'archiveSetting': None, 'groupId': None, 'name': 'B6', 'description': '验证浮点数小数位，舍位', 'typeName': 'F32位浮点数IEEE754', 'config': {'readWriteMode': 0, 'address': '400085', 'interval': '10000', 'stringLength': 'null', 'zoom': '1', 'digit': '2', 'readWriteRule': '1'}, 'index': '6'}]
[2023-08-23 13:49:11,684] logger_util.py->write_log line:61 [INFO] 文件上传：None
[2023-08-23 13:49:11,693] logger_util.py->error_log line:65 [INFO] 断言失败:status_code不等于200
[2023-08-23 13:49:11,694] logger_util.py->write_log line:61 [INFO] 实际结果：序号<6>变量配置错误
[2023-08-23 13:49:11,694] logger_util.py->write_log line:61 [INFO] 接口请求失败！
[2023-08-23 13:49:11,694] logger_util.py->write_log line:61 [INFO] -------------接口请求结束-----------

[2023-08-23 13:49:11,695] logger_util.py->error_log line:65 [INFO] 断言异常：异常信息: Traceback (most recent call last):
  File "E:\Project_python\api_cms\common\requests_util.py", line 353, in validate_result
    error_log("断言失败:"+assert_key+"不等于"+str(assert_value))
  File "E:\Project_python\api_cms\common\logger_util.py", line 66, in error_log
    raise Exception(log_message)
Exception: 断言失败:status_code不等于200

[2023-08-23 13:49:11,695] logger_util.py->error_log line:65 [INFO] 分析YAML文件异常：异常信息: Traceback (most recent call last):
  File "E:\Project_python\api_cms\common\requests_util.py", line 353, in validate_result
    error_log("断言失败:"+assert_key+"不等于"+str(assert_value))
  File "E:\Project_python\api_cms\common\logger_util.py", line 66, in error_log
    raise Exception(log_message)
Exception: 断言失败:status_code不等于200

During handling of the above exception, another exception occurred:

Traceback (most recent call last):
  File "E:\Project_python\api_cms\common\requests_util.py", line 255, in analysis_yaml
    self.validate_result(yq_result, return_text, status_code)
  File "E:\Project_python\api_cms\common\requests_util.py", line 408, in validate_result
    error_log("断言异常：异常信息: %s" % str(traceback.format_exc()))
  File "E:\Project_python\api_cms\common\logger_util.py", line 66, in error_log
    raise Exception(log_message)
Exception: 断言异常：异常信息: Traceback (most recent call last):
  File "E:\Project_python\api_cms\common\requests_util.py", line 353, in validate_result
    error_log("断言失败:"+assert_key+"不等于"+str(assert_value))
  File "E:\Project_python\api_cms\common\logger_util.py", line 66, in error_log
    raise Exception(log_message)
Exception: 断言失败:status_code不等于200


[2023-08-23 13:49:11,722] logger_util.py->write_log line:61 [INFO] 
-------------接口请求开始-----------
[2023-08-23 13:49:11,722] logger_util.py->write_log line:61 [INFO] 接口名称：新增io变量
[2023-08-23 13:49:11,722] logger_util.py->write_log line:61 [INFO] 接口方式：post
[2023-08-23 13:49:11,722] logger_util.py->write_log line:61 [INFO] 接口路径：http://127.0.0.1:18000/api/v1/variable/tunnel/80/tag
[2023-08-23 13:49:11,722] logger_util.py->write_log line:61 [INFO] 请求头：{}
[2023-08-23 13:49:11,722] logger_util.py->write_log line:61 [INFO] 请求参数：[{'archiveSetting': None, 'groupId': None, 'name': 'B7', 'description': '验证浮点数小数位，四舍', 'typeName': 'F32位浮点数IEEE754', 'config': {'readWriteMode': 0, 'address': '400087', 'interval': '10000', 'stringLength': 'null', 'zoom': '1', 'digit': '2', 'readWriteRule': '2'}, 'index': '7'}]
[2023-08-23 13:49:11,722] logger_util.py->write_log line:61 [INFO] 文件上传：None
[2023-08-23 13:49:11,730] logger_util.py->error_log line:65 [INFO] 断言失败:status_code不等于200
[2023-08-23 13:49:11,730] logger_util.py->write_log line:61 [INFO] 实际结果：序号<7>变量配置错误
[2023-08-23 13:49:11,730] logger_util.py->write_log line:61 [INFO] 接口请求失败！
[2023-08-23 13:49:11,730] logger_util.py->write_log line:61 [INFO] -------------接口请求结束-----------

[2023-08-23 13:49:11,730] logger_util.py->error_log line:65 [INFO] 断言异常：异常信息: Traceback (most recent call last):
  File "E:\Project_python\api_cms\common\requests_util.py", line 353, in validate_result
    error_log("断言失败:"+assert_key+"不等于"+str(assert_value))
  File "E:\Project_python\api_cms\common\logger_util.py", line 66, in error_log
    raise Exception(log_message)
Exception: 断言失败:status_code不等于200

[2023-08-23 13:49:11,731] logger_util.py->error_log line:65 [INFO] 分析YAML文件异常：异常信息: Traceback (most recent call last):
  File "E:\Project_python\api_cms\common\requests_util.py", line 353, in validate_result
    error_log("断言失败:"+assert_key+"不等于"+str(assert_value))
  File "E:\Project_python\api_cms\common\logger_util.py", line 66, in error_log
    raise Exception(log_message)
Exception: 断言失败:status_code不等于200

During handling of the above exception, another exception occurred:

Traceback (most recent call last):
  File "E:\Project_python\api_cms\common\requests_util.py", line 255, in analysis_yaml
    self.validate_result(yq_result, return_text, status_code)
  File "E:\Project_python\api_cms\common\requests_util.py", line 408, in validate_result
    error_log("断言异常：异常信息: %s" % str(traceback.format_exc()))
  File "E:\Project_python\api_cms\common\logger_util.py", line 66, in error_log
    raise Exception(log_message)
Exception: 断言异常：异常信息: Traceback (most recent call last):
  File "E:\Project_python\api_cms\common\requests_util.py", line 353, in validate_result
    error_log("断言失败:"+assert_key+"不等于"+str(assert_value))
  File "E:\Project_python\api_cms\common\logger_util.py", line 66, in error_log
    raise Exception(log_message)
Exception: 断言失败:status_code不等于200


[2023-08-23 13:49:11,757] logger_util.py->write_log line:61 [INFO] 
-------------接口请求开始-----------
[2023-08-23 13:49:11,758] logger_util.py->write_log line:61 [INFO] 接口名称：新增io变量
[2023-08-23 13:49:11,758] logger_util.py->write_log line:61 [INFO] 接口方式：post
[2023-08-23 13:49:11,758] logger_util.py->write_log line:61 [INFO] 接口路径：http://127.0.0.1:18000/api/v1/variable/tunnel/80/tag
[2023-08-23 13:49:11,758] logger_util.py->write_log line:61 [INFO] 请求头：{}
[2023-08-23 13:49:11,758] logger_util.py->write_log line:61 [INFO] 请求参数：[{'archiveSetting': None, 'groupId': None, 'name': 'B8', 'description': '验证浮点数小数位，进位', 'typeName': 'F32位浮点数IEEE754', 'config': {'readWriteMode': 0, 'address': '400089', 'interval': '10000', 'stringLength': 'null', 'zoom': '1', 'digit': '2', 'readWriteRule': '3'}, 'index': '8'}]
[2023-08-23 13:49:11,758] logger_util.py->write_log line:61 [INFO] 文件上传：None
[2023-08-23 13:49:11,766] logger_util.py->error_log line:65 [INFO] 断言失败:status_code不等于200
[2023-08-23 13:49:11,766] logger_util.py->write_log line:61 [INFO] 实际结果：序号<8>变量配置错误
[2023-08-23 13:49:11,766] logger_util.py->write_log line:61 [INFO] 接口请求失败！
[2023-08-23 13:49:11,766] logger_util.py->write_log line:61 [INFO] -------------接口请求结束-----------

[2023-08-23 13:49:11,766] logger_util.py->error_log line:65 [INFO] 断言异常：异常信息: Traceback (most recent call last):
  File "E:\Project_python\api_cms\common\requests_util.py", line 353, in validate_result
    error_log("断言失败:"+assert_key+"不等于"+str(assert_value))
  File "E:\Project_python\api_cms\common\logger_util.py", line 66, in error_log
    raise Exception(log_message)
Exception: 断言失败:status_code不等于200

[2023-08-23 13:49:11,766] logger_util.py->error_log line:65 [INFO] 分析YAML文件异常：异常信息: Traceback (most recent call last):
  File "E:\Project_python\api_cms\common\requests_util.py", line 353, in validate_result
    error_log("断言失败:"+assert_key+"不等于"+str(assert_value))
  File "E:\Project_python\api_cms\common\logger_util.py", line 66, in error_log
    raise Exception(log_message)
Exception: 断言失败:status_code不等于200

During handling of the above exception, another exception occurred:

Traceback (most recent call last):
  File "E:\Project_python\api_cms\common\requests_util.py", line 255, in analysis_yaml
    self.validate_result(yq_result, return_text, status_code)
  File "E:\Project_python\api_cms\common\requests_util.py", line 408, in validate_result
    error_log("断言异常：异常信息: %s" % str(traceback.format_exc()))
  File "E:\Project_python\api_cms\common\logger_util.py", line 66, in error_log
    raise Exception(log_message)
Exception: 断言异常：异常信息: Traceback (most recent call last):
  File "E:\Project_python\api_cms\common\requests_util.py", line 353, in validate_result
    error_log("断言失败:"+assert_key+"不等于"+str(assert_value))
  File "E:\Project_python\api_cms\common\logger_util.py", line 66, in error_log
    raise Exception(log_message)
Exception: 断言失败:status_code不等于200


[2023-08-23 13:49:11,792] logger_util.py->write_log line:61 [INFO] 
-------------接口请求开始-----------
[2023-08-23 13:49:11,793] logger_util.py->write_log line:61 [INFO] 接口名称：新增io变量
[2023-08-23 13:49:11,793] logger_util.py->write_log line:61 [INFO] 接口方式：post
[2023-08-23 13:49:11,793] logger_util.py->write_log line:61 [INFO] 接口路径：http://127.0.0.1:18000/api/v1/variable/tunnel/80/tag
[2023-08-23 13:49:11,793] logger_util.py->write_log line:61 [INFO] 请求头：{}
[2023-08-23 13:49:11,793] logger_util.py->write_log line:61 [INFO] 请求参数：[{'archiveSetting': None, 'groupId': None, 'name': 'A1', 'description': '二进制', 'typeName': '二进制', 'config': {'readWriteMode': 0, 'address': '400001.0 ', 'interval': '10000', 'stringLength': 'null', 'zoom': 'null', 'digit': 'null', 'readWriteRule': '1'}, 'index': '9'}]
[2023-08-23 13:49:11,793] logger_util.py->write_log line:61 [INFO] 文件上传：None
[2023-08-23 13:49:11,801] logger_util.py->error_log line:65 [INFO] 断言失败:status_code不等于200
[2023-08-23 13:49:11,801] logger_util.py->write_log line:61 [INFO] 实际结果：序号<9>变量配置错误：变量名<A1>已存在，请重新输入
[2023-08-23 13:49:11,801] logger_util.py->write_log line:61 [INFO] 接口请求失败！
[2023-08-23 13:49:11,801] logger_util.py->write_log line:61 [INFO] -------------接口请求结束-----------

[2023-08-23 13:49:11,801] logger_util.py->error_log line:65 [INFO] 断言异常：异常信息: Traceback (most recent call last):
  File "E:\Project_python\api_cms\common\requests_util.py", line 353, in validate_result
    error_log("断言失败:"+assert_key+"不等于"+str(assert_value))
  File "E:\Project_python\api_cms\common\logger_util.py", line 66, in error_log
    raise Exception(log_message)
Exception: 断言失败:status_code不等于200

[2023-08-23 13:49:11,802] logger_util.py->error_log line:65 [INFO] 分析YAML文件异常：异常信息: Traceback (most recent call last):
  File "E:\Project_python\api_cms\common\requests_util.py", line 353, in validate_result
    error_log("断言失败:"+assert_key+"不等于"+str(assert_value))
  File "E:\Project_python\api_cms\common\logger_util.py", line 66, in error_log
    raise Exception(log_message)
Exception: 断言失败:status_code不等于200

During handling of the above exception, another exception occurred:

Traceback (most recent call last):
  File "E:\Project_python\api_cms\common\requests_util.py", line 255, in analysis_yaml
    self.validate_result(yq_result, return_text, status_code)
  File "E:\Project_python\api_cms\common\requests_util.py", line 408, in validate_result
    error_log("断言异常：异常信息: %s" % str(traceback.format_exc()))
  File "E:\Project_python\api_cms\common\logger_util.py", line 66, in error_log
    raise Exception(log_message)
Exception: 断言异常：异常信息: Traceback (most recent call last):
  File "E:\Project_python\api_cms\common\requests_util.py", line 353, in validate_result
    error_log("断言失败:"+assert_key+"不等于"+str(assert_value))
  File "E:\Project_python\api_cms\common\logger_util.py", line 66, in error_log
    raise Exception(log_message)
Exception: 断言失败:status_code不等于200


[2023-08-23 13:49:11,829] logger_util.py->write_log line:61 [INFO] 
-------------接口请求开始-----------
[2023-08-23 13:49:11,829] logger_util.py->write_log line:61 [INFO] 接口名称：新增io变量
[2023-08-23 13:49:11,829] logger_util.py->write_log line:61 [INFO] 接口方式：post
[2023-08-23 13:49:11,829] logger_util.py->write_log line:61 [INFO] 接口路径：http://127.0.0.1:18000/api/v1/variable/tunnel/80/tag
[2023-08-23 13:49:11,829] logger_util.py->write_log line:61 [INFO] 请求头：{}
[2023-08-23 13:49:11,830] logger_util.py->write_log line:61 [INFO] 请求参数：[{'archiveSetting': None, 'groupId': None, 'name': 'A2', 'description': '有符号8位整型', 'typeName': '有符号8位整型', 'config': {'readWriteMode': 0, 'address': '400002', 'interval': '10000', 'stringLength': 'null', 'zoom': '1', 'digit': 'null', 'readWriteRule': '1'}, 'index': '10'}]
[2023-08-23 13:49:11,830] logger_util.py->write_log line:61 [INFO] 文件上传：None
[2023-08-23 13:49:11,838] logger_util.py->error_log line:65 [INFO] 断言失败:status_code不等于200
[2023-08-23 13:49:11,839] logger_util.py->write_log line:61 [INFO] 实际结果：序号<10>变量配置错误：变量名<A2>已存在，请重新输入
[2023-08-23 13:49:11,839] logger_util.py->write_log line:61 [INFO] 接口请求失败！
[2023-08-23 13:49:11,839] logger_util.py->write_log line:61 [INFO] -------------接口请求结束-----------

[2023-08-23 13:49:11,839] logger_util.py->error_log line:65 [INFO] 断言异常：异常信息: Traceback (most recent call last):
  File "E:\Project_python\api_cms\common\requests_util.py", line 353, in validate_result
    error_log("断言失败:"+assert_key+"不等于"+str(assert_value))
  File "E:\Project_python\api_cms\common\logger_util.py", line 66, in error_log
    raise Exception(log_message)
Exception: 断言失败:status_code不等于200

[2023-08-23 13:49:11,839] logger_util.py->error_log line:65 [INFO] 分析YAML文件异常：异常信息: Traceback (most recent call last):
  File "E:\Project_python\api_cms\common\requests_util.py", line 353, in validate_result
    error_log("断言失败:"+assert_key+"不等于"+str(assert_value))
  File "E:\Project_python\api_cms\common\logger_util.py", line 66, in error_log
    raise Exception(log_message)
Exception: 断言失败:status_code不等于200

During handling of the above exception, another exception occurred:

Traceback (most recent call last):
  File "E:\Project_python\api_cms\common\requests_util.py", line 255, in analysis_yaml
    self.validate_result(yq_result, return_text, status_code)
  File "E:\Project_python\api_cms\common\requests_util.py", line 408, in validate_result
    error_log("断言异常：异常信息: %s" % str(traceback.format_exc()))
  File "E:\Project_python\api_cms\common\logger_util.py", line 66, in error_log
    raise Exception(log_message)
Exception: 断言异常：异常信息: Traceback (most recent call last):
  File "E:\Project_python\api_cms\common\requests_util.py", line 353, in validate_result
    error_log("断言失败:"+assert_key+"不等于"+str(assert_value))
  File "E:\Project_python\api_cms\common\logger_util.py", line 66, in error_log
    raise Exception(log_message)
Exception: 断言失败:status_code不等于200


[2023-08-23 13:49:11,865] logger_util.py->write_log line:61 [INFO] 
-------------接口请求开始-----------
[2023-08-23 13:49:11,866] logger_util.py->write_log line:61 [INFO] 接口名称：新增io变量
[2023-08-23 13:49:11,866] logger_util.py->write_log line:61 [INFO] 接口方式：post
[2023-08-23 13:49:11,866] logger_util.py->write_log line:61 [INFO] 接口路径：http://127.0.0.1:18000/api/v1/variable/tunnel/80/tag
[2023-08-23 13:49:11,866] logger_util.py->write_log line:61 [INFO] 请求头：{}
[2023-08-23 13:49:11,866] logger_util.py->write_log line:61 [INFO] 请求参数：[{'archiveSetting': None, 'groupId': None, 'name': 'A3', 'description': '无符号8位整型', 'typeName': '无符号8位整型', 'config': {'readWriteMode': 0, 'address': '400003', 'interval': '10000', 'stringLength': 'null', 'zoom': '1', 'digit': 'null', 'readWriteRule': '1'}, 'index': '11'}]
[2023-08-23 13:49:11,866] logger_util.py->write_log line:61 [INFO] 文件上传：None
[2023-08-23 13:49:11,874] logger_util.py->error_log line:65 [INFO] 断言失败:status_code不等于200
[2023-08-23 13:49:11,874] logger_util.py->write_log line:61 [INFO] 实际结果：序号<11>变量配置错误：变量名<A3>已存在，请重新输入
[2023-08-23 13:49:11,874] logger_util.py->write_log line:61 [INFO] 接口请求失败！
[2023-08-23 13:49:11,874] logger_util.py->write_log line:61 [INFO] -------------接口请求结束-----------

[2023-08-23 13:49:11,874] logger_util.py->error_log line:65 [INFO] 断言异常：异常信息: Traceback (most recent call last):
  File "E:\Project_python\api_cms\common\requests_util.py", line 353, in validate_result
    error_log("断言失败:"+assert_key+"不等于"+str(assert_value))
  File "E:\Project_python\api_cms\common\logger_util.py", line 66, in error_log
    raise Exception(log_message)
Exception: 断言失败:status_code不等于200

[2023-08-23 13:49:11,875] logger_util.py->error_log line:65 [INFO] 分析YAML文件异常：异常信息: Traceback (most recent call last):
  File "E:\Project_python\api_cms\common\requests_util.py", line 353, in validate_result
    error_log("断言失败:"+assert_key+"不等于"+str(assert_value))
  File "E:\Project_python\api_cms\common\logger_util.py", line 66, in error_log
    raise Exception(log_message)
Exception: 断言失败:status_code不等于200

During handling of the above exception, another exception occurred:

Traceback (most recent call last):
  File "E:\Project_python\api_cms\common\requests_util.py", line 255, in analysis_yaml
    self.validate_result(yq_result, return_text, status_code)
  File "E:\Project_python\api_cms\common\requests_util.py", line 408, in validate_result
    error_log("断言异常：异常信息: %s" % str(traceback.format_exc()))
  File "E:\Project_python\api_cms\common\logger_util.py", line 66, in error_log
    raise Exception(log_message)
Exception: 断言异常：异常信息: Traceback (most recent call last):
  File "E:\Project_python\api_cms\common\requests_util.py", line 353, in validate_result
    error_log("断言失败:"+assert_key+"不等于"+str(assert_value))
  File "E:\Project_python\api_cms\common\logger_util.py", line 66, in error_log
    raise Exception(log_message)
Exception: 断言失败:status_code不等于200


[2023-08-23 13:49:11,901] logger_util.py->write_log line:61 [INFO] 
-------------接口请求开始-----------
[2023-08-23 13:49:11,901] logger_util.py->write_log line:61 [INFO] 接口名称：新增io变量
[2023-08-23 13:49:11,901] logger_util.py->write_log line:61 [INFO] 接口方式：post
[2023-08-23 13:49:11,901] logger_util.py->write_log line:61 [INFO] 接口路径：http://127.0.0.1:18000/api/v1/variable/tunnel/80/tag
[2023-08-23 13:49:11,901] logger_util.py->write_log line:61 [INFO] 请求头：{}
[2023-08-23 13:49:11,901] logger_util.py->write_log line:61 [INFO] 请求参数：[{'archiveSetting': None, 'groupId': None, 'name': 'A4', 'description': '有符号16位整型', 'typeName': '有符号16位整型', 'config': {'readWriteMode': 0, 'address': '400004', 'interval': '10000', 'stringLength': 'null', 'zoom': '1', 'digit': 'null', 'readWriteRule': '1'}, 'index': '12'}]
[2023-08-23 13:49:11,901] logger_util.py->write_log line:61 [INFO] 文件上传：None
[2023-08-23 13:49:11,909] logger_util.py->error_log line:65 [INFO] 断言失败:status_code不等于200
[2023-08-23 13:49:11,909] logger_util.py->write_log line:61 [INFO] 实际结果：序号<12>变量配置错误：变量名<A4>已存在，请重新输入
[2023-08-23 13:49:11,909] logger_util.py->write_log line:61 [INFO] 接口请求失败！
[2023-08-23 13:49:11,909] logger_util.py->write_log line:61 [INFO] -------------接口请求结束-----------

[2023-08-23 13:49:11,909] logger_util.py->error_log line:65 [INFO] 断言异常：异常信息: Traceback (most recent call last):
  File "E:\Project_python\api_cms\common\requests_util.py", line 353, in validate_result
    error_log("断言失败:"+assert_key+"不等于"+str(assert_value))
  File "E:\Project_python\api_cms\common\logger_util.py", line 66, in error_log
    raise Exception(log_message)
Exception: 断言失败:status_code不等于200

[2023-08-23 13:49:11,910] logger_util.py->error_log line:65 [INFO] 分析YAML文件异常：异常信息: Traceback (most recent call last):
  File "E:\Project_python\api_cms\common\requests_util.py", line 353, in validate_result
    error_log("断言失败:"+assert_key+"不等于"+str(assert_value))
  File "E:\Project_python\api_cms\common\logger_util.py", line 66, in error_log
    raise Exception(log_message)
Exception: 断言失败:status_code不等于200

During handling of the above exception, another exception occurred:

Traceback (most recent call last):
  File "E:\Project_python\api_cms\common\requests_util.py", line 255, in analysis_yaml
    self.validate_result(yq_result, return_text, status_code)
  File "E:\Project_python\api_cms\common\requests_util.py", line 408, in validate_result
    error_log("断言异常：异常信息: %s" % str(traceback.format_exc()))
  File "E:\Project_python\api_cms\common\logger_util.py", line 66, in error_log
    raise Exception(log_message)
Exception: 断言异常：异常信息: Traceback (most recent call last):
  File "E:\Project_python\api_cms\common\requests_util.py", line 353, in validate_result
    error_log("断言失败:"+assert_key+"不等于"+str(assert_value))
  File "E:\Project_python\api_cms\common\logger_util.py", line 66, in error_log
    raise Exception(log_message)
Exception: 断言失败:status_code不等于200


[2023-08-23 13:49:11,935] logger_util.py->write_log line:61 [INFO] 
-------------接口请求开始-----------
[2023-08-23 13:49:11,936] logger_util.py->write_log line:61 [INFO] 接口名称：新增io变量
[2023-08-23 13:49:11,936] logger_util.py->write_log line:61 [INFO] 接口方式：post
[2023-08-23 13:49:11,936] logger_util.py->write_log line:61 [INFO] 接口路径：http://127.0.0.1:18000/api/v1/variable/tunnel/80/tag
[2023-08-23 13:49:11,936] logger_util.py->write_log line:61 [INFO] 请求头：{}
[2023-08-23 13:49:11,936] logger_util.py->write_log line:61 [INFO] 请求参数：[{'archiveSetting': None, 'groupId': None, 'name': 'A5', 'description': '无符号16位整型', 'typeName': '无符号16位整型', 'config': {'readWriteMode': 0, 'address': '400005', 'interval': '10000', 'stringLength': 'null', 'zoom': '1', 'digit': 'null', 'readWriteRule': '1'}, 'index': '13'}]
[2023-08-23 13:49:11,936] logger_util.py->write_log line:61 [INFO] 文件上传：None
[2023-08-23 13:49:11,947] logger_util.py->error_log line:65 [INFO] 断言失败:status_code不等于200
[2023-08-23 13:49:11,947] logger_util.py->write_log line:61 [INFO] 实际结果：序号<13>变量配置错误：变量名<A5>已存在，请重新输入
[2023-08-23 13:49:11,947] logger_util.py->write_log line:61 [INFO] 接口请求失败！
[2023-08-23 13:49:11,947] logger_util.py->write_log line:61 [INFO] -------------接口请求结束-----------

[2023-08-23 13:49:11,948] logger_util.py->error_log line:65 [INFO] 断言异常：异常信息: Traceback (most recent call last):
  File "E:\Project_python\api_cms\common\requests_util.py", line 353, in validate_result
    error_log("断言失败:"+assert_key+"不等于"+str(assert_value))
  File "E:\Project_python\api_cms\common\logger_util.py", line 66, in error_log
    raise Exception(log_message)
Exception: 断言失败:status_code不等于200

[2023-08-23 13:49:11,948] logger_util.py->error_log line:65 [INFO] 分析YAML文件异常：异常信息: Traceback (most recent call last):
  File "E:\Project_python\api_cms\common\requests_util.py", line 353, in validate_result
    error_log("断言失败:"+assert_key+"不等于"+str(assert_value))
  File "E:\Project_python\api_cms\common\logger_util.py", line 66, in error_log
    raise Exception(log_message)
Exception: 断言失败:status_code不等于200

During handling of the above exception, another exception occurred:

Traceback (most recent call last):
  File "E:\Project_python\api_cms\common\requests_util.py", line 255, in analysis_yaml
    self.validate_result(yq_result, return_text, status_code)
  File "E:\Project_python\api_cms\common\requests_util.py", line 408, in validate_result
    error_log("断言异常：异常信息: %s" % str(traceback.format_exc()))
  File "E:\Project_python\api_cms\common\logger_util.py", line 66, in error_log
    raise Exception(log_message)
Exception: 断言异常：异常信息: Traceback (most recent call last):
  File "E:\Project_python\api_cms\common\requests_util.py", line 353, in validate_result
    error_log("断言失败:"+assert_key+"不等于"+str(assert_value))
  File "E:\Project_python\api_cms\common\logger_util.py", line 66, in error_log
    raise Exception(log_message)
Exception: 断言失败:status_code不等于200


[2023-08-23 13:49:11,976] logger_util.py->write_log line:61 [INFO] 
-------------接口请求开始-----------
[2023-08-23 13:49:11,976] logger_util.py->write_log line:61 [INFO] 接口名称：新增io变量
[2023-08-23 13:49:11,976] logger_util.py->write_log line:61 [INFO] 接口方式：post
[2023-08-23 13:49:11,976] logger_util.py->write_log line:61 [INFO] 接口路径：http://127.0.0.1:18000/api/v1/variable/tunnel/80/tag
[2023-08-23 13:49:11,976] logger_util.py->write_log line:61 [INFO] 请求头：{}
[2023-08-23 13:49:11,976] logger_util.py->write_log line:61 [INFO] 请求参数：[{'archiveSetting': None, 'groupId': None, 'name': 'A6', 'description': '有符号32位整型', 'typeName': '有符号32位整型', 'config': {'readWriteMode': 0, 'address': '400013', 'interval': '10000', 'stringLength': 'null', 'zoom': '1', 'digit': 'null', 'readWriteRule': '1'}, 'index': '14'}]
[2023-08-23 13:49:11,977] logger_util.py->write_log line:61 [INFO] 文件上传：None
[2023-08-23 13:49:11,985] logger_util.py->error_log line:65 [INFO] 断言失败:status_code不等于200
[2023-08-23 13:49:11,985] logger_util.py->write_log line:61 [INFO] 实际结果：序号<14>变量配置错误：变量名<A6>已存在，请重新输入
[2023-08-23 13:49:11,985] logger_util.py->write_log line:61 [INFO] 接口请求失败！
[2023-08-23 13:49:11,985] logger_util.py->write_log line:61 [INFO] -------------接口请求结束-----------

[2023-08-23 13:49:11,985] logger_util.py->error_log line:65 [INFO] 断言异常：异常信息: Traceback (most recent call last):
  File "E:\Project_python\api_cms\common\requests_util.py", line 353, in validate_result
    error_log("断言失败:"+assert_key+"不等于"+str(assert_value))
  File "E:\Project_python\api_cms\common\logger_util.py", line 66, in error_log
    raise Exception(log_message)
Exception: 断言失败:status_code不等于200

[2023-08-23 13:49:11,986] logger_util.py->error_log line:65 [INFO] 分析YAML文件异常：异常信息: Traceback (most recent call last):
  File "E:\Project_python\api_cms\common\requests_util.py", line 353, in validate_result
    error_log("断言失败:"+assert_key+"不等于"+str(assert_value))
  File "E:\Project_python\api_cms\common\logger_util.py", line 66, in error_log
    raise Exception(log_message)
Exception: 断言失败:status_code不等于200

During handling of the above exception, another exception occurred:

Traceback (most recent call last):
  File "E:\Project_python\api_cms\common\requests_util.py", line 255, in analysis_yaml
    self.validate_result(yq_result, return_text, status_code)
  File "E:\Project_python\api_cms\common\requests_util.py", line 408, in validate_result
    error_log("断言异常：异常信息: %s" % str(traceback.format_exc()))
  File "E:\Project_python\api_cms\common\logger_util.py", line 66, in error_log
    raise Exception(log_message)
Exception: 断言异常：异常信息: Traceback (most recent call last):
  File "E:\Project_python\api_cms\common\requests_util.py", line 353, in validate_result
    error_log("断言失败:"+assert_key+"不等于"+str(assert_value))
  File "E:\Project_python\api_cms\common\logger_util.py", line 66, in error_log
    raise Exception(log_message)
Exception: 断言失败:status_code不等于200


[2023-08-23 13:49:12,013] logger_util.py->write_log line:61 [INFO] 
-------------接口请求开始-----------
[2023-08-23 13:49:12,013] logger_util.py->write_log line:61 [INFO] 接口名称：新增io变量
[2023-08-23 13:49:12,013] logger_util.py->write_log line:61 [INFO] 接口方式：post
[2023-08-23 13:49:12,014] logger_util.py->write_log line:61 [INFO] 接口路径：http://127.0.0.1:18000/api/v1/variable/tunnel/80/tag
[2023-08-23 13:49:12,014] logger_util.py->write_log line:61 [INFO] 请求头：{}
[2023-08-23 13:49:12,014] logger_util.py->write_log line:61 [INFO] 请求参数：[{'archiveSetting': None, 'groupId': None, 'name': 'A7', 'description': '无符号32位整型', 'typeName': '无符号32位整型', 'config': {'readWriteMode': 0, 'address': '400015', 'interval': '10000', 'stringLength': 'null', 'zoom': '1', 'digit': 'null', 'readWriteRule': '1'}, 'index': '15'}]
[2023-08-23 13:49:12,014] logger_util.py->write_log line:61 [INFO] 文件上传：None
[2023-08-23 13:49:12,022] logger_util.py->error_log line:65 [INFO] 断言失败:status_code不等于200
[2023-08-23 13:49:12,022] logger_util.py->write_log line:61 [INFO] 实际结果：序号<15>变量配置错误：变量名<A7>已存在，请重新输入
[2023-08-23 13:49:12,022] logger_util.py->write_log line:61 [INFO] 接口请求失败！
[2023-08-23 13:49:12,022] logger_util.py->write_log line:61 [INFO] -------------接口请求结束-----------

[2023-08-23 13:49:12,022] logger_util.py->error_log line:65 [INFO] 断言异常：异常信息: Traceback (most recent call last):
  File "E:\Project_python\api_cms\common\requests_util.py", line 353, in validate_result
    error_log("断言失败:"+assert_key+"不等于"+str(assert_value))
  File "E:\Project_python\api_cms\common\logger_util.py", line 66, in error_log
    raise Exception(log_message)
Exception: 断言失败:status_code不等于200

[2023-08-23 13:49:12,023] logger_util.py->error_log line:65 [INFO] 分析YAML文件异常：异常信息: Traceback (most recent call last):
  File "E:\Project_python\api_cms\common\requests_util.py", line 353, in validate_result
    error_log("断言失败:"+assert_key+"不等于"+str(assert_value))
  File "E:\Project_python\api_cms\common\logger_util.py", line 66, in error_log
    raise Exception(log_message)
Exception: 断言失败:status_code不等于200

During handling of the above exception, another exception occurred:

Traceback (most recent call last):
  File "E:\Project_python\api_cms\common\requests_util.py", line 255, in analysis_yaml
    self.validate_result(yq_result, return_text, status_code)
  File "E:\Project_python\api_cms\common\requests_util.py", line 408, in validate_result
    error_log("断言异常：异常信息: %s" % str(traceback.format_exc()))
  File "E:\Project_python\api_cms\common\logger_util.py", line 66, in error_log
    raise Exception(log_message)
Exception: 断言异常：异常信息: Traceback (most recent call last):
  File "E:\Project_python\api_cms\common\requests_util.py", line 353, in validate_result
    error_log("断言失败:"+assert_key+"不等于"+str(assert_value))
  File "E:\Project_python\api_cms\common\logger_util.py", line 66, in error_log
    raise Exception(log_message)
Exception: 断言失败:status_code不等于200


[2023-08-23 13:49:12,049] logger_util.py->write_log line:61 [INFO] 
-------------接口请求开始-----------
[2023-08-23 13:49:12,049] logger_util.py->write_log line:61 [INFO] 接口名称：新增io变量
[2023-08-23 13:49:12,049] logger_util.py->write_log line:61 [INFO] 接口方式：post
[2023-08-23 13:49:12,049] logger_util.py->write_log line:61 [INFO] 接口路径：http://127.0.0.1:18000/api/v1/variable/tunnel/80/tag
[2023-08-23 13:49:12,049] logger_util.py->write_log line:61 [INFO] 请求头：{}
[2023-08-23 13:49:12,050] logger_util.py->write_log line:61 [INFO] 请求参数：[{'archiveSetting': None, 'groupId': None, 'name': 'A8', 'description': '有符号64位整型', 'typeName': '有符号64位整型', 'config': {'readWriteMode': 0, 'address': '400025', 'interval': '10000', 'stringLength': 'null', 'zoom': '1', 'digit': 'null', 'readWriteRule': '1'}, 'index': '16'}]
[2023-08-23 13:49:12,050] logger_util.py->write_log line:61 [INFO] 文件上传：None
[2023-08-23 13:49:12,058] logger_util.py->error_log line:65 [INFO] 断言失败:status_code不等于200
[2023-08-23 13:49:12,058] logger_util.py->write_log line:61 [INFO] 实际结果：序号<16>变量配置错误：变量名<A8>已存在，请重新输入
[2023-08-23 13:49:12,058] logger_util.py->write_log line:61 [INFO] 接口请求失败！
[2023-08-23 13:49:12,059] logger_util.py->write_log line:61 [INFO] -------------接口请求结束-----------

[2023-08-23 13:49:12,059] logger_util.py->error_log line:65 [INFO] 断言异常：异常信息: Traceback (most recent call last):
  File "E:\Project_python\api_cms\common\requests_util.py", line 353, in validate_result
    error_log("断言失败:"+assert_key+"不等于"+str(assert_value))
  File "E:\Project_python\api_cms\common\logger_util.py", line 66, in error_log
    raise Exception(log_message)
Exception: 断言失败:status_code不等于200

[2023-08-23 13:49:12,059] logger_util.py->error_log line:65 [INFO] 分析YAML文件异常：异常信息: Traceback (most recent call last):
  File "E:\Project_python\api_cms\common\requests_util.py", line 353, in validate_result
    error_log("断言失败:"+assert_key+"不等于"+str(assert_value))
  File "E:\Project_python\api_cms\common\logger_util.py", line 66, in error_log
    raise Exception(log_message)
Exception: 断言失败:status_code不等于200

During handling of the above exception, another exception occurred:

Traceback (most recent call last):
  File "E:\Project_python\api_cms\common\requests_util.py", line 255, in analysis_yaml
    self.validate_result(yq_result, return_text, status_code)
  File "E:\Project_python\api_cms\common\requests_util.py", line 408, in validate_result
    error_log("断言异常：异常信息: %s" % str(traceback.format_exc()))
  File "E:\Project_python\api_cms\common\logger_util.py", line 66, in error_log
    raise Exception(log_message)
Exception: 断言异常：异常信息: Traceback (most recent call last):
  File "E:\Project_python\api_cms\common\requests_util.py", line 353, in validate_result
    error_log("断言失败:"+assert_key+"不等于"+str(assert_value))
  File "E:\Project_python\api_cms\common\logger_util.py", line 66, in error_log
    raise Exception(log_message)
Exception: 断言失败:status_code不等于200


[2023-08-23 13:49:12,086] logger_util.py->write_log line:61 [INFO] 
-------------接口请求开始-----------
[2023-08-23 13:49:12,086] logger_util.py->write_log line:61 [INFO] 接口名称：新增io变量
[2023-08-23 13:49:12,086] logger_util.py->write_log line:61 [INFO] 接口方式：post
[2023-08-23 13:49:12,087] logger_util.py->write_log line:61 [INFO] 接口路径：http://127.0.0.1:18000/api/v1/variable/tunnel/80/tag
[2023-08-23 13:49:12,087] logger_util.py->write_log line:61 [INFO] 请求头：{}
[2023-08-23 13:49:12,087] logger_util.py->write_log line:61 [INFO] 请求参数：[{'archiveSetting': None, 'groupId': None, 'name': 'A9', 'description': '无符号64位整型', 'typeName': '无符号64位整型', 'config': {'readWriteMode': 0, 'address': '400029', 'interval': '10000', 'stringLength': 'null', 'zoom': '1', 'digit': 'null', 'readWriteRule': '1'}, 'index': '17'}]
[2023-08-23 13:49:12,087] logger_util.py->write_log line:61 [INFO] 文件上传：None
[2023-08-23 13:49:12,094] logger_util.py->error_log line:65 [INFO] 断言失败:status_code不等于200
[2023-08-23 13:49:12,094] logger_util.py->write_log line:61 [INFO] 实际结果：序号<17>变量配置错误：变量名<A9>已存在，请重新输入
[2023-08-23 13:49:12,094] logger_util.py->write_log line:61 [INFO] 接口请求失败！
[2023-08-23 13:49:12,095] logger_util.py->write_log line:61 [INFO] -------------接口请求结束-----------

[2023-08-23 13:49:12,095] logger_util.py->error_log line:65 [INFO] 断言异常：异常信息: Traceback (most recent call last):
  File "E:\Project_python\api_cms\common\requests_util.py", line 353, in validate_result
    error_log("断言失败:"+assert_key+"不等于"+str(assert_value))
  File "E:\Project_python\api_cms\common\logger_util.py", line 66, in error_log
    raise Exception(log_message)
Exception: 断言失败:status_code不等于200

[2023-08-23 13:49:12,095] logger_util.py->error_log line:65 [INFO] 分析YAML文件异常：异常信息: Traceback (most recent call last):
  File "E:\Project_python\api_cms\common\requests_util.py", line 353, in validate_result
    error_log("断言失败:"+assert_key+"不等于"+str(assert_value))
  File "E:\Project_python\api_cms\common\logger_util.py", line 66, in error_log
    raise Exception(log_message)
Exception: 断言失败:status_code不等于200

During handling of the above exception, another exception occurred:

Traceback (most recent call last):
  File "E:\Project_python\api_cms\common\requests_util.py", line 255, in analysis_yaml
    self.validate_result(yq_result, return_text, status_code)
  File "E:\Project_python\api_cms\common\requests_util.py", line 408, in validate_result
    error_log("断言异常：异常信息: %s" % str(traceback.format_exc()))
  File "E:\Project_python\api_cms\common\logger_util.py", line 66, in error_log
    raise Exception(log_message)
Exception: 断言异常：异常信息: Traceback (most recent call last):
  File "E:\Project_python\api_cms\common\requests_util.py", line 353, in validate_result
    error_log("断言失败:"+assert_key+"不等于"+str(assert_value))
  File "E:\Project_python\api_cms\common\logger_util.py", line 66, in error_log
    raise Exception(log_message)
Exception: 断言失败:status_code不等于200


[2023-08-23 13:49:12,121] logger_util.py->write_log line:61 [INFO] 
-------------接口请求开始-----------
[2023-08-23 13:49:12,121] logger_util.py->write_log line:61 [INFO] 接口名称：新增io变量
[2023-08-23 13:49:12,121] logger_util.py->write_log line:61 [INFO] 接口方式：post
[2023-08-23 13:49:12,121] logger_util.py->write_log line:61 [INFO] 接口路径：http://127.0.0.1:18000/api/v1/variable/tunnel/80/tag
[2023-08-23 13:49:12,121] logger_util.py->write_log line:61 [INFO] 请求头：{}
[2023-08-23 13:49:12,121] logger_util.py->write_log line:61 [INFO] 请求参数：[{'archiveSetting': None, 'groupId': None, 'name': 'A10', 'description': 'F32位浮点数IEEE754', 'typeName': 'F32位浮点数IEEE754', 'config': {'readWriteMode': 0, 'address': '400045', 'interval': '10000', 'stringLength': 'null', 'zoom': '1', 'digit': 'null', 'readWriteRule': '1'}, 'index': '18'}]
[2023-08-23 13:49:12,121] logger_util.py->write_log line:61 [INFO] 文件上传：None
[2023-08-23 13:49:12,129] logger_util.py->error_log line:65 [INFO] 断言失败:status_code不等于200
[2023-08-23 13:49:12,129] logger_util.py->write_log line:61 [INFO] 实际结果：序号<18>变量配置错误：变量名<A10>已存在，请重新输入
[2023-08-23 13:49:12,129] logger_util.py->write_log line:61 [INFO] 接口请求失败！
[2023-08-23 13:49:12,129] logger_util.py->write_log line:61 [INFO] -------------接口请求结束-----------

[2023-08-23 13:49:12,129] logger_util.py->error_log line:65 [INFO] 断言异常：异常信息: Traceback (most recent call last):
  File "E:\Project_python\api_cms\common\requests_util.py", line 353, in validate_result
    error_log("断言失败:"+assert_key+"不等于"+str(assert_value))
  File "E:\Project_python\api_cms\common\logger_util.py", line 66, in error_log
    raise Exception(log_message)
Exception: 断言失败:status_code不等于200

[2023-08-23 13:49:12,129] logger_util.py->error_log line:65 [INFO] 分析YAML文件异常：异常信息: Traceback (most recent call last):
  File "E:\Project_python\api_cms\common\requests_util.py", line 353, in validate_result
    error_log("断言失败:"+assert_key+"不等于"+str(assert_value))
  File "E:\Project_python\api_cms\common\logger_util.py", line 66, in error_log
    raise Exception(log_message)
Exception: 断言失败:status_code不等于200

During handling of the above exception, another exception occurred:

Traceback (most recent call last):
  File "E:\Project_python\api_cms\common\requests_util.py", line 255, in analysis_yaml
    self.validate_result(yq_result, return_text, status_code)
  File "E:\Project_python\api_cms\common\requests_util.py", line 408, in validate_result
    error_log("断言异常：异常信息: %s" % str(traceback.format_exc()))
  File "E:\Project_python\api_cms\common\logger_util.py", line 66, in error_log
    raise Exception(log_message)
Exception: 断言异常：异常信息: Traceback (most recent call last):
  File "E:\Project_python\api_cms\common\requests_util.py", line 353, in validate_result
    error_log("断言失败:"+assert_key+"不等于"+str(assert_value))
  File "E:\Project_python\api_cms\common\logger_util.py", line 66, in error_log
    raise Exception(log_message)
Exception: 断言失败:status_code不等于200


[2023-08-23 13:49:12,156] logger_util.py->write_log line:61 [INFO] 
-------------接口请求开始-----------
[2023-08-23 13:49:12,156] logger_util.py->write_log line:61 [INFO] 接口名称：新增io变量
[2023-08-23 13:49:12,156] logger_util.py->write_log line:61 [INFO] 接口方式：post
[2023-08-23 13:49:12,156] logger_util.py->write_log line:61 [INFO] 接口路径：http://127.0.0.1:18000/api/v1/variable/tunnel/80/tag
[2023-08-23 13:49:12,156] logger_util.py->write_log line:61 [INFO] 请求头：{}
[2023-08-23 13:49:12,156] logger_util.py->write_log line:61 [INFO] 请求参数：[{'archiveSetting': None, 'groupId': None, 'name': 'A11', 'description': 'F64位浮点数IEEE754', 'typeName': 'F64位浮点数IEEE754', 'config': {'readWriteMode': 0, 'address': '400055', 'interval': '10000', 'stringLength': 'null', 'zoom': '1', 'digit': 'null', 'readWriteRule': '1'}, 'index': '19'}]
[2023-08-23 13:49:12,156] logger_util.py->write_log line:61 [INFO] 文件上传：None
[2023-08-23 13:49:12,164] logger_util.py->error_log line:65 [INFO] 断言失败:status_code不等于200
[2023-08-23 13:49:12,164] logger_util.py->write_log line:61 [INFO] 实际结果：序号<19>变量配置错误：变量名<A11>已存在，请重新输入
[2023-08-23 13:49:12,164] logger_util.py->write_log line:61 [INFO] 接口请求失败！
[2023-08-23 13:49:12,164] logger_util.py->write_log line:61 [INFO] -------------接口请求结束-----------

[2023-08-23 13:49:12,164] logger_util.py->error_log line:65 [INFO] 断言异常：异常信息: Traceback (most recent call last):
  File "E:\Project_python\api_cms\common\requests_util.py", line 353, in validate_result
    error_log("断言失败:"+assert_key+"不等于"+str(assert_value))
  File "E:\Project_python\api_cms\common\logger_util.py", line 66, in error_log
    raise Exception(log_message)
Exception: 断言失败:status_code不等于200

[2023-08-23 13:49:12,165] logger_util.py->error_log line:65 [INFO] 分析YAML文件异常：异常信息: Traceback (most recent call last):
  File "E:\Project_python\api_cms\common\requests_util.py", line 353, in validate_result
    error_log("断言失败:"+assert_key+"不等于"+str(assert_value))
  File "E:\Project_python\api_cms\common\logger_util.py", line 66, in error_log
    raise Exception(log_message)
Exception: 断言失败:status_code不等于200

During handling of the above exception, another exception occurred:

Traceback (most recent call last):
  File "E:\Project_python\api_cms\common\requests_util.py", line 255, in analysis_yaml
    self.validate_result(yq_result, return_text, status_code)
  File "E:\Project_python\api_cms\common\requests_util.py", line 408, in validate_result
    error_log("断言异常：异常信息: %s" % str(traceback.format_exc()))
  File "E:\Project_python\api_cms\common\logger_util.py", line 66, in error_log
    raise Exception(log_message)
Exception: 断言异常：异常信息: Traceback (most recent call last):
  File "E:\Project_python\api_cms\common\requests_util.py", line 353, in validate_result
    error_log("断言失败:"+assert_key+"不等于"+str(assert_value))
  File "E:\Project_python\api_cms\common\logger_util.py", line 66, in error_log
    raise Exception(log_message)
Exception: 断言失败:status_code不等于200


[2023-08-23 13:49:12,191] logger_util.py->write_log line:61 [INFO] 
-------------接口请求开始-----------
[2023-08-23 13:49:12,191] logger_util.py->write_log line:61 [INFO] 接口名称：新增io变量
[2023-08-23 13:49:12,191] logger_util.py->write_log line:61 [INFO] 接口方式：post
[2023-08-23 13:49:12,191] logger_util.py->write_log line:61 [INFO] 接口路径：http://127.0.0.1:18000/api/v1/variable/tunnel/80/tag
[2023-08-23 13:49:12,191] logger_util.py->write_log line:61 [INFO] 请求头：{}
[2023-08-23 13:49:12,191] logger_util.py->write_log line:61 [INFO] 请求参数：[{'archiveSetting': None, 'groupId': None, 'name': 'A12', 'description': '字符串', 'typeName': '字符串', 'config': {'readWriteMode': 0, 'address': '400060', 'interval': '10000', 'stringLength': '10', 'zoom': 'null', 'digit': 'null', 'readWriteRule': '1'}, 'index': '20'}]
[2023-08-23 13:49:12,191] logger_util.py->write_log line:61 [INFO] 文件上传：None
[2023-08-23 13:49:12,201] logger_util.py->error_log line:65 [INFO] 断言失败:status_code不等于200
[2023-08-23 13:49:12,201] logger_util.py->write_log line:61 [INFO] 实际结果：序号<20>变量配置错误：变量名<A12>已存在，请重新输入
[2023-08-23 13:49:12,201] logger_util.py->write_log line:61 [INFO] 接口请求失败！
[2023-08-23 13:49:12,201] logger_util.py->write_log line:61 [INFO] -------------接口请求结束-----------

[2023-08-23 13:49:12,202] logger_util.py->error_log line:65 [INFO] 断言异常：异常信息: Traceback (most recent call last):
  File "E:\Project_python\api_cms\common\requests_util.py", line 353, in validate_result
    error_log("断言失败:"+assert_key+"不等于"+str(assert_value))
  File "E:\Project_python\api_cms\common\logger_util.py", line 66, in error_log
    raise Exception(log_message)
Exception: 断言失败:status_code不等于200

[2023-08-23 13:49:12,202] logger_util.py->error_log line:65 [INFO] 分析YAML文件异常：异常信息: Traceback (most recent call last):
  File "E:\Project_python\api_cms\common\requests_util.py", line 353, in validate_result
    error_log("断言失败:"+assert_key+"不等于"+str(assert_value))
  File "E:\Project_python\api_cms\common\logger_util.py", line 66, in error_log
    raise Exception(log_message)
Exception: 断言失败:status_code不等于200

During handling of the above exception, another exception occurred:

Traceback (most recent call last):
  File "E:\Project_python\api_cms\common\requests_util.py", line 255, in analysis_yaml
    self.validate_result(yq_result, return_text, status_code)
  File "E:\Project_python\api_cms\common\requests_util.py", line 408, in validate_result
    error_log("断言异常：异常信息: %s" % str(traceback.format_exc()))
  File "E:\Project_python\api_cms\common\logger_util.py", line 66, in error_log
    raise Exception(log_message)
Exception: 断言异常：异常信息: Traceback (most recent call last):
  File "E:\Project_python\api_cms\common\requests_util.py", line 353, in validate_result
    error_log("断言失败:"+assert_key+"不等于"+str(assert_value))
  File "E:\Project_python\api_cms\common\logger_util.py", line 66, in error_log
    raise Exception(log_message)
Exception: 断言失败:status_code不等于200


