[2023-08-08 10:15:20,981] logger_util.py->error_log line:65 [INFO] 发送请求异常：异常信息: Traceback (most recent call last):
  File "E:\Project_python\api_SIOT\common\requests_util.py", line 318, in send_request
    kwargs[key] = self.replace_load(value)
  File "E:\Project_python\api_SIOT\common\requests_util.py", line 157, in replace_load
    data = self.int_load(data)
  File "E:\Project_python\api_SIOT\common\requests_util.py", line 121, in int_load
    int_value = int(new_value)
ValueError: invalid literal for int() with base 10: "_SINT1': 'ddt{{-11}}"

[2023-08-08 10:15:20,981] logger_util.py->error_log line:65 [INFO] 分析YAML文件异常：异常信息: Traceback (most recent call last):
  File "E:\Project_python\api_SIOT\common\requests_util.py", line 318, in send_request
    kwargs[key] = self.replace_load(value)
  File "E:\Project_python\api_SIOT\common\requests_util.py", line 157, in replace_load
    data = self.int_load(data)
  File "E:\Project_python\api_SIOT\common\requests_util.py", line 121, in int_load
    int_value = int(new_value)
ValueError: invalid literal for int() with base 10: "_SINT1': 'ddt{{-11}}"

During handling of the above exception, another exception occurred:

Traceback (most recent call last):
  File "E:\Project_python\api_SIOT\common\requests_util.py", line 197, in analysis_yaml
    res = self.send_request(name =name,method=method,
  File "E:\Project_python\api_SIOT\common\requests_util.py", line 338, in send_request
    error_log("发送请求异常：异常信息: %s" % str(traceback.format_exc()))
  File "E:\Project_python\api_SIOT\common\logger_util.py", line 66, in error_log
    raise Exception(log_message)
Exception: 发送请求异常：异常信息: Traceback (most recent call last):
  File "E:\Project_python\api_SIOT\common\requests_util.py", line 318, in send_request
    kwargs[key] = self.replace_load(value)
  File "E:\Project_python\api_SIOT\common\requests_util.py", line 157, in replace_load
    data = self.int_load(data)
  File "E:\Project_python\api_SIOT\common\requests_util.py", line 121, in int_load
    int_value = int(new_value)
ValueError: invalid literal for int() with base 10: "_SINT1': 'ddt{{-11}}"


[2023-08-08 10:15:21,099] logger_util.py->error_log line:65 [INFO] 发送请求异常：异常信息: Traceback (most recent call last):
  File "E:\Project_python\api_SIOT\common\requests_util.py", line 318, in send_request
    kwargs[key] = self.replace_load(value)
  File "E:\Project_python\api_SIOT\common\requests_util.py", line 157, in replace_load
    data = self.int_load(data)
  File "E:\Project_python\api_SIOT\common\requests_util.py", line 121, in int_load
    int_value = int(new_value)
ValueError: invalid literal for int() with base 10: "_INT1': 'ddt{{22}}"

[2023-08-08 10:15:21,100] logger_util.py->error_log line:65 [INFO] 分析YAML文件异常：异常信息: Traceback (most recent call last):
  File "E:\Project_python\api_SIOT\common\requests_util.py", line 318, in send_request
    kwargs[key] = self.replace_load(value)
  File "E:\Project_python\api_SIOT\common\requests_util.py", line 157, in replace_load
    data = self.int_load(data)
  File "E:\Project_python\api_SIOT\common\requests_util.py", line 121, in int_load
    int_value = int(new_value)
ValueError: invalid literal for int() with base 10: "_INT1': 'ddt{{22}}"

During handling of the above exception, another exception occurred:

Traceback (most recent call last):
  File "E:\Project_python\api_SIOT\common\requests_util.py", line 197, in analysis_yaml
    res = self.send_request(name =name,method=method,
  File "E:\Project_python\api_SIOT\common\requests_util.py", line 338, in send_request
    error_log("发送请求异常：异常信息: %s" % str(traceback.format_exc()))
  File "E:\Project_python\api_SIOT\common\logger_util.py", line 66, in error_log
    raise Exception(log_message)
Exception: 发送请求异常：异常信息: Traceback (most recent call last):
  File "E:\Project_python\api_SIOT\common\requests_util.py", line 318, in send_request
    kwargs[key] = self.replace_load(value)
  File "E:\Project_python\api_SIOT\common\requests_util.py", line 157, in replace_load
    data = self.int_load(data)
  File "E:\Project_python\api_SIOT\common\requests_util.py", line 121, in int_load
    int_value = int(new_value)
ValueError: invalid literal for int() with base 10: "_INT1': 'ddt{{22}}"


